Workbook

Sheet AMCU Details
K1: =SUBTOTAL(9,K3:K1197) -> 31721992 | L1: =SUBTOTAL(9,L3:L1197) -> 9535101.1 | M1: =SUBTOTAL(9,M3:M1197) -> 30000 | P1: =SUBTOTAL(9,P3:P1197) -> 22216891 | Q1: =SUBTOTAL(9,Q3:Q1197) -> 7284344.1 | R1: =SUBTOTAL(9,R3:R1197) -> 1985000 | U1: =SUBTOTAL(9,U3:U1197) -> 190328 | V1: =SUBTOTAL(9,V3:V1197) -> 75429 | W1: =SUBTOTAL(9,W3:W1197) -> 7897.0656 | X1: =SUBTOTAL(9,X3:X1197) -> 11825.474 | Y1: =SUBTOTAL(9,Y3:Y1197) -> 19528.991 | Z1: =SUBTOTAL(9,Z3:Z1197) -> 19478.036 | AA1: =SUBTOTAL(9,AA3:AA1197) -> 26919.933 | AB1: =SUBTOTAL(9,AB3:AB1197) -> 19517.205 | ... DK1: =SUBTOTAL(9,DK3:DK1197) -> 651011.69
A2: Owner | B2: MPG Code | C2: MPG Code New | D2: MPG Name | E2: BMC | F2: Date of Purchase | G2: Issue Date | H2: AMCU No | I2: SD Payment Status | J2: Centre Status | K2: Assets Value | L2: Total Deduction | M2: Amount Returned | N2: Returned Date | O2: Benificery Name | P2: Recoverable Value | Q2: EMI | R2: SD | S2: UTR/UPI | T2: Down Payment Date | U2: Old Deposit | V2: Farmer Payment | W2: Apr-22 | X2: May-22 | Y2: Jun-22 | Z2: Jul-22 | AA2: Aug-22 | AB2: SEp-22 | AC2: Oct-22 | AD2: Nov-22 | AE2: Dec-22 | AF2: Jan-23 | AG2: Feb-23 | AH2: Mar-23 | AI2: FY 22-23 | AJ2: Apr-23 | AK2: May-23 | AL2: Jun-23 | AM2: Jul-23 | AN2: Aug-23 | AO2: SEp-23 | AP2: Oct-23 | AQ2: Nov-23 | AR2: Dec-23 | AS2: Jan-24 | AT2: Feb-24 | AU2: Mar-24 | AV2: FY 23-24 | AW2: Apr-24 | AX2: May-24 | AY2: Jun-24 | AZ2: Jul-24 | BA2: Aug-24 | BB2: 20-26 Sep | BC2: SEp-24 | BD2: 27-03 Oct | BE2: 05-11 Oct | BF2: 11-17 Oct | BG2: 18-24 | BH2: 25-31 | BI2: Oct-24 | BJ2: 01-07 Nov | BK2: 08-14 Nov | BL2: 15-21 Nov | BM2: 22-28 Nov | BN2: Nov-24 | BO2: 29-05 Dec | BP2: 06-12 Dec | BQ2: 13-19 Dec | BR2: 20-26 Dec | BS2: Dec-24 | BT2: 27 Dec -02 Jan | BU2: 03-09 Jan | BV2: 10-16 Jan | BW2: 17-23 Jan | BX2: 24-30 Jan | BY2: Jan-25 | BZ2: 0-06 Feb | CA2: 07-13 Feb | CB2: 14-20 Feb | CC2: 21-27 Feb | CD2: Feb-25 | CE2: 28-06 Mar | CF2: 07-13 Mar | CG2: 14-20 Mar | CH2: 21-27 Mar | CI2: 28-31 Mar | CJ2: Mar-25 | CK2: FY 24-25 | CL2: 01-03 Apr | CM2: 4-10 Apr | CN2: 11-17 Apr | CO2: 18-24 Apr | CP2: Apr-25 | CQ2: 25-01 May | CR2: 02-08 May | CS2: 09-15 May | CT2: 16-22 May | CU2: 23-29 May | CV2: May-25 | CW2: 30-05 Jun | CX2: 06-12 Jun | CY2: 13-18 Jun | CZ2: 19-26 Jun | DA2: Jun-25 | DB2: Jul-25 | DC2: Aug-25 | DD2: Sep-25 | DE2: Oct-25 | DF2: Nov-25 | DG2: Dec-25 | DH2: Jan-26 | DI2: Feb-26 | DJ2: Mar-26 | DK2: FY 25-26
A3: PRAVAH/ITC | B3: 01170 | C3: 00000000 | D3: #N/A | E3: Halsi | G3: 44595 | I3: =IF(Table1[[#This Row],[Centre Status]]="Returned","NA",IF(Table1[[#This Row],[SD]]>19000,"Full Payment",IF(Table1[[#This Row],[SD]]<1,"No Payment","Partial Payment"))) -> No Payment | J3: Active | K3: 64000 | L3: =Q3+R3+U3+Table1[[#This Row],[Farmer Payment]] -> 1567 | P3: =K3-L3+M3 -> 62433 | Q3: =AI3+AV3+CK3+Table1[[#This Row],[FY 25-26]] -> 1567 | W3: 0 | X3: 0 | Y3: 783 | Z3: 784 | AA3: 0 | AB3: 0 | AC3: 0 | AD3: 0 | AE3: 0 | AF3: 0 | AG3: 0 | AH3: 0 | AI3: =SUM(W3:AH3) -> 1567 | AJ3: 0 | AK3: 0 | AL3: 0 | AM3: 0 | AN3: 0 | AO3: 0 | AP3: 0 | AQ3: 0 | AR3: 0 | AS3: 0 | AT3: 0 | AU3: 0 | AV3: =SUM(AJ3:AU3) -> 0 | AW3: 0 | AX3: 0 | AY3: 0 | AZ3: 0 | BA3: 0 | BB3: 0 | BC3: 0 | BD3: 0 | BE3: 0 | BF3: 0 | BG3: 0 | BH3: 0 | BI3: 0 | BJ3: 0 | BK3: 0 | BL3: 0 | BM3: 0 | BN3: 0 | BO3: 0 | BP3: 0 | BQ3: 0 | BR3: 0 | BS3: 0 | BT3: 0 | BU3: 0 | BV3: 0 | BW3: 0 | BX3: 0 | BY3: 0 | BZ3: 0 | CA3: 0 | CB3: 0 | CC3: 0 | CD3: 0 | CE3: 0 | CF3: 0 | CG3: 0 | CH3: 0 | CI3: 0 | CJ3: 0 | CK3: =SUM(AW3:CJ3) -> 0 | CM3: 0 | CN3: 0 | CO3: 0 | CP3: 0 | CQ3: 0 | CR3: 0 | CS3: 0 | CT3: 0 | CU3: 0 | CV3: 0 | CW3: 0 | CX3: 0 | CY3: 0 | CZ3: 0 | DK3: =SUM(Table1[[#This Row],[01-03 Apr]:[Mar-26]]) -> 0
A4: PRAVAH/ITC | B4: 01186 | C4: 00000000 | D4: #N/A | E4: Halsi | G4: 44595 | H4: 277356 | I4: =IF(Table1[[#This Row],[Centre Status]]="Returned","NA",IF(Table1[[#This Row],[SD]]>19000,"Full Payment",IF(Table1[[#This Row],[SD]]<1,"No Payment","Partial Payment"))) -> No Payment | J4: Active | K4: 64000 | L4: =Q4+R4+U4+Table1[[#This Row],[Farmer Payment]] -> 5896.4322 | P4: =K4-L4+M4 -> 58103.568 | Q4: =AI4+AV4+CK4+Table1[[#This Row],[FY 25-26]] -> 5896.4322 | W4: 0 | X4: 0 | Y4: 1861 | Z4: 1861 | AA4: 2174.4322 | AB4: 0 | AC4: 0 | AD4: 0 | AE4: 0 | AF4: 0 | AG4: 0 | AH4: 0 | AI4: =SUM(W4:AH4) -> 5896.4322 | AJ4: 0 | AK4: 0 | AL4: 0 | AM4: 0 | AN4: 0 | AO4: 0 | AP4: 0 | AQ4: 0 | AR4: 0 | AS4: 0 | AT4: 0 | AU4: 0 | AV4: =SUM(AJ4:AU4) -> 0 | AW4: 0 | AX4: 0 | AY4: 0 | AZ4: 0 | BA4: 0 | BB4: 0 | BC4: 0 | BD4: 0 | BE4: 0 | BF4: 0 | BG4: 0 | BH4: 0 | BI4: 0 | BJ4: 0 | BK4: 0 | BL4: 0 | BM4: 0 | BN4: 0 | BO4: 0 | BP4: 0 | BQ4: 0 | BR4: 0 | BS4: 0 | BT4: 0 | BU4: 0 | BV4: 0 | BW4: 0 | BX4: 0 | BY4: 0 | BZ4: 0 | CA4: 0 | CB4: 0 | CC4: 0 | CD4: 0 | CE4: 0 | CF4: 0 | CG4: 0 | CH4: 0 | CI4: 0 | CJ4: 0 | CK4: =SUM(AW4:CJ4) -> 0 | CM4: 0 | CN4: 0 | CO4: 0 | CP4: 0 | CQ4: 0 | CR4: 0 | CS4: 0 | CT4: 0 | CU4: 0 | CV4: 0 | CW4: 0 | CX4: 0 | CY4: 0 | CZ4: 0 | DK4: =SUM(Table1[[#This Row],[01-03 Apr]:[Mar-26]]) -> 0
A5: PRAVAH/ITC | B5: 1187 | C5: 10020017 | D5: Gomukh Ramchanderpur 2 | E5: Laldiyara | G5: 44565 | H5: 274122 | I5: =IF(Table1[[#This Row],[Centre Status]]="Returned","NA",IF(Table1[[#This Row],[SD]]>19000,"Full Payment",IF(Table1[[#This Row],[SD]]<1,"No Payment","Partial Payment"))) -> Full Payment | J5: Active | K5: 64000 | L5: =Q5+R5+U5+Table1[[#This Row],[Farmer Payment]] -> 64000 | P5: =K5-L5+M5 -> 0 | Q5: =AI5+AV5+CK5+Table1[[#This Row],[FY 25-26]] -> 44000 | R5: 20000 | S5: 208683739594 | T5: 44647 | W5: 3603.8126 | X5: 0 | Y5: 13546.712 | Z5: 10993.01 | AA5: 15399.013 | AB5: 457.4528 | AC5: 0 | AD5: 0 | AE5: 0 | AF5: 0 | AG5: 0 | AH5: 0 | AI5: =SUM(W5:AH5) -> 44000 | AJ5: 0 | AK5: 0 | AL5: 0 | AM5: 0 | AN5: 0 | AO5: 0 | AP5: 0 | AQ5: 0 | AR5: 0 | AS5: 0 | AT5: 0 | AU5: 0 | AV5: =SUM(AJ5:AU5) -> 0 | AW5: 0 | AX5: 0 | AY5: 0 | AZ5: 0 | BA5: 0 | BB5: 0 | BC5: 0 | BD5: 0 | BE5: 0 | BF5: 0 | BG5: 0 | BH5: 0 | BI5: 0 | BJ5: 0 | BK5: 0 | BL5: 0 | BM5: 0 | BN5: 0 | BO5: 0 | BP5: 0 | BQ5: 0 | BR5: 0 | BS5: 0 | BT5: 0 | BU5: 0 | BV5: 0 | BW5: 0 | BX5: 0 | BY5: 0 | BZ5: 0 | CA5: 0 | CB5: 0 | CC5: 0 | CD5: 0 | CE5: 0 | CF5: 0 | CG5: 0 | CH5: 0 | CI5: 0 | CJ5: 0 | CK5: =SUM(AW5:CJ5) -> 0 | CM5: 0 | CN5: 0 | CO5: 0 | CP5: 0 | CQ5: 0 | CR5: 0 | CS5: 0 | CT5: 0 | CU5: 0 | CV5: 0 | CW5: 0 | CX5: 0 | CY5: 0 | CZ5: 0 | DK5: =SUM(Table1[[#This Row],[01-03 Apr]:[Mar-26]]) -> 0
C6: 10010082 | D6: Gomukh Sharmatola Sahuri | E6: Manjhaul | G6: 45556 | H6: 381762 | I6: =IF(Table1[[#This Row],[Centre Status]]="Returned","NA",IF(Table1[[#This Row],[SD]]>19000,"Full Payment",IF(Table1[[#This Row],[SD]]<1,"No Payment","Partial Payment"))) -> Full Payment | J6: Active | K6: 110000 | L6: =Q6+R6+U6+Table1[[#This Row],[Farmer Payment]] -> 44235.135 | P6: =K6-L6+M6 -> 65764.865 | Q6: =AI6+AV6+CK6+Table1[[#This Row],[FY 25-26]] -> 24235.135 | R6: 20000 | S6: 426496921266 | T6: 45555 | AI6: =SUM(W6:AH6) -> 0 | AV6: =SUM(AJ6:AU6) -> 0 | BB6: 0 | BC6: 0 | BD6: 0 | BE6: 0 | BF6: 0 | BG6: 0 | BH6: 0 | BI6: 455 | BJ6: 0 | BK6: 0 | BL6: 500 | BM6: 500 | BN6: 861 | BO6: 0 | BP6: 0 | BQ6: 0 | BR6: 0 | BS6: 1733.671 | BT6: 500 | BU6: 500 | BV6: 0 | BW6: 0 | BX6: 0 | BY6: 2757.7018 | BZ6: 0 | CA6: 0 | CB6: 0 | CC6: 0 | CD6: 4465.5445 | CE6: 0 | CF6: 0 | CG6: 0 | CH6: 0 | CI6: 0 | CJ6: 5203.0765 | CK6: =SUM(AW6:CJ6) -> 17475.994 | CM6: 0 | CN6: 0 | CO6: 0 | CP6: 2767.9216 | CQ6: 0 | CR6: 0 | CS6: 0 | CT6: 0 | CU6: 0 | CV6: 3991.2198 | CW6: 0 | CX6: 0 | CY6: 0 | CZ6: 0 | DK6: =SUM(Table1[[#This Row],[01-03 Apr]:[Mar-26]]) -> 6759.1414
C7: 10140125 | D7: Gomukh Dullahpur Niyajipur | E7: Dumraon | G7: 45566 | H7: 399066 | I7: =IF(Table1[[#This Row],[Centre Status]]="Returned","NA",IF(Table1[[#This Row],[SD]]>19000,"Full Payment",IF(Table1[[#This Row],[SD]]<1,"No Payment","Partial Payment"))) -> NA | J7: Returned | K7: 110000 | L7: =Q7+R7+U7+Table1[[#This Row],[Farmer Payment]] -> 20000 | M7: =20000+20000 -> 40000 | N7: 45705 | O7: Rajesh kumar | P7: =K7-L7+M7 -> 130000 | Q7: =AI7+AV7+CK7+Table1[[#This Row],[FY 25-26]] -> 0 | R7: 20000 | S7: 427123622077 | T7: 45562 | AI7: =SUM(W7:AH7) -> 0 | AV7: =SUM(AJ7:AU7) -> 0 | BB7: 0 | BC7: 0 | BD7: 0 | BE7: 0 | BF7: 0 | BG7: 0 | BH7: 0 | BI7: 0 | BJ7: 0 | BK7: 0 | BL7: 0 | BM7: 0 | BN7: 0 | BO7: 0 | BP7: 0 | BQ7: 0 | BR7: 0 | BS7: 0 | BT7: 0 | BU7: 0 | BV7: 0 | BW7: 0 | BX7: 0 | BY7: 0 | BZ7: 0 | CA7: 0 | CB7: 0 | CC7: 0 | CD7: 0 | CE7: 0 | CF7: 0 | CG7: 0 | CH7: 0 | CI7: 0 | CJ7: 0 | CK7: =SUM(AW7:CJ7) -> 0 | CM7: 0 | CN7: 0 | CO7: 0 | CP7: 0 | CQ7: 0 | CR7: 0 | CS7: 0 | CT7: 0 | CU7: 0 | CV7: 0 | CW7: 0 | CX7: 0 | CY7: 0 | CZ7: 0 | DK7: =SUM(Table1[[#This Row],[01-03 Apr]:[Mar-26]]) -> 0
C8: 10530070 | D8: GOMUKH PARAN 2 | E8: Kalyanpur | G8: 45834 | I8: =IF(Table1[[#This Row],[Centre Status]]="Returned","NA",IF(Table1[[#This Row],[SD]]>19000,"Full Payment",IF(Table1[[#This Row],[SD]]<1,"No Payment","Partial Payment"))) -> No Payment | J8: Active | K8: 110000 | L8: =Q8+R8+U8+Table1[[#This Row],[Farmer Payment]] -> 0 | P8: =K8-L8+M8 -> 110000 | Q8: =AI8+AV8+CK8+Table1[[#This Row],[FY 25-26]] -> 0 | AI8: =SUM(W8:AH8) -> 0 | AV8: =SUM(AJ8:AU8) -> 0 | CK8: =SUM(AW8:CJ8) -> 0 | CW8: 0 | CX8: 0 | CY8: 0 | CZ8: 0 | DK8: =SUM(Table1[[#This Row],[01-03 Apr]:[Mar-26]]) -> 0
C9: 10530071 | D9: GOMUKH KHARAGPUR | E9: Kalyanpur | G9: 45834 | I9: =IF(Table1[[#This Row],[Centre Status]]="Returned","NA",IF(Table1[[#This Row],[SD]]>19000,"Full Payment",IF(Table1[[#This Row],[SD]]<1,"No Payment","Partial Payment"))) -> No Payment | J9: Active | K9: 110000 | L9: =Q9+R9+U9+Table1[[#This Row],[Farmer Payment]] -> 0 | P9: =K9-L9+M9 -> 110000 | Q9: =AI9+AV9+CK9+Table1[[#This Row],[FY 25-26]] -> 0 | AI9: =SUM(W9:AH9) -> 0 | AV9: =SUM(AJ9:AU9) -> 0 | CK9: =SUM(AW9:CJ9) -> 0 | CW9: 0 | CX9: 0 | CY9: 0 | CZ9: 0 | DK9: =SUM(Table1[[#This Row],[01-03 Apr]:[Mar-26]]) -> 0
C10: 10110158 | D10: GOMUKH CHOWKI 2 | E10: S kamal | G10: 45842 | I10: =IF(Table1[[#This Row],[Centre Status]]="Returned","NA",IF(Table1[[#This Row],[SD]]>19000,"Full Payment",IF(Table1[[#This Row],[SD]]<1,"No Payment","Partial Payment"))) -> Full Payment | J10: Active | K10: 110000 | L10: =Q10+R10+U10+Table1[[#This Row],[Farmer Payment]] -> 20000 | P10: =K10-L10+M10 -> 90000 | Q10: =AI10+AV10+CK10+Table1[[#This Row],[FY 25-26]] -> 0 | R10: 20000 | S10: 516276355328 | T10: 45819 | AI10: =SUM(W10:AH10) -> 0 | AV10: =SUM(AJ10:AU10) -> 0 | CK10: =SUM(AW10:CJ10) -> 0 | CW10: 0 | CX10: 0 | CY10: 0 | CZ10: 0 | DK10: =SUM(Table1[[#This Row],[01-03 Apr]:[Mar-26]]) -> 0
C11: 10110159 | D11: GOMUKH MOHABA | E11: S kamal | G11: 45842 | I11: =IF(Table1[[#This Row],[Centre Status]]="Returned","NA",IF(Table1[[#This Row],[SD]]>19000,"Full Payment",IF(Table1[[#This Row],[SD]]<1,"No Payment","Partial Payment"))) -> Full Payment | J11: Active | K11: 110000 | L11: =Q11+R11+U11+Table1[[#This Row],[Farmer Payment]] -> 20000 | P11: =K11-L11+M11 -> 90000 | Q11: =AI11+AV11+CK11+Table1[[#This Row],[FY 25-26]] -> 0 | R11: 20000 | S11: 516760882866 | T11: 45824 | AI11: =SUM(W11:AH11) -> 0 | AV11: =SUM(AJ11:AU11) -> 0 | CK11: =SUM(AW11:CJ11) -> 0 | CW11: 0 | CX11: 0 | CY11: 0 | CZ11: 0 | DK11: =SUM(Table1[[#This Row],[01-03 Apr]:[Mar-26]]) -> 0
C12: 10080100 | D12: Sibutol Naya Tola | E12: Teghra | G12: 45842 | H12: 0 | I12: =IF(Table1[[#This Row],[Centre Status]]="Returned","NA",IF(Table1[[#This Row],[SD]]>19000,"Full Payment",IF(Table1[[#This Row],[SD]]<1,"No Payment","Partial Payment"))) -> Full Payment | J12: Active | K12: 110000 | L12: =Q12+R12+U12+Table1[[#This Row],[Farmer Payment]] -> 20000 | P12: =K12-L12+M12 -> 90000 | Q12: =AI12+AV12+CK12+Table1[[#This Row],[FY 25-26]] -> 0 | R12: 20000 | S12: 572989707262 | T12: 45824 | AI12: =SUM(W12:AH12) -> 0 | AV12: =SUM(AJ12:AU12) -> 0 | CK12: =SUM(AW12:CJ12) -> 0 | CW12: 0 | CX12: 0 | CY12: 0 | CZ12: 0 | DK12: =SUM(Table1[[#This Row],[01-03 Apr]:[Mar-26]]) -> 0
C13: 10120108 | D13: GOMUKH MANIKA EAST | E13: dalsingsarai | I13: =IF(Table1[[#This Row],[Centre Status]]="Returned","NA",IF(Table1[[#This Row],[SD]]>19000,"Full Payment",IF(Table1[[#This Row],[SD]]<1,"No Payment","Partial Payment"))) -> No Payment | J13: Active | K13: 110000 | L13: =Q13+R13+U13+Table1[[#This Row],[Farmer Payment]] -> 0 | P13: =K13-L13+M13 -> 110000 | Q13: =AI13+AV13+CK13+Table1[[#This Row],[FY 25-26]] -> 0 | AI13: =SUM(W13:AH13) -> 0 | AV13: =SUM(AJ13:AU13) -> 0 | CK13: =SUM(AW13:CJ13) -> 0 | DK13: =SUM(Table1[[#This Row],[01-03 Apr]:[Mar-26]]) -> 0
C14: 10530067 | D14: GOMUKH BANDRA W-6 | E14: Kalyanpur | I14: =IF(Table1[[#This Row],[Centre Status]]="Returned","NA",IF(Table1[[#This Row],[SD]]>19000,"Full Payment",IF(Table1[[#This Row],[SD]]<1,"No Payment","Partial Payment"))) -> No Payment | J14: Active | K14: 110000 | L14: =Q14+R14+U14+Table1[[#This Row],[Farmer Payment]] -> 0 | P14: =K14-L14+M14 -> 110000 | Q14: =AI14+AV14+CK14+Table1[[#This Row],[FY 25-26]] -> 0 | AI14: =SUM(W14:AH14) -> 0 | AV14: =SUM(AJ14:AU14) -> 0 | CK14: =SUM(AW14:CJ14) -> 0 | DK14: =SUM(Table1[[#This Row],[01-03 Apr]:[Mar-26]]) -> 0
C15: 10530074 | D15: GOMUKH BALAHA W-9 | E15: Kalyanpur | G15: 45834 | I15: =IF(Table1[[#This Row],[Centre Status]]="Returned","NA",IF(Table1[[#This Row],[SD]]>19000,"Full Payment",IF(Table1[[#This Row],[SD]]<1,"No Payment","Partial Payment"))) -> Partial Payment | J15: Active | K15: 110000 | L15: =Q15+R15+U15+Table1[[#This Row],[Farmer Payment]] -> 10000 | P15: =K15-L15+M15 -> 100000 | Q15: =AI15+AV15+CK15+Table1[[#This Row],[FY 25-26]] -> 0 | R15: 10000 | S15: 374860488193 | T15: 45826 | AI15: =SUM(W15:AH15) -> 0 | AV15: =SUM(AJ15:AU15) -> 0 | CK15: =SUM(AW15:CJ15) -> 0 | CW15: 0 | CX15: 0 | CY15: 0 | CZ15: 0 | DK15: =SUM(Table1[[#This Row],[01-03 Apr]:[Mar-26]]) -> 0
C16: 10140183 | D16: Gomukh Uttardahan | E16: Dumraon | I16: =IF(Table1[[#This Row],[Centre Status]]="Returned","NA",IF(Table1[[#This Row],[SD]]>19000,"Full Payment",IF(Table1[[#This Row],[SD]]<1,"No Payment","Partial Payment"))) -> Partial Payment | J16: Active | K16: 110000 | L16: =Q16+R16+U16+Table1[[#This Row],[Farmer Payment]] -> 10000 | P16: =K16-L16+M16 -> 100000 | Q16: =AI16+AV16+CK16+Table1[[#This Row],[FY 25-26]] -> 0 | R16: 10000 | S16: 022405583427 | T16: 45818 | AI16: =SUM(W16:AH16) -> 0 | AV16: =SUM(AJ16:AU16) -> 0 | CK16: =SUM(AW16:CJ16) -> 0 | CW16: 0 | CX16: 0 | CY16: 0 | CZ16: 0 | DK16: =SUM(Table1[[#This Row],[01-03 Apr]:[Mar-26]]) -> 0
C17: 10140182 | D17: Gomukh Pandeypur | E17: Dumraon | I17: =IF(Table1[[#This Row],[Centre Status]]="Returned","NA",IF(Table1[[#This Row],[SD]]>19000,"Full Payment",IF(Table1[[#This Row],[SD]]<1,"No Payment","Partial Payment"))) -> Partial Payment | J17: Active | K17: 110000 | L17: =Q17+R17+U17+Table1[[#This Row],[Farmer Payment]] -> 8000 | P17: =K17-L17+M17 -> 102000 | Q17: =AI17+AV17+CK17+Table1[[#This Row],[FY 25-26]] -> 0 | R17: 8000 | S17: 398060379840 | T17: 45806 | AI17: =SUM(W17:AH17) -> 0 | AV17: =SUM(AJ17:AU17) -> 0 | CK17: =SUM(AW17:CJ17) -> 0 | DK17: =SUM(Table1[[#This Row],[01-03 Apr]:[Mar-26]]) -> 0
C18: 10140178 | D18: Gomukh Tiyar | E18: Dumraon | I18: =IF(Table1[[#This Row],[Centre Status]]="Returned","NA",IF(Table1[[#This Row],[SD]]>19000,"Full Payment",IF(Table1[[#This Row],[SD]]<1,"No Payment","Partial Payment"))) -> Partial Payment | J18: Active | K18: 110000 | L18: =Q18+R18+U18+Table1[[#This Row],[Farmer Payment]] -> 10908 | P18: =K18-L18+M18 -> 99092 | Q18: =AI18+AV18+CK18+Table1[[#This Row],[FY 25-26]] -> 908 | R18: 10000 | S18: 252667001659 | T18: 45784 | AI18: =SUM(W18:AH18) -> 0 | AV18: =SUM(AJ18:AU18) -> 0 | CK18: =SUM(AW18:CJ18) -> 0 | CP18: 0 | CR18: 0 | CS18: 0 | CT18: 0 | CU18: 0 | CV18: 908 | CW18: 0 | CX18: 0 | CY18: 0 | CZ18: 0 | DK18: =SUM(Table1[[#This Row],[01-03 Apr]:[Mar-26]]) -> 908
C19: 10140179 | D19: Gomukh Rajpur | E19: Dumraon | I19: =IF(Table1[[#This Row],[Centre Status]]="Returned","NA",IF(Table1[[#This Row],[SD]]>19000,"Full Payment",IF(Table1[[#This Row],[SD]]<1,"No Payment","Partial Payment"))) -> Partial Payment | J19: Active | K19: 110000 | L19: =Q19+R19+U19+Table1[[#This Row],[Farmer Payment]] -> 10476 | P19: =K19-L19+M19 -> 99524 | Q19: =AI19+AV19+CK19+Table1[[#This Row],[FY 25-26]] -> 476 | R19: 10000 | S19: 550550496098 | T19: 45796 | AI19: =SUM(W19:AH19) -> 0 | AV19: =SUM(AJ19:AU19) -> 0 | CK19: =SUM(AW19:CJ19) -> 0 | CP19: 0 | CR19: 0 | CS19: 0 | CT19: 0 | CU19: 0 | CV19: 476 | CW19: 0 | CX19: 0 | CY19: 0 | CZ19: 0 | DK19: =SUM(Table1[[#This Row],[01-03 Apr]:[Mar-26]]) -> 476
C20: 10140180 | D20: Gomukh Gangauli Dubha | E20: Dumraon | I20: =IF(Table1[[#This Row],[Centre Status]]="Returned","NA",IF(Table1[[#This Row],[SD]]>19000,"Full Payment",IF(Table1[[#This Row],[SD]]<1,"No Payment","Partial Payment"))) -> Partial Payment | J20: Active | K20: 110000 | L20: =Q20+R20+U20+Table1[[#This Row],[Farmer Payment]] -> 10000 | P20: =K20-L20+M20 -> 100000 | Q20: =AI20+AV20+CK20+Table1[[#This Row],[FY 25-26]] -> 0 | R20: 10000 | S20: 846061232899 | T20: 45794 | AI20: =SUM(W20:AH20) -> 0 | AV20: =SUM(AJ20:AU20) -> 0 | CK20: =SUM(AW20:CJ20) -> 0 | CR20: 0 | CT20: 0 | CU20: 0 | CV20: 0 | CW20: 0 | CX20: 0 | CY20: 0 | CZ20: 0 | DK20: =SUM(Table1[[#This Row],[01-03 Apr]:[Mar-26]]) -> 0
C21: 10540008 | D21: GOMUKH PARRI | E21: Alauli | G21: 45832 | I21: =IF(Table1[[#This Row],[Centre Status]]="Returned","NA",IF(Table1[[#This Row],[SD]]>19000,"Full Payment",IF(Table1[[#This Row],[SD]]<1,"No Payment","Partial Payment"))) -> Full Payment | J21: Active | K21: 110000 | L21: =Q21+R21+U21+Table1[[#This Row],[Farmer Payment]] -> 20000 | P21: =K21-L21+M21 -> 90000 | Q21: =AI21+AV21+CK21+Table1[[#This Row],[FY 25-26]] -> 0 | R21: 20000 | T21: 45801 | AI21: =SUM(W21:AH21) -> 0 | AV21: =SUM(AJ21:AU21) -> 0 | CK21: =SUM(AW21:CJ21) -> 0 | CV21: 0 | CW21: 0 | CX21: 0 | CY21: 0 | CZ21: 0 | DK21: =SUM(Table1[[#This Row],[01-03 Apr]:[Mar-26]]) -> 0
C22: 10540009 | D22: GOMUKH BHIKHARI GHAT | E22: Alauli | G22: 45832 | I22: =IF(Table1[[#This Row],[Centre Status]]="Returned","NA",IF(Table1[[#This Row],[SD]]>19000,"Full Payment",IF(Table1[[#This Row],[SD]]<1,"No Payment","Partial Payment"))) -> Full Payment | J22: Active | K22: 110000 | L22: =Q22+R22+U22+Table1[[#This Row],[Farmer Payment]] -> 20000 | P22: =K22-L22+M22 -> 90000 | Q22: =AI22+AV22+CK22+Table1[[#This Row],[FY 25-26]] -> 0 | R22: 20000 | S22: 105321869290 | T22: 45801 | AI22: =SUM(W22:AH22) -> 0 | AV22: =SUM(AJ22:AU22) -> 0 | CK22: =SUM(AW22:CJ22) -> 0 | CV22: 0 | CW22: 0 | CX22: 0 | CY22: 0 | CZ22: 0 | DK22: =SUM(Table1[[#This Row],[01-03 Apr]:[Mar-26]]) -> 0
C23: 10080098 | D23: Rani Panchwati | E23: Majhaul(Gadhpura) | I23: =IF(Table1[[#This Row],[Centre Status]]="Returned","NA",IF(Table1[[#This Row],[SD]]>19000,"Full Payment",IF(Table1[[#This Row],[SD]]<1,"No Payment","Partial Payment"))) -> Partial Payment | J23: Active | K23: 110000 | L23: =Q23+R23+U23+Table1[[#This Row],[Farmer Payment]] -> 10000 | P23: =K23-L23+M23 -> 100000 | Q23: =AI23+AV23+CK23+Table1[[#This Row],[FY 25-26]] -> 0 | R23: 10000 | S23: 284703126001 | T23: 45800 | AI23: =SUM(W23:AH23) -> 0 | AV23: =SUM(AJ23:AU23) -> 0 | CK23: =SUM(AW23:CJ23) -> 0 | CR23: 0 | CT23: 0 | CU23: 0 | CV23: 0 | CW23: 0 | CX23: 0 | CY23: 0 | CZ23: 0 | DK23: =SUM(Table1[[#This Row],[01-03 Apr]:[Mar-26]]) -> 0
C24: 10540005 | D24: GOMUKH GADBANNI | E24: Alauli | I24: =IF(Table1[[#This Row],[Centre Status]]="Returned","NA",IF(Table1[[#This Row],[SD]]>19000,"Full Payment",IF(Table1[[#This Row],[SD]]<1,"No Payment","Partial Payment"))) -> Full Payment | J24: Active | K24: 110000 | L24: =Q24+R24+U24+Table1[[#This Row],[Farmer Payment]] -> 20109 | P24: =K24-L24+M24 -> 89891 | Q24: =AI24+AV24+CK24+Table1[[#This Row],[FY 25-26]] -> 109 | R24: 20000 | S24: 305429278180 | T24: 45794 | AI24: =SUM(W24:AH24) -> 0 | AV24: =SUM(AJ24:AU24) -> 0 | CK24: =SUM(AW24:CJ24) -> 0 | CP24: 0 | CR24: 0 | CS24: 0 | CT24: 0 | CU24: 0 | CV24: 109 | CW24: 0 | CX24: 0 | CY24: 0 | CZ24: 0 | DK24: =SUM(Table1[[#This Row],[01-03 Apr]:[Mar-26]]) -> 109
C25: 10540006 | D25: GOMUKH AMBA | E25: Alauli | I25: =IF(Table1[[#This Row],[Centre Status]]="Returned","NA",IF(Table1[[#This Row],[SD]]>19000,"Full Payment",IF(Table1[[#This Row],[SD]]<1,"No Payment","Partial Payment"))) -> Full Payment | J25: Active | K25: 110000 | L25: =Q25+R25+U25+Table1[[#This Row],[Farmer Payment]] -> 20000 | P25: =K25-L25+M25 -> 90000 | Q25: =AI25+AV25+CK25+Table1[[#This Row],[FY 25-26]] -> 0 | R25: 20000 | S25: 753384965934 | T25: 45794 | AI25: =SUM(W25:AH25) -> 0 | AV25: =SUM(AJ25:AU25) -> 0 | CK25: =SUM(AW25:CJ25) -> 0 | CP25: 0 | CR25: 0 | CS25: 0 | CT25: 0 | CU25: 0 | CV25: 0 | CW25: 0 | CX25: 0 | CY25: 0 | CZ25: 0 | DK25: =SUM(Table1[[#This Row],[01-03 Apr]:[Mar-26]]) -> 0
C26: 10540007 | D26: GOMUKH GORIYAMI | E26: Alauli | I26: =IF(Table1[[#This Row],[Centre Status]]="Returned","NA",IF(Table1[[#This Row],[SD]]>19000,"Full Payment",IF(Table1[[#This Row],[SD]]<1,"No Payment","Partial Payment"))) -> Full Payment | J26: Active | K26: 110000 | L26: =Q26+R26+U26+Table1[[#This Row],[Farmer Payment]] -> 20000 | P26: =K26-L26+M26 -> 90000 | Q26: =AI26+AV26+CK26+Table1[[#This Row],[FY 25-26]] -> 0 | R26: 20000 | S26: 924823190609 | T26: 45797 | AI26: =SUM(W26:AH26) -> 0 | AV26: =SUM(AJ26:AU26) -> 0 | CK26: =SUM(AW26:CJ26) -> 0 | CP26: 0 | CR26: 0 | CS26: 0 | CT26: 0 | CU26: 0 | CV26: 0 | CW26: 0 | CX26: 0 | CY26: 0 | CZ26: 0 | DK26: =SUM(Table1[[#This Row],[01-03 Apr]:[Mar-26]]) -> 0
C27: 10140177 | D27: Gomukh Giridhar Baraw | E27: Dumraon | I27: =IF(Table1[[#This Row],[Centre Status]]="Returned","NA",IF(Table1[[#This Row],[SD]]>19000,"Full Payment",IF(Table1[[#This Row],[SD]]<1,"No Payment","Partial Payment"))) -> Partial Payment | J27: Active | K27: 110000 | L27: =Q27+R27+U27+Table1[[#This Row],[Farmer Payment]] -> 10076 | P27: =K27-L27+M27 -> 99924 | Q27: =AI27+AV27+CK27+Table1[[#This Row],[FY 25-26]] -> 76 | R27: 10000 | S27: 666539780403 | T27: 45791 | AI27: =SUM(W27:AH27) -> 0 | AV27: =SUM(AJ27:AU27) -> 0 | CK27: =SUM(AW27:CJ27) -> 0 | CP27: 0 | CR27: 0 | CS27: 0 | CT27: 0 | CU27: 0 | CV27: 76 | CW27: 0 | CX27: 0 | CY27: 0 | CZ27: 0 | DK27: =SUM(Table1[[#This Row],[01-03 Apr]:[Mar-26]]) -> 76
C28: 10060109 | D28: PACHRUKHI | E28: sonvarsha | I28: =IF(Table1[[#This Row],[Centre Status]]="Returned","NA",IF(Table1[[#This Row],[SD]]>19000,"Full Payment",IF(Table1[[#This Row],[SD]]<1,"No Payment","Partial Payment"))) -> Partial Payment | J28: Active | K28: 110000 | L28: =Q28+R28+U28+Table1[[#This Row],[Farmer Payment]] -> 10000 | P28: =K28-L28+M28 -> 100000 | Q28: =AI28+AV28+CK28+Table1[[#This Row],[FY 25-26]] -> 0 | R28: 10000 | S28: 105668245033 | T28: 45808 | AI28: =SUM(W28:AH28) -> 0 | AV28: =SUM(AJ28:AU28) -> 0 | CK28: =SUM(AW28:CJ28) -> 0 | CV28: 0 | CW28: 0 | CX28: 0 | CY28: 0 | CZ28: 0 | DK28: =SUM(Table1[[#This Row],[01-03 Apr]:[Mar-26]]) -> 0
C29: 10060110 | D29: ORABAGICHA | E29: sonvarsha | I29: =IF(Table1[[#This Row],[Centre Status]]="Returned","NA",IF(Table1[[#This Row],[SD]]>19000,"Full Payment",IF(Table1[[#This Row],[SD]]<1,"No Payment","Partial Payment"))) -> Partial Payment | J29: Active | K29: 110000 | L29: =Q29+R29+U29+Table1[[#This Row],[Farmer Payment]] -> 10000 | P29: =K29-L29+M29 -> 100000 | Q29: =AI29+AV29+CK29+Table1[[#This Row],[FY 25-26]] -> 0 | R29: 10000 | S29: 105604215713 | T29: 45806 | AI29: =SUM(W29:AH29) -> 0 | AV29: =SUM(AJ29:AU29) -> 0 | CK29: =SUM(AW29:CJ29) -> 0 | CV29: 0 | CW29: 0 | CX29: 0 | CY29: 0 | CZ29: 0 | DK29: =SUM(Table1[[#This Row],[01-03 Apr]:[Mar-26]]) -> 0
C30: 10030072 | D30: HARLACHAK | E30: Asarganj | I30: =IF(Table1[[#This Row],[Centre Status]]="Returned","NA",IF(Table1[[#This Row],[SD]]>19000,"Full Payment",IF(Table1[[#This Row],[SD]]<1,"No Payment","Partial Payment"))) -> No Payment | J30: Active | K30: 110000 | L30: =Q30+R30+U30+Table1[[#This Row],[Farmer Payment]] -> 0 | P30: =K30-L30+M30 -> 110000 | Q30: =AI30+AV30+CK30+Table1[[#This Row],[FY 25-26]] -> 0 | AI30: =SUM(W30:AH30) -> 0 | AV30: =SUM(AJ30:AU30) -> 0 | CK30: =SUM(AW30:CJ30) -> 0 | CV30: 0 | CW30: 0 | CX30: 0 | CY30: 0 | CZ30: 0 | DK30: =SUM(Table1[[#This Row],[01-03 Apr]:[Mar-26]]) -> 0
C31: 10030073 | D31: KHIRDIH | E31: Asarganj | I31: =IF(Table1[[#This Row],[Centre Status]]="Returned","NA",IF(Table1[[#This Row],[SD]]>19000,"Full Payment",IF(Table1[[#This Row],[SD]]<1,"No Payment","Partial Payment"))) -> No Payment | J31: Active | K31: 110000 | L31: =Q31+R31+U31+Table1[[#This Row],[Farmer Payment]] -> 0 | P31: =K31-L31+M31 -> 110000 | Q31: =AI31+AV31+CK31+Table1[[#This Row],[FY 25-26]] -> 0 | AI31: =SUM(W31:AH31) -> 0 | AV31: =SUM(AJ31:AU31) -> 0 | CK31: =SUM(AW31:CJ31) -> 0 | CV31: 0 | CW31: 0 | CX31: 0 | CY31: 0 | CZ31: 0 | DK31: =SUM(Table1[[#This Row],[01-03 Apr]:[Mar-26]]) -> 0
C32: 10060111 | D32: KHAJURIYA | E32: sonvarsha | I32: =IF(Table1[[#This Row],[Centre Status]]="Returned","NA",IF(Table1[[#This Row],[SD]]>19000,"Full Payment",IF(Table1[[#This Row],[SD]]<1,"No Payment","Partial Payment"))) -> Partial Payment | J32: Active | K32: 110000 | L32: =Q32+R32+U32+Table1[[#This Row],[Farmer Payment]] -> 15000 | P32: =K32-L32+M32 -> 95000 | Q32: =AI32+AV32+CK32+Table1[[#This Row],[FY 25-26]] -> 0 | R32: 15000 | S32: 624874214920 | T32: 45798 | AI32: =SUM(W32:AH32) -> 0 | AV32: =SUM(AJ32:AU32) -> 0 | CK32: =SUM(AW32:CJ32) -> 0 | CV32: 0 | CW32: 0 | CX32: 0 | CY32: 0 | CZ32: 0 | DK32: =SUM(Table1[[#This Row],[01-03 Apr]:[Mar-26]]) -> 0
C33: 10080099 | D33: Bihat - Chakballi | E33: Manjhaul | I33: =IF(Table1[[#This Row],[Centre Status]]="Returned","NA",IF(Table1[[#This Row],[SD]]>19000,"Full Payment",IF(Table1[[#This Row],[SD]]<1,"No Payment","Partial Payment"))) -> Full Payment | J33: Active | K33: 110000 | L33: =Q33+R33+U33+Table1[[#This Row],[Farmer Payment]] -> 20000 | P33: =K33-L33+M33 -> 90000 | Q33: =AI33+AV33+CK33+Table1[[#This Row],[FY 25-26]] -> 0 | R33: 20000 | S33: 104891278164 | T33: 45794 | AI33: =SUM(W33:AH33) -> 0 | AV33: =SUM(AJ33:AU33) -> 0 | CK33: =SUM(AW33:CJ33) -> 0 | CR33: 0 | CT33: 0 | CU33: 0 | CV33: 0 | CW33: 0 | CX33: 0 | CY33: 0 | CZ33: 0 | DK33: =SUM(Table1[[#This Row],[01-03 Apr]:[Mar-26]]) -> 0
C34: 10110104 | D34: GOMUKH RON | E34: Sahebpur Kamal | H34: 386752 | I34: =IF(Table1[[#This Row],[Centre Status]]="Returned","NA",IF(Table1[[#This Row],[SD]]>19000,"Full Payment",IF(Table1[[#This Row],[SD]]<1,"No Payment","Partial Payment"))) -> Full Payment | J34: Active | K34: 110000 | L34: =Q34+R34+U34+Table1[[#This Row],[Farmer Payment]] -> 29605.071 | P34: =K34-L34+M34 -> 80394.929 | Q34: =AI34+AV34+CK34+Table1[[#This Row],[FY 25-26]] -> 9605.0711 | R34: 20000 | S34: 459299204482 | T34: 46014 | AI34: =SUM(W34:AH34) -> 0 | AV34: =SUM(AJ34:AU34) -> 0 | BP34: 0 | BR34: 0 | BU34: 0 | BV34: 0 | BW34: 0 | BX34: 0 | BY34: 0 | BZ34: 0 | CA34: 0 | CB34: 0 | CC34: 0 | CD34: 0 | CE34: 0 | CF34: 0 | CG34: 0 | CH34: 0 | CI34: 0 | CJ34: 3539.0862 | CK34: =SUM(AW34:CJ34) -> 3539.0862 | CM34: 0 | CN34: 0 | CO34: 0 | CP34: 2911.6575 | CQ34: 0 | CR34: 0 | CS34: 0 | CT34: 0 | CU34: 0 | CV34: 3154.3274 | CW34: 0 | CX34: 0 | CY34: 0 | CZ34: 0 | DK34: =SUM(Table1[[#This Row],[01-03 Apr]:[Mar-26]]) -> 6065.9849
C35: 10110103 | D35: GOMUKH KAMATHAN | E35: Sahebpur Kamal | H35: 387339 | I35: =IF(Table1[[#This Row],[Centre Status]]="Returned","NA",IF(Table1[[#This Row],[SD]]>19000,"Full Payment",IF(Table1[[#This Row],[SD]]<1,"No Payment","Partial Payment"))) -> Partial Payment | J35: Active | K35: 110000 | L35: =Q35+R35+U35+Table1[[#This Row],[Farmer Payment]] -> 5000 | P35: =K35-L35+M35 -> 105000 | Q35: =AI35+AV35+CK35+Table1[[#This Row],[FY 25-26]] -> 0 | R35: 5000 | S35: 435368727369 | T35: 46009 | AI35: =SUM(W35:AH35) -> 0 | AV35: =SUM(AJ35:AU35) -> 0 | BP35: 0 | BR35: 0 | BU35: 0 | BV35: 0 | BW35: 0 | BX35: 0 | BY35: 0 | BZ35: 0 | CA35: 0 | CB35: 0 | CC35: 0 | CD35: 0 | CE35: 0 | CF35: 0 | CG35: 0 | CH35: 0 | CI35: 0 | CJ35: 0 | CK35: =SUM(AW35:CJ35) -> 0 | CM35: 0 | CN35: 0 | CO35: 0 | CP35: 0 | CQ35: 0 | CR35: 0 | CS35: 0 | CT35: 0 | CU35: 0 | CV35: 0 | CW35: 0 | CX35: 0 | CY35: 0 | CZ35: 0 | DK35: =SUM(Table1[[#This Row],[01-03 Apr]:[Mar-26]]) -> 0
C36: 10140153 | D36: Gomukh Bramhpur | E36: Dumraon | H36: 387358 | I36: =IF(Table1[[#This Row],[Centre Status]]="Returned","NA",IF(Table1[[#This Row],[SD]]>19000,"Full Payment",IF(Table1[[#This Row],[SD]]<1,"No Payment","Partial Payment"))) -> Partial Payment | J36: Active | K36: 110000 | L36: =Q36+R36+U36+Table1[[#This Row],[Farmer Payment]] -> 15583 | P36: =K36-L36+M36 -> 94417 | Q36: =AI36+AV36+CK36+Table1[[#This Row],[FY 25-26]] -> 5583 | R36: 10000 | S36: 404083753894 | T36: 45659 | AI36: =SUM(W36:AH36) -> 0 | AV36: =SUM(AJ36:AU36) -> 0 | BP36: 0 | BR36: 0 | BV36: 0 | BW36: 0 | BX36: 0 | BY36: 0 | BZ36: 0 | CA36: 0 | CB36: 0 | CC36: 0 | CD36: 0 | CE36: 0 | CF36: 0 | CG36: 0 | CH36: 0 | CI36: 0 | CJ36: 1861 | CK36: =SUM(AW36:CJ36) -> 1861 | CM36: 0 | CN36: 0 | CO36: 0 | CP36: 1861 | CQ36: 0 | CR36: 0 | CS36: 0 | CT36: 0 | CU36: 0 | CV36: 1861 | CW36: 0 | CX36: 0 | CY36: 0 | CZ36: 0 | DK36: =SUM(Table1[[#This Row],[01-03 Apr]:[Mar-26]]) -> 3722
C37: 10110141 | D37: GHAMARIYA | E37: Sahebpur Kamal | I37: =IF(Table1[[#This Row],[Centre Status]]="Returned","NA",IF(Table1[[#This Row],[SD]]>19000,"Full Payment",IF(Table1[[#This Row],[SD]]<1,"No Payment","Partial Payment"))) -> Full Payment | J37: Active | K37: 110000 | L37: =Q37+R37+U37+Table1[[#This Row],[Farmer Payment]] -> 21861 | P37: =K37-L37+M37 -> 88139 | Q37: =AI37+AV37+CK37+Table1[[#This Row],[FY 25-26]] -> 1861 | R37: 20000 | S37: 342259970412 | T37: 45754 | AI37: =SUM(W37:AH37) -> 0 | AV37: =SUM(AJ37:AU37) -> 0 | CF37: 0 | CG37: 0 | CH37: 0 | CI37: 0 | CJ37: 0 | CK37: =SUM(AW37:CJ37) -> 0 | CM37: 0 | CN37: 0 | CO37: 0 | CP37: 0 | CQ37: 0 | CR37: 0 | CS37: 0 | CT37: 0 | CU37: 0 | CV37: 1861 | CW37: 0 | CX37: 0 | CY37: 0 | CZ37: 0 | DK37: =SUM(Table1[[#This Row],[01-03 Apr]:[Mar-26]]) -> 1861
C38: 10530027 | D38: Kolwara | E38: Kalyanpur | H38: 23120074 | I38: =IF(Table1[[#This Row],[Centre Status]]="Returned","NA",IF(Table1[[#This Row],[SD]]>19000,"Full Payment",IF(Table1[[#This Row],[SD]]<1,"No Payment","Partial Payment"))) -> Full Payment | J38: Active | K38: 110000 | L38: =Q38+R38+U38+Table1[[#This Row],[Farmer Payment]] -> 21861 | P38: =K38-L38+M38 -> 88139 | Q38: =AI38+AV38+CK38+Table1[[#This Row],[FY 25-26]] -> 1861 | R38: 20000 | S38: 282553634463 | T38: 45716 | AI38: =SUM(W38:AH38) -> 0 | AV38: =SUM(AJ38:AU38) -> 0 | CK38: =SUM(AW38:CJ38) -> 0 | CM38: 0 | CP38: 0 | CQ38: 0 | CR38: 0 | CS38: 0 | CT38: 0 | CU38: 0 | CV38: 1861 | CW38: 0 | CX38: 0 | CY38: 0 | CZ38: 0 | DK38: =SUM(Table1[[#This Row],[01-03 Apr]:[Mar-26]]) -> 1861
C39: 10530044 | D39: Gomukh Punas | E39: Kalyanpur | H39: 23120088 | I39: =IF(Table1[[#This Row],[Centre Status]]="Returned","NA",IF(Table1[[#This Row],[SD]]>19000,"Full Payment",IF(Table1[[#This Row],[SD]]<1,"No Payment","Partial Payment"))) -> Full Payment | J39: Active | K39: 110000 | L39: =Q39+R39+U39+Table1[[#This Row],[Farmer Payment]] -> 21861 | P39: =K39-L39+M39 -> 88139 | Q39: =AI39+AV39+CK39+Table1[[#This Row],[FY 25-26]] -> 1861 | R39: 20000 | S39: 953340644063 | T39: 45740 | AI39: =SUM(W39:AH39) -> 0 | AV39: =SUM(AJ39:AU39) -> 0 | CK39: =SUM(AW39:CJ39) -> 0 | CM39: 0 | CP39: 0 | CQ39: 0 | CR39: 0 | CS39: 0 | CT39: 0 | CU39: 0 | CV39: 1861 | CW39: 0 | CX39: 0 | CY39: 0 | CZ39: 0 | DK39: =SUM(Table1[[#This Row],[01-03 Apr]:[Mar-26]]) -> 1861
C40: 10530046 | D40: Loharkha | E40: Kalyanpur | H40: 24010126 | I40: =IF(Table1[[#This Row],[Centre Status]]="Returned","NA",IF(Table1[[#This Row],[SD]]>19000,"Full Payment",IF(Table1[[#This Row],[SD]]<1,"No Payment","Partial Payment"))) -> NA | J40: Returned | K40: 110000 | L40: =Q40+R40+U40+Table1[[#This Row],[Farmer Payment]] -> 0 | M40: 20000 | N40: 45790 | P40: =K40-L40+M40 -> 130000 | Q40: =AI40+AV40+CK40+Table1[[#This Row],[FY 25-26]] -> 0 | AI40: =SUM(W40:AH40) -> 0 | AV40: =SUM(AJ40:AU40) -> 0 | CK40: =SUM(AW40:CJ40) -> 0 | CM40: 0 | CP40: 0 | CQ40: 0 | CR40: 0 | CS40: 0 | CT40: 0 | CU40: 0 | CV40: 0 | CW40: 0 | CX40: 0 | CY40: 0 | CZ40: 0 | DK40: =SUM(Table1[[#This Row],[01-03 Apr]:[Mar-26]]) -> 0
...

Sheet Sheet1
N1: Comm Down Paymnet
B2: MPG Code New | C2: MPG Name | D2: BMC | E2: Assets Value | F2: Total Deduction | G2: Amount Returned | H2: Returned Date | I2: Benificery Name | J2: Recoverable Value | K2: EMI | L2: SD | N2: Apr | O2: May | P2: Jun | Q2: Jul | R2: Aug | S2: Sep | T2: Oct | U2: Nov | V2: Dec | W2: Jan | X2: Feb | Y2: Mar | Z2: Apr | AA2: Total Down Payment | AB2: Total Down Payment | AD2: Due | AE2: Pending Payment for Payment
B3: 0 | C3: #N/A | D3: Halsi | E3: 64000 | F3: 1567 | J3: 62433 | K3: 1567 | N3: 0 | O3: 0 | P3: 0 | V3: 0 | W3: 0 | AA3: =SUM(L3:W3) -> 0 | AC3: 20000 | AD3: =AC3-AA3 -> 20000
B4: 0 | C4: #N/A | D4: Halsi | E4: 64000 | F4: 5896.4322 | J4: 58103.568 | K4: 5896.4322 | N4: 0 | O4: 0 | P4: 0 | V4: 0 | W4: 0 | AA4: =SUM(L4:W4) -> 0 | AC4: 20000 | AD4: =AC4-AA4 -> 20000
B5: 10530070 | C5: GOMUKH PARAN 2 | D5: Kalyanpur | E5: 110000 | F5: 0 | J5: 110000 | K5: 0 | L5: 14000 | N5: 0 | O5: 0 | P5: 0 | Q5: 3291 | R5: 2709 | V5: 0 | W5: 0 | AA5: =SUM(L5:W5) -> 20000 | AC5: 20000 | AD5: =AC5-AA5 -> 0
B6: 10530071 | C6: GOMUKH KHARAGPUR | D6: Kalyanpur | E6: 110000 | F6: 0 | J6: 110000 | K6: 0 | N6: 0 | O6: 0 | P6: 0 | V6: 0 | W6: 0 | AA6: =SUM(L6:W6) -> 0 | AC6: 20000 | AD6: =AC6-AA6 -> 20000
B7: 10120108 | C7: GOMUKH MANIKA EAST | D7: dalsingsarai | E7: 110000 | F7: 0 | J7: 110000 | K7: 0 | L7: 10000 | N7: 0 | O7: 0 | P7: 0 | Q7: 67 | R7: 1798 | V7: 0 | W7: 72 | X7: 2377 | AA7: =SUM(L7:X7) -> 14314 | AC7: 20000 | AD7: =AC7-AA7 -> 5686
B8: 10530067 | C8: GOMUKH BANDRA W-6 | D8: Kalyanpur | E8: 110000 | F8: 0 | J8: 110000 | K8: 0 | N8: 0 | O8: 0 | P8: 0 | V8: 0 | W8: 0 | AA8: =SUM(L8:W8) -> 0 | AC8: 20000 | AD8: =AC8-AA8 -> 20000
B9: 10530074 | C9: GOMUKH BALAHA W-9 | D9: Kalyanpur | E9: 110000 | F9: 10000 | J9: 100000 | K9: 0 | L9: 10000 | N9: 0 | O9: 0 | P9: 0 | Q9: 1954 | R9: 2945 | T9: 1685 | V9: 0 | W9: 3416 | AA9: =SUM(L9:W9) -> 20000 | AC9: 20000 | AD9: =AC9-AA9 -> 0
B10: 10140183 | C10: Gomukh Uttardahan | D10: Dumraon | E10: 110000 | F10: 10000 | J10: 100000 | K10: 0 | L10: 10000 | N10: 0 | O10: 0 | P10: 0 | Q10: 4387 | R10: 7445 | V10: 0 | W10: 0 | AA10: =SUM(L10:W10) -> 21832 | AC10: 20000 | AD10: =AC10-AA10 -> -1832
B11: 10140182 | C11: Gomukh Pandeypur | D11: Dumraon | E11: 110000 | F11: 8000 | J11: 102000 | K11: 0 | L11: 8000 | N11: 0 | O11: 0 | P11: 0 | Q11: 2087 | R11: 2161 | V11: 0 | W11: 0 | AA11: =SUM(L11:W11) -> 12248 | AC11: 20000 | AD11: =AC11-AA11 -> 7752
B12: 10140178 | C12: Gomukh Tiyar | D12: Dumraon | E12: 110000 | F12: 10908 | J12: 99092 | K12: 908 | L12: 10000 | N12: 0 | O12: 0 | P12: 0 | Q12: 530 | V12: 0 | W12: 0 | AA12: =SUM(L12:W12) -> 10530 | AC12: 20000 | AD12: =AC12-AA12 -> 9470
B13: 10140179 | C13: Gomukh Rajpur | D13: Dumraon | E13: 110000 | F13: 10476 | J13: 99524 | K13: 476 | L13: 10000 | N13: 0 | O13: 0 | P13: 3407 | Q13: 3357 | R13: 2906 | V13: 0 | W13: 0 | AA13: =SUM(L13:W13) -> 19670 | AC13: 20000 | AD13: =AC13-AA13 -> 330
B14: 10140180 | C14: Gomukh Gangauli Dubha | D14: Dumraon | E14: 110000 | F14: 10000 | J14: 100000 | K14: 0 | L14: 10000 | N14: 0 | O14: 0 | P14: 0 | Q14: 1475 | R14: 2100 | T14: 539 | V14: 1693 | W14: 0 | AA14: =SUM(L14:W14) -> 15807 | AC14: 20000 | AD14: =AC14-AA14 -> 4193
B15: 10080098 | C15: Rani Panchwati | D15: Majhaul(Gadhpura) | E15: 110000 | F15: 10000 | J15: 100000 | K15: 0 | L15: 10000 | N15: 0 | O15: 0 | P15: 1086 | Q15: 4643 | R15: 1868 | V15: 0 | W15: 0 | AA15: =SUM(L15:W15) -> 17597 | AC15: 20000 | AD15: =AC15-AA15 -> 2403
B16: 10140177 | C16: Gomukh Giridhar Baraw | D16: Dumraon | E16: 110000 | F16: 10076 | J16: 99924 | K16: 76 | L16: 10000 | N16: 0 | O16: 0 | P16: 0 | V16: 0 | W16: 0 | AA16: =SUM(L16:W16) -> 10000 | AC16: 20000 | AD16: =AC16-AA16 -> 10000
B17: 10060109 | C17: PACHRUKHI | D17: sonvarsha | E17: 110000 | F17: 10000 | J17: 100000 | K17: 0 | L17: 10000 | N17: 0 | O17: 0 | P17: 0 | Q17: 2161 | R17: 5130 | S17: 0 | T17: 2707 | V17: 0 | W17: 0 | AA17: =SUM(L17:W17) -> 19998 | AC17: 20000 | AD17: =AC17-AA17 -> 2
B18: 10060110 | C18: ORABAGICHA | D18: sonvarsha | E18: 110000 | F18: 10000 | J18: 100000 | K18: 0 | L18: 10000 | N18: 0 | O18: 0 | P18: 0 | Q18: 5736 | R18: 3038 | V18: 0 | W18: 0 | AA18: =SUM(L18:W18) -> 18774 | AC18: 20000 | AD18: =AC18-AA18 -> 1226
B19: 10030072 | C19: HARLACHAK | D19: Asarganj | E19: 110000 | F19: 0 | J19: 110000 | K19: 0 | N19: 0 | O19: 0 | P19: 0 | Q19: 2624 | R19: 2417 | V19: 0 | W19: 0 | AA19: =SUM(L19:W19) -> 5041 | AC19: 20000 | AD19: =AC19-AA19 -> 14959
B20: 10030073 | C20: KHIRDIH | D20: Asarganj | E20: 110000 | F20: 0 | J20: 110000 | K20: 0 | N20: 0 | O20: 0 | P20: 0 | Q20: 599 | R20: 2413 | V20: 0 | W20: 0 | AA20: =SUM(L20:W20) -> 3012 | AC20: 20000 | AD20: =AC20-AA20 -> 16988
B21: 10060111 | C21: KHAJURIYA | D21: sonvarsha | E21: 110000 | F21: 15000 | J21: 95000 | K21: 0 | L21: 15000 | N21: 0 | O21: 0 | P21: 0 | Q21: 5142 | V21: 0 | W21: 0 | AA21: =SUM(L21:W21) -> 20142 | AC21: 20000 | AD21: =AC21-AA21 -> -142 | AE21: 45931
B22: 10110103 | C22: GOMUKH KAMATHAN | D22: Sahebpur Kamal | E22: 110000 | F22: 5000 | J22: 105000 | K22: 0 | L22: 5000 | N22: 0 | O22: 0 | P22: 0 | V22: 0 | W22: 0 | AA22: =SUM(L22:W22) -> 5000 | AC22: 20000 | AD22: =AC22-AA22 -> 15000
B23: 10140153 | C23: Gomukh Bramhpur | D23: Dumraon | E23: 110000 | F23: 15583 | J23: 94417 | K23: 5583 | L23: 10000 | N23: 650 | O23: 0 | P23: 1536 | Q23: 605 | V23: 852 | W23: 1390 | AA23: =SUM(L23:W23) -> 15033 | AC23: 20000 | AD23: =AC23-AA23 -> 4967
B24: 10130098 | C24: Gomukh Gaopur Bhagwatpur | D24: Musrigharari | E24: 110000 | F24: 1861 | J24: 108139 | K24: 1861 | L24: 10000 | N24: 1924 | O24: 1203 | P24: 3519 | Q24: 3304 | R24: 3258 | V24: 0 | W24: 0 | AA24: =SUM(L24:W24) -> 23208 | AC24: 20000 | AD24: =AC24-AA24 -> -3208
B25: 10120107 | C25: Gomukh Ramaiya | D25: Dalsingh Sarai | E25: 110000 | F25: 282 | J25: 109718 | K25: 13052 | L25: 10000 | N25: 0 | O25: 0 | P25: 1685 | Q25: 2146 | R25: 2771 | T25: 2573 | U25: 825 | V25: 0 | W25: 0 | AA25: =SUM(L25:W25) -> 20000 | AC25: 20000 | AD25: =AC25-AA25 -> 0
B26: 10130100 | C26: Gomukh Rajwara | D26: Musrigharari | E26: 110000 | F26: 0 | J26: 110000 | K26: 0 | N26: 0 | O26: 0 | P26: 0 | Q26: 543 | R26: 1390 | V26: 0 | W26: 110 | AA26: =SUM(L26:W26) -> 2043 | AC26: 20000 | AD26: =AC26-AA26 -> 17957
B27: 10130102 | C27: GOMUKH NIKASPUR | D27: Musrigharari | E27: 110000 | F27: 10000 | J27: 100000 | K27: 0 | L27: 10000 | N27: 0 | O27: 0 | P27: 0 | Q27: 1064 | R27: 2903 | V27: 2182 | W27: 3407 | AA27: =SUM(L27:W27) -> 19556 | AC27: 20000 | AD27: =AC27-AA27 -> 444
B28: 10530062 | C28: Gomukh Malinagar East | D28: Kalyanpur | E28: 110000 | F28: 195 | J28: 109805 | K28: 0 | N28: 0 | O28: 0 | P28: 0 | V28: 0 | W28: 0 | AA28: =SUM(L28:W28) -> 0 | AC28: 20000 | AD28: =AC28-AA28 -> 20000
B29: 10120098 | C29: GOMUKH JALALPUR | D29: Dalsinghsarai | E29: 64000 | F29: 11861 | J29: 52139 | K29: 1861 | L29: 10000 | N29: 2639 | O29: 2460 | P29: 0 | Q29: 79 | V29: 0 | W29: 0 | AA29: =SUM(L29:W29) -> 15178 | AC29: 20000 | AD29: =AC29-AA29 -> 4822
B30: 10130095 | C30: Gomukh Saidpur | D30: Dalsinghsarai | E30: 110000 | F30: 1861 | J30: 108139 | K30: 1861 | N30: 2380 | O30: 581 | P30: 0 | V30: 0 | W30: 0 | AA30: =SUM(L30:W30) -> 2961 | AC30: 20000 | AD30: =AC30-AA30 -> 17039
B31: 10060106 | C31: PIPARPATI | D31: SONVARSHA | E31: 110000 | F31: 10000 | J31: 100000 | K31: 0 | L31: 10000 | N31: 0 | O31: 0 | P31: 0 | U31: 355 | V31: 2941 | W31: 929 | AA31: =SUM(L31:W31) -> 14225 | AC31: 20000 | AD31: =AC31-AA31 -> 5775
B32: 10130093 | C32: Gomukh Sherpur Narsari East | D32: Dalsinghsarai | E32: 110000 | F32: 1861 | J32: 108139 | K32: 1861 | N32: 3678 | O32: 805 | P32: 170 | Q32: 1579 | R32: 50 | U32: 322 | V32: 1187 | W32: 854 | AA32: =SUM(L32:W32) -> 8645 | AC32: 20000 | AD32: =AC32-AA32 -> 11355
B33: 10110151 | C33: GOMUKH MINAPUR | D33: Sahebpur Kamal | E33: 110000 | F33: 0 | J33: 110000 | K33: 0 | N33: 0 | O33: 0 | P33: 0 | V33: 0 | W33: 0 | AA33: =SUM(L33:W33) -> 0 | AC33: 20000 | AD33: =AC33-AA33 -> 20000
B34: 10140168 | C34: Gomukh Suraundha | D34: buxar | E34: 110000 | F34: 627 | J34: 109373 | K34: 627 | N34: 625 | O34: 0 | P34: 0 | V34: 0 | W34: 0 | AA34: =SUM(L34:W34) -> 625 | AC34: 20000 | AD34: =AC34-AA34 -> 19375
B35: 10140169 | C35: Gomukh Semra Nandpur | D35: Buxar | E35: 110000 | F35: 1040 | J35: 108960 | K35: 1040 | N35: 4340 | O35: 0 | P35: 0 | R35: 1113 | V35: 0 | W35: 0 | AA35: =SUM(L35:W35) -> 5453 | AC35: 20000 | AD35: =AC35-AA35 -> 14547
B36: 10140156 | C36: Gomukh Mashariya | D36: Buxar | E36: 110000 | F36: 3722 | J36: 106278 | K36: 3722 | N36: 3583 | O36: 3409 | P36: 8105 | Q36: 4903 | R36: 0 | V36: 0 | W36: 0 | AA36: =SUM(L36:W36) -> 20000 | AC36: 20000 | AD36: =AC36-AA36 -> 0
B37: 10140120 | C37: Gomukh Sikraul lakh | D37: Buxar | E37: 110000 | F37: 0 | J37: 110000 | K37: 0 | N37: 0 | O37: 0 | P37: 0 | V37: 0 | W37: 0 | AA37: =SUM(L37:W37) -> 0 | AC37: 20000 | AD37: =AC37-AA37 -> 20000
B38: 10140119 | C38: Gomukh Banswar | D38: Buxar | E38: 110000 | F38: 4625.5597 | J38: 105374.44 | K38: 4625.5597 | N38: 0 | O38: 0 | P38: 0 | V38: 0 | W38: 0 | AA38: =SUM(L38:W38) -> 0 | AC38: 20000 | AD38: =AC38-AA38 -> 20000
B39: 10120105 | C39: GOMUKH HANUMAN NAGAR | D39: Dalsingh Sarai | E39: 110000 | F39: 10506 | J39: 99494 | K39: 506 | L39: 10000 | N39: 0 | O39: 0 | P39: 0 | V39: 0 | W39: 0 | AA39: =SUM(L39:W39) -> 10000 | AC39: 20000 | AD39: =AC39-AA39 -> 10000
B40: 10080095 | C40: Jaynagar | D40: Teghra | E40: 110000 | F40: 10000 | J40: 100000 | K40: 0 | L40: 10000 | N40: 0 | O40: 0 | P40: 0 | Q40: 869 | R40: 1477 | V40: 0 | W40: 0 | AA40: =SUM(L40:W40) -> 12346 | AC40: 20000 | AD40: =AC40-AA40 -> 7654
...

Sheet Sheet2
A1: Date | B1: Particulars | D1: Vch Type | E1: Vch No. | F1: Debit
A2: 13/9/23 | F2: 3718
A3: 28/9/23 | F3: 10000
A4: 20000 | F4: 20000 | G4: Revert
A5: 45412 | B5: Cr | C5: HDFC Bank Ltd. - 50100063899098 | D5: Payment | E5: 84 | F5: 7335
A6: 45426 | B6: Cr | C6: HDFC Bank Ltd. - 50100063899098 | D6: Payment | E6: 124 | F6: 4000
A7: 45429 | B7: Cr | C7: HDFC Bank Ltd. - 50100063899098 | D7: Payment | E7: 145 | F7: 20000
A8: 45450 | B8: Cr | C8: HDFC Bank Ltd. - 50100063899098 | D8: Payment | E8: 212 | F8: 20000
A9: 45461 | B9: Cr | C9: HDFC Bank Ltd. - 50100063899098 | D9: Payment | E9: 248 | F9: 67008 | G9: Check cancilled
A10: 45467 | B10: Cr | C10: HDFC Bank Ltd. - 50100063899098 | D10: Payment | E10: 269 | F10: 13131
A11: 45467 | B11: Cr | C11: HDFC Bank Ltd. - 50100063899098 | D11: Payment | E11: 270 | F11: 15573
L12: 8611 | M12: Amit 2nd lot
A13: 45520 | F13: 5000 | G13: Mahila Re issue Cheque

Sheet PRAVAH
B1: Pravah | E1: Kradex | J1: EIPL
A2: Date | B2: Amount | C2: Purpose | E2: Date | F2: Amount | G2: Purpose | I2: Date | J2: Amount | K2: Purpose
A3: 44676 | B3: 150000 | C3: Battery | E3: 44841 | F3: 150000 | G3: AMCU | I3: 45159 | J3: 700000 | K3: AMCU | L3: ok
A4: 44963 | B4: 204000 | C4: Battery | E4: 44845 | F4: 310000 | G4: AMCU | I4: 45205 | J4: 250000 | K4: AMCU | L4: ok
A5: 44981 | B5: 136000 | C5: Battery | E5: 44855 | F5: 40000 | G5: AMCU | I5: 45238 | J5: 250000 | K5: AMCU | L5: ok
A6: 45031 | B6: 69000 | C6: Battery | E6: 44929 | F6: 250000 | G6: AMCU | I6: 45252 | J6: 250000 | K6: AMCU | L6: ok
A7: 45112 | B7: 109500 | C7: Battery | E7: 45014 | F7: 101967 | G7: AMCU | I7: 45268 | J7: 250000 | K7: AMCU | L7: ok
A8: 45252 | B8: 38075 | C8: Battery | E8: 45090 | F8: 53240 | G8: AMCU | I8: 45299 | J8: 250000 | K8: AMCU | L8: ok | O8: =750000+101967+53240+26620+26620+26620+873835+26620 -> 1885522
A9: 45664 | B9: 72100 | C9: Battery | E9: 45103 | F9: 26620 | G9: AMCU | I9: 45358 | J9: 250000 | K9: AMCU | L9: ok
A10: 45733 | B10: =64396+54250 -> 118646 | C10: Battery | E10: 45134 | F10: 26620 | G10: AMCU | I10: 45426 | J10: 804132 | K10: AMCU
B11: =SUM(B3:B10) -> 897321 | E11: 45175 | F11: 26620 | G11: AMCU | I11: 45448 | J11: 0 | K11: AMCU
E12: 45252 | F12: 873835 | G12: AMCU | J12: =SUM(J3:J11) -> 3004132
F13: =SUM(F3:F12) -> 1858902 | J13: =+J12+F13 -> 4863034
F14: 19715
F15: =+F13+F14 -> 1878617

Sheet Summary
A1: Status as on 28th Feb 25 | E1: Reco | F1: 45846
A2: Security Status of EMI Model (Wef 01/03/2022) | E2: Ledger Name | F2: Amt
A3: Particulars | B3: Amount | E3: AMCU Down Payment | F3: 2355189
A4: Receved as security | B4: =+'AMCU Details'!R1 -> 1985000 | C4: =+B5+B4 -> 3228531.7 | E4: New Assets EMI | F4: 20334481
A5: Unreconciled Security | B5: 1243531.7 | E5: Total | F5: =SUM(F3:F4) -> 22689670
A6: EMI Deduction | B6: =+'AMCU Details'!Q1 -> 7284344.1 | E6: Diff | F6: =+B14-F5 -> -19284454
A7: Total | B7: =+B4+B6+B5 -> 10512876
A8: Retun to MPGs | B8: =+'AMCU Details'!M1 -> 30000
A9: Yet to Map | B9: 0
A10: Fund tr to 51 AMCU purchase | B10: =750000+101967+53240+26620+26620+26620+873835+26620 -> 1885522
B11: =+PRAVAH!J12 -> 3004132
A12: AC - 167600, DPU, 1021611, Coller - 5138, Furnture - 21000, Lab Equipment - 41536, laptop - 33800. | B12: 1290685
A13: Paid to PRAVAH | B13: =+PRAVAH!B11 -> 897321
A14: Net Balance with Daya | B14: =+B7-B8-B10-B13-B11-B9-B12 -> 3405215.8
