Workbook
Name Purchase: Table3[]

Sheet Stock Munger
A1: Item Name | B1: UoM | C1: Opening Stock | D1: Received Stock | E1: Issue Stock | F1: Closing Balance | G1: Reorder Qty | H1: Reorder Level | I1: Open Rate | J1: Stock Value | K1: Stock Staus
A2: 1% Iodine Solution (100ml) | B2: Nos | C2: 15 | D2: 0 | E2: 5 | F2: 10 | G2: 15 | H2: 5 | I2: 90 | J2: 900 | K2: Stock Available
A3: Amber Colour Bottle (250 ML) | B3: Nos | C3: 140 | D3: 0 | E3: 14 | F3: 126 | G3: 50 | H3: 40 | I3: 120 | J3: 15120 | K3: Stock Available
A4: Amyl 500ml | B4: Nos | C4: 50 | D4: 0 | E4: 17 | F4: 33 | G4: 50 | H4: 30 | I4: 366 | J4: 12071 | K4: Stock Available
A5: Analyzer Calibration Cheking Log Book | B5: Nos | C5: 13 | D5: 100 | E5: 0 | F5: 113 | G5: 100 | H5: 20 | I5: 127 | J5: 14401 | K5: Stock Available
A6: Beaker 100 Ml | B6: Nos | C6: 24 | D6: 0 | E6: 6 | F6: 18 | G6: 48 | H6: 10 | I6: 33 | J6: 597 | K6: Stock Available
A7: Beaker 250 ML Borosilicate | B7: Nos | C7: 12 | D7: 0 | E7: 5 | F7: 7 | G7: 48 | H7: 10 | I7: 47 | J7: 330 | K7: PO Required
A8: Beaker 500 Ml | B8: Nos | C8: 49 | D8: 0 | E8: 6 | F8: 43 | G8: 48 | H8: 10 | I8: 64 | J8: 2739 | K8: Stock Available
A9: Beaker 50 ML | B9: Nos | C9: 8 | D9: 0 | E9: 4 | F9: 4 | G9: 48 | H9: 10 | I9: 16 | J9: 64 | K9: PO Required
A10: BMC Cleaning Brush 2" | B10: Nos | C10: 41 | D10: 0 | E10: 4 | F10: 37 | G10: 10 | H10: 10 | I10: 212 | J10: 7859 | K10: Stock Available
A11: BMC Day Book | B11: Nos | C11: 106 | D11: 300 | E11: 98 | F11: 308 | G11: 300 | H11: 60 | I11: 122 | J11: 37434 | K11: Stock Available
A12: Burete Stand | B12: Nos | C12: 16 | D12: 0 | E12: 3 | F12: 13 | G12: 20 | H12: 5 | I12: 258 | J12: 3355 | K12: Stock Available
A13: Burret 50 ML Borosilicate | B13: Nos | C13: 14 | D13: 0 | E13: 6 | F13: 8 | G13: 20 | H13: 5 | I13: 99 | J13: 796 | K13: Stock Available
... A97: Tilt Measure 1 Ml with Bottle | B97: Nos | C97: 256 | D97: 0 | E97: 6 | F97: 250 | G97: 500 | H97: 50 | I97: 32 | J97: 8022 | K97: Stock Available

Sheet Pending Recoveries
A1: Date | B1: (All)
H2: Consumable deduction summary
A3: To BMC/MPG Code | B3: BMC MPG Name | C3: Recovery Done | D3: Sum of Amt | H3: To BMC/MPG Code | I3: BMC MPG Name | J3: Recovery Done | K3: C/F_BAL (FYI-24-25) | L3: C/F_BAL (FYI-25-26) | M3: Purchase Add Amount | N3: Total | O3: Apr | P3: May | Q3: Jun | R3: Jul | S3: Aug | T3: Sep | U3: Oct | V3: Nov | W3: Dec | X3: Jan | Y3: Feb | Z3: Mar | AA3: Balance | AB3: Blank | AC3: Gaurav | AD3: Diff | AE3: Remarks
A4: 2 | B4: Nova Dairy | C4: Pending | D4: 8010.4 | H4: 10520003 | I4: Nova Dairy | J4: Pending | K4: 0 | L4: 9308.4 | M4: 10795.2 | N4: =K4+M4+L4 -> 20103.6 | O4: 0 | P4: 0 | Q4: 0 | R4: 0 | S4: 0 | T4: 0 | U4: 0 | V4: 0 | W4: 0 | Y4: 0 | Z4: 0 | AA4: =N4-SUM(O4:Z4) -> 20103.6 | AC4: =IFERROR(VLOOKUP(H4,'[1]Pending Recoveries'!$A:$D,4,0),0) -> 10795.2 | AD4: =AA4-AC4 -> 9308.4 | AE4: =AC4-M4 -> 0
A5: 1002 | B5: Laldiyara | C5: Pending | D5: 28773.24 | H5: 1002 | I5: Laldiyara | J5: Pending | K5: 0 | L5: 0.19 | M5: 19211.68 | N5: =K5+M5+L5 -> 19211.87 | O5: 0 | P5: 0 | Q5: 0 | R5: 0 | S5: 0 | T5: 0 | U5: 0 | V5: 0 | W5: 0 | Y5: 0 | Z5: 0 | AA5: =N5-SUM(O5:Z5) -> 19211.87 | AC5: =IFERROR(VLOOKUP(H5,'[1]Pending Recoveries'!$A:$D,4,0),0) -> 19211.68 | AD5: =AA5-AC5 -> 0.19 | AE5: =AC5-M5 -> 0
A6: 1003 | B6: Asarganj | C6: Pending | D6: 99.47 | H6: 1003 | I6: Asarganj | J6: Pending | K6: 0 | L6: 0.47 | M6: 0 | N6: =K6+M6+L6 -> 0.47 | O6: 0 | P6: 0 | Q6: 0 | R6: 0 | S6: 0 | T6: 0 | U6: 0 | V6: 0 | W6: 0 | Y6: 0 | Z6: 0 | AA6: =N6-SUM(O6:Z6) -> 0.47 | AC6: =IFERROR(VLOOKUP(H6,'[1]Pending Recoveries'!$A:$D,4,0),0) -> 0 | AD6: =AA6-AC6 -> 0.47 | AE6: =AC6-M6 -> 0
A7: 1004 | B7: Tofir | C7: Pending | D7: 2145.71 | H7: 1004 | I7: Tofir | J7: Pending | K7: 0 | L7: 1707.81 | M7: 0 | N7: =K7+M7+L7 -> 1707.81 | O7: 0 | P7: 0 | Q7: 0 | R7: 0 | S7: 0 | T7: 0 | U7: 0 | V7: 0 | W7: 0 | Y7: 0 | Z7: 0 | AA7: =N7-SUM(O7:Z7) -> 1707.81 | AC7: =IFERROR(VLOOKUP(H7,'[1]Pending Recoveries'!$A:$D,4,0),0) -> 0 | AD7: =AA7-AC7 -> 1707.81 | AE7: =AC7-M7 -> 0
A8: 1006 | B8: Sonvarsha | C8: Pending | D8: 25566.8 | H8: 1006 | I8: Sonvarsha | J8: Pending | K8: 8310 | L8: 0.32 | M8: 0 | N8: =K8+M8+L8 -> 8310.32 | O8: 0 | P8: 0 | Q8: 0 | R8: 0 | S8: 0 | T8: 0 | U8: 0 | V8: 0 | W8: 0 | Y8: 0 | Z8: 0 | AA8: =N8-SUM(O8:Z8) -> 8310.32 | AC8: =IFERROR(VLOOKUP(H8,'[1]Pending Recoveries'!$A:$D,4,0),0) -> 0 | AD8: =AA8-AC8 -> 8310.32 | AE8: =AC8-M8 -> 0
A9: 1007 | B9: Araria | C9: Pending | D9: 31005.2 | H9: 1007 | I9: Araria | J9: Pending | K9: 0 | L9: 0.3 | M9: 19175.416 | N9: =K9+M9+L9 -> 19175.716 | O9: 0 | P9: 0 | Q9: 0 | R9: 0 | S9: 0 | T9: 0 | U9: 0 | V9: 0 | W9: 0 | Y9: 0 | Z9: 0 | AA9: =N9-SUM(O9:Z9) -> 19175.716 | AC9: =IFERROR(VLOOKUP(H9,'[1]Pending Recoveries'!$A:$D,4,0),0) -> 19175.416 | AD9: =AA9-AC9 -> 0.3 | AE9: =AC9-M9 -> 0
A10: 1008 | B10: Teghra | C10: Pending | D10: 11247.46 | H10: 1008 | I10: Teghra | J10: Pending | K10: 0 | L10: -0.14 | M10: 8349.34 | N10: =K10+M10+L10 -> 8349.2 | O10: 0 | P10: 0 | Q10: 0 | R10: 0 | S10: 0 | T10: 0 | U10: 0 | V10: 0 | W10: 0 | Y10: 0 | Z10: 0 | AA10: =N10-SUM(O10:Z10) -> 8349.2 | AC10: =IFERROR(VLOOKUP(H10,'[1]Pending Recoveries'!$A:$D,4,0),0) -> 8349.34 | AD10: =AA10-AC10 -> -0.14 | AE10: =AC10-M10 -> 0
A11: 1009 | B11: Halsi | C11: Pending | D11: 24532.44 | H11: 1009 | I11: Halsi | J11: Pending | K11: 0 | L11: 0.27 | M11: 8712.5 | N11: =K11+M11+L11 -> 8712.77 | O11: 0 | P11: 0 | Q11: 0 | R11: 0 | S11: 0 | T11: 0 | U11: 0 | V11: 0 | W11: 0 | Y11: 0 | Z11: 0 | AA11: =N11-SUM(O11:Z11) -> 8712.77 | AC11: =IFERROR(VLOOKUP(H11,'[1]Pending Recoveries'!$A:$D,4,0),0) -> 8712.5 | AD11: =AA11-AC11 -> 0.27 | AE11: =AC11-M11 -> 0
A12: 10010013 | B12: Gomukh Kumbhi | C12: Pending | D12: 155.09 | H12: 10010013 | I12: Gomukh Kumbhi | J12: Pending | K12: 0 | L12: 0.09 | M12: 0 | N12: =K12+M12+L12 -> 0.09 | O12: 0 | P12: 0 | Q12: 0 | R12: 0 | S12: 0 | T12: 0 | U12: 0 | V12: 0 | W12: 0 | Y12: 0 | Z12: 0 | AA12: =N12-SUM(O12:Z12) -> 0.09 | AC12: =IFERROR(VLOOKUP(H12,'[1]Pending Recoveries'!$A:$D,4,0),0) -> 0 | AD12: =AA12-AC12 -> 0.09 | AE12: =AC12-M12 -> 0
A13: 10010019 | B13: Gomukh Jagdar | C13: Pending | D13: 880.71 | H13: 10010019 | I13: Gomukh Jagdar | J13: Pending | K13: 0 | L13: 0 | M13: 0 | N13: =K13+M13+L13 -> 0 | O13: 0 | P13: 0 | Q13: 0 | R13: 0 | S13: 0 | T13: 0 | U13: 0 | V13: 0 | W13: 0 | Y13: 0 | Z13: 0 | AA13: =N13-SUM(O13:Z13) -> 0 | AC13: =IFERROR(VLOOKUP(H13,'[1]Pending Recoveries'!$A:$D,4,0),0) -> 0 | AD13: =AA13-AC13 -> 0 | AE13: =AC13-M13 -> 0
A14: 10010021 | B14: Gomukh Moradpur | C14: Pending | D14: 52.49 | H14: 10010021 | I14: Gomukh Moradpur | J14: Pending | K14: 469 | L14: 521.49 | M14: 0 | N14: =K14+M14+L14 -> 990.49 | O14: 0 | P14: 0 | Q14: 0 | R14: 0 | S14: 0 | T14: 0 | U14: 0 | V14: 0 | W14: 0 | Y14: 0 | Z14: 0 | AA14: =N14-SUM(O14:Z14) -> 990.49 | AC14: =IFERROR(VLOOKUP(H14,'[1]Pending Recoveries'!$A:$D,4,0),0) -> 0 | AD14: =AA14-AC14 -> 990.49 | AE14: =AC14-M14 -> 0
A15: 10010027 | B15: Gomukh Paroriya | C15: Pending | D15: 52.49 | H15: 10010027 | I15: Gomukh Paroriya | J15: Pending | K15: 0 | L15: 52.49 | M15: 0 | N15: =K15+M15+L15 -> 52.49 | O15: 0 | P15: 0 | Q15: 0 | R15: 0 | S15: 0 | T15: 0 | U15: 0 | V15: 0 | W15: 0 | Y15: 0 | Z15: 0 | AA15: =N15-SUM(O15:Z15) -> 52.49 | AC15: =IFERROR(VLOOKUP(H15,'[1]Pending Recoveries'!$A:$D,4,0),0) -> 0 | AD15: =AA15-AC15 -> 52.49 | AE15: =AC15-M15 -> 0
... A246: 10560001 | B246: Gomukh Chautham(Mithun kumar VLC) | C246: Pending | D246: 1209.52 | H246: 10560001 | I246: Gomukh Chautham(Mithun kumar VLC) | J246: Pending | K246: 0 | L246: 0 | M246: 6745.1455 | N246: =K246+M246+L246 -> 6745.1455 | O246: 3634.92 | P246: 2920.5 | Q246: 0 | R246: 0 | S246: 0 | T246: 0 | U246: 0 | V246: 0 | W246: 0 | Y246: 0 | Z246: 0 | AA246: =N246-SUM(O246:Z246) -> 189.72549 | AC246: =IFERROR(VLOOKUP(H246,'[1]Pending Recoveries'!$A:$D,4,0),0) -> 6745.1455 | AD246: =AA246-AC246 -> -6555.42 | AE246: =AC246-M246 -> 0
A247: Grand Total | D247: 247545.79 | H247: 10110076 | I247: GOMUKH SRINAGAR | J247: Pending | K247: 0 | L247: -257 | M247: 0 | N247: =K247+M247+L247 -> -257 | O247: 0 | P247: 0 | Q247: 0 | R247: 0 | S247: 0 | T247: 0 | U247: 0 | V247: 0 | W247: 0 | Y247: 0 | Z247: 0 | AA247: =N247-SUM(O247:Z247) -> -257 | AC247: =IFERROR(VLOOKUP(H247,'[1]Pending Recoveries'!$A:$D,4,0),0) -> 0 | AD247: =AA247-AC247 -> -257 | AE247: =AC247-M247 -> 0
H248: 10010005 | J248: Pending | K248: 330 | L248: 330 | M248: 0 | N248: =K248+M248+L248 -> 660 | O248: 0 | P248: 0 | Q248: 0 | R248: 0 | S248: 0 | T248: 0 | U248: 0 | V248: 0 | W248: 0 | Y248: 0 | Z248: 0 | AA248: =N248-SUM(O248:Z248) -> 660 | AC248: =IFERROR(VLOOKUP(H248,'[1]Pending Recoveries'!$A:$D,4,0),0) -> 0 | AD248: =AA248-AC248 -> 660 | AE248: =AC248-M248 -> 0
H249: 10010006 | J249: Pending | K249: 0 | L249: 0 | M249: 0 | N249: =K249+M249+L249 -> 0 | O249: 0 | P249: 0 | Q249: 0 | R249: 0 | S249: 0 | T249: 0 | U249: 0 | V249: 0 | W249: 0 | Y249: 0 | Z249: 0 | AA249: =N249-SUM(O249:Z249) -> 0 | AC249: =IFERROR(VLOOKUP(H249,'[1]Pending Recoveries'!$A:$D,4,0),0) -> 0 | AD249: =AA249-AC249 -> 0 | AE249: =AC249-M249 -> 0
H250: 10010007 | J250: Pending | K250: 0 | L250: 0 | M250: 0 | N250: =K250+M250+L250 -> 0 | O250: 0 | P250: 0 | Q250: 0 | R250: 0 | S250: 0 | T250: 0 | U250: 0 | V250: 0 | W250: 0 | Y250: 0 | Z250: 0 | AA250: =N250-SUM(O250:Z250) -> 0 | AC250: =IFERROR(VLOOKUP(H250,'[1]Pending Recoveries'!$A:$D,4,0),0) -> 0 | AD250: =AA250-AC250 -> 0 | AE250: =AC250-M250 -> 0
H251: 10010008 | J251: Pending | K251: 96 | L251: 96 | M251: 0 | N251: =K251+M251+L251 -> 192 | O251: 0 | P251: 0 | Q251: 0 | R251: 0 | S251: 0 | T251: 0 | U251: 0 | V251: 0 | W251: 0 | Y251: 0 | Z251: 0 | AA251: =N251-SUM(O251:Z251) -> 192 | AC251: =IFERROR(VLOOKUP(H251,'[1]Pending Recoveries'!$A:$D,4,0),0) -> 0 | AD251: =AA251-AC251 -> 192 | AE251: =AC251-M251 -> 0
H252: 10010009 | J252: Pending | K252: 204 | L252: 204 | M252: 0 | N252: =K252+M252+L252 -> 408 | O252: 0 | P252: 0 | Q252: 0 | R252: 0 | S252: 0 | T252: 0 | U252: 0 | V252: 0 | W252: 0 | Y252: 0 | Z252: 0 | AA252: =N252-SUM(O252:Z252) -> 408 | AC252: =IFERROR(VLOOKUP(H252,'[1]Pending Recoveries'!$A:$D,4,0),0) -> 0 | AD252: =AA252-AC252 -> 408 | AE252: =AC252-M252 -> 0
H253: 10010012 | J253: Pending | K253: 0 | L253: 0 | M253: 0 | N253: =K253+M253+L253 -> 0 | O253: 0 | P253: 0 | Q253: 0 | R253: 0 | S253: 0 | T253: 0 | U253: 0 | V253: 0 | W253: 0 | Y253: 0 | Z253: 0 | AA253: =N253-SUM(O253:Z253) -> 0 | AC253: =IFERROR(VLOOKUP(H253,'[1]Pending Recoveries'!$A:$D,4,0),0) -> 0 | AD253: =AA253-AC253 -> 0 | AE253: =AC253-M253 -> 0
H254: 10010014 | J254: Pending | K254: 204 | L254: 204 | M254: 0 | N254: =K254+M254+L254 -> 408 | O254: 0 | P254: 0 | Q254: 0 | R254: 0 | S254: 0 | T254: 0 | U254: 0 | V254: 0 | W254: 0 | Y254: 0 | Z254: 0 | AA254: =N254-SUM(O254:Z254) -> 408 | AC254: =IFERROR(VLOOKUP(H254,'[1]Pending Recoveries'!$A:$D,4,0),0) -> 0 | AD254: =AA254-AC254 -> 408 | AE254: =AC254-M254 -> 0
H255: 10010015 | J255: Pending | K255: 204 | L255: 204 | M255: 0 | N255: =K255+M255+L255 -> 408 | O255: 0 | P255: 0 | Q255: 0 | R255: 0 | S255: 0 | T255: 0 | U255: 0 | V255: 0 | W255: 0 | Y255: 0 | Z255: 0 | AA255: =N255-SUM(O255:Z255) -> 408 | AC255: =IFERROR(VLOOKUP(H255,'[1]Pending Recoveries'!$A:$D,4,0),0) -> 0 | AD255: =AA255-AC255 -> 408 | AE255: =AC255-M255 -> 0
H256: 10010016 | J256: Pending | K256: 125 | L256: 125 | M256: 0 | N256: =K256+M256+L256 -> 250 | O256: 0 | P256: 0 | Q256: 0 | R256: 0 | S256: 0 | T256: 0 | U256: 0 | V256: 0 | W256: 0 | Y256: 0 | Z256: 0 | AA256: =N256-SUM(O256:Z256) -> 250 | AC256: =IFERROR(VLOOKUP(H256,'[1]Pending Recoveries'!$A:$D,4,0),0) -> 0 | AD256: =AA256-AC256 -> 250 | AE256: =AC256-M256 -> 0
H257: 10010017 | J257: Pending | K257: 0 | L257: 0 | M257: 0 | N257: =K257+M257+L257 -> 0 | O257: 0 | P257: 0 | Q257: 0 | R257: 0 | S257: 0 | T257: 0 | U257: 0 | V257: 0 | W257: 0 | Y257: 0 | Z257: 0 | AA257: =N257-SUM(O257:Z257) -> 0 | AC257: =IFERROR(VLOOKUP(H257,'[1]Pending Recoveries'!$A:$D,4,0),0) -> 0 | AD257: =AA257-AC257 -> 0 | AE257: =AC257-M257 -> 0
H258: 10010018 | J258: Pending | K258: 204 | L258: 204 | M258: 0 | N258: =K258+M258+L258 -> 408 | O258: 0 | P258: 0 | Q258: 0 | R258: 0 | S258: 0 | T258: 0 | U258: 0 | V258: 0 | W258: 0 | Y258: 0 | Z258: 0 | AA258: =N258-SUM(O258:Z258) -> 408 | AC258: =IFERROR(VLOOKUP(H258,'[1]Pending Recoveries'!$A:$D,4,0),0) -> 0 | AD258: =AA258-AC258 -> 408 | AE258: =AC258-M258 -> 0
H259: 10010024 | J259: Pending | K259: 0 | L259: 0 | M259: 0 | N259: =K259+M259+L259 -> 0 | O259: 0 | P259: 0 | Q259: 0 | R259: 0 | S259: 0 | T259: 0 | U259: 0 | V259: 0 | W259: 0 | Y259: 0 | Z259: 0 | AA259: =N259-SUM(O259:Z259) -> 0 | AC259: =IFERROR(VLOOKUP(H259,'[1]Pending Recoveries'!$A:$D,4,0),0) -> 0 | AD259: =AA259-AC259 -> 0 | AE259: =AC259-M259 -> 0
... H727: 10110134 | J727: Pending | K727: 0 | L727: 209.16 | M727: 1154.54 | N727: =K727+M727+L727 -> 1363.7 | O727: 0 | P727: 0 | Q727: 0 | R727: 0 | S727: 0 | T727: 0 | U727: 0 | V727: 0 | W727: 0 | Y727: 0 | Z727: 0 | AA727: =N727-SUM(O727:Z727) -> 1363.7 | AC727: =IFERROR(VLOOKUP(H727,'[1]Pending Recoveries'!$A:$D,4,0),0) -> 1154.54 | AD727: =AA727-AC727 -> 209.16 | AE727: =AC727-M727 -> 0
H728: 10120091 | I728: GOMUKH MOHANPUR | J728: Pending | K728: 0 | L728: 0 | M728: 0 | N728: =K728+M728+L728 -> 0 | O728: 0 | P728: 0 | Q728: 0 | R728: 0 | S728: 0 | T728: 0 | U728: 0 | V728: 0 | W728: 0 | Y728: 0 | Z728: 0 | AA728: =N728-SUM(O728:Z728) -> 0 | AC728: =IFERROR(VLOOKUP(H728,'[1]Pending Recoveries'!$A:$D,4,0),0) -> 0 | AD728: =AA728-AC728 -> 0 | AE728: =AC728-M728 -> 0
H729: 10120104 | I729: Gomukh Mordiwa East | J729: Pending | K729: 0 | L729: 0 | M729: 0 | N729: =K729+M729+L729 -> 0 | O729: 0 | P729: 0 | Q729: 0 | R729: 0 | S729: 0 | T729: 0 | U729: 0 | V729: 0 | W729: 0 | Y729: 0 | Z729: 0 | AA729: =N729-SUM(O729:Z729) -> 0 | AC729: =IFERROR(VLOOKUP(H729,'[1]Pending Recoveries'!$A:$D,4,0),0) -> 0 | AD729: =AA729-AC729 -> 0 | AE729: =AC729-M729 -> 0
H730: 10120108 | I730: GOMUKH MANIKA EAST | J730: Pending | K730: 0 | L730: 0 | M730: 0 | N730: =K730+M730+L730 -> 0 | O730: 0 | P730: 0 | Q730: 0 | R730: 0 | S730: 0 | T730: 0 | U730: 0 | V730: 0 | W730: 0 | Y730: 0 | Z730: 0 | AA730: =N730-SUM(O730:Z730) -> 0 | AC730: =IFERROR(VLOOKUP(H730,'[1]Pending Recoveries'!$A:$D,4,0),0) -> 0 | AD730: =AA730-AC730 -> 0 | AE730: =AC730-M730 -> 0
H731: 10120111 | I731: GOMUKH Kisanpur Tabhka | J731: Pending | K731: 0 | L731: 0 | M731: 0 | N731: =K731+M731+L731 -> 0 | O731: 0 | P731: 0 | Q731: 0 | R731: 0 | S731: 0 | T731: 0 | U731: 0 | V731: 0 | W731: 0 | Y731: 0 | Z731: 0 | AA731: =N731-SUM(O731:Z731) -> 0 | AC731: =IFERROR(VLOOKUP(H731,'[1]Pending Recoveries'!$A:$D,4,0),0) -> 0 | AD731: =AA731-AC731 -> 0 | AE731: =AC731-M731 -> 0
H732: 10120114 | I732: GOMUKH PATHAKTOL | J732: Pending | K732: 0 | L732: 458.32 | M732: 0 | N732: =K732+M732+L732 -> 458.32 | O732: 0 | P732: 0 | Q732: 0 | R732: 0 | S732: 0 | T732: 0 | U732: 0 | V732: 0 | W732: 0 | Y732: 0 | Z732: 0 | AA732: =N732-SUM(O732:Z732) -> 458.32 | AC732: =IFERROR(VLOOKUP(H732,'[1]Pending Recoveries'!$A:$D,4,0),0) -> 0 | AD732: =AA732-AC732 -> 458.32 | AE732: =AC732-M732 -> 0
H733: 10130044 | I733: Lakshmipur Western Tol - Rajeev | J733: Pending | K733: 0 | L733: 0 | M733: 0 | N733: =K733+M733+L733 -> 0 | O733: 0 | P733: 0 | Q733: 0 | R733: 0 | S733: 0 | T733: 0 | U733: 0 | V733: 0 | W733: 0 | Y733: 0 | Z733: 0 | AA733: =N733-SUM(O733:Z733) -> 0 | AC733: =IFERROR(VLOOKUP(H733,'[1]Pending Recoveries'!$A:$D,4,0),0) -> 0 | AD733: =AA733-AC733 -> 0 | AE733: =AC733-M733 -> 0
H734: 10130073 | I734: Dagarua | J734: Pending | K734: 0 | L734: 109.8 | M734: 0 | N734: =K734+M734+L734 -> 109.8 | O734: 0 | P734: 0 | Q734: 0 | R734: 0 | S734: 0 | T734: 0 | U734: 0 | V734: 0 | W734: 0 | Y734: 0 | Z734: 0 | AA734: =N734-SUM(O734:Z734) -> 109.8 | AC734: =IFERROR(VLOOKUP(H734,'[1]Pending Recoveries'!$A:$D,4,0),0) -> 0 | AD734: =AA734-AC734 -> 109.8 | AE734: =AC734-M734 -> 0
H735: 10130077 | I735: Gomukh Akaha | J735: Pending | K735: 0 | L735: 0 | M735: 0 | N735: =K735+M735+L735 -> 0 | O735: 0 | P735: 0 | Q735: 0 | R735: 0 | S735: 0 | T735: 0 | U735: 0 | V735: 0 | W735: 0 | Y735: 0 | Z735: 0 | AA735: =N735-SUM(O735:Z735) -> 0 | AC735: =IFERROR(VLOOKUP(H735,'[1]Pending Recoveries'!$A:$D,4,0),0) -> 0 | AD735: =AA735-AC735 -> 0 | AE735: =AC735-M735 -> 0
H736: 10130085 | I736: Gomukh Repura | J736: Pending | K736: 0 | L736: 15.52 | M736: 0 | N736: =K736+M736+L736 -> 15.52 | O736: 0 | P736: 0 | Q736: 0 | R736: 0 | S736: 0 | T736: 0 | U736: 0 | V736: 0 | W736: 0 | Y736: 0 | Z736: 0 | AA736: =N736-SUM(O736:Z736) -> 15.52 | AC736: =IFERROR(VLOOKUP(H736,'[1]Pending Recoveries'!$A:$D,4,0),0) -> 0 | AD736: =AA736-AC736 -> 15.52 | AE736: =AC736-M736 -> 0
H737: 10130091 | I737: Gomukh Nipur | J737: Pending | K737: 0 | L737: 0 | M737: 0 | N737: =K737+M737+L737 -> 0 | O737: 0 | P737: 0 | Q737: 0 | R737: 0 | S737: 0 | T737: 0 | U737: 0 | V737: 0 | W737: 0 | Y737: 0 | Z737: 0 | AA737: =N737-SUM(O737:Z737) -> 0 | AC737: =IFERROR(VLOOKUP(H737,'[1]Pending Recoveries'!$A:$D,4,0),0) -> 0 | AD737: =AA737-AC737 -> 0 | AE737: =AC737-M737 -> 0
...

Sheet Issue
A1: Date | B1: Type | C1: Challan No | D1: From Location Code | E1: Location | F1: Type of Location | G1: To BMC/MPG Code | H1: BMC MPG Name | I1: Type of Location2 | J1: Item Name | K1: UoM | L1: Qty Issued | M1: Rate | N1: Amt | O1: Recoverable | P1: Recovery Done | Q1: Remarks
A2: 45748 | B2: Transfer | C2: 120 | D2: 1 | E2: =IFERROR(VLOOKUP(Table4[[#This Row],[From Location Code]],Table5[#All],3,0),"") -> Munger | F2: =IFERROR(VLOOKUP(Table4[[#This Row],[From Location Code]],Table5[#All],2,0),"") -> Main Godown | G2: 1014 | H2: =IFERROR(VLOOKUP(Table4[[#This Row],[To BMC/MPG Code]],Table5[#All],3,0),"") -> Dumraon | I2: =IFERROR(VLOOKUP(Table4[[#This Row],[To BMC/MPG Code]],Table5[#All],2,0),"") -> BMC | J2: Sample Bottle 100 ML | K2: =IFERROR(VLOOKUP(Table4[[#This Row],[Item Name]],Table2[[Item Name]:[UoM]],2,0),"") -> Nos | L2: 68 | M2: =IFERROR(VLOOKUP(Table4[[#This Row],[Item Name]],Table2[[#All],[Item Name]:[Open Rate]],8,0),"") -> 2.83 | N2: =IFERROR(+Table4[[#This Row],[Qty Issued]]*Table4[[#This Row],[Rate]],"") -> 192.44 | O2: No | P2: NA
A3: 45748 | B3: Transfer | C3: 120 | D3: 1 | E3: =IFERROR(VLOOKUP(Table4[[#This Row],[From Location Code]],Table5[#All],3,0),"") -> Munger | F3: =IFERROR(VLOOKUP(Table4[[#This Row],[From Location Code]],Table5[#All],2,0),"") -> Main Godown | G3: 1014 | H3: =IFERROR(VLOOKUP(Table4[[#This Row],[To BMC/MPG Code]],Table5[#All],3,0),"") -> Dumraon | I3: =IFERROR(VLOOKUP(Table4[[#This Row],[To BMC/MPG Code]],Table5[#All],2,0),"") -> BMC | J3: MPG Register | K3: =IFERROR(VLOOKUP(Table4[[#This Row],[Item Name]],Table2[[Item Name]:[UoM]],2,0),"") -> Nos | L3: 51 | M3: =IFERROR(VLOOKUP(Table4[[#This Row],[Item Name]],Table2[[#All],[Item Name]:[Open Rate]],8,0),"") -> 129.8 | N3: =IFERROR(+Table4[[#This Row],[Qty Issued]]*Table4[[#This Row],[Rate]],"") -> 6619.8 | O3: No | P3: NA
A4: 45748 | B4: Transfer | C4: 120 | D4: 1 | E4: =IFERROR(VLOOKUP(Table4[[#This Row],[From Location Code]],Table5[#All],3,0),"") -> Munger | F4: =IFERROR(VLOOKUP(Table4[[#This Row],[From Location Code]],Table5[#All],2,0),"") -> Main Godown | G4: 1014 | H4: =IFERROR(VLOOKUP(Table4[[#This Row],[To BMC/MPG Code]],Table5[#All],3,0),"") -> Dumraon | I4: =IFERROR(VLOOKUP(Table4[[#This Row],[To BMC/MPG Code]],Table5[#All],2,0),"") -> BMC | J4: Milk Cane Plunger S. S. | K4: =IFERROR(VLOOKUP(Table4[[#This Row],[Item Name]],Table2[[Item Name]:[UoM]],2,0),"") -> Nos | L4: 13 | M4: =IFERROR(VLOOKUP(Table4[[#This Row],[Item Name]],Table2[[#All],[Item Name]:[Open Rate]],8,0),"") -> 112.1 | N4: =IFERROR(+Table4[[#This Row],[Qty Issued]]*Table4[[#This Row],[Rate]],"") -> 1457.3 | O4: No | P4: NA
A5: 45748 | B5: Transfer | C5: 120 | D5: 1 | E5: =IFERROR(VLOOKUP(Table4[[#This Row],[From Location Code]],Table5[#All],3,0),"") -> Munger | F5: =IFERROR(VLOOKUP(Table4[[#This Row],[From Location Code]],Table5[#All],2,0),"") -> Main Godown | G5: 1014 | H5: =IFERROR(VLOOKUP(Table4[[#This Row],[To BMC/MPG Code]],Table5[#All],3,0),"") -> Dumraon | I5: =IFERROR(VLOOKUP(Table4[[#This Row],[To BMC/MPG Code]],Table5[#All],2,0),"") -> BMC | J5: Plastic Strainer | K5: =IFERROR(VLOOKUP(Table4[[#This Row],[Item Name]],Table2[[Item Name]:[UoM]],2,0),"") -> Nos | L5: 14 | M5: =IFERROR(VLOOKUP(Table4[[#This Row],[Item Name]],Table2[[#All],[Item Name]:[Open Rate]],8,0),"") -> 29.5 | N5: =IFERROR(+Table4[[#This Row],[Qty Issued]]*Table4[[#This Row],[Rate]],"") -> 413 | O5: No | P5: NA
A6: 45748 | B6: Transfer | C6: 120 | D6: 1 | E6: =IFERROR(VLOOKUP(Table4[[#This Row],[From Location Code]],Table5[#All],3,0),"") -> Munger | F6: =IFERROR(VLOOKUP(Table4[[#This Row],[From Location Code]],Table5[#All],2,0),"") -> Main Godown | G6: 1014 | H6: =IFERROR(VLOOKUP(Table4[[#This Row],[To BMC/MPG Code]],Table5[#All],3,0),"") -> Dumraon | I6: =IFERROR(VLOOKUP(Table4[[#This Row],[To BMC/MPG Code]],Table5[#All],2,0),"") -> BMC | J6: Eko Day Cleaning Sol | K6: =IFERROR(VLOOKUP(Table4[[#This Row],[Item Name]],Table2[[Item Name]:[UoM]],2,0),"") -> Nos | L6: 61 | M6: =IFERROR(VLOOKUP(Table4[[#This Row],[Item Name]],Table2[[#All],[Item Name]:[Open Rate]],8,0),"") -> 348.52 | N6: =IFERROR(+Table4[[#This Row],[Qty Issued]]*Table4[[#This Row],[Rate]],"") -> 21259.72 | O6: No | P6: NA
A7: 45748 | B7: Transfer | C7: 156 | D7: 1 | E7: =IFERROR(VLOOKUP(Table4[[#This Row],[From Location Code]],Table5[#All],3,0),"") -> Munger | F7: =IFERROR(VLOOKUP(Table4[[#This Row],[From Location Code]],Table5[#All],2,0),"") -> Main Godown | G7: 1014 | H7: =IFERROR(VLOOKUP(Table4[[#This Row],[To BMC/MPG Code]],Table5[#All],3,0),"") -> Dumraon | I7: =IFERROR(VLOOKUP(Table4[[#This Row],[To BMC/MPG Code]],Table5[#All],2,0),"") -> BMC | J7: FAT Scan Weekly | K7: =IFERROR(VLOOKUP(Table4[[#This Row],[Item Name]],Table2[[Item Name]:[UoM]],2,0),"") -> Nos | L7: 39 | M7: =IFERROR(VLOOKUP(Table4[[#This Row],[Item Name]],Table2[[#All],[Item Name]:[Open Rate]],8,0),"") -> 348.52 | N7: =IFERROR(+Table4[[#This Row],[Qty Issued]]*Table4[[#This Row],[Rate]],"") -> 13592.28 | O7: No | P7: NA
A8: 45748 | B8: Transfer | C8: 156 | D8: 1 | E8: =IFERROR(VLOOKUP(Table4[[#This Row],[From Location Code]],Table5[#All],3,0),"") -> Munger | F8: =IFERROR(VLOOKUP(Table4[[#This Row],[From Location Code]],Table5[#All],2,0),"") -> Main Godown | G8: 1014 | H8: =IFERROR(VLOOKUP(Table4[[#This Row],[To BMC/MPG Code]],Table5[#All],3,0),"") -> Dumraon | I8: =IFERROR(VLOOKUP(Table4[[#This Row],[To BMC/MPG Code]],Table5[#All],2,0),"") -> BMC | J8: Eco Power Solution | K8: =IFERROR(VLOOKUP(Table4[[#This Row],[Item Name]],Table2[[Item Name]:[UoM]],2,0),"") -> Nos | L8: 3 | M8: =IFERROR(VLOOKUP(Table4[[#This Row],[Item Name]],Table2[[#All],[Item Name]:[Open Rate]],8,0),"") -> 348.52 | N8: =IFERROR(+Table4[[#This Row],[Qty Issued]]*Table4[[#This Row],[Rate]],"") -> 1045.56 | O8: No | P8: NA
A9: 45748 | B9: Transfer | C9: 156 | D9: 1 | E9: =IFERROR(VLOOKUP(Table4[[#This Row],[From Location Code]],Table5[#All],3,0),"") -> Munger | F9: =IFERROR(VLOOKUP(Table4[[#This Row],[From Location Code]],Table5[#All],2,0),"") -> Main Godown | G9: 1014 | H9: =IFERROR(VLOOKUP(Table4[[#This Row],[To BMC/MPG Code]],Table5[#All],3,0),"") -> Dumraon | I9: =IFERROR(VLOOKUP(Table4[[#This Row],[To BMC/MPG Code]],Table5[#All],2,0),"") -> BMC | J9: EKO Plunger | K9: =IFERROR(VLOOKUP(Table4[[#This Row],[Item Name]],Table2[[Item Name]:[UoM]],2,0),"") -> Nos | L9: 6 | M9: =IFERROR(VLOOKUP(Table4[[#This Row],[Item Name]],Table2[[#All],[Item Name]:[Open Rate]],8,0),"") -> 56.02 | N9: =IFERROR(+Table4[[#This Row],[Qty Issued]]*Table4[[#This Row],[Rate]],"") -> 336.12 | O9: No | P9: NA
A10: 45748 | B10: Consumed | C10: 169 | D10: 1 | E10: =IFERROR(VLOOKUP(Table4[[#This Row],[From Location Code]],Table5[#All],3,0),"") -> Munger | F10: =IFERROR(VLOOKUP(Table4[[#This Row],[From Location Code]],Table5[#All],2,0),"") -> Main Godown | G10: 10090042 | H10: =IFERROR(VLOOKUP(Table4[[#This Row],[To BMC/MPG Code]],Table5[#All],3,0),"") -> REWAI | I10: =IFERROR(VLOOKUP(Table4[[#This Row],[To BMC/MPG Code]],Table5[#All],2,0),"") -> MPG | J10: Eko Day Cleaning Sol | K10: =IFERROR(VLOOKUP(Table4[[#This Row],[Item Name]],Table2[[Item Name]:[UoM]],2,0),"") -> Nos | L10: 2 | M10: =IFERROR(VLOOKUP(Table4[[#This Row],[Item Name]],Table2[[#All],[Item Name]:[Open Rate]],8,0),"") -> 348.52 | N10: =IFERROR(+Table4[[#This Row],[Qty Issued]]*Table4[[#This Row],[Rate]],"") -> 697.04 | O10: Yes | P10: Pending
A11: 45748 | B11: Consumed | C11: 169 | D11: 1 | E11: =IFERROR(VLOOKUP(Table4[[#This Row],[From Location Code]],Table5[#All],3,0),"") -> Munger | F11: =IFERROR(VLOOKUP(Table4[[#This Row],[From Location Code]],Table5[#All],2,0),"") -> Main Godown | G11: 10090056 | H11: =IFERROR(VLOOKUP(Table4[[#This Row],[To BMC/MPG Code]],Table5[#All],3,0),"") -> NARAYANPUR | I11: =IFERROR(VLOOKUP(Table4[[#This Row],[To BMC/MPG Code]],Table5[#All],2,0),"") -> MPG | J11: Eko Day Cleaning Sol | K11: =IFERROR(VLOOKUP(Table4[[#This Row],[Item Name]],Table2[[Item Name]:[UoM]],2,0),"") -> Nos | L11: 1 | M11: =IFERROR(VLOOKUP(Table4[[#This Row],[Item Name]],Table2[[#All],[Item Name]:[Open Rate]],8,0),"") -> 348.52 | N11: =IFERROR(+Table4[[#This Row],[Qty Issued]]*Table4[[#This Row],[Rate]],"") -> 348.52 | O11: Yes | P11: Pending
A12: 45748 | B12: Consumed | C12: 169 | D12: 1 | E12: =IFERROR(VLOOKUP(Table4[[#This Row],[From Location Code]],Table5[#All],3,0),"") -> Munger | F12: =IFERROR(VLOOKUP(Table4[[#This Row],[From Location Code]],Table5[#All],2,0),"") -> Main Godown | G12: 10090029 | H12: =IFERROR(VLOOKUP(Table4[[#This Row],[To BMC/MPG Code]],Table5[#All],3,0),"") -> RAMNAGAR | I12: =IFERROR(VLOOKUP(Table4[[#This Row],[To BMC/MPG Code]],Table5[#All],2,0),"") -> MPG | J12: Eko Day Cleaning Sol | K12: =IFERROR(VLOOKUP(Table4[[#This Row],[Item Name]],Table2[[Item Name]:[UoM]],2,0),"") -> Nos | L12: 1 | M12: =IFERROR(VLOOKUP(Table4[[#This Row],[Item Name]],Table2[[#All],[Item Name]:[Open Rate]],8,0),"") -> 348.52 | N12: =IFERROR(+Table4[[#This Row],[Qty Issued]]*Table4[[#This Row],[Rate]],"") -> 348.52 | O12: Yes | P12: Pending
A13: 45748 | B13: Consumed | C13: 169 | D13: 1 | E13: =IFERROR(VLOOKUP(Table4[[#This Row],[From Location Code]],Table5[#All],3,0),"") -> Munger | F13: =IFERROR(VLOOKUP(Table4[[#This Row],[From Location Code]],Table5[#All],2,0),"") -> Main Godown | G13: 10090009 | H13: =IFERROR(VLOOKUP(Table4[[#This Row],[To BMC/MPG Code]],Table5[#All],3,0),"") -> SONDHI | I13: =IFERROR(VLOOKUP(Table4[[#This Row],[To BMC/MPG Code]],Table5[#All],2,0),"") -> MPG | J13: Eko Day Cleaning Sol | K13: =IFERROR(VLOOKUP(Table4[[#This Row],[Item Name]],Table2[[Item Name]:[UoM]],2,0),"") -> Nos | L13: 1 | M13: =IFERROR(VLOOKUP(Table4[[#This Row],[Item Name]],Table2[[#All],[Item Name]:[Open Rate]],8,0),"") -> 348.52 | N13: =IFERROR(+Table4[[#This Row],[Qty Issued]]*Table4[[#This Row],[Rate]],"") -> 348.52 | O13: Yes | P13: Pending
... A108: 45749 | B108: Transfer | C108: 170 | D108: 1 | E108: =IFERROR(VLOOKUP(Table4[[#This Row],[From Location Code]],Table5[#All],3,0),"") -> Munger | F108: =IFERROR(VLOOKUP(Table4[[#This Row],[From Location Code]],Table5[#All],2,0),"") -> Main Godown | G108: 1014 | H108: =IFERROR(VLOOKUP(Table4[[#This Row],[To BMC/MPG Code]],Table5[#All],3,0),"") -> Dumraon | I108: =IFERROR(VLOOKUP(Table4[[#This Row],[To BMC/MPG Code]],Table5[#All],2,0),"") -> BMC | J108: MPG Register | K108: =IFERROR(VLOOKUP(Table4[[#This Row],[Item Name]],Table2[[Item Name]:[UoM]],2,0),"") -> Nos | L108: 50 | M108: =IFERROR(VLOOKUP(Table4[[#This Row],[Item Name]],Table2[[#All],[Item Name]:[Open Rate]],8,0),"") -> 129.8 | N108: =IFERROR(+Table4[[#This Row],[Qty Issued]]*Table4[[#This Row],[Rate]],"") -> 6490 | O108: No | P108: NA
A109: 45750 | B109: Consumed | C109: 171 | D109: 1 | E109: =IFERROR(VLOOKUP(Table4[[#This Row],[From Location Code]],Table5[#All],3,0),"") -> Munger | F109: =IFERROR(VLOOKUP(Table4[[#This Row],[From Location Code]],Table5[#All],2,0),"") -> Main Godown | G109: Lab | H109: =IFERROR(VLOOKUP(Table4[[#This Row],[To BMC/MPG Code]],Table5[#All],3,0),"") -> Daya_Lab | I109: =IFERROR(VLOOKUP(Table4[[#This Row],[To BMC/MPG Code]],Table5[#All],2,0),"") -> Lab | J109: Milk Despatch Challan | K109: =IFERROR(VLOOKUP(Table4[[#This Row],[Item Name]],Table2[[Item Name]:[UoM]],2,0),"") -> Nos | L109: 1 | M109: =IFERROR(VLOOKUP(Table4[[#This Row],[Item Name]],Table2[[#All],[Item Name]:[Open Rate]],8,0),"") -> 94.4 | N109: =IFERROR(+Table4[[#This Row],[Qty Issued]]*Table4[[#This Row],[Rate]],"") -> 94.4 | O109: No | P109: NA
A110: 45751 | B110: Consumed | C110: 172 | D110: 1 | E110: =IFERROR(VLOOKUP(Table4[[#This Row],[From Location Code]],Table5[#All],3,0),"") -> Munger | F110: =IFERROR(VLOOKUP(Table4[[#This Row],[From Location Code]],Table5[#All],2,0),"") -> Main Godown | G110: 1001 | H110: =IFERROR(VLOOKUP(Table4[[#This Row],[To BMC/MPG Code]],Table5[#All],3,0),"") -> Majhaul | I110: =IFERROR(VLOOKUP(Table4[[#This Row],[To BMC/MPG Code]],Table5[#All],2,0),"") -> BMC | J110: Buterometer | K110: =IFERROR(VLOOKUP(Table4[[#This Row],[Item Name]],Table2[[Item Name]:[UoM]],2,0),"") -> Nos | L110: 2 | M110: =IFERROR(VLOOKUP(Table4[[#This Row],[Item Name]],Table2[[#All],[Item Name]:[Open Rate]],8,0),"") -> 132.7 | N110: =IFERROR(+Table4[[#This Row],[Qty Issued]]*Table4[[#This Row],[Rate]],"") -> 265.4 | O110: No | P110: NA
A111: 45751 | B111: Consumed | C111: 172 | D111: 1 | E111: =IFERROR(VLOOKUP(Table4[[#This Row],[From Location Code]],Table5[#All],3,0),"") -> Munger | F111: =IFERROR(VLOOKUP(Table4[[#This Row],[From Location Code]],Table5[#All],2,0),"") -> Main Godown | G111: 1001 | H111: =IFERROR(VLOOKUP(Table4[[#This Row],[To BMC/MPG Code]],Table5[#All],3,0),"") -> Majhaul | I111: =IFERROR(VLOOKUP(Table4[[#This Row],[To BMC/MPG Code]],Table5[#All],2,0),"") -> BMC | J111: Lactometer 0-40 | K111: =IFERROR(VLOOKUP(Table4[[#This Row],[Item Name]],Table2[[Item Name]:[UoM]],2,0),"") -> Nos | L111: 2 | M111: =IFERROR(VLOOKUP(Table4[[#This Row],[Item Name]],Table2[[#All],[Item Name]:[Open Rate]],8,0),"") -> 132.7 | N111: =IFERROR(+Table4[[#This Row],[Qty Issued]]*Table4[[#This Row],[Rate]],"") -> 265.4 | O111: No | P111: NA
A112: 45751 | B112: Consumed | C112: 172 | D112: 1 | E112: =IFERROR(VLOOKUP(Table4[[#This Row],[From Location Code]],Table5[#All],3,0),"") -> Munger | F112: =IFERROR(VLOOKUP(Table4[[#This Row],[From Location Code]],Table5[#All],2,0),"") -> Main Godown | G112: 1001 | H112: =IFERROR(VLOOKUP(Table4[[#This Row],[To BMC/MPG Code]],Table5[#All],3,0),"") -> Majhaul | I112: =IFERROR(VLOOKUP(Table4[[#This Row],[To BMC/MPG Code]],Table5[#All],2,0),"") -> BMC | J112: Milk Pipete 10.75 ML | K112: =IFERROR(VLOOKUP(Table4[[#This Row],[Item Name]],Table2[[Item Name]:[UoM]],2,0),"") -> Nos | L112: 2 | M112: =IFERROR(VLOOKUP(Table4[[#This Row],[Item Name]],Table2[[#All],[Item Name]:[Open Rate]],8,0),"") -> 132.7 | N112: =IFERROR(+Table4[[#This Row],[Qty Issued]]*Table4[[#This Row],[Rate]],"") -> 265.4 | O112: No | P112: NA
A113: 45751 | B113: Consumed | C113: 172 | D113: 1 | E113: =IFERROR(VLOOKUP(Table4[[#This Row],[From Location Code]],Table5[#All],3,0),"") -> Munger | F113: =IFERROR(VLOOKUP(Table4[[#This Row],[From Location Code]],Table5[#All],2,0),"") -> Main Godown | G113: 1001 | H113: =IFERROR(VLOOKUP(Table4[[#This Row],[To BMC/MPG Code]],Table5[#All],3,0),"") -> Majhaul | I113: =IFERROR(VLOOKUP(Table4[[#This Row],[To BMC/MPG Code]],Table5[#All],2,0),"") -> BMC | J113: Ethyl Alcohol 500 ML Pack | K113: =IFERROR(VLOOKUP(Table4[[#This Row],[Item Name]],Table2[[Item Name]:[UoM]],2,0),"") -> Nos | L113: 5 | M113: =IFERROR(VLOOKUP(Table4[[#This Row],[Item Name]],Table2[[#All],[Item Name]:[Open Rate]],8,0),"") -> 271.4 | N113: =IFERROR(+Table4[[#This Row],[Qty Issued]]*Table4[[#This Row],[Rate]],"") -> 1357 | O113: No | P113: NA
A114: 45751 | B114: Consumed | C114: 172 | D114: 1 | E114: =IFERROR(VLOOKUP(Table4[[#This Row],[From Location Code]],Table5[#All],3,0),"") -> Munger | F114: =IFERROR(VLOOKUP(Table4[[#This Row],[From Location Code]],Table5[#All],2,0),"") -> Main Godown | G114: 1001 | H114: =IFERROR(VLOOKUP(Table4[[#This Row],[To BMC/MPG Code]],Table5[#All],3,0),"") -> Majhaul | I114: =IFERROR(VLOOKUP(Table4[[#This Row],[To BMC/MPG Code]],Table5[#All],2,0),"") -> BMC | J114: Tanker Seal | K114: =IFERROR(VLOOKUP(Table4[[#This Row],[Item Name]],Table2[[Item Name]:[UoM]],2,0),"") -> Nos | L114: 200 | M114: =IFERROR(VLOOKUP(Table4[[#This Row],[Item Name]],Table2[[#All],[Item Name]:[Open Rate]],8,0),"") -> 12.71 | N114: =IFERROR(+Table4[[#This Row],[Qty Issued]]*Table4[[#This Row],[Rate]],"") -> 2542 | O114: No | P114: NA
A115: 45751 | B115: Consumed | C115: 172 | D115: 1 | E115: =IFERROR(VLOOKUP(Table4[[#This Row],[From Location Code]],Table5[#All],3,0),"") -> Munger | F115: =IFERROR(VLOOKUP(Table4[[#This Row],[From Location Code]],Table5[#All],2,0),"") -> Main Godown | G115: 1001 | H115: =IFERROR(VLOOKUP(Table4[[#This Row],[To BMC/MPG Code]],Table5[#All],3,0),"") -> Majhaul | I115: =IFERROR(VLOOKUP(Table4[[#This Row],[To BMC/MPG Code]],Table5[#All],2,0),"") -> BMC | J115: Sodium Hydroxide N/10 Solution | K115: =IFERROR(VLOOKUP(Table4[[#This Row],[Item Name]],Table2[[Item Name]:[UoM]],2,0),"") -> Nos | L115: 1 | M115: =IFERROR(VLOOKUP(Table4[[#This Row],[Item Name]],Table2[[#All],[Item Name]:[Open Rate]],8,0),"") -> 135.7 | N115: =IFERROR(+Table4[[#This Row],[Qty Issued]]*Table4[[#This Row],[Rate]],"") -> 135.7 | O115: No | P115: NA
A116: 45751 | B116: Consumed | C116: 172 | D116: 1 | E116: =IFERROR(VLOOKUP(Table4[[#This Row],[From Location Code]],Table5[#All],3,0),"") -> Munger | F116: =IFERROR(VLOOKUP(Table4[[#This Row],[From Location Code]],Table5[#All],2,0),"") -> Main Godown | G116: 1001 | H116: =IFERROR(VLOOKUP(Table4[[#This Row],[To BMC/MPG Code]],Table5[#All],3,0),"") -> Majhaul | I116: =IFERROR(VLOOKUP(Table4[[#This Row],[To BMC/MPG Code]],Table5[#All],2,0),"") -> BMC | J116: Phenolphthaleing Indicator | K116: =IFERROR(VLOOKUP(Table4[[#This Row],[Item Name]],Table2[[Item Name]:[UoM]],2,0),"") -> Nos | L116: 1 | M116: =IFERROR(VLOOKUP(Table4[[#This Row],[Item Name]],Table2[[#All],[Item Name]:[Open Rate]],8,0),"") -> 106.2 | N116: =IFERROR(+Table4[[#This Row],[Qty Issued]]*Table4[[#This Row],[Rate]],"") -> 106.2 | O116: No | P116: NA
A117: 45751 | B117: Consumed | C117: 172 | D117: 1 | E117: =IFERROR(VLOOKUP(Table4[[#This Row],[From Location Code]],Table5[#All],3,0),"") -> Munger | F117: =IFERROR(VLOOKUP(Table4[[#This Row],[From Location Code]],Table5[#All],2,0),"") -> Main Godown | G117: 1001 | H117: =IFERROR(VLOOKUP(Table4[[#This Row],[To BMC/MPG Code]],Table5[#All],3,0),"") -> Majhaul | I117: =IFERROR(VLOOKUP(Table4[[#This Row],[To BMC/MPG Code]],Table5[#All],2,0),"") -> BMC | J117: Amyl 500ml | K117: =IFERROR(VLOOKUP(Table4[[#This Row],[Item Name]],Table2[[Item Name]:[UoM]],2,0),"") -> Nos | L117: 2 | M117: =IFERROR(VLOOKUP(Table4[[#This Row],[Item Name]],Table2[[#All],[Item Name]:[Open Rate]],8,0),"") -> 365.8 | N117: =IFERROR(+Table4[[#This Row],[Qty Issued]]*Table4[[#This Row],[Rate]],"") -> 731.6 | O117: No | P117: NA
A118: 45751 | B118: Consumed | C118: 172 | D118: 1 | E118: =IFERROR(VLOOKUP(Table4[[#This Row],[From Location Code]],Table5[#All],3,0),"") -> Munger | F118: =IFERROR(VLOOKUP(Table4[[#This Row],[From Location Code]],Table5[#All],2,0),"") -> Main Godown | G118: 1001 | H118: =IFERROR(VLOOKUP(Table4[[#This Row],[To BMC/MPG Code]],Table5[#All],3,0),"") -> Majhaul | I118: =IFERROR(VLOOKUP(Table4[[#This Row],[To BMC/MPG Code]],Table5[#All],2,0),"") -> BMC | J118: Pipette Gradulated 10 ML | K118: =IFERROR(VLOOKUP(Table4[[#This Row],[Item Name]],Table2[[Item Name]:[UoM]],2,0),"") -> Nos | L118: 2 | M118: =IFERROR(VLOOKUP(Table4[[#This Row],[Item Name]],Table2[[#All],[Item Name]:[Open Rate]],8,0),"") -> 23.46 | N118: =IFERROR(+Table4[[#This Row],[Qty Issued]]*Table4[[#This Row],[Rate]],"") -> 46.92 | O118: No | P118: NA
A119: 45754 | B119: Consumed | C119: 174 | D119: 1 | E119: =IFERROR(VLOOKUP(Table4[[#This Row],[From Location Code]],Table5[#All],3,0),"") -> Munger | F119: =IFERROR(VLOOKUP(Table4[[#This Row],[From Location Code]],Table5[#All],2,0),"") -> Main Godown | G119: 1007 | H119: =IFERROR(VLOOKUP(Table4[[#This Row],[To BMC/MPG Code]],Table5[#All],3,0),"") -> Araria | I119: =IFERROR(VLOOKUP(Table4[[#This Row],[To BMC/MPG Code]],Table5[#All],2,0),"") -> BMC | J119: TEEPOL | K119: =IFERROR(VLOOKUP(Table4[[#This Row],[Item Name]],Table2[[Item Name]:[UoM]],2,0),"") -> Nos | L119: 50 | M119: =IFERROR(VLOOKUP(Table4[[#This Row],[Item Name]],Table2[[#All],[Item Name]:[Open Rate]],8,0),"") -> 51.92 | N119: =IFERROR(+Table4[[#This Row],[Qty Issued]]*Table4[[#This Row],[Rate]],"") -> 2596 | O119: Yes | P119: Pending
A120: 45754 | B120: Consumed | C120: 174 | D120: 1 | E120: =IFERROR(VLOOKUP(Table4[[#This Row],[From Location Code]],Table5[#All],3,0),"") -> Munger | F120: =IFERROR(VLOOKUP(Table4[[#This Row],[From Location Code]],Table5[#All],2,0),"") -> Main Godown | G120: 1007 | H120: =IFERROR(VLOOKUP(Table4[[#This Row],[To BMC/MPG Code]],Table5[#All],3,0),"") -> Araria | I120: =IFERROR(VLOOKUP(Table4[[#This Row],[To BMC/MPG Code]],Table5[#All],2,0),"") -> BMC | J120: Satol - 5 KG | K120: =IFERROR(VLOOKUP(Table4[[#This Row],[Item Name]],Table2[[Item Name]:[UoM]],2,0),"") -> Nos | L120: 10 | M120: =IFERROR(VLOOKUP(Table4[[#This Row],[Item Name]],Table2[[#All],[Item Name]:[Open Rate]],8,0),"") -> 135.7 | N120: =IFERROR(+Table4[[#This Row],[Qty Issued]]*Table4[[#This Row],[Rate]],"") -> 1357 | O120: Yes | P120: Pending
A121: 45754 | B121: Consumed | C121: 174 | D121: 1 | E121: =IFERROR(VLOOKUP(Table4[[#This Row],[From Location Code]],Table5[#All],3,0),"") -> Munger | F121: =IFERROR(VLOOKUP(Table4[[#This Row],[From Location Code]],Table5[#All],2,0),"") -> Main Godown | G121: 1007 | H121: =IFERROR(VLOOKUP(Table4[[#This Row],[To BMC/MPG Code]],Table5[#All],3,0),"") -> Araria | I121: =IFERROR(VLOOKUP(Table4[[#This Row],[To BMC/MPG Code]],Table5[#All],2,0),"") -> BMC | J121: Sulphuric Acid SQ 05 Lt | K121: =IFERROR(VLOOKUP(Table4[[#This Row],[Item Name]],Table2[[Item Name]:[UoM]],2,0),"") -> Nos | L121: 1 | M121: =IFERROR(VLOOKUP(Table4[[#This Row],[Item Name]],Table2[[#All],[Item Name]:[Open Rate]],8,0),"") -> 812.2 | N121: =IFERROR(+Table4[[#This Row],[Qty Issued]]*Table4[[#This Row],[Rate]],"") -> 812.2 | O121: Yes | P121: Pending
... A130: 45761 | B130: Consumed | C130: 177 | D130: 1 | E130: =IFERROR(VLOOKUP(Table4[[#This Row],[From Location Code]],Table5[#All],3,0),"") -> Munger | F130: =IFERROR(VLOOKUP(Table4[[#This Row],[From Location Code]],Table5[#All],2,0),"") -> Main Godown | G130: 1002 | H130: =IFERROR(VLOOKUP(Table4[[#This Row],[To BMC/MPG Code]],Table5[#All],3,0),"") -> Laldiyara | I130: =IFERROR(VLOOKUP(Table4[[#This Row],[To BMC/MPG Code]],Table5[#All],2,0),"") -> BMC | J130: Milk Despatch Challan | K130: =IFERROR(VLOOKUP(Table4[[#This Row],[Item Name]],Table2[[Item Name]:[UoM]],2,0),"") -> Nos | L130: 10 | M130: =IFERROR(VLOOKUP(Table4[[#This Row],[Item Name]],Table2[[#All],[Item Name]:[Open Rate]],8,0),"") -> 94.4 | N130: =IFERROR(+Table4[[#This Row],[Qty Issued]]*Table4[[#This Row],[Rate]],"") -> 944 | O130: Yes | P130: Pending
A131: 45761 | B131: Consumed | D131: 1 | E131: =IFERROR(VLOOKUP(Table4[[#This Row],[From Location Code]],Table5[#All],3,0),"") -> Munger | F131: =IFERROR(VLOOKUP(Table4[[#This Row],[From Location Code]],Table5[#All],2,0),"") -> Main Godown | G131: 1054 | H131: =IFERROR(VLOOKUP(Table4[[#This Row],[To BMC/MPG Code]],Table5[#All],3,0),"") -> Alauli | I131: =IFERROR(VLOOKUP(Table4[[#This Row],[To BMC/MPG Code]],Table5[#All],2,0),"") -> BMC | J131: Beaker 100 Ml | K131: =IFERROR(VLOOKUP(Table4[[#This Row],[Item Name]],Table2[[Item Name]:[UoM]],2,0),"") -> Nos | L131: 2 | M131: =IFERROR(VLOOKUP(Table4[[#This Row],[Item Name]],Table2[[#All],[Item Name]:[Open Rate]],8,0),"") -> 33.18 | N131: =IFERROR(+Table4[[#This Row],[Qty Issued]]*Table4[[#This Row],[Rate]],"") -> 66.36 | O131: No | P131: NA
A132: 45761 | B132: Consumed | D132: 1 | E132: =IFERROR(VLOOKUP(Table4[[#This Row],[From Location Code]],Table5[#All],3,0),"") -> Munger | F132: =IFERROR(VLOOKUP(Table4[[#This Row],[From Location Code]],Table5[#All],2,0),"") -> Main Godown | G132: 1054 | H132: =IFERROR(VLOOKUP(Table4[[#This Row],[To BMC/MPG Code]],Table5[#All],3,0),"") -> Alauli | I132: =IFERROR(VLOOKUP(Table4[[#This Row],[To BMC/MPG Code]],Table5[#All],2,0),"") -> BMC | J132: Beaker 500 Ml | K132: =IFERROR(VLOOKUP(Table4[[#This Row],[Item Name]],Table2[[Item Name]:[UoM]],2,0),"") -> Nos | L132: 2 | M132: =IFERROR(VLOOKUP(Table4[[#This Row],[Item Name]],Table2[[#All],[Item Name]:[Open Rate]],8,0),"") -> 63.7 | N132: =IFERROR(+Table4[[#This Row],[Qty Issued]]*Table4[[#This Row],[Rate]],"") -> 127.4 | O132: No | P132: NA
A133: 45761 | B133: Consumed | D133: 1 | E133: =IFERROR(VLOOKUP(Table4[[#This Row],[From Location Code]],Table5[#All],3,0),"") -> Munger | F133: =IFERROR(VLOOKUP(Table4[[#This Row],[From Location Code]],Table5[#All],2,0),"") -> Main Godown | G133: 1054 | H133: =IFERROR(VLOOKUP(Table4[[#This Row],[To BMC/MPG Code]],Table5[#All],3,0),"") -> Alauli | I133: =IFERROR(VLOOKUP(Table4[[#This Row],[To BMC/MPG Code]],Table5[#All],2,0),"") -> BMC | J133: Beaker 50 ML | K133: =IFERROR(VLOOKUP(Table4[[#This Row],[Item Name]],Table2[[Item Name]:[UoM]],2,0),"") -> Nos | L133: 2 | M133: =IFERROR(VLOOKUP(Table4[[#This Row],[Item Name]],Table2[[#All],[Item Name]:[Open Rate]],8,0),"") -> 15.88 | N133: =IFERROR(+Table4[[#This Row],[Qty Issued]]*Table4[[#This Row],[Rate]],"") -> 31.76 | O133: No | P133: NA
A134: 45761 | B134: Consumed | D134: 1 | E134: =IFERROR(VLOOKUP(Table4[[#This Row],[From Location Code]],Table5[#All],3,0),"") -> Munger | F134: =IFERROR(VLOOKUP(Table4[[#This Row],[From Location Code]],Table5[#All],2,0),"") -> Main Godown | G134: 1054 | H134: =IFERROR(VLOOKUP(Table4[[#This Row],[To BMC/MPG Code]],Table5[#All],3,0),"") -> Alauli | I134: =IFERROR(VLOOKUP(Table4[[#This Row],[To BMC/MPG Code]],Table5[#All],2,0),"") -> BMC | J134: Conical Flask 100 ML | K134: =IFERROR(VLOOKUP(Table4[[#This Row],[Item Name]],Table2[[Item Name]:[UoM]],2,0),"") -> Nos | L134: 1 | M134: =IFERROR(VLOOKUP(Table4[[#This Row],[Item Name]],Table2[[#All],[Item Name]:[Open Rate]],8,0),"") -> 29.47 | N134: =IFERROR(+Table4[[#This Row],[Qty Issued]]*Table4[[#This Row],[Rate]],"") -> 29.47 | O134: No | P134: NA
A135: 45761 | B135: Consumed | D135: 1 | E135: =IFERROR(VLOOKUP(Table4[[#This Row],[From Location Code]],Table5[#All],3,0),"") -> Munger | F135: =IFERROR(VLOOKUP(Table4[[#This Row],[From Location Code]],Table5[#All],2,0),"") -> Main Godown | G135: 1054 | H135: =IFERROR(VLOOKUP(Table4[[#This Row],[To BMC/MPG Code]],Table5[#All],3,0),"") -> Alauli | I135: =IFERROR(VLOOKUP(Table4[[#This Row],[To BMC/MPG Code]],Table5[#All],2,0),"") -> BMC | J135: Pipette Gradulated 10 ML | K135: =IFERROR(VLOOKUP(Table4[[#This Row],[Item Name]],Table2[[Item Name]:[UoM]],2,0),"") -> Nos | L135: 2 | M135: =IFERROR(VLOOKUP(Table4[[#This Row],[Item Name]],Table2[[#All],[Item Name]:[Open Rate]],8,0),"") -> 23.46 | N135: =IFERROR(+Table4[[#This Row],[Qty Issued]]*Table4[[#This Row],[Rate]],"") -> 46.92 | O135: No | P135: NA
A136: 45761 | B136: Consumed | D136: 1 | E136: =IFERROR(VLOOKUP(Table4[[#This Row],[From Location Code]],Table5[#All],3,0),"") -> Munger | F136: =IFERROR(VLOOKUP(Table4[[#This Row],[From Location Code]],Table5[#All],2,0),"") -> Main Godown | G136: 1054 | H136: =IFERROR(VLOOKUP(Table4[[#This Row],[To BMC/MPG Code]],Table5[#All],3,0),"") -> Alauli | I136: =IFERROR(VLOOKUP(Table4[[#This Row],[To BMC/MPG Code]],Table5[#All],2,0),"") -> BMC | J136: Pipette Gradulated 1 ML | K136: =IFERROR(VLOOKUP(Table4[[#This Row],[Item Name]],Table2[[Item Name]:[UoM]],2,0),"") -> Nos | L136: 2 | M136: =IFERROR(VLOOKUP(Table4[[#This Row],[Item Name]],Table2[[#All],[Item Name]:[Open Rate]],8,0),"") -> 22.42 | N136: =IFERROR(+Table4[[#This Row],[Qty Issued]]*Table4[[#This Row],[Rate]],"") -> 44.84 | O136: No | P136: NA
A137: 45761 | B137: Consumed | D137: 1 | E137: =IFERROR(VLOOKUP(Table4[[#This Row],[From Location Code]],Table5[#All],3,0),"") -> Munger | F137: =IFERROR(VLOOKUP(Table4[[#This Row],[From Location Code]],Table5[#All],2,0),"") -> Main Godown | G137: 1054 | H137: =IFERROR(VLOOKUP(Table4[[#This Row],[To BMC/MPG Code]],Table5[#All],3,0),"") -> Alauli | I137: =IFERROR(VLOOKUP(Table4[[#This Row],[To BMC/MPG Code]],Table5[#All],2,0),"") -> BMC | J137: Pipette Gradulated 2 ML | K137: =IFERROR(VLOOKUP(Table4[[#This Row],[Item Name]],Table2[[Item Name]:[UoM]],2,0),"") -> Nos | L137: 2 | M137: =IFERROR(VLOOKUP(Table4[[#This Row],[Item Name]],Table2[[#All],[Item Name]:[Open Rate]],8,0),"") -> 28.46 | N137: =IFERROR(+Table4[[#This Row],[Qty Issued]]*Table4[[#This Row],[Rate]],"") -> 56.92 | O137: No | P137: NA
A138: 45761 | B138: Consumed | D138: 1 | E138: =IFERROR(VLOOKUP(Table4[[#This Row],[From Location Code]],Table5[#All],3,0),"") -> Munger | F138: =IFERROR(VLOOKUP(Table4[[#This Row],[From Location Code]],Table5[#All],2,0),"") -> Main Godown | G138: 1054 | H138: =IFERROR(VLOOKUP(Table4[[#This Row],[To BMC/MPG Code]],Table5[#All],3,0),"") -> Alauli | I138: =IFERROR(VLOOKUP(Table4[[#This Row],[To BMC/MPG Code]],Table5[#All],2,0),"") -> BMC | J138: Reagent Bottle 250 ML | K138: =IFERROR(VLOOKUP(Table4[[#This Row],[Item Name]],Table2[[Item Name]:[UoM]],2,0),"") -> Nos | L138: 6 | M138: =IFERROR(VLOOKUP(Table4[[#This Row],[Item Name]],Table2[[#All],[Item Name]:[Open Rate]],8,0),"") -> 88.5 | N138: =IFERROR(+Table4[[#This Row],[Qty Issued]]*Table4[[#This Row],[Rate]],"") -> 531 | O138: No | P138: NA
A139: 45761 | B139: Consumed | D139: 1 | E139: =IFERROR(VLOOKUP(Table4[[#This Row],[From Location Code]],Table5[#All],3,0),"") -> Munger | F139: =IFERROR(VLOOKUP(Table4[[#This Row],[From Location Code]],Table5[#All],2,0),"") -> Main Godown | G139: 1054 | H139: =IFERROR(VLOOKUP(Table4[[#This Row],[To BMC/MPG Code]],Table5[#All],3,0),"") -> Alauli | I139: =IFERROR(VLOOKUP(Table4[[#This Row],[To BMC/MPG Code]],Table5[#All],2,0),"") -> BMC | J139: Lactometer Jar Small | K139: =IFERROR(VLOOKUP(Table4[[#This Row],[Item Name]],Table2[[Item Name]:[UoM]],2,0),"") -> Nos | L139: 2 | M139: =IFERROR(VLOOKUP(Table4[[#This Row],[Item Name]],Table2[[#All],[Item Name]:[Open Rate]],8,0),"") -> 18.95 | N139: =IFERROR(+Table4[[#This Row],[Qty Issued]]*Table4[[#This Row],[Rate]],"") -> 37.9 | O139: No | P139: NA
A140: 45761 | B140: Consumed | D140: 1 | E140: =IFERROR(VLOOKUP(Table4[[#This Row],[From Location Code]],Table5[#All],3,0),"") -> Munger | F140: =IFERROR(VLOOKUP(Table4[[#This Row],[From Location Code]],Table5[#All],2,0),"") -> Main Godown | G140: 1054 | H140: =IFERROR(VLOOKUP(Table4[[#This Row],[To BMC/MPG Code]],Table5[#All],3,0),"") -> Alauli | I140: =IFERROR(VLOOKUP(Table4[[#This Row],[To BMC/MPG Code]],Table5[#All],2,0),"") -> BMC | J140: Tilt Measure 10cc PI Superior | K140: =IFERROR(VLOOKUP(Table4[[#This Row],[Item Name]],Table2[[Item Name]:[UoM]],2,0),"") -> Nos | L140: 2 | M140: =IFERROR(VLOOKUP(Table4[[#This Row],[Item Name]],Table2[[#All],[Item Name]:[Open Rate]],8,0),"") -> 23.71 | N140: =IFERROR(+Table4[[#This Row],[Qty Issued]]*Table4[[#This Row],[Rate]],"") -> 47.42 | O140: No | P140: NA
A141: 45761 | B141: Consumed | D141: 1 | E141: =IFERROR(VLOOKUP(Table4[[#This Row],[From Location Code]],Table5[#All],3,0),"") -> Munger | F141: =IFERROR(VLOOKUP(Table4[[#This Row],[From Location Code]],Table5[#All],2,0),"") -> Main Godown | G141: 1054 | H141: =IFERROR(VLOOKUP(Table4[[#This Row],[To BMC/MPG Code]],Table5[#All],3,0),"") -> Alauli | I141: =IFERROR(VLOOKUP(Table4[[#This Row],[To BMC/MPG Code]],Table5[#All],2,0),"") -> BMC | J141: Tilt Measure 1 Ml with Bottle | K141: =IFERROR(VLOOKUP(Table4[[#This Row],[Item Name]],Table2[[Item Name]:[UoM]],2,0),"") -> Nos | L141: 2 | M141: =IFERROR(VLOOKUP(Table4[[#This Row],[Item Name]],Table2[[#All],[Item Name]:[Open Rate]],8,0),"") -> 32.09 | N141: =IFERROR(+Table4[[#This Row],[Qty Issued]]*Table4[[#This Row],[Rate]],"") -> 64.18 | O141: No | P141: NA
A142: 45761 | B142: Consumed | D142: 1 | E142: =IFERROR(VLOOKUP(Table4[[#This Row],[From Location Code]],Table5[#All],3,0),"") -> Munger | F142: =IFERROR(VLOOKUP(Table4[[#This Row],[From Location Code]],Table5[#All],2,0),"") -> Main Godown | G142: 1054 | H142: =IFERROR(VLOOKUP(Table4[[#This Row],[To BMC/MPG Code]],Table5[#All],3,0),"") -> Alauli | I142: =IFERROR(VLOOKUP(Table4[[#This Row],[To BMC/MPG Code]],Table5[#All],2,0),"") -> BMC | J142: Sample Bottle 100 ML | K142: =IFERROR(VLOOKUP(Table4[[#This Row],[Item Name]],Table2[[Item Name]:[UoM]],2,0),"") -> Nos | L142: 50 | M142: =IFERROR(VLOOKUP(Table4[[#This Row],[Item Name]],Table2[[#All],[Item Name]:[Open Rate]],8,0),"") -> 2.83 | N142: =IFERROR(+Table4[[#This Row],[Qty Issued]]*Table4[[#This Row],[Rate]],"") -> 141.5 | O142: No | P142: NA
...

Sheet Pending Consumption
A1: S No | B1: Name of BMC | C1: Item Name | D1: Issue | E1: Consumed | F1: Balance
A2: 1 | B2: Sahibpur Kamal | C2: 1% Iodine Solution (100ml) | D2: =SUMIFS(Table4[[#All],[Qty Issued]],Table4[[#All],[BMC MPG Name]],'Pending Consumption'!$B2,Table4[[#All],[Item Name]],'Pending Consumption'!$C2,Table4[[#All],[Type]],"Transfer") -> 0 | E2: =SUMIFS(Table4[[#All],[Qty Issued]],Table4[[#All],[Location]],'Pending Consumption'!B2,Table4[[#All],[Item Name]],'Pending Consumption'!$C2,Table4[[#All],[Type]],"Transfer") -> 0 | F2: =+D2-E2 -> 0
A3: 2 | B3: Sahibpur Kamal | C3: Amber Colour Bottle (250 ML) | D3: =SUMIFS(Table4[[#All],[Qty Issued]],Table4[[#All],[BMC MPG Name]],'Pending Consumption'!$B3,Table4[[#All],[Item Name]],'Pending Consumption'!$C3,Table4[[#All],[Type]],"Transfer") -> 0 | E3: =SUMIFS(Table4[[#All],[Qty Issued]],Table4[[#All],[Location]],'Pending Consumption'!B3,Table4[[#All],[Item Name]],'Pending Consumption'!$C3,Table4[[#All],[Type]],"Transfer") -> 0 | F3: =+D3-E3 -> 0
A4: 3 | B4: Sahibpur Kamal | C4: Amyl 500ml | D4: =SUMIFS(Table4[[#All],[Qty Issued]],Table4[[#All],[BMC MPG Name]],'Pending Consumption'!$B4,Table4[[#All],[Item Name]],'Pending Consumption'!$C4,Table4[[#All],[Type]],"Transfer") -> 0 | E4: =SUMIFS(Table4[[#All],[Qty Issued]],Table4[[#All],[Location]],'Pending Consumption'!B4,Table4[[#All],[Item Name]],'Pending Consumption'!$C4,Table4[[#All],[Type]],"Transfer") -> 0 | F4: =+D4-E4 -> 0
A5: 4 | B5: Sahibpur Kamal | C5: Analyzer Calibration Cheking Log Book | D5: =SUMIFS(Table4[[#All],[Qty Issued]],Table4[[#All],[BMC MPG Name]],'Pending Consumption'!$B5,Table4[[#All],[Item Name]],'Pending Consumption'!$C5,Table4[[#All],[Type]],"Transfer") -> 0 | E5: =SUMIFS(Table4[[#All],[Qty Issued]],Table4[[#All],[Location]],'Pending Consumption'!B5,Table4[[#All],[Item Name]],'Pending Consumption'!$C5,Table4[[#All],[Type]],"Transfer") -> 0 | F5: =+D5-E5 -> 0
A6: 5 | B6: Sahibpur Kamal | C6: Beaker 100 Ml | D6: =SUMIFS(Table4[[#All],[Qty Issued]],Table4[[#All],[BMC MPG Name]],'Pending Consumption'!$B6,Table4[[#All],[Item Name]],'Pending Consumption'!$C6,Table4[[#All],[Type]],"Transfer") -> 0 | E6: =SUMIFS(Table4[[#All],[Qty Issued]],Table4[[#All],[Location]],'Pending Consumption'!B6,Table4[[#All],[Item Name]],'Pending Consumption'!$C6,Table4[[#All],[Type]],"Transfer") -> 0 | F6: =+D6-E6 -> 0
A7: 6 | B7: Sahibpur Kamal | C7: Beaker 250 ML Borosilicate | D7: =SUMIFS(Table4[[#All],[Qty Issued]],Table4[[#All],[BMC MPG Name]],'Pending Consumption'!$B7,Table4[[#All],[Item Name]],'Pending Consumption'!$C7,Table4[[#All],[Type]],"Transfer") -> 0 | E7: =SUMIFS(Table4[[#All],[Qty Issued]],Table4[[#All],[Location]],'Pending Consumption'!B7,Table4[[#All],[Item Name]],'Pending Consumption'!$C7,Table4[[#All],[Type]],"Transfer") -> 0 | F7: =+D7-E7 -> 0
A8: 7 | B8: Sahibpur Kamal | C8: Beaker 500 Ml | D8: =SUMIFS(Table4[[#All],[Qty Issued]],Table4[[#All],[BMC MPG Name]],'Pending Consumption'!$B8,Table4[[#All],[Item Name]],'Pending Consumption'!$C8,Table4[[#All],[Type]],"Transfer") -> 0 | E8: =SUMIFS(Table4[[#All],[Qty Issued]],Table4[[#All],[Location]],'Pending Consumption'!B8,Table4[[#All],[Item Name]],'Pending Consumption'!$C8,Table4[[#All],[Type]],"Transfer") -> 0 | F8: =+D8-E8 -> 0
A9: 8 | B9: Sahibpur Kamal | C9: Beaker 50 ML | D9: =SUMIFS(Table4[[#All],[Qty Issued]],Table4[[#All],[BMC MPG Name]],'Pending Consumption'!$B9,Table4[[#All],[Item Name]],'Pending Consumption'!$C9,Table4[[#All],[Type]],"Transfer") -> 0 | E9: =SUMIFS(Table4[[#All],[Qty Issued]],Table4[[#All],[Location]],'Pending Consumption'!B9,Table4[[#All],[Item Name]],'Pending Consumption'!$C9,Table4[[#All],[Type]],"Transfer") -> 0 | F9: =+D9-E9 -> 0
A10: 9 | B10: Sahibpur Kamal | C10: BMC Cleaning Brush 2" | D10: =SUMIFS(Table4[[#All],[Qty Issued]],Table4[[#All],[BMC MPG Name]],'Pending Consumption'!$B10,Table4[[#All],[Item Name]],'Pending Consumption'!$C10,Table4[[#All],[Type]],"Transfer") -> 0 | E10: =SUMIFS(Table4[[#All],[Qty Issued]],Table4[[#All],[Location]],'Pending Consumption'!B10,Table4[[#All],[Item Name]],'Pending Consumption'!$C10,Table4[[#All],[Type]],"Transfer") -> 0 | F10: =+D10-E10 -> 0
A11: 10 | B11: Sahibpur Kamal | C11: BMC Day Book | D11: =SUMIFS(Table4[[#All],[Qty Issued]],Table4[[#All],[BMC MPG Name]],'Pending Consumption'!$B11,Table4[[#All],[Item Name]],'Pending Consumption'!$C11,Table4[[#All],[Type]],"Transfer") -> 0 | E11: =SUMIFS(Table4[[#All],[Qty Issued]],Table4[[#All],[Location]],'Pending Consumption'!B11,Table4[[#All],[Item Name]],'Pending Consumption'!$C11,Table4[[#All],[Type]],"Transfer") -> 0 | F11: =+D11-E11 -> 0
A12: 11 | B12: Sahibpur Kamal | C12: Burete Stand | D12: =SUMIFS(Table4[[#All],[Qty Issued]],Table4[[#All],[BMC MPG Name]],'Pending Consumption'!$B12,Table4[[#All],[Item Name]],'Pending Consumption'!$C12,Table4[[#All],[Type]],"Transfer") -> 0 | E12: =SUMIFS(Table4[[#All],[Qty Issued]],Table4[[#All],[Location]],'Pending Consumption'!B12,Table4[[#All],[Item Name]],'Pending Consumption'!$C12,Table4[[#All],[Type]],"Transfer") -> 0 | F12: =+D12-E12 -> 0
A13: 12 | B13: Sahibpur Kamal | C13: Burret 50 ML Borosilicate | D13: =SUMIFS(Table4[[#All],[Qty Issued]],Table4[[#All],[BMC MPG Name]],'Pending Consumption'!$B13,Table4[[#All],[Item Name]],'Pending Consumption'!$C13,Table4[[#All],[Type]],"Transfer") -> 0 | E13: =SUMIFS(Table4[[#All],[Qty Issued]],Table4[[#All],[Location]],'Pending Consumption'!B13,Table4[[#All],[Item Name]],'Pending Consumption'!$C13,Table4[[#All],[Type]],"Transfer") -> 0 | F13: =+D13-E13 -> 0
... A97: 96 | B97: Sahibpur Kamal | C97: Tilt Measure 1 Ml with Bottle | D97: =SUMIFS(Table4[[#All],[Qty Issued]],Table4[[#All],[BMC MPG Name]],'Pending Consumption'!$B97,Table4[[#All],[Item Name]],'Pending Consumption'!$C97,Table4[[#All],[Type]],"Transfer") -> 0 | E97: =SUMIFS(Table4[[#All],[Qty Issued]],Table4[[#All],[Location]],'Pending Consumption'!B97,Table4[[#All],[Item Name]],'Pending Consumption'!$C97,Table4[[#All],[Type]],"Transfer") -> 0 | F97: =+D97-E97 -> 0
B98: Kalyanpur | C98: 1% Iodine Solution (100ml) | D98: =SUMIFS(Table4[[#All],[Qty Issued]],Table4[[#All],[BMC MPG Name]],'Pending Consumption'!$B98,Table4[[#All],[Item Name]],'Pending Consumption'!$C98,Table4[[#All],[Type]],"Transfer") -> 0 | E98: =SUMIFS(Table4[[#All],[Qty Issued]],Table4[[#All],[Location]],'Pending Consumption'!B98,Table4[[#All],[Item Name]],'Pending Consumption'!$C98,Table4[[#All],[Type]],"Transfer") -> 0 | F98: =+D98-E98 -> 0
B99: Kalyanpur | C99: Amber Colour Bottle (250 ML) | D99: =SUMIFS(Table4[[#All],[Qty Issued]],Table4[[#All],[BMC MPG Name]],'Pending Consumption'!$B99,Table4[[#All],[Item Name]],'Pending Consumption'!$C99,Table4[[#All],[Type]],"Transfer") -> 0 | E99: =SUMIFS(Table4[[#All],[Qty Issued]],Table4[[#All],[Location]],'Pending Consumption'!B99,Table4[[#All],[Item Name]],'Pending Consumption'!$C99,Table4[[#All],[Type]],"Transfer") -> 0 | F99: =+D99-E99 -> 0
B100: Kalyanpur | C100: Amyl 500ml | D100: =SUMIFS(Table4[[#All],[Qty Issued]],Table4[[#All],[BMC MPG Name]],'Pending Consumption'!$B100,Table4[[#All],[Item Name]],'Pending Consumption'!$C100,Table4[[#All],[Type]],"Transfer") -> 0 | E100: =SUMIFS(Table4[[#All],[Qty Issued]],Table4[[#All],[Location]],'Pending Consumption'!B100,Table4[[#All],[Item Name]],'Pending Consumption'!$C100,Table4[[#All],[Type]],"Transfer") -> 0 | F100: =+D100-E100 -> 0
B101: Kalyanpur | C101: Analyzer Calibration Cheking Log Book | D101: =SUMIFS(Table4[[#All],[Qty Issued]],Table4[[#All],[BMC MPG Name]],'Pending Consumption'!$B101,Table4[[#All],[Item Name]],'Pending Consumption'!$C101,Table4[[#All],[Type]],"Transfer") -> 0 | E101: =SUMIFS(Table4[[#All],[Qty Issued]],Table4[[#All],[Location]],'Pending Consumption'!B101,Table4[[#All],[Item Name]],'Pending Consumption'!$C101,Table4[[#All],[Type]],"Transfer") -> 0 | F101: =+D101-E101 -> 0
B102: Kalyanpur | C102: Beaker 100 Ml | D102: =SUMIFS(Table4[[#All],[Qty Issued]],Table4[[#All],[BMC MPG Name]],'Pending Consumption'!$B102,Table4[[#All],[Item Name]],'Pending Consumption'!$C102,Table4[[#All],[Type]],"Transfer") -> 0 | E102: =SUMIFS(Table4[[#All],[Qty Issued]],Table4[[#All],[Location]],'Pending Consumption'!B102,Table4[[#All],[Item Name]],'Pending Consumption'!$C102,Table4[[#All],[Type]],"Transfer") -> 0 | F102: =+D102-E102 -> 0
B103: Kalyanpur | C103: Beaker 250 ML Borosilicate | D103: =SUMIFS(Table4[[#All],[Qty Issued]],Table4[[#All],[BMC MPG Name]],'Pending Consumption'!$B103,Table4[[#All],[Item Name]],'Pending Consumption'!$C103,Table4[[#All],[Type]],"Transfer") -> 0 | E103: =SUMIFS(Table4[[#All],[Qty Issued]],Table4[[#All],[Location]],'Pending Consumption'!B103,Table4[[#All],[Item Name]],'Pending Consumption'!$C103,Table4[[#All],[Type]],"Transfer") -> 0 | F103: =+D103-E103 -> 0
B104: Kalyanpur | C104: Beaker 500 Ml | D104: =SUMIFS(Table4[[#All],[Qty Issued]],Table4[[#All],[BMC MPG Name]],'Pending Consumption'!$B104,Table4[[#All],[Item Name]],'Pending Consumption'!$C104,Table4[[#All],[Type]],"Transfer") -> 0 | E104: =SUMIFS(Table4[[#All],[Qty Issued]],Table4[[#All],[Location]],'Pending Consumption'!B104,Table4[[#All],[Item Name]],'Pending Consumption'!$C104,Table4[[#All],[Type]],"Transfer") -> 0 | F104: =+D104-E104 -> 0
B105: Kalyanpur | C105: Beaker 50 ML | D105: =SUMIFS(Table4[[#All],[Qty Issued]],Table4[[#All],[BMC MPG Name]],'Pending Consumption'!$B105,Table4[[#All],[Item Name]],'Pending Consumption'!$C105,Table4[[#All],[Type]],"Transfer") -> 0 | E105: =SUMIFS(Table4[[#All],[Qty Issued]],Table4[[#All],[Location]],'Pending Consumption'!B105,Table4[[#All],[Item Name]],'Pending Consumption'!$C105,Table4[[#All],[Type]],"Transfer") -> 0 | F105: =+D105-E105 -> 0
B106: Kalyanpur | C106: BMC Cleaning Brush 2" | D106: =SUMIFS(Table4[[#All],[Qty Issued]],Table4[[#All],[BMC MPG Name]],'Pending Consumption'!$B106,Table4[[#All],[Item Name]],'Pending Consumption'!$C106,Table4[[#All],[Type]],"Transfer") -> 0 | E106: =SUMIFS(Table4[[#All],[Qty Issued]],Table4[[#All],[Location]],'Pending Consumption'!B106,Table4[[#All],[Item Name]],'Pending Consumption'!$C106,Table4[[#All],[Type]],"Transfer") -> 0 | F106: =+D106-E106 -> 0
B107: Kalyanpur | C107: BMC Day Book | D107: =SUMIFS(Table4[[#All],[Qty Issued]],Table4[[#All],[BMC MPG Name]],'Pending Consumption'!$B107,Table4[[#All],[Item Name]],'Pending Consumption'!$C107,Table4[[#All],[Type]],"Transfer") -> 0 | E107: =SUMIFS(Table4[[#All],[Qty Issued]],Table4[[#All],[Location]],'Pending Consumption'!B107,Table4[[#All],[Item Name]],'Pending Consumption'!$C107,Table4[[#All],[Type]],"Transfer") -> 0 | F107: =+D107-E107 -> 0
B108: Kalyanpur | C108: Burete Stand | D108: =SUMIFS(Table4[[#All],[Qty Issued]],Table4[[#All],[BMC MPG Name]],'Pending Consumption'!$B108,Table4[[#All],[Item Name]],'Pending Consumption'!$C108,Table4[[#All],[Type]],"Transfer") -> 0 | E108: =SUMIFS(Table4[[#All],[Qty Issued]],Table4[[#All],[Location]],'Pending Consumption'!B108,Table4[[#All],[Item Name]],'Pending Consumption'!$C108,Table4[[#All],[Type]],"Transfer") -> 0 | F108: =+D108-E108 -> 0
