Workbook

Sheet Daily Losses
A2: Cycle | C2: Date | D2: Shift | E2: Itki | F2: Pali | G2: Hisri Thakurgaon | H2: Choreya | I2: Baski | J2: Ormanjhi Rmc | K2: Piragutu Rmc | L2: Bhandra Rmc | M2: Chanho
A3: 1-2July | B3: 46174 | C3: 45717 | D3: M | E3: =Itki!AQ4 -> 2555.55 | F3: =Pali!AQ4 -> -150.2325 | G3: =Hisri!AQ4 -> 992.2743 | H3: =Choriya!AQ4 -> 64.18545 | I3: =Baski!AQ4 -> 0 | J3: =Orja!AQ4 -> 127.0965 | K3: =Piragutu!AQ4 -> 1201.185 | L3: =Bhandra!AQ4 -> -110.22 | M3: =Chanho!AQ4 -> -2906.97
A4: 1-2July | B4: 46174 | C4: 45717 | D4: E | E4: =Itki!AQ5 -> 75.6309 | F4: =Pali!AQ5 -> -900.9375 | G4: =Hisri!AQ5 -> 3.876 | H4: =Choriya!AQ5 -> 30.4269 | I4: =Baski!AQ5 -> 0 | J4: =Orja!AQ5 -> 102.5904 | K4: =Piragutu!AQ5 -> 62.9112 | L4: =Bhandra!AQ5 -> 129.018 | M4: =Chanho!AQ5 -> -14.6094
A5: 1-2July | B5: 46175 | C5: 45718 | D5: M | E5: =Itki!AQ6 -> 4042.8141 | F5: =Pali!AQ6 -> -49.725 | G5: =Hisri!AQ6 -> 572.139 | H5: =Choriya!AQ6 -> 16.353 | I5: =Baski!AQ6 -> 0 | J5: =Orja!AQ6 -> -732.6519 | K5: =Piragutu!AQ6 -> 1977.9879 | L5: =Bhandra!AQ6 -> 98.7528 | M5: =Chanho!AQ6 -> 464.7444
A6: 1-2July | B6: 46175 | C6: 45718 | D6: E | E6: =Itki!AQ7 -> 65.14665 | F6: =Pali!AQ7 -> -4632.54 | G6: =Hisri!AQ7 -> 11.91705 | H6: =Choriya!AQ7 -> 370.659 | I6: =Baski!AQ7 -> 0 | J6: =Orja!AQ7 -> 224.07 | K6: =Piragutu!AQ7 -> 153.2823 | L6: =Bhandra!AQ7 -> 203.0742 | M6: =Chanho!AQ7 -> 2364.885
A7: 3-9 July | B7: 46145 | C7: 45719 | D7: M | E7: =Itki!AQ8 -> 0 | F7: =Pali!AQ8 -> 0 | G7: =Hisri!AQ8 -> 0 | H7: =Choriya!AQ8 -> 0 | I7: =Baski!AQ8 -> 0 | J7: =Orja!AQ8 -> 0 | K7: =Piragutu!AQ8 -> 0 | L7: =Bhandra!AQ8 -> 0 | M7: =Chanho!AQ8 -> 0
A8: 3-9 July | B8: 46145 | C8: 45719 | D8: E | E8: =Itki!AQ9 -> 0 | F8: =Pali!AQ9 -> 0 | G8: =Hisri!AQ9 -> 0 | H8: =Choriya!AQ9 -> 0 | I8: =Baski!AQ9 -> 0 | J8: =Orja!AQ9 -> 0 | K8: =Piragutu!AQ9 -> 0 | L8: =Bhandra!AQ9 -> 0 | M8: =Chanho!AQ9 -> 0
A9: 3-9 July | B9: 46146 | C9: 45720 | D9: M | E9: =Itki!AQ10 -> 0 | F9: =Pali!AQ10 -> 0 | G9: =Hisri!AQ10 -> 0 | H9: =Choriya!AQ10 -> 0 | I9: =Baski!AQ10 -> 0 | J9: =Orja!AQ10 -> 0 | K9: =Piragutu!AQ10 -> 0 | L9: =Bhandra!AQ10 -> 0 | M9: =Chanho!AQ10 -> 0
A10: 3-9 July | B10: 46146 | C10: 45720 | D10: E | E10: =Itki!AQ11 -> 0 | F10: =Pali!AQ11 -> 0 | G10: =Hisri!AQ11 -> 0 | H10: =Choriya!AQ11 -> 0 | I10: =Baski!AQ11 -> 0 | J10: =Orja!AQ11 -> 0 | K10: =Piragutu!AQ11 -> 0 | L10: =Bhandra!AQ11 -> 0 | M10: =Chanho!AQ11 -> 0
A11: 3-9 July | B11: 46147 | C11: 45721 | D11: M | E11: =Itki!AQ12 -> 0 | F11: =Pali!AQ12 -> 0 | G11: =Hisri!AQ12 -> 0 | H11: =Choriya!AQ12 -> 0 | I11: =Baski!AQ12 -> 0 | J11: =Orja!AQ12 -> 0 | K11: =Piragutu!AQ12 -> 0 | L11: =Bhandra!AQ12 -> 0 | M11: =Chanho!AQ12 -> 0
A12: 3-9 July | B12: 46147 | C12: 45721 | D12: E | E12: =Itki!AQ13 -> 0 | F12: =Pali!AQ13 -> 0 | G12: =Hisri!AQ13 -> 0 | H12: =Choriya!AQ13 -> 0 | I12: =Baski!AQ13 -> 0 | J12: =Orja!AQ13 -> 0 | K12: =Piragutu!AQ13 -> 0 | L12: =Bhandra!AQ13 -> 0 | M12: =Chanho!AQ13 -> 0
A13: 3-9 July | B13: 46148 | C13: 45722 | D13: M | E13: =Itki!AQ14 -> 0 | F13: =Pali!AQ14 -> 0 | G13: =Hisri!AQ14 -> 0 | H13: =Choriya!AQ14 -> 0 | I13: =Baski!AQ14 -> 0 | J13: =Orja!AQ14 -> 0 | K13: =Piragutu!AQ14 -> 0 | L13: =Bhandra!AQ14 -> 0 | M13: =Chanho!AQ14 -> 0
A14: 3-9 July | B14: 46148 | C14: 45722 | D14: E | E14: =Itki!AQ15 -> 0 | F14: =Pali!AQ15 -> 0 | G14: =Hisri!AQ15 -> 0 | H14: =Choriya!AQ15 -> 0 | I14: =Baski!AQ15 -> 0 | J14: =Orja!AQ15 -> 0 | K14: =Piragutu!AQ15 -> 0 | L14: =Bhandra!AQ15 -> 0 | M14: =Chanho!AQ15 -> 0
A15: 3-9 July | C15: 45723 | D15: M | E15: =Itki!AQ16 -> 0 | F15: =Pali!AQ16 -> 0 | G15: =Hisri!AQ16 -> 0 | H15: =Choriya!AQ16 -> 0 | I15: =Baski!AQ16 -> 0 | J15: =Orja!AQ16 -> 0 | K15: =Piragutu!AQ16 -> 0 | L15: =Bhandra!AQ16 -> 0 | M15: =Chanho!AQ16 -> 0
A16: 3-9 July | C16: 45723 | D16: E | E16: =Itki!AQ17 -> 0 | F16: =Pali!AQ17 -> 0 | G16: =Hisri!AQ17 -> 0 | H16: =Choriya!AQ17 -> 0 | I16: =Baski!AQ17 -> 0 | J16: =Orja!AQ17 -> 0 | K16: =Piragutu!AQ17 -> 0 | L16: =Bhandra!AQ17 -> 0 | M16: =Chanho!AQ17 -> 0
A17: 3-9 July | C17: 45724 | D17: M | E17: =Itki!AQ18 -> 0 | F17: =Pali!AQ18 -> 0 | G17: =Hisri!AQ18 -> 0 | H17: =Choriya!AQ18 -> 0 | I17: =Baski!AQ18 -> 0 | J17: =Orja!AQ18 -> 0 | K17: =Piragutu!AQ18 -> 0 | L17: =Bhandra!AQ18 -> 0 | M17: =Chanho!AQ18 -> 0
A18: 3-9 July | C18: 45724 | D18: E | E18: =Itki!AQ19 -> 0 | F18: =Pali!AQ19 -> 0 | G18: =Hisri!AQ19 -> 0 | H18: =Choriya!AQ19 -> 0 | I18: =Baski!AQ19 -> 0 | J18: =Orja!AQ19 -> 0 | K18: =Piragutu!AQ19 -> 0 | L18: =Bhandra!AQ19 -> 0 | M18: =Chanho!AQ19 -> 0
A19: 3-9 July | C19: 45725 | D19: M | E19: =Itki!AQ20 -> 0 | F19: =Pali!AQ20 -> 0 | G19: =Hisri!AQ20 -> 0 | H19: =Choriya!AQ20 -> 0 | I19: =Baski!AQ20 -> 0 | J19: =Orja!AQ20 -> 0 | K19: =Piragutu!AQ20 -> 0 | L19: =Bhandra!AQ20 -> 0 | M19: =Chanho!AQ20 -> 0
A20: 3-9 July | C20: 45725 | D20: E | E20: =Itki!AQ21 -> 0 | F20: =Pali!AQ21 -> 0 | G20: =Hisri!AQ21 -> 0 | H20: =Choriya!AQ21 -> 0 | I20: =Baski!AQ21 -> 0 | J20: =Orja!AQ21 -> 0 | K20: =Piragutu!AQ21 -> 0 | L20: =Bhandra!AQ21 -> 0 | M20: =Chanho!AQ21 -> 0
A21: 10-16July | C21: 45726 | D21: M | E21: =Itki!AQ22 -> 0 | F21: =Pali!AQ22 -> 0 | G21: =Hisri!AQ22 -> 0 | H21: =Choriya!AQ22 -> 0 | I21: =Baski!AQ22 -> 0 | J21: =Orja!AQ22 -> 0 | K21: =Piragutu!AQ22 -> 0 | L21: =Bhandra!AQ22 -> 0 | M21: =Chanho!AQ22 -> 0
A22: 10-16July | C22: 45726 | D22: E | E22: =Itki!AQ23 -> 0 | F22: =Pali!AQ23 -> 0 | G22: =Hisri!AQ23 -> 0 | H22: =Choriya!AQ23 -> 0 | I22: =Baski!AQ23 -> 0 | J22: =Orja!AQ23 -> 0 | K22: =Piragutu!AQ23 -> 0 | L22: =Bhandra!AQ23 -> 0 | M22: =Chanho!AQ23 -> 0
A23: 10-16July | C23: 45727 | D23: M | E23: =Itki!AQ24 -> 0 | F23: =Pali!AQ24 -> 0 | G23: =Hisri!AQ24 -> 0 | H23: =Choriya!AQ24 -> 0 | I23: =Baski!AQ24 -> 0 | J23: =Orja!AQ24 -> 0 | K23: =Piragutu!AQ24 -> 0 | L23: =Bhandra!AQ24 -> 0 | M23: =Chanho!AQ24 -> 0
A24: 10-16July | C24: 45727 | D24: E | E24: =Itki!AQ25 -> 0 | F24: =Pali!AQ25 -> 0 | G24: =Hisri!AQ25 -> 0 | H24: =Choriya!AQ25 -> 0 | I24: =Baski!AQ25 -> 0 | J24: =Orja!AQ25 -> 0 | K24: =Piragutu!AQ25 -> 0 | L24: =Bhandra!AQ25 -> 0 | M24: =Chanho!AQ25 -> 0
A25: 10-16July | C25: 45728 | D25: M | E25: =Itki!AQ26 -> 0 | F25: =Pali!AQ26 -> 0 | G25: =Hisri!AQ26 -> 0 | H25: =Choriya!AQ26 -> 0 | I25: =Baski!AQ26 -> 0 | J25: =Orja!AQ26 -> 0 | K25: =Piragutu!AQ26 -> 0 | L25: =Bhandra!AQ26 -> 0 | M25: =Chanho!AQ26 -> 0
A26: 10-16July | C26: 45728 | D26: E | E26: =Itki!AQ27 -> 0 | F26: =Pali!AQ27 -> 0 | G26: =Hisri!AQ27 -> 0 | H26: =Choriya!AQ27 -> 0 | I26: =Baski!AQ27 -> 0 | J26: =Orja!AQ27 -> 0 | K26: =Piragutu!AQ27 -> 0 | L26: =Bhandra!AQ27 -> 0 | M26: =Chanho!AQ27 -> 0
... A62: 24-30 July | C62: 45746 | D62: E | E62: =Itki!AQ63 -> 0 | F62: =Pali!AQ63 -> 0 | G62: =Hisri!AQ63 -> 0 | H62: =Choriya!AQ63 -> 0 | I62: =Baski!AQ63 -> 0 | J62: =Orja!AQ63 -> 0 | K62: =Piragutu!AQ63 -> 0 | L62: =Bhandra!AQ63 -> 0 | M62: =Chanho!AQ63 -> 0
A63: 31-31 July | C63: 45747 | D63: M | E63: =Itki!AQ64 -> 0 | F63: =Pali!AQ64 -> 0 | G63: =Hisri!AQ64 -> 0 | H63: =Choriya!AQ64 -> 0 | I63: =Baski!AQ64 -> 0 | J63: =Orja!AQ64 -> 0 | K63: =Piragutu!AQ64 -> 0 | L63: =Bhandra!AQ64 -> 0 | M63: =Chanho!AQ64 -> 0 | S63: -1 | T63: Gain
A64: 31-31 July | C64: 45747 | D64: E | E64: =Itki!AQ65 -> 0 | F64: =Pali!AQ65 -> 0 | G64: =Hisri!AQ65 -> 0 | H64: =Choriya!AQ65 -> 0 | I64: =Baski!AQ65 -> 0 | J64: =Orja!AQ65 -> 0 | K64: =Piragutu!AQ65 -> 0 | L64: =Bhandra!AQ65 -> 0 | M64: =Chanho!AQ65 -> 0 | S64: 1 | T64: Loss
C65: Total | E65: =SUM(E3:E64) -> 6739.1417 | F65: =SUM(F3:F64) -> -5733.435 | G65: =SUM(G3:G64) -> 1580.2063 | H65: =SUM(H3:H64) -> 481.62435 | I65: =SUM(I3:I64) -> 0 | J65: =SUM(J3:J64) -> -278.895 | K65: =SUM(K3:K64) -> 3395.3664 | L65: =SUM(L3:L64) -> 320.625 | M65: =SUM(M3:M64) -> -91.95
C68: Date | D68: Shift | E68: Itki | F68: Pali | G68: Hisri Thakurgaon | H68: Choreya | I68: Baski | J68: Ormanjhi Rmc | K68: Piragutu Rmc | L68: Bhandra Rmc | M68: Chanho
C69: 1-2July | E69: =SUMIF($A$3:$A$64,$C69,E$3:E$64) -> 6739.1417 | F69: =SUMIF($A$3:$A$64,$C69,F$3:F$64) -> -5733.435 | G69: =SUMIF($A$3:$A$64,$C69,G$3:G$64) -> 1580.2063 | H69: =SUMIF($A$3:$A$64,$C69,H$3:H$64) -> 481.62435 | I69: =SUMIF($A$3:$A$64,$C69,I$3:I$64) -> 0 | J69: =SUMIF($A$3:$A$64,$C69,J$3:J$64) -> -278.895 | K69: =SUMIF($A$3:$A$64,$C69,K$3:K$64) -> 3395.3664 | L69: =SUMIF($A$3:$A$64,$C69,L$3:L$64) -> 320.625 | M69: =SUMIF($A$3:$A$64,$C69,M$3:M$64) -> -91.95
C70: 3-9 July | E70: =SUMIF($A$3:$A$64,$C70,E$3:E$64) -> 0 | F70: =SUMIF($A$3:$A$64,$C70,F$3:F$64) -> 0 | G70: =SUMIF($A$3:$A$64,$C70,G$3:G$64) -> 0 | H70: =SUMIF($A$3:$A$64,$C70,H$3:H$64) -> 0 | I70: =SUMIF($A$3:$A$64,$C70,I$3:I$64) -> 0 | J70: =SUMIF($A$3:$A$64,$C70,J$3:J$64) -> 0 | K70: =SUMIF($A$3:$A$64,$C70,K$3:K$64) -> 0 | L70: =SUMIF($A$3:$A$64,$C70,L$3:L$64) -> 0 | M70: =SUMIF($A$3:$A$64,$C70,M$3:M$64) -> 0
C71: 10-16July | E71: =SUMIF($A$3:$A$64,$C71,E$3:E$64) -> 0 | F71: =SUMIF($A$3:$A$64,$C71,F$3:F$64) -> 0 | G71: =SUMIF($A$3:$A$64,$C71,G$3:G$64) -> 0 | H71: =SUMIF($A$3:$A$64,$C71,H$3:H$64) -> 0 | I71: =SUMIF($A$3:$A$64,$C71,I$3:I$64) -> 0 | J71: =SUMIF($A$3:$A$64,$C71,J$3:J$64) -> 0 | K71: =SUMIF($A$3:$A$64,$C71,K$3:K$64) -> 0 | L71: =SUMIF($A$3:$A$64,$C71,L$3:L$64) -> 0 | M71: =SUMIF($A$3:$A$64,$C71,M$3:M$64) -> 0
C72: 17-23July | E72: =SUMIF($A$3:$A$64,$C72,E$3:E$64) -> 0 | F72: =SUMIF($A$3:$A$64,$C72,F$3:F$64) -> 0 | G72: =SUMIF($A$3:$A$64,$C72,G$3:G$64) -> 0 | H72: =SUMIF($A$3:$A$64,$C72,H$3:H$64) -> 0 | I72: =SUMIF($A$3:$A$64,$C72,I$3:I$64) -> 0 | J72: =SUMIF($A$3:$A$64,$C72,J$3:J$64) -> 0 | K72: =SUMIF($A$3:$A$64,$C72,K$3:K$64) -> 0 | L72: =SUMIF($A$3:$A$64,$C72,L$3:L$64) -> 0 | M72: =SUMIF($A$3:$A$64,$C72,M$3:M$64) -> 0
C73: 24-30 July | E73: =SUMIF($A$3:$A$64,$C73,E$3:E$64) -> 0 | F73: =SUMIF($A$3:$A$64,$C73,F$3:F$64) -> 0 | G73: =SUMIF($A$3:$A$64,$C73,G$3:G$64) -> 0 | H73: =SUMIF($A$3:$A$64,$C73,H$3:H$64) -> 0 | I73: =SUMIF($A$3:$A$64,$C73,I$3:I$64) -> 0 | J73: =SUMIF($A$3:$A$64,$C73,J$3:J$64) -> 0 | K73: =SUMIF($A$3:$A$64,$C73,K$3:K$64) -> 0 | L73: =SUMIF($A$3:$A$64,$C73,L$3:L$64) -> 0 | M73: =SUMIF($A$3:$A$64,$C73,M$3:M$64) -> 0
C74: 31-31 July
C75: Grand Total | E75: =SUM(E69:E73) -> 6739.1417 | F75: =SUM(F69:F73) -> -5733.435 | G75: =SUM(G69:G73) -> 1580.2063 | H75: =SUM(H69:H73) -> 481.62435 | I75: =SUM(I69:I73) -> 0 | J75: =SUM(J69:J73) -> -278.895 | K75: =SUM(K69:K73) -> 3395.3664 | L75: =SUM(L69:L73) -> 320.625 | M75: =SUM(M69:M73) -> -91.95

Sheet Sheet1
C2: State | D2: Type | E2: Code | F2: BMC Name | G2: MTD Volume | H2: Vol Kg | I2: FAT kg | J2: SNF Kg | K2: FAT Rate | L2: SNF Rate | M2: Amount | N2: Loss/gain per Kg | O2: Remarks
C3: JH | D3: SP RMC | E3: 2001 | F3: Itki | G3: =Itki!J66 -> 11895.707 | H3: =Itki!AM66 -> -27.9969 | I3: =Itki!AN66 -> -10.474123 | J3: =Itki!AO66 -> -6.752621 | K3: 450 | L3: =K3*2/3 -> 300 | M3: =I3*K3+J3*L3 -> -6739.1417 | N3: =M3/G3 -> -0.5665188 | O3: Report till updated 02 July
C4: JH | D4: SP RMC | E4: 2002 | F4: Pali | G4: =Pali!J66 -> 10783.451 | H4: =Pali!AM66 -> -39.4511 | I4: =Pali!AN66 -> 9.2925 | J4: =Pali!AO66 -> 5.1727 | K4: 450 | L4: =K4*2/3 -> 300 | M4: =I4*K4+J4*L4 -> 5733.435 | N4: =M4/G4 -> 0.53168832 | O4: Report till updated 02 July
C5: JH | D5: SP RMC | E5: 2003 | F5: Hisri Thakurgaon | G5: =Hisri!J66 -> 2489.51 | H5: =Hisri!AM66 -> 19.23 | I5: =Hisri!AN66 -> -0.977765 | J5: =Hisri!AO66 -> -3.800707 | K5: 450 | L5: =K5*2/3 -> 300 | M5: =I5*K5+J5*L5 -> -1580.2063 | N5: =M5/G5 -> -0.63474593 | O5: Report till updated 02 July
C6: JH | D6: SP RMC | E6: 2004 | F6: Choreya | G6: =Choriya!J66 -> 2522.0271 | H6: =Choriya!AM66 -> 35.6829 | I6: =Choriya!AN66 -> 4.167807 | J6: =Choriya!AO66 -> -7.857125 | K6: 450 | L6: =K6*2/3 -> 300 | M6: =I6*K6+J6*L6 -> -481.62435 | N6: =M6/G6 -> -0.19096716 | O6: Report till updated 30 June
C7: JH | D7: SP RMC | E7: 2005 | F7: Baski | G7: =Baski!J66 -> 0 | H7: =Baski!AM66 -> 0 | I7: =Baski!AN66 -> 0 | J7: =Baski!AO66 -> 0 | K7: 450 | L7: =K7*2/3 -> 300 | M7: =I7*K7+J7*L7 -> 0 | N7: =M7/G7 -> #DIV/0!
C8: JH | D8: SP RMC | E8: 2006 | F8: Ormanjhi Rmc | G8: =Orja!J66 -> 4170.161 | H8: =Orja!AM66 -> -35.161 | I8: =Orja!AN66 -> 1.9259 | J8: =Orja!AO66 -> -1.9592 | K8: 450 | L8: =K8*2/3 -> 300 | M8: =I8*K8+J8*L8 -> 278.895 | N8: =M8/G8 -> 0.066878713 | O8: Report till updated 30 June
C9: JH | D9: SP RMC | E9: 2007 | F9: Piragutu Rmc | G9: =Piragutu!J66 -> 2880.0345 | H9: =Piragutu!AM66 -> 14.5255 | I9: =Piragutu!AN66 -> -3.091464 | J9: =Piragutu!AO66 -> -6.680692 | K9: 450 | L9: =K9*2/3 -> 300 | M9: =I9*K9+J9*L9 -> -3395.3664 | N9: =M9/G9 -> -1.1789325 | O9: Report till updated 02 July
C10: JH | D10: SP RMC | E10: 2008 | F10: Bhandra Rmc | G10: =Bhandra!J66 -> 4936.2956 | H10: =Bhandra!AM66 -> -119.2956 | I10: =Bhandra!AN66 -> 1.8003 | J10: =Bhandra!AO66 -> -3.7692 | K10: 450 | L10: =K10*2/3 -> 300 | M10: =I10*K10+J10*L10 -> -320.625 | N10: =M10/G10 -> -0.064952553 | O10: Report till updated 30 June
C11: JH | D11: SP RMC | E11: 2009 | F11: Chanho | G11: =Chanho!J66 -> 4716.3082 | H11: =Chanho!AM66 -> 16.6918 | I11: =Chanho!AN66 -> 2.4742 | J11: =Chanho!AO66 -> -3.4048 | K11: 450 | L11: =K11*2/3 -> 300 | M11: =I11*K11+J11*L11 -> 91.95 | N11: =M11/G11 -> 0.019496181 | O11: Report till updated 02 July
C12: Jharkhand Total | G12: =SUM(G3:G10) -> 39677.186 | H12: =SUM(H3:H10) -> -152.4662 | I12: =SUM(I3:I10) -> 2.643155 | J12: =SUM(J3:J10) -> -25.646845 | K12: =SUM(K3:K9) -> 3150 | L12: =SUM(L3:L9) -> 2100 | M12: =SUM(M3:M10) -> -6504.6337 | N12: =M12/G12 -> -0.16393889

Sheet July 26
H2: RMC wise Dispatch | M2: RMC wise Receipt | R2: Tanker Receipt at Plant | W2: Chemist Name | Y2: Round Off
A3: Challan No | B3: Tanker No. | C3: Chamber | D3: Date | E3: Type | F3: RMC Code | G3: RMC Name | H3: Vol-Kg | I3: FAT% | J3: SNF% | K3: FAT Kg | L3: SNF Kg | M3: Vol-Kg | N3: FAT% | O3: SNF% | P3: FAT Kg | Q3: SNF Kg | R3: Vol-Kg | S3: FAT% | T3: SNF% | U3: FAT Kg | V3: SNF Kg | Y3: Vol | Z3: Fat% | AA3: Snf%
A4: 80119 | B4: 1023 | C4: Single | D4: 46204 | F4: 2003 | G4: =VLOOKUP(F4,$AD$9:$AE$17,2,0) -> Hisri | H4: 2048 | I4: 3.8 | J4: 8.29 | K4: =H4*I4% -> 77.824 | L4: =H4*J4% -> 169.7792 | M4: =$R$4*H4/SUM($H$4:$H$7) -> 2045.652 | N4: =P4/M4*100 -> 3.7449898 | O4: =Q4/M4*100 -> 8.213686 | P4: =$U$4*K4/SUM($K$4:$K$7) -> 76.60946 | Q4: =$V$4*L4/SUM($L$4:$L$7) -> 168.02344 | R4: 6970 | S4: 4 | T4: 8.33 | U4: =R4*S4% -> 278.8 | V4: =R4*T4% -> 580.601 | Y4: =ROUND(M4,0) -> 2046 | Z4: =ROUND(N4,2) -> 3.74 | AA4: =ROUND(O4,2) -> 8.21
A5: 80119 | B5: 1023 | C5: Single | D5: 46204 | F5: 2007 | G5: =VLOOKUP(F5,$AD$9:$AE$17,2,0) -> Piragutu | H5: 1496 | I5: 4.4 | J5: 8.41 | K5: =H5*I5% -> 65.824 | L5: =H5*J5% -> 125.8136 | M5: =$R$4*H5/SUM($H$4:$H$7) -> 1494.2849 | N5: =P5/M5*100 -> 4.3363039 | O5: =Q5/M5*100 -> 8.3325813 | P5: =$U$4*K5/SUM($K$4:$K$7) -> 64.796735 | Q5: =$V$4*L5/SUM($L$4:$L$7) -> 124.5125 | Y5: =ROUND(M5,0) -> 1494 | Z5: =ROUND(N5,2) -> 4.34 | AA5: =ROUND(O5,2) -> 8.33
A6: 80119 | B6: 1023 | C6: Single | D6: 46204 | F6: 2009 | G6: =VLOOKUP(F6,$AD$9:$AE$17,2,0) -> Chanho | H6: 2270 | I6: 4.2 | J6: 8.5 | K6: =H6*I6% -> 95.34 | L6: =H6*J6% -> 192.95 | M6: =$R$4*H6/SUM($H$4:$H$7) -> 2267.3975 | N6: =P6/M6*100 -> 4.1391992 | O6: =Q6/M6*100 -> 8.4217528 | P6: =$U$4*K6/SUM($K$4:$K$7) -> 93.852101 | Q6: =$V$4*L6/SUM($L$4:$L$7) -> 190.95462 | Y6: =ROUND(M6,0) -> 2267 | Z6: =ROUND(N6,2) -> 4.14 | AA6: =ROUND(O6,2) -> 8.42
A7: 80119 | B7: 1023 | C7: Single | D7: 46204 | F7: 2006 | G7: =VLOOKUP(F7,$AD$9:$AE$17,2,0) -> Ormanjhi | H7: 1164 | I7: 3.8 | J7: 8.43 | K7: =H7*I7% -> 44.232 | L7: =H7*J7% -> 98.1252 | M7: =$R$4*H7/SUM($H$4:$H$7) -> 1162.6655 | N7: =P7/M7*100 -> 3.7449898 | O7: =Q7/M7*100 -> 8.3523972 | P7: =$U$4*K7/SUM($K$4:$K$7) -> 43.541705 | Q7: =$V$4*L7/SUM($L$4:$L$7) -> 97.110443 | Y7: =ROUND(M7,0) -> 1163 | Z7: =ROUND(N7,2) -> 3.74 | AA7: =ROUND(O7,2) -> 8.35
A8: 80096 | B8: 9944 | C8: Single | D8: 46205 | F8: 2009 | G8: =VLOOKUP(F8,$AD$9:$AE$17,2,0) -> Chanho | H8: 2260 | I8: 4.2 | J8: 8.37 | K8: =H8*I8% -> 94.92 | L8: =H8*J8% -> 189.162 | M8: =$R$8*H8/SUM($H$8:$H$10) -> 2285.4434 | N8: =P8/M8*100 -> 4.0708707 | O8: =Q8/M8*100 -> 8.1687486 | P8: =$U$8*K8/SUM($K$8:$K$10) -> 93.037445 | Q8: =$V$8*L8/SUM($L$8:$L$10) -> 186.69213 | R8: 5120 | S8: 4 | T8: 8.14 | U8: =R8*S8% -> 204.8 | V8: =R8*T8% -> 416.768 | W8: Amit Kr. Singh | Y8: =ROUND(M8,0) -> 2285 | Z8: =ROUND(N8,2) -> 4.07 | AA8: =ROUND(O8,2) -> 8.17
A9: 80096 | B9: 9944 | C9: Single | D9: 46205 | F9: 2003 | G9: =VLOOKUP(F9,$AD$9:$AE$17,2,0) -> Hisri | H9: 1301 | I9: 3.8 | J9: 8.29 | K9: =H9*I9% -> 49.438 | L9: =H9*J9% -> 107.8529 | M9: =$R$8*H9/SUM($H$8:$H$10) -> 1315.6468 | N9: =P9/M9*100 -> 3.6831687 | O9: =Q9/M9*100 -> 8.0906721 | P9: =$U$8*K9/SUM($K$8:$K$10) -> 48.457493 | Q9: =$V$8*L9/SUM($L$8:$L$10) -> 106.44467 | Y9: =ROUND(M9,0) -> 1316 | Z9: =ROUND(N9,2) -> 3.68 | AA9: =ROUND(O9,2) -> 8.09 | AD9: 2001 | AE9: Itki
A10: 80096 | B10: 9944 | C10: Single | D10: 46205 | F10: 2007 | G10: =VLOOKUP(F10,$AD$9:$AE$17,2,0) -> Piragutu | H10: 1502 | I10: 4.3 | J10: 8.34 | K10: =H10*I10% -> 64.586 | L10: =H10*J10% -> 125.2668 | M10: =$R$8*H10/SUM($H$8:$H$10) -> 1518.9097 | N10: =P10/M10*100 -> 4.1677962 | O10: =Q10/M10*100 -> 8.1394699 | P10: =$U$8*K10/SUM($K$8:$K$10) -> 63.305062 | Q10: =$V$8*L10/SUM($L$8:$L$10) -> 123.6312 | Y10: =ROUND(M10,0) -> 1519 | Z10: =ROUND(N10,2) -> 4.17 | AA10: =ROUND(O10,2) -> 8.14 | AD10: 2002 | AE10: Pali
A11: 80149 | B11: 9944 | C11: Single | D11: 46204 | F11: 2001 | G11: =VLOOKUP(F11,$AD$9:$AE$17,2,0) -> Itki | H11: 4202 | I11: 3.95 | J11: 8.51 | K11: =H11*I11% -> 165.979 | L11: =H11*J11% -> 357.5902 | M11: =$R$11*H11/SUM($H$11:$H$12) -> 4201.1042 | N11: =P11/M11*100 -> 3.9225855 | O11: =Q11/M11*100 -> 8.4775006 | P11: =$U$11*K11/SUM($K$11:$K$12) -> 164.79191 | Q11: =$V$11*L11/SUM($L$11:$L$12) -> 356.14864 | R11: 9380 | S11: 3.95 | T11: 8.45 | U11: =R11*S11% -> 370.51 | V11: =R11*T11% -> 792.61 | W11: Mahesh | Y11: =ROUND(M11,0) -> 4201 | Z11: =ROUND(N11,2) -> 3.92 | AA11: =ROUND(O11,2) -> 8.48 | AD11: 2003 | AE11: Hisri
A12: 80149 | B12: 9944 | C12: Single | D12: 46204 | F12: 2002 | G12: =VLOOKUP(F12,$AD$9:$AE$17,2,0) -> Pali | H12: 5180 | I12: 4 | J12: 8.46 | K12: =H12*I12% -> 207.2 | L12: =H12*J12% -> 438.228 | M12: =$R$11*H12/SUM($H$11:$H$12) -> 5178.8958 | N12: =P12/M12*100 -> 3.9722385 | O12: =Q12/M12*100 -> 8.4276916 | P12: =$U$11*K12/SUM($K$11:$K$12) -> 205.71809 | Q12: =$V$11*L12/SUM($L$11:$L$12) -> 436.46136 | Y12: =ROUND(M12,0) -> 5179 | Z12: =ROUND(N12,2) -> 3.97 | AA12: =ROUND(O12,2) -> 8.43 | AD12: 2004 | AE12: Chorya
A13: 80150 | B13: 8504 | C13: Single | D13: 46205 | F13: 2001 | G13: =VLOOKUP(F13,$AD$9:$AE$17,2,0) -> Itki | H13: 4540 | I13: 3.9 | J13: 8.56 | K13: =H13*I13% -> 177.06 | L13: =H13*J13% -> 388.624 | M13: =$R$13*H13/SUM($H$13) -> 4510 | N13: =P13/M13*100 -> 3.7 | O13: =Q13/M13*100 -> 8.34 | P13: =$U$13*K13/SUM($K$13) -> 166.87 | Q13: =$V$13*L13/SUM($L$13) -> 376.134 | R13: 4510 | S13: 3.7 | T13: 8.34 | U13: =R13*S13% -> 166.87 | V13: =R13*T13% -> 376.134 | W13: Mahesh | Y13: =ROUND(M13,0) -> 4510 | Z13: =ROUND(N13,2) -> 3.7 | AA13: =ROUND(O13,2) -> 8.34 | AD13: 2005 | AE13: Baski2
A14: 80120 | B14: 1023 | C14: Single | D14: 46205 | F14: 2004 | G14: =VLOOKUP(F14,$AD$9:$AE$17,2,0) -> Chorya | H14: 2195 | I14: 3.35 | J14: 7.85 | K14: =H14*I14% -> 73.5325 | L14: =H14*J14% -> 172.3075 | M14: =$R$14*H14/SUM($H$14:$H$16) -> 2195 | N14: =P14/M14*100 -> 3.3570069 | O14: =Q14/M14*100 -> 7.9007021 | P14: =$U$14*K14/SUM($K$14:$K$16) -> 73.6863 | Q14: =$V$14*L14/SUM($L$14:$L$16) -> 173.42041 | R14: 8630 | S14: 3.9 | T14: 8.37 | U14: =R14*S14% -> 336.57 | V14: =R14*T14% -> 722.331 | W14: Deepak | Y14: =ROUND(M14,0) -> 2195 | Z14: =ROUND(N14,2) -> 3.36 | AA14: =ROUND(O14,2) -> 7.9 | AD14: 2006 | AE14: Ormanjhi
A15: 80120 | B15: 1023 | C15: Single | D15: 46205 | F15: 2002 | G15: =VLOOKUP(F15,$AD$9:$AE$17,2,0) -> Pali | H15: 5290 | I15: 4.05 | J15: 8.47 | K15: =H15*I15% -> 214.245 | L15: =H15*J15% -> 448.063 | M15: =$R$14*H15/SUM($H$14:$H$16) -> 5290 | N15: =P15/M15*100 -> 4.058471 | O15: =Q15/M15*100 -> 8.5247066 | P15: =$U$14*K15/SUM($K$14:$K$16) -> 214.69311 | Q15: =$V$14*L15/SUM($L$14:$L$16) -> 450.95698 | Y15: =ROUND(M15,0) -> 5290 | Z15: =ROUND(N15,2) -> 4.06 | AA15: =ROUND(O15,2) -> 8.52 | AD15: 2007 | AE15: Piragutu
A16: 80120 | B16: 1023 | C16: Single | D16: 46205 | F16: 2006 | G16: =VLOOKUP(F16,$AD$9:$AE$17,2,0) -> Ormanjhi | H16: 1145 | I16: 4.2 | J16: 8.5 | K16: =H16*I16% -> 48.09 | L16: =H16*J16% -> 97.325 | M16: =$R$14*H16/SUM($H$14:$H$16) -> 1145 | N16: =P16/M16*100 -> 4.2087847 | O16: =Q16/M16*100 -> 8.5549004 | P16: =$U$14*K16/SUM($K$14:$K$16) -> 48.190585 | Q16: =$V$14*L16/SUM($L$14:$L$16) -> 97.953609 | Y16: =ROUND(M16,0) -> 1145 | Z16: =ROUND(N16,2) -> 4.21 | AA16: =ROUND(O16,2) -> 8.55 | AD16: 2008 | AE16: Bhandra
G17: =VLOOKUP(F17,$AD$9:$AE$17,2,0) -> #N/A | K17: =H17*I17% -> 0 | L17: =H17*J17% -> 0 | M17: =$R$16*H17/SUM($H$16:$H$17) -> 0 | N17: =P17/M17*100 -> #DIV/0! | O17: =Q17/M17*100 -> #DIV/0! | P17: =$U$16*K17/SUM($K$16:$K$17) -> 0 | Q17: =$V$16*L17/SUM($L$16:$L$17) -> 0 | Y17: =ROUND(M17,0) -> 0 | Z17: =ROUND(N17,2) -> #DIV/0! | AA17: =ROUND(O17,2) -> #DIV/0! | AD17: 2009 | AE17: Chanho
G18: =VLOOKUP(F18,$AD$9:$AE$17,2,0) -> #N/A | K18: =H18*I18% -> 0 | L18: =H18*J18% -> 0 | M18: =$R$4*H18/SUM($H$4:$H$7) -> 0 | N18: =P18/M18*100 -> #DIV/0! | O18: =Q18/M18*100 -> #DIV/0! | P18: =$U$4*K18/SUM($K$4:$K$7) -> 0 | Q18: =$V$4*L18/SUM($L$4:$L$7) -> 0 | Y18: =ROUND(M18,0) -> 0 | Z18: =ROUND(N18,2) -> #DIV/0! | AA18: =ROUND(O18,2) -> #DIV/0!
G19: =VLOOKUP(F19,$AD$9:$AE$17,2,0) -> #N/A | K19: =H19*I19% -> 0 | L19: =H19*J19% -> 0 | M19: =$R$4*H19/SUM($H$4:$H$7) -> 0 | N19: =P19/M19*100 -> #DIV/0! | O19: =Q19/M19*100 -> #DIV/0! | P19: =$U$4*K19/SUM($K$4:$K$7) -> 0 | Q19: =$V$4*L19/SUM($L$4:$L$7) -> 0 | Y19: =ROUND(M19,0) -> 0 | Z19: =ROUND(N19,2) -> #DIV/0! | AA19: =ROUND(O19,2) -> #DIV/0!
G20: =VLOOKUP(F20,$AD$9:$AE$17,2,0) -> #N/A | K20: =H20*I20% -> 0 | L20: =H20*J20% -> 0 | M20: =$R$4*H20/SUM($H$4:$H$7) -> 0 | N20: =P20/M20*100 -> #DIV/0! | O20: =Q20/M20*100 -> #DIV/0! | P20: =$U$4*K20/SUM($K$4:$K$7) -> 0 | Q20: =$V$4*L20/SUM($L$4:$L$7) -> 0 | Y20: =ROUND(M20,0) -> 0 | Z20: =ROUND(N20,2) -> #DIV/0! | AA20: =ROUND(O20,2) -> #DIV/0!
G21: =VLOOKUP(F21,$AD$9:$AE$17,2,0) -> #N/A | K21: =H21*I21% -> 0 | L21: =H21*J21% -> 0 | M21: =$R$4*H21/SUM($H$4:$H$7) -> 0 | N21: =P21/M21*100 -> #DIV/0! | O21: =Q21/M21*100 -> #DIV/0! | P21: =$U$4*K21/SUM($K$4:$K$7) -> 0 | Q21: =$V$4*L21/SUM($L$4:$L$7) -> 0 | Y21: =ROUND(M21,0) -> 0 | Z21: =ROUND(N21,2) -> #DIV/0! | AA21: =ROUND(O21,2) -> #DIV/0!
G22: =VLOOKUP(F22,$AD$9:$AE$17,2,0) -> #N/A | K22: =H22*I22% -> 0 | L22: =H22*J22% -> 0 | M22: =$R$4*H22/SUM($H$4:$H$7) -> 0 | N22: =P22/M22*100 -> #DIV/0! | O22: =Q22/M22*100 -> #DIV/0! | P22: =$U$4*K22/SUM($K$4:$K$7) -> 0 | Q22: =$V$4*L22/SUM($L$4:$L$7) -> 0 | Y22: =ROUND(M22,0) -> 0 | Z22: =ROUND(N22,2) -> #DIV/0! | AA22: =ROUND(O22,2) -> #DIV/0!
G23: =VLOOKUP(F23,$AD$9:$AE$17,2,0) -> #N/A | K23: =H23*I23% -> 0 | L23: =H23*J23% -> 0 | M23: =$R$4*H23/SUM($H$4:$H$7) -> 0 | N23: =P23/M23*100 -> #DIV/0! | O23: =Q23/M23*100 -> #DIV/0! | P23: =$U$4*K23/SUM($K$4:$K$7) -> 0 | Q23: =$V$4*L23/SUM($L$4:$L$7) -> 0 | Y23: =ROUND(M23,0) -> 0 | Z23: =ROUND(N23,2) -> #DIV/0! | AA23: =ROUND(O23,2) -> #DIV/0!
G24: =VLOOKUP(F24,$AD$9:$AE$17,2,0) -> #N/A | K24: =H24*I24% -> 0 | L24: =H24*J24% -> 0 | M24: =$R$4*H24/SUM($H$4:$H$7) -> 0 | N24: =P24/M24*100 -> #DIV/0! | O24: =Q24/M24*100 -> #DIV/0! | P24: =$U$4*K24/SUM($K$4:$K$7) -> 0 | Q24: =$V$4*L24/SUM($L$4:$L$7) -> 0 | Y24: =ROUND(M24,0) -> 0 | Z24: =ROUND(N24,2) -> #DIV/0! | AA24: =ROUND(O24,2) -> #DIV/0!
G25: =VLOOKUP(F25,$AD$9:$AE$17,2,0) -> #N/A | K25: =H25*I25% -> 0 | L25: =H25*J25% -> 0 | M25: =$R$4*H25/SUM($H$4:$H$7) -> 0 | N25: =P25/M25*100 -> #DIV/0! | O25: =Q25/M25*100 -> #DIV/0! | P25: =$U$4*K25/SUM($K$4:$K$7) -> 0 | Q25: =$V$4*L25/SUM($L$4:$L$7) -> 0 | Y25: =ROUND(M25,0) -> 0 | Z25: =ROUND(N25,2) -> #DIV/0! | AA25: =ROUND(O25,2) -> #DIV/0!
G26: =VLOOKUP(F26,$AD$9:$AE$17,2,0) -> #N/A | K26: =H26*I26% -> 0 | L26: =H26*J26% -> 0 | M26: =$R$4*H26/SUM($H$4:$H$7) -> 0 | N26: =P26/M26*100 -> #DIV/0! | O26: =Q26/M26*100 -> #DIV/0! | P26: =$U$4*K26/SUM($K$4:$K$7) -> 0 | Q26: =$V$4*L26/SUM($L$4:$L$7) -> 0 | Y26: =ROUND(M26,0) -> 0 | Z26: =ROUND(N26,2) -> #DIV/0! | AA26: =ROUND(O26,2) -> #DIV/0!
G27: =VLOOKUP(F27,$AD$9:$AE$17,2,0) -> #N/A | K27: =H27*I27% -> 0 | L27: =H27*J27% -> 0 | M27: =$R$4*H27/SUM($H$4:$H$7) -> 0 | N27: =P27/M27*100 -> #DIV/0! | O27: =Q27/M27*100 -> #DIV/0! | P27: =$U$4*K27/SUM($K$4:$K$7) -> 0 | Q27: =$V$4*L27/SUM($L$4:$L$7) -> 0 | Y27: =ROUND(M27,0) -> 0 | Z27: =ROUND(N27,2) -> #DIV/0! | AA27: =ROUND(O27,2) -> #DIV/0!
G28: =VLOOKUP(F28,$AD$9:$AE$17,2,0) -> #N/A | K28: =H28*I28% -> 0 | L28: =H28*J28% -> 0 | M28: =$R$4*H28/SUM($H$4:$H$7) -> 0 | N28: =P28/M28*100 -> #DIV/0! | O28: =Q28/M28*100 -> #DIV/0! | P28: =$U$4*K28/SUM($K$4:$K$7) -> 0 | Q28: =$V$4*L28/SUM($L$4:$L$7) -> 0 | Y28: =ROUND(M28,0) -> 0 | Z28: =ROUND(N28,2) -> #DIV/0! | AA28: =ROUND(O28,2) -> #DIV/0!
G29: =VLOOKUP(F29,$AD$9:$AE$17,2,0) -> #N/A | K29: =H29*I29% -> 0 | L29: =H29*J29% -> 0 | M29: =$R$4*H29/SUM($H$4:$H$7) -> 0 | N29: =P29/M29*100 -> #DIV/0! | O29: =Q29/M29*100 -> #DIV/0! | P29: =$U$4*K29/SUM($K$4:$K$7) -> 0 | Q29: =$V$4*L29/SUM($L$4:$L$7) -> 0 | Y29: =ROUND(M29,0) -> 0 | Z29: =ROUND(N29,2) -> #DIV/0! | AA29: =ROUND(O29,2) -> #DIV/0!
... G122: =VLOOKUP(F122,$AD$9:$AE$17,2,0) -> #N/A | K122: =H122*I122% -> 0 | L122: =H122*J122% -> 0 | M122: =$R$4*H122/SUM($H$4:$H$7) -> 0 | N122: =P122/M122*100 -> #DIV/0! | O122: =Q122/M122*100 -> #DIV/0! | P122: =$U$4*K122/SUM($K$4:$K$7) -> 0 | Q122: =$V$4*L122/SUM($L$4:$L$7) -> 0 | Y122: =ROUND(M122,0) -> 0 | Z122: =ROUND(N122,2) -> #DIV/0! | AA122: =ROUND(O122,2) -> #DIV/0!

Sheet Nov 25
H2: RMC wise Dispatch | M2: RMC wise Receipt | R2: Tanker Receipt at Plant | X2: Round Off
A3: Challan No | B3: Tanker No. | C3: Chamber | D3: Date | E3: Type | F3: RMC Code | G3: RMC Name | H3: Vol-Kg | I3: FAT% | J3: SNF% | K3: FAT Kg | L3: SNF Kg | M3: Vol-Kg | N3: FAT% | O3: SNF% | P3: FAT Kg | Q3: SNF Kg | R3: Vol-Kg | S3: FAT% | T3: SNF% | U3: FAT Kg | V3: SNF Kg | X3: Vol | Y3: Fat% | Z3: Snf%
A4: 72438 | B4: 9944 | C4: Single | D4: 45962 | F4: 2009 | G4: =VLOOKUP(F4,$AC$11:$AD$19,2,0) -> Chanho | H4: 2890 | I4: 4.15 | J4: 8.3 | K4: =H4*I4% -> 119.935 | L4: =H4*J4% -> 239.87 | M4: =$R$4*H4/SUM($H$4:$H$5) -> 2918.7849 | N4: =P4/M4*100 -> 4.1713242 | O4: =Q4/M4*100 -> 8.338686 | P4: =$U$4*K4/SUM($K$4:$K$5) -> 121.75198 | Q4: =$V$4*L4/SUM($L$4:$L$5) -> 243.3883 | R4: 5070 | S4: 4.15 | T4: 8.36 | U4: =R4*S4% -> 210.405 | V4: =R4*T4% -> 423.852 | X4: =ROUND(M4,0) -> 2919 | Y4: =ROUND(N4,2) -> 4.17 | Z4: =ROUND(O4,2) -> 8.34
A5: 72438 | B5: 9944 | C5: Single | D5: 45962 | F5: 2006 | G5: =VLOOKUP(F5,$AC$11:$AD$19,2,0) -> Ormanjhi | H5: 2130 | I5: 4.1 | J5: 8.35 | K5: =H5*I5% -> 87.33 | L5: =H5*J5% -> 177.855 | M5: =$R$4*H5/SUM($H$4:$H$5) -> 2151.2151 | N5: =P5/M5*100 -> 4.1210672 | O5: =Q5/M5*100 -> 8.388919 | P5: =$U$4*K5/SUM($K$4:$K$5) -> 88.653022 | Q5: =$V$4*L5/SUM($L$4:$L$5) -> 180.4637 | X5: =ROUND(M5,0) -> 2151 | Y5: =ROUND(N5,2) -> 4.12 | Z5: =ROUND(O5,2) -> 8.39
A6: 72230 | B6: 1023 | C6: Rear | D6: 45962 | F6: 2003 | G6: =VLOOKUP(F6,$AC$11:$AD$19,2,0) -> Hisri | H6: 1064 | I6: 4.1 | J6: 8.23 | K6: =H6*I6% -> 43.624 | L6: =H6*J6% -> 87.5672 | M6: =$R$6*H6/SUM($H$6:$H$7) -> 1057.1521 | N6: =P6/M6*100 -> 3.8393099 | O6: =Q6/M6*100 -> 8.0759971 | P6: =$U$6*K6/SUM($K$6:$K$7) -> 40.587344 | Q6: =$V$6*L6/SUM($L$6:$L$7) -> 85.375569 | R6: 2470 | S6: 4 | T6: 8.25 | U6: =R6*S6% -> 98.8 | V6: =R6*T6% -> 203.775 | X6: =ROUND(M6,0) -> 1057 | Y6: =ROUND(N6,2) -> 3.84 | Z6: =ROUND(O6,2) -> 8.08
A7: 72230 | B7: 1023 | C7: Rear | D7: 45962 | F7: 2007 | G7: =VLOOKUP(F7,$AC$11:$AD$19,2,0) -> Piragutu | H7: 1422 | I7: 4.4 | J7: 8.54 | K7: =H7*I7% -> 62.568 | L7: =H7*J7% -> 121.4388 | M7: =$R$6*H7/SUM($H$6:$H$7) -> 1412.8479 | N7: =P7/M7*100 -> 4.120235 | O7: =Q7/M7*100 -> 8.3801963 | P7: =$U$6*K7/SUM($K$6:$K$7) -> 58.212656 | Q7: =$V$6*L7/SUM($L$6:$L$7) -> 118.39943 | X7: =ROUND(M7,0) -> 1413 | Y7: =ROUND(N7,2) -> 4.12 | Z7: =ROUND(O7,2) -> 8.38
A8: 72230 | B8: 1023 | C8: Front | D8: 45962 | F8: 2002 | G8: =VLOOKUP(F8,$AC$11:$AD$19,2,0) -> Pali | H8: 3190 | I8: 4.1 | J8: 8.35 | K8: =H8*I8% -> 130.79 | L8: =H8*J8% -> 266.365 | M8: =$R$8*H8/SUM($H$8) -> 3090 | N8: =P8/M8*100 -> 4.2 | O8: =Q8/M8*100 -> 8.21 | P8: =$U$8*K8/SUM($K$8) -> 129.78 | Q8: =$V$8*L8/SUM($L$8) -> 253.689 | R8: 3090 | S8: 4.2 | T8: 8.21 | U8: =R8*S8% -> 129.78 | V8: =R8*T8% -> 253.689 | X8: =ROUND(M8,0) -> 3090 | Y8: =ROUND(N8,2) -> 4.2 | Z8: =ROUND(O8,2) -> 8.21
A9: 72190 | B9: 1023 | C9: Rear | D9: 45963 | F9: 2004 | G9: =VLOOKUP(F9,$AC$11:$AD$19,2,0) -> Chorya | H9: 1526 | I9: 3.45 | J9: 8.03 | K9: =H9*I9% -> 52.647 | L9: =H9*J9% -> 122.5378 | M9: =$R$9*H9/SUM($H$9:$H$10) -> 1542.9026 | N9: =P9/M9*100 -> 3.4334739 | O9: =Q9/M9*100 -> 8.0482752 | P9: =$U$9*K9/SUM($K$9:$K$10) -> 52.975158 | Q9: =$V$9*L9/SUM($L$9:$L$10) -> 124.17705 | R9: 3560 | S9: 3.8 | T9: 8.23 | U9: =R9*S9% -> 135.28 | V9: =R9*T9% -> 292.988 | X9: =ROUND(M9,0) -> 1543 | Y9: =ROUND(N9,2) -> 3.43 | Z9: =ROUND(O9,2) -> 8.05
A10: 72190 | B10: 1023 | C10: Rear | D10: 45963 | F10: 2006 | G10: =VLOOKUP(F10,$AC$11:$AD$19,2,0) -> Ormanjhi | H10: 1995 | I10: 4.1 | J10: 8.35 | K10: =H10*I10% -> 81.795 | L10: =H10*J10% -> 166.5825 | M10: =$R$9*H10/SUM($H$9:$H$10) -> 2017.0974 | N10: =P10/M10*100 -> 4.0803603 | O10: =Q10/M10*100 -> 8.3690035 | P10: =$U$9*K10/SUM($K$9:$K$10) -> 82.304842 | Q10: =$V$9*L10/SUM($L$9:$L$10) -> 168.81095 | X10: =ROUND(M10,0) -> 2017 | Y10: =ROUND(N10,2) -> 4.08 | Z10: =ROUND(O10,2) -> 8.37
A11: 72190 | B11: 1023 | C11: Front | D11: 45963 | F11: 2002 | G11: =VLOOKUP(F11,$AC$11:$AD$19,2,0) -> Pali | H11: 3170 | I11: 4.2 | J11: 8.37 | K11: =H11*I11% -> 133.14 | L11: =H11*J11% -> 265.329 | M11: =$R$11*H11/SUM($H$11) -> 3080 | N11: =P11/M11*100 -> 4.15 | O11: =Q11/M11*100 -> 8.11 | P11: =$U$11*K11/SUM($K$11) -> 127.82 | Q11: =$V$11*L11/SUM($L$11) -> 249.788 | R11: 3080 | S11: 4.15 | T11: 8.11 | U11: =R11*S11% -> 127.82 | V11: =R11*T11% -> 249.788 | X11: =ROUND(M11,0) -> 3080 | Y11: =ROUND(N11,2) -> 4.15 | Z11: =ROUND(O11,2) -> 8.11 | AC11: 2001 | AD11: Itki
A12: 72333 | B12: 1846 | C12: Single | D12: 45963 | F12: 2009 | G12: =VLOOKUP(F12,$AC$11:$AD$19,2,0) -> Chanho | H12: 1691 | I12: 4.35 | J12: 8.46 | K12: =H12*I12% -> 73.5585 | L12: =H12*J12% -> 143.0586 | M12: =$R$12*H12/SUM($H$12:$H$14) -> 1691.3879 | N12: =P12/M12*100 -> 4.3461364 | O12: =Q12/M12*100 -> 8.4034918 | P12: =$U$12*K12/SUM($K$12:$K$14) -> 73.510027 | Q12: =$V$12*L12/SUM($L$12:$L$14) -> 142.13565 | R12: 4360 | S12: 4.4 | T12: 8.41 | U12: =R12*S12% -> 191.84 | V12: =R12*T12% -> 366.676 | X12: =ROUND(M12,0) -> 1691 | Y12: =ROUND(N12,2) -> 4.35 | Z12: =ROUND(O12,2) -> 8.4 | AC12: 2002 | AD12: Pali
A13: 72333 | B13: 1846 | C13: Single | D13: 45963 | F13: 2007 | G13: =VLOOKUP(F13,$AC$11:$AD$19,2,0) -> Piragutu | H13: 1588 | I13: 4.6 | J13: 8.58 | K13: =H13*I13% -> 73.048 | L13: =H13*J13% -> 136.2504 | M13: =$R$12*H13/SUM($H$12:$H$14) -> 1588.3643 | N13: =P13/M13*100 -> 4.5959144 | O13: =Q13/M13*100 -> 8.5226903 | P13: =$U$12*K13/SUM($K$12:$K$14) -> 72.999864 | Q13: =$V$12*L13/SUM($L$12:$L$14) -> 135.37137 | X13: =ROUND(M13,0) -> 1588 | Y13: =ROUND(N13,2) -> 4.6 | Z13: =ROUND(O13,2) -> 8.52 | AC13: 2003 | AD13: Hisri
A14: 72333 | B14: 1846 | C14: Single | D14: 45963 | F14: 2003 | G14: =VLOOKUP(F14,$AC$11:$AD$19,2,0) -> Hisri | H14: 1080 | I14: 4.2 | J14: 8.31 | K14: =H14*I14% -> 45.36 | L14: =H14*J14% -> 89.748 | M14: =$R$12*H14/SUM($H$12:$H$14) -> 1080.2478 | N14: =P14/M14*100 -> 4.1962697 | O14: =Q14/M14*100 -> 8.2544937 | P14: =$U$12*K14/SUM($K$12:$K$14) -> 45.330109 | Q14: =$V$12*L14/SUM($L$12:$L$14) -> 89.168984 | X14: =ROUND(M14,0) -> 1080 | Y14: =ROUND(N14,2) -> 4.2 | Z14: =ROUND(O14,2) -> 8.25 | AC14: 2004 | AD14: Chorya
A15: 72192 | B15: 1846 | C15: Single | D15: 45965 | F15: 2007 | G15: =VLOOKUP(F15,$AC$11:$AD$19,2,0) -> Piragutu | H15: 1333.7 | I15: 4.5 | J15: 8.62 | K15: =H15*I15% -> 60.0165 | L15: =H15*J15% -> 114.96494 | M15: =$R$15*H15/SUM($H$15:$H$16) -> 1371.1293 | N15: =P15/M15*100 -> 4.5010093 | O15: =Q15/M15*100 -> 8.5378652 | P15: =$U$15*K15/SUM($K$15:$K$16) -> 61.714656 | Q15: =$V$15*L15/SUM($L$15:$L$16) -> 117.06517 | R15: 3220 | S15: 4.3 | T15: 8.39 | U15: =R15*S15% -> 138.46 | V15: =R15*T15% -> 270.158 | X15: =ROUND(M15,0) -> 1371 | Y15: =ROUND(N15,2) -> 4.5 | Z15: =ROUND(O15,2) -> 8.54 | AC15: 2005 | AD15: Baski2
A16: 72192 | B16: 1846 | C16: Single | D16: 45965 | F16: 2006 | G16: =VLOOKUP(F16,$AC$11:$AD$19,2,0) -> Ormanjhi | H16: 1798.4 | I16: 4.15 | J16: 8.36 | K16: =H16*I16% -> 74.6336 | L16: =H16*J16% -> 150.34624 | M16: =$R$15*H16/SUM($H$15:$H$16) -> 1848.8707 | N16: =P16/M16*100 -> 4.1509308 | O16: =Q16/M16*100 -> 8.2803426 | P16: =$U$15*K16/SUM($K$15:$K$16) -> 76.745344 | Q16: =$V$15*L16/SUM($L$15:$L$16) -> 153.09283 | X16: =ROUND(M16,0) -> 1849 | Y16: =ROUND(N16,2) -> 4.15 | Z16: =ROUND(O16,2) -> 8.28 | AC16: 2006 | AD16: Ormanjhi
A17: 72351 | B17: 9944 | C17: Single | D17: 45964 | F17: 2003 | G17: =VLOOKUP(F17,$AC$11:$AD$19,2,0) -> Hisri | H17: 1091 | I17: 4.15 | J17: 8.24 | K17: =H17*I17% -> 45.2765 | L17: =H17*J17% -> 89.8984 | M17: =$R$17*H17/SUM($H$17:$H$19) -> 1086.947 | N17: =P17/M17*100 -> 4.1393837 | O17: =Q17/M17*100 -> 8.1867713 | P17: =$U$17*K17/SUM($K$17:$K$19) -> 44.992906 | Q17: =$V$17*L17/SUM($L$17:$L$19) -> 88.985863 | R17: 5900 | S17: 4.25 | T17: 8.32 | U17: =R17*S17% -> 250.75 | V17: =R17*T17% -> 490.88 | X17: =ROUND(M17,0) -> 1087 | Y17: =ROUND(N17,2) -> 4.14 | Z17: =ROUND(O17,2) -> 8.19 | AC17: 2007 | AD17: Piragutu
A18: 72351 | B18: 9944 | C18: Single | D18: 45964 | F18: 2007 | G18: =VLOOKUP(F18,$AC$11:$AD$19,2,0) -> Piragutu | H18: 1384 | I18: 4.5 | J18: 8.49 | K18: =H18*I18% -> 62.28 | L18: =H18*J18% -> 117.5016 | M18: =$R$17*H18/SUM($H$17:$H$19) -> 1378.8585 | N18: =P18/M18*100 -> 4.4884883 | O18: =Q18/M18*100 -> 8.4351564 | P18: =$U$17*K18/SUM($K$17:$K$19) -> 61.889902 | Q18: =$V$17*L18/SUM($L$17:$L$19) -> 116.30887 | X18: =ROUND(M18,0) -> 1379 | Y18: =ROUND(N18,2) -> 4.49 | Z18: =ROUND(O18,2) -> 8.44 | AC18: 2008 | AD18: Bhandra
A19: 72351 | B19: 9944 | C19: Single | D19: 45964 | F19: 2002 | G19: =VLOOKUP(F19,$AC$11:$AD$19,2,0) -> Pali | H19: 3447 | I19: 4.2 | J19: 8.37 | K19: =H19*I19% -> 144.774 | L19: =H19*J19% -> 288.5139 | M19: =$R$17*H19/SUM($H$17:$H$19) -> 3434.1945 | N19: =P19/M19*100 -> 4.1892558 | O19: =Q19/M19*100 -> 8.3159316 | P19: =$U$17*K19/SUM($K$17:$K$19) -> 143.86719 | Q19: =$V$17*L19/SUM($L$17:$L$19) -> 285.58527 | X19: =ROUND(M19,0) -> 3434 | Y19: =ROUND(N19,2) -> 4.19 | Z19: =ROUND(O19,2) -> 8.32 | AC19: 2009 | AD19: Chanho
A20: 72353 | B20: 9944 | C20: Single | D20: 45967 | F20: 2003 | G20: =VLOOKUP(F20,$AC$11:$AD$19,2,0) -> Hisri | H20: 1281 | I20: 4.2 | J20: 8.25 | K20: =H20*I20% -> 53.802 | L20: =H20*J20% -> 105.6825 | M20: =$R$20*H20/SUM($H$20:$H$22) -> 1299.8382 | N20: =P20/M20*100 -> 4.1891261 | O20: =Q20/M20*100 -> 8.1256515 | P20: =$U$20*K20/SUM($K$20:$K$22) -> 54.451863 | Q20: =$V$20*L20/SUM($L$20:$L$22) -> 105.62033 | R20: 4140 | S20: 4.25 | T20: 8.26 | U20: =R20*S20% -> 175.95 | V20: =R20*T20% -> 341.964 | X20: =ROUND(M20,0) -> 1300 | Y20: =ROUND(N20,2) -> 4.19 | Z20: =ROUND(O20,2) -> 8.13
A21: 72353 | B21: 9944 | C21: Single | D21: 45967 | F21: 2007 | G21: =VLOOKUP(F21,$AC$11:$AD$19,2,0) -> Piragutu | H21: 1345 | I21: 4.45 | J21: 8.48 | K21: =H21*I21% -> 59.8525 | L21: =H21*J21% -> 114.056 | M21: =$R$20*H21/SUM($H$20:$H$22) -> 1364.7794 | N21: =P21/M21*100 -> 4.4384789 | O21: =Q21/M21*100 -> 8.3521849 | P21: =$U$20*K21/SUM($K$20:$K$22) -> 60.575446 | Q21: =$V$20*L21/SUM($L$20:$L$22) -> 113.9889 | X21: =ROUND(M21,0) -> 1365 | Y21: =ROUND(N21,2) -> 4.44 | Z21: =ROUND(O21,2) -> 8.35
A22: 72353 | B22: 9944 | C22: Single | D22: 45967 | F22: 2006 | G22: =VLOOKUP(F22,$AC$11:$AD$19,2,0) -> Ormanjhi | H22: 1454 | I22: 4.14 | J22: 8.42 | K22: =H22*I22% -> 60.1956 | L22: =H22*J22% -> 122.4268 | M22: =$R$20*H22/SUM($H$20:$H$22) -> 1475.3824 | N22: =P22/M22*100 -> 4.1292815 | O22: =Q22/M22*100 -> 8.2930892 | P22: =$U$20*K22/SUM($K$20:$K$22) -> 60.92269 | Q22: =$V$20*L22/SUM($L$20:$L$22) -> 122.35477 | X22: =ROUND(M22,0) -> 1475 | Y22: =ROUND(N22,2) -> 4.13 | Z22: =ROUND(O22,2) -> 8.29
A23: 72335 | B23: 1023 | C23: Front | D23: 45965 | F23: 2009 | G23: =VLOOKUP(F23,$AC$11:$AD$19,2,0) -> Chanho | H23: 2293 | I23: 4.3 | J23: 8.27 | K23: =H23*I23% -> 98.599 | L23: =H23*J23% -> 189.6311 | M23: =$R$23*H23/SUM($H$23:$H$24) -> 2288.9368 | N23: =P23/M23*100 -> 4.25 | O23: =Q23/M23*100 -> 8.07 | P23: =$U$23*K23/SUM($K$23:$K$24) -> 97.279814 | Q23: =$V$23*L23/SUM($L$23:$L$24) -> 184.7172 | R23: 3380 | S23: 4.25 | T23: 8.07 | U23: =R23*S23% -> 143.65 | V23: =R23*T23% -> 272.766 | X23: =ROUND(M23,0) -> 2289 | Y23: =ROUND(N23,2) -> 4.25 | Z23: =ROUND(O23,2) -> 8.07
A24: 72335 | B24: 1023 | C24: Front | D24: 45965 | F24: 2003 | G24: =VLOOKUP(F24,$AC$11:$AD$19,2,0) -> Hisri | H24: 1093 | I24: 4.3 | J24: 8.27 | K24: =H24*I24% -> 46.999 | L24: =H24*J24% -> 90.3911 | M24: =$R$23*H24/SUM($H$23:$H$24) -> 1091.0632 | N24: =P24/M24*100 -> 4.25 | O24: =Q24/M24*100 -> 8.07 | P24: =$U$23*K24/SUM($K$23:$K$24) -> 46.370186 | Q24: =$V$23*L24/SUM($L$23:$L$24) -> 88.0488 | X24: =ROUND(M24,0) -> 1091 | Y24: =ROUND(N24,2) -> 4.25 | Z24: =ROUND(O24,2) -> 8.07
A25: 72336 | B25: 1846 | C25: Single | D25: 45966 | F25: 2009 | G25: =VLOOKUP(F25,$AC$11:$AD$19,2,0) -> Chanho | H25: 1993 | I25: 4.35 | J25: 8.4 | K25: =H25*I25% -> 86.6955 | L25: =H25*J25% -> 167.412 | M25: =$R$25*H25/SUM($H$25:$H$27) -> 2019.5621 | N25: =P25/M25*100 -> 4.2581499 | O25: =Q25/M25*100 -> 8.1693645 | P25: =$U$25*K25/SUM($K$25:$K$27) -> 85.995981 | Q25: =$V$25*L25/SUM($L$25:$L$27) -> 164.98539 | R25: 4790 | S25: 4.1 | T25: 8.04 | U25: =R25*S25% -> 196.39 | V25: =R25*T25% -> 385.116 | X25: =ROUND(M25,0) -> 2020 | Y25: =ROUND(N25,2) -> 4.26 | Z25: =ROUND(O25,2) -> 8.17
A26: 72336 | B26: 1846 | C26: Single | D26: 45966 | F26: 2004 | G26: =VLOOKUP(F26,$AC$11:$AD$19,2,0) -> Chorya | H26: 1229 | I26: 3.3 | J26: 7.57 | K26: =H26*I26% -> 40.557 | L26: =H26*J26% -> 93.0353 | M26: =$R$25*H26/SUM($H$25:$H$27) -> 1245.3797 | N26: =P26/M26*100 -> 3.2303206 | O26: =Q26/M26*100 -> 7.3621535 | P26: =$U$25*K26/SUM($K$25:$K$27) -> 40.229758 | Q26: =$V$25*L26/SUM($L$25:$L$27) -> 91.686768 | X26: =ROUND(M26,0) -> 1245 | Y26: =ROUND(N26,2) -> 3.23 | Z26: =ROUND(O26,2) -> 7.36
A27: 72336 | B27: 1846 | C27: Single | D27: 45966 | F27: 2007 | G27: =VLOOKUP(F27,$AC$11:$AD$19,2,0) -> Piragutu | H27: 1505 | I27: 4.7 | J27: 8.66 | K27: =H27*I27% -> 70.735 | L27: =H27*J27% -> 130.333 | M27: =$R$25*H27/SUM($H$25:$H$27) -> 1525.0582 | N27: =P27/M27*100 -> 4.6007596 | O27: =Q27/M27*100 -> 8.4222258 | P27: =$U$25*K27/SUM($K$25:$K$27) -> 70.164261 | Q27: =$V$25*L27/SUM($L$25:$L$27) -> 128.44384 | X27: =ROUND(M27,0) -> 1525 | Y27: =ROUND(N27,2) -> 4.6 | Z27: =ROUND(O27,2) -> 8.42
A28: 72193 | B28: 1023 | C28: Single | D28: 45966 | F28: 2003 | G28: =VLOOKUP(F28,$AC$11:$AD$19,2,0) -> Hisri | H28: 1116 | I28: 4.15 | J28: 8.24 | K28: =H28*I28% -> 46.314 | L28: =H28*J28% -> 91.9584 | M28: =$R$28*H28/SUM($H$28:$H$29) -> 1113.3127 | N28: =P28/M28*100 -> 4.15 | O28: =Q28/M28*100 -> 8.2489813 | P28: =$U$28*K28/SUM($K$28:$K$29) -> 46.202477 | Q28: =$V$28*L28/SUM($L$28:$L$29) -> 91.836956 | R28: 2900 | S28: 4.15 | T28: 8.36 | U28: =R28*S28% -> 120.35 | V28: =R28*T28% -> 242.44 | X28: =ROUND(M28,0) -> 1113 | Y28: =ROUND(N28,2) -> 4.15 | Z28: =ROUND(O28,2) -> 8.25
A29: 72193 | B29: 1023 | C29: Single | D29: 45966 | F29: 2006 | G29: =VLOOKUP(F29,$AC$11:$AD$19,2,0) -> Ormanjhi | H29: 1791 | I29: 4.15 | J29: 8.42 | K29: =H29*I29% -> 74.3265 | L29: =H29*J29% -> 150.8022 | M29: =$R$28*H29/SUM($H$28:$H$29) -> 1786.6873 | N29: =P29/M29*100 -> 4.15 | O29: =Q29/M29*100 -> 8.4291775 | P29: =$U$28*K29/SUM($K$28:$K$29) -> 74.147523 | Q29: =$V$28*L29/SUM($L$28:$L$29) -> 150.60304 | X29: =ROUND(M29,0) -> 1787 | Y29: =ROUND(N29,2) -> 4.15 | Z29: =ROUND(O29,2) -> 8.43
A30: 72196 | B30: 1846 | C30: Single | D30: 45968 | F30: 2004 | G30: =VLOOKUP(F30,$AC$11:$AD$19,2,0) -> Chorya | H30: 931 | I30: 3.45 | J30: 8.1 | K30: =H30*I30% -> 32.1195 | L30: =H30*J30% -> 75.411 | M30: =$R$30*H30/SUM($H$30:$H$32) -> 931 | N30: =P30/M30*100 -> 3.4594678 | O30: =Q30/M30*100 -> 8.1170877 | P30: =$U$30*K30/SUM($K$30:$K$32) -> 32.207645 | Q30: =$V$30*L30/SUM($L$30:$L$32) -> 75.570086 | R30: 3580 | S30: 4.2 | T30: 8.37 | U30: =R30*S30% -> 150.36 | V30: =R30*T30% -> 299.646 | X30: =ROUND(M30,0) -> 931 | Y30: =ROUND(N30,2) -> 3.46 | Z30: =ROUND(O30,2) -> 8.12
A31: 72196 | B31: 1846 | C31: Single | D31: 45968 | F31: 2003 | G31: =VLOOKUP(F31,$AC$11:$AD$19,2,0) -> Hisri | H31: 1150 | I31: 4.25 | J31: 8.26 | K31: =H31*I31% -> 48.875 | L31: =H31*J31% -> 94.99 | M31: =$R$30*H31/SUM($H$30:$H$32) -> 1150 | N31: =P31/M31*100 -> 4.2616632 | O31: =Q31/M31*100 -> 8.2774252 | P31: =$U$30*K31/SUM($K$30:$K$32) -> 49.009126 | Q31: =$V$30*L31/SUM($L$30:$L$32) -> 95.19039 | X31: =ROUND(M31,0) -> 1150 | Y31: =ROUND(N31,2) -> 4.26 | Z31: =ROUND(O31,2) -> 8.28
A32: 72196 | B32: 1846 | C32: Single | D32: 45968 | F32: 2007 | G32: =VLOOKUP(F32,$AC$11:$AD$19,2,0) -> Piragutu | H32: 1499 | I32: 4.6 | J32: 8.58 | K32: =H32*I32% -> 68.954 | L32: =H32*J32% -> 128.6142 | M32: =$R$30*H32/SUM($H$30:$H$32) -> 1499 | N32: =P32/M32*100 -> 4.6126237 | O32: =Q32/M32*100 -> 8.5981003 | P32: =$U$30*K32/SUM($K$30:$K$32) -> 69.143229 | Q32: =$V$30*L32/SUM($L$30:$L$32) -> 128.88552 | X32: =ROUND(M32,0) -> 1499 | Y32: =ROUND(N32,2) -> 4.61 | Z32: =ROUND(O32,2) -> 8.6
A33: 72337 | B33: 1023 | C33: Rear | D33: 45968 | F33: 2009 | G33: =VLOOKUP(F33,$AC$11:$AD$19,2,0) -> Chanho | H33: 1602 | I33: 4.25 | J33: 8.51 | K33: =H33*I33% -> 68.085 | L33: =H33*J33% -> 136.3302 | M33: =$R$33*H33/SUM($H$33) -> 1620 | N33: =P33/M33*100 -> 4.2 | O33: =Q33/M33*100 -> 8.31 | P33: =$U$33*K33/SUM($K$33) -> 68.04 | Q33: =$V$33*L33/SUM($L$33) -> 134.622 | R33: 1620 | S33: 4.2 | T33: 8.31 | U33: =R33*S33% -> 68.04 | V33: =R33*T33% -> 134.622 | X33: =ROUND(M33,0) -> 1620 | Y33: =ROUND(N33,2) -> 4.2 | Z33: =ROUND(O33,2) -> 8.31
A34: 72337 | B34: 1023 | C34: Front | D34: 45968 | F34: 2002 | G34: =VLOOKUP(F34,$AC$11:$AD$19,2,0) -> Pali | H34: 4330 | I34: 4.15 | J34: 8.36 | K34: =H34*I34% -> 179.695 | L34: =H34*J34% -> 361.988 | M34: =$R$34*H34/SUM($H$34) -> 4340 | N34: =P34/M34*100 -> 4.15 | O34: =Q34/M34*100 -> 8.36 | P34: =$U$34*K34/SUM($K$34) -> 180.11 | Q34: =$V$34*L34/SUM($L$34) -> 362.824 | R34: 4340 | S34: 4.15 | T34: 8.36 | U34: =R34*S34% -> 180.11 | V34: =R34*T34% -> 362.824 | X34: =ROUND(M34,0) -> 4340 | Y34: =ROUND(N34,2) -> 4.15 | Z34: =ROUND(O34,2) -> 8.36
A35: 71474 | B35: 1023 | C35: Rear | D35: 45967 | F35: 2002 | G35: =VLOOKUP(F35,$AC$11:$AD$19,2,0) -> Pali | H35: 4330 | I35: 4.1 | J35: 8.35 | K35: =H35*I35% -> 177.53 | L35: =H35*J35% -> 361.555 | M35: =$R$35*H35/SUM($H$35) -> 4320 | N35: =P35/M35*100 -> 4.1 | O35: =Q35/M35*100 -> 8.35 | P35: =$U$35*K35/SUM($K$35) -> 177.12 | Q35: =$V$35*L35/SUM($L$35) -> 360.72 | R35: 4320 | S35: 4.1 | T35: 8.35 | U35: =R35*S35% -> 177.12 | V35: =R35*T35% -> 360.72 | X35: =ROUND(M35,0) -> 4320 | Y35: =ROUND(N35,2) -> 4.1 | Z35: =ROUND(O35,2) -> 8.35
A36: 71474 | B36: 1023 | C36: Front | D36: 45967 | F36: 2009 | G36: =VLOOKUP(F36,$AC$11:$AD$19,2,0) -> Chanho | H36: 2310 | I36: 4.2 | J36: 8.18 | K36: =H36*I36% -> 97.02 | L36: =H36*J36% -> 188.958 | M36: =$R$36*H36/SUM($H$36) -> 2330 | N36: =P36/M36*100 -> 4.15 | O36: =Q36/M36*100 -> 8.17 | P36: =$U$36*K36/SUM($K$36) -> 96.695 | Q36: =$V$36*L36/SUM($L$36) -> 190.361 | R36: 2330 | S36: 4.15 | T36: 8.17 | U36: =R36*S36% -> 96.695 | V36: =R36*T36% -> 190.361 | X36: =ROUND(M36,0) -> 2330 | Y36: =ROUND(N36,2) -> 4.15 | Z36: =ROUND(O36,2) -> 8.17
A37: 72198 | B37: 1023 | C37: Rear | D37: 45971 | F37: 2006 | G37: =VLOOKUP(F37,$AC$11:$AD$19,2,0) -> Ormanjhi | H37: 1551 | I37: 4.2 | J37: 8.43 | K37: =H37*I37% -> 65.142 | L37: =H37*J37% -> 130.7493 | M37: =$R$37*H37/SUM($H$37:$H$38) -> 1551 | N37: =P37/M37*100 -> 4.1838644 | O37: =Q37/M37*100 -> 8.4356551 | P37: =$U$37*K37/SUM($K$37:$K$38) -> 64.891737 | Q37: =$V$37*L37/SUM($L$37:$L$38) -> 130.83701 | R37: 3190 | S37: 3.8 | T37: 8.23 | U37: =R37*S37% -> 121.22 | V37: =R37*T37% -> 262.537 | X37: =ROUND(M37,0) -> 1551 | Y37: =ROUND(N37,2) -> 4.18 | Z37: =ROUND(O37,2) -> 8.44
A38: 72198 | B38: 1023 | C38: Rear | D38: 45971 | F38: 2004 | G38: =VLOOKUP(F38,$AC$11:$AD$19,2,0) -> Chorya | H38: 1639 | I38: 3.45 | J38: 8.03 | K38: =H38*I38% -> 56.5455 | L38: =H38*J38% -> 131.6117 | M38: =$R$37*H38/SUM($H$37:$H$38) -> 1639 | N38: =P38/M38*100 -> 3.4367458 | O38: =Q38/M38*100 -> 8.0353868 | P38: =$U$37*K38/SUM($K$37:$K$38) -> 56.328263 | Q38: =$V$37*L38/SUM($L$37:$L$38) -> 131.69999 | X38: =ROUND(M38,0) -> 1639 | Y38: =ROUND(N38,2) -> 3.44 | Z38: =ROUND(O38,2) -> 8.04
A39: 72198 | B39: 1023 | C39: Front | D39: 45971 | F39: 2009 | G39: =VLOOKUP(F39,$AC$11:$AD$19,2,0) -> Chanho | H39: 1624 | I39: 4.25 | J39: 8.32 | K39: =H39*I39% -> 69.02 | L39: =H39*J39% -> 135.1168 | M39: =$R$39*H39/SUM($H$39:$H$40) -> 1625.0318 | N39: =P39/M39*100 -> 4.2546075 | O39: =Q39/M39*100 -> 8.230276 | P39: =$U$39*K39/SUM($K$39:$K$40) -> 69.138723 | Q39: =$V$39*L39/SUM($L$39:$L$40) -> 133.7446 | R39: 3150 | S39: 4.4 | T39: 8.35 | U39: =R39*S39% -> 138.6 | V39: =R39*T39% -> 263.025 | X39: =ROUND(M39,0) -> 1625 | Y39: =ROUND(N39,2) -> 4.25 | Z39: =ROUND(O39,2) -> 8.23
A40: 72198 | B40: 1023 | C40: Front | D40: 45971 | F40: 2007 | G40: =VLOOKUP(F40,$AC$11:$AD$19,2,0) -> Piragutu | H40: 1524 | I40: 4.55 | J40: 8.57 | K40: =H40*I40% -> 69.342 | L40: =H40*J40% -> 130.6068 | M40: =$R$39*H40/SUM($H$39:$H$40) -> 1524.9682 | N40: =P40/M40*100 -> 4.5549327 | O40: =Q40/M40*100 -> 8.4775799 | P40: =$U$39*K40/SUM($K$39:$K$40) -> 69.461277 | Q40: =$V$39*L40/SUM($L$39:$L$40) -> 129.2804 | X40: =ROUND(M40,0) -> 1525 | Y40: =ROUND(N40,2) -> 4.55 | Z40: =ROUND(O40,2) -> 8.48
A41: 72340 | B41: 1023 | C41: Rear | D41: 45970 | F41: 2007 | G41: =VLOOKUP(F41,$AC$11:$AD$19,2,0) -> Piragutu | H41: 1430 | I41: 4.7 | J41: 8.6 | K41: =H41*I41% -> 67.21 | L41: =H41*J41% -> 122.98 | M41: =$R$41*H41/SUM($H$41:$H$42) -> 1403.3209 | N41: =P41/M41*100 -> 4.6339451 | O41: =Q41/M41*100 -> 8.5498352 | P41: =$U$41*K41/SUM($K$41:$K$42) -> 65.02912 | Q41: =$V$41*L41/SUM($L$41:$L$42) -> 119.98162 | R41: 2630 | S41: 4.45 | T41: 8.42 | U41: =R41*S41% -> 117.035 | V41: =R41*T41% -> 221.446 | X41: =ROUND(M41,0) -> 1403 | Y41: =ROUND(N41,2) -> 4.63 | Z41: =ROUND(O41,2) -> 8.55
...

Sheet Oct 25
H2: RMC wise Dispatch | M2: RMC wise Receipt | R2: Tanker Receipt at Plant | X2: Round Off
A3: Challan No | B3: Tanker No. | C3: Chamber | D3: Date | E3: Type | F3: RMC Code | G3: RMC Name | H3: Vol-Kg | I3: FAT% | J3: SNF% | K3: FAT Kg | L3: SNF Kg | M3: Vol-Kg | N3: FAT% | O3: SNF% | P3: FAT Kg | Q3: SNF Kg | R3: Vol-Kg | S3: FAT% | T3: SNF% | U3: FAT Kg | V3: SNF Kg | X3: Vol | Y3: Fat% | Z3: Snf%
A4: 72210 | B4: 9944 | C4: Single | D4: 45932 | F4: 2009 | G4: =VLOOKUP(F4,$AC$11:$AD$19,2,0) -> Chanho | H4: 1405 | I4: 4.1 | J4: 8.29 | K4: =H4*I4% -> 57.605 | L4: =H4*J4% -> 116.4745 | M4: =$R$4*H4/SUM($H$4:$H$5) -> 1402.7005 | N4: =P4/M4*100 -> 4.1072362 | O4: =Q4/M4*100 -> 8.2742241 | P4: =$U$4*K4/SUM($K$4:$K$5) -> 57.612222 | Q4: =$V$4*L4/SUM($L$4:$L$5) -> 116.06258 | R4: 4880 | S4: 4.25 | T4: 8.26 | U4: =R4*S4% -> 207.4 | V4: =R4*T4% -> 403.088 | X4: =ROUND(M4,0) -> 1403 | Y4: =ROUND(N4,2) -> 4.11 | Z4: =ROUND(O4,2) -> 8.27
A5: 72210 | B5: 9944 | C5: Single | D5: 45932 | F5: 2008 | G5: =VLOOKUP(F5,$AC$11:$AD$19,2,0) -> Bhandra | H5: 3483 | I5: 4.3 | J5: 8.27 | K5: =H5*I5% -> 149.769 | L5: =H5*J5% -> 288.0441 | M5: =$R$4*H5/SUM($H$4:$H$5) -> 3477.2995 | N5: =P5/M5*100 -> 4.3075892 | O5: =Q5/M5*100 -> 8.2542622 | P5: =$U$4*K5/SUM($K$4:$K$5) -> 149.78778 | Q5: =$V$4*L5/SUM($L$4:$L$5) -> 287.02542 | X5: =ROUND(M5,0) -> 3477 | Y5: =ROUND(N5,2) -> 4.31 | Z5: =ROUND(O5,2) -> 8.25
A6: 72243 | B6: 1023 | C6: Front | D6: 45932 | F6: 2004 | G6: =VLOOKUP(F6,$AC$11:$AD$19,2,0) -> Choria | H6: 1063 | I6: 3 | J6: 8 | K6: =H6*I6% -> 31.89 | L6: =H6*J6% -> 85.04 | M6: =$R$6*H6/SUM($H$6:$H$8) -> 1065.9203 | N6: =P6/M6*100 -> 2.9966542 | O6: =Q6/M6*100 -> 7.8656965 | P6: =$U$6*K6/SUM($K$6:$K$8) -> 31.941946 | Q6: =$V$6*L6/SUM($L$6:$L$8) -> 83.842058 | R6: 3650 | S6: 3.9 | T6: 8.12 | U6: =R6*S6% -> 142.35 | V6: =R6*T6% -> 296.38 | X6: =ROUND(M6,0) -> 1066 | Y6: =ROUND(N6,2) -> 3 | Z6: =ROUND(O6,2) -> 7.87
A7: 72243 | B7: 1023 | C7: Front | D7: 45932 | F7: 2007 | G7: =VLOOKUP(F7,$AC$11:$AD$19,2,0) -> Piragutu | H7: 1412 | I7: 4.3 | J7: 8.51 | K7: =H7*I7% -> 60.716 | L7: =H7*J7% -> 120.1612 | M7: =$R$6*H7/SUM($H$6:$H$8) -> 1415.8791 | N7: =P7/M7*100 -> 4.2952044 | O7: =Q7/M7*100 -> 8.3671347 | P7: =$U$6*K7/SUM($K$6:$K$8) -> 60.814902 | Q7: =$V$6*L7/SUM($L$6:$L$8) -> 118.46851 | X7: =ROUND(M7,0) -> 1416 | Y7: =ROUND(N7,2) -> 4.3 | Z7: =ROUND(O7,2) -> 8.37
A8: 72243 | B8: 1023 | C8: Front | D8: 45932 | F8: 2003 | G8: =VLOOKUP(F8,$AC$11:$AD$19,2,0) -> Hisri | H8: 1165 | I8: 4.25 | J8: 8.19 | K8: =H8*I8% -> 49.5125 | L8: =H8*J8% -> 95.4135 | M8: =$R$6*H8/SUM($H$6:$H$8) -> 1168.2005 | N8: =P8/M8*100 -> 4.2452601 | O8: =Q8/M8*100 -> 8.0525068 | P8: =$U$6*K8/SUM($K$6:$K$8) -> 49.593152 | Q8: =$V$6*L8/SUM($L$6:$L$8) -> 94.069429 | X8: =ROUND(M8,0) -> 1168 | Y8: =ROUND(N8,2) -> 4.25 | Z8: =ROUND(O8,2) -> 8.05
A9: 72243 | B9: 1023 | C9: Rear | D9: 45932 | F9: 2006 | G9: =VLOOKUP(F9,$AC$11:$AD$19,2,0) -> Ormanjhi | H9: 1685 | I9: 4.1 | J9: 8.32 | K9: =H9*I9% -> 69.085 | L9: =H9*J9% -> 140.192 | M9: =$R$9*H9/SUM($H$9) -> 1700 | N9: =P9/M9*100 -> 4.1 | O9: =Q9/M9*100 -> 8.23 | P9: =$U$9*K9/SUM($K$9) -> 69.7 | Q9: =$V$9*L9/SUM($L$9) -> 139.91 | R9: 1700 | S9: 4.1 | T9: 8.23 | U9: =R9*S9% -> 69.7 | V9: =R9*T9% -> 139.91 | X9: =ROUND(M9,0) -> 1700 | Y9: =ROUND(N9,2) -> 4.1 | Z9: =ROUND(O9,2) -> 8.23
A10: 72242 | B10: 1023 | C10: Rear | D10: 45931 | F10: 2003 | G10: =VLOOKUP(F10,$AC$11:$AD$19,2,0) -> Hisri | H10: 1097 | I10: 4.25 | J10: 8.23 | K10: =H10*I10% -> 46.6225 | L10: =H10*J10% -> 90.2831 | M10: =$R$10*H10/SUM($H$10:$H$12) -> 1098.4607 | N10: =P10/M10*100 -> 4.2288804 | O10: =Q10/M10*100 -> 8.1682523 | P10: =$U$10*K10/SUM($K$10:$K$12) -> 46.45259 | Q10: =$V$10*L10/SUM($L$10:$L$12) -> 89.725043 | R10: 3760 | S10: 4.25 | T10: 8.32 | U10: =R10*S10% -> 159.8 | V10: =R10*T10% -> 312.832 | X10: =ROUND(M10,0) -> 1098 | Y10: =ROUND(N10,2) -> 4.23 | Z10: =ROUND(O10,2) -> 8.17
A11: 72242 | B11: 1023 | C11: Rear | D11: 45931 | F11: 2007 | G11: =VLOOKUP(F11,$AC$11:$AD$19,2,0) -> Piragutu | H11: 1382 | I11: 4.4 | J11: 8.47 | K11: =H11*I11% -> 60.808 | L11: =H11*J11% -> 117.0554 | M11: =$R$10*H11/SUM($H$10:$H$12) -> 1383.8402 | N11: =P11/M11*100 -> 4.378135 | O11: =Q11/M11*100 -> 8.4064517 | P11: =$U$10*K11/SUM($K$10:$K$12) -> 60.586393 | Q11: =$V$10*L11/SUM($L$10:$L$12) -> 116.33186 | X11: =ROUND(M11,0) -> 1384 | Y11: =ROUND(N11,2) -> 4.38 | Z11: =ROUND(O11,2) -> 8.41 | AC11: 2001 | AD11: Itki
A12: 72242 | B12: 1023 | C12: Rear | D12: 45931 | F12: 2006 | G12: =VLOOKUP(F12,$AC$11:$AD$19,2,0) -> Ormanjhi | H12: 1276 | I12: 4.15 | J12: 8.42 | K12: =H12*I12% -> 52.954 | L12: =H12*J12% -> 107.4392 | M12: =$R$10*H12/SUM($H$10:$H$12) -> 1277.6991 | N12: =P12/M12*100 -> 4.1293774 | O12: =Q12/M12*100 -> 8.3568268 | P12: =$U$10*K12/SUM($K$10:$K$12) -> 52.761016 | Q12: =$V$10*L12/SUM($L$10:$L$12) -> 106.7751 | X12: =ROUND(M12,0) -> 1278 | Y12: =ROUND(N12,2) -> 4.13 | Z12: =ROUND(O12,2) -> 8.36 | AC12: 2002 | AD12: Pali
A13: 72242 | B13: 1023 | C13: Front | D13: 45931 | F13: 2002 | G13: =VLOOKUP(F13,$AC$11:$AD$19,2,0) -> Pali | H13: 3710 | I13: 4.2 | J13: 8.37 | K13: =H13*I13% -> 155.82 | L13: =H13*J13% -> 310.527 | M13: =$R$13*H13/SUM($H$13) -> 3570 | N13: =P13/M13*100 -> 4.15 | O13: =Q13/M13*100 -> 8.24 | P13: =$U$13*K13/SUM($K$13) -> 148.155 | Q13: =$V$13*L13/SUM($L$13) -> 294.168 | R13: 3570 | S13: 4.15 | T13: 8.24 | U13: =R13*S13% -> 148.155 | V13: =R13*T13% -> 294.168 | X13: =ROUND(M13,0) -> 3570 | Y13: =ROUND(N13,2) -> 4.15 | Z13: =ROUND(O13,2) -> 8.24 | AC13: 2003 | AD13: Hisri
A14: 70088 | B14: 8504 | C14: Single | D14: 45932 | F14: 2001 | G14: =VLOOKUP(F14,$AC$11:$AD$19,2,0) -> Itki | H14: 3668 | I14: 4.3 | J14: 8.52 | K14: =H14*I14% -> 157.724 | L14: =H14*J14% -> 312.5136 | M14: =$R$14*H14/SUM($H$14) -> 3680 | N14: =P14/M14*100 -> 4.2 | O14: =Q14/M14*100 -> 8.43 | P14: =$U$14*K14/SUM($K$14) -> 154.56 | Q14: =$V$14*L14/SUM($L$14) -> 310.224 | R14: 3680 | S14: 4.2 | T14: 8.43 | U14: =R14*S14% -> 154.56 | V14: =R14*T14% -> 310.224 | X14: =ROUND(M14,0) -> 3680 | Y14: =ROUND(N14,2) -> 4.2 | Z14: =ROUND(O14,2) -> 8.43 | AC14: 2004 | AD14: Choria
A15: 72245 | B15: 8504 | C15: Single | D15: 45934 | F15: 2002 | G15: =VLOOKUP(F15,$AC$11:$AD$19,2,0) -> Pali | H15: 3272 | I15: 4.25 | J15: 8.44 | K15: =H15*I15% -> 139.06 | L15: =H15*J15% -> 276.1568 | M15: =$R$15*H15/SUM($H$15) -> 3170 | N15: =P15/M15*100 -> 4.15 | O15: =Q15/M15*100 -> 8.36 | P15: =$U$15*K15/SUM($K$15) -> 131.555 | Q15: =$V$15*L15/SUM($L$15) -> 265.012 | R15: 3170 | S15: 4.15 | T15: 8.36 | U15: =R15*S15% -> 131.555 | V15: =R15*T15% -> 265.012 | X15: =ROUND(M15,0) -> 3170 | Y15: =ROUND(N15,2) -> 4.15 | Z15: =ROUND(O15,2) -> 8.36 | AC15: 2005 | AD15: Baski2
A16: 70090 | B16: 9944 | C16: Single | D16: 45934 | F16: 2009 | G16: =VLOOKUP(F16,$AC$11:$AD$19,2,0) -> Chanho | H16: 1370 | I16: 4.2 | J16: 8.31 | K16: =H16*I16% -> 57.54 | L16: =H16*J16% -> 113.847 | M16: =$R$16*H16/SUM($H$16:$H$17) -> 1368.1792 | N16: =P16/M16*100 -> 4.1892993 | O16: =Q16/M16*100 -> 8.3676493 | P16: =$U$16*K16/SUM($K$16:$K$17) -> 57.317123 | Q16: =$V$16*L16/SUM($L$16:$L$17) -> 114.48444 | R16: 5260 | S16: 4.3 | T16: 8.39 | U16: =R16*S16% -> 226.18 | V16: =R16*T16% -> 441.314 | X16: =ROUND(M16,0) -> 1368 | Y16: =ROUND(N16,2) -> 4.19 | Z16: =ROUND(O16,2) -> 8.37 | AC16: 2006 | AD16: Ormanjhi
A17: 70090 | B17: 9944 | C17: Single | D17: 45934 | F17: 2008 | G17: =VLOOKUP(F17,$AC$11:$AD$19,2,0) -> Bhandra | H17: 3897 | I17: 4.35 | J17: 8.34 | K17: =H17*I17% -> 169.5195 | L17: =H17*J17% -> 325.0098 | M17: =$R$16*H17/SUM($H$16:$H$17) -> 3891.8208 | N17: =P17/M17*100 -> 4.3389171 | O17: =Q17/M17*100 -> 8.3978574 | P17: =$U$16*K17/SUM($K$16:$K$17) -> 168.86288 | Q17: =$V$16*L17/SUM($L$16:$L$17) -> 326.82956 | X17: =ROUND(M17,0) -> 3892 | Y17: =ROUND(N17,2) -> 4.34 | Z17: =ROUND(O17,2) -> 8.4 | AC17: 2007 | AD17: Piragutu
A18: 72246 | B18: 1023 | C18: Single | D18: 45935 | F18: 2004 | G18: =VLOOKUP(F18,$AC$11:$AD$19,2,0) -> Choria | H18: 1222 | I18: 3.1 | J18: 8 | K18: =H18*I18% -> 37.882 | L18: =H18*J18% -> 97.76 | M18: =$R$18*H18/SUM($H$18:$H$20) -> 1223.5143 | N18: =P18/M18*100 -> 2.980773 | O18: =Q18/M18*100 -> 7.7987459 | P18: =$U$18*K18/SUM($K$18:$K$20) -> 36.470183 | Q18: =$V$18*L18/SUM($L$18:$L$20) -> 95.418768 | R18: 4040 | S18: 3.75 | T18: 8.03 | U18: =R18*S18% -> 151.5 | V18: =R18*T18% -> 324.412 | X18: =ROUND(M18,0) -> 1224 | Y18: =ROUND(N18,2) -> 2.98 | Z18: =ROUND(O18,2) -> 7.8 | AC18: 2008 | AD18: Bhandra
A19: 72246 | B19: 1023 | C19: Single | D19: 45935 | F19: 2007 | G19: =VLOOKUP(F19,$AC$11:$AD$19,2,0) -> Piragutu | H19: 1471 | I19: 4.3 | J19: 8.45 | K19: =H19*I19% -> 63.253 | L19: =H19*J19% -> 124.2995 | M19: =$R$18*H19/SUM($H$18:$H$20) -> 1472.8228 | N19: =P19/M19*100 -> 4.1346206 | O19: =Q19/M19*100 -> 8.2374254 | P19: =$U$18*K19/SUM($K$18:$K$20) -> 60.895635 | Q19: =$V$18*L19/SUM($L$18:$L$20) -> 121.32268 | X19: =ROUND(M19,0) -> 1473 | Y19: =ROUND(N19,2) -> 4.13 | Z19: =ROUND(O19,2) -> 8.24 | AC19: 2009 | AD19: Chanho
A20: 72246 | B20: 1023 | C20: Single | D20: 45935 | F20: 2003 | G20: =VLOOKUP(F20,$AC$11:$AD$19,2,0) -> Hisri | H20: 1342 | I20: 4.19 | J20: 8.22 | K20: =H20*I20% -> 56.2298 | L20: =H20*J20% -> 110.3124 | M20: =$R$18*H20/SUM($H$18:$H$20) -> 1343.6629 | N20: =P20/M20*100 -> 4.0288513 | O20: =Q20/M20*100 -> 8.0132114 | P20: =$U$18*K20/SUM($K$18:$K$20) -> 54.134182 | Q20: =$V$18*L20/SUM($L$18:$L$20) -> 107.67055 | X20: =ROUND(M20,0) -> 1344 | Y20: =ROUND(N20,2) -> 4.03 | Z20: =ROUND(O20,2) -> 8.01
A21: 72211 | B21: 1023 | C21: Rear | D21: 45934 | F21: 2003 | G21: =VLOOKUP(F21,$AC$11:$AD$19,2,0) -> Hisri | H21: 1080 | I21: 4.25 | J21: 8.19 | K21: =H21*I21% -> 45.9 | L21: =H21*J21% -> 88.452 | M21: =$R$21*H21/SUM($H$21:$H$22) -> 1081.8589 | N21: =P21/M21*100 -> 4.1809007 | O21: =Q21/M21*100 -> 7.8630247 | P21: =$U$21*K21/SUM($K$21:$K$22) -> 45.231444 | Q21: =$V$21*L21/SUM($L$21:$L$22) -> 85.06683 | R21: 2910 | S21: 4.15 | T21: 8.05 | U21: =R21*S21% -> 120.765 | V21: =R21*T21% -> 234.255 | X21: =ROUND(M21,0) -> 1082 | Y21: =ROUND(N21,2) -> 4.18 | Z21: =ROUND(O21,2) -> 7.86
A22: 72211 | B22: 1023 | C22: Rear | D22: 45934 | F22: 2007 | G22: =VLOOKUP(F22,$AC$11:$AD$19,2,0) -> Piragutu | H22: 1825 | I22: 4.2 | J22: 8.5 | K22: =H22*I22% -> 76.65 | L22: =H22*J22% -> 155.125 | M22: =$R$21*H22/SUM($H$21:$H$22) -> 1828.1411 | N22: =P22/M22*100 -> 4.1317136 | O22: =Q22/M22*100 -> 8.1606484 | P22: =$U$21*K22/SUM($K$21:$K$22) -> 75.533556 | Q22: =$V$21*L22/SUM($L$21:$L$22) -> 149.18817 | X22: =ROUND(M22,0) -> 1828 | Y22: =ROUND(N22,2) -> 4.13 | Z22: =ROUND(O22,2) -> 8.16
A23: 72211 | B23: 1023 | C23: Front | D23: 45934 | F23: 2006 | G23: =VLOOKUP(F23,$AC$11:$AD$19,2,0) -> Ormanjhi | H23: 2540 | I23: 4.1 | J23: 8.41 | K23: =H23*I23% -> 104.14 | L23: =H23*J23% -> 213.614 | M23: =$R$23*H23/SUM($H$23) -> 2560 | N23: =P23/M23*100 -> 4.1 | O23: =Q23/M23*100 -> 8.16 | P23: =$U$23*K23/SUM($K$23) -> 104.96 | Q23: =$V$23*L23/SUM($L$23) -> 208.896 | R23: 2560 | S23: 4.1 | T23: 8.16 | U23: =R23*S23% -> 104.96 | V23: =R23*T23% -> 208.896 | X23: =ROUND(M23,0) -> 2560 | Y23: =ROUND(N23,2) -> 4.1 | Z23: =ROUND(O23,2) -> 8.16
A24: 72212 | B24: 9944 | C24: Single | D24: 45935 | F24: 2008 | G24: =VLOOKUP(F24,$AC$11:$AD$19,2,0) -> Bhandra | H24: 3794 | I24: 4.35 | J24: 8.4 | K24: =H24*I24% -> 165.039 | L24: =H24*J24% -> 318.696 | M24: =$R$24*H24/SUM($H$24:$H$25) -> 3798.4082 | N24: =P24/M24*100 -> 4.3263858 | O24: =Q24/M24*100 -> 8.2752272 | P24: =$U$24*K24/SUM($K$24:$K$25) -> 164.33379 | Q24: =$V$24*L24/SUM($L$24:$L$25) -> 314.32691 | R24: 5170 | S24: 4.3 | T24: 8.27 | U24: =R24*S24% -> 222.31 | V24: =R24*T24% -> 427.559 | X24: =ROUND(M24,0) -> 3798 | Y24: =ROUND(N24,2) -> 4.33 | Z24: =ROUND(O24,2) -> 8.28
A25: 72212 | B25: 9944 | C25: Single | D25: 45935 | F25: 2009 | G25: =VLOOKUP(F25,$AC$11:$AD$19,2,0) -> Chanho | H25: 1370 | I25: 4.25 | J25: 8.38 | K25: =H25*I25% -> 58.225 | L25: =H25*J25% -> 114.806 | M25: =$R$24*H25/SUM($H$24:$H$25) -> 1371.5918 | N25: =P25/M25*100 -> 4.2269287 | O25: =Q25/M25*100 -> 8.2555242 | P25: =$U$24*K25/SUM($K$24:$K$25) -> 57.976206 | Q25: =$V$24*L25/SUM($L$24:$L$25) -> 113.23209 | X25: =ROUND(M25,0) -> 1372 | Y25: =ROUND(N25,2) -> 4.23 | Z25: =ROUND(O25,2) -> 8.26
A26: 72213 | B26: 9944 | C26: Single | D26: 45936 | F26: 2008 | G26: =VLOOKUP(F26,$AC$11:$AD$19,2,0) -> Bhandra | H26: 3868 | I26: 4.4 | J26: 8.41 | K26: =H26*I26% -> 170.192 | L26: =H26*J26% -> 325.2988 | M26: =$R$26*H26/SUM($H$26:$H$27) -> 3862.0811 | N26: =P26/M26*100 -> 4.338475 | O26: =Q26/M26*100 -> 8.4291093 | P26: =$U$26*K26/SUM($K$26:$K$27) -> 167.55542 | Q26: =$V$26*L26/SUM($L$26:$L$27) -> 325.53904 | R26: 5220 | S26: 4.3 | T26: 8.39 | U26: =R26*S26% -> 224.46 | V26: =R26*T26% -> 437.958 | X26: =ROUND(M26,0) -> 3862 | Y26: =ROUND(N26,2) -> 4.34 | Z26: =ROUND(O26,2) -> 8.43
A27: 72213 | B27: 9944 | C27: Single | D27: 45936 | F27: 2009 | G27: =VLOOKUP(F27,$AC$11:$AD$19,2,0) -> Chanho | H27: 1360 | I27: 4.25 | J27: 8.26 | K27: =H27*I27% -> 57.8 | L27: =H27*J27% -> 112.336 | M27: =$R$26*H27/SUM($H$26:$H$27) -> 1357.9189 | N27: =P27/M27*100 -> 4.1905725 | O27: =Q27/M27*100 -> 8.2787685 | P27: =$U$26*K27/SUM($K$26:$K$27) -> 56.904576 | Q27: =$V$26*L27/SUM($L$26:$L$27) -> 112.41896 | X27: =ROUND(M27,0) -> 1358 | Y27: =ROUND(N27,2) -> 4.19 | Z27: =ROUND(O27,2) -> 8.28
