Workbook

Sheet Sheet2
D3: Values
A4: ref_code | B4: name | C4: Type | D4: Sum of qty | E4: Sum of amount | G4: MCC | H4: BMC | K4: 10520002 | L4: Maa Durga Dairy | M4: VLC | N4: 37574 | O4: 1468984.8
A5: 10010013 | B5: Gomukh Kumbhi | C5: MPG | D5: 539.8 | E5: 20378.33 | F5: =VLOOKUP(A5,'[1]MPG Payment'!$C$3:$G$996,5,0) -> 539.8 | G5: =_xlfn.XLOOKUP(A5,Sheet1!D:D,Sheet1!A:A) -> Majhaul | H5: =_xlfn.XLOOKUP(G5,'[1]MCC-BMC'!$D:$D,'[1]MCC-BMC'!$C:$C) -> 1001 | K5: 10520003 | L5: Nova Bihar Dairy | M5: VLC | N5: 42806 | O5: 1868362.3
A6: 10010019 | B6: Gomukh Jagdar | C6: MPG | D6: 870.7 | E6: 34052.02 | F6: =VLOOKUP(A6,'[1]MPG Payment'!$C$3:$G$996,5,0) -> 870.7 | G6: =_xlfn.XLOOKUP(A6,Sheet1!D:D,Sheet1!A:A) -> Majhaul | H6: =_xlfn.XLOOKUP(G6,'[1]MCC-BMC'!$D:$D,'[1]MCC-BMC'!$C:$C) -> 1001 | K6: 10520005 | L6: Rakesh Dairy | M6: VLC | N6: 14690 | O6: 547216.12
A7: 10010038 | B7: Gomukh Goriyari | C7: MPG | D7: 898.32 | E7: 36880.49 | F7: =VLOOKUP(A7,'[1]MPG Payment'!$C$3:$G$996,5,0) -> 898.32 | G7: =_xlfn.XLOOKUP(A7,Sheet1!D:D,Sheet1!A:A) -> Hasanpur | H7: =_xlfn.XLOOKUP(G7,'[1]MCC-BMC'!$D:$D,'[1]MCC-BMC'!$C:$C) -> 1058 | K7: 10520006 | L7: Suddh Dairy | M7: VLC | N7: 27850 | O7: 1015675
A8: 10010044 | B8: Gomukh Kanausi | C8: MPG | D8: 266.92 | E8: 10951 | F8: =VLOOKUP(A8,'[1]MPG Payment'!$C$3:$G$996,5,0) -> 266.92 | G8: =_xlfn.XLOOKUP(A8,Sheet1!D:D,Sheet1!A:A) -> Hasanpur | H8: =_xlfn.XLOOKUP(G8,'[1]MCC-BMC'!$D:$D,'[1]MCC-BMC'!$C:$C) -> 1058 | K8: 10520010 | L8: Anik Kumar | M8: VLC | N8: 5239 | O8: 213512.57
A9: 10010047 | B9: Mohanpur - Chandan | C9: VLC | D9: 304.4 | E9: 11934.76 | F9: =VLOOKUP(A9,'[1]MPG Payment'!$C$3:$G$996,5,0) -> 304.4 | G9: =_xlfn.XLOOKUP(A9,Sheet1!D:D,Sheet1!A:A) -> Majhaul | H9: =_xlfn.XLOOKUP(G9,'[1]MCC-BMC'!$D:$D,'[1]MCC-BMC'!$C:$C) -> 1001
A10: 10010049 | B10: Birpur-2 - Pankaj | C10: VLC | D10: 377.3 | E10: 14733.16 | F10: =VLOOKUP(A10,'[1]MPG Payment'!$C$3:$G$996,5,0) -> 377.3 | G10: =_xlfn.XLOOKUP(A10,Sheet1!D:D,Sheet1!A:A) -> Majhaul | H10: =_xlfn.XLOOKUP(G10,'[1]MCC-BMC'!$D:$D,'[1]MCC-BMC'!$C:$C) -> 1001
A11: 10010050 | B11: Ekamba - Ashutosh | C11: MPG | D11: 1326.46 | E11: 56669.54 | F11: =VLOOKUP(A11,'[1]MPG Payment'!$C$3:$G$996,5,0) -> 1326.46 | G11: =_xlfn.XLOOKUP(A11,Sheet1!D:D,Sheet1!A:A) -> Hasanpur | H11: =_xlfn.XLOOKUP(G11,'[1]MCC-BMC'!$D:$D,'[1]MCC-BMC'!$C:$C) -> 1058
A12: 10010055 | B12: GOMUKH BIRPUR PASCHIM | C12: MPG | D12: 96.5 | E12: 4031.67 | F12: =VLOOKUP(A12,'[1]MPG Payment'!$C$3:$G$996,5,0) -> 96.5 | G12: =_xlfn.XLOOKUP(A12,Sheet1!D:D,Sheet1!A:A) -> Majhaul | H12: =_xlfn.XLOOKUP(G12,'[1]MCC-BMC'!$D:$D,'[1]MCC-BMC'!$C:$C) -> 1001
A13: 10010057 | B13: Manish Dairy | C13: VLC | D13: 10349.8 | E13: 391721.52 | F13: =VLOOKUP(A13,'[1]MPG Payment'!$C$3:$G$996,5,0) -> 10349.8 | G13: =_xlfn.XLOOKUP(A13,Sheet1!D:D,Sheet1!A:A) -> Majhaul | H13: =_xlfn.XLOOKUP(G13,'[1]MCC-BMC'!$D:$D,'[1]MCC-BMC'!$C:$C) -> 1001
A14: 10010076 | B14: Gomukh Bhith-02 | C14: MPG | D14: 950.4 | E14: 42632.9 | F14: =VLOOKUP(A14,'[1]MPG Payment'!$C$3:$G$996,5,0) -> 950.4 | G14: =_xlfn.XLOOKUP(A14,Sheet1!D:D,Sheet1!A:A) -> Majhaul | H14: =_xlfn.XLOOKUP(G14,'[1]MCC-BMC'!$D:$D,'[1]MCC-BMC'!$C:$C) -> 1001
A15: 10010079 | B15: Chandan Dairy | C15: VLC | D15: 214.5 | E15: 9160.99 | F15: =VLOOKUP(A15,'[1]MPG Payment'!$C$3:$G$996,5,0) -> 214.5 | G15: =_xlfn.XLOOKUP(K4,Sheet1!D:D,Sheet1!A:A) -> 3P Network | H15: =_xlfn.XLOOKUP(G15,'[1]MCC-BMC'!$D:$D,'[1]MCC-BMC'!$C:$C) -> 1052
A16: 10010082 | B16: Gomukh Sharmatola Sahuri | C16: MPG | D16: 1291.7 | E16: 50584 | F16: =VLOOKUP(A16,'[1]MPG Payment'!$C$3:$G$996,5,0) -> 1291.7 | G16: =_xlfn.XLOOKUP(K5,Sheet1!D:D,Sheet1!A:A) -> 3P Network | H16: =_xlfn.XLOOKUP(G16,'[1]MCC-BMC'!$D:$D,'[1]MCC-BMC'!$C:$C) -> 1052
A17: 10010084 | B17: Sangat- Sanjeev Kumar | C17: VLC | D17: 252.7 | E17: 8797.52 | F17: =VLOOKUP(A17,'[1]MPG Payment'!$C$3:$G$996,5,0) -> 252.7 | G17: =_xlfn.XLOOKUP(K6,Sheet1!D:D,Sheet1!A:A) -> 3P Network | H17: =_xlfn.XLOOKUP(G17,'[1]MCC-BMC'!$D:$D,'[1]MCC-BMC'!$C:$C) -> 1052
A18: 10010086 | B18: Gomukh Garhi Bisanpur | C18: MPG | D18: 144.84 | E18: 6738.02 | F18: =VLOOKUP(A18,'[1]MPG Payment'!$C$3:$G$996,5,0) -> 144.84 | G18: =_xlfn.XLOOKUP(K7,Sheet1!D:D,Sheet1!A:A) -> DalsinghSarai | H18: =_xlfn.XLOOKUP(G18,'[1]MCC-BMC'!$D:$D,'[1]MCC-BMC'!$C:$C) -> 1012
A19: 10010089 | B19: Gomukh Barkurwa | C19: MPG | D19: 478.14 | E19: 20368.75 | F19: =VLOOKUP(A19,'[1]MPG Payment'!$C$3:$G$996,5,0) -> 478.14 | G19: =_xlfn.XLOOKUP(K8,Sheet1!D:D,Sheet1!A:A) -> Kalyanpur | H19: =_xlfn.XLOOKUP(G19,'[1]MCC-BMC'!$D:$D,'[1]MCC-BMC'!$C:$C) -> 1053
A20: 10010092 | B20: Kamla- Amarjeet | C20: VLC | D20: 768.8 | E20: 25940.47 | F20: =VLOOKUP(A20,'[1]MPG Payment'!$C$3:$G$996,5,0) -> 768.8 | G20: =_xlfn.XLOOKUP(A20,Sheet1!D:D,Sheet1!A:A) -> Majhaul | H20: =_xlfn.XLOOKUP(G20,'[1]MCC-BMC'!$D:$D,'[1]MCC-BMC'!$C:$C) -> 1001
A21: 10010095 | B21: Gomukh Goha-02 | C21: MPG | D21: 248.1 | E21: 10205.62 | F21: =VLOOKUP(A21,'[1]MPG Payment'!$C$3:$G$996,5,0) -> 248.1 | G21: =_xlfn.XLOOKUP(A21,Sheet1!D:D,Sheet1!A:A) -> Hasanpur | H21: =_xlfn.XLOOKUP(G21,'[1]MCC-BMC'!$D:$D,'[1]MCC-BMC'!$C:$C) -> 1058
A22: 10010097 | B22: Gomukh Cheria Bariarpur | C22: MPG | D22: 1086.6 | E22: 42017.4 | F22: =VLOOKUP(A22,'[1]MPG Payment'!$C$3:$G$996,5,0) -> 1086.6 | G22: =_xlfn.XLOOKUP(A22,Sheet1!D:D,Sheet1!A:A) -> Majhaul | H22: =_xlfn.XLOOKUP(G22,'[1]MCC-BMC'!$D:$D,'[1]MCC-BMC'!$C:$C) -> 1001
A23: 10010099 | B23: Gomukh Bagraha-01 | C23: MPG | D23: 223.26 | E23: 9659.08 | F23: =VLOOKUP(A23,'[1]MPG Payment'!$C$3:$G$996,5,0) -> 223.26 | G23: =_xlfn.XLOOKUP(A23,Sheet1!D:D,Sheet1!A:A) -> Hasanpur | H23: =_xlfn.XLOOKUP(G23,'[1]MCC-BMC'!$D:$D,'[1]MCC-BMC'!$C:$C) -> 1058
A24: 10010108 | B24: Gomukh Pirauna | C24: MPG | D24: 221.9 | E24: 8113.94 | F24: =VLOOKUP(A24,'[1]MPG Payment'!$C$3:$G$996,5,0) -> 221.9 | G24: =_xlfn.XLOOKUP(A24,Sheet1!D:D,Sheet1!A:A) -> Majhaul | H24: =_xlfn.XLOOKUP(G24,'[1]MCC-BMC'!$D:$D,'[1]MCC-BMC'!$C:$C) -> 1001
A25: 10010109 | B25: Parra- Nagendra Kumar | C25: VLC | D25: 284.8 | E25: 9895.65 | F25: =VLOOKUP(A25,'[1]MPG Payment'!$C$3:$G$996,5,0) -> 284.8 | G25: =_xlfn.XLOOKUP(A25,Sheet1!D:D,Sheet1!A:A) -> Majhaul | H25: =_xlfn.XLOOKUP(G25,'[1]MCC-BMC'!$D:$D,'[1]MCC-BMC'!$C:$C) -> 1001
A26: 10010113 | B26: Gomukh Basahi | C26: MPG | D26: 792.6 | E26: 31801.71 | F26: =VLOOKUP(A26,'[1]MPG Payment'!$C$3:$G$996,5,0) -> 792.6 | G26: =_xlfn.XLOOKUP(A26,Sheet1!D:D,Sheet1!A:A) -> Majhaul | H26: =_xlfn.XLOOKUP(G26,'[1]MCC-BMC'!$D:$D,'[1]MCC-BMC'!$C:$C) -> 1001
A27: 10010121 | B27: Gomukh Sawantpur | C27: MPG | D27: 1342 | E27: 52229.67 | F27: =VLOOKUP(A27,'[1]MPG Payment'!$C$3:$G$996,5,0) -> 1342 | G27: =_xlfn.XLOOKUP(A27,Sheet1!D:D,Sheet1!A:A) -> Majhaul | H27: =_xlfn.XLOOKUP(G27,'[1]MCC-BMC'!$D:$D,'[1]MCC-BMC'!$C:$C) -> 1001
A28: 10010125 | B28: Maida- Ram Kumar | C28: VLC | D28: 428 | E28: 19077.98 | F28: =VLOOKUP(A28,'[1]MPG Payment'!$C$3:$G$996,5,0) -> 428 | G28: =_xlfn.XLOOKUP(A28,Sheet1!D:D,Sheet1!A:A) -> Majhaul | H28: =_xlfn.XLOOKUP(G28,'[1]MCC-BMC'!$D:$D,'[1]MCC-BMC'!$C:$C) -> 1001
A29: 10010128 | B29: Gomukh Aure Bikrampur | C29: MPG | D29: 924.6 | E29: 39360.72 | F29: =VLOOKUP(A29,'[1]MPG Payment'!$C$3:$G$996,5,0) -> 924.6 | G29: =_xlfn.XLOOKUP(A29,Sheet1!D:D,Sheet1!A:A) -> Majhaul | H29: =_xlfn.XLOOKUP(G29,'[1]MCC-BMC'!$D:$D,'[1]MCC-BMC'!$C:$C) -> 1001
A30: 10010129 | B30: Manjhaul- Gulshan Kumar | C30: VLC | D30: 1007.6 | E30: 43097.69 | F30: =VLOOKUP(A30,'[1]MPG Payment'!$C$3:$G$996,5,0) -> 1007.6 | G30: =_xlfn.XLOOKUP(A30,Sheet1!D:D,Sheet1!A:A) -> Majhaul | H30: =_xlfn.XLOOKUP(G30,'[1]MCC-BMC'!$D:$D,'[1]MCC-BMC'!$C:$C) -> 1001
A31: 10010130 | B31: Khaira Manjhaul | C31: VLC | D31: 505.4 | E31: 18620.93 | F31: =VLOOKUP(A31,'[1]MPG Payment'!$C$3:$G$996,5,0) -> 505.4 | G31: =_xlfn.XLOOKUP(A31,Sheet1!D:D,Sheet1!A:A) -> Majhaul | H31: =_xlfn.XLOOKUP(G31,'[1]MCC-BMC'!$D:$D,'[1]MCC-BMC'!$C:$C) -> 1001
... A1001: 10660038 | B1001: GOMUKH Dharampur | C1001: VLC | D1001: 2494.6 | E1001: 107516.56 | F1001: =VLOOKUP(A1001,'[1]MPG Payment'!$C$3:$G$996,5,0) -> 2494.6 | G1001: =_xlfn.XLOOKUP(A1001,Sheet1!D:D,Sheet1!A:A) -> Gaighat | H1001: =_xlfn.XLOOKUP(G1001,'[1]MCC-BMC'!$D:$D,'[1]MCC-BMC'!$C:$C) -> 1066
A1002: Grand Total | D1002: 1150000.5 | E1002: 47154596
A1007: 10520002 | B1007: Maa Durga Dairy | C1007: VLC | D1007: 37574 | E1007: 1468984.8
A1008: 10520003 | B1008: Nova Bihar Dairy | C1008: VLC | D1008: 42806 | E1008: 1868362.3
A1009: 10520005 | B1009: Rakesh Dairy | C1009: VLC | D1009: 14690 | E1009: 547216.12
A1010: 10520012 | B1010: Sarvodaya Dairy | C1010: MPG | D1010: 6952 | E1010: 271677.7
E1011: =SUM(E1007:E1010) -> 4156241
E1012: =GETPIVOTDATA("Sum of amount",$A$3)-E1011 -> 42998355
E1014: 42998355

Sheet Sheet1
A1: bmc_name | B1: route_code | C1: route_name | D1: ref_code | E1: name | F1: collection_date | G1: Shift | H1: Type | I1: animal_type_name | J1: qty | K1: fat | L1: snf | M1: rate | N1: amount | O1: qlty_auto
A2: Majhaul | B2: 100103 | C2: Birpur | D2: 10010108 | E2: Gomukh Pirauna | F2: 46220 | G2: Morning | H2: MPG | I2: Cow | J2: 14.5 | K2: 4.1 | L2: 7.9 | M2: 37.96 | N2: 550.42 | O2: A
A3: Majhaul | B3: 100103 | C3: Birpur | D3: 10010055 | E3: GOMUKH BIRPUR PASCHIM | F3: 46220 | G3: Morning | H3: MPG | I3: Mix | J3: 8 | K3: 5.8 | L3: 8.1 | M3: 41.08 | N3: 328.64 | O3: A
A4: Majhaul | B4: 100103 | C4: Birpur | D4: 10010019 | E4: Gomukh Jagdar | F4: 46220 | G4: Morning | H4: MPG | I4: Cow | J4: 59.6 | K4: 4.2 | L4: 8.3 | M4: 40.59 | N4: 2419.16 | O4: A
A5: Majhaul | B5: 100103 | C5: Birpur | D5: 10010082 | E5: Gomukh Sharmatola Sahuri | F5: 46220 | G5: Morning | H5: MPG | I5: Cow | J5: 92.1 | K5: 4.1 | L5: 8.1 | M5: 39.62 | N5: 3649 | O5: A
A6: Majhaul | B6: 100103 | C6: Birpur | D6: 10010076 | E6: Gomukh Bhith-02 | F6: 46220 | G6: Morning | H6: MPG | I6: Mix | J6: 51.8 | K6: 5.3 | L6: 8.7 | M6: 45.73 | N6: 2368.81 | O6: A
A7: Majhaul | B7: 100103 | C7: Birpur | D7: 10010109 | E7: Parra- Nagendra Kumar | F7: 46220 | G7: Morning | H7: VLC | I7: Cow | J7: 20.6 | K7: 4.1 | L7: 7.7 | M7: 37.43 | N7: 771.06 | O7: A
A8: Majhaul | B8: 100103 | C8: Birpur | D8: 10010149 | E8: Gomukh Meida | F8: 46220 | G8: Morning | H8: MPG | I8: Cow | J8: 14.8 | K8: 4.1 | L8: 8.1 | M8: 39.62 | N8: 586.38 | O8: A
A9: Majhaul | B9: 100102 | C9: Paroria | D9: 10010084 | E9: Sangat- Sanjeev Kumar | F9: 46220 | G9: Morning | H9: VLC | I9: Cow | J9: 4.5 | K9: 3.7 | L9: 7.7 | M9: 35.77 | N9: 160.97 | O9: A
A10: Majhaul | B10: 100102 | C10: Paroria | D10: 10010092 | E10: Kamla- Amarjeet | F10: 46220 | G10: Morning | H10: VLC | I10: Cow | J10: 27.1 | K10: 3.6 | L10: 7.7 | M10: 35.35 | N10: 957.99 | O10: A
A11: Majhaul | B11: 100102 | C11: Paroria | D11: 10010129 | E11: Manjhaul- Gulshan Kumar | F11: 46220 | G11: Morning | H11: VLC | I11: Mix | J11: 32 | K11: 5.6 | L11: 8.6 | M11: 47.26 | N11: 1512.32 | O11: A
A12: Majhaul | B12: 100102 | C12: Paroria | D12: 10010130 | E12: Khaira Manjhaul | F12: 46220 | G12: Morning | H12: VLC | I12: Mix | J12: 17.1 | K12: 5.6 | L12: 8.2 | M12: 41.59 | N12: 711.19 | O12: A
A13: Majhaul | B13: 100103 | C13: Birpur | D13: 10010148 | E13: Gomukh Meghaul-02 | F13: 46220 | G13: Morning | H13: MPG | I13: Cow | J13: 16.5 | K13: 4.7 | L13: 8.3 | M13: 42.67 | N13: 704.06 | O13: A
... A8492: MAHADAT PUR 2 | B8492: 103601 | C8492: RMC | D8492: 10360001 | E8492: MAHADAT PUR 2 | F8492: 46226 | G8492: Evening | H8492: MPG | I8492: Cow | J8492: 242 | K8492: 3.8 | L8492: 8.1 | M8492: 38.02 | N8492: 9201.45 | O8492: A
A8493: Dumraon | D8493: 10510002 | E8493: Diyaman | F8493: 46220 | G8493: Morning | H8493: MPG | I8493: Cow | J8493: 97 | K8493: 4.5 | L8493: 8.2 | M8493: 41.56 | N8493: 4031.32 | O8493: M
A8494: Dumraon | D8494: 10510004 | E8494: HENHA | F8494: 46220 | G8494: Morning | H8494: MPG | I8494: Cow | J8494: 181.5 | K8494: 4 | L8494: 8 | M8494: 38.92 | N8494: 7063.98 | O8494: M
A8495: Dumraon | D8495: 10510001 | E8495: ARAK | F8495: 46220 | G8495: Morning | H8495: MPG | I8495: Cow | J8495: 164 | K8495: 3.7 | L8495: 8.2 | M8495: 38.23 | N8495: 6269.72 | O8495: M
A8496: Dumraon | D8496: 10510002 | E8496: Diyaman | F8496: 46220 | G8496: Evening | H8496: MPG | I8496: Cow | J8496: 68.5 | K8496: 4.7 | L8496: 8.3 | M8496: 42.67 | N8496: 2922.9 | O8496: M
A8497: Dumraon | D8497: 10510004 | E8497: HENHA | F8497: 46220 | G8497: Evening | H8497: MPG | I8497: Cow | J8497: 161 | K8497: 3.9 | L8497: 8 | M8497: 38.5 | N8497: 6198.5 | O8497: M
A8498: Dumraon | D8498: 10510001 | E8498: ARAK | F8498: 46220 | G8498: Evening | H8498: MPG | I8498: Cow | J8498: 189.1 | K8498: 3.7 | L8498: 8.1 | M8498: 37.95 | N8498: 7176.35 | O8498: M
A8499: Dumraon | D8499: 10510002 | E8499: Diyaman | F8499: 46221 | G8499: Morning | H8499: MPG | I8499: Cow | J8499: 95.1 | K8499: 4.7 | L8499: 8.2 | M8499: 42.4 | N8499: 4032.24 | O8499: M
A8500: Dumraon | D8500: 10510004 | E8500: HENHA | F8500: 46221 | G8500: Morning | H8500: MPG | I8500: Cow | J8500: 182.1 | K8500: 4.1 | L8500: 8 | M8500: 39.34 | N8500: 7163.81 | O8500: M
A8501: Dumraon | D8501: 10510001 | E8501: ARAK | F8501: 46221 | G8501: Morning | H8501: MPG | I8501: Cow | J8501: 145 | K8501: 3.9 | L8501: 8.1 | M8501: 38.78 | N8501: 5623.1 | O8501: M
A8502: Dumraon | D8502: 10510004 | E8502: HENHA | F8502: 46221 | G8502: Evening | H8502: MPG | I8502: Cow | J8502: 145.7 | K8502: 3.8 | L8502: 8 | M8502: 38.09 | N8502: 5549.71 | O8502: M
A8503: Dumraon | D8503: 10510002 | E8503: Diyaman | F8503: 46221 | G8503: Evening | H8503: MPG | I8503: Cow | J8503: 71.1 | K8503: 4.4 | L8503: 8.3 | M8503: 41.42 | N8503: 2944.96 | O8503: M
A8504: Dumraon | D8504: 10510001 | E8504: ARAK | F8504: 46221 | G8504: Evening | H8504: MPG | I8504: Cow | J8504: 165 | K8504: 3.8 | L8504: 8.1 | M8504: 38.37 | N8504: 6331.05 | O8504: M
... A8536: 3P Network | D8536: 10520003 | E8536: Nova Bihar Dairy | F8536: 46220 | G8536: Morning | H8536: VLC | I8536: Mix | J8536: 10699 | K8536: 5.1 | L8536: 8.3 | M8536: 44.34 | N8536: 474393.66 | O8536: M
A8537: 3P Network | B8537: 105201 | C8537: 3p | D8537: 10520005 | E8537: Rakesh Dairy | F8537: 46220 | G8537: Morning | H8537: VLC | I8537: Cow | J8537: 2913 | K8537: 3.5 | L8537: 8.3 | M8537: 37.67 | N8537: 109732.71 | O8537: M
A8538: 3P Network | B8538: 105201 | C8538: 3p | D8538: 10520011 | E8538: Nand Kishor Kumar | F8538: 46220 | G8538: Morning | H8538: MPG | I8538: Cow | J8538: 4718 | K8538: 4.1 | L8538: 8.1 | M8538: 39.62 | N8538: 186927.16 | O8538: M
A8539: 3P Network | B8539: 105201 | C8539: 3p | D8539: 10520012 | E8539: Sarvodaya Dairy | F8539: 46220 | G8539: Morning | H8539: MPG | I8539: Cow | J8539: 1010 | K8539: 4.5 | L8539: 8.1 | M8539: 41.28 | N8539: 41692.8 | O8539: M
A8540: 3P Network | D8540: 10520002 | E8540: Maa Durga Dairy | F8540: 46220 | G8540: Evening | H8540: VLC | I8540: Cow | J8540: 3058 | K8540: 3.9 | L8540: 8.1 | M8540: 38.78 | N8540: 118589.24 | O8540: M
A8541: 3P Network | B8541: 105201 | C8541: 3p | D8541: 10520005 | E8541: Rakesh Dairy | F8541: 46220 | G8541: Evening | H8541: VLC | I8541: Cow | J8541: 2903 | K8541: 3.3 | L8541: 8.2 | M8541: 36.56 | N8541: 106133.68 | O8541: M
A8542: 3P Network | B8542: 105201 | C8542: 3p | D8542: 10520012 | E8542: Sarvodaya Dairy | F8542: 46220 | G8542: Evening | H8542: MPG | I8542: Cow | J8542: 1612 | K8542: 4 | L8542: 8 | M8542: 38.92 | N8542: 62739.04 | O8542: M
A8543: 3P Network | D8543: 10520002 | E8543: Maa Durga Dairy | F8543: 46221 | G8543: Morning | H8543: VLC | I8543: Cow | J8543: 3058 | K8543: 3.8 | L8543: 8.3 | M8543: 38.92 | N8543: 119017.36 | O8543: M
A8544: 3P Network | D8544: 10520003 | E8544: Nova Bihar Dairy | F8544: 46221 | G8544: Morning | H8544: VLC | I8544: Mix | J8544: 10689 | K8544: 5 | L8544: 8.3 | M8544: 43.93 | N8544: 469567.77 | O8544: M
A8545: 3P Network | B8545: 105201 | C8545: 3p | D8545: 10520011 | E8545: Nand Kishor Kumar | F8545: 46221 | G8545: Morning | H8545: MPG | I8545: Cow | J8545: 4854 | K8545: 3.9 | L8545: 8.2 | M8545: 39.06 | N8545: 189597.24 | O8545: M
A8546: 3P Network | D8546: 10520002 | E8546: Maa Durga Dairy | F8546: 46221 | G8546: Evening | H8546: VLC | I8546: Cow | J8546: 3049 | K8546: 3.7 | L8546: 8.2 | M8546: 38.23 | N8546: 116563.27 | O8546: M
A8547: 3P Network | D8547: 10520002 | E8547: Maa Durga Dairy | F8547: 46222 | G8547: Morning | H8547: VLC | I8547: Cow | J8547: 3049 | K8547: 3.7 | L8547: 8.3 | M8547: 38.5 | N8547: 117386.5 | O8547: M
A8548: 3P Network | B8548: 105201 | C8548: 3p | D8548: 10520005 | E8548: Rakesh Dairy | F8548: 46222 | G8548: Morning | H8548: VLC | I8548: Cow | J8548: 2981 | K8548: 3.3 | L8548: 8.2 | M8548: 36.56 | N8548: 108985.36 | O8548: M
A8549: 3P Network | B8549: 105201 | C8549: 3p | D8549: 10520011 | E8549: Nand Kishor Kumar | F8549: 46222 | G8549: Morning | H8549: MPG | I8549: Cow | J8549: 2049 | K8549: 4.2 | L8549: 8 | M8549: 39.76 | N8549: 81468.24 | O8549: M
...
