Workbook
Name Account_Details: #REF!
Name Amount: #REF!
Name CF_Recovery: #REF!
Name Code: #REF!
Name FAT_Range: #REF!
Name Net_Amount: #REF!
Name Other_Ded: #REF!
Name Rate_Chart_Kaimur: #REF!
Name Sample_Milk: #REF!
Name SNF_Range: #REF!
Name Vol_L: #REF!

Sheet MPG Payment
A2: BMC Code | B2: MCC Name | C2: Code | D2: Old Code | E2: MPG NAME | F2: Type | G2: Farmer Payment | H2: BMC Volume | I2: BMC Amount | J2: Payable | K2: Vet Deduction | L2: CF Deduction | M2: Other | N2: Advance | O2: Payable to MPG | P2: Hold Amount | Q2: Final Payment | R2: Stop Payment | S2: Hold Reason | T2: Cycle | V2: Sahayak Comm @ 1.75% | W2: Retain Comm @ 0.25% | X2: Payable Commission | Y2: Other Deduction | Z2: Net payable | AB2: beneficiary_name | AC2: bank_account_no | AD2: IFSC | AE2: u | AF2: am | AG2: Diff
A3: 1062 | B3: Ramgarh | C3: 10620002 | D3: =VLOOKUP(C3,DSC_Master!$C$1:D101,2,0) -> 64592 | E3: =VLOOKUP(C3,DSC_Master!$C$1:$K$200,4,0) -> UDHAPURA DSK | F3: MPG | G3: Indirect | H3: 643 | I3: 24824.004 | J3: =I3 -> 24824.004 | M3: 0 | O3: =J3-SUM(K3:N3) -> 24824.004 | P3: =IF(R3="Yes",O3,0) -> 0 | Q3: =O3-P3 -> 24824.004 | R3: 0 | T3: {=SUBSTITUTE(SUBSTITUTE(MID(CELL("filename"),FIND("[",CELL("filename"))+1,FIND("]",CELL("filename"))-FIND("[",CELL("filename"))-1),"Farmer Payment-",""),".xlsb","")} -> Ramgarh Kaimur_Farmer Payment_01-30 Jun.xlsx | V3: =I3*1.75% -> 434.42006 | W3: =I3*0.25% -> 62.060009 | X3: =V3-W3 -> 372.36005 | Y3: 0 | Z3: =X3-Y3 -> 372.36005 | AB3: =VLOOKUP(C3,DSC_Master!$C$1:$K$200,9,0) -> BAL GOPAL YADAV | AC3: =VLOOKUP(C3,DSC_Master!$C$1:$J$201,8,0) -> 37483995547 | AD3: =VLOOKUP(C3,DSC_Master!$C$1:$J$201,7,0) -> SBIN0000076 | AF3: 24830.52 | AG3: =Q3-AF3 -> -6.5164609
A4: 1062 | B4: Ramgarh | C4: 10620004 | D4: =VLOOKUP(C4,DSC_Master!$C$1:D102,2,0) -> 64600 | E4: =VLOOKUP(C4,DSC_Master!$C$1:$K$200,4,0) -> BHAMBHHOR DSK | F4: MPG | G4: Indirect | H4: 450 | I4: 17853.408 | J4: =I4 -> 17853.408 | M4: 0 | O4: =J4-SUM(K4:N4) -> 17853.408 | P4: =IF(R4="Yes",O4,0) -> 0 | Q4: =O4-P4 -> 17853.408 | R4: 0 | T4: {=SUBSTITUTE(SUBSTITUTE(MID(CELL("filename"),FIND("[",CELL("filename"))+1,FIND("]",CELL("filename"))-FIND("[",CELL("filename"))-1),"Farmer Payment-",""),".xlsb","")} -> Ramgarh Kaimur_Farmer Payment_01-30 Jun.xlsx | V4: =I4*1.75% -> 312.43464 | W4: =I4*0.25% -> 44.63352 | X4: =V4-W4 -> 267.80112 | Y4: 0 | Z4: =X4-Y4 -> 267.80112 | AB4: =VLOOKUP(C4,DSC_Master!$C$1:$K$200,9,0) -> DEEPAK KUMAR YADAV | AC4: =VLOOKUP(C4,DSC_Master!$C$1:$J$201,8,0) -> 924010010956816 | AD4: =VLOOKUP(C4,DSC_Master!$C$1:$J$201,7,0) -> UTIB0001632 | AF4: 17851.71 | AG4: =Q4-AF4 -> 1.6978088
A5: 1062 | B5: Ramgarh | C5: 10620005 | D5: =VLOOKUP(C5,DSC_Master!$C$1:D103,2,0) -> 64505 | E5: =VLOOKUP(C5,DSC_Master!$C$1:$K$200,4,0) -> MAHUWARIYA DSK | F5: MPG | G5: Indirect | H5: 681 | I5: 37878.588 | J5: =I5 -> 37878.588 | M5: 0 | O5: =J5-SUM(K5:N5) -> 37878.588 | P5: =IF(R5="Yes",O5,0) -> 0 | Q5: =O5-P5 -> 37878.588 | R5: 0 | T5: {=SUBSTITUTE(SUBSTITUTE(MID(CELL("filename"),FIND("[",CELL("filename"))+1,FIND("]",CELL("filename"))-FIND("[",CELL("filename"))-1),"Farmer Payment-",""),".xlsb","")} -> Ramgarh Kaimur_Farmer Payment_01-30 Jun.xlsx | V5: =I5*1.75% -> 662.87529 | W5: =I5*0.25% -> 94.69647 | X5: =V5-W5 -> 568.17882 | Y5: 0 | Z5: =X5-Y5 -> 568.17882 | AB5: =VLOOKUP(C5,DSC_Master!$C$1:$K$200,9,0) -> DINESH KUMAR | AC5: =VLOOKUP(C5,DSC_Master!$C$1:$J$201,8,0) -> 20315506501 | AD5: =VLOOKUP(C5,DSC_Master!$C$1:$J$201,7,0) -> SBIN0014328 | AF5: 37879.9 | AG5: =Q5-AF5 -> -1.3118475
A6: 1062 | B6: Ramgarh | C6: 10620009 | D6: =VLOOKUP(C6,DSC_Master!$C$1:D104,2,0) -> 64571 | E6: =VLOOKUP(C6,DSC_Master!$C$1:$K$200,4,0) -> JAVRI DSK | F6: MPG | G6: Indirect | H6: 942 | I6: 43414.257 | J6: =I6 -> 43414.257 | M6: 0 | O6: =J6-SUM(K6:N6) -> 43414.257 | P6: =IF(R6="Yes",O6,0) -> 0 | Q6: =O6-P6 -> 43414.257 | R6: 0 | T6: {=SUBSTITUTE(SUBSTITUTE(MID(CELL("filename"),FIND("[",CELL("filename"))+1,FIND("]",CELL("filename"))-FIND("[",CELL("filename"))-1),"Farmer Payment-",""),".xlsb","")} -> Ramgarh Kaimur_Farmer Payment_01-30 Jun.xlsx | V6: =I6*1.75% -> 759.74949 | W6: =I6*0.25% -> 108.53564 | X6: =V6-W6 -> 651.21385 | Y6: 0 | Z6: =X6-Y6 -> 651.21385 | AB6: =VLOOKUP(C6,DSC_Master!$C$1:$K$200,9,0) -> KANHAIYA YADAV | AC6: =VLOOKUP(C6,DSC_Master!$C$1:$J$201,8,0) -> 42108869535 | AD6: =VLOOKUP(C6,DSC_Master!$C$1:$J$201,7,0) -> SBIN0014328 | AF6: 43414.69 | AG6: =Q6-AF6 -> -0.4333045
A7: 1062 | B7: Ramgarh | C7: 10620010 | D7: =VLOOKUP(C7,DSC_Master!$C$1:D105,2,0) -> 64508 | E7: =VLOOKUP(C7,DSC_Master!$C$1:$K$200,4,0) -> LARMA DSK | F7: MPG | G7: Indirect | H7: 475 | I7: 24373.428 | J7: =I7 -> 24373.428 | M7: 0 | O7: =J7-SUM(K7:N7) -> 24373.428 | P7: =IF(R7="Yes",O7,0) -> 0 | Q7: =O7-P7 -> 24373.428 | R7: 0 | T7: {=SUBSTITUTE(SUBSTITUTE(MID(CELL("filename"),FIND("[",CELL("filename"))+1,FIND("]",CELL("filename"))-FIND("[",CELL("filename"))-1),"Farmer Payment-",""),".xlsb","")} -> Ramgarh Kaimur_Farmer Payment_01-30 Jun.xlsx | V7: =I7*1.75% -> 426.53499 | W7: =I7*0.25% -> 60.93357 | X7: =V7-W7 -> 365.60142 | Y7: 0 | Z7: =X7-Y7 -> 365.60142 | AB7: =VLOOKUP(C7,DSC_Master!$C$1:$K$200,9,0) -> KHUSHABU YADAV | AC7: =VLOOKUP(C7,DSC_Master!$C$1:$J$201,8,0) -> 2367000100137224 | AD7: =VLOOKUP(C7,DSC_Master!$C$1:$J$201,7,0) -> PUNB0236700 | AF7: 24374.09 | AG7: =Q7-AF7 -> -0.6619705
A8: 1062 | B8: Ramgarh | C8: 10620012 | D8: =VLOOKUP(C8,DSC_Master!$C$1:D106,2,0) -> 64515 | E8: =VLOOKUP(C8,DSC_Master!$C$1:$K$200,4,0) -> DHARHARA DSK | F8: MPG | G8: Indirect | H8: 714 | I8: 32722.539 | J8: =I8 -> 32722.539 | M8: 0 | O8: =J8-SUM(K8:N8) -> 32722.539 | P8: =IF(R8="Yes",O8,0) -> 0 | Q8: =O8-P8 -> 32722.539 | R8: 0 | T8: {=SUBSTITUTE(SUBSTITUTE(MID(CELL("filename"),FIND("[",CELL("filename"))+1,FIND("]",CELL("filename"))-FIND("[",CELL("filename"))-1),"Farmer Payment-",""),".xlsb","")} -> Ramgarh Kaimur_Farmer Payment_01-30 Jun.xlsx | V8: =I8*1.75% -> 572.64442 | W8: =I8*0.25% -> 81.806346 | X8: =V8-W8 -> 490.83808 | Y8: 0 | Z8: =X8-Y8 -> 490.83808 | AB8: =VLOOKUP(C8,DSC_Master!$C$1:$K$200,9,0) -> SHREE NIWAS YADAV | AC8: =VLOOKUP(C8,DSC_Master!$C$1:$J$201,8,0) -> 37905177514 | AD8: =VLOOKUP(C8,DSC_Master!$C$1:$J$201,7,0) -> SBIN0006137 | AF8: 32723.06 | AG8: =Q8-AF8 -> -0.5214765
A9: 1062 | B9: Ramgarh | C9: 10620013 | D9: =VLOOKUP(C9,DSC_Master!$C$1:D107,2,0) -> 64523 | E9: =VLOOKUP(C9,DSC_Master!$C$1:$K$200,4,0) -> KHADSARA DSK | F9: MPG | G9: Indirect | H9: 224 | I9: 12621.311 | J9: =I9 -> 12621.311 | M9: 0 | O9: =J9-SUM(K9:N9) -> 12621.311 | P9: =IF(R9="Yes",O9,0) -> 0 | Q9: =O9-P9 -> 12621.311 | R9: 0 | T9: {=SUBSTITUTE(SUBSTITUTE(MID(CELL("filename"),FIND("[",CELL("filename"))+1,FIND("]",CELL("filename"))-FIND("[",CELL("filename"))-1),"Farmer Payment-",""),".xlsb","")} -> Ramgarh Kaimur_Farmer Payment_01-30 Jun.xlsx | V9: =I9*1.75% -> 220.87293 | W9: =I9*0.25% -> 31.553276 | X9: =V9-W9 -> 189.31966 | Y9: 0 | Z9: =X9-Y9 -> 189.31966 | AB9: =VLOOKUP(C9,DSC_Master!$C$1:$K$200,9,0) -> SONU KUMAR | AC9: =VLOOKUP(C9,DSC_Master!$C$1:$J$201,8,0) -> 20421372063 | AD9: =VLOOKUP(C9,DSC_Master!$C$1:$J$201,7,0) -> SBIN0014328 | AF9: 12621.54 | AG9: =Q9-AF9 -> -0.2294381
A10: 1062 | B10: Ramgarh | C10: 10620014 | D10: =VLOOKUP(C10,DSC_Master!$C$1:D108,2,0) -> 60628 | E10: =VLOOKUP(C10,DSC_Master!$C$1:$K$200,4,0) -> BAIJNATH DSK | F10: MPG | G10: Indirect | H10: 349 | I10: 15665.383 | J10: =I10 -> 15665.383 | M10: 0 | O10: =J10-SUM(K10:N10) -> 15665.383 | P10: =IF(R10="Yes",O10,0) -> 0 | Q10: =O10-P10 -> 15665.383 | R10: 0 | T10: {=SUBSTITUTE(SUBSTITUTE(MID(CELL("filename"),FIND("[",CELL("filename"))+1,FIND("]",CELL("filename"))-FIND("[",CELL("filename"))-1),"Farmer Payment-",""),".xlsb","")} -> Ramgarh Kaimur_Farmer Payment_01-30 Jun.xlsx | V10: =I10*1.75% -> 274.14421 | W10: =I10*0.25% -> 39.163458 | X10: =V10-W10 -> 234.98075 | Y10: 0 | Z10: =X10-Y10 -> 234.98075 | AB10: =VLOOKUP(C10,DSC_Master!$C$1:$K$200,9,0) -> PARASH SINGH | AC10: =VLOOKUP(C10,DSC_Master!$C$1:$J$201,8,0) -> 2784000100175715 | AD10: =VLOOKUP(C10,DSC_Master!$C$1:$J$201,7,0) -> PUNB0278400 | AF10: 15665.48 | AG10: =Q10-AF10 -> -0.096809
A11: 1062 | B11: Ramgarh | C11: 10620015 | D11: =VLOOKUP(C11,DSC_Master!$C$1:D109,2,0) -> 64537 | E11: =VLOOKUP(C11,DSC_Master!$C$1:$K$200,4,0) -> KASTHARI DSK | F11: MPG | G11: Indirect | H11: 535 | I11: 23127.004 | J11: =I11 -> 23127.004 | M11: 0 | O11: =J11-SUM(K11:N11) -> 23127.004 | P11: =IF(R11="Yes",O11,0) -> 0 | Q11: =O11-P11 -> 23127.004 | R11: 0 | T11: {=SUBSTITUTE(SUBSTITUTE(MID(CELL("filename"),FIND("[",CELL("filename"))+1,FIND("]",CELL("filename"))-FIND("[",CELL("filename"))-1),"Farmer Payment-",""),".xlsb","")} -> Ramgarh Kaimur_Farmer Payment_01-30 Jun.xlsx | V11: =I11*1.75% -> 404.72257 | W11: =I11*0.25% -> 57.81751 | X11: =V11-W11 -> 346.90506 | Y11: 0 | Z11: =X11-Y11 -> 346.90506 | AB11: =VLOOKUP(C11,DSC_Master!$C$1:$K$200,9,0) -> PAWAN KUMAR SINGH | AC11: =VLOOKUP(C11,DSC_Master!$C$1:$J$201,8,0) -> 2374001500005364 | AD11: =VLOOKUP(C11,DSC_Master!$C$1:$J$201,7,0) -> PUNB0237400 | AF11: 23127.6 | AG11: =Q11-AF11 -> -0.5960269
A12: 1062 | B12: Ramgarh | C12: 10620016 | D12: =VLOOKUP(C12,DSC_Master!$C$1:D110,2,0) -> 64522 | E12: =VLOOKUP(C12,DSC_Master!$C$1:$K$200,4,0) -> MADANPURA DSK | F12: MPG | G12: Indirect | H12: 291 | I12: 14901.531 | J12: =I12 -> 14901.531 | M12: 0 | O12: =J12-SUM(K12:N12) -> 14901.531 | P12: =IF(R12="Yes",O12,0) -> 0 | Q12: =O12-P12 -> 14901.531 | R12: 0 | T12: {=SUBSTITUTE(SUBSTITUTE(MID(CELL("filename"),FIND("[",CELL("filename"))+1,FIND("]",CELL("filename"))-FIND("[",CELL("filename"))-1),"Farmer Payment-",""),".xlsb","")} -> Ramgarh Kaimur_Farmer Payment_01-30 Jun.xlsx | V12: =I12*1.75% -> 260.7768 | W12: =I12*0.25% -> 37.253828 | X12: =V12-W12 -> 223.52297 | Y12: 0 | Z12: =X12-Y12 -> 223.52297 | AB12: =VLOOKUP(C12,DSC_Master!$C$1:$K$200,9,0) -> RAM CHARAN RAI | AC12: =VLOOKUP(C12,DSC_Master!$C$1:$J$201,8,0) -> 2374000100165377 | AD12: =VLOOKUP(C12,DSC_Master!$C$1:$J$201,7,0) -> PUNB0237400 | AF12: 14901.6 | AG12: =Q12-AF12 -> -0.0686774
A13: 1062 | B13: Ramgarh | C13: 10620017 | D13: =VLOOKUP(C13,DSC_Master!$C$1:D111,2,0) -> 64555 | E13: =VLOOKUP(C13,DSC_Master!$C$1:$K$200,4,0) -> DEHWALIYA DSK | F13: MPG | G13: Indirect | H13: 298 | I13: 10800.353 | J13: =I13 -> 10800.353 | M13: 0 | O13: =J13-SUM(K13:N13) -> 10800.353 | P13: =IF(R13="Yes",O13,0) -> 0 | Q13: =O13-P13 -> 10800.353 | R13: 0 | T13: {=SUBSTITUTE(SUBSTITUTE(MID(CELL("filename"),FIND("[",CELL("filename"))+1,FIND("]",CELL("filename"))-FIND("[",CELL("filename"))-1),"Farmer Payment-",""),".xlsb","")} -> Ramgarh Kaimur_Farmer Payment_01-30 Jun.xlsx | V13: =I13*1.75% -> 189.00618 | W13: =I13*0.25% -> 27.000883 | X13: =V13-W13 -> 162.0053 | Y13: 0 | Z13: =X13-Y13 -> 162.0053 | AB13: =VLOOKUP(C13,DSC_Master!$C$1:$K$200,9,0) -> SATENDRA YADAV | AC13: =VLOOKUP(C13,DSC_Master!$C$1:$J$201,8,0) -> 14462413000951 | AD13: =VLOOKUP(C13,DSC_Master!$C$1:$J$201,7,0) -> PUNB0269600 | AF13: 10800.25 | AG13: =Q13-AF13 -> 0.103376
A14: 1062 | B14: Ramgarh | C14: 10620019 | D14: =VLOOKUP(C14,DSC_Master!$C$1:D112,2,0) -> 64569 | E14: =VLOOKUP(C14,DSC_Master!$C$1:$K$200,4,0) -> BICCHIYA DSK | F14: MPG | G14: Indirect | H14: 1149 | I14: 50932.866 | J14: =I14 -> 50932.866 | M14: 0 | O14: =J14-SUM(K14:N14) -> 50932.866 | P14: =IF(R14="Yes",O14,0) -> 0 | Q14: =O14-P14 -> 50932.866 | R14: 0 | T14: {=SUBSTITUTE(SUBSTITUTE(MID(CELL("filename"),FIND("[",CELL("filename"))+1,FIND("]",CELL("filename"))-FIND("[",CELL("filename"))-1),"Farmer Payment-",""),".xlsb","")} -> Ramgarh Kaimur_Farmer Payment_01-30 Jun.xlsx | V14: =I14*1.75% -> 891.32515 | W14: =I14*0.25% -> 127.33216 | X14: =V14-W14 -> 763.99299 | Y14: 0 | Z14: =X14-Y14 -> 763.99299 | AB14: =VLOOKUP(C14,DSC_Master!$C$1:$K$200,9,0) -> VANSHIDHAR SINGH | AC14: =VLOOKUP(C14,DSC_Master!$C$1:$J$201,8,0) -> 50200067834898 | AD14: =VLOOKUP(C14,DSC_Master!$C$1:$J$201,7,0) -> HDFC0002625 | AF14: 50933.09 | AG14: =Q14-AF14 -> -0.2241701
... A60: 1062 | B60: Ramgarh | C60: 10620109 | D60: =VLOOKUP(C60,DSC_Master!$C$1:D158,2,0) -> 20109 | E60: =VLOOKUP(C60,DSC_Master!$C$1:$K$200,4,0) -> YUVRAJPUR DSK | F60: MPG | G60: Indirect | H60: 8340 | I60: 371598.55 | J60: =I60 -> 371598.55 | M60: 0 | O60: =J60-SUM(K60:N60) -> 371598.55 | P60: =IF(R60="Yes",O60,0) -> 0 | Q60: =O60-P60 -> 371598.55 | R60: 0 | T60: {=SUBSTITUTE(SUBSTITUTE(MID(CELL("filename"),FIND("[",CELL("filename"))+1,FIND("]",CELL("filename"))-FIND("[",CELL("filename"))-1),"Farmer Payment-",""),".xlsb","")} -> Ramgarh Kaimur_Farmer Payment_01-30 Jun.xlsx | V60: =I60*1.75% -> 6502.9747 | W60: =I60*0.25% -> 928.99638 | X60: =V60-W60 -> 5573.9783 | Y60: 0 | Z60: =X60-Y60 -> 5573.9783 | AB60: =VLOOKUP(C60,DSC_Master!$C$1:$K$200,9,0) -> PRIYANKA PANDEY | AC60: =VLOOKUP(C60,DSC_Master!$C$1:$J$201,8,0) -> 0662001500012630 | AD60: =VLOOKUP(C60,DSC_Master!$C$1:$J$201,7,0) -> PUNB0066200 | AF60: 371593.2 | AG60: =Q60-AF60 -> 5.35371
A61: 1062 | B61: Ramgarh | C61: 10620111 | D61: =VLOOKUP(C61,DSC_Master!$C$1:D156,2,0) -> 20111 | E61: =VLOOKUP(C61,DSC_Master!$C$1:$K$200,4,0) -> SUHWAL | F61: MPG | G61: Indirect | H61: 360 | I61: 15962.867 | J61: =I61 -> 15962.867 | M61: 0 | O61: =J61-SUM(K61:N61) -> 15962.867 | P61: =IF(R61="Yes",O61,0) -> 0 | Q61: =O61-P61 -> 15962.867 | R61: 0 | T61: {=SUBSTITUTE(SUBSTITUTE(MID(CELL("filename"),FIND("[",CELL("filename"))+1,FIND("]",CELL("filename"))-FIND("[",CELL("filename"))-1),"Farmer Payment-",""),".xlsb","")} -> Ramgarh Kaimur_Farmer Payment_01-30 Jun.xlsx | V61: =I61*1.75% -> 279.35017 | W61: =I61*0.25% -> 39.907167 | X61: =V61-W61 -> 239.443 | Y61: 0 | Z61: =X61-Y61 -> 239.443 | AB61: =VLOOKUP(C61,DSC_Master!$C$1:$K$200,9,0) -> PRIYA PANDEY | AC61: =VLOOKUP(C61,DSC_Master!$C$1:$J$201,8,0) -> 43605915887 | AD61: =VLOOKUP(C61,DSC_Master!$C$1:$J$201,7,0) -> SBIN0003683 | AF61: 15962.1 | AG61: =Q61-AF61 -> 0.766635
A62: 1062 | B62: Ramgarh | C62: 10620112 | D62: =VLOOKUP(C62,DSC_Master!$C$1:D157,2,0) -> 20112 | E62: =VLOOKUP(C62,DSC_Master!$C$1:$K$200,4,0) -> PARSATHUA DSK | F62: MPG | G62: Indirect | H62: 158 | I62: 6441.4435 | J62: =I62 -> 6441.4435 | M62: 0 | O62: =J62-SUM(K62:N62) -> 6441.4435 | P62: =IF(R62="Yes",O62,0) -> 0 | Q62: =O62-P62 -> 6441.4435 | R62: 0 | T62: {=SUBSTITUTE(SUBSTITUTE(MID(CELL("filename"),FIND("[",CELL("filename"))+1,FIND("]",CELL("filename"))-FIND("[",CELL("filename"))-1),"Farmer Payment-",""),".xlsb","")} -> Ramgarh Kaimur_Farmer Payment_01-30 Jun.xlsx | V62: =I62*1.75% -> 112.72526 | W62: =I62*0.25% -> 16.103609 | X62: =V62-W62 -> 96.621652 | Y62: 0 | Z62: =X62-Y62 -> 96.621652 | AB62: =VLOOKUP(C62,DSC_Master!$C$1:$K$200,9,0) -> ANJU DEVI | AC62: =VLOOKUP(C62,DSC_Master!$C$1:$J$201,8,0) -> 50100615862671 | AD62: =VLOOKUP(C62,DSC_Master!$C$1:$J$201,7,0) -> HDFC0002625 | AF62: 6441.6 | AG62: =Q62-AF62 -> -0.1565061
A63: 1062 | B63: Ramgarh | C63: 10620115 | D63: =VLOOKUP(C63,DSC_Master!$C$1:D158,2,0) -> 20115 | E63: =VLOOKUP(C63,DSC_Master!$C$1:$K$200,4,0) -> BADAKI KULHARIA DSK | F63: MPG | G63: Indirect | H63: 604 | I63: 22501.363 | J63: =I63 -> 22501.363 | M63: 0 | O63: =J63-SUM(K63:N63) -> 22501.363 | P63: =IF(R63="Yes",O63,0) -> 0 | Q63: =O63-P63 -> 22501.363 | R63: 0 | T63: {=SUBSTITUTE(SUBSTITUTE(MID(CELL("filename"),FIND("[",CELL("filename"))+1,FIND("]",CELL("filename"))-FIND("[",CELL("filename"))-1),"Farmer Payment-",""),".xlsb","")} -> Ramgarh Kaimur_Farmer Payment_01-30 Jun.xlsx | V63: =I63*1.75% -> 393.77385 | W63: =I63*0.25% -> 56.253408 | X63: =V63-W63 -> 337.52045 | Y63: 0 | Z63: =X63-Y63 -> 337.52045 | AB63: =VLOOKUP(C63,DSC_Master!$C$1:$K$200,9,0) -> AJAY KUMAR SINGH | AC63: =VLOOKUP(C63,DSC_Master!$C$1:$J$201,8,0) -> 41684045867 | AD63: =VLOOKUP(C63,DSC_Master!$C$1:$J$201,7,0) -> SBIN0017163 | AF63: 22511.87 | AG63: =Q63-AF63 -> -10.506906
A64: 1062 | B64: Ramgarh | C64: 10620119 | D64: =VLOOKUP(C64,DSC_Master!$C$1:D159,2,0) -> 20119 | E64: =VLOOKUP(C64,DSC_Master!$C$1:$K$200,4,0) -> KURRA NEW DSK | F64: MPG | G64: Indirect | H64: 4690 | I64: 187755.36 | J64: =I64 -> 187755.36 | M64: 0 | O64: =J64-SUM(K64:N64) -> 187755.36 | P64: =IF(R64="Yes",O64,0) -> 0 | Q64: =O64-P64 -> 187755.36 | R64: 0 | T64: {=SUBSTITUTE(SUBSTITUTE(MID(CELL("filename"),FIND("[",CELL("filename"))+1,FIND("]",CELL("filename"))-FIND("[",CELL("filename"))-1),"Farmer Payment-",""),".xlsb","")} -> Ramgarh Kaimur_Farmer Payment_01-30 Jun.xlsx | V64: =I64*1.75% -> 3285.7188 | W64: =I64*0.25% -> 469.3884 | X64: =V64-W64 -> 2816.3304 | Y64: 0 | Z64: =X64-Y64 -> 2816.3304 | AB64: =VLOOKUP(C64,DSC_Master!$C$1:$K$200,9,0) -> DIVYANSHI DAIRY MILK | AC64: =VLOOKUP(C64,DSC_Master!$C$1:$J$201,8,0) -> 8136244333 | AD64: =VLOOKUP(C64,DSC_Master!$C$1:$J$201,7,0) -> IDIB000M430 | AF64: 186723.25 | AG64: =Q64-AF64 -> 1032.1105
A65: 1062 | B65: Ramgarh | C65: 10620120 | D65: =VLOOKUP(C65,DSC_Master!$C$1:D160,2,0) -> 20120 | E65: =VLOOKUP(C65,DSC_Master!$C$1:$K$200,4,0) -> TIYARA DSK | F65: MPG | G65: Indirect | H65: 176 | I65: 8885.9281 | J65: =I65 -> 8885.9281 | M65: 0 | O65: =J65-SUM(K65:N65) -> 8885.9281 | P65: =IF(R65="Yes",O65,0) -> 0 | Q65: =O65-P65 -> 8885.9281 | R65: 0 | T65: {=SUBSTITUTE(SUBSTITUTE(MID(CELL("filename"),FIND("[",CELL("filename"))+1,FIND("]",CELL("filename"))-FIND("[",CELL("filename"))-1),"Farmer Payment-",""),".xlsb","")} -> Ramgarh Kaimur_Farmer Payment_01-30 Jun.xlsx | V65: =I65*1.75% -> 155.50374 | W65: =I65*0.25% -> 22.21482 | X65: =V65-W65 -> 133.28892 | Y65: 0 | Z65: =X65-Y65 -> 133.28892 | AB65: =VLOOKUP(C65,DSC_Master!$C$1:$K$200,9,0) -> NIRMAL SINGH | AC65: =VLOOKUP(C65,DSC_Master!$C$1:$J$201,8,0) -> 2784000100110417 | AD65: =VLOOKUP(C65,DSC_Master!$C$1:$J$201,7,0) -> PUNB0278400 | AF65: 8886.21 | AG65: =Q65-AF65 -> -0.28195
A66: 1062 | B66: Ramgarh | C66: 10620121 | D66: =VLOOKUP(C66,DSC_Master!$C$1:D161,2,0) -> 20121 | E66: =VLOOKUP(C66,DSC_Master!$C$1:$K$200,4,0) -> DUMDUMA DSK | F66: MPG | G66: Indirect | H66: 827 | I66: 34211.24 | J66: =I66 -> 34211.24 | M66: 0 | O66: =J66-SUM(K66:N66) -> 34211.24 | P66: =IF(R66="Yes",O66,0) -> 0 | Q66: =O66-P66 -> 34211.24 | R66: 0 | T66: {=SUBSTITUTE(SUBSTITUTE(MID(CELL("filename"),FIND("[",CELL("filename"))+1,FIND("]",CELL("filename"))-FIND("[",CELL("filename"))-1),"Farmer Payment-",""),".xlsb","")} -> Ramgarh Kaimur_Farmer Payment_01-30 Jun.xlsx | V66: =I66*1.75% -> 598.6967 | W66: =I66*0.25% -> 85.5281 | X66: =V66-W66 -> 513.1686 | Y66: 0 | Z66: =X66-Y66 -> 513.1686 | AB66: =VLOOKUP(C66,DSC_Master!$C$1:$K$200,9,0) -> CHANDRA MANI RAI | AC66: =VLOOKUP(C66,DSC_Master!$C$1:$J$201,8,0) -> 625310110008012 | AD66: =VLOOKUP(C66,DSC_Master!$C$1:$J$201,7,0) -> BKID0006253 | AF66: 34210.84 | AG66: =Q66-AF66 -> 0.4000357
A67: 1062 | B67: Ramgarh | C67: 10620122 | D67: =VLOOKUP(C67,DSC_Master!$C$1:D162,2,0) -> 20122 | E67: =VLOOKUP(C67,DSC_Master!$C$1:$K$200,4,0) -> NOUAN DSK | F67: MPG | G67: Indirect | H67: 63 | I67: 2189.3201 | J67: =I67 -> 2189.3201 | M67: 0 | O67: =J67-SUM(K67:N67) -> 2189.3201 | P67: =IF(R67="Yes",O67,0) -> 0 | Q67: =O67-P67 -> 2189.3201 | R67: 0 | T67: {=SUBSTITUTE(SUBSTITUTE(MID(CELL("filename"),FIND("[",CELL("filename"))+1,FIND("]",CELL("filename"))-FIND("[",CELL("filename"))-1),"Farmer Payment-",""),".xlsb","")} -> Ramgarh Kaimur_Farmer Payment_01-30 Jun.xlsx | V67: =I67*1.75% -> 38.313101 | W67: =I67*0.25% -> 5.4733001 | X67: =V67-W67 -> 32.839801 | Y67: 0 | Z67: =X67-Y67 -> 32.839801 | AB67: =VLOOKUP(C67,DSC_Master!$C$1:$K$200,9,0) -> JAISHANKAR JAISWAL | AC67: =VLOOKUP(C67,DSC_Master!$C$1:$J$201,8,0) -> 461110110007555 | AD67: =VLOOKUP(C67,DSC_Master!$C$1:$J$201,7,0) -> BKID0004611 | AF67: 2189.25 | AG67: =Q67-AF67 -> 0.070056
A68: 1062 | B68: Ramgarh | C68: 10620123 | D68: =VLOOKUP(C68,DSC_Master!$C$1:D163,2,0) -> 20123 | E68: =VLOOKUP(C68,DSC_Master!$C$1:$K$200,4,0) -> SAKRAULI DSK | F68: MPG | G68: Indirect | H68: 302 | I68: 11472.701 | J68: =I68 -> 11472.701 | M68: 0 | O68: =J68-SUM(K68:N68) -> 11472.701 | P68: =IF(R68="Yes",O68,0) -> 0 | Q68: =O68-P68 -> 11472.701 | R68: 0 | T68: {=SUBSTITUTE(SUBSTITUTE(MID(CELL("filename"),FIND("[",CELL("filename"))+1,FIND("]",CELL("filename"))-FIND("[",CELL("filename"))-1),"Farmer Payment-",""),".xlsb","")} -> Ramgarh Kaimur_Farmer Payment_01-30 Jun.xlsx | V68: =I68*1.75% -> 200.77227 | W68: =I68*0.25% -> 28.681753 | X68: =V68-W68 -> 172.09052 | Y68: 0 | Z68: =X68-Y68 -> 172.09052 | AB68: =VLOOKUP(C68,DSC_Master!$C$1:$K$200,9,0) -> BECHU PASSI | AC68: =VLOOKUP(C68,DSC_Master!$C$1:$J$201,8,0) -> 2696000100200761 | AD68: =VLOOKUP(C68,DSC_Master!$C$1:$J$201,7,0) -> PUNB0269600 | AF68: 11472.58 | AG68: =Q68-AF68 -> 0.1211576
A69: 1062 | B69: Ramgarh | C69: 10620124 | D69: =VLOOKUP(C69,DSC_Master!$C$1:D164,2,0) -> 20124 | E69: =VLOOKUP(C69,DSC_Master!$C$1:$K$200,4,0) -> ISARI DSK | F69: MPG | G69: Indirect | H69: 129 | I69: 5264.9851 | J69: =I69 -> 5264.9851 | M69: 0 | O69: =J69-SUM(K69:N69) -> 5264.9851 | P69: =IF(R69="Yes",O69,0) -> 0 | Q69: =O69-P69 -> 5264.9851 | R69: 0 | T69: {=SUBSTITUTE(SUBSTITUTE(MID(CELL("filename"),FIND("[",CELL("filename"))+1,FIND("]",CELL("filename"))-FIND("[",CELL("filename"))-1),"Farmer Payment-",""),".xlsb","")} -> Ramgarh Kaimur_Farmer Payment_01-30 Jun.xlsx | V69: =I69*1.75% -> 92.137239 | W69: =I69*0.25% -> 13.162463 | X69: =V69-W69 -> 78.974776 | Y69: 0 | Z69: =X69-Y69 -> 78.974776 | AB69: =VLOOKUP(C69,DSC_Master!$C$1:$K$200,9,0) -> KUMAR ARJUN SINGH | AC69: =VLOOKUP(C69,DSC_Master!$C$1:$J$201,8,0) -> 42013101468 | AD69: =VLOOKUP(C69,DSC_Master!$C$1:$J$201,7,0) -> SBIN0017163 | AF69: 0 | AG69: =Q69-AF69 -> 5264.9851
A70: 1062 | B70: Ramgarh | C70: 10620125 | D70: =VLOOKUP(C70,DSC_Master!$C$1:D163,2,0) -> 20125 | E70: =VLOOKUP(C70,DSC_Master!$C$1:$K$200,4,0) -> KUCHHILA DSK | F70: MPG | G70: Indirect | H70: 48 | I70: 2062.5012 | J70: =I70 -> 2062.5012 | M70: 0 | O70: =J70-SUM(K70:N70) -> 2062.5012 | P70: =IF(R70="Yes",O70,0) -> 0 | Q70: =O70-P70 -> 2062.5012 | R70: 0 | T70: {=SUBSTITUTE(SUBSTITUTE(MID(CELL("filename"),FIND("[",CELL("filename"))+1,FIND("]",CELL("filename"))-FIND("[",CELL("filename"))-1),"Farmer Payment-",""),".xlsb","")} -> Ramgarh Kaimur_Farmer Payment_01-30 Jun.xlsx | V70: =I70*1.75% -> 36.09377 | W70: =I70*0.25% -> 5.1562529 | X70: =V70-W70 -> 30.937517 | Y70: 0 | Z70: =X70-Y70 -> 30.937517 | AB70: =VLOOKUP(C70,DSC_Master!$C$1:$K$200,9,0) -> DINBANDHU RAI | AC70: =VLOOKUP(C70,DSC_Master!$C$1:$J$201,8,0) -> 2397000100605573 | AD70: =VLOOKUP(C70,DSC_Master!$C$1:$J$201,7,0) -> PUNB0239700 | AF70: 0 | AG70: =Q70-AF70 -> 2062.5012
F71: Total: | G71: =COUNTA(G3:G70) -> 68 | H71: =SUBTOTAL(109,H3:H70) -> 59556 | I71: =SUBTOTAL(109,I3:I70) -> 2536229.5 | J71: =SUBTOTAL(109,J3:J70) -> 2536229.5 | K71: =SUBTOTAL(109,K3:K70) -> 0 | L71: =SUBTOTAL(109,L3:L70) -> 0 | M71: =SUBTOTAL(109,M3:M70) -> 0 | N71: =SUBTOTAL(109,N3:N70) -> 0 | O71: =SUBTOTAL(109,O3:O70) -> 2536229.5 | ... Q71: =SUBTOTAL(109,Q3:Q70) -> 2536229.5 | R71: =COUNTIF(R2:R70,"Yes") -> 0 | V71: =SUM(V3:V70) -> 44384.017 | W71: =SUM(W3:W70) -> 6340.5739 | X71: =SUM(X3:X70) -> 38043.443 | Y71: =SUM(Y3:Y70) -> 0 | Z71: =SUM(Z3:Z70) -> 38043.443 | AF71: =SUM(AF3:AF70) -> 2527404.8 | AG71: =SUM(AG3:AG70) -> 8824.7005
E73: Particulars | F73: Value
E74: No of MPGs | F74: =G71 -> 68
E75: BMC Volume | F75: =H71 -> 59556
E76: BMC Receipt Amount | F76: =I71 -> 2536229.5
E77: Payable Amount (Min) | F77: =J71 -> 2536229.5
E78: Vet Deduction | F78: =-K71 -> 0
E79: CF Deduction | F79: =-L71 -> 0
E80: Other | F80: =-M71 -> 0
E81: Advance | F81: =-N71 -> 0
E82: Payable to MPG | F82: =SUM(F77:F81) -> 2536229.5
E83: Hold Amount | F83: =P71 -> 0
E84: Final Payment | F84: =F82-F83 -> 2536229.5 | G84: =F84-Q71 -> 0
E86: Total Commission @ 1.75% | F86: =Data!R2 -> 196626.41
E87: Retain Commission @ 0.25% | F87: =F76*0.25% -> 6340.5739
E88: Payable Commission @ 1.50% | F88: =F86-F87 -> 190285.84
...

Sheet Sheet1
A1: union_code | B1: bmc_code | C1: dcs_code | D1: society_code_ex | E1: dcs_short_name | F1: Mobile No | G1: ifsc | H1: bank_account_no | I1: beneficiary_name | J1: Balance Payable/Recoverable | K1: Remarks | L1: Recovery in 06-12 Feb | M1: Balance
A2: 001 | B2: 1062 | C2: 10620001 | D2: 64540 | E2: KARARI DSK | F2: 9934591684 | G2: HDFC0002625 | H2: 50100615862020 | I2: AKHILESH PANDEY | J2: 23.246194 | K2: Recovery from cycle | L2: =VLOOKUP(C2,'MPG Payment'!$C$3:$N$70,12,0) -> #N/A | M2: =J2-L2 -> #N/A
A3: 001 | B3: 1062 | C3: 10620012 | D3: 64515 | E3: DHARHARA DSK | F3: 7783847657 | G3: SBIN0006137 | H3: 37905177514 | I3: SHREE NIWAS YADAV | J3: 354.68346 | K3: Recovery from cycle | L3: =VLOOKUP(C3,'MPG Payment'!$C$3:$N$70,12,0) -> 0 | M3: =J3-L3 -> 354.68346
A4: 001 | B4: 1062 | C4: 10620015 | D4: 64537 | E4: KASTHARI DSK | F4: 9905909472 | G4: PUNB0237400 | H4: 2374001500005364 | I4: PAWAN KUMAR SINGH | J4: 13702.66 | K4: Recovery from cycle | L4: =VLOOKUP(C4,'MPG Payment'!$C$3:$N$70,12,0) -> 0 | M4: =J4-L4 -> 13702.66
A5: 001 | B5: 1062 | C5: 10620018 | D5: 64591 | E5: LURPURWA DSK | F5: 8002591740 | G5: UBIN0560308 | H5: 603002010018335 | I5: SAVARU SINGH | J5: 19750.367 | K5: Recovery from cycle | L5: =VLOOKUP(C5,'MPG Payment'!$C$3:$N$70,12,0) -> #N/A | M5: =J5-L5 -> #N/A
A6: 001 | B6: 1062 | C6: 10620020 | D6: 64552 | E6: KRAPALPUR DSK | F6: 7739708957 | G6: PUNB0237400 | H6: 2374000100170476 | I6: VIJAY NARAYAN SINGH | J6: 27305.976 | K6: Recovery from cycle | L6: =VLOOKUP(C6,'MPG Payment'!$C$3:$N$70,12,0) -> 0 | M6: =J6-L6 -> 27305.976
A7: 001 | B7: 1062 | C7: 10620022 | D7: 64545 | E7: SURYAPURA DSK | F7: 9199217582 | G7: BKID0004611 | H7: 461110110009490 | I7: AJAY KUMAR SINGH | J7: 3356.0228 | K7: Recovery from cycle | L7: =VLOOKUP(C7,'MPG Payment'!$C$3:$N$70,12,0) -> #N/A | M7: =J7-L7 -> #N/A
A8: 001 | B8: 1062 | C8: 10620024 | D8: 60610 | E8: KARIRAM DSK | F8: 9199729020 | G8: PUNB0600800 | H8: 6008001700141624 | I8: BHARAT SINGH | J8: 3070.7935 | K8: Recovery from cycle | L8: =VLOOKUP(C8,'MPG Payment'!$C$3:$N$70,12,0) -> 0 | M8: =J8-L8 -> 3070.7935
A9: 001 | B9: 1062 | C9: 10620026 | D9: 64528 | E9: TARITHA DSK | F9: 9135981264 | G9: BKID0004611 | H9: 461118210002964 | I9: MANOJ KUMAR SINGH | J9: 3272.5795 | K9: Recovery from cycle | L9: =VLOOKUP(C9,'MPG Payment'!$C$3:$N$70,12,0) -> 0 | M9: =J9-L9 -> 3272.5795
A10: 001 | B10: 1062 | C10: 10620034 | D10: 64509 | E10: CHHOTKI KULHARIYA | F10: 7250947683 | G10: HDFC0002625 | H10: 50100492904593 | I10: ABHIMANYU KUMAR SINGH | J10: 4658.6176 | K10: Recovery from cycle | L10: =VLOOKUP(C10,'MPG Payment'!$C$3:$N$70,12,0) -> 0 | M10: =J10-L10 -> 4658.6176
A11: 001 | B11: 1062 | C11: 10620061 | D11: 60605 | E11: BADORA DSK | F11: 9170623981 | G11: SBIN0011251 | H11: 40819491150 | I11: SUMAN DEVI | J11: 46684.153 | K11: Recovery from cycle | L11: =VLOOKUP(C11,'MPG Payment'!$C$3:$N$70,12,0) -> 0 | M11: =J11-L11 -> 46684.153
A12: 001 | B12: 1062 | C12: 10620062 | D12: 64590 | E12: CHATRA DSK | F12: 9934761888 | G12: SBIN0002964 | H12: 39981585891 | I12: USHA DEVI | J12: 22196.225 | K12: Recovery from cycle | L12: =VLOOKUP(C12,'MPG Payment'!$C$3:$N$70,12,0) -> 0 | M12: =J12-L12 -> 22196.225
A13: 001 | B13: 1062 | C13: 10620065 | D13: 64589 | E13: NIPURAN DSK | F13: 7763028752 | G13: PUNB0237400 | H13: 2374000100181126 | I13: NITESH KUMAR YADAV | J13: 4097.9232 | K13: Recovery from cycle | L13: =VLOOKUP(C13,'MPG Payment'!$C$3:$N$70,12,0) -> #N/A | M13: =J13-L13 -> #N/A
... A17: 001 | B17: 1062 | C17: 10620094 | D17: 64572 | E17: MATHURADERA DSK | F17: 7061423987 | G17: PUNB0154700 | H17: 1547000100166038 | I17: SURENDRA YADAV | J17: 9307.5261 | K17: Recovery from cycle | L17: =VLOOKUP(C17,'MPG Payment'!$C$3:$N$70,12,0) -> #N/A | M17: =J17-L17 -> #N/A
J18: =SUM(J2:J17) -> 172704.2 | L18: =SUM(L2:L17) -> #N/A | M18: =J18-L18 -> #N/A

Sheet TS Loss Gain
B1: Ramgarh Bmc | AP1: 436.77 | AQ1: 291.18
B2: Date | C2: Shift | D2: OB | I2: Milk from MPG in Kg | M2: Transfer from other BMC/RMC | R2: Total Milk Receipt in Kg | U2: Tanker Dispatch Details | AC2: Plant Receipt | AH2: CB | AM2: Loss/(Gain)
D3: Qty KG | E3: Fat% | F3: Snf% | G3: FAT Kg | H3: SNF Kg | I3: Qty Kg | J3: Qty Kg | K3: Fat% | L3: Snf% | M3: From | N3: Tanker No | O3: Qty Kg | P3: Fat% | Q3: Snf% | R3: Qty Kg | S3: FAT Kg | T3: SNF Kg | U3: Tanker | V3: Challan | W3: To | X3: Qty KG | Y3: Fat% | Z3: Snf% | AA3: FAT Kg | AB3: SNF Kg | AC3: Qty KG | AD3: Fat% | AE3: Snf% | AF3: FAT Kg | AG3: SNF Kg | AH3: Qty KG | AI3: Fat% | AJ3: Snf% | AK3: FAT Kg | AL3: SNF Kg | AM3: Qty KG | AN3: FAT Kg | AO3: SNF Kg | AP3: TS Loss% | AQ3: Amount
B4: 46054 | C4: M | D4: 0 | E4: 0 | F4: 0 | G4: =+D4*E4% -> 0 | H4: =+D4*F4% -> 0 | I4: 20910 | J4: 20910 | K4: 5.3178001 | L4: 8.3824582 | R4: =O4+J4 -> 20910 | S4: =(J4*K4%)+(O4*P4%) -> 1111.952 | T4: =(J4*L4%)+(O4*Q4%) -> 1752.772 | U4: 5280 | V4: KMR 01 | W4: Hajipur | X4: 14940 | Y4: 5.3 | Z4: 8.3 | AA4: =X4*Y4% -> 791.82 | AB4: =X4*Z4% -> 1240.02 | AC4: 14940 | AD4: 5.3 | AE4: 8.3 | AF4: =AC4*AD4% -> 791.82 | AG4: =AC4*AE4% -> 1240.02 | AH4: 5970 | AI4: 5.36 | AJ4: 8.59 | AK4: =AH4*AI4% -> 319.992 | AL4: =AH4*AJ4% -> 512.823 | AM4: =+D4+R4-AC4-AH4 -> 0 | AN4: =+G4+S4-AF4-AK4 -> 0.14 | AO4: =+H4+T4-AG4-AL4 -> -0.071 | AP4: =(AN4+AO4)/(S4+T4) -> 2.408609e-05 | AQ4: =($AP$1*AN4+$AQ$1*AO4) -> 40.47402 | AR4: =(D4+J4+O4)-(X4+AH4) -> 0
B5: =+B4 -> 46054 | C5: E | D5: 5970 | E5: 5.36 | F5: 8.59 | G5: =+D5*E5% -> 319.992 | H5: =+D5*F5% -> 512.823 | I5: 8469 | J5: 8469 | K5: 5.4522376 | L5: 8.5376077 | R5: =O5+J5 -> 8469 | S5: =(J5*K5%)+(O5*P5%) -> 461.75 | T5: =(J5*L5%)+(O5*Q5%) -> 723.05 | U5: 0 | V5: 0 | W5: 0 | X5: 0 | Y5: 0 | Z5: 0 | AA5: =X5*Y5% -> 0 | AB5: =X5*Z5% -> 0 | AF5: =AC5*AD5% -> 0 | AG5: =AC5*AE5% -> 0 | AH5: 14459 | AI5: 5.41 | AJ5: 8.55 | AK5: =AH5*AI5% -> 782.2319 | AL5: =AH5*AJ5% -> 1236.2445 | AM5: =+D5+R5-AC5-AH5 -> -20 | AN5: =+G5+S5-AF5-AK5 -> -0.4899 | AO5: =+H5+T5-AG5-AL5 -> -0.3715 | AP5: =(AN5+AO5)/(S5+T5) -> -0.00072704254 | AQ5: =($AP$1*AN5+$AQ$1*AO5) -> -322.14699 | AR5: =(D5+J5+O5)-(X5+AH5) -> -20
B6: =+B4+1 -> 46055 | C6: M | D6: 14459 | E6: 5.41 | F6: 8.55 | G6: =+D6*E6% -> 782.2319 | H6: =+D6*F6% -> 1236.2445 | I6: 8285 | J6: 8285 | K6: 5.5487628 | L6: 8.6249849 | R6: =O6+J6 -> 8285 | S6: =(J6*K6%)+(O6*P6%) -> 459.715 | T6: =(J6*L6%)+(O6*Q6%) -> 714.58 | U6: 5280 | V6: KMR 02 | W6: Hajipur | X6: 18830 | Y6: 5.35 | Z6: 8.6 | AA6: =X6*Y6% -> 1007.405 | AB6: =X6*Z6% -> 1619.38 | AC6: 18760 | AD6: 5.35 | AE6: 8.41 | AF6: =AC6*AD6% -> 1003.66 | AG6: =AC6*AE6% -> 1577.716 | AH6: 3934 | AI6: 5.45 | AJ6: 8.57 | AK6: =AH6*AI6% -> 214.403 | AL6: =AH6*AJ6% -> 337.1438 | AM6: =+D6+R6-AC6-AH6 -> 50 | AN6: =+G6+S6-AF6-AK6 -> 23.8839 | AO6: =+H6+T6-AG6-AL6 -> 35.9647 | AP6: =(AN6+AO6)/(S6+T6) -> 0.050965558 | AQ6: =($AP$1*AN6+$AQ$1*AO6) -> 20903.972 | AR6: =(D6+J6+O6)-(X6+AH6) -> -20
B7: =+B5+1 -> 46055 | C7: E | D7: 3934 | E7: 5.45 | F7: 8.57 | G7: =+D7*E7% -> 214.403 | H7: =+D7*F7% -> 337.1438 | I7: 5624 | J7: 5624 | K7: 5.5403983 | L7: 8.4842105 | R7: =O7+J7 -> 5624 | S7: =(J7*K7%)+(O7*P7%) -> 311.592 | T7: =(J7*L7%)+(O7*Q7%) -> 477.152 | U7: 0 | V7: 0 | W7: 0 | X7: 0 | Y7: 0 | Z7: 0 | AA7: =X7*Y7% -> 0 | AB7: =X7*Z7% -> 0 | AF7: =AC7*AD7% -> 0 | AG7: =AC7*AE7% -> 0 | AH7: 9558 | AI7: 5.5 | AJ7: 8.52 | AK7: =AH7*AI7% -> 525.69 | AL7: =AH7*AJ7% -> 814.3416 | AM7: =+D7+R7-AC7-AH7 -> 0 | AN7: =+G7+S7-AF7-AK7 -> 0.305 | AO7: =+H7+T7-AG7-AL7 -> -0.0458 | AP7: =(AN7+AO7)/(S7+T7) -> 0.00032862374 | AQ7: =($AP$1*AN7+$AQ$1*AO7) -> 119.87881 | AR7: =(D7+J7+O7)-(X7+AH7) -> 0
B8: =+B6+1 -> 46056 | C8: M | D8: 9558 | E8: 5.5 | F8: 8.52 | G8: =+D8*E8% -> 525.69 | H8: =+D8*F8% -> 814.3416 | I8: 6861 | J8: 6861 | K8: 5.5343827 | L8: 8.596808 | R8: =O8+J8 -> 6861 | S8: =(J8*K8%)+(O8*P8%) -> 379.714 | T8: =(J8*L8%)+(O8*Q8%) -> 589.827 | U8: 00 | V8: 0 | W8: 0 | X8: 0 | Y8: 0 | Z8: 0 | AA8: =X8*Y8% -> 0 | AB8: =X8*Z8% -> 0 | AF8: =AC8*AD8% -> 0 | AG8: =AC8*AE8% -> 0 | AH8: 16429 | AI8: 5.51 | AJ8: 8.55 | AK8: =AH8*AI8% -> 905.2379 | AL8: =AH8*AJ8% -> 1404.6795 | AM8: =+D8+R8-AC8-AH8 -> -10 | AN8: =+G8+S8-AF8-AK8 -> 0.1661 | AO8: =+H8+T8-AG8-AL8 -> -0.5109 | AP8: =(AN8+AO8)/(S8+T8) -> -0.0003556322 | AQ8: =($AP$1*AN8+$AQ$1*AO8) -> -76.216365 | AR8: =(D8+J8+O8)-(X8+AH8) -> -10
B9: =+B7+1 -> 46056 | C9: E | D9: 16429 | E9: 5.51 | F9: 8.55 | G9: =+D9*E9% -> 905.2379 | H9: =+D9*F9% -> 1404.6795 | I9: 7190 | J9: 7190 | K9: 5.3776078 | L9: 8.5348679 | R9: =O9+J9 -> 7190 | S9: =(J9*K9%)+(O9*P9%) -> 386.65 | T9: =(J9*L9%)+(O9*Q9%) -> 613.657 | U9: 5280 | V9: KMR 03 | W9: Hajipur | X9: 18800 | Y9: 5.2 | Z9: 8.2 | AA9: =X9*Y9% -> 977.6 | AB9: =X9*Z9% -> 1541.6 | AC9: 18780 | AD9: 5.15 | AE9: 8.12 | AF9: =AC9*AD9% -> 967.17 | AG9: =AC9*AE9% -> 1524.936 | AH9: 4829 | AI9: 5.47 | AJ9: 8.54 | AK9: =AH9*AI9% -> 264.1463 | AL9: =AH9*AJ9% -> 412.3966 | AM9: =+D9+R9-AC9-AH9 -> 10 | AN9: =+G9+S9-AF9-AK9 -> 60.5716 | AO9: =+H9+T9-AG9-AL9 -> 81.0039 | AP9: =(AN9+AO9)/(S9+T9) -> 0.14153205 | AQ9: =($AP$1*AN9+$AQ$1*AO9) -> 50042.573 | AR9: =(D9+J9+O9)-(X9+AH9) -> -10
B10: =+B8+1 -> 46057 | C10: M | D10: 4829 | E10: 5.47 | F10: 8.54 | G10: =+D10*E10% -> 264.1463 | H10: =+D10*F10% -> 412.3966 | I10: 4601 | J10: 4601 | K10: 5.3553141 | L10: 8.6052597 | R10: =O10+J10 -> 4601 | S10: =(J10*K10%)+(O10*P10%) -> 246.398 | T10: =(J10*L10%)+(O10*Q10%) -> 395.928 | U10: 0 | V10: 0 | W10: 0 | X10: 0 | Y10: 0 | Z10: 0 | AA10: =X10*Y10% -> 0 | AB10: =X10*Z10% -> 0 | AF10: =AC10*AD10% -> 0 | AG10: =AC10*AE10% -> 0 | AH10: 9440 | AI10: 5.39 | AJ10: 8.53 | AK10: =AH10*AI10% -> 508.816 | AL10: =AH10*AJ10% -> 805.232 | AM10: =+D10+R10-AC10-AH10 -> -10 | AN10: =+G10+S10-AF10-AK10 -> 1.7283 | AO10: =+H10+T10-AG10-AL10 -> 3.0926 | AP10: =(AN10+AO10)/(S10+T10) -> 0.0075053789 | AQ10: =($AP$1*AN10+$AQ$1*AO10) -> 1655.3729 | AR10: =(D10+J10+O10)-(X10+AH10) -> -10
B11: =+B9+1 -> 46057 | C11: E | D11: 9440 | E11: 5.39 | F11: 8.53 | G11: =+D11*E11% -> 508.816 | H11: =+D11*F11% -> 805.232 | I11: 4919 | J11: 4919 | K11: 5.3969913 | L11: 8.4898353 | R11: =O11+J11 -> 4919 | S11: =(J11*K11%)+(O11*P11%) -> 265.478 | T11: =(J11*L11%)+(O11*Q11%) -> 417.615 | U11: 0 | V11: 0 | W11: 0 | X11: 0 | Y11: 0 | Z11: 0 | AA11: =X11*Y11% -> 0 | AB11: =X11*Z11% -> 0 | AF11: =AC11*AD11% -> 0 | AG11: =AC11*AE11% -> 0 | AH11: 14379 | AI11: 5.38 | AJ11: 8.5 | AK11: =AH11*AI11% -> 773.5902 | AL11: =AH11*AJ11% -> 1222.215 | AM11: =+D11+R11-AC11-AH11 -> -20 | AN11: =+G11+S11-AF11-AK11 -> 0.7038 | AO11: =+H11+T11-AG11-AL11 -> 0.632 | AP11: =(AN11+AO11)/(S11+T11) -> 0.001955517 | AQ11: =($AP$1*AN11+$AQ$1*AO11) -> 491.42449 | AR11: =(D11+J11+O11)-(X11+AH11) -> -20
B12: =+B10+1 -> 46058 | C12: M | D12: 14379 | E12: 5.38 | F12: 8.5 | G12: =+D12*E12% -> 773.5902 | H12: =+D12*F12% -> 1222.215 | I12: 5240 | J12: 5240 | K12: 5.6366794 | L12: 8.6313168 | R12: =O12+J12 -> 5240 | S12: =(J12*K12%)+(O12*P12%) -> 295.362 | T12: =(J12*L12%)+(O12*Q12%) -> 452.281 | U12: 5280 | V12: KMR 04 | W12: Hajipur | X12: 18780 | Y12: 5.55 | Z12: 8.65 | AA12: =X12*Y12% -> 1042.29 | AB12: =X12*Z12% -> 1624.47 | AC12: 18840 | AD12: 5.55 | AE12: 8.52 | AF12: =AC12*AD12% -> 1045.62 | AG12: =AC12*AE12% -> 1605.168 | AH12: 879 | AI12: 5.44 | AJ12: 8.52 | AK12: =AH12*AI12% -> 47.8176 | AL12: =AH12*AJ12% -> 74.8908 | AM12: =+D12+R12-AC12-AH12 -> -100 | AN12: =+G12+S12-AF12-AK12 -> -24.4854 | AO12: =+H12+T12-AG12-AL12 -> -5.5628 | AP12: =(AN12+AO12)/(S12+T12) -> -0.040190572 | AQ12: =($AP$1*AN12+$AQ$1*AO12) -> -12314.264 | AR12: =(D12+J12+O12)-(X12+AH12) -> -40
B13: =+B11+1 -> 46058 | C13: E | D13: 879 | E13: 5.44 | F13: 8.52 | G13: =+D13*E13% -> 47.8176 | H13: =+D13*F13% -> 74.8908 | I13: 5430 | J13: 5430 | K13: 5.1667956 | L13: 8.5652855 | R13: =O13+J13 -> 5430 | S13: =(J13*K13%)+(O13*P13%) -> 280.557 | T13: =(J13*L13%)+(O13*Q13%) -> 465.095 | U13: 0 | V13: 0 | W13: 0 | X13: 0 | Y13: 0 | Z13: 0 | AA13: =X13*Y13% -> 0 | AB13: =X13*Z13% -> 0 | AF13: =AC13*AD13% -> 0 | AG13: =AC13*AE13% -> 0 | AH13: 6319 | AI13: 5.2 | AJ13: 8.55 | AK13: =AH13*AI13% -> 328.588 | AL13: =AH13*AJ13% -> 540.2745 | AM13: =+D13+R13-AC13-AH13 -> -10 | AN13: =+G13+S13-AF13-AK13 -> -0.2134 | AO13: =+H13+T13-AG13-AL13 -> -0.2887 | AP13: =(AN13+AO13)/(S13+T13) -> -0.00067337042 | AQ13: =($AP$1*AN13+$AQ$1*AO13) -> -177.27038 | AR13: =(D13+J13+O13)-(X13+AH13) -> -10 | AS13: =SUM(AQ4:AQ13) -> 60363.798
B14: =+B12+1 -> 46059 | C14: M | D14: 6319 | E14: 5.2 | F14: 8.55 | G14: =+D14*E14% -> 328.588 | H14: =+D14*F14% -> 540.2745 | I14: 5637 | J14: 5637 | K14: 5.5152386 | L14: 8.6147064 | R14: =O14+J14 -> 5637 | S14: =(J14*K14%)+(O14*P14%) -> 310.894 | T14: =(J14*L14%)+(O14*Q14%) -> 485.611 | U14: 0 | V14: 0 | W14: 0 | X14: 0 | Y14: 0 | Z14: 0 | AA14: =X14*Y14% -> 0 | AB14: =X14*Z14% -> 0 | AF14: =AC14*AD14% -> 0 | AG14: =AC14*AE14% -> 0 | AH14: 11966 | AI14: 5.35 | AJ14: 8.57 | AK14: =AH14*AI14% -> 640.181 | AL14: =AH14*AJ14% -> 1025.4862 | AM14: =+D14+R14-AC14-AH14 -> -10 | AN14: =+G14+S14-AF14-AK14 -> -0.699 | AO14: =+H14+T14-AG14-AL14 -> 0.3993 | AP14: =(AN14+AO14)/(S14+T14) -> -0.00037626882 | AQ14: =($AP$1*AN14+$AQ$1*AO14) -> -189.03406 | AR14: =(D14+J14+O14)-(X14+AH14) -> -10
B15: =+B13+1 -> 46059 | C15: E | D15: 11966 | E15: 5.35 | F15: 8.57 | G15: =+D15*E15% -> 640.181 | H15: =+D15*F15% -> 1025.4862 | I15: 4761 | J15: 4761 | K15: 5.4387314 | L15: 8.5452636 | R15: =O15+J15 -> 4761 | S15: =(J15*K15%)+(O15*P15%) -> 258.938 | T15: =(J15*L15%)+(O15*Q15%) -> 406.84 | U15: 0 | V15: 0 | W15: 0 | X15: 0 | Y15: 0 | Z15: 0 | AA15: =X15*Y15% -> 0 | AB15: =X15*Z15% -> 0 | AF15: =AC15*AD15% -> 0 | AG15: =AC15*AE15% -> 0 | AH15: 16737 | AI15: 5.37 | AJ15: 8.56 | AK15: =AH15*AI15% -> 898.7769 | AL15: =AH15*AJ15% -> 1432.6872 | AM15: =+D15+R15-AC15-AH15 -> -10 | AN15: =+G15+S15-AF15-AK15 -> 0.3421 | AO15: =+H15+T15-AG15-AL15 -> -0.361 | AP15: =(AN15+AO15)/(S15+T15) -> -2.8387841e-05 | AQ15: =($AP$1*AN15+$AQ$1*AO15) -> 44.303037 | AR15: =(D15+J15+O15)-(X15+AH15) -> -10
B16: =+B14+1 -> 46060 | C16: M | D16: 16737 | E16: 5.37 | F16: 8.56 | G16: =+D16*E16% -> 898.7769 | H16: =+D16*F16% -> 1432.6872 | I16: 7868 | J16: 7868 | K16: 5.2064692 | L16: 8.4920564 | R16: =O16+J16 -> 7868 | S16: =(J16*K16%)+(O16*P16%) -> 409.645 | T16: =(J16*L16%)+(O16*Q16%) -> 668.155 | U16: 0 | V16: 0 | W16: 0 | X16: 0 | Y16: 0 | Z16: 0 | AA16: =X16*Y16% -> 0 | AB16: =X16*Z16% -> 0 | AF16: =AC16*AD16% -> 0 | AG16: =AC16*AE16% -> 0 | AH16: 24615 | AI16: 5.32 | AJ16: 8.53 | AK16: =AH16*AI16% -> 1309.518 | AL16: =AH16*AJ16% -> 2099.6595 | AM16: =+D16+R16-AC16-AH16 -> -10 | AN16: =+G16+S16-AF16-AK16 -> -1.0961 | AO16: =+H16+T16-AG16-AL16 -> 1.1827 | AP16: =(AN16+AO16)/(S16+T16) -> 8.0348859e-05 | AQ16: =($AP$1*AN16+$AQ$1*AO16) -> -134.36501 | AR16: =(D16+J16+O16)-(X16+AH16) -> -10
B17: =+B15+1 -> 46060 | C17: E | D17: 24615 | E17: 5.32 | F17: 8.53 | G17: =+D17*E17% -> 1309.518 | H17: =+D17*F17% -> 2099.6595 | I17: 6349 | J17: 6349 | K17: 5.4990392 | L17: 8.6212947 | R17: =O17+J17 -> 6349 | S17: =(J17*K17%)+(O17*P17%) -> 349.134 | T17: =(J17*L17%)+(O17*Q17%) -> 547.366 | U17: 00 | V17: 0 | W17: 0 | X17: 0 | Y17: 0 | Z17: 0 | AA17: =X17*Y17% -> 0 | AB17: =X17*Z17% -> 0 | AF17: =AC17*AD17% -> 0 | AG17: =AC17*AE17% -> 0 | AH17: 30974 | AI17: 5.35 | AJ17: 8.55 | AK17: =AH17*AI17% -> 1657.109 | AL17: =AH17*AJ17% -> 2648.277 | AM17: =+D17+R17-AC17-AH17 -> -10 | AN17: =+G17+S17-AF17-AK17 -> 1.543 | AO17: =+H17+T17-AG17-AL17 -> -1.2515 | AP17: =(AN17+AO17)/(S17+T17) -> 0.00032515337 | AQ17: =($AP$1*AN17+$AQ$1*AO17) -> 309.52434 | AR17: =(D17+J17+O17)-(X17+AH17) -> -10
B18: =+B16+1 -> 46061 | C18: M | D18: 30974 | E18: 5.35 | F18: 8.55 | G18: =+D18*E18% -> 1657.109 | H18: =+D18*F18% -> 2648.277 | I18: 6100 | J18: 6100 | K18: 5.5326393 | L18: 8.5830984 | R18: =O18+J18 -> 6100 | S18: =(J18*K18%)+(O18*P18%) -> 337.491 | T18: =(J18*L18%)+(O18*Q18%) -> 523.569 | U18: 5280 | V18: 82005 | W18: Hajipur | X18: 18750 | Y18: 5.55 | Z18: 8.65 | AA18: =X18*Y18% -> 1040.625 | AB18: =X18*Z18% -> 1621.875 | AC18: 18760 | AD18: 5.35 | AE18: 8.35 | AF18: =AC18*AD18% -> 1003.66 | AG18: =AC18*AE18% -> 1566.46 | AH18: 18334 | AI18: 5.38 | AJ18: 8.55 | AK18: =AH18*AI18% -> 986.3692 | AL18: =AH18*AJ18% -> 1567.557 | AM18: =+D18+R18-AC18-AH18 -> -20 | AN18: =+G18+S18-AF18-AK18 -> 4.5708 | AO18: =+H18+T18-AG18-AL18 -> 37.829 | AP18: =(AN18+AO18)/(S18+T18) -> 0.0492414 | AQ18: =($AP$1*AN18+$AQ$1*AO18) -> 13011.437 | AR18: =(D18+J18+O18)-(X18+AH18) -> -10
B19: =+B17+1 -> 46061 | C19: E | D19: 18334 | E19: 5.38 | F19: 8.55 | G19: =+D19*E19% -> 986.3692 | H19: =+D19*F19% -> 1567.557 | I19: 7022 | J19: 7022 | K19: 5.3281401 | L19: 8.495685 | R19: =O19+J19 -> 7022 | S19: =(J19*K19%)+(O19*P19%) -> 374.142 | T19: =(J19*L19%)+(O19*Q19%) -> 596.567 | U19: 0 | V19: 0 | W19: 0 | X19: 0 | Y19: 0 | Z19: 0 | AA19: =X19*Y19% -> 0 | AB19: =X19*Z19% -> 0 | AF19: =AC19*AD19% -> 0 | AG19: =AC19*AE19% -> 0 | AH19: 25366 | AI19: 5.36 | AJ19: 8.53 | AK19: =AH19*AI19% -> 1359.6176 | AL19: =AH19*AJ19% -> 2163.7198 | AM19: =+D19+R19-AC19-AH19 -> -10 | AN19: =+G19+S19-AF19-AK19 -> 0.8936 | AO19: =+H19+T19-AG19-AL19 -> 0.4042 | AP19: =(AN19+AO19)/(S19+T19) -> 0.0013369609 | AQ19: =($AP$1*AN19+$AQ$1*AO19) -> 507.99263 | AR19: =(D19+J19+O19)-(X19+AH19) -> -10
B20: =+B18+1 -> 46062 | C20: M | D20: 25366 | E20: 5.36 | F20: 8.53 | G20: =+D20*E20% -> 1359.6176 | H20: =+D20*F20% -> 2163.7198 | I20: 6305 | J20: 6305 | K20: 5.2935289 | L20: 8.5433783 | R20: =O20+J20 -> 6305 | S20: =(J20*K20%)+(O20*P20%) -> 333.757 | T20: =(J20*L20%)+(O20*Q20%) -> 538.66 | U20: 5280 | V20: 82007 | W20: Hajipur | X20: 18790 | Y20: 5.15 | Z20: 8.19 | AA20: =X20*Y20% -> 967.685 | AB20: =X20*Z20% -> 1538.901 | AC20: 18690 | AD20: 5.35 | AE20: 8.48 | AF20: =AC20*AD20% -> 999.915 | AG20: =AC20*AE20% -> 1584.912 | AH20: 12891 | AI20: 5.35 | AJ20: 8.53 | AK20: =AH20*AI20% -> 689.6685 | AL20: =AH20*AJ20% -> 1099.6023 | AM20: =+D20+R20-AC20-AH20 -> 90 | AN20: =+G20+S20-AF20-AK20 -> 3.7911 | AO20: =+H20+T20-AG20-AL20 -> 17.8655 | AP20: =(AN20+AO20)/(S20+T20) -> 0.02482368 | AQ20: =($AP$1*AN20+$AQ$1*AO20) -> 6857.915 | AR20: =(D20+J20+O20)-(X20+AH20) -> -10
B21: =+B19+1 -> 46062 | C21: E | D21: 12891 | E21: 5.35 | F21: 8.53 | G21: =+D21*E21% -> 689.6685 | H21: =+D21*F21% -> 1099.6023 | I21: 7560 | J21: 7560 | K21: 5.4646693 | L21: 8.557791 | R21: =O21+J21 -> 7560 | S21: =(J21*K21%)+(O21*P21%) -> 413.129 | T21: =(J21*L21%)+(O21*Q21%) -> 646.969 | U21: 0 | V21: 0 | W21: 0 | X21: 0 | Y21: 0 | Z21: 0 | AA21: =X21*Y21% -> 0 | AB21: =X21*Z21% -> 0 | AF21: =AC21*AD21% -> 0 | AG21: =AC21*AE21% -> 0 | AH21: 20461 | AI21: 5.39 | AJ21: 8.54 | AK21: =AH21*AI21% -> 1102.8479 | AL21: =AH21*AJ21% -> 1747.3694 | AM21: =+D21+R21-AC21-AH21 -> -10 | AN21: =+G21+S21-AF21-AK21 -> -0.0504 | AO21: =+H21+T21-AG21-AL21 -> -0.7981 | AP21: =(AN21+AO21)/(S21+T21) -> -0.0008003977 | AQ21: =($AP$1*AN21+$AQ$1*AO21) -> -254.40397 | AR21: =(D21+J21+O21)-(X21+AH21) -> -10
B22: =+B20+1 -> 46063 | C22: M | D22: 20461 | E22: 5.39 | F22: 8.54 | G22: =+D22*E22% -> 1102.8479 | H22: =+D22*F22% -> 1747.3694 | I22: 6363 | J22: 6363 | K22: 5.4041961 | L22: 8.5608047 | R22: =O22+J22 -> 6363 | S22: =(J22*K22%)+(O22*P22%) -> 343.869 | T22: =(J22*L22%)+(O22*Q22%) -> 544.724 | U22: 5280 | V22: 82008 | W22: Hajipur | X22: 18790 | Y22: 5.35 | Z22: 8.48 | AA22: =X22*Y22% -> 1005.265 | AB22: =X22*Z22% -> 1593.392 | AC22: 18710 | AD22: 5.25 | AE22: 8.33 | AF22: =AC22*AD22% -> 982.275 | AG22: =AC22*AE22% -> 1558.543 | AH22: 8044 | AI22: 5.39 | AJ22: 8.54 | AK22: =AH22*AI22% -> 433.5716 | AL22: =AH22*AJ22% -> 686.9576 | AM22: =+D22+R22-AC22-AH22 -> 70 | AN22: =+G22+S22-AF22-AK22 -> 30.8703 | AO22: =+H22+T22-AG22-AL22 -> 46.5928 | AP22: =(AN22+AO22)/(S22+T22) -> 0.087175006 | AQ22: =($AP$1*AN22+$AQ$1*AO22) -> 27050.112 | AR22: =(D22+J22+O22)-(X22+AH22) -> -10
B23: =+B21+1 -> 46063 | C23: E | D23: 8044 | E23: 5.39 | F23: 8.54 | G23: =+D23*E23% -> 433.5716 | H23: =+D23*F23% -> 686.9576 | I23: 6735 | J23: 6735 | K23: 5.4001336 | L23: 8.46049 | R23: =O23+J23 -> 6735 | S23: =(J23*K23%)+(O23*P23%) -> 363.699 | T23: =(J23*L23%)+(O23*Q23%) -> 569.814 | U23: 0 | V23: 0 | W23: 0 | X23: 0 | Y23: 0 | Z23: 0 | AA23: =X23*Y23% -> 0 | AB23: =X23*Z23% -> 0 | AF23: =AC23*AD23% -> 0 | AG23: =AC23*AE23% -> 0 | AH23: 14789 | AI23: 5.39 | AJ23: 8.5 | AK23: =AH23*AI23% -> 797.1271 | AL23: =AH23*AJ23% -> 1257.065 | AM23: =+D23+R23-AC23-AH23 -> -10 | AN23: =+G23+S23-AF23-AK23 -> 0.1435 | AO23: =+H23+T23-AG23-AL23 -> -0.2934 | AP23: =(AN23+AO23)/(S23+T23) -> -0.00016057623 | AQ23: =($AP$1*AN23+$AQ$1*AO23) -> -22.755717 | AR23: =(D23+J23+O23)-(X23+AH23) -> -10
B24: =+B22+1 -> 46064 | C24: M | D24: 14789 | E24: 5.39 | F24: 8.5 | G24: =+D24*E24% -> 797.1271 | H24: =+D24*F24% -> 1257.065 | I24: 5703 | J24: 5703 | K24: 5.3567245 | L24: 8.5889181 | R24: =O24+J24 -> 5703 | S24: =(J24*K24%)+(O24*P24%) -> 305.494 | T24: =(J24*L24%)+(O24*Q24%) -> 489.826 | U24: 0 | V24: 0 | W24: 0 | X24: 0 | Y24: 0 | Z24: 0 | AA24: =X24*Y24% -> 0 | AB24: =X24*Z24% -> 0 | AF24: =AC24*AD24% -> 0 | AG24: =AC24*AE24% -> 0 | AH24: 20502 | AI24: 5.38 | AJ24: 8.52 | AK24: =AH24*AI24% -> 1103.0076 | AL24: =AH24*AJ24% -> 1746.7704 | AM24: =+D24+R24-AC24-AH24 -> -10 | AN24: =+G24+S24-AF24-AK24 -> -0.3865 | AO24: =+H24+T24-AG24-AL24 -> 0.1206 | AP24: =(AN24+AO24)/(S24+T24) -> -0.00033433084 | AQ24: =($AP$1*AN24+$AQ$1*AO24) -> -133.6953 | AR24: =(D24+J24+O24)-(X24+AH24) -> -10
B25: =+B23+1 -> 46064 | C25: E | D25: 20502 | E25: 5.38 | F25: 8.52 | G25: =+D25*E25% -> 1103.0076 | H25: =+D25*F25% -> 1746.7704 | I25: 7060 | J25: 7060 | K25: 5.3508782 | L25: 8.5414306 | R25: =O25+J25 -> 7060 | S25: =(J25*K25%)+(O25*P25%) -> 377.772 | T25: =(J25*L25%)+(O25*Q25%) -> 603.025 | U25: 5280 | V25: 82009 | W25: Hajipur | X25: 18500 | Y25: 5.45 | Z25: 8.63 | AA25: =X25*Y25% -> 1008.25 | AB25: =X25*Z25% -> 1596.55 | AC25: 18540 | AD25: 5.4 | AE25: 8.43 | AF25: =AC25*AD25% -> 1001.16 | AG25: =AC25*AE25% -> 1562.922 | AH25: 9072 | AI25: 5.37 | AJ25: 8.52 | AK25: =AH25*AI25% -> 487.1664 | AL25: =AH25*AJ25% -> 772.9344 | AM25: =+D25+R25-AC25-AH25 -> -50 | AN25: =+G25+S25-AF25-AK25 -> -7.5468 | AO25: =+H25+T25-AG25-AL25 -> 13.939 | AP25: =(AN25+AO25)/(S25+T25) -> 0.0065173527 | AQ25: =($AP$1*AN25+$AQ$1*AO25) -> 762.54218 | AR25: =(D25+J25+O25)-(X25+AH25) -> -10
B26: =+B24+1 -> 46065 | C26: M | D26: 9072 | E26: 5.37 | F26: 8.52 | G26: =+D26*E26% -> 487.1664 | H26: =+D26*F26% -> 772.9344 | I26: 5669 | J26: 5669 | K26: 5.4099312 | L26: 8.5826601 | R26: =O26+J26 -> 5669 | S26: =(J26*K26%)+(O26*P26%) -> 306.689 | T26: =(J26*L26%)+(O26*Q26%) -> 486.551 | U26: 0 | V26: 0 | W26: 0 | X26: 0 | Y26: 0 | Z26: 0 | AA26: =X26*Y26% -> 0 | AB26: =X26*Z26% -> 0 | AF26: =AC26*AD26% -> 0 | AG26: =AC26*AE26% -> 0 | AH26: 14751 | AI26: 5.38 | AJ26: 8.54 | AK26: =AH26*AI26% -> 793.6038 | AL26: =AH26*AJ26% -> 1259.7354 | AM26: =+D26+R26-AC26-AH26 -> -10 | AN26: =+G26+S26-AF26-AK26 -> 0.2516 | AO26: =+H26+T26-AG26-AL26 -> -0.25 | AP26: =(AN26+AO26)/(S26+T26) -> 2.017044e-06 | AQ26: =($AP$1*AN26+$AQ$1*AO26) -> 37.096332 | AR26: =(D26+J26+O26)-(X26+AH26) -> -10
B27: =+B25+1 -> 46065 | C27: E | D27: 14751 | E27: 5.38 | F27: 8.54 | G27: =+D27*E27% -> 793.6038 | H27: =+D27*F27% -> 1259.7354 | I27: 6898 | J27: 6898 | K27: 5.133546 | L27: 8.4471731 | R27: =O27+J27 -> 6898 | S27: =(J27*K27%)+(O27*P27%) -> 354.112 | T27: =(J27*L27%)+(O27*Q27%) -> 582.686 | U27: 5280 | V27: 82010 | W27: Hajipur | X27: 18700 | Y27: 5.35 | Z27: 8.54 | AA27: =X27*Y27% -> 1000.45 | AB27: =X27*Z27% -> 1596.98 | AC27: 18730 | AD27: 5.3 | AE27: 8.34 | AF27: =AC27*AD27% -> 992.69 | AG27: =AC27*AE27% -> 1562.082 | AH27: 2959 | AI27: 5.3 | AJ27: 8.51 | AK27: =AH27*AI27% -> 156.827 | AL27: =AH27*AJ27% -> 251.8109 | AM27: =+D27+R27-AC27-AH27 -> -40 | AN27: =+G27+S27-AF27-AK27 -> -1.8012 | AO27: =+H27+T27-AG27-AL27 -> 28.5285 | AP27: =(AN27+AO27)/(S27+T27) -> 0.028530484 | AQ27: =($AP$1*AN27+$AQ$1*AO27) -> 7520.2185 | AR27: =(D27+J27+O27)-(X27+AH27) -> -10 | AS27: =SUM(AQ14:AQ27) -> 55366.887
B28: =+B26+1 -> 46066 | C28: M | G28: =+D28*E28% -> 0 | H28: =+D28*F28% -> 0 | J28: =I28 -> 0 | R28: =O28+J28 -> 0 | S28: =(J28*K28%)+(O28*P28%) -> 0 | T28: =(J28*L28%)+(O28*Q28%) -> 0 | AA28: =X28*Y28% -> 0 | AB28: =X28*Z28% -> 0 | AF28: =AC28*AD28% -> 0 | AG28: =AC28*AE28% -> 0 | AK28: =AH28*AI28% -> 0 | AL28: =AH28*AJ28% -> 0 | AM28: =+D28+R28-AC28-AH28 -> 0 | AN28: =+G28+S28-AF28-AK28 -> 0 | AO28: =+H28+T28-AG28-AL28 -> 0 | AP28: =(AN28+AO28)/(S28+T28) -> #DIV/0! | AQ28: =($AP$1*AN28+$AQ$1*AO28) -> 0 | AR28: =(D28+J28+O28)-(X28+AH28) -> 0
B29: =+B27+1 -> 46066 | C29: E | G29: =+D29*E29% -> 0 | H29: =+D29*F29% -> 0 | J29: =I29 -> 0 | R29: =O29+J29 -> 0 | S29: =(J29*K29%)+(O29*P29%) -> 0 | T29: =(J29*L29%)+(O29*Q29%) -> 0 | AA29: =X29*Y29% -> 0 | AB29: =X29*Z29% -> 0 | AF29: =AC29*AD29% -> 0 | AG29: =AC29*AE29% -> 0 | AK29: =AH29*AI29% -> 0 | AL29: =AH29*AJ29% -> 0 | AM29: =+D29+R29-AC29-AH29 -> 0 | AN29: =+G29+S29-AF29-AK29 -> 0 | AO29: =+H29+T29-AG29-AL29 -> 0 | AP29: =(AN29+AO29)/(S29+T29) -> #DIV/0! | AQ29: =($AP$1*AN29+$AQ$1*AO29) -> 0 | AR29: =(D29+J29+O29)-(X29+AH29) -> 0
B30: =+B28+1 -> 46067 | C30: M | G30: =+D30*E30% -> 0 | H30: =+D30*F30% -> 0 | J30: =I30 -> 0 | R30: =O30+J30 -> 0 | S30: =(J30*K30%)+(O30*P30%) -> 0 | T30: =(J30*L30%)+(O30*Q30%) -> 0 | AA30: =X30*Y30% -> 0 | AB30: =X30*Z30% -> 0 | AF30: =AC30*AD30% -> 0 | AG30: =AC30*AE30% -> 0 | AK30: =AH30*AI30% -> 0 | AL30: =AH30*AJ30% -> 0 | AM30: =+D30+R30-AC30-AH30 -> 0 | AN30: =+G30+S30-AF30-AK30 -> 0 | AO30: =+H30+T30-AG30-AL30 -> 0 | AP30: =(AN30+AO30)/(S30+T30) -> #DIV/0! | AQ30: =($AP$1*AN30+$AQ$1*AO30) -> 0 | AR30: =(D30+J30+O30)-(X30+AH30) -> 0
B31: =+B29+1 -> 46067 | C31: E | G31: =+D31*E31% -> 0 | H31: =+D31*F31% -> 0 | J31: =I31 -> 0 | R31: =O31+J31 -> 0 | S31: =(J31*K31%)+(O31*P31%) -> 0 | T31: =(J31*L31%)+(O31*Q31%) -> 0 | AA31: =X31*Y31% -> 0 | AB31: =X31*Z31% -> 0 | AF31: =AC31*AD31% -> 0 | AG31: =AC31*AE31% -> 0 | AK31: =AH31*AI31% -> 0 | AL31: =AH31*AJ31% -> 0 | AM31: =+D31+R31-AC31-AH31 -> 0 | AN31: =+G31+S31-AF31-AK31 -> 0 | AO31: =+H31+T31-AG31-AL31 -> 0 | AP31: =(AN31+AO31)/(S31+T31) -> #DIV/0! | AQ31: =($AP$1*AN31+$AQ$1*AO31) -> 0 | AR31: =(D31+J31+O31)-(X31+AH31) -> 0
B32: =+B30+1 -> 46068 | C32: M | G32: =+D32*E32% -> 0 | H32: =+D32*F32% -> 0 | J32: =I32 -> 0 | R32: =O32+J32 -> 0 | S32: =(J32*K32%)+(O32*P32%) -> 0 | T32: =(J32*L32%)+(O32*Q32%) -> 0 | AA32: =X32*Y32% -> 0 | AB32: =X32*Z32% -> 0 | AF32: =AC32*AD32% -> 0 | AG32: =AC32*AE32% -> 0 | AK32: =AH32*AI32% -> 0 | AL32: =AH32*AJ32% -> 0 | AM32: =+D32+R32-AC32-AH32 -> 0 | AN32: =+G32+S32-AF32-AK32 -> 0 | AO32: =+H32+T32-AG32-AL32 -> 0 | AP32: =(AN32+AO32)/(S32+T32) -> #DIV/0! | AQ32: =($AP$1*AN32+$AQ$1*AO32) -> 0 | AR32: =(D32+J32+O32)-(X32+AH32) -> 0
B33: =+B31+1 -> 46068 | C33: E | G33: =+D33*E33% -> 0 | H33: =+D33*F33% -> 0 | J33: =I33 -> 0 | R33: =O33+J33 -> 0 | S33: =(J33*K33%)+(O33*P33%) -> 0 | T33: =(J33*L33%)+(O33*Q33%) -> 0 | AA33: =X33*Y33% -> 0 | AB33: =X33*Z33% -> 0 | AF33: =AC33*AD33% -> 0 | AG33: =AC33*AE33% -> 0 | AK33: =AH33*AI33% -> 0 | AL33: =AH33*AJ33% -> 0 | AM33: =+D33+R33-AC33-AH33 -> 0 | AN33: =+G33+S33-AF33-AK33 -> 0 | AO33: =+H33+T33-AG33-AL33 -> 0 | AP33: =(AN33+AO33)/(S33+T33) -> #DIV/0! | AQ33: =($AP$1*AN33+$AQ$1*AO33) -> 0 | AR33: =(D33+J33+O33)-(X33+AH33) -> 0
B34: =+B32+1 -> 46069 | C34: M | G34: =+D34*E34% -> 0 | H34: =+D34*F34% -> 0 | J34: =I34 -> 0 | R34: =O34+J34 -> 0 | S34: =(J34*K34%)+(O34*P34%) -> 0 | T34: =(J34*L34%)+(O34*Q34%) -> 0 | AA34: =X34*Y34% -> 0 | AB34: =X34*Z34% -> 0 | AF34: =AC34*AD34% -> 0 | AG34: =AC34*AE34% -> 0 | AK34: =AH34*AI34% -> 0 | AL34: =AH34*AJ34% -> 0 | AM34: =+D34+R34-AC34-AH34 -> 0 | AN34: =+G34+S34-AF34-AK34 -> 0 | AO34: =+H34+T34-AG34-AL34 -> 0 | AP34: =(AN34+AO34)/(S34+T34) -> #DIV/0! | AQ34: =($AP$1*AN34+$AQ$1*AO34) -> 0 | AR34: =(D34+J34+O34)-(X34+AH34) -> 0
B35: =+B33+1 -> 46069 | C35: E | G35: =+D35*E35% -> 0 | H35: =+D35*F35% -> 0 | J35: =I35 -> 0 | R35: =O35+J35 -> 0 | S35: =(J35*K35%)+(O35*P35%) -> 0 | T35: =(J35*L35%)+(O35*Q35%) -> 0 | AA35: =X35*Y35% -> 0 | AB35: =X35*Z35% -> 0 | AF35: =AC35*AD35% -> 0 | AG35: =AC35*AE35% -> 0 | AK35: =AH35*AI35% -> 0 | AL35: =AH35*AJ35% -> 0 | AM35: =+D35+R35-AC35-AH35 -> 0 | AN35: =+G35+S35-AF35-AK35 -> 0 | AO35: =+H35+T35-AG35-AL35 -> 0 | AP35: =(AN35+AO35)/(S35+T35) -> #DIV/0! | AQ35: =($AP$1*AN35+$AQ$1*AO35) -> 0 | AR35: =(D35+J35+O35)-(X35+AH35) -> 0
B36: =+B34+1 -> 46070 | C36: M | G36: =+D36*E36% -> 0 | H36: =+D36*F36% -> 0 | J36: =I36 -> 0 | R36: =O36+J36 -> 0 | S36: =(J36*K36%)+(O36*P36%) -> 0 | T36: =(J36*L36%)+(O36*Q36%) -> 0 | AA36: =X36*Y36% -> 0 | AB36: =X36*Z36% -> 0 | AF36: =AC36*AD36% -> 0 | AG36: =AC36*AE36% -> 0 | AK36: =AH36*AI36% -> 0 | AL36: =AH36*AJ36% -> 0 | AM36: =+D36+R36-AC36-AH36 -> 0 | AN36: =+G36+S36-AF36-AK36 -> 0 | AO36: =+H36+T36-AG36-AL36 -> 0 | AP36: =(AN36+AO36)/(S36+T36) -> #DIV/0! | AQ36: =($AP$1*AN36+$AQ$1*AO36) -> 0 | AR36: =(D36+J36+O36)-(X36+AH36) -> 0
B37: =+B35+1 -> 46070 | C37: E | G37: =+D37*E37% -> 0 | H37: =+D37*F37% -> 0 | J37: =I37 -> 0 | R37: =O37+J37 -> 0 | S37: =(J37*K37%)+(O37*P37%) -> 0 | T37: =(J37*L37%)+(O37*Q37%) -> 0 | AA37: =X37*Y37% -> 0 | AB37: =X37*Z37% -> 0 | AF37: =AC37*AD37% -> 0 | AG37: =AC37*AE37% -> 0 | AK37: =AH37*AI37% -> 0 | AL37: =AH37*AJ37% -> 0 | AM37: =+D37+R37-AC37-AH37 -> 0 | AN37: =+G37+S37-AF37-AK37 -> 0 | AO37: =+H37+T37-AG37-AL37 -> 0 | AP37: =(AN37+AO37)/(S37+T37) -> #DIV/0! | AQ37: =($AP$1*AN37+$AQ$1*AO37) -> 0 | AR37: =(D37+J37+O37)-(X37+AH37) -> 0
B38: =+B36+1 -> 46071 | C38: M | G38: =+D38*E38% -> 0 | H38: =+D38*F38% -> 0 | J38: =I38 -> 0 | R38: =O38+J38 -> 0 | S38: =(J38*K38%)+(O38*P38%) -> 0 | T38: =(J38*L38%)+(O38*Q38%) -> 0 | AA38: =X38*Y38% -> 0 | AB38: =X38*Z38% -> 0 | AF38: =AC38*AD38% -> 0 | AG38: =AC38*AE38% -> 0 | AK38: =AH38*AI38% -> 0 | AL38: =AH38*AJ38% -> 0 | AM38: =+D38+R38-AC38-AH38 -> 0 | AN38: =+G38+S38-AF38-AK38 -> 0 | AO38: =+H38+T38-AG38-AL38 -> 0 | AP38: =(AN38+AO38)/(S38+T38) -> #DIV/0! | AQ38: =($AP$1*AN38+$AQ$1*AO38) -> 0 | AR38: =(D38+J38+O38)-(X38+AH38) -> 0
B39: =+B37+1 -> 46071 | C39: E | G39: =+D39*E39% -> 0 | H39: =+D39*F39% -> 0 | J39: =I39 -> 0 | R39: =O39+J39 -> 0 | S39: =(J39*K39%)+(O39*P39%) -> 0 | T39: =(J39*L39%)+(O39*Q39%) -> 0 | AA39: =X39*Y39% -> 0 | AB39: =X39*Z39% -> 0 | AF39: =AC39*AD39% -> 0 | AG39: =AC39*AE39% -> 0 | AK39: =AH39*AI39% -> 0 | AL39: =AH39*AJ39% -> 0 | AM39: =+D39+R39-AC39-AH39 -> 0 | AN39: =+G39+S39-AF39-AK39 -> 0 | AO39: =+H39+T39-AG39-AL39 -> 0 | AP39: =(AN39+AO39)/(S39+T39) -> #DIV/0! | AQ39: =($AP$1*AN39+$AQ$1*AO39) -> 0 | AR39: =(D39+J39+O39)-(X39+AH39) -> 0
... B65: =+B63+1 -> 46084 | C65: E | G65: =+D65*E65% -> 0 | H65: =+D65*F65% -> 0 | J65: =I65 -> 0 | R65: =O65+J65 -> 0 | S65: =(J65*K65%)+(O65*P65%) -> 0 | T65: =(J65*L65%)+(O65*Q65%) -> 0 | AA65: =X65*Y65% -> 0 | AB65: =X65*Z65% -> 0 | AF65: =AC65*AD65% -> 0 | AG65: =AC65*AE65% -> 0 | AK65: =AH65*AI65% -> 0 | AL65: =AH65*AJ65% -> 0 | AM65: =+D65+R65-AC65-AH65 -> 0 | AN65: =+G65+S65-AF65-AK65 -> 0 | AO65: =+H65+T65-AG65-AL65 -> 0 | AP65: =(AN65+AO65)/(S65+T65) -> #DIV/0! | AQ65: =($AP$1*AN65+$AQ$1*AO65) -> 0 | AR65: =(D65+J65+O65)-(X65+AH65) -> 0
...

Sheet DSC_Master
A1: union_code | B1: bmc_code | C1: dcs_code | D1: society_code_ex | E1: society_name | F1: dcs_short_name | G1: address | H1: Mobile No | I1: ifsc | J1: bank_account_no | K1: beneficiary_name | L1: route | S1: Row Labels | T1: No of Society | U1: Sum of Balance Payable/Recoverable
A2: 001 | B2: 1062 | C2: 10620001 | D2: 64540 | E2: AKHILESH PANDEY | F2: KARARI DSK | G2: KARARI ,KAIMUR,MOANIA,BIHAR , 821105 | H2: 9934591684 | I2: HDFC0002625 | J2: 50100615862020 | K2: AKHILESH PANDEY | L2: 106201 | S2: 0 | T2: 10 | U2: 0
A3: 001 | B3: 1062 | C3: 10620002 | D3: 64592 | E3: BAL GOPAL YADAV | F3: UDHAPURA DSK | G3: UDHAPURA ,KAIMUR,MOANIA,BIHAR , 821105 | H3: 8924850648 | I3: SBIN0000076 | J3: 37483995547 | K3: BAL GOPAL YADAV | L3: 106201 | S3: Excess payment | T3: 3 | U3: -247810.4
A4: 001 | B4: 1062 | C4: 10620003 | D4: 64520 | E4: BANSI DHAR SINGH | F4: BICHHIYA DSK | G4: BICHHIYA ,KAIMUR,MOANIA,BIHAR , 821105 | H4: 7352968008 | I4: PUNB0237400 | J4: 2374000100106055 | K4: BANSI DHAR SINGH | L4: 106201 | S4: No Pouring | T4: 13 | U4: -205623.89
A5: 001 | B5: 1062 | C5: 10620004 | D5: 64600 | E5: DEEPAK KUMAR YADAV | F5: BHAMBHHOR DSK | G5: BHAMBHHOR ,KAIMUR,MOANIA,BIHAR , 821109 | H5: 6303590024 | I5: UTIB0001632 | J5: 924010010956816 | K5: DEEPAK KUMAR YADAV | L5: 106201 | S5: Recovery from cycle | T5: 16 | U5: -172704.2
A6: 001 | B6: 1062 | C6: 10620005 | D6: 64505 | E6: DINESH KUMAR | F6: MAHUWARIYA DSK | G6: MAHUWARIYA ,KAIMUR,MOANIA,BIHAR , 821105 | H6: 8603752849 | I6: SBIN0014328 | J6: 20315506501 | K6: DINESH KUMAR | L6: 106201 | S6: Payable to MPG | T6: 58 | U6: 2175338.7
A7: 001 | B7: 1062 | C7: 10620006 | D7: 64601 | E7: JAY PRAKASH PANDEY | F7: SIRIYAUA DSK | G7: SIRIYAUA ,KAIMUR,MOANIA,BIHAR , 821110 | H7: 7077788223 | I7: PUNB0278400 | J7: 2784000100290227 | K7: JAY PRAKASH PANDEY | L7: 106201 | S7: Grand Total | T7: 100 | U7: 1549200.3
A8: 001 | B8: 1062 | C8: 10620007 | D8: 64546 | E8: UDEY PRATAP DUBEY | F8: KURRA DSK | G8: KURRA ,KAIMUR,MOANIA,BIHAR , 821109 | H8: 9113390853 | I8: BKID0004619 | J8: 461918210002275 | K8: UDAY PRATAP DUBEY | L8: 106201
A9: 001 | B9: 1062 | C9: 10620008 | D9: 64544 | E9: KAMLESH SINGH | F9: ASHUDHA DSK | G9: ASHUDHA ,KAIMUR,MOANIA,BIHAR , 821110 | H9: 6200554595 | I9: BDBL0001544 | J9: 20100077569381 | K9: KAMLESH SINGH | L9: 106201
A10: 001 | B10: 1062 | C10: 10620009 | D10: 64571 | E10: KANHAIYA YADAV | F10: JAVRI DSK | G10: JAVRI ,KAIMUR,MOANIA,BIHAR , 821105 | H10: 7004978468 | I10: SBIN0014328 | J10: 42108869535 | K10: KANHAIYA YADAV | L10: 106201
A11: 001 | B11: 1062 | C11: 10620010 | D11: 64508 | E11: KHUSHABU YADAV | F11: LARMA DSK | G11: LARMA ,KAIMUR,MOANIA,BIHAR , 821105 | H11: 9065296057 | I11: PUNB0236700 | J11: 2367000100137224 | K11: KHUSHABU YADAV | L11: 106201
A12: 001 | B12: 1062 | C12: 10620011 | D12: 64556 | E12: MALTI DEVI | F12: KABILASPUR DSK | G12: KABILASPUR ,KAIMUR,MOANIA,BIHAR , 821105 | H12: 6200620118 | I12: PUNB0237400 | J12: 2374002100002492 | K12: MALTI DEVI | L12: 106201
A13: 001 | B13: 1062 | C13: 10620012 | D13: 64515 | E13: MR SHREE NIWAS YADAV | F13: DHARHARA DSK | G13: DHARARA ,KAIMUR,MOANIA,BIHAR , 821105 | H13: 7783847657 | I13: SBIN0006137 | J13: 37905177514 | K13: SHREE NIWAS YADAV | L13: 106201
A14: 001 | B14: 1062 | C14: 10620013 | D14: 64523 | E14: Mr SONU KUMAR | F14: KHADSARA DSK | G14: KHARSARA ,KAIMUR,MOANIA,BIHAR , 821105 | H14: 8757865353 | I14: SBIN0014328 | J14: 20421372063 | K14: SONU KUMAR | L14: 106201
A15: 001 | B15: 1062 | C15: 10620014 | D15: 60628 | E15: PARASH SINGH | F15: BAIJNATH DSK | G15: BAIJNATH ,KAIMUR,MOANIA,BIHAR , 821110 | H15: 9905772355 | I15: PUNB0278400 | J15: 2784000100175715 | K15: PARASH SINGH | L15: 106201
A16: 001 | B16: 1062 | C16: 10620015 | D16: 64537 | E16: PAWAN KUMAR SINGH | F16: KASTHARI DSK | G16: KASTHARI ,KAIMUR,MOANIA,BIHAR , 821105 | H16: 9905909472 | I16: PUNB0237400 | J16: 2374001500005364 | K16: PAWAN KUMAR SINGH | L16: 106201
A17: 001 | B17: 1062 | C17: 10620016 | D17: 64522 | E17: RAM CHARAN RAI | F17: MADANPURA DSK | G17: MADANPURA ,KAIMUR,MOANIA,BIHAR , 821105 | H17: 9065026841 | I17: PUNB0237400 | J17: 2374000100165377 | K17: RAM CHARAN RAI | L17: 106201
A18: 001 | B18: 1062 | C18: 10620017 | D18: 64555 | E18: SATENDRA YADAV | F18: DEHWALIYA DSK | G18: DEHVALYA ,KAIMUR,MOANIA,BIHAR , 821105 | H18: 9625596113 | I18: PUNB0269600 | J18: 14462413000951 | K18: SATENDRA YADAV | L18: 106201
A19: 001 | B19: 1062 | C19: 10620018 | D19: 64591 | E19: SAVARU SINGH | F19: LURPURWA DSK | G19: LURPURWA ,KAIMUR,MOANIA,BIHAR , 821109 | H19: 8002591740 | I19: UBIN0560308 | J19: 603002010018335 | K19: SAVARU SINGH | L19: 106201
... A99: 001 | B99: 1062 | C99: 10620098 | D99: 64579 | E99: VIKASH RAI | F99: RAJAPUR DSK | G99: RAJPUR ,BUXER,DUMRAWN,BIHAR , 802131 | H99: 9831104177 | I99: KARB0000294 | J99: 2942500100123701 | K99: VIKASH RAI | L99: 106201
A100: 001 | B100: 1062 | C100: 10620099 | D100: 64504 | E100: SURESH KHARWAR | F100: NONAR DSK | H100: 6203275422 | I100: PUNB0278400 | J100: 2784000100286464 | K100: SURESH KHARWAR | L100: 106201
