Workbook

Sheet PDF
A1: MCC | B1: (All) | C1: Sahayak Comission Month Of Oct'25
C3: Values
A4: Code | B4: MPG NAME | C4: BMC Volume | D4: BMC Amount | E4: Sahayak Comission @ 0.75/- | F4: Std gain @ 0.95/- | G4: Farmer Sample Milk | H4: AMC from MPG @ 0.10/- | I4: Actual Volume Penalty | J4: Net Sahayak Income | K4: New Assets EMI | L4: Can Deduction | M4: PCB Ded | N4: Other | O4: Consumables | P4: Payble to Sahyak | Q4: Hold | R4: Net Payble
A5: 10120099 | B5: GOMUKH Chiranjipur | C5: 11844.5 | D5: 450545.24 | E5: 8883.375 | F5: 11252.275 | G5: 0 | H5: 1184.45 | I5: 0 | J5: 18951 | K5: 0 | L5: 0 | M5: 0 | N5: 0 | O5: 0 | P5: 18951 | Q5: 0 | R5: 18951
A6: 10120099 Total | C6: 11844.5 | D6: 450545.24 | E6: 8883.375 | F6: 11252.275 | G6: 0 | H6: 1184.45 | I6: 0 | J6: 18951 | K6: 0 | L6: 0 | M6: 0 | N6: 0 | O6: 0 | P6: 18951 | Q6: 0 | R6: 18951
A8: Grand Total | C8: 11844.5 | D8: 450545.24 | E8: 8883.375 | F8: 11252.275 | G8: 0 | H8: 1184.45 | I8: 0 | J8: 18951 | K8: 0 | L8: 0 | M8: 0 | N8: 0 | O8: 0 | P8: 18951 | Q8: 0 | R8: 18951

Sheet Shayak Income 
M1: MPG Payment | Q1: MPG Sheet | R1: Internal | T1: MPG Deduction | W1: Other Security Deduction | AG1: -1
A2: Opening Balance ____ | M2: =SUBTOTAL(9,M4:M1057) -> 4064088.6 | N2: =SUBTOTAL(9,N4:N1057) -> 1.6645502e+08 | O2: Income | W2: =SUBTOTAL(9,W4:W1057) -> 828722.81 | X2: =SUBTOTAL(9,X4:X1057) -> 88989.118 | Y2: =SUBTOTAL(9,Y4:Y1057) -> 46315 | Z2: =SUBTOTAL(9,Z4:Z1057) -> 77099.34 | AA2: =SUBTOTAL(9,AA4:AA1057) -> 53086.634 | AB2: =SUBTOTAL(9,AB4:AB1057) -> 5314485 | AC2: =SUBTOTAL(9,AC4:AC1057) -> 254097 | AD2: =SUBTOTAL(9,AD4:AD1057) -> 5060388 | AG2: -1 | AN2: =SUBTOTAL(9,AN4:AN1057) -> 1239371.5 | AO2: =SUBTOTAL(9,AO4:AO1057) -> 130688 | AP2: =SUBTOTAL(9,AP4:AP1057) -> 828722.81 | AQ2: =SUBTOTAL(9,AQ4:AQ1057) -> 959410.81
A3: AMCU | B3: Milk Cans | C3: Assets Value | D3: Code | E3: MPG NAME | F3: Amcu type | G3: VLC Type | H3: Farmer Payment | I3: BMC Code | J3: MCC | K3: status | L3: Start Date | M3: BMC Volume | N3: BMC Amount | O3: Sahayak Comission @ 0.75/- | P3: Std gain @ 0.95/- | Q3: Farmer Sample Milk | R3: Std Gain @ 3% | S3: Reserve from Std Gain | T3: AMC from MPG @ 0.10/- | U3: Actual Volume Penalty | V3: Net Sahayak Income | W3: New Assets EMI | X3: Can Deduction | Y3: PCB Ded | Z3: Other | AA3: Consumables | AB3: Payble to Sahyak | AC3: Hold | AD3: Net Payble | AE3: Payment relase | AG3: Stop Payment | AH3: Remarks | AI3: Pending Down Payment | AJ3: Recommendation | AK3: 31-06 Aug | AL3: Irregular Pourer | AM3: No of pouring shift | AN3: EMI | AO3: Recovery from Milk | AP3: Recovery from Com | AQ3: Net Recovered | AT3: HDFC | AU3: OTHER | AV3: Remarks
A4: =IFERROR(VLOOKUP(D4,'Monthly Deduction'!$I$3:$J$957,2,0),0) -> 19281.576 | B4: =IFERROR(VLOOKUP(D4,'Monthly Deduction'!$E$3:$F$957,2,0),0) -> 16000 | C4: =A4+B4 -> 35281.576 | D4: 10010013 | E4: =VLOOKUP(D4,'MPG Payment '!$E$3:$G$497305,2,0) -> Gomukh Kumbhi | F4: =IFERROR(_xlfn.XLOOKUP(D4,'Monthly Deduction'!$I$3:$I$957,'Monthly Deduction'!$H$3:$H$957),0) -> 0 | G4: =VLOOKUP(D4,'MPG Payment '!$E$3:$G$333666,3,0) -> MPG | H4: =VLOOKUP(D4,'MPG Payment '!$E$3:$H$333666,4,0) -> Direct | I4: =INDEX('MPG Payment '!$C:$C,MATCH('Shayak Income '!D4,'MPG Payment '!E:E,0)) -> 1001 | J4: =INDEX('MPG Payment '!$D:$D,MATCH('Shayak Income '!D4,'MPG Payment '!E:E,0)) -> Majhaul | K4: Old | L4: 45013 | M4: =SUMIF('MPG Payment '!$E$3:$E$344841,'Shayak Income '!D4,'MPG Payment '!$I$3:$I$344841) -> 2231.3 | N4: =SUMIF('MPG Payment '!$E$3:$E$344841,'Shayak Income '!D4,'MPG Payment '!$J$3:$J$344841) -> 84420.7 | O4: =+M4*0.75 -> 1673.475 | P4: =+M4*0.95 -> 2119.735 | Q4: =SUMIF('MPG Payment '!$E$3:$E$344841,'Shayak Income '!D4,'MPG Payment '!$S$3:$S$344841) -> 265.22 | R4: =+N4*3% -> 2532.621 | S4: =R4-P4 -> 412.886 | T4: =M4*0.1 -> 223.13 | U4: =((((((IF(K4="New",0,SUMIF('MPG Payment '!$E$3:$E$344841,'Shayak Income '!D4,'MPG Payment '!$AC$3:$AC$344841))))+0)+0)+0)+0)+0 -> 431.93841 | V4: =ROUND((SUM(O4:Q4)-SUM(T4:U4)),0) -> 3403 | W4: =(((AN4-AO4)))+0 -> 1861 | X4: 0 | Y4: =IFERROR(VLOOKUP(D4,'Monthly Deduction'!$M$2:$N$640,2,0),0) -> 0 | Z4: 0 | AA4: =IFERROR(VLOOKUP(D4,'Monthly Deduction'!A:B,2,0),0) -> 0 | AB4: =ROUND(IFERROR(V4-SUM(W4:AA4),0),0) -> 1542 | AC4: 0 | AD4: =ROUND(AB4-AC4,0) -> 1542 | AE4: =IF(AC4<>0,"Yes","Release") -> Release | AG4: 0 | AI4: 0 | AK4: 372.9 | AL4: =COUNTIF(AK4:AK4,"=NA") -> 0 | AN4: =((MIN(IF(A4>0,MAX(N4*2%,1861),0),A4)))+0 -> 1861 | AO4: =SUMIF('MPG Payment '!E:E,'Shayak Income '!D4,'MPG Payment '!AJ:AJ) -> 0 | AP4: =W4 -> 1861 | AQ4: =AO4+AP4 -> 1861 | AS4: =B4-X4 -> 16000
A5: =IFERROR(VLOOKUP(D5,'Monthly Deduction'!$I$3:$J$957,2,0),0) -> 24418.274 | B5: =IFERROR(VLOOKUP(D5,'Monthly Deduction'!$E$3:$F$957,2,0),0) -> 6400 | C5: =A5+B5 -> 30818.274 | D5: 10010019 | E5: =VLOOKUP(D5,'MPG Payment '!$E$3:$G$497305,2,0) -> Gomukh Jagdar | F5: =IFERROR(_xlfn.XLOOKUP(D5,'Monthly Deduction'!$I$3:$I$957,'Monthly Deduction'!$H$3:$H$957),0) -> 0 | G5: =VLOOKUP(D5,'MPG Payment '!$E$3:$G$333666,3,0) -> MPG | H5: =VLOOKUP(D5,'MPG Payment '!$E$3:$H$333666,4,0) -> Direct | I5: =INDEX('MPG Payment '!$C:$C,MATCH('Shayak Income '!D5,'MPG Payment '!E:E,0)) -> 1001 | J5: =INDEX('MPG Payment '!$D:$D,MATCH('Shayak Income '!D5,'MPG Payment '!E:E,0)) -> Majhaul | K5: Old | L5: 45040 | M5: =SUMIF('MPG Payment '!$E$3:$E$344841,'Shayak Income '!D5,'MPG Payment '!$I$3:$I$344841) -> 3615.7 | N5: =SUMIF('MPG Payment '!$E$3:$E$344841,'Shayak Income '!D5,'MPG Payment '!$J$3:$J$344841) -> 140356.54 | O5: =+M5*0.75 -> 2711.775 | P5: =+M5*0.95 -> 3434.915 | Q5: =SUMIF('MPG Payment '!$E$3:$E$344841,'Shayak Income '!D5,'MPG Payment '!$S$3:$S$344841) -> 1821.46 | R5: =+N5*3% -> 4210.6962 | S5: =R5-P5 -> 775.7812 | T5: =M5*0.1 -> 361.57 | U5: =((((((IF(K5="New",0,SUMIF('MPG Payment '!$E$3:$E$344841,'Shayak Income '!D5,'MPG Payment '!$AC$3:$AC$344841))))+0)+0)+0)+0)+0 -> 0 | V5: =ROUND((SUM(O5:Q5)-SUM(T5:U5)),0) -> 7607 | W5: =(((AN5-AO5)))+0 -> 2807.1308 | X5: 0 | Y5: =IFERROR(VLOOKUP(D5,'Monthly Deduction'!$M$2:$N$640,2,0),0) -> 0 | Z5: 0 | AA5: =IFERROR(VLOOKUP(D5,'Monthly Deduction'!A:B,2,0),0) -> 0 | AB5: =ROUND(IFERROR(V5-SUM(W5:AA5),0),0) -> 4800 | AC5: 0 | AD5: =ROUND(AB5-AC5,0) -> 4800 | AE5: =IF(AC5<>0,"Yes","Release") -> Release | AG5: 0 | AI5: 0 | AK5: 822.2 | AL5: =COUNTIF(AK5:AK5,"=NA") -> 0 | AN5: =((MIN(IF(A5>0,MAX(N5*2%,1861),0),A5)))+0 -> 2807.1308 | AO5: =SUMIF('MPG Payment '!E:E,'Shayak Income '!D5,'MPG Payment '!AJ:AJ) -> 0 | AP5: =W5 -> 2807.1308 | AQ5: =AO5+AP5 -> 2807.1308 | AS5: =B5-X5 -> 6400
A6: =IFERROR(VLOOKUP(D6,'Monthly Deduction'!$I$3:$J$957,2,0),0) -> 29772.487 | B6: =IFERROR(VLOOKUP(D6,'Monthly Deduction'!$E$3:$F$957,2,0),0) -> 5744.916 | C6: =A6+B6 -> 35517.403 | D6: 10010038 | E6: =VLOOKUP(D6,'MPG Payment '!$E$3:$G$497305,2,0) -> Gomukh Goriyari | F6: =IFERROR(_xlfn.XLOOKUP(D6,'Monthly Deduction'!$I$3:$I$957,'Monthly Deduction'!$H$3:$H$957),0) -> 0 | G6: =VLOOKUP(D6,'MPG Payment '!$E$3:$G$333666,3,0) -> MPG | H6: =VLOOKUP(D6,'MPG Payment '!$E$3:$H$333666,4,0) -> Direct | I6: =INDEX('MPG Payment '!$C:$C,MATCH('Shayak Income '!D6,'MPG Payment '!E:E,0)) -> 1058 | J6: =INDEX('MPG Payment '!$D:$D,MATCH('Shayak Income '!D6,'MPG Payment '!E:E,0)) -> Hasanpur | K6: Old | L6: 45128 | M6: =SUMIF('MPG Payment '!$E$3:$E$344841,'Shayak Income '!D6,'MPG Payment '!$I$3:$I$344841) -> 3578.58 | N6: =SUMIF('MPG Payment '!$E$3:$E$344841,'Shayak Income '!D6,'MPG Payment '!$J$3:$J$344841) -> 143943.17 | O6: =+M6*0.75 -> 2683.935 | P6: =+M6*0.95 -> 3399.651 | Q6: =SUMIF('MPG Payment '!$E$3:$E$344841,'Shayak Income '!D6,'MPG Payment '!$S$3:$S$344841) -> 862.01 | R6: =+N6*3% -> 4318.2951 | S6: =R6-P6 -> 918.6441 | T6: =M6*0.1 -> 357.858 | U6: =((((((IF(K6="New",0,SUMIF('MPG Payment '!$E$3:$E$344841,'Shayak Income '!D6,'MPG Payment '!$AC$3:$AC$344841))))+0)+0)+0)+0)+0 -> 0 | V6: =ROUND((SUM(O6:Q6)-SUM(T6:U6)),0) -> 6588 | W6: =(((AN6-AO6)))+0 -> 2878.8634 | X6: 0 | Y6: =IFERROR(VLOOKUP(D6,'Monthly Deduction'!$M$2:$N$640,2,0),0) -> 0 | Z6: 413 | AA6: =IFERROR(VLOOKUP(D6,'Monthly Deduction'!A:B,2,0),0) -> 0 | AB6: =ROUND(IFERROR(V6-SUM(W6:AA6),0),0) -> 3296 | AC6: 0 | AD6: =ROUND(AB6-AC6,0) -> 3296 | AE6: =IF(AC6<>0,"Yes","Release") -> Release | AG6: 0 | AH6: EIPL Deduction | AI6: 0 | AK6: 763.02 | AL6: =COUNTIF(AK6:AK6,"=NA") -> 0 | AN6: =((MIN(IF(A6>0,MAX(N6*2%,1861),0),A6)))+0 -> 2878.8634 | AO6: =SUMIF('MPG Payment '!E:E,'Shayak Income '!D6,'MPG Payment '!AJ:AJ) -> 0 | AP6: =W6 -> 2878.8634 | AQ6: =AO6+AP6 -> 2878.8634 | AS6: =B6-X6 -> 5744.916
A7: =IFERROR(VLOOKUP(D7,'Monthly Deduction'!$I$3:$J$957,2,0),0) -> 0 | B7: =IFERROR(VLOOKUP(D7,'Monthly Deduction'!$E$3:$F$957,2,0),0) -> 0 | C7: =A7+B7 -> 0 | D7: 10010047 | E7: =VLOOKUP(D7,'MPG Payment '!$E$3:$G$497305,2,0) -> Mohanpur - Chandan | F7: =IFERROR(_xlfn.XLOOKUP(D7,'Monthly Deduction'!$I$3:$I$957,'Monthly Deduction'!$H$3:$H$957),0) -> 0 | G7: =VLOOKUP(D7,'MPG Payment '!$E$3:$G$333666,3,0) -> vlc | H7: =VLOOKUP(D7,'MPG Payment '!$E$3:$H$333666,4,0) -> Indirect | I7: =INDEX('MPG Payment '!$C:$C,MATCH('Shayak Income '!D7,'MPG Payment '!E:E,0)) -> 1001 | J7: =INDEX('MPG Payment '!$D:$D,MATCH('Shayak Income '!D7,'MPG Payment '!E:E,0)) -> Majhaul | K7: Old | L7: 45121 | M7: =SUMIF('MPG Payment '!$E$3:$E$344841,'Shayak Income '!D7,'MPG Payment '!$I$3:$I$344841) -> 527.9 | N7: =SUMIF('MPG Payment '!$E$3:$E$344841,'Shayak Income '!D7,'MPG Payment '!$J$3:$J$344841) -> 20684.89 | O7: =+M7*0.75 -> 395.925 | P7: =+M7*0.95 -> 501.505 | Q7: =SUMIF('MPG Payment '!$E$3:$E$344841,'Shayak Income '!D7,'MPG Payment '!$S$3:$S$344841) -> 0 | R7: =+N7*3% -> 620.5467 | S7: =R7-P7 -> 119.0417 | T7: =M7*0.1 -> 52.79 | U7: =((((((IF(K7="New",0,SUMIF('MPG Payment '!$E$3:$E$344841,'Shayak Income '!D7,'MPG Payment '!$AC$3:$AC$344841))))+0)+0)+0)+0)+-952 -> 844.17392 | V7: =ROUND((SUM(O7:Q7)-SUM(T7:U7)),0) -> 0 | W7: 0 | X7: 0 | Y7: 0 | Z7: 0 | AA7: 0 | AB7: =ROUND(IFERROR(V7-SUM(W7:AA7),0),0) -> 0 | AC7: 0 | AD7: =ROUND(AB7-AC7,0) -> 0 | AE7: =IF(AC7<>0,"Yes","Release") -> Release | AG7: 0 | AI7: 0 | AK7: 28.13 | AL7: =COUNTIF(AK7:AK7,"=NA") -> 0 | AN7: =((MIN(IF(A7>0,MAX(N7*2%,1861),0),A7)))+0 -> 0 | AO7: =SUMIF('MPG Payment '!E:E,'Shayak Income '!D7,'MPG Payment '!AJ:AJ) -> 0 | AP7: =W7 -> 0 | AQ7: =AO7+AP7 -> 0 | AS7: =B7-X7 -> 0
A8: =IFERROR(VLOOKUP(D8,'Monthly Deduction'!$I$3:$J$957,2,0),0) -> 30233.6 | B8: =IFERROR(VLOOKUP(D8,'Monthly Deduction'!$E$3:$F$957,2,0),0) -> 0 | C8: =A8+B8 -> 30233.6 | D8: 10010050 | E8: =VLOOKUP(D8,'MPG Payment '!$E$3:$G$497305,2,0) -> Ekamba - Ashutosh | F8: =IFERROR(_xlfn.XLOOKUP(D8,'Monthly Deduction'!$I$3:$I$957,'Monthly Deduction'!$H$3:$H$957),0) -> 0 | G8: =VLOOKUP(D8,'MPG Payment '!$E$3:$G$333666,3,0) -> vlc | H8: =VLOOKUP(D8,'MPG Payment '!$E$3:$H$333666,4,0) -> Indirect | I8: =INDEX('MPG Payment '!$C:$C,MATCH('Shayak Income '!D8,'MPG Payment '!E:E,0)) -> 1058 | J8: =INDEX('MPG Payment '!$D:$D,MATCH('Shayak Income '!D8,'MPG Payment '!E:E,0)) -> Hasanpur | K8: Old | L8: 45098 | M8: =SUMIF('MPG Payment '!$E$3:$E$344841,'Shayak Income '!D8,'MPG Payment '!$I$3:$I$344841) -> 5015.62 | N8: =SUMIF('MPG Payment '!$E$3:$E$344841,'Shayak Income '!D8,'MPG Payment '!$J$3:$J$344841) -> 217108.75 | O8: =+M8*0.75 -> 3761.715 | P8: =+M8*0.95 -> 4764.839 | Q8: =SUMIF('MPG Payment '!$E$3:$E$344841,'Shayak Income '!D8,'MPG Payment '!$S$3:$S$344841) -> 0 | R8: =+N8*3% -> 6513.2625 | S8: =R8-P8 -> 1748.4235 | T8: =M8*0.1 -> 501.562 | U8: =((((((IF(K8="New",0,SUMIF('MPG Payment '!$E$3:$E$344841,'Shayak Income '!D8,'MPG Payment '!$AC$3:$AC$344841))))+0)+0)+0)+0)+0 -> 0 | V8: =ROUND((SUM(O8:Q8)-SUM(T8:U8)),0) -> 8025 | W8: =(((AN8-AO8)))+0 -> 4342.175 | X8: 0 | Y8: =IFERROR(VLOOKUP(D8,'Monthly Deduction'!$M$2:$N$640,2,0),0) -> 0 | Z8: 0 | AA8: =IFERROR(VLOOKUP(D8,'Monthly Deduction'!A:B,2,0),0) -> 0 | AB8: =ROUND(IFERROR(V8-SUM(W8:AA8),0),0) -> 3683 | AC8: 0 | AD8: =ROUND(AB8-AC8,0) -> 3683 | AE8: =IF(AC8<>0,"Yes","Release") -> Release | AG8: 0 | AI8: 0 | AK8: 977.33 | AL8: =COUNTIF(AK8:AK8,"=NA") -> 0 | AN8: =((MIN(IF(A8>0,MAX(N8*2%,1861),0),A8)))+0 -> 4342.175 | AO8: =SUMIF('MPG Payment '!E:E,'Shayak Income '!D8,'MPG Payment '!AJ:AJ) -> 0 | AP8: =W8 -> 4342.175 | AQ8: =AO8+AP8 -> 4342.175 | AS8: =B8-X8 -> 0
A9: =IFERROR(VLOOKUP(D9,'Monthly Deduction'!$I$3:$J$957,2,0),0) -> 22582.277 | B9: =IFERROR(VLOOKUP(D9,'Monthly Deduction'!$E$3:$F$957,2,0),0) -> 6970.1518 | C9: =A9+B9 -> 29552.429 | D9: 10010051 | E9: =VLOOKUP(D9,'MPG Payment '!$E$3:$G$497305,2,0) -> Gomukh Dunahi | F9: =IFERROR(_xlfn.XLOOKUP(D9,'Monthly Deduction'!$I$3:$I$957,'Monthly Deduction'!$H$3:$H$957),0) -> 0 | G9: =VLOOKUP(D9,'MPG Payment '!$E$3:$G$333666,3,0) -> MPG | H9: =VLOOKUP(D9,'MPG Payment '!$E$3:$H$333666,4,0) -> Direct | I9: =INDEX('MPG Payment '!$C:$C,MATCH('Shayak Income '!D9,'MPG Payment '!E:E,0)) -> 1058 | J9: =INDEX('MPG Payment '!$D:$D,MATCH('Shayak Income '!D9,'MPG Payment '!E:E,0)) -> Hasanpur | K9: Old | L9: 45219 | M9: =SUMIF('MPG Payment '!$E$3:$E$344841,'Shayak Income '!D9,'MPG Payment '!$I$3:$I$344841) -> 81.59 | N9: =SUMIF('MPG Payment '!$E$3:$E$344841,'Shayak Income '!D9,'MPG Payment '!$J$3:$J$344841) -> 3336.3 | O9: =+M9*0.75 -> 61.1925 | P9: =+M9*0.95 -> 77.5105 | Q9: =SUMIF('MPG Payment '!$E$3:$E$344841,'Shayak Income '!D9,'MPG Payment '!$S$3:$S$344841) -> 79.17 | R9: =+N9*3% -> 100.089 | S9: =R9-P9 -> 22.5785 | T9: =M9*0.1 -> 8.159 | U9: =((((((IF(K9="New",0,SUMIF('MPG Payment '!$E$3:$E$344841,'Shayak Income '!D9,'MPG Payment '!$AC$3:$AC$344841))))+0)+0)+0)+0)+-296 -> 209.74857 | V9: =ROUND((SUM(O9:Q9)-SUM(T9:U9)),0) -> 0 | W9: 0 | X9: 0 | Y9: 0 | Z9: 0 | AA9: 0 | AB9: =ROUND(IFERROR(V9-SUM(W9:AA9),0),0) -> 0 | AC9: 0 | AD9: =ROUND(AB9-AC9,0) -> 0 | AE9: =IF(AC9<>0,"Yes","Release") -> Release | AG9: 0 | AI9: 0 | AK9: 155.27 | AL9: =COUNTIF(AK9:AK9,"=NA") -> 0 | AN9: =((MIN(IF(A9>0,MAX(N9*2%,1861),0),A9)))+0 -> 1861 | AO9: =SUMIF('MPG Payment '!E:E,'Shayak Income '!D9,'MPG Payment '!AJ:AJ) -> 0 | AP9: =W9 -> 0 | AQ9: =AO9+AP9 -> 0 | AS9: =B9-X9 -> 6970.1518
A10: =IFERROR(VLOOKUP(D10,'Monthly Deduction'!$I$3:$J$957,2,0),0) -> 78375.427 | B10: =IFERROR(VLOOKUP(D10,'Monthly Deduction'!$E$3:$F$957,2,0),0) -> 6400 | C10: =A10+B10 -> 84775.427 | D10: 10010055 | E10: =VLOOKUP(D10,'MPG Payment '!$E$3:$G$497305,2,0) -> GOMUKH BIRPUR PASCHIM | F10: =IFERROR(_xlfn.XLOOKUP(D10,'Monthly Deduction'!$I$3:$I$957,'Monthly Deduction'!$H$3:$H$957),0) -> 0 | G10: =VLOOKUP(D10,'MPG Payment '!$E$3:$G$333666,3,0) -> MPG | H10: =VLOOKUP(D10,'MPG Payment '!$E$3:$H$333666,4,0) -> Direct | I10: =INDEX('MPG Payment '!$C:$C,MATCH('Shayak Income '!D10,'MPG Payment '!E:E,0)) -> 1001 | J10: =INDEX('MPG Payment '!$D:$D,MATCH('Shayak Income '!D10,'MPG Payment '!E:E,0)) -> Majhaul | K10: Old | L10: 45231 | M10: =SUMIF('MPG Payment '!$E$3:$E$344841,'Shayak Income '!D10,'MPG Payment '!$I$3:$I$344841) -> 398.2 | N10: =SUMIF('MPG Payment '!$E$3:$E$344841,'Shayak Income '!D10,'MPG Payment '!$J$3:$J$344841) -> 16578.31 | O10: =+M10*0.75 -> 298.65 | P10: =+M10*0.95 -> 378.29 | Q10: =SUMIF('MPG Payment '!$E$3:$E$344841,'Shayak Income '!D10,'MPG Payment '!$S$3:$S$344841) -> 0 | R10: =+N10*3% -> 497.3493 | S10: =R10-P10 -> 119.0593 | T10: =M10*0.1 -> 39.82 | U10: =((((((IF(K10="New",0,SUMIF('MPG Payment '!$E$3:$E$344841,'Shayak Income '!D10,'MPG Payment '!$AC$3:$AC$344841))))+0)+0)+0)+0)+-1363 -> 637.05971 | V10: =ROUND((SUM(O10:Q10)-SUM(T10:U10)),0) -> 0 | W10: 0 | X10: 0 | Y10: 0 | Z10: 0 | AA10: 0 | AB10: =ROUND(IFERROR(V10-SUM(W10:AA10),0),0) -> 0 | AC10: 0 | AD10: =ROUND(AB10-AC10,0) -> 0 | AE10: =IF(AC10<>0,"Yes","Release") -> Release | AG10: 0 | AI10: 0 | AK10: 93.83 | AL10: =COUNTIF(AK10:AK10,"=NA") -> 0 | AN10: =((MIN(IF(A10>0,MAX(N10*2%,1861),0),A10)))+0 -> 1861 | AO10: =SUMIF('MPG Payment '!E:E,'Shayak Income '!D10,'MPG Payment '!AJ:AJ) -> 2000 | AP10: =W10 -> 0 | AQ10: =AO10+AP10 -> 2000 | AS10: =B10-X10 -> 6400
A11: =IFERROR(VLOOKUP(D11,'Monthly Deduction'!$I$3:$J$957,2,0),0) -> 0 | B11: =IFERROR(VLOOKUP(D11,'Monthly Deduction'!$E$3:$F$957,2,0),0) -> 0 | C11: =A11+B11 -> 0 | D11: 10010057 | E11: =VLOOKUP(D11,'MPG Payment '!$E$3:$G$497305,2,0) -> Manish Dairy | F11: =IFERROR(_xlfn.XLOOKUP(D11,'Monthly Deduction'!$I$3:$I$957,'Monthly Deduction'!$H$3:$H$957),0) -> 0 | G11: =VLOOKUP(D11,'MPG Payment '!$E$3:$G$333666,3,0) -> vlc | H11: =VLOOKUP(D11,'MPG Payment '!$E$3:$H$333666,4,0) -> Indirect | I11: =INDEX('MPG Payment '!$C:$C,MATCH('Shayak Income '!D11,'MPG Payment '!E:E,0)) -> 1001 | J11: =INDEX('MPG Payment '!$D:$D,MATCH('Shayak Income '!D11,'MPG Payment '!E:E,0)) -> Majhaul | K11: Old | L11: 45000 | M11: =SUMIF('MPG Payment '!$E$3:$E$344841,'Shayak Income '!D11,'MPG Payment '!$I$3:$I$344841) -> 36779.8 | N11: =SUMIF('MPG Payment '!$E$3:$E$344841,'Shayak Income '!D11,'MPG Payment '!$J$3:$J$344841) -> 1389812.2 | O11: =+M11*0.75 -> 27584.85 | P11: =+M11*0.95 -> 34940.81 | Q11: =SUMIF('MPG Payment '!$E$3:$E$344841,'Shayak Income '!D11,'MPG Payment '!$S$3:$S$344841) -> 0 | R11: =+N11*3% -> 41694.365 | S11: =R11-P11 -> 6753.5548 | T11: =M11*0.1 -> 3677.98 | U11: =((((((IF(K11="New",0,SUMIF('MPG Payment '!$E$3:$E$344841,'Shayak Income '!D11,'MPG Payment '!$AC$3:$AC$344841))))+0)+0)+0)+0)+0 -> 0 | V11: =ROUND((SUM(O11:Q11)-SUM(T11:U11)),0) -> 58848 | W11: =(((AN11-AO11)))+0 -> 0 | X11: =((MIN(IF(B11>0,MAX(N11*2%),0),B11)))+0 -> 0 | Y11: =IFERROR(VLOOKUP(D11,'Monthly Deduction'!$M$2:$N$640,2,0),0) -> 0 | Z11: 0 | AA11: =IFERROR(VLOOKUP(D11,'Monthly Deduction'!A:B,2,0),0) -> 0 | AB11: =ROUND(IFERROR(V11-SUM(W11:AA11),0),0) -> 58848 | AC11: 0 | AD11: =ROUND(AB11-AC11,0) -> 58848 | AE11: =IF(AC11<>0,"Yes","Release") -> Release | AG11: 0 | AI11: 0 | AK11: 6216 | AL11: =COUNTIF(AK11:AK11,"=NA") -> 0 | AN11: =((MIN(IF(A11>0,MAX(N11*2%,1861),0),A11)))+0 -> 0 | AO11: =SUMIF('MPG Payment '!E:E,'Shayak Income '!D11,'MPG Payment '!AJ:AJ) -> 0 | AP11: =W11 -> 0 | AQ11: =AO11+AP11 -> 0 | AS11: =B11-X11 -> 0
A12: =IFERROR(VLOOKUP(D12,'Monthly Deduction'!$I$3:$J$957,2,0),0) -> 42586.743 | B12: =IFERROR(VLOOKUP(D12,'Monthly Deduction'!$E$3:$F$957,2,0),0) -> 16599 | C12: =A12+B12 -> 59185.743 | D12: 10010076 | E12: =VLOOKUP(D12,'MPG Payment '!$E$3:$G$497305,2,0) -> Gomukh Bhith-02 | F12: =IFERROR(_xlfn.XLOOKUP(D12,'Monthly Deduction'!$I$3:$I$957,'Monthly Deduction'!$H$3:$H$957),0) -> 0 | G12: =VLOOKUP(D12,'MPG Payment '!$E$3:$G$333666,3,0) -> MPG | H12: =VLOOKUP(D12,'MPG Payment '!$E$3:$H$333666,4,0) -> Direct | I12: =INDEX('MPG Payment '!$C:$C,MATCH('Shayak Income '!D12,'MPG Payment '!E:E,0)) -> 1001 | J12: =INDEX('MPG Payment '!$D:$D,MATCH('Shayak Income '!D12,'MPG Payment '!E:E,0)) -> Majhaul | K12: Old | L12: 45471 | M12: =SUMIF('MPG Payment '!$E$3:$E$344841,'Shayak Income '!D12,'MPG Payment '!$I$3:$I$344841) -> 3203.4 | N12: =SUMIF('MPG Payment '!$E$3:$E$344841,'Shayak Income '!D12,'MPG Payment '!$J$3:$J$344841) -> 140070.81 | O12: =+M12*0.75 -> 2402.55 | P12: =+M12*0.95 -> 3043.23 | Q12: =SUMIF('MPG Payment '!$E$3:$E$344841,'Shayak Income '!D12,'MPG Payment '!$S$3:$S$344841) -> 0 | R12: =+N12*3% -> 4202.1243 | S12: =R12-P12 -> 1158.8943 | T12: =M12*0.1 -> 320.34 | U12: =((((((IF(K12="New",0,SUMIF('MPG Payment '!$E$3:$E$344841,'Shayak Income '!D12,'MPG Payment '!$AC$3:$AC$344841))))+0)+0)+0)+0)+0 -> 98.084929 | V12: =ROUND((SUM(O12:Q12)-SUM(T12:U12)),0) -> 5027 | W12: =(((AN12-AO12)))+0 -> 2801.4162 | X12: 0 | Y12: 2226 | Z12: 0 | AA12: =IFERROR(VLOOKUP(D12,'Monthly Deduction'!A:B,2,0),0) -> 0 | AB12: =ROUND(IFERROR(V12-SUM(W12:AA12),0),0) -> 0 | AC12: 0 | AD12: =ROUND(AB12-AC12,0) -> 0 | AE12: =IF(AC12<>0,"Yes","Release") -> Release | AG12: 0 | AI12: 0 | AK12: 722.58 | AL12: =COUNTIF(AK12:AK12,"=NA") -> 0 | AN12: =((MIN(IF(A12>0,MAX(N12*2%,1861),0),A12)))+0 -> 2801.4162 | AO12: =SUMIF('MPG Payment '!E:E,'Shayak Income '!D12,'MPG Payment '!AJ:AJ) -> 0 | AP12: =W12 -> 2801.4162 | AQ12: =AO12+AP12 -> 2801.4162 | AS12: =B12-X12 -> 16599
A13: =IFERROR(VLOOKUP(D13,'Monthly Deduction'!$I$3:$J$957,2,0),0) -> 17208.325 | B13: =IFERROR(VLOOKUP(D13,'Monthly Deduction'!$E$3:$F$957,2,0),0) -> 25600 | C13: =A13+B13 -> 42808.325 | D13: 10010082 | E13: =VLOOKUP(D13,'MPG Payment '!$E$3:$G$497305,2,0) -> Gomukh Sharmatola Sahuri | F13: =IFERROR(_xlfn.XLOOKUP(D13,'Monthly Deduction'!$I$3:$I$957,'Monthly Deduction'!$H$3:$H$957),0) -> 0 | G13: =VLOOKUP(D13,'MPG Payment '!$E$3:$G$333666,3,0) -> MPG | H13: =VLOOKUP(D13,'MPG Payment '!$E$3:$H$333666,4,0) -> Direct | I13: =INDEX('MPG Payment '!$C:$C,MATCH('Shayak Income '!D13,'MPG Payment '!E:E,0)) -> 1001 | J13: =INDEX('MPG Payment '!$D:$D,MATCH('Shayak Income '!D13,'MPG Payment '!E:E,0)) -> Majhaul | K13: Old | L13: 45568 | M13: =SUMIF('MPG Payment '!$E$3:$E$344841,'Shayak Income '!D13,'MPG Payment '!$I$3:$I$344841) -> 4784.1 | N13: =SUMIF('MPG Payment '!$E$3:$E$344841,'Shayak Income '!D13,'MPG Payment '!$J$3:$J$344841) -> 186101.66 | O13: =+M13*0.75 -> 3588.075 | P13: =+M13*0.95 -> 4544.895 | Q13: =SUMIF('MPG Payment '!$E$3:$E$344841,'Shayak Income '!D13,'MPG Payment '!$S$3:$S$344841) -> 0 | R13: =+N13*3% -> 5583.0498 | S13: =R13-P13 -> 1038.1548 | T13: =M13*0.1 -> 478.41 | U13: =((((((IF(K13="New",0,SUMIF('MPG Payment '!$E$3:$E$344841,'Shayak Income '!D13,'MPG Payment '!$AC$3:$AC$344841))))+0)+0)+0)+0)+0 -> 0 | V13: =ROUND((SUM(O13:Q13)-SUM(T13:U13)),0) -> 7655 | W13: =(((AN13-AO13)))+0 -> 3722.0332 | X13: 0 | Y13: =IFERROR(VLOOKUP(D13,'Monthly Deduction'!$M$2:$N$640,2,0),0) -> 0 | Z13: 0 | AA13: =IFERROR(VLOOKUP(D13,'Monthly Deduction'!A:B,2,0),0) -> 0 | AB13: =ROUND(IFERROR(V13-SUM(W13:AA13),0),0) -> 3933 | AC13: 0 | AD13: =ROUND(AB13-AC13,0) -> 3933 | AE13: =IF(AC13<>0,"Yes","Release") -> Release | AG13: 0 | AI13: 0 | AK13: 1160.54 | AL13: =COUNTIF(AK13:AK13,"=NA") -> 0 | AN13: =((MIN(IF(A13>0,MAX(N13*2%,1861),0),A13)))+0 -> 3722.0332 | AO13: =SUMIF('MPG Payment '!E:E,'Shayak Income '!D13,'MPG Payment '!AJ:AJ) -> 0 | AP13: =W13 -> 3722.0332 | AQ13: =AO13+AP13 -> 3722.0332 | AS13: =B13-X13 -> 25600
A14: =IFERROR(VLOOKUP(D14,'Monthly Deduction'!$I$3:$J$957,2,0),0) -> 0 | B14: =IFERROR(VLOOKUP(D14,'Monthly Deduction'!$E$3:$F$957,2,0),0) -> 0 | C14: =A14+B14 -> 0 | D14: 10010084 | E14: =VLOOKUP(D14,'MPG Payment '!$E$3:$G$497305,2,0) -> Sangat- Sanjeev Kumar | F14: =IFERROR(_xlfn.XLOOKUP(D14,'Monthly Deduction'!$I$3:$I$957,'Monthly Deduction'!$H$3:$H$957),0) -> 0 | G14: =VLOOKUP(D14,'MPG Payment '!$E$3:$G$333666,3,0) -> vlc | H14: =VLOOKUP(D14,'MPG Payment '!$E$3:$H$333666,4,0) -> Indirect | I14: =INDEX('MPG Payment '!$C:$C,MATCH('Shayak Income '!D14,'MPG Payment '!E:E,0)) -> 1001 | J14: =INDEX('MPG Payment '!$D:$D,MATCH('Shayak Income '!D14,'MPG Payment '!E:E,0)) -> Majhaul | K14: Old | L14: 45567 | M14: =SUMIF('MPG Payment '!$E$3:$E$344841,'Shayak Income '!D14,'MPG Payment '!$I$3:$I$344841) -> 1017.7 | N14: =SUMIF('MPG Payment '!$E$3:$E$344841,'Shayak Income '!D14,'MPG Payment '!$J$3:$J$344841) -> 34594.48 | O14: =+M14*0.75 -> 763.275 | P14: =+M14*0.95 -> 966.815 | Q14: =SUMIF('MPG Payment '!$E$3:$E$344841,'Shayak Income '!D14,'MPG Payment '!$S$3:$S$344841) -> 0 | R14: =+N14*3% -> 1037.8344 | S14: =R14-P14 -> 71.0194 | T14: =M14*0.1 -> 101.77 | U14: =((((((IF(K14="New",0,SUMIF('MPG Payment '!$E$3:$E$344841,'Shayak Income '!D14,'MPG Payment '!$AC$3:$AC$344841))))+0)+0)+0)+0)+0 -> 1227.1777 | V14: =ROUND((SUM(O14:Q14)-SUM(T14:U14)),0) -> 401 | W14: =(((AN14-AO14)))+0 -> 0 | X14: =((MIN(IF(B14>0,MAX(N14*2%),0),B14)))+0 -> 0 | Y14: =IFERROR(VLOOKUP(D14,'Monthly Deduction'!$M$2:$N$640,2,0),0) -> 0 | Z14: 0 | AA14: =IFERROR(VLOOKUP(D14,'Monthly Deduction'!A:B,2,0),0) -> 0 | AB14: =ROUND(IFERROR(V14-SUM(W14:AA14),0),0) -> 401 | AC14: 0 | AD14: =ROUND(AB14-AC14,0) -> 401 | AE14: =IF(AC14<>0,"Yes","Release") -> Release | AG14: 0 | AI14: 0 | AK14: 156.3 | AL14: =COUNTIF(AK14:AK14,"=NA") -> 0 | AN14: =((MIN(IF(A14>0,MAX(N14*2%,1861),0),A14)))+0 -> 0 | AO14: =SUMIF('MPG Payment '!E:E,'Shayak Income '!D14,'MPG Payment '!AJ:AJ) -> 0 | AP14: =W14 -> 0 | AQ14: =AO14+AP14 -> 0 | AS14: =B14-X14 -> 0
A15: =IFERROR(VLOOKUP(D15,'Monthly Deduction'!$I$3:$J$957,2,0),0) -> 66070 | B15: =IFERROR(VLOOKUP(D15,'Monthly Deduction'!$E$3:$F$957,2,0),0) -> 6400 | C15: =A15+B15 -> 72470 | D15: 10010086 | E15: =VLOOKUP(D15,'MPG Payment '!$E$3:$G$497305,2,0) -> Gomukh Garhi Bisanpur | F15: =IFERROR(_xlfn.XLOOKUP(D15,'Monthly Deduction'!$I$3:$I$957,'Monthly Deduction'!$H$3:$H$957),0) -> 0 | G15: =VLOOKUP(D15,'MPG Payment '!$E$3:$G$333666,3,0) -> MPG | H15: =VLOOKUP(D15,'MPG Payment '!$E$3:$H$333666,4,0) -> Direct | I15: =INDEX('MPG Payment '!$C:$C,MATCH('Shayak Income '!D15,'MPG Payment '!E:E,0)) -> 1058 | J15: =INDEX('MPG Payment '!$D:$D,MATCH('Shayak Income '!D15,'MPG Payment '!E:E,0)) -> Hasanpur | K15: Old | L15: 45631 | M15: =SUMIF('MPG Payment '!$E$3:$E$344841,'Shayak Income '!D15,'MPG Payment '!$I$3:$I$344841) -> 340.43 | N15: =SUMIF('MPG Payment '!$E$3:$E$344841,'Shayak Income '!D15,'MPG Payment '!$J$3:$J$344841) -> 16211.8 | O15: =+M15*0.75 -> 255.3225 | P15: =+M15*0.95 -> 323.4085 | Q15: =SUMIF('MPG Payment '!$E$3:$E$344841,'Shayak Income '!D15,'MPG Payment '!$S$3:$S$344841) -> 360.83 | R15: =+N15*3% -> 486.354 | S15: =R15-P15 -> 162.9455 | T15: =M15*0.1 -> 34.043 | U15: =((((((IF(K15="New",0,SUMIF('MPG Payment '!$E$3:$E$344841,'Shayak Income '!D15,'MPG Payment '!$AC$3:$AC$344841))))+0)+0)+0)+0)+-1441 -> 906.00265 | V15: =ROUND((SUM(O15:Q15)-SUM(T15:U15)),0) -> 0 | W15: 0 | X15: 0 | Y15: 0 | Z15: 0 | AA15: 0 | AB15: =ROUND(IFERROR(V15-SUM(W15:AA15),0),0) -> 0 | AC15: 0 | AD15: =ROUND(AB15-AC15,0) -> 0 | AE15: =IF(AC15<>0,"Yes","Release") -> Release | AG15: 0 | AI15: 0 | AK15: 58.25 | AL15: =COUNTIF(AK15:AK15,"=NA") -> 0 | AN15: =((MIN(IF(A15>0,MAX(N15*2%,1861),0),A15)))+0 -> 1861 | AO15: =SUMIF('MPG Payment '!E:E,'Shayak Income '!D15,'MPG Payment '!AJ:AJ) -> 1500 | AP15: =W15 -> 0 | AQ15: =AO15+AP15 -> 1500 | AS15: =B15-X15 -> 6400
A16: =IFERROR(VLOOKUP(D16,'Monthly Deduction'!$I$3:$J$957,2,0),0) -> 0 | B16: =IFERROR(VLOOKUP(D16,'Monthly Deduction'!$E$3:$F$957,2,0),0) -> 0 | C16: =A16+B16 -> 0 | D16: 10010087 | E16: =VLOOKUP(D16,'MPG Payment '!$E$3:$G$497305,2,0) -> Bagaraha-Gopal Yadav | F16: =IFERROR(_xlfn.XLOOKUP(D16,'Monthly Deduction'!$I$3:$I$957,'Monthly Deduction'!$H$3:$H$957),0) -> 0 | G16: =VLOOKUP(D16,'MPG Payment '!$E$3:$G$333666,3,0) -> vlc | H16: =VLOOKUP(D16,'MPG Payment '!$E$3:$H$333666,4,0) -> Indirect | I16: =INDEX('MPG Payment '!$C:$C,MATCH('Shayak Income '!D16,'MPG Payment '!E:E,0)) -> 1058 | J16: =INDEX('MPG Payment '!$D:$D,MATCH('Shayak Income '!D16,'MPG Payment '!E:E,0)) -> Hasanpur | K16: Old | L16: 45597 | M16: =SUMIF('MPG Payment '!$E$3:$E$344841,'Shayak Income '!D16,'MPG Payment '!$I$3:$I$344841) -> 133.74 | N16: =SUMIF('MPG Payment '!$E$3:$E$344841,'Shayak Income '!D16,'MPG Payment '!$J$3:$J$344841) -> 4762.38 | O16: =+M16*0.75 -> 100.305 | P16: =+M16*0.95 -> 127.053 | Q16: =SUMIF('MPG Payment '!$E$3:$E$344841,'Shayak Income '!D16,'MPG Payment '!$S$3:$S$344841) -> 0 | R16: =+N16*3% -> 142.8714 | S16: =R16-P16 -> 15.8184 | T16: =M16*0.1 -> 13.374 | U16: =((((((IF(K16="New",0,SUMIF('MPG Payment '!$E$3:$E$344841,'Shayak Income '!D16,'MPG Payment '!$AC$3:$AC$344841))))+0)+0)+0)+0)+-189 -> 214.28179 | V16: =ROUND((SUM(O16:Q16)-SUM(T16:U16)),0) -> 0 | W16: 0 | X16: 0 | Y16: 0 | Z16: 0 | AA16: 0 | AB16: =ROUND(IFERROR(V16-SUM(W16:AA16),0),0) -> 0 | AC16: =AB16 -> 0 | AD16: =ROUND(AB16-AC16,0) -> 0 | AE16: =IF(AC16<>0,"Yes","Release") -> Release | AG16: 0 | AH16: Non pouring | AI16: 0 | AK16: 0 | AL16: =COUNTIF(AK16:AK16,"=NA") -> 0 | AN16: =((MIN(IF(A16>0,MAX(N16*2%,1861),0),A16)))+0 -> 0 | AO16: =SUMIF('MPG Payment '!E:E,'Shayak Income '!D16,'MPG Payment '!AJ:AJ) -> 0 | AP16: =W16 -> 0 | AQ16: =AO16+AP16 -> 0 | AS16: =B16-X16 -> 0
A17: =IFERROR(VLOOKUP(D17,'Monthly Deduction'!$I$3:$J$957,2,0),0) -> 72787.047 | B17: =IFERROR(VLOOKUP(D17,'Monthly Deduction'!$E$3:$F$957,2,0),0) -> 5699 | C17: =A17+B17 -> 78486.047 | D17: 10010089 | E17: =VLOOKUP(D17,'MPG Payment '!$E$3:$G$497305,2,0) -> Gomukh Barkurwa | F17: =IFERROR(_xlfn.XLOOKUP(D17,'Monthly Deduction'!$I$3:$I$957,'Monthly Deduction'!$H$3:$H$957),0) -> 0 | G17: =VLOOKUP(D17,'MPG Payment '!$E$3:$G$333666,3,0) -> MPG | H17: =VLOOKUP(D17,'MPG Payment '!$E$3:$H$333666,4,0) -> Direct | I17: =INDEX('MPG Payment '!$C:$C,MATCH('Shayak Income '!D17,'MPG Payment '!E:E,0)) -> 1058 | J17: =INDEX('MPG Payment '!$D:$D,MATCH('Shayak Income '!D17,'MPG Payment '!E:E,0)) -> Hasanpur | K17: Old | L17: 45627 | M17: =SUMIF('MPG Payment '!$E$3:$E$344841,'Shayak Income '!D17,'MPG Payment '!$I$3:$I$344841) -> 1985.29 | N17: =SUMIF('MPG Payment '!$E$3:$E$344841,'Shayak Income '!D17,'MPG Payment '!$J$3:$J$344841) -> 84683.87 | O17: =+M17*0.75 -> 1488.9675 | P17: =+M17*0.95 -> 1886.0255 | Q17: =SUMIF('MPG Payment '!$E$3:$E$344841,'Shayak Income '!D17,'MPG Payment '!$S$3:$S$344841) -> 490.09 | R17: =+N17*3% -> 2540.5161 | S17: =R17-P17 -> 654.4906 | T17: =M17*0.1 -> 198.529 | U17: =((((((IF(K17="New",0,SUMIF('MPG Payment '!$E$3:$E$344841,'Shayak Income '!D17,'MPG Payment '!$AC$3:$AC$344841))))+0)+0)+0)+0)+0 -> 696.14463 | V17: =ROUND((SUM(O17:Q17)-SUM(T17:U17)),0) -> 2970 | W17: =(((AN17-AO17)))+0 -> 1861 | X17: 0 | Y17: =IFERROR(VLOOKUP(D17,'Monthly Deduction'!$M$2:$N$640,2,0),0) -> 0 | Z17: 0 | AA17: =IFERROR(VLOOKUP(D17,'Monthly Deduction'!A:B,2,0),0) -> 0 | AB17: =ROUND(IFERROR(V17-SUM(W17:AA17),0),0) -> 1109 | AC17: 0 | AD17: =ROUND(AB17-AC17,0) -> 1109 | AE17: =IF(AC17<>0,"Yes","Release") -> Release | AG17: 0 | AI17: 0 | AK17: 468.17 | AL17: =COUNTIF(AK17:AK17,"=NA") -> 0 | AN17: =((MIN(IF(A17>0,MAX(N17*2%,1861),0),A17)))+0 -> 1861 | AO17: =SUMIF('MPG Payment '!E:E,'Shayak Income '!D17,'MPG Payment '!AJ:AJ) -> 0 | AP17: =W17 -> 1861 | AQ17: =AO17+AP17 -> 1861 | AS17: =B17-X17 -> 5699
A18: =IFERROR(VLOOKUP(D18,'Monthly Deduction'!$I$3:$J$957,2,0),0) -> 0 | B18: =IFERROR(VLOOKUP(D18,'Monthly Deduction'!$E$3:$F$957,2,0),0) -> 0 | C18: =A18+B18 -> 0 | D18: 10010092 | E18: =VLOOKUP(D18,'MPG Payment '!$E$3:$G$497305,2,0) -> Kamla- Amarjeet | F18: =IFERROR(_xlfn.XLOOKUP(D18,'Monthly Deduction'!$I$3:$I$957,'Monthly Deduction'!$H$3:$H$957),0) -> 0 | G18: =VLOOKUP(D18,'MPG Payment '!$E$3:$G$333666,3,0) -> vlc | H18: =VLOOKUP(D18,'MPG Payment '!$E$3:$H$333666,4,0) -> Indirect | I18: =INDEX('MPG Payment '!$C:$C,MATCH('Shayak Income '!D18,'MPG Payment '!E:E,0)) -> 1001 | J18: =INDEX('MPG Payment '!$D:$D,MATCH('Shayak Income '!D18,'MPG Payment '!E:E,0)) -> Majhaul | K18: Old | L18: 45689 | M18: =SUMIF('MPG Payment '!$E$3:$E$344841,'Shayak Income '!D18,'MPG Payment '!$I$3:$I$344841) -> 2867.6 | N18: =SUMIF('MPG Payment '!$E$3:$E$344841,'Shayak Income '!D18,'MPG Payment '!$J$3:$J$344841) -> 92714.09 | O18: =+M18*0.75 -> 2150.7 | P18: =+M18*0.95 -> 2724.22 | Q18: =SUMIF('MPG Payment '!$E$3:$E$344841,'Shayak Income '!D18,'MPG Payment '!$S$3:$S$344841) -> 0 | R18: =+N18*3% -> 2781.4227 | S18: =R18-P18 -> 57.2027 | T18: =M18*0.1 -> 286.76 | U18: =((((((IF(K18="New",0,SUMIF('MPG Payment '!$E$3:$E$344841,'Shayak Income '!D18,'MPG Payment '!$AC$3:$AC$344841))))+0)+0)+0)+0)+0 -> 92.581663 | V18: =ROUND((SUM(O18:Q18)-SUM(T18:U18)),0) -> 4496 | W18: =(((AN18-AO18)))+0 -> 0 | X18: =((MIN(IF(B18>0,MAX(N18*2%),0),B18)))+0 -> 0 | Y18: =IFERROR(VLOOKUP(D18,'Monthly Deduction'!$M$2:$N$640,2,0),0) -> 0 | Z18: 0 | AA18: =IFERROR(VLOOKUP(D18,'Monthly Deduction'!A:B,2,0),0) -> 0 | AB18: =ROUND(IFERROR(V18-SUM(W18:AA18),0),0) -> 4496 | AC18: 0 | AD18: =ROUND(AB18-AC18,0) -> 4496 | AE18: =IF(AC18<>0,"Yes","Release") -> Release | AG18: 0 | AI18: 0 | AK18: 406.9 | AL18: =COUNTIF(AK18:AK18,"=NA") -> 0 | AN18: =((MIN(IF(A18>0,MAX(N18*2%,1861),0),A18)))+0 -> 0 | AO18: =SUMIF('MPG Payment '!E:E,'Shayak Income '!D18,'MPG Payment '!AJ:AJ) -> 0 | AP18: =W18 -> 0 | AQ18: =AO18+AP18 -> 0 | AS18: =B18-X18 -> 0
A19: =IFERROR(VLOOKUP(D19,'Monthly Deduction'!$I$3:$J$957,2,0),0) -> 71548 | B19: =IFERROR(VLOOKUP(D19,'Monthly Deduction'!$E$3:$F$957,2,0),0) -> 3016.2028 | C19: =A19+B19 -> 74564.203 | D19: 10010095 | E19: =VLOOKUP(D19,'MPG Payment '!$E$3:$G$497305,2,0) -> Gomukh Goha-02 | F19: =IFERROR(_xlfn.XLOOKUP(D19,'Monthly Deduction'!$I$3:$I$957,'Monthly Deduction'!$H$3:$H$957),0) -> 0 | G19: =VLOOKUP(D19,'MPG Payment '!$E$3:$G$333666,3,0) -> MPG | H19: =VLOOKUP(D19,'MPG Payment '!$E$3:$H$333666,4,0) -> Direct | I19: =INDEX('MPG Payment '!$C:$C,MATCH('Shayak Income '!D19,'MPG Payment '!E:E,0)) -> 1058 | J19: =INDEX('MPG Payment '!$D:$D,MATCH('Shayak Income '!D19,'MPG Payment '!E:E,0)) -> Hasanpur | K19: Old | L19: 45700 | M19: =SUMIF('MPG Payment '!$E$3:$E$344841,'Shayak Income '!D19,'MPG Payment '!$I$3:$I$344841) -> 1004.1 | N19: =SUMIF('MPG Payment '!$E$3:$E$344841,'Shayak Income '!D19,'MPG Payment '!$J$3:$J$344841) -> 42066.85 | O19: =+M19*0.75 -> 753.075 | P19: =+M19*0.95 -> 953.895 | Q19: =SUMIF('MPG Payment '!$E$3:$E$344841,'Shayak Income '!D19,'MPG Payment '!$S$3:$S$344841) -> 776.04 | R19: =+N19*3% -> 1262.0055 | S19: =R19-P19 -> 308.1105 | T19: =M19*0.1 -> 100.41 | U19: =((((((IF(K19="New",0,SUMIF('MPG Payment '!$E$3:$E$344841,'Shayak Income '!D19,'MPG Payment '!$AC$3:$AC$344841))))+0)+0)+0)+0)+0 -> 1502.8033 | V19: =ROUND((SUM(O19:Q19)-SUM(T19:U19)),0) -> 880 | W19: 880 | X19: 0 | Y19: =IFERROR(VLOOKUP(D19,'Monthly Deduction'!$M$2:$N$640,2,0),0) -> 0 | Z19: 0 | AA19: =IFERROR(VLOOKUP(D19,'Monthly Deduction'!A:B,2,0),0) -> 0 | AB19: =ROUND(IFERROR(V19-SUM(W19:AA19),0),0) -> 0 | AC19: 0 | AD19: =ROUND(AB19-AC19,0) -> 0 | AE19: =IF(AC19<>0,"Yes","Release") -> Release | AG19: 0 | AI19: 0 | AK19: 201.57 | AL19: =COUNTIF(AK19:AK19,"=NA") -> 0 | AN19: =((MIN(IF(A19>0,MAX(N19*2%,1861),0),A19)))+0 -> 1861 | AO19: =SUMIF('MPG Payment '!E:E,'Shayak Income '!D19,'MPG Payment '!AJ:AJ) -> 0 | AP19: =W19 -> 880 | AQ19: =AO19+AP19 -> 880 | AS19: =B19-X19 -> 3016.2028
A20: =IFERROR(VLOOKUP(D20,'Monthly Deduction'!$I$3:$J$957,2,0),0) -> 44473.397 | B20: =IFERROR(VLOOKUP(D20,'Monthly Deduction'!$E$3:$F$957,2,0),0) -> 17290.967 | C20: =A20+B20 -> 61764.363 | D20: 10010097 | E20: =VLOOKUP(D20,'MPG Payment '!$E$3:$G$497305,2,0) -> Gomukh Cheria Bariarpur | F20: =IFERROR(_xlfn.XLOOKUP(D20,'Monthly Deduction'!$I$3:$I$957,'Monthly Deduction'!$H$3:$H$957),0) -> 0 | G20: =VLOOKUP(D20,'MPG Payment '!$E$3:$G$333666,3,0) -> MPG | H20: =VLOOKUP(D20,'MPG Payment '!$E$3:$H$333666,4,0) -> Direct | I20: =INDEX('MPG Payment '!$C:$C,MATCH('Shayak Income '!D20,'MPG Payment '!E:E,0)) -> 1001 | J20: =INDEX('MPG Payment '!$D:$D,MATCH('Shayak Income '!D20,'MPG Payment '!E:E,0)) -> Majhaul | K20: Old | L20: 45708 | M20: =SUMIF('MPG Payment '!$E$3:$E$344841,'Shayak Income '!D20,'MPG Payment '!$I$3:$I$344841) -> 4607.6 | N20: =SUMIF('MPG Payment '!$E$3:$E$344841,'Shayak Income '!D20,'MPG Payment '!$J$3:$J$344841) -> 178316.71 | O20: =+M20*0.75 -> 3455.7 | P20: =+M20*0.95 -> 4377.22 | Q20: =SUMIF('MPG Payment '!$E$3:$E$344841,'Shayak Income '!D20,'MPG Payment '!$S$3:$S$344841) -> 343.57 | R20: =+N20*3% -> 5349.5013 | S20: =R20-P20 -> 972.2813 | T20: =M20*0.1 -> 460.76 | U20: =((((((IF(K20="New",0,SUMIF('MPG Payment '!$E$3:$E$344841,'Shayak Income '!D20,'MPG Payment '!$AC$3:$AC$344841))))+0)+0)+0)+0)+0 -> 0 | V20: =ROUND((SUM(O20:Q20)-SUM(T20:U20)),0) -> 7716 | W20: =(((AN20-AO20)))+0 -> 3566.3342 | X20: 0 | Y20: =IFERROR(VLOOKUP(D20,'Monthly Deduction'!$M$2:$N$640,2,0),0) -> 0 | Z20: 0 | AA20: =IFERROR(VLOOKUP(D20,'Monthly Deduction'!A:B,2,0),0) -> 0 | AB20: =ROUND(IFERROR(V20-SUM(W20:AA20),0),0) -> 4150 | AC20: 0 | AD20: =ROUND(AB20-AC20,0) -> 4150 | AE20: =IF(AC20<>0,"Yes","Release") -> Release | AG20: 0 | AI20: 0 | AK20: 973.6 | AL20: =COUNTIF(AK20:AK20,"=NA") -> 0 | AN20: =((MIN(IF(A20>0,MAX(N20*2%,1861),0),A20)))+0 -> 3566.3342 | AO20: =SUMIF('MPG Payment '!E:E,'Shayak Income '!D20,'MPG Payment '!AJ:AJ) -> 0 | AP20: =W20 -> 3566.3342 | AQ20: =AO20+AP20 -> 3566.3342 | AS20: =B20-X20 -> 17290.967
A21: =IFERROR(VLOOKUP(D21,'Monthly Deduction'!$I$3:$J$957,2,0),0) -> 68485 | B21: =IFERROR(VLOOKUP(D21,'Monthly Deduction'!$E$3:$F$957,2,0),0) -> 6400 | C21: =A21+B21 -> 74885 | D21: 10010099 | E21: =VLOOKUP(D21,'MPG Payment '!$E$3:$G$497305,2,0) -> Gomukh Bagraha-01 | F21: =IFERROR(_xlfn.XLOOKUP(D21,'Monthly Deduction'!$I$3:$I$957,'Monthly Deduction'!$H$3:$H$957),0) -> 0 | G21: =VLOOKUP(D21,'MPG Payment '!$E$3:$G$333666,3,0) -> MPG | H21: =VLOOKUP(D21,'MPG Payment '!$E$3:$H$333666,4,0) -> Direct | I21: =INDEX('MPG Payment '!$C:$C,MATCH('Shayak Income '!D21,'MPG Payment '!E:E,0)) -> 1058 | J21: =INDEX('MPG Payment '!$D:$D,MATCH('Shayak Income '!D21,'MPG Payment '!E:E,0)) -> Hasanpur | K21: Old | L21: 45736 | M21: =SUMIF('MPG Payment '!$E$3:$E$344841,'Shayak Income '!D21,'MPG Payment '!$I$3:$I$344841) -> 780.52 | N21: =SUMIF('MPG Payment '!$E$3:$E$344841,'Shayak Income '!D21,'MPG Payment '!$J$3:$J$344841) -> 33748.8 | O21: =+M21*0.75 -> 585.39 | P21: =+M21*0.95 -> 741.494 | Q21: =SUMIF('MPG Payment '!$E$3:$E$344841,'Shayak Income '!D21,'MPG Payment '!$S$3:$S$344841) -> 583.79 | R21: =+N21*3% -> 1012.464 | S21: =R21-P21 -> 270.97 | T21: =M21*0.1 -> 78.052 | U21: =((((((IF(K21="New",0,SUMIF('MPG Payment '!$E$3:$E$344841,'Shayak Income '!D21,'MPG Payment '!$AC$3:$AC$344841))))+0)+0)+0)+0)+0 -> 1735.6632 | V21: =ROUND((SUM(O21:Q21)-SUM(T21:U21)),0) -> 97 | W21: 97 | X21: 0 | Y21: =IFERROR(VLOOKUP(D21,'Monthly Deduction'!$M$2:$N$640,2,0),0) -> 0 | Z21: 0 | AA21: =IFERROR(VLOOKUP(D21,'Monthly Deduction'!A:B,2,0),0) -> 0 | AB21: =ROUND(IFERROR(V21-SUM(W21:AA21),0),0) -> 0 | AC21: 0 | AD21: =ROUND(AB21-AC21,0) -> 0 | AE21: =IF(AC21<>0,"Yes","Release") -> Release | AG21: 0 | AI21: 0 | AK21: 125.19 | AL21: =COUNTIF(AK21:AK21,"=NA") -> 0 | AN21: =((MIN(IF(A21>0,MAX(N21*2%,1861),0),A21)))+0 -> 1861 | AO21: =SUMIF('MPG Payment '!E:E,'Shayak Income '!D21,'MPG Payment '!AJ:AJ) -> 1500 | AP21: =W21 -> 97 | AQ21: =AO21+AP21 -> 1597 | AS21: =B21-X21 -> 6400
A22: =IFERROR(VLOOKUP(D22,'Monthly Deduction'!$I$3:$J$957,2,0),0) -> 87749 | B22: =IFERROR(VLOOKUP(D22,'Monthly Deduction'!$E$3:$F$957,2,0),0) -> 6400 | C22: =A22+B22 -> 94149 | D22: 10010108 | E22: =VLOOKUP(D22,'MPG Payment '!$E$3:$G$497305,2,0) -> Gomukh Pirauna | F22: =IFERROR(_xlfn.XLOOKUP(D22,'Monthly Deduction'!$I$3:$I$957,'Monthly Deduction'!$H$3:$H$957),0) -> 0 | G22: =VLOOKUP(D22,'MPG Payment '!$E$3:$G$333666,3,0) -> MPG | H22: =VLOOKUP(D22,'MPG Payment '!$E$3:$H$333666,4,0) -> Direct | I22: =INDEX('MPG Payment '!$C:$C,MATCH('Shayak Income '!D22,'MPG Payment '!E:E,0)) -> 1001 | J22: =INDEX('MPG Payment '!$D:$D,MATCH('Shayak Income '!D22,'MPG Payment '!E:E,0)) -> Majhaul | K22: Old | L22: 45777 | M22: =SUMIF('MPG Payment '!$E$3:$E$344841,'Shayak Income '!D22,'MPG Payment '!$I$3:$I$344841) -> 956.1 | N22: =SUMIF('MPG Payment '!$E$3:$E$344841,'Shayak Income '!D22,'MPG Payment '!$J$3:$J$344841) -> 34333.04 | O22: =+M22*0.75 -> 717.075 | P22: =+M22*0.95 -> 908.295 | Q22: =SUMIF('MPG Payment '!$E$3:$E$344841,'Shayak Income '!D22,'MPG Payment '!$S$3:$S$344841) -> 30.59 | R22: =+N22*3% -> 1029.9912 | S22: =R22-P22 -> 121.6962 | T22: =M22*0.1 -> 95.61 | U22: =((((((IF(K22="New",0,SUMIF('MPG Payment '!$E$3:$E$344841,'Shayak Income '!D22,'MPG Payment '!$AC$3:$AC$344841))))+0)+0)+0)+0)+0 -> 1327.2896 | V22: =ROUND((SUM(O22:Q22)-SUM(T22:U22)),0) -> 233 | W22: 233 | X22: 0 | Y22: =IFERROR(VLOOKUP(D22,'Monthly Deduction'!$M$2:$N$640,2,0),0) -> 0 | Z22: 0 | AA22: =IFERROR(VLOOKUP(D22,'Monthly Deduction'!A:B,2,0),0) -> 0 | AB22: =ROUND(IFERROR(V22-SUM(W22:AA22),0),0) -> 0 | AC22: =AB22 -> 0 | AD22: =ROUND(AB22-AC22,0) -> 0 | AE22: =IF(AC22<>0,"Yes","Release") -> Release | AG22: 0 | AH22: Agreement issue / Down Payment | AI22: 9803 | AK22: 106.57 | AL22: =COUNTIF(AK22:AK22,"=NA") -> 0 | AN22: =((MIN(IF(A22>0,MAX(N22*2%,1861),0),A22)))+0 -> 1861 | AO22: =SUMIF('MPG Payment '!E:E,'Shayak Income '!D22,'MPG Payment '!AJ:AJ) -> 1500 | AP22: =W22 -> 233 | AQ22: =AO22+AP22 -> 1733 | AS22: =B22-X22 -> 6400
A23: =IFERROR(VLOOKUP(D23,'Monthly Deduction'!$I$3:$J$957,2,0),0) -> 0 | B23: =IFERROR(VLOOKUP(D23,'Monthly Deduction'!$E$3:$F$957,2,0),0) -> 0 | C23: =A23+B23 -> 0 | D23: 10010109 | E23: =VLOOKUP(D23,'MPG Payment '!$E$3:$G$497305,2,0) -> Parra- Nagendra Kumar | F23: =IFERROR(_xlfn.XLOOKUP(D23,'Monthly Deduction'!$I$3:$I$957,'Monthly Deduction'!$H$3:$H$957),0) -> 0 | G23: =VLOOKUP(D23,'MPG Payment '!$E$3:$G$333666,3,0) -> vlc | H23: =VLOOKUP(D23,'MPG Payment '!$E$3:$H$333666,4,0) -> Indirect | I23: =INDEX('MPG Payment '!$C:$C,MATCH('Shayak Income '!D23,'MPG Payment '!E:E,0)) -> 1001 | J23: =INDEX('MPG Payment '!$D:$D,MATCH('Shayak Income '!D23,'MPG Payment '!E:E,0)) -> Majhaul | K23: Old | L23: 45777 | M23: =SUMIF('MPG Payment '!$E$3:$E$344841,'Shayak Income '!D23,'MPG Payment '!$I$3:$I$344841) -> 1139.6 | N23: =SUMIF('MPG Payment '!$E$3:$E$344841,'Shayak Income '!D23,'MPG Payment '!$J$3:$J$344841) -> 39508.1 | O23: =+M23*0.75 -> 854.7 | P23: =+M23*0.95 -> 1082.62 | Q23: =SUMIF('MPG Payment '!$E$3:$E$344841,'Shayak Income '!D23,'MPG Payment '!$S$3:$S$344841) -> 0 | R23: =+N23*3% -> 1185.243 | S23: =R23-P23 -> 102.623 | T23: =M23*0.1 -> 113.96 | U23: =((((((IF(K23="New",0,SUMIF('MPG Payment '!$E$3:$E$344841,'Shayak Income '!D23,'MPG Payment '!$AC$3:$AC$344841))))+0)+0)+0)+0)+0 -> 1151.2635 | V23: =ROUND((SUM(O23:Q23)-SUM(T23:U23)),0) -> 672 | W23: =(((AN23-AO23)))+0 -> 0 | X23: =((MIN(IF(B23>0,MAX(N23*2%),0),B23)))+0 -> 0 | Y23: =IFERROR(VLOOKUP(D23,'Monthly Deduction'!$M$2:$N$640,2,0),0) -> 0 | Z23: 0 | AA23: =IFERROR(VLOOKUP(D23,'Monthly Deduction'!A:B,2,0),0) -> 0 | AB23: =ROUND(IFERROR(V23-SUM(W23:AA23),0),0) -> 672 | AC23: 0 | AD23: =ROUND(AB23-AC23,0) -> 672 | AE23: =IF(AC23<>0,"Yes","Release") -> Release | AG23: 0 | AI23: 0 | AK23: 244.63 | AL23: =COUNTIF(AK23:AK23,"=NA") -> 0 | AN23: =((MIN(IF(A23>0,MAX(N23*2%,1861),0),A23)))+0 -> 0 | AO23: =SUMIF('MPG Payment '!E:E,'Shayak Income '!D23,'MPG Payment '!AJ:AJ) -> 0 | AP23: =W23 -> 0 | AQ23: =AO23+AP23 -> 0 | AS23: =B23-X23 -> 0
A24: =IFERROR(VLOOKUP(D24,'Monthly Deduction'!$I$3:$J$957,2,0),0) -> 68205.747 | B24: =IFERROR(VLOOKUP(D24,'Monthly Deduction'!$E$3:$F$957,2,0),0) -> 12800 | C24: =A24+B24 -> 81005.747 | D24: 10010113 | E24: =VLOOKUP(D24,'MPG Payment '!$E$3:$G$497305,2,0) -> Gomukh Basahi | F24: =IFERROR(_xlfn.XLOOKUP(D24,'Monthly Deduction'!$I$3:$I$957,'Monthly Deduction'!$H$3:$H$957),0) -> 0 | G24: =VLOOKUP(D24,'MPG Payment '!$E$3:$G$333666,3,0) -> MPG | H24: =VLOOKUP(D24,'MPG Payment '!$E$3:$H$333666,4,0) -> Direct | I24: =INDEX('MPG Payment '!$C:$C,MATCH('Shayak Income '!D24,'MPG Payment '!E:E,0)) -> 1001 | J24: =INDEX('MPG Payment '!$D:$D,MATCH('Shayak Income '!D24,'MPG Payment '!E:E,0)) -> Majhaul | K24: Old | L24: 45810 | M24: =SUMIF('MPG Payment '!$E$3:$E$344841,'Shayak Income '!D24,'MPG Payment '!$I$3:$I$344841) -> 3405.2 | N24: =SUMIF('MPG Payment '!$E$3:$E$344841,'Shayak Income '!D24,'MPG Payment '!$J$3:$J$344841) -> 137136.07 | O24: =+M24*0.75 -> 2553.9 | P24: =+M24*0.95 -> 3234.94 | Q24: =SUMIF('MPG Payment '!$E$3:$E$344841,'Shayak Income '!D24,'MPG Payment '!$S$3:$S$344841) -> 413.65 | R24: =+N24*3% -> 4114.0821 | S24: =R24-P24 -> 879.1421 | T24: =M24*0.1 -> 340.52 | U24: =((((((IF(K24="New",0,SUMIF('MPG Payment '!$E$3:$E$344841,'Shayak Income '!D24,'MPG Payment '!$AC$3:$AC$344841))))+0)+0)+0)+0)+0 -> 0 | V24: =ROUND((SUM(O24:Q24)-SUM(T24:U24)),0) -> 5862 | W24: =(((AN24-AO24)))+0 -> 2742.7214 | X24: 0 | Y24: =IFERROR(VLOOKUP(D24,'Monthly Deduction'!$M$2:$N$640,2,0),0) -> 0 | Z24: 0 | AA24: =IFERROR(VLOOKUP(D24,'Monthly Deduction'!A:B,2,0),0) -> 0 | AB24: =ROUND(IFERROR(V24-SUM(W24:AA24),0),0) -> 3119 | AC24: 0 | AD24: =ROUND(AB24-AC24,0) -> 3119 | AE24: =IF(AC24<>0,"Yes","Release") -> Release | AG24: 0 | AI24: 0 | AK24: 696.2 | AL24: =COUNTIF(AK24:AK24,"=NA") -> 0 | AN24: =((MIN(IF(A24>0,MAX(N24*2%,1861),0),A24)))+0 -> 2742.7214 | AO24: =SUMIF('MPG Payment '!E:E,'Shayak Income '!D24,'MPG Payment '!AJ:AJ) -> 0 | AP24: =W24 -> 2742.7214 | AQ24: =AO24+AP24 -> 2742.7214 | AS24: =B24-X24 -> 12800
A25: =IFERROR(VLOOKUP(D25,'Monthly Deduction'!$I$3:$J$957,2,0),0) -> 42701.196 | B25: =IFERROR(VLOOKUP(D25,'Monthly Deduction'!$E$3:$F$957,2,0),0) -> 16000 | C25: =A25+B25 -> 58701.196 | D25: 10010121 | E25: =VLOOKUP(D25,'MPG Payment '!$E$3:$G$497305,2,0) -> Gomukh Sawantpur | F25: =IFERROR(_xlfn.XLOOKUP(D25,'Monthly Deduction'!$I$3:$I$957,'Monthly Deduction'!$H$3:$H$957),0) -> 0 | G25: =VLOOKUP(D25,'MPG Payment '!$E$3:$G$333666,3,0) -> MPG | H25: =VLOOKUP(D25,'MPG Payment '!$E$3:$H$333666,4,0) -> Direct | I25: =INDEX('MPG Payment '!$C:$C,MATCH('Shayak Income '!D25,'MPG Payment '!E:E,0)) -> 1001 | J25: =INDEX('MPG Payment '!$D:$D,MATCH('Shayak Income '!D25,'MPG Payment '!E:E,0)) -> Majhaul | K25: Old | L25: 45842 | M25: =SUMIF('MPG Payment '!$E$3:$E$344841,'Shayak Income '!D25,'MPG Payment '!$I$3:$I$344841) -> 5378.7 | N25: =SUMIF('MPG Payment '!$E$3:$E$344841,'Shayak Income '!D25,'MPG Payment '!$J$3:$J$344841) -> 207037.88 | O25: =+M25*0.75 -> 4034.025 | P25: =+M25*0.95 -> 5109.765 | Q25: =SUMIF('MPG Payment '!$E$3:$E$344841,'Shayak Income '!D25,'MPG Payment '!$S$3:$S$344841) -> 208.24 | R25: =+N25*3% -> 6211.1364 | S25: =R25-P25 -> 1101.3714 | T25: =M25*0.1 -> 537.87 | U25: =((((((IF(K25="New",0,SUMIF('MPG Payment '!$E$3:$E$344841,'Shayak Income '!D25,'MPG Payment '!$AC$3:$AC$344841))))+0)+0)+0)+0)+0 -> 0 | V25: =ROUND((SUM(O25:Q25)-SUM(T25:U25)),0) -> 8814 | W25: =(((AN25-AO25)))+0 -> 4140.7576 | X25: 0 | Y25: =IFERROR(VLOOKUP(D25,'Monthly Deduction'!$M$2:$N$640,2,0),0) -> 0 | Z25: 0 | AA25: =IFERROR(VLOOKUP(D25,'Monthly Deduction'!A:B,2,0),0) -> 0 | AB25: =ROUND(IFERROR(V25-SUM(W25:AA25),0),0) -> 4673 | AC25: 0 | AD25: =ROUND(AB25-AC25,0) -> 4673 | AE25: =IF(AC25<>0,"Yes","Release") -> Release | AG25: 0 | AI25: 0 | AK25: 1080.5 | AL25: =COUNTIF(AK25:AK25,"=NA") -> 0 | AN25: =((MIN(IF(A25>0,MAX(N25*2%,1861),0),A25)))+0 -> 4140.7576 | AO25: =SUMIF('MPG Payment '!E:E,'Shayak Income '!D25,'MPG Payment '!AJ:AJ) -> 0 | AP25: =W25 -> 4140.7576 | AQ25: =AO25+AP25 -> 4140.7576 | AS25: =B25-X25 -> 16000
A26: =IFERROR(VLOOKUP(D26,'Monthly Deduction'!$I$3:$J$957,2,0),0) -> 0 | B26: =IFERROR(VLOOKUP(D26,'Monthly Deduction'!$E$3:$F$957,2,0),0) -> 0 | C26: =A26+B26 -> 0 | D26: 10010125 | E26: =VLOOKUP(D26,'MPG Payment '!$E$3:$G$497305,2,0) -> Maida- Ram Kumar | F26: =IFERROR(_xlfn.XLOOKUP(D26,'Monthly Deduction'!$I$3:$I$957,'Monthly Deduction'!$H$3:$H$957),0) -> 0 | G26: =VLOOKUP(D26,'MPG Payment '!$E$3:$G$333666,3,0) -> vlc | H26: =VLOOKUP(D26,'MPG Payment '!$E$3:$H$333666,4,0) -> Indirect | I26: =INDEX('MPG Payment '!$C:$C,MATCH('Shayak Income '!D26,'MPG Payment '!E:E,0)) -> 1001 | J26: =INDEX('MPG Payment '!$D:$D,MATCH('Shayak Income '!D26,'MPG Payment '!E:E,0)) -> Majhaul | K26: Old | L26: 45869 | M26: =SUMIF('MPG Payment '!$E$3:$E$344841,'Shayak Income '!D26,'MPG Payment '!$I$3:$I$344841) -> 1174.6 | N26: =SUMIF('MPG Payment '!$E$3:$E$344841,'Shayak Income '!D26,'MPG Payment '!$J$3:$J$344841) -> 50962.27 | O26: =+M26*0.75 -> 880.95 | P26: =+M26*0.95 -> 1115.87 | Q26: =SUMIF('MPG Payment '!$E$3:$E$344841,'Shayak Income '!D26,'MPG Payment '!$S$3:$S$344841) -> 0 | R26: =+N26*3% -> 1528.8681 | S26: =R26-P26 -> 412.9981 | T26: =M26*0.1 -> 117.46 | U26: =((((((IF(K26="New",0,SUMIF('MPG Payment '!$E$3:$E$344841,'Shayak Income '!D26,'MPG Payment '!$AC$3:$AC$344841))))+0)+0)+0)+0)+0 -> 1330.1852 | V26: =ROUND((SUM(O26:Q26)-SUM(T26:U26)),0) -> 549 | W26: =(((AN26-AO26)))+0 -> 0 | X26: =((MIN(IF(B26>0,MAX(N26*2%),0),B26)))+0 -> 0 | Y26: =IFERROR(VLOOKUP(D26,'Monthly Deduction'!$M$2:$N$640,2,0),0) -> 0 | Z26: 0 | AA26: =IFERROR(VLOOKUP(D26,'Monthly Deduction'!A:B,2,0),0) -> 0 | AB26: =ROUND(IFERROR(V26-SUM(W26:AA26),0),0) -> 549 | AC26: 0 | AD26: =ROUND(AB26-AC26,0) -> 549 | AE26: =IF(AC26<>0,"Yes","Release") -> Release | AG26: 0 | AI26: 0 | AK26: 317.6 | AL26: =COUNTIF(AK26:AK26,"=NA") -> 0 | AN26: =((MIN(IF(A26>0,MAX(N26*2%,1861),0),A26)))+0 -> 0 | AO26: =SUMIF('MPG Payment '!E:E,'Shayak Income '!D26,'MPG Payment '!AJ:AJ) -> 0 | AP26: =W26 -> 0 | AQ26: =AO26+AP26 -> 0 | AS26: =B26-X26 -> 0
A27: =IFERROR(VLOOKUP(D27,'Monthly Deduction'!$I$3:$J$957,2,0),0) -> 41865.425 | B27: =IFERROR(VLOOKUP(D27,'Monthly Deduction'!$E$3:$F$957,2,0),0) -> 16000 | C27: =A27+B27 -> 57865.425 | D27: 10010128 | E27: =VLOOKUP(D27,'MPG Payment '!$E$3:$G$497305,2,0) -> Gomukh Aure Bikrampur | F27: =IFERROR(_xlfn.XLOOKUP(D27,'Monthly Deduction'!$I$3:$I$957,'Monthly Deduction'!$H$3:$H$957),0) -> 0 | G27: =VLOOKUP(D27,'MPG Payment '!$E$3:$G$333666,3,0) -> MPG | H27: =VLOOKUP(D27,'MPG Payment '!$E$3:$H$333666,4,0) -> Direct | I27: =INDEX('MPG Payment '!$C:$C,MATCH('Shayak Income '!D27,'MPG Payment '!E:E,0)) -> 1001 | J27: =INDEX('MPG Payment '!$D:$D,MATCH('Shayak Income '!D27,'MPG Payment '!E:E,0)) -> Majhaul | K27: Old | L27: 45869 | M27: =SUMIF('MPG Payment '!$E$3:$E$344841,'Shayak Income '!D27,'MPG Payment '!$I$3:$I$344841) -> 3903.4 | N27: =SUMIF('MPG Payment '!$E$3:$E$344841,'Shayak Income '!D27,'MPG Payment '!$J$3:$J$344841) -> 167166.49 | O27: =+M27*0.75 -> 2927.55 | P27: =+M27*0.95 -> 3708.23 | Q27: =SUMIF('MPG Payment '!$E$3:$E$344841,'Shayak Income '!D27,'MPG Payment '!$S$3:$S$344841) -> 0 | R27: =+N27*3% -> 5014.9947 | S27: =R27-P27 -> 1306.7647 | T27: =M27*0.1 -> 390.34 | U27: =((((((IF(K27="New",0,SUMIF('MPG Payment '!$E$3:$E$344841,'Shayak Income '!D27,'MPG Payment '!$AC$3:$AC$344841))))+0)+0)+0)+0)+0 -> 0 | V27: =ROUND((SUM(O27:Q27)-SUM(T27:U27)),0) -> 6245 | W27: =(((AN27-AO27)))+0 -> 3343.3298 | X27: 0 | Y27: =IFERROR(VLOOKUP(D27,'Monthly Deduction'!$M$2:$N$640,2,0),0) -> 0 | Z27: 0 | AA27: =IFERROR(VLOOKUP(D27,'Monthly Deduction'!A:B,2,0),0) -> 0 | AB27: =ROUND(IFERROR(V27-SUM(W27:AA27),0),0) -> 2902 | AC27: 0 | AD27: =ROUND(AB27-AC27,0) -> 2902 | AE27: =IF(AC27<>0,"Yes","Release") -> Release | AG27: 0 | AI27: 0 | AK27: 1227.4 | AL27: =COUNTIF(AK27:AK27,"=NA") -> 0 | AN27: =((MIN(IF(A27>0,MAX(N27*2%,1861),0),A27)))+0 -> 3343.3298 | AO27: =SUMIF('MPG Payment '!E:E,'Shayak Income '!D27,'MPG Payment '!AJ:AJ) -> 0 | AP27: =W27 -> 3343.3298 | AQ27: =AO27+AP27 -> 3343.3298 | AS27: =B27-X27 -> 16000
A28: =IFERROR(VLOOKUP(D28,'Monthly Deduction'!$I$3:$J$957,2,0),0) -> 0 | B28: =IFERROR(VLOOKUP(D28,'Monthly Deduction'!$E$3:$F$957,2,0),0) -> 0 | C28: =A28+B28 -> 0 | D28: 10010129 | E28: =VLOOKUP(D28,'MPG Payment '!$E$3:$G$497305,2,0) -> Manjhaul- Gulshan Kumar | F28: =IFERROR(_xlfn.XLOOKUP(D28,'Monthly Deduction'!$I$3:$I$957,'Monthly Deduction'!$H$3:$H$957),0) -> 0 | G28: =VLOOKUP(D28,'MPG Payment '!$E$3:$G$333666,3,0) -> vlc | H28: =VLOOKUP(D28,'MPG Payment '!$E$3:$H$333666,4,0) -> Indirect | I28: =INDEX('MPG Payment '!$C:$C,MATCH('Shayak Income '!D28,'MPG Payment '!E:E,0)) -> 1001 | J28: =INDEX('MPG Payment '!$D:$D,MATCH('Shayak Income '!D28,'MPG Payment '!E:E,0)) -> Majhaul | K28: Old | L28: 45869 | M28: =SUMIF('MPG Payment '!$E$3:$E$344841,'Shayak Income '!D28,'MPG Payment '!$I$3:$I$344841) -> 3307.2 | N28: =SUMIF('MPG Payment '!$E$3:$E$344841,'Shayak Income '!D28,'MPG Payment '!$J$3:$J$344841) -> 139788.44 | O28: =+M28*0.75 -> 2480.4 | P28: =+M28*0.95 -> 3141.84 | Q28: =SUMIF('MPG Payment '!$E$3:$E$344841,'Shayak Income '!D28,'MPG Payment '!$S$3:$S$344841) -> 0 | R28: =+N28*3% -> 4193.6532 | S28: =R28-P28 -> 1051.8132 | T28: =M28*0.1 -> 330.72 | U28: =((((((IF(K28="New",0,SUMIF('MPG Payment '!$E$3:$E$344841,'Shayak Income '!D28,'MPG Payment '!$AC$3:$AC$344841))))+0)+0)+0)+0)+0 -> 249.15465 | V28: =ROUND((SUM(O28:Q28)-SUM(T28:U28)),0) -> 5042 | W28: =(((AN28-AO28)))+0 -> 0 | X28: =((MIN(IF(B28>0,MAX(N28*2%),0),B28)))+0 -> 0 | Y28: =IFERROR(VLOOKUP(D28,'Monthly Deduction'!$M$2:$N$640,2,0),0) -> 0 | Z28: 0 | AA28: =IFERROR(VLOOKUP(D28,'Monthly Deduction'!A:B,2,0),0) -> 0 | AB28: =ROUND(IFERROR(V28-SUM(W28:AA28),0),0) -> 5042 | AC28: 0 | AD28: =ROUND(AB28-AC28,0) -> 5042 | AE28: =IF(AC28<>0,"Yes","Release") -> Release | AG28: 0 | AI28: 0 | AK28: 452.7 | AL28: =COUNTIF(AK28:AK28,"=NA") -> 0 | AN28: =((MIN(IF(A28>0,MAX(N28*2%,1861),0),A28)))+0 -> 0 | AO28: =SUMIF('MPG Payment '!E:E,'Shayak Income '!D28,'MPG Payment '!AJ:AJ) -> 0 | AP28: =W28 -> 0 | AQ28: =AO28+AP28 -> 0 | AS28: =B28-X28 -> 0
A29: =IFERROR(VLOOKUP(D29,'Monthly Deduction'!$I$3:$J$957,2,0),0) -> 0 | B29: =IFERROR(VLOOKUP(D29,'Monthly Deduction'!$E$3:$F$957,2,0),0) -> 0 | C29: =A29+B29 -> 0 | D29: 10010130 | E29: =VLOOKUP(D29,'MPG Payment '!$E$3:$G$497305,2,0) -> Khaira Manjhaul | F29: =IFERROR(_xlfn.XLOOKUP(D29,'Monthly Deduction'!$I$3:$I$957,'Monthly Deduction'!$H$3:$H$957),0) -> 0 | G29: =VLOOKUP(D29,'MPG Payment '!$E$3:$G$333666,3,0) -> vlc | H29: =VLOOKUP(D29,'MPG Payment '!$E$3:$H$333666,4,0) -> Indirect | I29: =INDEX('MPG Payment '!$C:$C,MATCH('Shayak Income '!D29,'MPG Payment '!E:E,0)) -> 1001 | J29: =INDEX('MPG Payment '!$D:$D,MATCH('Shayak Income '!D29,'MPG Payment '!E:E,0)) -> Majhaul | K29: Old | L29: 45870 | M29: =SUMIF('MPG Payment '!$E$3:$E$344841,'Shayak Income '!D29,'MPG Payment '!$I$3:$I$344841) -> 1785 | N29: =SUMIF('MPG Payment '!$E$3:$E$344841,'Shayak Income '!D29,'MPG Payment '!$J$3:$J$344841) -> 65862.27 | O29: =+M29*0.75 -> 1338.75 | P29: =+M29*0.95 -> 1695.75 | Q29: =SUMIF('MPG Payment '!$E$3:$E$344841,'Shayak Income '!D29,'MPG Payment '!$S$3:$S$344841) -> 0 | R29: =+N29*3% -> 1975.8681 | S29: =R29-P29 -> 280.1181 | T29: =M29*0.1 -> 178.5 | U29: =((((((IF(K29="New",0,SUMIF('MPG Payment '!$E$3:$E$344841,'Shayak Income '!D29,'MPG Payment '!$AC$3:$AC$344841))))+0)+0)+0)+0)+0 -> 745.7534 | V29: =ROUND((SUM(O29:Q29)-SUM(T29:U29)),0) -> 2110 | W29: =(((AN29-AO29)))+0 -> 0 | X29: =((MIN(IF(B29>0,MAX(N29*2%),0),B29)))+0 -> 0 | Y29: =IFERROR(VLOOKUP(D29,'Monthly Deduction'!$M$2:$N$640,2,0),0) -> 0 | Z29: 0 | AA29: =IFERROR(VLOOKUP(D29,'Monthly Deduction'!A:B,2,0),0) -> 0 | AB29: =ROUND(IFERROR(V29-SUM(W29:AA29),0),0) -> 2110 | AC29: 0 | AD29: =ROUND(AB29-AC29,0) -> 2110 | AE29: =IF(AC29<>0,"Yes","Release") -> Release | AG29: 0 | AI29: 0 | AK29: 345.1 | AL29: =COUNTIF(AK29:AK29,"=NA") -> 0 | AN29: =((MIN(IF(A29>0,MAX(N29*2%,1861),0),A29)))+0 -> 0 | AO29: =SUMIF('MPG Payment '!E:E,'Shayak Income '!D29,'MPG Payment '!AJ:AJ) -> 0 | AP29: =W29 -> 0 | AQ29: =AO29+AP29 -> 0 | AS29: =B29-X29 -> 0
A30: =IFERROR(VLOOKUP(D30,'Monthly Deduction'!$I$3:$J$957,2,0),0) -> 0 | B30: =IFERROR(VLOOKUP(D30,'Monthly Deduction'!$E$3:$F$957,2,0),0) -> 0 | C30: =A30+B30 -> 0 | D30: 10010131 | E30: =VLOOKUP(D30,'MPG Payment '!$E$3:$G$497305,2,0) -> Mehda Shahpur | F30: =IFERROR(_xlfn.XLOOKUP(D30,'Monthly Deduction'!$I$3:$I$957,'Monthly Deduction'!$H$3:$H$957),0) -> 0 | G30: =VLOOKUP(D30,'MPG Payment '!$E$3:$G$333666,3,0) -> vlc | H30: =VLOOKUP(D30,'MPG Payment '!$E$3:$H$333666,4,0) -> Indirect | I30: =INDEX('MPG Payment '!$C:$C,MATCH('Shayak Income '!D30,'MPG Payment '!E:E,0)) -> 1001 | J30: =INDEX('MPG Payment '!$D:$D,MATCH('Shayak Income '!D30,'MPG Payment '!E:E,0)) -> Majhaul | K30: Old | L30: 45870 | M30: =SUMIF('MPG Payment '!$E$3:$E$344841,'Shayak Income '!D30,'MPG Payment '!$I$3:$I$344841) -> 2838.8 | N30: =SUMIF('MPG Payment '!$E$3:$E$344841,'Shayak Income '!D30,'MPG Payment '!$J$3:$J$344841) -> 107591.78 | O30: =+M30*0.75 -> 2129.1 | P30: =+M30*0.95 -> 2696.86 | Q30: =SUMIF('MPG Payment '!$E$3:$E$344841,'Shayak Income '!D30,'MPG Payment '!$S$3:$S$344841) -> 0 | R30: =+N30*3% -> 3227.7534 | S30: =R30-P30 -> 530.8934 | T30: =M30*0.1 -> 283.88 | U30: =((((((IF(K30="New",0,SUMIF('MPG Payment '!$E$3:$E$344841,'Shayak Income '!D30,'MPG Payment '!$AC$3:$AC$344841))))+0)+0)+0)+0)+0 -> 215.66983 | V30: =ROUND((SUM(O30:Q30)-SUM(T30:U30)),0) -> 4326 | W30: =(((AN30-AO30)))+0 -> 0 | X30: =((MIN(IF(B30>0,MAX(N30*2%),0),B30)))+0 -> 0 | Y30: =IFERROR(VLOOKUP(D30,'Monthly Deduction'!$M$2:$N$640,2,0),0) -> 0 | Z30: 0 | AA30: =IFERROR(VLOOKUP(D30,'Monthly Deduction'!A:B,2,0),0) -> 0 | AB30: =ROUND(IFERROR(V30-SUM(W30:AA30),0),0) -> 4326 | AC30: 0 | AD30: =ROUND(AB30-AC30,0) -> 4326 | AE30: =IF(AC30<>0,"Yes","Release") -> Release | AG30: 0 | AI30: 0 | AK30: 324.6 | AL30: =COUNTIF(AK30:AK30,"=NA") -> 0 | AN30: =((MIN(IF(A30>0,MAX(N30*2%,1861),0),A30)))+0 -> 0 | AO30: =SUMIF('MPG Payment '!E:E,'Shayak Income '!D30,'MPG Payment '!AJ:AJ) -> 0 | AP30: =W30 -> 0 | AQ30: =AO30+AP30 -> 0 | AS30: =B30-X30 -> 0
A31: =IFERROR(VLOOKUP(D31,'Monthly Deduction'!$I$3:$J$957,2,0),0) -> 0 | B31: =IFERROR(VLOOKUP(D31,'Monthly Deduction'!$E$3:$F$957,2,0),0) -> 0 | C31: =A31+B31 -> 0 | D31: 10020002 | E31: =VLOOKUP(D31,'MPG Payment '!$E$3:$G$497305,2,0) -> PIPARIYA DIH -2 | F31: =IFERROR(_xlfn.XLOOKUP(D31,'Monthly Deduction'!$I$3:$I$957,'Monthly Deduction'!$H$3:$H$957),0) -> 0 | G31: =VLOOKUP(D31,'MPG Payment '!$E$3:$G$333666,3,0) -> MPG | H31: =VLOOKUP(D31,'MPG Payment '!$E$3:$H$333666,4,0) -> Direct | I31: =INDEX('MPG Payment '!$C:$C,MATCH('Shayak Income '!D31,'MPG Payment '!E:E,0)) -> 1002 | J31: =INDEX('MPG Payment '!$D:$D,MATCH('Shayak Income '!D31,'MPG Payment '!E:E,0)) -> Laldiyara | K31: Old | L31: 42979 | M31: =SUMIF('MPG Payment '!$E$3:$E$344841,'Shayak Income '!D31,'MPG Payment '!$I$3:$I$344841) -> 9646.5 | N31: =SUMIF('MPG Payment '!$E$3:$E$344841,'Shayak Income '!D31,'MPG Payment '!$J$3:$J$344841) -> 445239.29 | O31: =+M31*0.75 -> 7234.875 | P31: =+M31*0.95 -> 9164.175 | Q31: =SUMIF('MPG Payment '!$E$3:$E$344841,'Shayak Income '!D31,'MPG Payment '!$S$3:$S$344841) -> 4046.71 | R31: =+N31*3% -> 13357.179 | S31: =R31-P31 -> 4193.0037 | T31: =M31*0.1 -> 964.65 | U31: =((((((IF(K31="New",0,SUMIF('MPG Payment '!$E$3:$E$344841,'Shayak Income '!D31,'MPG Payment '!$AC$3:$AC$344841))))+0)+0)+0)+0)+0 -> 0 | V31: =ROUND((SUM(O31:Q31)-SUM(T31:U31)),0) -> 19481 | W31: =(((AN31-AO31)))+0 -> 0 | X31: =((MIN(IF(B31>0,MAX(N31*2%),0),B31)))+0 -> 0 | Y31: =IFERROR(VLOOKUP(D31,'Monthly Deduction'!$M$2:$N$640,2,0),0) -> 0 | Z31: 0 | AA31: =IFERROR(VLOOKUP(D31,'Monthly Deduction'!A:B,2,0),0) -> 0 | AB31: =ROUND(IFERROR(V31-SUM(W31:AA31),0),0) -> 19481 | AC31: 0 | AD31: =ROUND(AB31-AC31,0) -> 19481 | AE31: =IF(AC31<>0,"Yes","Release") -> Release | AG31: 0 | AI31: 0 | AK31: 2652.1 | AL31: =COUNTIF(AK31:AK31,"=NA") -> 0 | AN31: =((MIN(IF(A31>0,MAX(N31*2%,1861),0),A31)))+0 -> 0 | AO31: =SUMIF('MPG Payment '!E:E,'Shayak Income '!D31,'MPG Payment '!AJ:AJ) -> 0 | AP31: =W31 -> 0 | AQ31: =AO31+AP31 -> 0 | AS31: =B31-X31 -> 0
A32: =IFERROR(VLOOKUP(D32,'Monthly Deduction'!$I$3:$J$957,2,0),0) -> 0 | B32: =IFERROR(VLOOKUP(D32,'Monthly Deduction'!$E$3:$F$957,2,0),0) -> 0 | C32: =A32+B32 -> 0 | D32: 10020004 | E32: =VLOOKUP(D32,'MPG Payment '!$E$3:$G$497305,2,0) -> LAL DIYARA -1 | F32: =IFERROR(_xlfn.XLOOKUP(D32,'Monthly Deduction'!$I$3:$I$957,'Monthly Deduction'!$H$3:$H$957),0) -> 0 | G32: =VLOOKUP(D32,'MPG Payment '!$E$3:$G$333666,3,0) -> MPG | H32: =VLOOKUP(D32,'MPG Payment '!$E$3:$H$333666,4,0) -> Direct | I32: =INDEX('MPG Payment '!$C:$C,MATCH('Shayak Income '!D32,'MPG Payment '!E:E,0)) -> 1002 | J32: =INDEX('MPG Payment '!$D:$D,MATCH('Shayak Income '!D32,'MPG Payment '!E:E,0)) -> Laldiyara | K32: Old | L32: 42979 | M32: =SUMIF('MPG Payment '!$E$3:$E$344841,'Shayak Income '!D32,'MPG Payment '!$I$3:$I$344841) -> 2196.6 | N32: =SUMIF('MPG Payment '!$E$3:$E$344841,'Shayak Income '!D32,'MPG Payment '!$J$3:$J$344841) -> 88368.15 | O32: =+M32*0.75 -> 1647.45 | P32: =+M32*0.95 -> 2086.77 | Q32: =SUMIF('MPG Payment '!$E$3:$E$344841,'Shayak Income '!D32,'MPG Payment '!$S$3:$S$344841) -> 0 | R32: =+N32*3% -> 2651.0445 | S32: =R32-P32 -> 564.2745 | T32: =M32*0.1 -> 219.66 | U32: =((((((IF(K32="New",0,SUMIF('MPG Payment '!$E$3:$E$344841,'Shayak Income '!D32,'MPG Payment '!$AC$3:$AC$344841))))+0)+0)+0)+0)+0 -> 485.14124 | V32: =ROUND((SUM(O32:Q32)-SUM(T32:U32)),0) -> 3029 | W32: =(((AN32-AO32)))+0 -> 0 | X32: =((MIN(IF(B32>0,MAX(N32*2%),0),B32)))+0 -> 0 | Y32: =IFERROR(VLOOKUP(D32,'Monthly Deduction'!$M$2:$N$640,2,0),0) -> 0 | Z32: 0 | AA32: =IFERROR(VLOOKUP(D32,'Monthly Deduction'!A:B,2,0),0) -> 0 | AB32: =ROUND(IFERROR(V32-SUM(W32:AA32),0),0) -> 3029 | AC32: 0 | AD32: =ROUND(AB32-AC32,0) -> 3029 | AE32: =IF(AC32<>0,"Yes","Release") -> Release | AG32: 0 | AI32: 0 | AK32: 488.9 | AL32: =COUNTIF(AK32:AK32,"=NA") -> 0 | AN32: =((MIN(IF(A32>0,MAX(N32*2%,1861),0),A32)))+0 -> 0 | AO32: =SUMIF('MPG Payment '!E:E,'Shayak Income '!D32,'MPG Payment '!AJ:AJ) -> 0 | AP32: =W32 -> 0 | AQ32: =AO32+AP32 -> 0 | AS32: =B32-X32 -> 0
