Workbook
Name Purchase: Table3[]
Name Table4: 'Stock Munger'!$D$88

Sheet Stock Munger
A1: Item Name | B1: UoM | C1: Opening Stock | D1: Received Stock | E1: Issue Stock | F1: Closing Balance | G1: Reorder Qty | H1: Reorder Level | I1: Open Rate | J1: Stock Value | K1: Stock Staus
A2: 1% Iodine Solution (100ml) | B2: Nos | C2: 13 | D2: 0 | E2: 1 | F2: 12 | G2: 15 | H2: 5 | I2: 90 | J2: 1080 | K2: Stock Available
A3: Amber Colour Bottle (250 ML) | B3: Nos | C3: 120 | D3: 0 | E3: 2 | F3: 118 | G3: 50 | H3: 40 | I3: 120 | J3: 14160 | K3: Stock Available
A4: Amyl 500ml | B4: Nos | C4: 47 | D4: 0 | E4: 24 | F4: 23 | G4: 50 | H4: 30 | I4: 366 | J4: 8413 | K4: PO Required
A5: Analyzer Calibration Cheking Log Book | B5: Nos | C5: 61 | D5: 0 | E5: 27 | F5: 34 | G5: 100 | H5: 20 | I5: 127 | J5: 4333 | K5: Stock Available
A6: Beaker 100 Ml | B6: Nos | C6: 16 | D6: 0 | E6: 3 | F6: 13 | G6: 48 | H6: 10 | I6: 33 | J6: 431 | K6: Stock Available
A7: Beaker 250 ML Borosilicate | B7: Nos | C7: 20 | D7: 0 | E7: 2 | F7: 18 | G7: 48 | H7: 10 | I7: 65 | J7: 1168 | K7: Stock Available
A8: Beaker 500 Ml | B8: Nos | C8: 25 | D8: 0 | E8: 2 | F8: 23 | G8: 48 | H8: 10 | I8: 64 | J8: 1465 | K8: Stock Available
A9: Beaker 50 ML | B9: Nos | C9: 28 | D9: 0 | E9: 3 | F9: 25 | G9: 48 | H9: 10 | I9: 16 | J9: 397 | K9: Stock Available
A10: BMC Cleaning Brush 2" | B10: Nos | C10: 26 | D10: 0 | E10: 3 | F10: 23 | G10: 10 | H10: 10 | I10: 212 | J10: 4885 | K10: Stock Available
A11: BMC Day Book | B11: Nos | C11: 90 | D11: 0 | E11: 86 | F11: 4 | G11: 300 | H11: 60 | I11: 122 | J11: 486 | K11: PO Required
A12: Burete Stand | B12: Nos | C12: 2 | D12: 0 | E12: 1 | F12: 1 | G12: 20 | H12: 5 | I12: 258 | J12: 258 | K12: PO Required
A13: Burret 50 ML Borosilicate | B13: Nos | C13: 8 | D13: 0 | E13: 3 | F13: 5 | G13: 20 | H13: 5 | I13: 99 | J13: 497 | K13: PO Required
... A97: Tilt Measure 1 Ml with Bottle | B97: Nos | C97: 230 | D97: 0 | E97: 8 | F97: 222 | G97: 500 | H97: 50 | I97: 32 | J97: 7124 | K97: Stock Available

Sheet Pending Recoveries
A1: Date | B1: (All)
A3: To BMC/MPG Code | B3: BMC MPG Name | C3: Recovery Done | D3: Sum of Amt
A4: 1002 | B4: Laldiyara | C4: Pending | D4: 19211.68
A5: 1007 | B5: Araria | C5: Pending | D5: 5616.8
A6: 1009 | B6: Halsi | C6: Pending | D6: 8712.5
A7: 1008 | B7: Teghra | C7: Pending | D7: 3204.32
A8: 10140002 | B8: Simri | C8: Pending | D8: 458.32
A9: 10140007 | B9: ENGLISH DUBAULI | C9: Pending | D9: 165.82
A10: 10140055 | B10: PURANA BHOJPUR | C10: Pending | D10: 1711.7
A11: 10140087 | B11: Gomukh Churamanpur | C11: Pending | D11: 1637.68
A12: 10140099 | B12: Gomukh Dhakaich | C12: Pending | D12: 1529
A13: 10510001 | B13: ARAK | C13: Pending | D13: 1208.99
A14: 10140145 | B14: Gomukh Pokhraha | C14: Pending | D14: 129.8
A15: 10140166 | B15: Gomukh KritSagar | C15: Pending | D15: 184.7
... A114: 10600013 | B114: Gomukh Chhotaki hardiya | C114: Pending | D114: 259.6
A115: Grand Total | D115: 126626.26

Sheet Issue
A1: Date | B1: Type | C1: Challan No | D1: From Location Code | E1: Location | F1: Type of Location | G1: To BMC/MPG Code | H1: BMC MPG Name | I1: Type of Location2 | J1: Item Name | K1: UoM | L1: Qty Issued | M1: Rate | N1: Amt | O1: Recoverable | P1: Recovery Done | Q1: Remarks
A2: 46113 | B2: Transfer | D2: 1 | E2: =IFERROR(VLOOKUP(Issue!$D2,Table5[#All],3,0),"") -> Munger | F2: =IFERROR(VLOOKUP(Issue!$D2,Table5[#All],2,0),"") -> Main Godown | G2: 1053 | H2: =IFERROR(VLOOKUP(Issue!$G2,Table5[#All],3,0),"") -> Kalyanpur | I2: =IFERROR(VLOOKUP(Issue!$G2,Table5[#All],2,0),"") -> BMC | J2: Eco Power Solution | K2: =IFERROR(VLOOKUP(Issue!$J2,Table2[[Item Name]:[UoM]],2,0),"") -> Nos | L2: 1 | M2: =IFERROR(VLOOKUP(Issue!$J2,Table2[[#All],[Item Name]:[Open Rate]],8,0),"") -> 348.52 | N2: =IFERROR(+Issue!$L2*Issue!$M2,"") -> 348.52 | O2: No | P2: NA
A3: 46113 | B3: Transfer | D3: 1 | E3: =IFERROR(VLOOKUP(Issue!$D3,Table5[#All],3,0),"") -> Munger | F3: =IFERROR(VLOOKUP(Issue!$D3,Table5[#All],2,0),"") -> Main Godown | G3: 1053 | H3: =IFERROR(VLOOKUP(Issue!$G3,Table5[#All],3,0),"") -> Kalyanpur | I3: =IFERROR(VLOOKUP(Issue!$G3,Table5[#All],2,0),"") -> BMC | J3: Eko Day Cleaning Sol | K3: =IFERROR(VLOOKUP(Issue!$J3,Table2[[Item Name]:[UoM]],2,0),"") -> Nos | L3: 21 | M3: =IFERROR(VLOOKUP(Issue!$J3,Table2[[#All],[Item Name]:[Open Rate]],8,0),"") -> 348.52 | N3: =IFERROR(+Issue!$L3*Issue!$M3,"") -> 7318.92 | O3: No | P3: NA
A4: 46113 | B4: Transfer | D4: 1 | E4: =IFERROR(VLOOKUP(Issue!$D4,Table5[#All],3,0),"") -> Munger | F4: =IFERROR(VLOOKUP(Issue!$D4,Table5[#All],2,0),"") -> Main Godown | G4: 1053 | H4: =IFERROR(VLOOKUP(Issue!$G4,Table5[#All],3,0),"") -> Kalyanpur | I4: =IFERROR(VLOOKUP(Issue!$G4,Table5[#All],2,0),"") -> BMC | J4: FAT Scan Weekly | K4: =IFERROR(VLOOKUP(Issue!$J4,Table2[[Item Name]:[UoM]],2,0),"") -> Nos | L4: 1 | M4: =IFERROR(VLOOKUP(Issue!$J4,Table2[[#All],[Item Name]:[Open Rate]],8,0),"") -> 348.52 | N4: =IFERROR(+Issue!$L4*Issue!$M4,"") -> 348.52 | O4: No | P4: NA
A5: 46113 | B5: Transfer | D5: 1 | E5: =IFERROR(VLOOKUP(Issue!$D5,Table5[#All],3,0),"") -> Munger | F5: =IFERROR(VLOOKUP(Issue!$D5,Table5[#All],2,0),"") -> Main Godown | G5: 1053 | H5: =IFERROR(VLOOKUP(Issue!$G5,Table5[#All],3,0),"") -> Kalyanpur | I5: =IFERROR(VLOOKUP(Issue!$G5,Table5[#All],2,0),"") -> BMC | J5: Milk Sampler Dipper SS Capacity 50ml | K5: =IFERROR(VLOOKUP(Issue!$J5,Table2[[Item Name]:[UoM]],2,0),"") -> Nos | L5: 4 | M5: =IFERROR(VLOOKUP(Issue!$J5,Table2[[#All],[Item Name]:[Open Rate]],8,0),"") -> 22.99 | N5: =IFERROR(+Issue!$L5*Issue!$M5,"") -> 91.96 | O5: No | P5: NA
A6: 46113 | B6: Transfer | D6: 1 | E6: =IFERROR(VLOOKUP(Issue!$D6,Table5[#All],3,0),"") -> Munger | F6: =IFERROR(VLOOKUP(Issue!$D6,Table5[#All],2,0),"") -> Main Godown | G6: 1053 | H6: =IFERROR(VLOOKUP(Issue!$G6,Table5[#All],3,0),"") -> Kalyanpur | I6: =IFERROR(VLOOKUP(Issue!$G6,Table5[#All],2,0),"") -> BMC | J6: MPG Register | K6: =IFERROR(VLOOKUP(Issue!$J6,Table2[[Item Name]:[UoM]],2,0),"") -> Nos | L6: 10 | M6: =IFERROR(VLOOKUP(Issue!$J6,Table2[[#All],[Item Name]:[Open Rate]],8,0),"") -> 129.8 | N6: =IFERROR(+Issue!$L6*Issue!$M6,"") -> 1298 | O6: No | P6: NA
A7: 46113 | B7: Transfer | D7: 1 | E7: =IFERROR(VLOOKUP(Issue!$D7,Table5[#All],3,0),"") -> Munger | F7: =IFERROR(VLOOKUP(Issue!$D7,Table5[#All],2,0),"") -> Main Godown | G7: 1053 | H7: =IFERROR(VLOOKUP(Issue!$G7,Table5[#All],3,0),"") -> Kalyanpur | I7: =IFERROR(VLOOKUP(Issue!$G7,Table5[#All],2,0),"") -> BMC | J7: Plastic Strainer | K7: =IFERROR(VLOOKUP(Issue!$J7,Table2[[Item Name]:[UoM]],2,0),"") -> Nos | L7: 4 | M7: =IFERROR(VLOOKUP(Issue!$J7,Table2[[#All],[Item Name]:[Open Rate]],8,0),"") -> 29.5 | N7: =IFERROR(+Issue!$L7*Issue!$M7,"") -> 118 | O7: No | P7: NA
A8: 46113 | B8: Transfer | D8: 1 | E8: =IFERROR(VLOOKUP(Issue!$D8,Table5[#All],3,0),"") -> Munger | F8: =IFERROR(VLOOKUP(Issue!$D8,Table5[#All],2,0),"") -> Main Godown | G8: 1053 | H8: =IFERROR(VLOOKUP(Issue!$G8,Table5[#All],3,0),"") -> Kalyanpur | I8: =IFERROR(VLOOKUP(Issue!$G8,Table5[#All],2,0),"") -> BMC | J8: Sample Bottle 100 ML | K8: =IFERROR(VLOOKUP(Issue!$J8,Table2[[Item Name]:[UoM]],2,0),"") -> Nos | L8: 4 | M8: =IFERROR(VLOOKUP(Issue!$J8,Table2[[#All],[Item Name]:[Open Rate]],8,0),"") -> 2.83 | N8: =IFERROR(+Issue!$L8*Issue!$M8,"") -> 11.32 | O8: No | P8: NA
A9: 46113 | B9: Transfer | D9: 1 | E9: =IFERROR(VLOOKUP(Issue!$D9,Table5[#All],3,0),"") -> Munger | F9: =IFERROR(VLOOKUP(Issue!$D9,Table5[#All],2,0),"") -> Main Godown | G9: 1053 | H9: =IFERROR(VLOOKUP(Issue!$G9,Table5[#All],3,0),"") -> Kalyanpur | I9: =IFERROR(VLOOKUP(Issue!$G9,Table5[#All],2,0),"") -> BMC | J9: Thermal Paper Roll - Small | K9: =IFERROR(VLOOKUP(Issue!$J9,Table2[[Item Name]:[UoM]],2,0),"") -> Nos | L9: 374 | M9: =IFERROR(VLOOKUP(Issue!$J9,Table2[[#All],[Item Name]:[Open Rate]],8,0),"") -> 9.15 | N9: =IFERROR(+Issue!$L9*Issue!$M9,"") -> 3422.1 | O9: No | P9: NA
A10: 46113 | B10: Transfer | D10: 1 | E10: =IFERROR(VLOOKUP(Issue!$D10,Table5[#All],3,0),"") -> Munger | F10: =IFERROR(VLOOKUP(Issue!$D10,Table5[#All],2,0),"") -> Main Godown | G10: 1014 | H10: =IFERROR(VLOOKUP(Issue!$G10,Table5[#All],3,0),"") -> Dumraon | I10: =IFERROR(VLOOKUP(Issue!$G10,Table5[#All],2,0),"") -> BMC | J10: Eco Power Solution | K10: =IFERROR(VLOOKUP(Issue!$J10,Table2[[Item Name]:[UoM]],2,0),"") -> Nos | L10: 18 | M10: =IFERROR(VLOOKUP(Issue!$J10,Table2[[#All],[Item Name]:[Open Rate]],8,0),"") -> 348.52 | N10: =IFERROR(+Issue!$L10*Issue!$M10,"") -> 6273.36 | O10: No | P10: NA
A11: 46113 | B11: Transfer | D11: 1 | E11: =IFERROR(VLOOKUP(Issue!$D11,Table5[#All],3,0),"") -> Munger | F11: =IFERROR(VLOOKUP(Issue!$D11,Table5[#All],2,0),"") -> Main Godown | G11: 1014 | H11: =IFERROR(VLOOKUP(Issue!$G11,Table5[#All],3,0),"") -> Dumraon | I11: =IFERROR(VLOOKUP(Issue!$G11,Table5[#All],2,0),"") -> BMC | J11: Eko Day Cleaning Sol | K11: =IFERROR(VLOOKUP(Issue!$J11,Table2[[Item Name]:[UoM]],2,0),"") -> Nos | L11: 96 | M11: =IFERROR(VLOOKUP(Issue!$J11,Table2[[#All],[Item Name]:[Open Rate]],8,0),"") -> 348.52 | N11: =IFERROR(+Issue!$L11*Issue!$M11,"") -> 33457.92 | O11: No | P11: NA
A12: 46113 | B12: Transfer | D12: 1 | E12: =IFERROR(VLOOKUP(Issue!$D12,Table5[#All],3,0),"") -> Munger | F12: =IFERROR(VLOOKUP(Issue!$D12,Table5[#All],2,0),"") -> Main Godown | G12: 1014 | H12: =IFERROR(VLOOKUP(Issue!$G12,Table5[#All],3,0),"") -> Dumraon | I12: =IFERROR(VLOOKUP(Issue!$G12,Table5[#All],2,0),"") -> BMC | J12: EKO Plunger | K12: =IFERROR(VLOOKUP(Issue!$J12,Table2[[Item Name]:[UoM]],2,0),"") -> Nos | L12: 81 | M12: =IFERROR(VLOOKUP(Issue!$J12,Table2[[#All],[Item Name]:[Open Rate]],8,0),"") -> 56.02 | N12: =IFERROR(+Issue!$L12*Issue!$M12,"") -> 4537.62 | O12: No | P12: NA
A13: 46113 | B13: Transfer | D13: 1 | E13: =IFERROR(VLOOKUP(Issue!$D13,Table5[#All],3,0),"") -> Munger | F13: =IFERROR(VLOOKUP(Issue!$D13,Table5[#All],2,0),"") -> Main Godown | G13: 1014 | H13: =IFERROR(VLOOKUP(Issue!$G13,Table5[#All],3,0),"") -> Dumraon | I13: =IFERROR(VLOOKUP(Issue!$G13,Table5[#All],2,0),"") -> BMC | J13: Farmers Passbook | K13: =IFERROR(VLOOKUP(Issue!$J13,Table2[[Item Name]:[UoM]],2,0),"") -> Nos | L13: 656 | M13: =IFERROR(VLOOKUP(Issue!$J13,Table2[[#All],[Item Name]:[Open Rate]],8,0),"") -> 5.13 | N13: =IFERROR(+Issue!$L13*Issue!$M13,"") -> 3365.28 | O13: No | P13: NA
... A29: 46113 | B29: Transfer | D29: 1 | E29: =IFERROR(VLOOKUP(Issue!$D29,Table5[#All],3,0),"") -> Munger | F29: =IFERROR(VLOOKUP(Issue!$D29,Table5[#All],2,0),"") -> Main Godown | G29: 1012 | H29: =IFERROR(VLOOKUP(Issue!$G29,Table5[#All],3,0),"") -> DalsinghSarai | I29: =IFERROR(VLOOKUP(Issue!$G29,Table5[#All],2,0),"") -> BMC | J29: MPG Register | K29: =IFERROR(VLOOKUP(Issue!$J29,Table2[[Item Name]:[UoM]],2,0),"") -> Nos | L29: 20 | M29: =IFERROR(VLOOKUP(Issue!$J29,Table2[[#All],[Item Name]:[Open Rate]],8,0),"") -> 129.8 | N29: =IFERROR(+Issue!$L29*Issue!$M29,"") -> 2596 | O29: No | P29: NA
A30: 46114 | B30: Consumed | C30: 623 | D30: 1 | E30: =IFERROR(VLOOKUP(Issue!$D30,Table5[#All],3,0),"") -> Munger | F30: =IFERROR(VLOOKUP(Issue!$D30,Table5[#All],2,0),"") -> Main Godown | G30: 1010 | H30: =IFERROR(VLOOKUP(Issue!$G30,Table5[#All],3,0),"") -> Parbatta | I30: =IFERROR(VLOOKUP(Issue!$G30,Table5[#All],2,0),"") -> BMC | J30: BMC Day Book | K30: =IFERROR(VLOOKUP(Issue!$J30,Table2[[Item Name]:[UoM]],2,0),"") -> Nos | L30: 10 | M30: =IFERROR(VLOOKUP(Issue!$J30,Table2[[#All],[Item Name]:[Open Rate]],8,0),"") -> 121.54 | N30: =IFERROR(+Issue!$L30*Issue!$M30,"") -> 1215.4 | O30: Yes | P30: Pending
A31: 46114 | B31: Consumed | C31: 623 | D31: 1 | E31: =IFERROR(VLOOKUP(Issue!$D31,Table5[#All],3,0),"") -> Munger | F31: =IFERROR(VLOOKUP(Issue!$D31,Table5[#All],2,0),"") -> Main Godown | G31: 1010 | H31: =IFERROR(VLOOKUP(Issue!$G31,Table5[#All],3,0),"") -> Parbatta | I31: =IFERROR(VLOOKUP(Issue!$G31,Table5[#All],2,0),"") -> BMC | J31: Buterometer | K31: =IFERROR(VLOOKUP(Issue!$J31,Table2[[Item Name]:[UoM]],2,0),"") -> Nos | L31: 1 | M31: =IFERROR(VLOOKUP(Issue!$J31,Table2[[#All],[Item Name]:[Open Rate]],8,0),"") -> 132.7 | N31: =IFERROR(+Issue!$L31*Issue!$M31,"") -> 132.7 | O31: Yes | P31: Pending
A32: 46114 | B32: Consumed | C32: 623 | D32: 1 | E32: =IFERROR(VLOOKUP(Issue!$D32,Table5[#All],3,0),"") -> Munger | F32: =IFERROR(VLOOKUP(Issue!$D32,Table5[#All],2,0),"") -> Main Godown | G32: 1010 | H32: =IFERROR(VLOOKUP(Issue!$G32,Table5[#All],3,0),"") -> Parbatta | I32: =IFERROR(VLOOKUP(Issue!$G32,Table5[#All],2,0),"") -> BMC | J32: Lactometer 0-40 | K32: =IFERROR(VLOOKUP(Issue!$J32,Table2[[Item Name]:[UoM]],2,0),"") -> Nos | L32: 1 | M32: =IFERROR(VLOOKUP(Issue!$J32,Table2[[#All],[Item Name]:[Open Rate]],8,0),"") -> 132.7 | N32: =IFERROR(+Issue!$L32*Issue!$M32,"") -> 132.7 | O32: Yes | P32: Pending
A33: 46116 | B33: Consumed | C33: 624 | D33: 1 | E33: =IFERROR(VLOOKUP(Issue!$D33,Table5[#All],3,0),"") -> Munger | F33: =IFERROR(VLOOKUP(Issue!$D33,Table5[#All],2,0),"") -> Main Godown | G33: 1054 | H33: =IFERROR(VLOOKUP(Issue!$G33,Table5[#All],3,0),"") -> Alauli | I33: =IFERROR(VLOOKUP(Issue!$G33,Table5[#All],2,0),"") -> BMC | J33: TEEPOL | K33: =IFERROR(VLOOKUP(Issue!$J33,Table2[[Item Name]:[UoM]],2,0),"") -> Nos | L33: 25 | M33: =IFERROR(VLOOKUP(Issue!$J33,Table2[[#All],[Item Name]:[Open Rate]],8,0),"") -> 51.92 | N33: =IFERROR(+Issue!$L33*Issue!$M33,"") -> 1298 | O33: No | P33: NA
A34: 46116 | B34: Consumed | C34: 624 | D34: 1 | E34: =IFERROR(VLOOKUP(Issue!$D34,Table5[#All],3,0),"") -> Munger | F34: =IFERROR(VLOOKUP(Issue!$D34,Table5[#All],2,0),"") -> Main Godown | G34: 1054 | H34: =IFERROR(VLOOKUP(Issue!$G34,Table5[#All],3,0),"") -> Alauli | I34: =IFERROR(VLOOKUP(Issue!$G34,Table5[#All],2,0),"") -> BMC | J34: Satol - 5 KG | K34: =IFERROR(VLOOKUP(Issue!$J34,Table2[[Item Name]:[UoM]],2,0),"") -> Nos | L34: 5 | M34: =IFERROR(VLOOKUP(Issue!$J34,Table2[[#All],[Item Name]:[Open Rate]],8,0),"") -> 135.7 | N34: =IFERROR(+Issue!$L34*Issue!$M34,"") -> 678.5 | O34: No | P34: NA
A35: 46116 | B35: Consumed | C35: 624 | D35: 1 | E35: =IFERROR(VLOOKUP(Issue!$D35,Table5[#All],3,0),"") -> Munger | F35: =IFERROR(VLOOKUP(Issue!$D35,Table5[#All],2,0),"") -> Main Godown | G35: 1054 | H35: =IFERROR(VLOOKUP(Issue!$G35,Table5[#All],3,0),"") -> Alauli | I35: =IFERROR(VLOOKUP(Issue!$G35,Table5[#All],2,0),"") -> BMC | J35: Sulphuric Acid SQ 05 Lt | K35: =IFERROR(VLOOKUP(Issue!$J35,Table2[[Item Name]:[UoM]],2,0),"") -> Nos | L35: 1 | M35: =IFERROR(VLOOKUP(Issue!$J35,Table2[[#All],[Item Name]:[Open Rate]],8,0),"") -> 812.2 | N35: =IFERROR(+Issue!$L35*Issue!$M35,"") -> 812.2 | O35: No | P35: NA
A36: 46116 | B36: Consumed | C36: 624 | D36: 1 | E36: =IFERROR(VLOOKUP(Issue!$D36,Table5[#All],3,0),"") -> Munger | F36: =IFERROR(VLOOKUP(Issue!$D36,Table5[#All],2,0),"") -> Main Godown | G36: 1054 | H36: =IFERROR(VLOOKUP(Issue!$G36,Table5[#All],3,0),"") -> Alauli | I36: =IFERROR(VLOOKUP(Issue!$G36,Table5[#All],2,0),"") -> BMC | J36: Test Tube with Rubber Cork | K36: =IFERROR(VLOOKUP(Issue!$J36,Table2[[Item Name]:[UoM]],2,0),"") -> Nos | L36: 30 | M36: =IFERROR(VLOOKUP(Issue!$J36,Table2[[#All],[Item Name]:[Open Rate]],8,0),"") -> 4.93 | N36: =IFERROR(+Issue!$L36*Issue!$M36,"") -> 147.9 | O36: No | P36: NA
A37: 46116 | B37: Consumed | C37: 624 | D37: 1 | E37: =IFERROR(VLOOKUP(Issue!$D37,Table5[#All],3,0),"") -> Munger | F37: =IFERROR(VLOOKUP(Issue!$D37,Table5[#All],2,0),"") -> Main Godown | G37: 1054 | H37: =IFERROR(VLOOKUP(Issue!$G37,Table5[#All],3,0),"") -> Alauli | I37: =IFERROR(VLOOKUP(Issue!$G37,Table5[#All],2,0),"") -> BMC | J37: Distil Water 5 Ltr | K37: =IFERROR(VLOOKUP(Issue!$J37,Table2[[Item Name]:[UoM]],2,0),"") -> Nos | L37: 1 | M37: =IFERROR(VLOOKUP(Issue!$J37,Table2[[#All],[Item Name]:[Open Rate]],8,0),"") -> 168 | N37: =IFERROR(+Issue!$L37*Issue!$M37,"") -> 168 | O37: No | P37: NA
A38: 46116 | B38: Consumed | C38: 625 | D38: 1 | E38: =IFERROR(VLOOKUP(Issue!$D38,Table5[#All],3,0),"") -> Munger | F38: =IFERROR(VLOOKUP(Issue!$D38,Table5[#All],2,0),"") -> Main Godown | G38: 1011 | H38: =IFERROR(VLOOKUP(Issue!$G38,Table5[#All],3,0),"") -> Sahibpur Kamal | I38: =IFERROR(VLOOKUP(Issue!$G38,Table5[#All],2,0),"") -> BMC | J38: Tanker Seal | K38: =IFERROR(VLOOKUP(Issue!$J38,Table2[[Item Name]:[UoM]],2,0),"") -> Nos | L38: 200 | M38: =IFERROR(VLOOKUP(Issue!$J38,Table2[[#All],[Item Name]:[Open Rate]],8,0),"") -> 12.71 | N38: =IFERROR(+Issue!$L38*Issue!$M38,"") -> 2542 | O38: No | P38: NA
A39: 46116 | B39: Consumed | C39: 625 | D39: 1 | E39: =IFERROR(VLOOKUP(Issue!$D39,Table5[#All],3,0),"") -> Munger | F39: =IFERROR(VLOOKUP(Issue!$D39,Table5[#All],2,0),"") -> Main Godown | G39: 1055 | H39: =IFERROR(VLOOKUP(Issue!$G39,Table5[#All],3,0),"") -> Matihani | I39: =IFERROR(VLOOKUP(Issue!$G39,Table5[#All],2,0),"") -> BMC | J39: Tanker Seal | K39: =IFERROR(VLOOKUP(Issue!$J39,Table2[[Item Name]:[UoM]],2,0),"") -> Nos | L39: 200 | M39: =IFERROR(VLOOKUP(Issue!$J39,Table2[[#All],[Item Name]:[Open Rate]],8,0),"") -> 12.71 | N39: =IFERROR(+Issue!$L39*Issue!$M39,"") -> 2542 | O39: No | P39: NA
A40: 46116 | B40: Consumed | C40: 625 | D40: 1 | E40: =IFERROR(VLOOKUP(Issue!$D40,Table5[#All],3,0),"") -> Munger | F40: =IFERROR(VLOOKUP(Issue!$D40,Table5[#All],2,0),"") -> Main Godown | G40: 1008 | H40: =IFERROR(VLOOKUP(Issue!$G40,Table5[#All],3,0),"") -> Teghra | I40: =IFERROR(VLOOKUP(Issue!$G40,Table5[#All],2,0),"") -> BMC | J40: Tanker Seal | K40: =IFERROR(VLOOKUP(Issue!$J40,Table2[[Item Name]:[UoM]],2,0),"") -> Nos | L40: 200 | M40: =IFERROR(VLOOKUP(Issue!$J40,Table2[[#All],[Item Name]:[Open Rate]],8,0),"") -> 12.71 | N40: =IFERROR(+Issue!$L40*Issue!$M40,"") -> 2542 | O40: Yes | P40: Pending
A41: 46116 | B41: Consumed | C41: 625 | D41: 1 | E41: =IFERROR(VLOOKUP(Issue!$D41,Table5[#All],3,0),"") -> Munger | F41: =IFERROR(VLOOKUP(Issue!$D41,Table5[#All],2,0),"") -> Main Godown | G41: 1011 | H41: =IFERROR(VLOOKUP(Issue!$G41,Table5[#All],3,0),"") -> Sahibpur Kamal | I41: =IFERROR(VLOOKUP(Issue!$G41,Table5[#All],2,0),"") -> BMC | J41: Milk Despatch Challan | K41: =IFERROR(VLOOKUP(Issue!$J41,Table2[[Item Name]:[UoM]],2,0),"") -> Nos | L41: 2 | M41: =IFERROR(VLOOKUP(Issue!$J41,Table2[[#All],[Item Name]:[Open Rate]],8,0),"") -> 94.4 | N41: =IFERROR(+Issue!$L41*Issue!$M41,"") -> 188.8 | O41: No | P41: NA
... A90: 46121 | B90: Consumed | C90: 631 | D90: 1 | E90: =IFERROR(VLOOKUP(Issue!$D90,Table5[#All],3,0),"") -> Munger | F90: =IFERROR(VLOOKUP(Issue!$D90,Table5[#All],2,0),"") -> Main Godown | G90: 1065 | H90: =IFERROR(VLOOKUP(Issue!$G90,Table5[#All],3,0),"") -> Bachhwara BMC | I90: =IFERROR(VLOOKUP(Issue!$G90,Table5[#All],2,0),"") -> MPG | J90: Sample Bottle Brush Large | K90: =IFERROR(VLOOKUP(Issue!$J90,Table2[[Item Name]:[UoM]],2,0),"") -> Nos | L90: 18 | M90: =IFERROR(VLOOKUP(Issue!$J90,Table2[[#All],[Item Name]:[Open Rate]],8,0),"") -> 1.68 | N90: =IFERROR(+Issue!$L90*Issue!$M90,"") -> 30.24 | O90: No | P90: NA
A91: 46121 | B91: Consumed | C91: 632 | D91: 1 | E91: =IFERROR(VLOOKUP(Issue!$D91,Table5[#All],3,0),"") -> Munger | F91: =IFERROR(VLOOKUP(Issue!$D91,Table5[#All],2,0),"") -> Main Godown | G91: Lab | H91: =IFERROR(VLOOKUP(Issue!$G91,Table5[#All],3,0),"") -> Daya_Lab | I91: =IFERROR(VLOOKUP(Issue!$G91,Table5[#All],2,0),"") -> Lab | J91: Para Dimethyle Amino | K91: =IFERROR(VLOOKUP(Issue!$J91,Table2[[Item Name]:[UoM]],2,0),"") -> Nos | L91: 1 | M91: =IFERROR(VLOOKUP(Issue!$J91,Table2[[#All],[Item Name]:[Open Rate]],8,0),"") -> 689.39 | N91: =IFERROR(+Issue!$L91*Issue!$M91,"") -> 689.39 | O91: No | P91: NA
A92: 46121 | B92: Consumed | C92: 632 | D92: 1 | E92: =IFERROR(VLOOKUP(Issue!$D92,Table5[#All],3,0),"") -> Munger | F92: =IFERROR(VLOOKUP(Issue!$D92,Table5[#All],2,0),"") -> Main Godown | G92: Lab | H92: =IFERROR(VLOOKUP(Issue!$G92,Table5[#All],3,0),"") -> Daya_Lab | I92: =IFERROR(VLOOKUP(Issue!$G92,Table5[#All],2,0),"") -> Lab | J92: Resorcinol | K92: =IFERROR(VLOOKUP(Issue!$J92,Table2[[Item Name]:[UoM]],2,0),"") -> Nos | L92: 1 | M92: =IFERROR(VLOOKUP(Issue!$J92,Table2[[#All],[Item Name]:[Open Rate]],8,0),"") -> 504.15 | N92: =IFERROR(+Issue!$L92*Issue!$M92,"") -> 504.15 | O92: No | P92: NA
A93: 46121 | B93: Consumed | C93: 632 | D93: 1 | E93: =IFERROR(VLOOKUP(Issue!$D93,Table5[#All],3,0),"") -> Munger | F93: =IFERROR(VLOOKUP(Issue!$D93,Table5[#All],2,0),"") -> Main Godown | G93: Lab | H93: =IFERROR(VLOOKUP(Issue!$G93,Table5[#All],3,0),"") -> Daya_Lab | I93: =IFERROR(VLOOKUP(Issue!$G93,Table5[#All],2,0),"") -> Lab | J93: Milk Despatch Challan | K93: =IFERROR(VLOOKUP(Issue!$J93,Table2[[Item Name]:[UoM]],2,0),"") -> Nos | L93: 5 | M93: =IFERROR(VLOOKUP(Issue!$J93,Table2[[#All],[Item Name]:[Open Rate]],8,0),"") -> 94.4 | N93: =IFERROR(+Issue!$L93*Issue!$M93,"") -> 472 | O93: No | P93: NA
A94: 46125 | B94: Consumed | C94: 634 | D94: 1 | E94: =IFERROR(VLOOKUP(Issue!$D94,Table5[#All],3,0),"") -> Munger | F94: =IFERROR(VLOOKUP(Issue!$D94,Table5[#All],2,0),"") -> Main Godown | G94: 1001 | H94: =IFERROR(VLOOKUP(Issue!$G94,Table5[#All],3,0),"") -> Majhaul | I94: =IFERROR(VLOOKUP(Issue!$G94,Table5[#All],2,0),"") -> BMC | J94: Tanker Seal | K94: =IFERROR(VLOOKUP(Issue!$J94,Table2[[Item Name]:[UoM]],2,0),"") -> Nos | L94: 200 | M94: =IFERROR(VLOOKUP(Issue!$J94,Table2[[#All],[Item Name]:[Open Rate]],8,0),"") -> 12.71 | N94: =IFERROR(+Issue!$L94*Issue!$M94,"") -> 2542 | O94: No | P94: NA
A95: 46125 | B95: Consumed | C95: 634 | D95: 1 | E95: =IFERROR(VLOOKUP(Issue!$D95,Table5[#All],3,0),"") -> Munger | F95: =IFERROR(VLOOKUP(Issue!$D95,Table5[#All],2,0),"") -> Main Godown | G95: 1001 | H95: =IFERROR(VLOOKUP(Issue!$G95,Table5[#All],3,0),"") -> Majhaul | I95: =IFERROR(VLOOKUP(Issue!$G95,Table5[#All],2,0),"") -> BMC | J95: Phenolphthaleing Indicator | K95: =IFERROR(VLOOKUP(Issue!$J95,Table2[[Item Name]:[UoM]],2,0),"") -> Nos | L95: 1 | M95: =IFERROR(VLOOKUP(Issue!$J95,Table2[[#All],[Item Name]:[Open Rate]],8,0),"") -> 106.2 | N95: =IFERROR(+Issue!$L95*Issue!$M95,"") -> 106.2 | O95: No | P95: NA
A96: 46125 | B96: Consumed | C96: 634 | D96: 1 | E96: =IFERROR(VLOOKUP(Issue!$D96,Table5[#All],3,0),"") -> Munger | F96: =IFERROR(VLOOKUP(Issue!$D96,Table5[#All],2,0),"") -> Main Godown | G96: 1001 | H96: =IFERROR(VLOOKUP(Issue!$G96,Table5[#All],3,0),"") -> Majhaul | I96: =IFERROR(VLOOKUP(Issue!$G96,Table5[#All],2,0),"") -> BMC | J96: Sodium Hydroxide N/10 Solution | K96: =IFERROR(VLOOKUP(Issue!$J96,Table2[[Item Name]:[UoM]],2,0),"") -> Nos | L96: 1 | M96: =IFERROR(VLOOKUP(Issue!$J96,Table2[[#All],[Item Name]:[Open Rate]],8,0),"") -> 135.7 | N96: =IFERROR(+Issue!$L96*Issue!$M96,"") -> 135.7 | O96: No | P96: NA
A97: 46125 | B97: Consumed | C97: 634 | D97: 1 | E97: =IFERROR(VLOOKUP(Issue!$D97,Table5[#All],3,0),"") -> Munger | F97: =IFERROR(VLOOKUP(Issue!$D97,Table5[#All],2,0),"") -> Main Godown | G97: 1001 | H97: =IFERROR(VLOOKUP(Issue!$G97,Table5[#All],3,0),"") -> Majhaul | I97: =IFERROR(VLOOKUP(Issue!$G97,Table5[#All],2,0),"") -> BMC | J97: Amyl 500ml | K97: =IFERROR(VLOOKUP(Issue!$J97,Table2[[Item Name]:[UoM]],2,0),"") -> Nos | L97: 1 | M97: =IFERROR(VLOOKUP(Issue!$J97,Table2[[#All],[Item Name]:[Open Rate]],8,0),"") -> 365.8 | N97: =IFERROR(+Issue!$L97*Issue!$M97,"") -> 365.8 | O97: No | P97: NA
A98: 46125 | B98: Consumed | C98: 634 | D98: 1 | E98: =IFERROR(VLOOKUP(Issue!$D98,Table5[#All],3,0),"") -> Munger | F98: =IFERROR(VLOOKUP(Issue!$D98,Table5[#All],2,0),"") -> Main Godown | G98: 1001 | H98: =IFERROR(VLOOKUP(Issue!$G98,Table5[#All],3,0),"") -> Majhaul | I98: =IFERROR(VLOOKUP(Issue!$G98,Table5[#All],2,0),"") -> BMC | J98: Hydrolic Acid | K98: =IFERROR(VLOOKUP(Issue!$J98,Table2[[Item Name]:[UoM]],2,0),"") -> Nos | L98: 1 | M98: =IFERROR(VLOOKUP(Issue!$J98,Table2[[#All],[Item Name]:[Open Rate]],8,0),"") -> 282.8 | N98: =IFERROR(+Issue!$L98*Issue!$M98,"") -> 282.8 | O98: No | P98: NA
A99: 46125 | B99: Consumed | C99: 634 | D99: 1 | E99: =IFERROR(VLOOKUP(Issue!$D99,Table5[#All],3,0),"") -> Munger | F99: =IFERROR(VLOOKUP(Issue!$D99,Table5[#All],2,0),"") -> Main Godown | G99: 1001 | H99: =IFERROR(VLOOKUP(Issue!$G99,Table5[#All],3,0),"") -> Majhaul | I99: =IFERROR(VLOOKUP(Issue!$G99,Table5[#All],2,0),"") -> BMC | J99: TEEPOL | K99: =IFERROR(VLOOKUP(Issue!$J99,Table2[[Item Name]:[UoM]],2,0),"") -> Nos | L99: 25 | M99: =IFERROR(VLOOKUP(Issue!$J99,Table2[[#All],[Item Name]:[Open Rate]],8,0),"") -> 51.92 | N99: =IFERROR(+Issue!$L99*Issue!$M99,"") -> 1298 | O99: No | P99: NA
A100: 46125 | B100: Consumed | C100: 634 | D100: 1 | E100: =IFERROR(VLOOKUP(Issue!$D100,Table5[#All],3,0),"") -> Munger | F100: =IFERROR(VLOOKUP(Issue!$D100,Table5[#All],2,0),"") -> Main Godown | G100: 1001 | H100: =IFERROR(VLOOKUP(Issue!$G100,Table5[#All],3,0),"") -> Majhaul | I100: =IFERROR(VLOOKUP(Issue!$G100,Table5[#All],2,0),"") -> BMC | J100: Satol - 5 KG | K100: =IFERROR(VLOOKUP(Issue!$J100,Table2[[Item Name]:[UoM]],2,0),"") -> Nos | L100: 5 | M100: =IFERROR(VLOOKUP(Issue!$J100,Table2[[#All],[Item Name]:[Open Rate]],8,0),"") -> 135.7 | N100: =IFERROR(+Issue!$L100*Issue!$M100,"") -> 678.5 | O100: No | P100: NA
A101: 46125 | B101: Consumed | C101: 634 | D101: 1 | E101: =IFERROR(VLOOKUP(Issue!$D101,Table5[#All],3,0),"") -> Munger | F101: =IFERROR(VLOOKUP(Issue!$D101,Table5[#All],2,0),"") -> Main Godown | G101: 1001 | H101: =IFERROR(VLOOKUP(Issue!$G101,Table5[#All],3,0),"") -> Majhaul | I101: =IFERROR(VLOOKUP(Issue!$G101,Table5[#All],2,0),"") -> BMC | J101: Register for Milk Reception Log Book | K101: =IFERROR(VLOOKUP(Issue!$J101,Table2[[Item Name]:[UoM]],2,0),"") -> Nos | L101: 6 | M101: =IFERROR(VLOOKUP(Issue!$J101,Table2[[#All],[Item Name]:[Open Rate]],8,0),"") -> 218.3 | N101: =IFERROR(+Issue!$L101*Issue!$M101,"") -> 1309.8 | O101: No | P101: NA
A102: 46125 | B102: Consumed | C102: 634 | D102: 1 | E102: =IFERROR(VLOOKUP(Issue!$D102,Table5[#All],3,0),"") -> Munger | F102: =IFERROR(VLOOKUP(Issue!$D102,Table5[#All],2,0),"") -> Main Godown | G102: 1001 | H102: =IFERROR(VLOOKUP(Issue!$G102,Table5[#All],3,0),"") -> Majhaul | I102: =IFERROR(VLOOKUP(Issue!$G102,Table5[#All],2,0),"") -> BMC | J102: BMC Day Book | K102: =IFERROR(VLOOKUP(Issue!$J102,Table2[[Item Name]:[UoM]],2,0),"") -> Nos | L102: 6 | M102: =IFERROR(VLOOKUP(Issue!$J102,Table2[[#All],[Item Name]:[Open Rate]],8,0),"") -> 121.54 | N102: =IFERROR(+Issue!$L102*Issue!$M102,"") -> 729.24 | O102: No | P102: NA
A103: 46125 | B103: Consumed | C103: 634 | D103: 1 | E103: =IFERROR(VLOOKUP(Issue!$D103,Table5[#All],3,0),"") -> Munger | F103: =IFERROR(VLOOKUP(Issue!$D103,Table5[#All],2,0),"") -> Main Godown | G103: 1001 | H103: =IFERROR(VLOOKUP(Issue!$G103,Table5[#All],3,0),"") -> Majhaul | I103: =IFERROR(VLOOKUP(Issue!$G103,Table5[#All],2,0),"") -> BMC | J103: Milk Despatch Challan | K103: =IFERROR(VLOOKUP(Issue!$J103,Table2[[Item Name]:[UoM]],2,0),"") -> Nos | L103: 6 | M103: =IFERROR(VLOOKUP(Issue!$J103,Table2[[#All],[Item Name]:[Open Rate]],8,0),"") -> 94.4 | N103: =IFERROR(+Issue!$L103*Issue!$M103,"") -> 566.4 | O103: No | P103: NA
...

Sheet Pending Consumption
A1: S No | B1: Name of BMC | C1: Item Name | D1: Issue | E1: Consumed | F1: Balance
A2: 1 | B2: Sahibpur Kamal | C2: 1% Iodine Solution (100ml) | D2: =SUMIFS(Issue!$L$1:$L$4036,Issue!$H$1:$H$4036,'Pending Consumption'!$B2,Issue!$J$1:$J$4036,'Pending Consumption'!$C2,Issue!$B$1:$B$4036,"Transfer") -> 0 | E2: =SUMIFS(Issue!$L$1:$L$4036,Issue!$E$1:$E$4036,'Pending Consumption'!B2,Issue!$J$1:$J$4036,'Pending Consumption'!$C2,Issue!$B$1:$B$4036,"Consumed") -> 0 | F2: =+D2-E2 -> 0
A3: 2 | B3: Sahibpur Kamal | C3: Amber Colour Bottle (250 ML) | D3: =SUMIFS(Issue!$L$1:$L$4036,Issue!$H$1:$H$4036,'Pending Consumption'!$B3,Issue!$J$1:$J$4036,'Pending Consumption'!$C3,Issue!$B$1:$B$4036,"Transfer") -> 0 | E3: =SUMIFS(Issue!$L$1:$L$4036,Issue!$E$1:$E$4036,'Pending Consumption'!B3,Issue!$J$1:$J$4036,'Pending Consumption'!$C3,Issue!$B$1:$B$4036,"Consumed") -> 0 | F3: =+D3-E3 -> 0
A4: 3 | B4: Sahibpur Kamal | C4: Amyl 500ml | D4: =SUMIFS(Issue!$L$1:$L$4036,Issue!$H$1:$H$4036,'Pending Consumption'!$B4,Issue!$J$1:$J$4036,'Pending Consumption'!$C4,Issue!$B$1:$B$4036,"Transfer") -> 0 | E4: =SUMIFS(Issue!$L$1:$L$4036,Issue!$E$1:$E$4036,'Pending Consumption'!B4,Issue!$J$1:$J$4036,'Pending Consumption'!$C4,Issue!$B$1:$B$4036,"Consumed") -> 0 | F4: =+D4-E4 -> 0
A5: 4 | B5: Sahibpur Kamal | C5: Analyzer Calibration Cheking Log Book | D5: =SUMIFS(Issue!$L$1:$L$4036,Issue!$H$1:$H$4036,'Pending Consumption'!$B5,Issue!$J$1:$J$4036,'Pending Consumption'!$C5,Issue!$B$1:$B$4036,"Transfer") -> 0 | E5: =SUMIFS(Issue!$L$1:$L$4036,Issue!$E$1:$E$4036,'Pending Consumption'!B5,Issue!$J$1:$J$4036,'Pending Consumption'!$C5,Issue!$B$1:$B$4036,"Consumed") -> 0 | F5: =+D5-E5 -> 0
A6: 5 | B6: Sahibpur Kamal | C6: Beaker 100 Ml | D6: =SUMIFS(Issue!$L$1:$L$4036,Issue!$H$1:$H$4036,'Pending Consumption'!$B6,Issue!$J$1:$J$4036,'Pending Consumption'!$C6,Issue!$B$1:$B$4036,"Transfer") -> 0 | E6: =SUMIFS(Issue!$L$1:$L$4036,Issue!$E$1:$E$4036,'Pending Consumption'!B6,Issue!$J$1:$J$4036,'Pending Consumption'!$C6,Issue!$B$1:$B$4036,"Consumed") -> 0 | F6: =+D6-E6 -> 0
A7: 6 | B7: Sahibpur Kamal | C7: Beaker 250 ML Borosilicate | D7: =SUMIFS(Issue!$L$1:$L$4036,Issue!$H$1:$H$4036,'Pending Consumption'!$B7,Issue!$J$1:$J$4036,'Pending Consumption'!$C7,Issue!$B$1:$B$4036,"Transfer") -> 0 | E7: =SUMIFS(Issue!$L$1:$L$4036,Issue!$E$1:$E$4036,'Pending Consumption'!B7,Issue!$J$1:$J$4036,'Pending Consumption'!$C7,Issue!$B$1:$B$4036,"Consumed") -> 0 | F7: =+D7-E7 -> 0
A8: 7 | B8: Sahibpur Kamal | C8: Beaker 500 Ml | D8: =SUMIFS(Issue!$L$1:$L$4036,Issue!$H$1:$H$4036,'Pending Consumption'!$B8,Issue!$J$1:$J$4036,'Pending Consumption'!$C8,Issue!$B$1:$B$4036,"Transfer") -> 0 | E8: =SUMIFS(Issue!$L$1:$L$4036,Issue!$E$1:$E$4036,'Pending Consumption'!B8,Issue!$J$1:$J$4036,'Pending Consumption'!$C8,Issue!$B$1:$B$4036,"Consumed") -> 0 | F8: =+D8-E8 -> 0
A9: 8 | B9: Sahibpur Kamal | C9: Beaker 50 ML | D9: =SUMIFS(Issue!$L$1:$L$4036,Issue!$H$1:$H$4036,'Pending Consumption'!$B9,Issue!$J$1:$J$4036,'Pending Consumption'!$C9,Issue!$B$1:$B$4036,"Transfer") -> 0 | E9: =SUMIFS(Issue!$L$1:$L$4036,Issue!$E$1:$E$4036,'Pending Consumption'!B9,Issue!$J$1:$J$4036,'Pending Consumption'!$C9,Issue!$B$1:$B$4036,"Consumed") -> 0 | F9: =+D9-E9 -> 0
A10: 9 | B10: Sahibpur Kamal | C10: BMC Cleaning Brush 2" | D10: =SUMIFS(Issue!$L$1:$L$4036,Issue!$H$1:$H$4036,'Pending Consumption'!$B10,Issue!$J$1:$J$4036,'Pending Consumption'!$C10,Issue!$B$1:$B$4036,"Transfer") -> 0 | E10: =SUMIFS(Issue!$L$1:$L$4036,Issue!$E$1:$E$4036,'Pending Consumption'!B10,Issue!$J$1:$J$4036,'Pending Consumption'!$C10,Issue!$B$1:$B$4036,"Consumed") -> 0 | F10: =+D10-E10 -> 0
A11: 10 | B11: Sahibpur Kamal | C11: BMC Day Book | D11: =SUMIFS(Issue!$L$1:$L$4036,Issue!$H$1:$H$4036,'Pending Consumption'!$B11,Issue!$J$1:$J$4036,'Pending Consumption'!$C11,Issue!$B$1:$B$4036,"Transfer") -> 0 | E11: =SUMIFS(Issue!$L$1:$L$4036,Issue!$E$1:$E$4036,'Pending Consumption'!B11,Issue!$J$1:$J$4036,'Pending Consumption'!$C11,Issue!$B$1:$B$4036,"Consumed") -> 0 | F11: =+D11-E11 -> 0
A12: 11 | B12: Sahibpur Kamal | C12: Burete Stand | D12: =SUMIFS(Issue!$L$1:$L$4036,Issue!$H$1:$H$4036,'Pending Consumption'!$B12,Issue!$J$1:$J$4036,'Pending Consumption'!$C12,Issue!$B$1:$B$4036,"Transfer") -> 0 | E12: =SUMIFS(Issue!$L$1:$L$4036,Issue!$E$1:$E$4036,'Pending Consumption'!B12,Issue!$J$1:$J$4036,'Pending Consumption'!$C12,Issue!$B$1:$B$4036,"Consumed") -> 0 | F12: =+D12-E12 -> 0
A13: 12 | B13: Sahibpur Kamal | C13: Burret 50 ML Borosilicate | D13: =SUMIFS(Issue!$L$1:$L$4036,Issue!$H$1:$H$4036,'Pending Consumption'!$B13,Issue!$J$1:$J$4036,'Pending Consumption'!$C13,Issue!$B$1:$B$4036,"Transfer") -> 0 | E13: =SUMIFS(Issue!$L$1:$L$4036,Issue!$E$1:$E$4036,'Pending Consumption'!B13,Issue!$J$1:$J$4036,'Pending Consumption'!$C13,Issue!$B$1:$B$4036,"Consumed") -> 0 | F13: =+D13-E13 -> 0
... A97: 96 | B97: Sahibpur Kamal | C97: Tilt Measure 1 Ml with Bottle | D97: =SUMIFS(Issue!$L$1:$L$4036,Issue!$H$1:$H$4036,'Pending Consumption'!$B97,Issue!$J$1:$J$4036,'Pending Consumption'!$C97,Issue!$B$1:$B$4036,"Transfer") -> 0 | E97: =SUMIFS(Issue!$L$1:$L$4036,Issue!$E$1:$E$4036,'Pending Consumption'!B97,Issue!$J$1:$J$4036,'Pending Consumption'!$C97,Issue!$B$1:$B$4036,"Consumed") -> 0 | F97: =+D97-E97 -> 0
B98: Kalyanpur | C98: 1% Iodine Solution (100ml) | D98: =SUMIFS(Issue!$L$1:$L$4036,Issue!$H$1:$H$4036,'Pending Consumption'!$B98,Issue!$J$1:$J$4036,'Pending Consumption'!$C98,Issue!$B$1:$B$4036,"Transfer") -> 0 | E98: =SUMIFS(Issue!$L$1:$L$4036,Issue!$E$1:$E$4036,'Pending Consumption'!B98,Issue!$J$1:$J$4036,'Pending Consumption'!$C98,Issue!$B$1:$B$4036,"Consumed") -> 0 | F98: =+D98-E98 -> 0
B99: Kalyanpur | C99: Amber Colour Bottle (250 ML) | D99: =SUMIFS(Issue!$L$1:$L$4036,Issue!$H$1:$H$4036,'Pending Consumption'!$B99,Issue!$J$1:$J$4036,'Pending Consumption'!$C99,Issue!$B$1:$B$4036,"Transfer") -> 0 | E99: =SUMIFS(Issue!$L$1:$L$4036,Issue!$E$1:$E$4036,'Pending Consumption'!B99,Issue!$J$1:$J$4036,'Pending Consumption'!$C99,Issue!$B$1:$B$4036,"Consumed") -> 0 | F99: =+D99-E99 -> 0
B100: Kalyanpur | C100: Amyl 500ml | D100: =SUMIFS(Issue!$L$1:$L$4036,Issue!$H$1:$H$4036,'Pending Consumption'!$B100,Issue!$J$1:$J$4036,'Pending Consumption'!$C100,Issue!$B$1:$B$4036,"Transfer") -> 0 | E100: =SUMIFS(Issue!$L$1:$L$4036,Issue!$E$1:$E$4036,'Pending Consumption'!B100,Issue!$J$1:$J$4036,'Pending Consumption'!$C100,Issue!$B$1:$B$4036,"Consumed") -> 0 | F100: =+D100-E100 -> 0
B101: Kalyanpur | C101: Analyzer Calibration Cheking Log Book | D101: =SUMIFS(Issue!$L$1:$L$4036,Issue!$H$1:$H$4036,'Pending Consumption'!$B101,Issue!$J$1:$J$4036,'Pending Consumption'!$C101,Issue!$B$1:$B$4036,"Transfer") -> 0 | E101: =SUMIFS(Issue!$L$1:$L$4036,Issue!$E$1:$E$4036,'Pending Consumption'!B101,Issue!$J$1:$J$4036,'Pending Consumption'!$C101,Issue!$B$1:$B$4036,"Consumed") -> 0 | F101: =+D101-E101 -> 0
B102: Kalyanpur | C102: Beaker 100 Ml | D102: =SUMIFS(Issue!$L$1:$L$4036,Issue!$H$1:$H$4036,'Pending Consumption'!$B102,Issue!$J$1:$J$4036,'Pending Consumption'!$C102,Issue!$B$1:$B$4036,"Transfer") -> 0 | E102: =SUMIFS(Issue!$L$1:$L$4036,Issue!$E$1:$E$4036,'Pending Consumption'!B102,Issue!$J$1:$J$4036,'Pending Consumption'!$C102,Issue!$B$1:$B$4036,"Consumed") -> 0 | F102: =+D102-E102 -> 0
B103: Kalyanpur | C103: Beaker 250 ML Borosilicate | D103: =SUMIFS(Issue!$L$1:$L$4036,Issue!$H$1:$H$4036,'Pending Consumption'!$B103,Issue!$J$1:$J$4036,'Pending Consumption'!$C103,Issue!$B$1:$B$4036,"Transfer") -> 0 | E103: =SUMIFS(Issue!$L$1:$L$4036,Issue!$E$1:$E$4036,'Pending Consumption'!B103,Issue!$J$1:$J$4036,'Pending Consumption'!$C103,Issue!$B$1:$B$4036,"Consumed") -> 0 | F103: =+D103-E103 -> 0
B104: Kalyanpur | C104: Beaker 500 Ml | D104: =SUMIFS(Issue!$L$1:$L$4036,Issue!$H$1:$H$4036,'Pending Consumption'!$B104,Issue!$J$1:$J$4036,'Pending Consumption'!$C104,Issue!$B$1:$B$4036,"Transfer") -> 0 | E104: =SUMIFS(Issue!$L$1:$L$4036,Issue!$E$1:$E$4036,'Pending Consumption'!B104,Issue!$J$1:$J$4036,'Pending Consumption'!$C104,Issue!$B$1:$B$4036,"Consumed") -> 0 | F104: =+D104-E104 -> 0
B105: Kalyanpur | C105: Beaker 50 ML | D105: =SUMIFS(Issue!$L$1:$L$4036,Issue!$H$1:$H$4036,'Pending Consumption'!$B105,Issue!$J$1:$J$4036,'Pending Consumption'!$C105,Issue!$B$1:$B$4036,"Transfer") -> 0 | E105: =SUMIFS(Issue!$L$1:$L$4036,Issue!$E$1:$E$4036,'Pending Consumption'!B105,Issue!$J$1:$J$4036,'Pending Consumption'!$C105,Issue!$B$1:$B$4036,"Consumed") -> 0 | F105: =+D105-E105 -> 0
B106: Kalyanpur | C106: BMC Cleaning Brush 2" | D106: =SUMIFS(Issue!$L$1:$L$4036,Issue!$H$1:$H$4036,'Pending Consumption'!$B106,Issue!$J$1:$J$4036,'Pending Consumption'!$C106,Issue!$B$1:$B$4036,"Transfer") -> 0 | E106: =SUMIFS(Issue!$L$1:$L$4036,Issue!$E$1:$E$4036,'Pending Consumption'!B106,Issue!$J$1:$J$4036,'Pending Consumption'!$C106,Issue!$B$1:$B$4036,"Consumed") -> 0 | F106: =+D106-E106 -> 0
B107: Kalyanpur | C107: BMC Day Book | D107: =SUMIFS(Issue!$L$1:$L$4036,Issue!$H$1:$H$4036,'Pending Consumption'!$B107,Issue!$J$1:$J$4036,'Pending Consumption'!$C107,Issue!$B$1:$B$4036,"Transfer") -> 0 | E107: =SUMIFS(Issue!$L$1:$L$4036,Issue!$E$1:$E$4036,'Pending Consumption'!B107,Issue!$J$1:$J$4036,'Pending Consumption'!$C107,Issue!$B$1:$B$4036,"Consumed") -> 0 | F107: =+D107-E107 -> 0
B108: Kalyanpur | C108: Burete Stand | D108: =SUMIFS(Issue!$L$1:$L$4036,Issue!$H$1:$H$4036,'Pending Consumption'!$B108,Issue!$J$1:$J$4036,'Pending Consumption'!$C108,Issue!$B$1:$B$4036,"Transfer") -> 0 | E108: =SUMIFS(Issue!$L$1:$L$4036,Issue!$E$1:$E$4036,'Pending Consumption'!B108,Issue!$J$1:$J$4036,'Pending Consumption'!$C108,Issue!$B$1:$B$4036,"Consumed") -> 0 | F108: =+D108-E108 -> 0
B109: Kalyanpur | C109: Burret 50 ML Borosilicate | D109: =SUMIFS(Issue!$L$1:$L$4036,Issue!$H$1:$H$4036,'Pending Consumption'!$B109,Issue!$J$1:$J$4036,'Pending Consumption'!$C109,Issue!$B$1:$B$4036,"Transfer") -> 0 | E109: =SUMIFS(Issue!$L$1:$L$4036,Issue!$E$1:$E$4036,'Pending Consumption'!B109,Issue!$J$1:$J$4036,'Pending Consumption'!$C109,Issue!$B$1:$B$4036,"Consumed") -> 0 | F109: =+D109-E109 -> 0
... B1249: Araria | C1249: Tilt Measure 1 Ml with Bottle | D1249: =SUMIFS(Issue!$L$1:$L$4036,Issue!$H$1:$H$4036,'Pending Consumption'!$B1249,Issue!$J$1:$J$4036,'Pending Consumption'!$C1249,Issue!$B$1:$B$4036,"Transfer") -> 0 | E1249: =SUMIFS(Issue!$L$1:$L$4036,Issue!$E$1:$E$4036,'Pending Consumption'!B1249,Issue!$J$1:$J$4036,'Pending Consumption'!$C1249,Issue!$B$1:$B$4036,"Consumed") -> 0 | F1249: =+D1249-E1249 -> 0

Sheet Purchase
A1: Vendor ID | B1: Vendor Name | C1: Invoice Date | D1: Invoice No | E1: PO Date | F1: PO No | G1: Date | H1: GRN No | I1: Receipt Location Code | J1: Location | K1: Item Name | L1: UoM | M1: Qty Received | N1: Rate | O1: Amt | P1: GST | Q1: Total Am t | R1: Frieght | S1: Total amt | T1: Cost/Per
A2: 6 | B2: =IFERROR(VLOOKUP(Table3[[#This Row],[Vendor ID]],Table6[[Vendor ID]:[Vendor Name]],2,0),"") -> Satol Chemicals LTD | C2: 46142 | D2: SCL/00635/26-27 | E2: 46139 | F2: BR/PO/15/26-27 | G2: 46156 | H2: 1 | I2: 1 | J2: =IFERROR(VLOOKUP(Table3[[#This Row],[Receipt Location Code]],Table5[#All],3,0),"") -> Munger | K2: TEEPOL | L2: =IFERROR(VLOOKUP(Table3[[#This Row],[Item Name]],Table2[[#All],[Item Name]:[Open Rate]],2,0),"") -> Nos | M2: 1000 | N2: 44 | O2: =+Table3[[#This Row],[Rate]]*Table3[[#This Row],[Qty Received]] -> 44000 | P2: =+Table3[[#This Row],[Amt]]*0.18 -> 7920 | Q2: =+Table3[[#This Row],[Amt]]+Table3[[#This Row],[GST]] -> 51920 | S2: =+Table3[[#This Row],[Total Am t]]+Table3[[#This Row],[Frieght]] -> 51920 | T2: =IFERROR(+Table3[[#This Row],[Total amt]]/Table3[[#This Row],[Qty Received]],0) -> 51.92
B3: =IFERROR(VLOOKUP(Table3[[#This Row],[Vendor ID]],Table6[[Vendor ID]:[Vendor Name]],2,0),"") | J3: =IFERROR(VLOOKUP(Table3[[#This Row],[Receipt Location Code]],Table5[#All],3,0),"") | L3: =IFERROR(VLOOKUP(Table3[[#This Row],[Item Name]],Table2[[#All],[Item Name]:[Open Rate]],2,0),"") | O3: =+Table3[[#This Row],[Rate]]*Table3[[#This Row],[Qty Received]] -> 0 | P3: =+Table3[[#This Row],[Amt]]*0.18 -> 0 | Q3: =+Table3[[#This Row],[Amt]]+Table3[[#This Row],[GST]] -> 0 | S3: =+Table3[[#This Row],[Total Am t]]+Table3[[#This Row],[Frieght]] -> 0 | T3: =IFERROR(+Table3[[#This Row],[Total amt]]/Table3[[#This Row],[Qty Received]],0) -> 0
B4: =IFERROR(VLOOKUP(Table3[[#This Row],[Vendor ID]],Table6[[Vendor ID]:[Vendor Name]],2,0),"") | J4: =IFERROR(VLOOKUP(Table3[[#This Row],[Receipt Location Code]],Table5[#All],3,0),"") | L4: =IFERROR(VLOOKUP(Table3[[#This Row],[Item Name]],Table2[[#All],[Item Name]:[Open Rate]],2,0),"") | O4: =+Table3[[#This Row],[Rate]]*Table3[[#This Row],[Qty Received]] -> 0 | P4: =+Table3[[#This Row],[Amt]]*0.12 -> 0 | Q4: =+Table3[[#This Row],[Amt]]+Table3[[#This Row],[GST]] -> 0 | S4: =+Table3[[#This Row],[Total Am t]]+Table3[[#This Row],[Frieght]] -> 0 | T4: =IFERROR(+Table3[[#This Row],[Total amt]]/Table3[[#This Row],[Qty Received]],0) -> 0
B5: =IFERROR(VLOOKUP(Table3[[#This Row],[Vendor ID]],Table6[[Vendor ID]:[Vendor Name]],2,0),"") | J5: =IFERROR(VLOOKUP(Table3[[#This Row],[Receipt Location Code]],Table5[#All],3,0),"") | L5: =IFERROR(VLOOKUP(Table3[[#This Row],[Item Name]],Table2[[#All],[Item Name]:[Open Rate]],2,0),"") | O5: =+Table3[[#This Row],[Rate]]*Table3[[#This Row],[Qty Received]] -> 0 | P5: =+Table3[[#This Row],[Amt]]*0.12 -> 0 | Q5: =+Table3[[#This Row],[Amt]]+Table3[[#This Row],[GST]] -> 0 | S5: =+Table3[[#This Row],[Total Am t]]+Table3[[#This Row],[Frieght]] -> 0 | T5: =IFERROR(+Table3[[#This Row],[Total amt]]/Table3[[#This Row],[Qty Received]],0) -> 0
B6: =IFERROR(VLOOKUP(Table3[[#This Row],[Vendor ID]],Table6[[Vendor ID]:[Vendor Name]],2,0),"") | J6: =IFERROR(VLOOKUP(Table3[[#This Row],[Receipt Location Code]],Table5[#All],3,0),"") | L6: =IFERROR(VLOOKUP(Table3[[#This Row],[Item Name]],Table2[[#All],[Item Name]:[Open Rate]],2,0),"") | O6: =+Table3[[#This Row],[Rate]]*Table3[[#This Row],[Qty Received]] -> 0 | P6: =+Table3[[#This Row],[Amt]]*0.18 -> 0 | Q6: =+Table3[[#This Row],[Amt]]+Table3[[#This Row],[GST]] -> 0 | S6: =+Table3[[#This Row],[Total Am t]]+Table3[[#This Row],[Frieght]] -> 0 | T6: =IFERROR(+Table3[[#This Row],[Total amt]]/Table3[[#This Row],[Qty Received]],0) -> 0
B7: =IFERROR(VLOOKUP(Table3[[#This Row],[Vendor ID]],Table6[[Vendor ID]:[Vendor Name]],2,0),"") | J7: =IFERROR(VLOOKUP(Table3[[#This Row],[Receipt Location Code]],Table5[#All],3,0),"") | L7: =IFERROR(VLOOKUP(Table3[[#This Row],[Item Name]],Table2[[#All],[Item Name]:[Open Rate]],2,0),"") | O7: =+Table3[[#This Row],[Rate]]*Table3[[#This Row],[Qty Received]] -> 0 | P7: =+Table3[[#This Row],[Amt]]*0.18 -> 0 | Q7: =+Table3[[#This Row],[Amt]]+Table3[[#This Row],[GST]] -> 0 | S7: =+Table3[[#This Row],[Total Am t]]+Table3[[#This Row],[Frieght]] -> 0 | T7: =IFERROR(+Table3[[#This Row],[Total amt]]/Table3[[#This Row],[Qty Received]],0) -> 0
B8: =IFERROR(VLOOKUP(Table3[[#This Row],[Vendor ID]],Table6[[Vendor ID]:[Vendor Name]],2,0),"") | J8: =IFERROR(VLOOKUP(Table3[[#This Row],[Receipt Location Code]],Table5[#All],3,0),"") | L8: =IFERROR(VLOOKUP(Table3[[#This Row],[Item Name]],Table2[[#All],[Item Name]:[Open Rate]],2,0),"") | O8: =+Table3[[#This Row],[Rate]]*Table3[[#This Row],[Qty Received]] -> 0 | P8: =+Table3[[#This Row],[Amt]]*0.18 -> 0 | Q8: =+Table3[[#This Row],[Amt]]+Table3[[#This Row],[GST]] -> 0 | S8: =+Table3[[#This Row],[Total Am t]]+Table3[[#This Row],[Frieght]] -> 0 | T8: =IFERROR(+Table3[[#This Row],[Total amt]]/Table3[[#This Row],[Qty Received]],0) -> 0
B9: =IFERROR(VLOOKUP(Table3[[#This Row],[Vendor ID]],Table6[[Vendor ID]:[Vendor Name]],2,0),"") | J9: =IFERROR(VLOOKUP(Table3[[#This Row],[Receipt Location Code]],Table5[#All],3,0),"") | L9: =IFERROR(VLOOKUP(Table3[[#This Row],[Item Name]],Table2[[#All],[Item Name]:[Open Rate]],2,0),"") | O9: =+Table3[[#This Row],[Rate]]*Table3[[#This Row],[Qty Received]] -> 0 | P9: =+Table3[[#This Row],[Amt]]*0.18 -> 0 | Q9: =+Table3[[#This Row],[Amt]]+Table3[[#This Row],[GST]] -> 0 | S9: =+Table3[[#This Row],[Total Am t]]+Table3[[#This Row],[Frieght]] -> 0 | T9: =IFERROR(+Table3[[#This Row],[Total amt]]/Table3[[#This Row],[Qty Received]],0) -> 0
B10: =IFERROR(VLOOKUP(Table3[[#This Row],[Vendor ID]],Table6[[Vendor ID]:[Vendor Name]],2,0),"") | J10: =IFERROR(VLOOKUP(Table3[[#This Row],[Receipt Location Code]],Table5[#All],3,0),"") | L10: =IFERROR(VLOOKUP(Table3[[#This Row],[Item Name]],Table2[[#All],[Item Name]:[Open Rate]],2,0),"") | O10: =+Table3[[#This Row],[Rate]]*Table3[[#This Row],[Qty Received]] -> 0 | P10: =+Table3[[#This Row],[Amt]]*0.18 -> 0 | Q10: =+Table3[[#This Row],[Amt]]+Table3[[#This Row],[GST]] -> 0 | S10: =+Table3[[#This Row],[Total Am t]]+Table3[[#This Row],[Frieght]] -> 0 | T10: =IFERROR(+Table3[[#This Row],[Total amt]]/Table3[[#This Row],[Qty Received]],0) -> 0
B11: =IFERROR(VLOOKUP(Table3[[#This Row],[Vendor ID]],Table6[[Vendor ID]:[Vendor Name]],2,0),"") | J11: =IFERROR(VLOOKUP(Table3[[#This Row],[Receipt Location Code]],Table5[#All],3,0),"") | L11: =IFERROR(VLOOKUP(Table3[[#This Row],[Item Name]],Table2[[#All],[Item Name]:[Open Rate]],2,0),"") | O11: =+Table3[[#This Row],[Rate]]*Table3[[#This Row],[Qty Received]] -> 0 | P11: =+Table3[[#This Row],[Amt]]*0.18 -> 0 | Q11: =+Table3[[#This Row],[Amt]]+Table3[[#This Row],[GST]] -> 0 | S11: =+Table3[[#This Row],[Total Am t]]+Table3[[#This Row],[Frieght]] -> 0 | T11: =IFERROR(+Table3[[#This Row],[Total amt]]/Table3[[#This Row],[Qty Received]],0) -> 0
B12: =IFERROR(VLOOKUP(Table3[[#This Row],[Vendor ID]],Table6[[Vendor ID]:[Vendor Name]],2,0),"") | J12: =IFERROR(VLOOKUP(Table3[[#This Row],[Receipt Location Code]],Table5[#All],3,0),"") | L12: =IFERROR(VLOOKUP(Table3[[#This Row],[Item Name]],Table2[[#All],[Item Name]:[Open Rate]],2,0),"") | O12: =+Table3[[#This Row],[Rate]]*Table3[[#This Row],[Qty Received]] -> 0 | P12: =+Table3[[#This Row],[Amt]]*0.18 -> 0 | Q12: =+Table3[[#This Row],[Amt]]+Table3[[#This Row],[GST]] -> 0 | S12: =+Table3[[#This Row],[Total Am t]]+Table3[[#This Row],[Frieght]] -> 0 | T12: =IFERROR(+Table3[[#This Row],[Total amt]]/Table3[[#This Row],[Qty Received]],0) -> 0
B13: =IFERROR(VLOOKUP(Table3[[#This Row],[Vendor ID]],Table6[[Vendor ID]:[Vendor Name]],2,0),"") | J13: =IFERROR(VLOOKUP(Table3[[#This Row],[Receipt Location Code]],Table5[#All],3,0),"") | L13: =IFERROR(VLOOKUP(Table3[[#This Row],[Item Name]],Table2[[#All],[Item Name]:[Open Rate]],2,0),"") | O13: =+Table3[[#This Row],[Rate]]*Table3[[#This Row],[Qty Received]] -> 0 | P13: =+Table3[[#This Row],[Amt]]*0.18 -> 0 | Q13: =+Table3[[#This Row],[Amt]]+Table3[[#This Row],[GST]] -> 0 | S13: =+Table3[[#This Row],[Total Am t]]+Table3[[#This Row],[Frieght]] -> 0 | T13: =IFERROR(+Table3[[#This Row],[Total amt]]/Table3[[#This Row],[Qty Received]],0) -> 0
B14: =IFERROR(VLOOKUP(Table3[[#This Row],[Vendor ID]],Table6[[Vendor ID]:[Vendor Name]],2,0),"") | J14: =IFERROR(VLOOKUP(Table3[[#This Row],[Receipt Location Code]],Table5[#All],3,0),"") | L14: =IFERROR(VLOOKUP(Table3[[#This Row],[Item Name]],Table2[[#All],[Item Name]:[Open Rate]],2,0),"") | O14: =+Table3[[#This Row],[Rate]]*Table3[[#This Row],[Qty Received]] -> 0 | P14: =+Table3[[#This Row],[Amt]]*0.18 -> 0 | Q14: =+Table3[[#This Row],[Amt]]+Table3[[#This Row],[GST]] -> 0 | S14: =+Table3[[#This Row],[Total Am t]]+Table3[[#This Row],[Frieght]] -> 0 | T14: =IFERROR(+Table3[[#This Row],[Total amt]]/Table3[[#This Row],[Qty Received]],0) -> 0
B15: =IFERROR(VLOOKUP(Table3[[#This Row],[Vendor ID]],Table6[[Vendor ID]:[Vendor Name]],2,0),"") | J15: =IFERROR(VLOOKUP(Table3[[#This Row],[Receipt Location Code]],Table5[#All],3,0),"") | L15: =IFERROR(VLOOKUP(Table3[[#This Row],[Item Name]],Table2[[#All],[Item Name]:[Open Rate]],2,0),"") | O15: =+Table3[[#This Row],[Rate]]*Table3[[#This Row],[Qty Received]] -> 0 | P15: =+Table3[[#This Row],[Amt]]*0.18 -> 0 | Q15: =+Table3[[#This Row],[Amt]]+Table3[[#This Row],[GST]] -> 0 | S15: =+Table3[[#This Row],[Total Am t]]+Table3[[#This Row],[Frieght]] -> 0 | T15: =IFERROR(+Table3[[#This Row],[Total amt]]/Table3[[#This Row],[Qty Received]],0) -> 0
B16: =IFERROR(VLOOKUP(Table3[[#This Row],[Vendor ID]],Table6[[Vendor ID]:[Vendor Name]],2,0),"") | J16: =IFERROR(VLOOKUP(Table3[[#This Row],[Receipt Location Code]],Table5[#All],3,0),"") | L16: =IFERROR(VLOOKUP(Table3[[#This Row],[Item Name]],Table2[[#All],[Item Name]:[Open Rate]],2,0),"") | O16: =+Table3[[#This Row],[Rate]]*Table3[[#This Row],[Qty Received]] -> 0 | P16: =+Table3[[#This Row],[Amt]]*0.18 -> 0 | Q16: =+Table3[[#This Row],[Amt]]+Table3[[#This Row],[GST]] -> 0 | S16: =+Table3[[#This Row],[Total Am t]]+Table3[[#This Row],[Frieght]] -> 0 | T16: =IFERROR(+Table3[[#This Row],[Total amt]]/Table3[[#This Row],[Qty Received]],0) -> 0
B17: =IFERROR(VLOOKUP(Table3[[#This Row],[Vendor ID]],Table6[[Vendor ID]:[Vendor Name]],2,0),"") | J17: =IFERROR(VLOOKUP(Table3[[#This Row],[Receipt Location Code]],Table5[#All],3,0),"") | L17: =IFERROR(VLOOKUP(Table3[[#This Row],[Item Name]],Table2[[#All],[Item Name]:[Open Rate]],2,0),"") | O17: =+Table3[[#This Row],[Rate]]*Table3[[#This Row],[Qty Received]] -> 0 | P17: =+Table3[[#This Row],[Amt]]*0.18 -> 0 | Q17: =+Table3[[#This Row],[Amt]]+Table3[[#This Row],[GST]] -> 0 | S17: =+Table3[[#This Row],[Total Am t]]+Table3[[#This Row],[Frieght]] -> 0 | T17: =IFERROR(+Table3[[#This Row],[Total amt]]/Table3[[#This Row],[Qty Received]],0) -> 0
... B55: =IFERROR(VLOOKUP(Table3[[#This Row],[Vendor ID]],Table6[[Vendor ID]:[Vendor Name]],2,0),"") | J55: =IFERROR(VLOOKUP(Table3[[#This Row],[Receipt Location Code]],Table5[#All],3,0),"") | L55: =IFERROR(VLOOKUP(Table3[[#This Row],[Item Name]],Table2[[#All],[Item Name]:[Open Rate]],2,0),"") | O55: =+Table3[[#This Row],[Rate]]*Table3[[#This Row],[Qty Received]] -> 0 | P55: =+Table3[[#This Row],[Amt]]*0.18 -> 0 | Q55: =+Table3[[#This Row],[Amt]]+Table3[[#This Row],[GST]] -> 0 | S55: =+Table3[[#This Row],[Total Am t]]+Table3[[#This Row],[Frieght]] -> 0 | T55: =IFERROR(+Table3[[#This Row],[Total amt]]/Table3[[#This Row],[Qty Received]],0) -> 0
B56: =IFERROR(VLOOKUP(Table3[[#This Row],[Vendor ID]],Table6[[Vendor ID]:[Vendor Name]],2,0),"") | J56: =IFERROR(VLOOKUP(Table3[[#This Row],[Receipt Location Code]],Table5[#All],3,0),"") | L56: =IFERROR(VLOOKUP(Table3[[#This Row],[Item Name]],Table2[[#All],[Item Name]:[Open Rate]],2,0),"") | O56: =+Table3[[#This Row],[Rate]]*Table3[[#This Row],[Qty Received]] -> 0 | P56: =+Table3[[#This Row],[Amt]]*0.05 -> 0 | Q56: =+Table3[[#This Row],[Amt]]+Table3[[#This Row],[GST]] -> 0 | S56: =+Table3[[#This Row],[Total Am t]]+Table3[[#This Row],[Frieght]] -> 0 | T56: =IFERROR(+Table3[[#This Row],[Total amt]]/Table3[[#This Row],[Qty Received]],0) -> 0
B57: =IFERROR(VLOOKUP(Table3[[#This Row],[Vendor ID]],Table6[[Vendor ID]:[Vendor Name]],2,0),"") | J57: =IFERROR(VLOOKUP(Table3[[#This Row],[Receipt Location Code]],Table5[#All],3,0),"") | L57: =IFERROR(VLOOKUP(Table3[[#This Row],[Item Name]],Table2[[#All],[Item Name]:[Open Rate]],2,0),"") | O57: =+Table3[[#This Row],[Rate]]*Table3[[#This Row],[Qty Received]] -> 0 | P57: =+Table3[[#This Row],[Amt]]*0.18 -> 0 | Q57: =+Table3[[#This Row],[Amt]]+Table3[[#This Row],[GST]] -> 0 | S57: =+Table3[[#This Row],[Total Am t]]+Table3[[#This Row],[Frieght]] -> 0 | T57: =IFERROR(+Table3[[#This Row],[Total amt]]/Table3[[#This Row],[Qty Received]],0) -> 0
B58: =IFERROR(VLOOKUP(Table3[[#This Row],[Vendor ID]],Table6[[Vendor ID]:[Vendor Name]],2,0),"") | J58: =IFERROR(VLOOKUP(Table3[[#This Row],[Receipt Location Code]],Table5[#All],3,0),"") | L58: =IFERROR(VLOOKUP(Table3[[#This Row],[Item Name]],Table2[[#All],[Item Name]:[Open Rate]],2,0),"") | O58: =+Table3[[#This Row],[Rate]]*Table3[[#This Row],[Qty Received]] -> 0 | P58: =+Table3[[#This Row],[Amt]]*0.18 -> 0 | Q58: =+Table3[[#This Row],[Amt]]+Table3[[#This Row],[GST]] -> 0 | S58: =+Table3[[#This Row],[Total Am t]]+Table3[[#This Row],[Frieght]] -> 0 | T58: =IFERROR(+Table3[[#This Row],[Total amt]]/Table3[[#This Row],[Qty Received]],0) -> 0
B59: =IFERROR(VLOOKUP(Table3[[#This Row],[Vendor ID]],Table6[[Vendor ID]:[Vendor Name]],2,0),"") | J59: =IFERROR(VLOOKUP(Table3[[#This Row],[Receipt Location Code]],Table5[#All],3,0),"") | L59: =IFERROR(VLOOKUP(Table3[[#This Row],[Item Name]],Table2[[#All],[Item Name]:[Open Rate]],2,0),"") | O59: =+Table3[[#This Row],[Rate]]*Table3[[#This Row],[Qty Received]] -> 0 | P59: =+Table3[[#This Row],[Amt]]*0.18 -> 0 | Q59: =+Table3[[#This Row],[Amt]]+Table3[[#This Row],[GST]] -> 0 | S59: =+Table3[[#This Row],[Total Am t]]+Table3[[#This Row],[Frieght]] -> 0 | T59: =IFERROR(+Table3[[#This Row],[Total amt]]/Table3[[#This Row],[Qty Received]],0) -> 0
B60: =IFERROR(VLOOKUP(Table3[[#This Row],[Vendor ID]],Table6[[Vendor ID]:[Vendor Name]],2,0),"") | J60: =IFERROR(VLOOKUP(Table3[[#This Row],[Receipt Location Code]],Table5[#All],3,0),"") | L60: =IFERROR(VLOOKUP(Table3[[#This Row],[Item Name]],Table2[[#All],[Item Name]:[Open Rate]],2,0),"") | O60: =+Table3[[#This Row],[Rate]]*Table3[[#This Row],[Qty Received]] -> 0 | P60: =+Table3[[#This Row],[Amt]]*0.05 -> 0 | Q60: =+Table3[[#This Row],[Amt]]+Table3[[#This Row],[GST]] -> 0 | S60: =+Table3[[#This Row],[Total Am t]]+Table3[[#This Row],[Frieght]] -> 0 | T60: =IFERROR(+Table3[[#This Row],[Total amt]]/Table3[[#This Row],[Qty Received]],0) -> 0
B61: =IFERROR(VLOOKUP(Table3[[#This Row],[Vendor ID]],Table6[[Vendor ID]:[Vendor Name]],2,0),"") | J61: =IFERROR(VLOOKUP(Table3[[#This Row],[Receipt Location Code]],Table5[#All],3,0),"") | L61: =IFERROR(VLOOKUP(Table3[[#This Row],[Item Name]],Table2[[#All],[Item Name]:[Open Rate]],2,0),"") | O61: =+Table3[[#This Row],[Rate]]*Table3[[#This Row],[Qty Received]] -> 0 | P61: =+Table3[[#This Row],[Amt]]*0.18 -> 0 | Q61: =+Table3[[#This Row],[Amt]]+Table3[[#This Row],[GST]] -> 0 | S61: =+Table3[[#This Row],[Total Am t]]+Table3[[#This Row],[Frieght]] -> 0 | T61: =IFERROR(+Table3[[#This Row],[Total amt]]/Table3[[#This Row],[Qty Received]],0) -> 0
B62: =IFERROR(VLOOKUP(Table3[[#This Row],[Vendor ID]],Table6[[Vendor ID]:[Vendor Name]],2,0),"") | J62: =IFERROR(VLOOKUP(Table3[[#This Row],[Receipt Location Code]],Table5[#All],3,0),"") | L62: =IFERROR(VLOOKUP(Table3[[#This Row],[Item Name]],Table2[[#All],[Item Name]:[Open Rate]],2,0),"") | O62: =+Table3[[#This Row],[Rate]]*Table3[[#This Row],[Qty Received]] -> 0 | P62: =+Table3[[#This Row],[Amt]]*0.18 -> 0 | Q62: =+Table3[[#This Row],[Amt]]+Table3[[#This Row],[GST]] -> 0 | S62: =+Table3[[#This Row],[Total Am t]]+Table3[[#This Row],[Frieght]] -> 0 | T62: =IFERROR(+Table3[[#This Row],[Total amt]]/Table3[[#This Row],[Qty Received]],0) -> 0
B63: =IFERROR(VLOOKUP(Table3[[#This Row],[Vendor ID]],Table6[[Vendor ID]:[Vendor Name]],2,0),"") | J63: =IFERROR(VLOOKUP(Table3[[#This Row],[Receipt Location Code]],Table5[#All],3,0),"") | L63: =IFERROR(VLOOKUP(Table3[[#This Row],[Item Name]],Table2[[#All],[Item Name]:[Open Rate]],2,0),"") | O63: =+Table3[[#This Row],[Rate]]*Table3[[#This Row],[Qty Received]] -> 0 | P63: =+Table3[[#This Row],[Amt]]*0.18 -> 0 | Q63: =+Table3[[#This Row],[Amt]]+Table3[[#This Row],[GST]] -> 0 | S63: =+Table3[[#This Row],[Total Am t]]+Table3[[#This Row],[Frieght]] -> 0 | T63: =IFERROR(+Table3[[#This Row],[Total amt]]/Table3[[#This Row],[Qty Received]],0) -> 0
B64: =IFERROR(VLOOKUP(Table3[[#This Row],[Vendor ID]],Table6[#All],2,0),"") | J64: =IFERROR(VLOOKUP(Table3[[#This Row],[Receipt Location Code]],Table5[#All],3,0),"") | L64: =IFERROR(VLOOKUP(Table3[[#This Row],[Item Name]],Table2[[#All],[Item Name]:[UoM]],2,0),"") | O64: =+Table3[[#This Row],[Rate]]*Table3[[#This Row],[Qty Received]] -> 0 | P64: =+Table3[[#This Row],[Amt]]*0.18 -> 0 | Q64: =+Table3[[#This Row],[Amt]]+Table3[[#This Row],[GST]] -> 0 | S64: =+Table3[[#This Row],[Total Am t]]+Table3[[#This Row],[Frieght]] -> 0 | T64: =IFERROR(+Table3[[#This Row],[Total amt]]/Table3[[#This Row],[Qty Received]],0) -> 0
B65: =IFERROR(VLOOKUP(Table3[[#This Row],[Vendor ID]],Table6[#All],2,0),"") | J65: =IFERROR(VLOOKUP(Table3[[#This Row],[Receipt Location Code]],Table5[#All],3,0),"") | L65: =IFERROR(VLOOKUP(Table3[[#This Row],[Item Name]],Table2[[#All],[Item Name]:[UoM]],2,0),"") | O65: =+Table3[[#This Row],[Rate]]*Table3[[#This Row],[Qty Received]] -> 0 | P65: =+Table3[[#This Row],[Amt]]*0.18 -> 0 | Q65: =+Table3[[#This Row],[Amt]]+Table3[[#This Row],[GST]] -> 0 | S65: =+Table3[[#This Row],[Total Am t]]+Table3[[#This Row],[Frieght]] -> 0 | T65: =IFERROR(+Table3[[#This Row],[Total amt]]/Table3[[#This Row],[Qty Received]],0) -> 0

Sheet Godown
A1: MPG/BMC Code | B1: Type | C1: Name | D1: BMC Area
A2: 1 | B2: Main Godown | C2: Munger | D2: NA
A3: 10070001 | B3: MPG | C3: MSKMPG LAKXMIPUR | D3: Araria
A4: 10070002 | B4: MPG | C4: Gomukh ID Araria | D4: Araria
A5: 10070003 | B5: MPG | C5: Gomukh ID Chaidha | D5: Araria
A6: 10070004 | B6: MPG | C6: Gomukh ID Pakrail | D6: Araria
A7: 10070008 | B7: MPG | C7: Gomukh ID Pipra | D7: Araria
A8: 10070010 | B8: MPG | C8: Gomukh Araria-1 | D8: Araria
A9: 10070013 | B9: MPG | C9: Gomukh Fatepur | D9: Araria
A10: 10070016 | B10: MPG | C10: Gomukh Gauchhari | D10: Araria
A11: 10070017 | B11: MPG | C11: Gomukh Arariya Uttari | D11: Araria
A12: 10070018 | B12: MPG | C12: Gomukh Arariya Karjaniya | D12: Araria
A13: 10070019 | B13: MPG | C13: Gomukh Aariya Dummer Kothi | D13: Araria
... A872: 1055 | B872: BMC | C872: Matihani | D872: Matihani
A873: Lab | B873: Lab | C873: Daya_Lab | D873: Munger
A874: 10540003 | B874: MPG | C874: GOMUKH ANANDPUR PARAS 2 | D874: Alauli
A875: 10540004 | B875: MPG | C875: GOMUKH SHYAM GHARARI | D875: Alauli
A876: 10540005 | B876: MPG | C876: GOMUKH GADBANNI | D876: Alauli
A877: 10540006 | B877: MPG | C877: GOMUKH AMBA | D877: Alauli
A878: 10540007 | B878: MPG | C878: GOMUKH GORIYAMI | D878: Alauli
A879: 10540008 | B879: MPG | C879: GOMUKH PARRI | D879: Alauli
A880: 10540009 | B880: MPG | C880: GOMUKH BHIKHARI GHAT | D880: Alauli
A881: 10540010 | B881: MPG | C881: Vikash Kumar | D881: Alauli
A882: 10540011 | B882: MPG | C882: Jayvir Kumar | D882: Alauli
A883: 10540012 | B883: MPG | C883: Rajkishore Yadav | D883: Alauli
A884: 10540013 | B884: MPG | C884: Jalkaura VLC | D884: Alauli
A885: 10540014 | B885: MPG | C885: BHADAS VLC | D885: Alauli
... A1261: 10600014 | B1261: MPG | C1261: Gumukh Dhamar Ajit | D1261: Behiya

Sheet Vendor
A1: Vendor ID | B1: Vendor Name | C1: Address | D1: PAN | E1: GST | F1: Mobile | G1: Email | H1: Supply For
A2: 1 | B2: R R Sales | H2: Tanker Seal
A3: 2 | B3: Minakshi Scientific
A4: 3 | B4: Geochem Bio Science
A5: 4 | B5: Indifoss Analytical Pvt Ltd
A6: 5 | B6: Baranwal Computer
A7: 6 | B7: Satol Chemicals LTD
A8: 7 | B8: Everest Instruments PVT LTD
A9: 8 | B9: JK India Instruments PVT LTD
A10: 9 | B10: Narang scientific Industries
A11: 10 | B11: Peejay Transprint

Sheet Item
A1: S.No | B1: Category | C1: Location | D1: Item Name | E1: UoM | F1: Vendor Name | G1: Stock as on 1st Apr | H1: Reorder Qty | I1: Reorder Level | J1: Avg Consumption of 2 Month | K1: Open Rate | L1: Column1 | M1: diff
A2: 1 | B2: Chemical | C2: Munger | D2: 1% Iodine Solution (100ml) | E2: Nos | F2: Maa enterpires | G2: 13 | H2: 15 | I2: 5 | J2: 1 | K2: 90 | L2: 15 | M2: =Table2[[#This Row],[Stock as on 1st Apr]]-Table2[[#This Row],[Column1]] -> -2
A3: 2 | B3: Glassware | C3: Munger | D3: Amber Colour Bottle (250 ML) | E3: Nos | F3: Maa enterpires | G3: 120 | H3: 50 | I3: 40 | J3: 20 | K3: 120 | L3: 140 | M3: =Table2[[#This Row],[Stock as on 1st Apr]]-Table2[[#This Row],[Column1]] -> -20
A4: 3 | B4: Chemical | C4: Munger | D4: Amyl 500ml | E4: Nos | F4: Maa enterpires | G4: 47 | H4: 50 | I4: 30 | J4: 15 | K4: 365.8 | L4: 50 | M4: =Table2[[#This Row],[Stock as on 1st Apr]]-Table2[[#This Row],[Column1]] -> -3
A5: 4 | B5: Stationery | C5: Munger | D5: Analyzer Calibration Cheking Log Book | E5: Nos | F5: Barnwal Computer | G5: 61 | H5: 100 | I5: 20 | J5: 15 | K5: 127.44 | L5: 13 | M5: =Table2[[#This Row],[Stock as on 1st Apr]]-Table2[[#This Row],[Column1]] -> 48
A6: 5 | B6: Glassware | C6: Munger | D6: Beaker 100 Ml | E6: Nos | F6: Jk India | G6: 16 | H6: 48 | I6: 10 | J6: 10 | K6: 33.18 | L6: 24 | M6: =Table2[[#This Row],[Stock as on 1st Apr]]-Table2[[#This Row],[Column1]] -> -8
A7: 6 | B7: Glassware | C7: Munger | D7: Beaker 250 ML Borosilicate | E7: Nos | F7: Jk India | G7: 20 | H7: 48 | I7: 10 | J7: 10 | K7: 64.9 | L7: 12 | M7: =Table2[[#This Row],[Stock as on 1st Apr]]-Table2[[#This Row],[Column1]] -> 8
A8: 7 | B8: Glassware | C8: Munger | D8: Beaker 500 Ml | E8: Nos | F8: Jk India | G8: 25 | H8: 48 | I8: 10 | J8: 10 | K8: 63.7 | L8: 49 | M8: =Table2[[#This Row],[Stock as on 1st Apr]]-Table2[[#This Row],[Column1]] -> -24
A9: 8 | B9: Glassware | C9: Munger | D9: Beaker 50 ML | E9: Nos | F9: Jk India | G9: 28 | H9: 48 | I9: 10 | J9: 10 | K9: 15.88 | L9: 8 | M9: =Table2[[#This Row],[Stock as on 1st Apr]]-Table2[[#This Row],[Column1]] -> 20
A10: 9 | B10: Consumables | C10: Munger | D10: BMC Cleaning Brush 2" | E10: Nos | F10: Surya Instruments | G10: 26 | H10: 10 | I10: 10 | J10: 10 | K10: 212.4 | L10: 41 | M10: =Table2[[#This Row],[Stock as on 1st Apr]]-Table2[[#This Row],[Column1]] -> -15
A11: 10 | B11: Stationery | C11: Munger | D11: BMC Day Book | E11: Nos | F11: Barnwal Computer | G11: 90 | H11: 300 | I11: 60 | J11: 30 | K11: 121.54 | L11: 106 | M11: =Table2[[#This Row],[Stock as on 1st Apr]]-Table2[[#This Row],[Column1]] -> -16
