Workbook

Sheet Shayak Income 
A2: Code | B2: MPG NAME | C2: VLC Type | D2: Farmer Payment | E2: BMC Code | F2: BMC Volume | G2: BMC Amount | H2: Sahayak Comission @ 1.05/- | I2: Deduction TS Loss | J2: Cattle Feed Deduction | K2: Hold | L2: Net Payble
A3: 20010001 | B3: Itki | C3: =VLOOKUP(A3,'MPG Payment '!$D$3:$G$7771,3,0) -> RMC | D3: =VLOOKUP(A3,'MPG Payment '!$D$3:$G$764,4,0) -> Direct | E3: =_xlfn.XLOOKUP(A3,'MPG Payment '!$D$2:$D$771,'MPG Payment '!$C$2:$C$771) -> BMC Code :2001 | F3: =SUMIF('MPG Payment '!$D$3:$D$79771,'Shayak Income '!A3,'MPG Payment '!$H$3:$H$79771) -> 42803.83 | G3: =SUMIF('MPG Payment '!$D$3:$D$79771,'Shayak Income '!A3,'MPG Payment '!$I$3:$I$79771) -> 1750829.2 | H3: =+F3*1.05 -> 44944.021 | I3: 0 | J3: 0 | K3: 0 | L3: =H3-I3-J3-K3 -> 44944.021
A4: 20010003 | B4: Bero | C4: =VLOOKUP(A4,'MPG Payment '!$D$3:$G$7771,3,0) -> MPG | D4: =VLOOKUP(A4,'MPG Payment '!$D$3:$G$764,4,0) -> Direct | E4: =_xlfn.XLOOKUP(A4,'MPG Payment '!$D$2:$D$771,'MPG Payment '!$C$2:$C$771) -> BMC Code :2001 | F4: =SUMIF('MPG Payment '!$D$3:$D$79771,'Shayak Income '!A4,'MPG Payment '!$H$3:$H$79771) -> 3603.38 | G4: =SUMIF('MPG Payment '!$D$3:$D$79771,'Shayak Income '!A4,'MPG Payment '!$I$3:$I$79771) -> 134799.99 | H4: =+F4*1.05 -> 3783.549 | I4: 0 | J4: 0 | K4: 0 | L4: =H4-I4-J4-K4 -> 3783.549
A5: 20010005 | B5: Basila | C5: =VLOOKUP(A5,'MPG Payment '!$D$3:$G$7771,3,0) -> MPG | D5: =VLOOKUP(A5,'MPG Payment '!$D$3:$G$764,4,0) -> Direct | E5: =_xlfn.XLOOKUP(A5,'MPG Payment '!$D$2:$D$771,'MPG Payment '!$C$2:$C$771) -> BMC Code :2001 | F5: =SUMIF('MPG Payment '!$D$3:$D$79771,'Shayak Income '!A5,'MPG Payment '!$H$3:$H$79771) -> 4387.28 | G5: =SUMIF('MPG Payment '!$D$3:$D$79771,'Shayak Income '!A5,'MPG Payment '!$I$3:$I$79771) -> 165519.26 | H5: =+F5*1.05 -> 4606.644 | I5: 0 | J5: 0 | K5: 0 | L5: =H5-I5-J5-K5 -> 4606.644
A6: 20010008 | B6: Erchoro | C6: =VLOOKUP(A6,'MPG Payment '!$D$3:$G$7771,3,0) -> MPG | D6: =VLOOKUP(A6,'MPG Payment '!$D$3:$G$764,4,0) -> Direct | E6: =_xlfn.XLOOKUP(A6,'MPG Payment '!$D$2:$D$771,'MPG Payment '!$C$2:$C$771) -> BMC Code :2001 | F6: =SUMIF('MPG Payment '!$D$3:$D$79771,'Shayak Income '!A6,'MPG Payment '!$H$3:$H$79771) -> 8274.93 | G6: =SUMIF('MPG Payment '!$D$3:$D$79771,'Shayak Income '!A6,'MPG Payment '!$I$3:$I$79771) -> 296055.68 | H6: =+F6*1.05 -> 8688.6765 | I6: 0 | J6: 0 | K6: 0 | L6: =H6-I6-J6-K6 -> 8688.6765
A7: 20010009 | B7: Makunda | C7: =VLOOKUP(A7,'MPG Payment '!$D$3:$G$7771,3,0) -> MPG | D7: =VLOOKUP(A7,'MPG Payment '!$D$3:$G$764,4,0) -> Direct | E7: =_xlfn.XLOOKUP(A7,'MPG Payment '!$D$2:$D$771,'MPG Payment '!$C$2:$C$771) -> BMC Code :2001 | F7: =SUMIF('MPG Payment '!$D$3:$D$79771,'Shayak Income '!A7,'MPG Payment '!$H$3:$H$79771) -> 2038.77 | G7: =SUMIF('MPG Payment '!$D$3:$D$79771,'Shayak Income '!A7,'MPG Payment '!$I$3:$I$79771) -> 81708.65 | H7: =+F7*1.05 -> 2140.7085 | I7: 0 | J7: 0 | K7: 0 | L7: =H7-I7-J7-K7 -> 2140.7085
A8: 20010012 | B8: NAGRI | C8: =VLOOKUP(A8,'MPG Payment '!$D$3:$G$7771,3,0) -> VLC | D8: =VLOOKUP(A8,'MPG Payment '!$D$3:$G$764,4,0) -> Indirect | E8: =_xlfn.XLOOKUP(A8,'MPG Payment '!$D$2:$D$771,'MPG Payment '!$C$2:$C$771) -> BMC Code :2001 | F8: =SUMIF('MPG Payment '!$D$3:$D$79771,'Shayak Income '!A8,'MPG Payment '!$H$3:$H$79771) -> 549.74 | G8: =SUMIF('MPG Payment '!$D$3:$D$79771,'Shayak Income '!A8,'MPG Payment '!$I$3:$I$79771) -> 16236.5 | H8: =+F8*1.05 -> 577.227 | I8: 0 | J8: 0 | K8: 0 | L8: =H8-I8-J8-K8 -> 577.227
A9: 20010015 | B9: BOREYA | C9: =VLOOKUP(A9,'MPG Payment '!$D$3:$G$7771,3,0) -> MPG | D9: =VLOOKUP(A9,'MPG Payment '!$D$3:$G$764,4,0) -> Direct | E9: =_xlfn.XLOOKUP(A9,'MPG Payment '!$D$2:$D$771,'MPG Payment '!$C$2:$C$771) -> BMC Code :2001 | F9: =SUMIF('MPG Payment '!$D$3:$D$79771,'Shayak Income '!A9,'MPG Payment '!$H$3:$H$79771) -> 12395.06 | G9: =SUMIF('MPG Payment '!$D$3:$D$79771,'Shayak Income '!A9,'MPG Payment '!$I$3:$I$79771) -> 488852.52 | H9: =+F9*1.05 -> 13014.813 | I9: 0 | J9: 0 | K9: 0 | L9: =H9-I9-J9-K9 -> 13014.813
A10: 20010016 | B10: ITA CHILDRI | C10: =VLOOKUP(A10,'MPG Payment '!$D$3:$G$7771,3,0) -> MPG | D10: =VLOOKUP(A10,'MPG Payment '!$D$3:$G$764,4,0) -> Direct | E10: =_xlfn.XLOOKUP(A10,'MPG Payment '!$D$2:$D$771,'MPG Payment '!$C$2:$C$771) -> BMC Code :2001 | F10: =SUMIF('MPG Payment '!$D$3:$D$79771,'Shayak Income '!A10,'MPG Payment '!$H$3:$H$79771) -> 910.81 | G10: =SUMIF('MPG Payment '!$D$3:$D$79771,'Shayak Income '!A10,'MPG Payment '!$I$3:$I$79771) -> 35687.25 | H10: =+F10*1.05 -> 956.3505 | I10: 0 | J10: 0 | K10: 0 | L10: =H10-I10-J10-K10 -> 956.3505
A11: 20010017 | B11: DIGHIYA | C11: =VLOOKUP(A11,'MPG Payment '!$D$3:$G$7771,3,0) -> MPG | D11: =VLOOKUP(A11,'MPG Payment '!$D$3:$G$764,4,0) -> Direct | E11: =_xlfn.XLOOKUP(A11,'MPG Payment '!$D$2:$D$771,'MPG Payment '!$C$2:$C$771) -> BMC Code :2001 | F11: =SUMIF('MPG Payment '!$D$3:$D$79771,'Shayak Income '!A11,'MPG Payment '!$H$3:$H$79771) -> 4637.39 | G11: =SUMIF('MPG Payment '!$D$3:$D$79771,'Shayak Income '!A11,'MPG Payment '!$I$3:$I$79771) -> 172615.91 | H11: =+F11*1.05 -> 4869.2595 | I11: 0 | J11: 0 | K11: 0 | L11: =H11-I11-J11-K11 -> 4869.2595
A12: 20010023 | B12: KATARPA | C12: =VLOOKUP(A12,'MPG Payment '!$D$3:$G$7771,3,0) -> MPG | D12: =VLOOKUP(A12,'MPG Payment '!$D$3:$G$764,4,0) -> Direct | E12: =_xlfn.XLOOKUP(A12,'MPG Payment '!$D$2:$D$771,'MPG Payment '!$C$2:$C$771) -> BMC Code :2001 | F12: =SUMIF('MPG Payment '!$D$3:$D$79771,'Shayak Income '!A12,'MPG Payment '!$H$3:$H$79771) -> 1689.6 | G12: =SUMIF('MPG Payment '!$D$3:$D$79771,'Shayak Income '!A12,'MPG Payment '!$I$3:$I$79771) -> 68575.3 | H12: =+F12*1.05 -> 1774.08 | I12: 0 | J12: 0 | K12: 0 | L12: =H12-I12-J12-K12 -> 1774.08
A13: 20010027 | B13: MURTO | C13: =VLOOKUP(A13,'MPG Payment '!$D$3:$G$7771,3,0) -> MPG | D13: =VLOOKUP(A13,'MPG Payment '!$D$3:$G$764,4,0) -> Direct | E13: =_xlfn.XLOOKUP(A13,'MPG Payment '!$D$2:$D$771,'MPG Payment '!$C$2:$C$771) -> BMC Code :2001 | F13: =SUMIF('MPG Payment '!$D$3:$D$79771,'Shayak Income '!A13,'MPG Payment '!$H$3:$H$79771) -> 2880.24 | G13: =SUMIF('MPG Payment '!$D$3:$D$79771,'Shayak Income '!A13,'MPG Payment '!$I$3:$I$79771) -> 107124.24 | H13: =+F13*1.05 -> 3024.252 | I13: 0 | J13: 0 | K13: 0 | L13: =H13-I13-J13-K13 -> 3024.252
A14: 20010033 | B14: KHATRIKHATANGA | C14: =VLOOKUP(A14,'MPG Payment '!$D$3:$G$7771,3,0) -> MPG | D14: =VLOOKUP(A14,'MPG Payment '!$D$3:$G$764,4,0) -> Direct | E14: =_xlfn.XLOOKUP(A14,'MPG Payment '!$D$2:$D$771,'MPG Payment '!$C$2:$C$771) -> BMC Code :2001 | F14: =SUMIF('MPG Payment '!$D$3:$D$79771,'Shayak Income '!A14,'MPG Payment '!$H$3:$H$79771) -> 1501.34 | G14: =SUMIF('MPG Payment '!$D$3:$D$79771,'Shayak Income '!A14,'MPG Payment '!$I$3:$I$79771) -> 60619.21 | H14: =+F14*1.05 -> 1576.407 | I14: 0 | J14: 0 | K14: 0 | L14: =H14-I14-J14-K14 -> 1576.407
... A47: 20040001 | B47: CHOREYA | C47: =VLOOKUP(A47,'MPG Payment '!$D$3:$G$7771,3,0) -> RMC | D47: =VLOOKUP(A47,'MPG Payment '!$D$3:$G$764,4,0) -> Direct | E47: =_xlfn.XLOOKUP(A47,'MPG Payment '!$D$2:$D$771,'MPG Payment '!$C$2:$C$771) -> BMC Code :2004 | F47: =SUMIF('MPG Payment '!$D$3:$D$79771,'Shayak Income '!A47,'MPG Payment '!$H$3:$H$79771) -> 33214.08 | G47: =SUMIF('MPG Payment '!$D$3:$D$79771,'Shayak Income '!A47,'MPG Payment '!$I$3:$I$79771) -> 1134763.3 | H47: =+F47*1.05 -> 34874.784 | I47: 34875 | J47: 0 | K47: 0 | L47: =H47-I47-J47-K47 -> -0.216
A48: 20040006 | B48: KADAM TOLI | C48: =VLOOKUP(A48,'MPG Payment '!$D$3:$G$7771,3,0) -> MPG | D48: =VLOOKUP(A48,'MPG Payment '!$D$3:$G$764,4,0) -> Direct | E48: =_xlfn.XLOOKUP(A48,'MPG Payment '!$D$2:$D$771,'MPG Payment '!$C$2:$C$771) -> BMC Code :2004 | F48: =SUMIF('MPG Payment '!$D$3:$D$79771,'Shayak Income '!A48,'MPG Payment '!$H$3:$H$79771) -> 1635.79 | G48: =SUMIF('MPG Payment '!$D$3:$D$79771,'Shayak Income '!A48,'MPG Payment '!$I$3:$I$79771) -> 63298.58 | H48: =+F48*1.05 -> 1717.5795 | I48: 0 | J48: 0 | K48: 0 | L48: =H48-I48-J48-K48 -> 1717.5795 | N48: 4918
A49: 20040007 | B49: MADHUKAM | C49: =VLOOKUP(A49,'MPG Payment '!$D$3:$G$7771,3,0) -> MPG | D49: =VLOOKUP(A49,'MPG Payment '!$D$3:$G$764,4,0) -> Direct | E49: =_xlfn.XLOOKUP(A49,'MPG Payment '!$D$2:$D$771,'MPG Payment '!$C$2:$C$771) -> BMC Code :2004 | F49: =SUMIF('MPG Payment '!$D$3:$D$79771,'Shayak Income '!A49,'MPG Payment '!$H$3:$H$79771) -> 1409.87 | G49: =SUMIF('MPG Payment '!$D$3:$D$79771,'Shayak Income '!A49,'MPG Payment '!$I$3:$I$79771) -> 52361.67 | H49: =+F49*1.05 -> 1480.3635 | I49: 0 | J49: 0 | K49: 0 | L49: =H49-I49-J49-K49 -> 1480.3635
A50: 20050001 | B50: Baski 2 | C50: =VLOOKUP(A50,'MPG Payment '!$D$3:$G$7771,3,0) -> RMC | D50: =VLOOKUP(A50,'MPG Payment '!$D$3:$G$764,4,0) -> Direct | E50: =_xlfn.XLOOKUP(A50,'MPG Payment '!$D$2:$D$771,'MPG Payment '!$C$2:$C$771) -> BMC Code :2002 | F50: =SUMIF('MPG Payment '!$D$3:$D$79771,'Shayak Income '!A50,'MPG Payment '!$H$3:$H$79771) -> 3636 | G50: =SUMIF('MPG Payment '!$D$3:$D$79771,'Shayak Income '!A50,'MPG Payment '!$I$3:$I$79771) -> 138338.73 | H50: =+F50*1.05 -> 3817.8 | I50: 0 | J50: 0 | K50: 0 | L50: =H50-I50-J50-K50 -> 3817.8
A51: 20050002 | B51: KANBHITHA | C51: =VLOOKUP(A51,'MPG Payment '!$D$3:$G$7771,3,0) -> MPG | D51: =VLOOKUP(A51,'MPG Payment '!$D$3:$G$764,4,0) -> Direct | E51: =_xlfn.XLOOKUP(A51,'MPG Payment '!$D$2:$D$771,'MPG Payment '!$C$2:$C$771) -> BMC Code :2002 | F51: =SUMIF('MPG Payment '!$D$3:$D$79771,'Shayak Income '!A51,'MPG Payment '!$H$3:$H$79771) -> 2920.4 | G51: =SUMIF('MPG Payment '!$D$3:$D$79771,'Shayak Income '!A51,'MPG Payment '!$I$3:$I$79771) -> 104566.76 | H51: =+F51*1.05 -> 3066.42 | I51: 0 | J51: 0 | K51: 0 | L51: =H51-I51-J51-K51 -> 3066.42
A52: 20050003 | B52: UCHARI | C52: =VLOOKUP(A52,'MPG Payment '!$D$3:$G$7771,3,0) -> MPG | D52: =VLOOKUP(A52,'MPG Payment '!$D$3:$G$764,4,0) -> Direct | E52: =_xlfn.XLOOKUP(A52,'MPG Payment '!$D$2:$D$771,'MPG Payment '!$C$2:$C$771) -> BMC Code :2002 | F52: =SUMIF('MPG Payment '!$D$3:$D$79771,'Shayak Income '!A52,'MPG Payment '!$H$3:$H$79771) -> 4320.7 | G52: =SUMIF('MPG Payment '!$D$3:$D$79771,'Shayak Income '!A52,'MPG Payment '!$I$3:$I$79771) -> 163730.92 | H52: =+F52*1.05 -> 4536.735 | I52: 0 | J52: 0 | K52: 0 | L52: =H52-I52-J52-K52 -> 4536.735
A53: 20060001 | B53: ORMANJHI | C53: =VLOOKUP(A53,'MPG Payment '!$D$3:$G$7771,3,0) -> RMC | D53: =VLOOKUP(A53,'MPG Payment '!$D$3:$G$764,4,0) -> Direct | E53: =_xlfn.XLOOKUP(A53,'MPG Payment '!$D$2:$D$771,'MPG Payment '!$C$2:$C$771) -> BMC Code :2006 | F53: =SUMIF('MPG Payment '!$D$3:$D$79771,'Shayak Income '!A53,'MPG Payment '!$H$3:$H$79771) -> 10167.18 | G53: =SUMIF('MPG Payment '!$D$3:$D$79771,'Shayak Income '!A53,'MPG Payment '!$I$3:$I$79771) -> 393167.83 | H53: =+F53*1.05 -> 10675.539 | I53: 0 | J53: 0 | K53: 0 | L53: =H53-I53-J53-K53 -> 10675.539
A54: 20060002 | B54: MANDRO | C54: =VLOOKUP(A54,'MPG Payment '!$D$3:$G$7771,3,0) -> MPG | D54: =VLOOKUP(A54,'MPG Payment '!$D$3:$G$764,4,0) -> Direct | E54: =_xlfn.XLOOKUP(A54,'MPG Payment '!$D$2:$D$771,'MPG Payment '!$C$2:$C$771) -> BMC Code :2006 | F54: =SUMIF('MPG Payment '!$D$3:$D$79771,'Shayak Income '!A54,'MPG Payment '!$H$3:$H$79771) -> 740.21 | G54: =SUMIF('MPG Payment '!$D$3:$D$79771,'Shayak Income '!A54,'MPG Payment '!$I$3:$I$79771) -> 28041.03 | H54: =+F54*1.05 -> 777.2205 | I54: 0 | J54: 0 | K54: 0 | L54: =H54-I54-J54-K54 -> 777.2205
A55: 20060003 | B55: DUMARDAGA | C55: =VLOOKUP(A55,'MPG Payment '!$D$3:$G$7771,3,0) -> MPG | D55: =VLOOKUP(A55,'MPG Payment '!$D$3:$G$764,4,0) -> Direct | E55: =_xlfn.XLOOKUP(A55,'MPG Payment '!$D$2:$D$771,'MPG Payment '!$C$2:$C$771) -> BMC Code :2006 | F55: =SUMIF('MPG Payment '!$D$3:$D$79771,'Shayak Income '!A55,'MPG Payment '!$H$3:$H$79771) -> 8553.94 | G55: =SUMIF('MPG Payment '!$D$3:$D$79771,'Shayak Income '!A55,'MPG Payment '!$I$3:$I$79771) -> 294238.98 | H55: =+F55*1.05 -> 8981.637 | I55: 0 | J55: 0 | K55: 0 | L55: =H55-I55-J55-K55 -> 8981.637
A56: 20060004 | B56: CHUTTU | C56: =VLOOKUP(A56,'MPG Payment '!$D$3:$G$7771,3,0) -> MPG | D56: =VLOOKUP(A56,'MPG Payment '!$D$3:$G$764,4,0) -> Direct | E56: =_xlfn.XLOOKUP(A56,'MPG Payment '!$D$2:$D$771,'MPG Payment '!$C$2:$C$771) -> BMC Code :2006 | F56: =SUMIF('MPG Payment '!$D$3:$D$79771,'Shayak Income '!A56,'MPG Payment '!$H$3:$H$79771) -> 6637.09 | G56: =SUMIF('MPG Payment '!$D$3:$D$79771,'Shayak Income '!A56,'MPG Payment '!$I$3:$I$79771) -> 251695.85 | H56: =+F56*1.05 -> 6968.9445 | I56: 0 | J56: 0 | K56: 0 | L56: =H56-I56-J56-K56 -> 6968.9445
A57: 20060005 | B57: JIRABAR | C57: =VLOOKUP(A57,'MPG Payment '!$D$3:$G$7771,3,0) -> MPG | D57: =VLOOKUP(A57,'MPG Payment '!$D$3:$G$764,4,0) -> Direct | E57: =_xlfn.XLOOKUP(A57,'MPG Payment '!$D$2:$D$771,'MPG Payment '!$C$2:$C$771) -> BMC Code :2006 | F57: =SUMIF('MPG Payment '!$D$3:$D$79771,'Shayak Income '!A57,'MPG Payment '!$H$3:$H$79771) -> 2214.86 | G57: =SUMIF('MPG Payment '!$D$3:$D$79771,'Shayak Income '!A57,'MPG Payment '!$I$3:$I$79771) -> 83067.18 | H57: =+F57*1.05 -> 2325.603 | I57: 0 | J57: 0 | K57: 0 | L57: =H57-I57-J57-K57 -> 2325.603
A58: 20060007 | B58: HOCHAR | C58: =VLOOKUP(A58,'MPG Payment '!$D$3:$G$7771,3,0) -> MPG | D58: =VLOOKUP(A58,'MPG Payment '!$D$3:$G$764,4,0) -> Direct | E58: =_xlfn.XLOOKUP(A58,'MPG Payment '!$D$2:$D$771,'MPG Payment '!$C$2:$C$771) -> BMC Code :2006 | F58: =SUMIF('MPG Payment '!$D$3:$D$79771,'Shayak Income '!A58,'MPG Payment '!$H$3:$H$79771) -> 6843.14 | G58: =SUMIF('MPG Payment '!$D$3:$D$79771,'Shayak Income '!A58,'MPG Payment '!$I$3:$I$79771) -> 265267.02 | H58: =+F58*1.05 -> 7185.297 | I58: 0 | J58: 0 | K58: 0 | L58: =H58-I58-J58-K58 -> 7185.297
A59: 20060008 | B59: ADELHATU | C59: =VLOOKUP(A59,'MPG Payment '!$D$3:$G$7771,3,0) -> VLC | D59: =VLOOKUP(A59,'MPG Payment '!$D$3:$G$764,4,0) -> Direct | E59: =_xlfn.XLOOKUP(A59,'MPG Payment '!$D$2:$D$771,'MPG Payment '!$C$2:$C$771) -> BMC Code :2006 | F59: =SUMIF('MPG Payment '!$D$3:$D$79771,'Shayak Income '!A59,'MPG Payment '!$H$3:$H$79771) -> 7014.81 | G59: =SUMIF('MPG Payment '!$D$3:$D$79771,'Shayak Income '!A59,'MPG Payment '!$I$3:$I$79771) -> 274062.09 | H59: =+F59*1.05 -> 7365.5505 | I59: 0 | J59: 0 | K59: 0 | L59: =H59-I59-J59-K59 -> 7365.5505
A60: 20060009 | B60: KUCHU | C60: =VLOOKUP(A60,'MPG Payment '!$D$3:$G$7771,3,0) -> MPG | D60: =VLOOKUP(A60,'MPG Payment '!$D$3:$G$764,4,0) -> Direct | E60: =_xlfn.XLOOKUP(A60,'MPG Payment '!$D$2:$D$771,'MPG Payment '!$C$2:$C$771) -> BMC Code :2006 | F60: =SUMIF('MPG Payment '!$D$3:$D$79771,'Shayak Income '!A60,'MPG Payment '!$H$3:$H$79771) -> 1261.58 | G60: =SUMIF('MPG Payment '!$D$3:$D$79771,'Shayak Income '!A60,'MPG Payment '!$I$3:$I$79771) -> 49289.23 | H60: =+F60*1.05 -> 1324.659 | I60: 0 | J60: 0 | K60: 0 | L60: =H60-I60-J60-K60 -> 1324.659
... A141: 20090028 | B141: FULDIH 2 | C141: =VLOOKUP(A141,'MPG Payment '!$D$3:$G$7771,3,0) -> VLC | D141: =VLOOKUP(A141,'MPG Payment '!$D$3:$G$764,4,0) -> Indirect | E141: =_xlfn.XLOOKUP(A141,'MPG Payment '!$D$2:$D$771,'MPG Payment '!$C$2:$C$771) -> BMC Code :2009 | F141: =SUMIF('MPG Payment '!$D$3:$D$79771,'Shayak Income '!A141,'MPG Payment '!$H$3:$H$79771) -> 643.48 | G141: =SUMIF('MPG Payment '!$D$3:$D$79771,'Shayak Income '!A141,'MPG Payment '!$I$3:$I$79771) -> 26158.16 | H141: =+F141*1.05 -> 675.654 | I141: 0 | J141: 0 | K141: 0 | L141: =H141-I141-J141-K141 -> 675.654
A142: =COUNTA(A3:A141) -> 139 | C142: =COUNT(C3:C141) -> 0 | F142: =SUBTOTAL(9,F2:F141) -> 557151.13 | G142: =SUBTOTAL(9,G2:G141) -> 21435065 | H142: =SUBTOTAL(9,H2:H141) -> 585008.69 | I142: =SUBTOTAL(9,I2:I141) -> 41295.425 | J142: =SUBTOTAL(9,J2:J141) -> 0 | L142: =SUBTOTAL(9,L2:L141) -> 543713.26
B170: Row Labels | C170: No of MPGs | D170: BMC Volume | E170: BMC Amount | F170: Sahayak Comission @ 1.05/- | G170: Deduction TS Loss | H170: Cattle Feed Deduction | I170: Net Payble
B171: BMC Code :2001 | C171: 28 | D171: 113063.83 | E171: 4402068.3 | F171: 118717.02 | G171: 0 | H171: 0 | I171: 118717.02
B172: BMC Code :2009 | C172: 24 | D172: 72658.74 | E172: 2823393.8 | F172: 76291.677 | G172: 2491 | H172: 0 | I172: 73800.677
B173: BMC Code :2002 | C173: 21 | D173: 122189.77 | E173: 4738642.9 | F173: 128299.26 | G173: 0 | H173: 0 | I173: 128299.26
B174: BMC Code :2003 | C174: 5 | D174: 29076.82 | E174: 1076558 | F174: 30530.661 | G174: 0 | H174: 0 | I174: 30530.661
B175: BMC Code :2004 | C175: 3 | D175: 36259.74 | E175: 1250423.5 | F175: 38072.727 | G175: 34875 | H175: 0 | I175: 3197.727
B176: BMC Code :2006 | C176: 17 | D176: 62852.71 | E176: 2368520.9 | F176: 65995.345 | G176: 0 | H176: 0 | I176: 65995.345
B177: BMC Code :2007 | C177: 17 | D177: 43417.49 | E177: 1795629.3 | F177: 45588.365 | G177: 3929.4255 | H177: 0 | I177: 41658.939
B178: BMC Code :2008 | C178: 24 | D178: 77632.03 | E178: 2979828.6 | F178: 81513.632 | G178: 0 | H178: 0 | I178: 81513.632
B179: Grand Total | C179: 139 | D179: 557151.13 | E179: 21435065 | F179: 585008.69 | G179: 41295.425 | H179: 0 | I179: 543713.26

Sheet Sheet1
N1: Type | O1: RMC
N2: Stop Payment | O2: (All)
A4: Code | B4: MPG NAME | P4: Values
A5: 20010001 | B5: Itki | N5: Code | O5: MPG NAME | P5: Sum of TS Loss | Q5: Sum of Closing Reserve
A6: 20010003 | B6: Bero | N6: 20010001 | O6: Itki | P6: 34962 | Q6: 5.18
A7: 20010005 | B7: Basila | N7: 20020001 | O7: Paali | P7: 87303 | Q7: 5.26
A8: 20010008 | B8: Erchoro | N8: 20030001 | O8: Hisri Thakurgaon | P8: 12782 | Q8: 622
A9: 20010009 | B9: Makunda | N9: 20040001 | O9: CHOREYA | P9: 23605 | Q9: 307.27
A10: 20010012 | B10: NAGRI | N10: 20050001 | O10: Baski 2 | P10: 0 | Q10: 226.73
A11: 20010015 | B11: BOREYA | N11: 20060001 | O11: ORMANJHI | P11: 0 | Q11: 136.83
A12: 20010016 | B12: ITA CHILDRI | N12: 20070001 | O12: PIRAGUTU | P12: 27463 | Q12: 14439.77
A13: 20010017 | B13: DIGHIYA | N13: 20080001 | O13: CHATTI BHANDRA | P13: 14688 | Q13: 376.43
A14: 20010023 | B14: KATARPA | N14: 20090001 | O14: Chanho | P14: 4 | Q14: 1.1
A15: 20010027 | B15: MURTO | N15: Grand Total | P15: 200807 | Q15: 16120.57
A16: 20010033 | B16: KHATRIKHATANGA
A17: 20010034 | B17: GARGAON
A18: 20010036 | B18: GHAGHRA
A19: 20010037 | B19: CHACHGURA
A20: 20010038 | B20: TIKRA TOLI
A21: 20010040 | B21: Gargaon2
A22: 20010041 | B22: TERO
A23: 20010042 | B23: RONHE
A24: 20010043 | B24: DARKHANDREY
A25: 20010052 | B25: Kumbatoli
A26: 20010053 | B26: TUTLO
A27: 20010054 | B27: NARKOPI
... A143: 20090028 | B143: FULDIH 2
A144: Grand Total

Sheet Sheet2
A1: Type | B1: RMC
A3: Sum of TS Loss | B3: Column Labels
A4: Row Labels | B4: 02-08 Jan | C4: 09-15 Jan | D4: 16-22 Jan | E4: 23-29 Jan | F4: Grand Total
A5: 20010001 | B5: 32242 | C5: 28544 | D5: 20747 | E5: 6367 | F5: 87900
A6: 20020001 | B6: 4545 | C6: 7603 | D6: 2575 | E6: 8268 | F6: 22991
A7: 20030001 | B7: 4437 | C7: 6041 | D7: 0 | E7: 2551 | F7: 13029
A8: 20040001 | B8: 1324 | C8: 809 | D8: 493 | E8: 6634 | F8: 9260
A9: 20050001 | B9: 0 | C9: 0 | D9: 0 | E9: 0 | F9: 0
A10: 20060001 | B10: 1438 | C10: 0 | D10: 0 | E10: 128 | F10: 1566
A11: 20070001 | B11: 114 | C11: 2643 | D11: 7015 | E11: 1644 | F11: 11416
A12: 20080001 | B12: 1135 | C12: 447 | D12: 529 | E12: 149 | F12: 2260
A13: 20090001 | B13: 0 | C13: 0 | D13: 0 | E13: 0 | F13: 0
A14: Grand Total | B14: 45235 | C14: 46087 | D14: 31359 | E14: 25741 | F14: 148422

Sheet Sheet3
A1: Type | B1: RMC
A3: Sum of TS Loss | B3: Column Labels
A4: Row Labels | B4: 30-05 Feb | C4: 06-12 Feb | D4: 13-19 Feb | E4: 20-26 Feb | F4: Grand Total
A5: 20010001 | B5: 7401 | C5: 17191 | D5: 3100 | E5: 10874 | F5: 38566
A6: 20020001 | B6: 2143 | C6: 19691 | D6: 7772 | E6: 0 | F6: 29606
A7: 20030001 | B7: 2541 | C7: 3128 | D7: 551 | E7: 3061 | F7: 9281
A8: 20040001 | B8: 8122 | C8: 0 | D8: 5925 | E8: 619 | F8: 14666
A9: 20050001 | B9: 0 | C9: 0 | D9: 0 | E9: 0 | F9: 0
A10: 20060001 | B10: 0 | C10: 0 | D10: 0 | E10: 0 | F10: 0
A11: 20070001 | B11: 7438 | C11: 0 | D11: 8603 | E11: 3285 | F11: 19326
A12: 20080001 | B12: 272 | C12: 0 | D12: 0 | E12: 103 | F12: 375
A13: 20090001 | B13: 0 | C13: 0 | D13: 0 | E13: 0 | F13: 0
A14: Grand Total | B14: 27917 | C14: 40010 | D14: 25951 | E14: 17942 | F14: 111820

Sheet MPG Payment 
H1: New Format | J1: Reg. Farmers | L1: Unreg. Farmers | N1: Total farmer
A2: Area | B2: Period | C2: BMC Code | D2: Code | E2: MPG NAME | F2: Type | G2: Farmer Payment | H2: BMC Volume | I2: BMC Amount | J2: Reg Vol | K2: reg Amt | L2: Unreg Vol | M2: Unreg Amt | N2: Total Vol | O2: Total Amt | P2: Payable | Q2: TS Loss | R2: Deduction for excess payment | S2: Loss Apportion | T2: CF Deduction | U2: Vet Deduction | V2: Advance | W2: Others | X2: Payment to Farmer A/c | Y2: Unreg. Farmer payment | Z2: Payment to MPGs A/c | AA2: Closing Reserve | AB2: Stop Payment | AC2: Diff | AD2: loss/gain | AE2: No of Farmers | AF2: Cycle | AG2: Remarks
A3: Ranchi | B3: 01-02 Apr | C3: BMC Code :2001 | D3: 20010001 | E3: Itki | F3: RMC | G3: Direct | H3: 9034.34 | I3: 380070.22 | J3: 9074.34 | K3: 381429.67 | L3: 0 | M3: 0 | N3: 9074.34 | O3: 381429.67 | P3: 380070.22 | Q3: 6564 | R3: 0 | S3: 1359.45 | T3: 0 | U3: 0 | V3: 0 | W3: 0 | X3: 373506 | Y3: 0 | Z3: 0 | AA3: 0.22 | AB3: 0 | AC3: 0 | AD3: 0.003576839 | AE3: 16 | AF3: 01. 01-02 Apr
A4: Ranchi | B4: 01-02 Apr | C4: BMC Code :2001 | D4: 20010003 | E4: Bero | F4: MPG | G4: Direct | H4: 367.72 | I4: 14021.19 | J4: 365.72 | K4: 14003.46 | L4: 0 | M4: 0 | N4: 365.72 | O4: 14003.46 | P4: 14003.46 | Q4: 0 | R4: 0 | S4: 0 | T4: 0 | U4: 0 | V4: 0 | W4: 0 | X4: 14003 | Y4: 0 | Z4: 0 | AA4: 18.19 | AB4: 0 | AC4: 0 | AD4: -0.0012645146 | AE4: 5 | AF4: 01. 01-02 Apr
A5: Ranchi | B5: 01-02 Apr | C5: BMC Code :2001 | D5: 20010005 | E5: Basila | F5: MPG | G5: Direct | H5: 315.74 | I5: 11923.45 | J5: 299.96 | K5: 11877.56 | L5: 0 | M5: 0 | N5: 299.96 | O5: 11877.56 | P5: 11877.56 | Q5: 0 | R5: 0 | S5: 0 | T5: 0 | U5: 0 | V5: 0 | W5: 0 | X5: 11877 | Y5: 0 | Z5: 0 | AA5: 46.45 | AB5: 0 | AC5: 1 | AD5: -0.0038487183 | AE5: 20 | AF5: 01. 01-02 Apr
A6: Ranchi | B6: 01-02 Apr | C6: BMC Code :2001 | D6: 20010008 | E6: Erchoro | F6: MPG | G6: Direct | H6: 540.88 | I6: 18965.27 | J6: 541.84 | K6: 20333.13 | L6: 0 | M6: 0 | N6: 541.84 | O6: 20333.13 | P6: 18965.27 | Q6: 0 | R6: 0 | S6: 1367.86 | T6: 0 | U6: 0 | V6: 0 | W6: 0 | X6: 18964 | Y6: 0 | Z6: 0 | AA6: 1.27 | AB6: Release1 | AC6: 1 | AD6: 0.072124468 | AE6: 16 | AF6: 01. 01-02 Apr | AG6: Letter not received
A7: Ranchi | B7: 01-02 Apr | C7: BMC Code :2001 | D7: 20010009 | E7: Makunda | F7: MPG | G7: Direct | H7: 178.08 | I7: 6979.17 | J7: 177.96 | K7: 7196.8 | L7: 0 | M7: 0 | N7: 177.96 | O7: 7196.8 | P7: 6979.17 | Q7: 0 | R7: 0 | S7: 217.63 | T7: 0 | U7: 0 | V7: 0 | W7: 0 | X7: 6979 | Y7: 0 | Z7: 0 | AA7: 0.17 | AB7: 0 | AC7: 0 | AD7: 0.031182791 | AE7: 5 | AF7: 01. 01-02 Apr
A8: Ranchi | B8: 01-02 Apr | C8: BMC Code :2001 | D8: 20010012 | E8: NAGRI | F8: VLC | G8: Indirect | H8: 25.5 | I8: 731.6 | J8: 0 | K8: 0 | L8: 0 | M8: 0 | N8: 0 | O8: 0 | P8: 731.6 | Q8: 0 | R8: 0 | S8: 0 | T8: 0 | U8: 0 | V8: 0 | W8: 0 | X8: 0 | Y8: 0 | Z8: 731.6 | AA8: 0 | AB8: 0 | AC8: 0 | AD8: -1 | AE8: 0 | AF8: 01. 01-02 Apr
A9: Ranchi | B9: 01-02 Apr | C9: BMC Code :2001 | D9: 20010015 | E9: BOREYA | F9: MPG | G9: Direct | H9: 824.06 | I9: 32281.44 | J9: 828.67 | K9: 33382.11 | L9: 0 | M9: 0 | N9: 828.67 | O9: 33382.11 | P9: 32281.44 | Q9: 0 | R9: 0 | S9: 1100.67 | T9: 0 | U9: 0 | V9: 0 | W9: 0 | X9: 32281 | Y9: 0 | Z9: 0 | AA9: 0.44 | AB9: Release1 | AC9: 0 | AD9: 0.034096063 | AE9: 51 | AF9: 01. 01-02 Apr | AG9: Letter not received
A10: Ranchi | B10: 01-02 Apr | C10: BMC Code :2001 | D10: 20010016 | E10: ITA CHILDRI | F10: MPG | G10: Direct | H10: 40.14 | I10: 1689.08 | J10: 42.11 | K10: 1716 | L10: 0 | M10: 0 | N10: 42.11 | O10: 1716 | P10: 1689.08 | Q10: 0 | R10: 0 | S10: 26.92 | T10: 0 | U10: 0 | V10: 0 | W10: 0 | X10: 1689 | Y10: 0 | Z10: 0 | AA10: 0.08 | AB10: 0 | AC10: 0 | AD10: 0.01593767 | AE10: 11 | AF10: 01. 01-02 Apr
A11: Ranchi | B11: 01-02 Apr | C11: BMC Code :2001 | D11: 20010017 | E11: DIGHIYA | F11: MPG | G11: Direct | H11: 369.38 | I11: 13806.14 | J11: 374.33 | K11: 14356.61 | L11: 0 | M11: 0 | N11: 374.33 | O11: 14356.61 | P11: 13806.14 | Q11: 0 | R11: 0 | S11: 550.47 | T11: 0 | U11: 0 | V11: 0 | W11: 0 | X11: 13806 | Y11: 0 | Z11: 0 | AA11: 0.14 | AB11: 0 | AC11: 0 | AD11: 0.039871391 | AE11: 21 | AF11: 01. 01-02 Apr
A12: Ranchi | B12: 01-02 Apr | C12: BMC Code :2001 | D12: 20010023 | E12: KATARPA | F12: MPG | G12: Direct | H12: 124.78 | I12: 4937.59 | J12: 119.99 | K12: 4908.99 | L12: 0 | M12: 0 | N12: 119.99 | O12: 4908.99 | P12: 4908.99 | Q12: 0 | R12: 0 | S12: 0 | T12: 0 | U12: 0 | V12: 0 | W12: 0 | X12: 4911 | Y12: 0 | Z12: 0 | AA12: 26.59 | AB12: 0 | AC12: -2 | AD12: -0.0057922995 | AE12: 15 | AF12: 01. 01-02 Apr
A13: Ranchi | B13: 01-02 Apr | C13: BMC Code :2001 | D13: 20010027 | E13: MURTO | F13: MPG | G13: Direct | H13: 178.92 | I13: 6809.93 | J13: 176.61 | K13: 7164.94 | L13: 9.29 | M13: 311.99 | N13: 185.9 | O13: 7476.93 | P13: 6809.93 | Q13: 0 | R13: 0 | S13: 667 | T13: 0 | U13: 0 | V13: 0 | W13: 0 | X13: 6497 | Y13: 312 | Z13: 0 | AA13: 0.93 | AB13: 0 | AC13: 1 | AD13: 0.097945206 | AE13: 12 | AF13: 01. 01-02 Apr
A14: Ranchi | B14: 01-02 Apr | C14: BMC Code :2001 | D14: 20010033 | E14: KHATRIKHATANGA | F14: MPG | G14: Direct | H14: 101.36 | I14: 4052.84 | J14: 101.94 | K14: 4093.14 | L14: 0 | M14: 0 | N14: 101.94 | O14: 4093.14 | P14: 4052.84 | Q14: 0 | R14: 0 | S14: 40.3 | T14: 0 | U14: 0 | V14: 0 | W14: 0 | X14: 4053 | Y14: 0 | Z14: 0 | AA14: -0.16 | AB14: 0 | AC14: 0 | AD14: 0.0099436445 | AE14: 3 | AF14: 01. 01-02 Apr
A15: Ranchi | B15: 01-02 Apr | C15: BMC Code :2001 | D15: 20010034 | E15: GARGAON | F15: MPG | G15: Direct | H15: 128.24 | I15: 4704.1 | J15: 129.07 | K15: 5007.31 | L15: 0 | M15: 0 | N15: 129.07 | O15: 5007.31 | P15: 4704.1 | Q15: 0 | R15: 0 | S15: 303.21 | T15: 0 | U15: 0 | V15: 0 | W15: 0 | X15: 4704 | Y15: 0 | Z15: 0 | AA15: 0.1 | AB15: 0 | AC15: 0 | AD15: 0.064456538 | AE15: 2 | AF15: 01. 01-02 Apr
A16: Ranchi | B16: 01-02 Apr | C16: BMC Code :2001 | D16: 20010036 | E16: GHAGHRA | F16: MPG | G16: Indirect | H16: 33.2 | I16: 1223.88 | J16: 0 | K16: 0 | L16: 0 | M16: 0 | N16: 0 | O16: 0 | P16: 1223.88 | Q16: 0 | R16: 0 | S16: 0 | T16: 0 | U16: 0 | V16: 0 | W16: 0 | X16: 0 | Y16: 0 | Z16: 1223.88 | AA16: 0 | AB16: 0 | AC16: 0 | AD16: -1 | AE16: 0 | AF16: 01. 01-02 Apr
A17: Ranchi | B17: 01-02 Apr | C17: BMC Code :2001 | D17: 20010037 | E17: CHACHGURA | F17: MPG | G17: Indirect | H17: 116.54 | I17: 4512.53 | J17: 0 | K17: 0 | L17: 0 | M17: 0 | N17: 0 | O17: 0 | P17: 4512.53 | Q17: 0 | R17: 0 | S17: 0 | T17: 0 | U17: 0 | V17: 0 | W17: 0 | X17: 0 | Y17: 0 | Z17: 4512.53 | AA17: 0 | AB17: 0 | AC17: 0 | AD17: -1 | AE17: 0 | AF17: 01. 01-02 Apr
A18: Ranchi | B18: 01-02 Apr | C18: BMC Code :2001 | D18: 20010038 | E18: TIKRA TOLI | F18: MPG | G18: Direct | H18: 78.02 | I18: 2800.72 | J18: 79.88 | K18: 2877.05 | L18: 0 | M18: 0 | N18: 79.88 | O18: 2877.05 | P18: 2800.72 | Q18: 0 | R18: 0 | S18: 76.33 | T18: 0 | U18: 0 | V18: 0 | W18: 0 | X18: 2801 | Y18: 0 | Z18: 0 | AA18: -0.28 | AB18: 0 | AC18: 0 | AD18: 0.027253706 | AE18: 1 | AF18: 01. 01-02 Apr
A19: Ranchi | B19: 01-02 Apr | C19: BMC Code :2001 | D19: 20010040 | E19: Gargaon2 | F19: MPG | G19: Direct | H19: 214.62 | I19: 8208.01 | J19: 214.26 | K19: 8103.38 | L19: 0 | M19: 0 | N19: 214.26 | O19: 8103.38 | P19: 8103.38 | Q19: 0 | R19: 0 | S19: 0 | T19: 0 | U19: 0 | V19: 0 | W19: 0 | X19: 8103 | Y19: 0 | Z19: 0 | AA19: 105.01 | AB19: 0 | AC19: 0 | AD19: -0.012747304 | AE19: 7 | AF19: 01. 01-02 Apr
A20: Ranchi | B20: 01-02 Apr | C20: BMC Code :2001 | D20: 20010041 | E20: TERO | F20: MPG | G20: Direct | H20: 27.08 | I20: 1045.46 | J20: 29.38 | K20: 1169.43 | L20: 0 | M20: 0 | N20: 29.38 | O20: 1169.43 | P20: 1045.46 | Q20: 0 | R20: 0 | S20: 123.97 | T20: 0 | U20: 0 | V20: 0 | W20: 0 | X20: 1045 | Y20: 0 | Z20: 0 | AA20: 0.46 | AB20: 0 | AC20: 0 | AD20: 0.11857938 | AE20: 5 | AF20: 01. 01-02 Apr
A21: Ranchi | B21: 01-02 Apr | C21: BMC Code :2001 | D21: 20010042 | E21: RONHE | F21: MPG | G21: Direct | H21: 162.86 | I21: 6660.25 | J21: 160.55 | K21: 6505.74 | L21: 0 | M21: 0 | N21: 160.55 | O21: 6505.74 | P21: 6505.74 | Q21: 0 | R21: 0 | S21: 0 | T21: 0 | U21: 0 | V21: 0 | W21: 0 | X21: 6506 | Y21: 0 | Z21: 0 | AA21: 154.25 | AB21: 0 | AC21: 0 | AD21: -0.023198829 | AE21: 21 | AF21: 01. 01-02 Apr
... A55: Ranchi | B55: 01-02 Apr | C55: BMC Code :2004 | D55: 20040001 | E55: CHOREYA | F55: RMC | G55: Direct | H55: 1301.48 | I55: 43632.63 | J55: 1301.48 | K55: 43632.63 | L55: 0 | M55: 0 | N55: 1301.48 | O55: 43632.63 | P55: 43632.63 | Q55: 1203 | R55: 0 | S55: 0 | T55: 0 | U55: 0 | V55: 0 | W55: 0 | X55: 42430 | Y55: 0 | Z55: 0 | AA55: -0.37 | AB55: 0 | AC55: 0 | AD55: -3.3350993e-16 | AE55: 21 | AF55: 01. 01-02 Apr
A56: Ranchi | B56: 01-02 Apr | C56: BMC Code :2004 | D56: 20040006 | E56: KADAM TOLI | F56: MPG | G56: Direct | H56: 107.05 | I56: 4222.76 | J56: 108.79 | K56: 4410.44 | L56: 0 | M56: 0 | N56: 108.79 | O56: 4410.44 | P56: 4222.76 | Q56: 0 | R56: 0 | S56: 187.68 | T56: 0 | U56: 0 | V56: 0 | W56: 0 | X56: 4223 | Y56: 0 | Z56: 0 | AA56: -0.24 | AB56: Release1 | AC56: 0 | AD56: 0.044444865 | AE56: 9 | AF56: 01. 01-02 Apr | AG56: Letter not received
A57: Ranchi | B57: 01-02 Apr | C57: BMC Code :2004 | D57: 20040007 | E57: MADHUKAM | F57: MPG | G57: Direct | H57: 78.52 | I57: 2975.83 | J57: 80.08 | K57: 3096.57 | L57: 0 | M57: 0 | N57: 80.08 | O57: 3096.57 | P57: 2975.83 | Q57: 0 | R57: 0 | S57: 120.74 | T57: 0 | U57: 0 | V57: 0 | W57: 0 | X57: 2976 | Y57: 0 | Z57: 0 | AA57: -0.17 | AB57: 0 | AC57: 0 | AD57: 0.040573554 | AE57: 10 | AF57: 01. 01-02 Apr
A58: Ranchi | B58: 01-02 Apr | C58: BMC Code :2002 | D58: 20050001 | E58: Baski 2 | F58: RMC | G58: Direct | H58: 212.3 | I58: 8216.07 | J58: 191.28 | K58: 7406.29 | L58: 24 | M58: 795.35 | N58: 215.28 | O58: 8201.64 | P58: 8201.64 | Q58: 0 | R58: 0 | S58: 0 | T58: 0 | U58: 0 | V58: 0 | W58: 0 | X58: 7405 | Y58: 795 | Z58: 0 | AA58: 16.07 | AB58: 0 | AC58: 2 | AD58: -0.0017563142 | AE58: 23 | AF58: 01. 01-02 Apr
A59: Ranchi | B59: 01-02 Apr | C59: BMC Code :2002 | D59: 20050002 | E59: KANBHITHA | F59: MPG | G59: Direct | H59: 197.1 | I59: 7105.63 | J59: 192.74 | K59: 7097.55 | L59: 0 | M59: 0 | N59: 192.74 | O59: 7097.55 | P59: 7097.55 | Q59: 0 | R59: 0 | S59: 0 | T59: 0 | U59: 0 | V59: 0 | W59: 0 | X59: 7096 | Y59: 0 | Z59: 0 | AA59: 9.63 | AB59: 0 | AC59: 2 | AD59: -0.0011371265 | AE59: 15 | AF59: 01. 01-02 Apr
A60: Ranchi | B60: 01-02 Apr | C60: BMC Code :2002 | D60: 20050003 | E60: UCHARI | F60: MPG | G60: Direct | H60: 291.2 | I60: 11146.05 | J60: 291.42 | K60: 11067.63 | L60: 0 | M60: 0 | N60: 291.42 | O60: 11067.63 | P60: 11067.63 | Q60: 0 | R60: 0 | S60: 0 | T60: 0 | U60: 0 | V60: 0 | W60: 0 | X60: 11069 | Y60: 0 | Z60: 0 | AA60: 77.05 | AB60: 0 | AC60: -1 | AD60: -0.0070356763 | AE60: 17 | AF60: 01. 01-02 Apr
A61: Ranchi | B61: 01-02 Apr | C61: BMC Code :2006 | D61: 20060001 | E61: ORMANJHI | F61: RMC | G61: Direct | H61: 388.17 | I61: 15078.54 | J61: 388.17 | K61: 15078.54 | L61: 0 | M61: 0 | N61: 388.17 | O61: 15078.54 | P61: 15078.54 | Q61: 0 | R61: 0 | S61: 0 | T61: 0 | U61: 0 | V61: 0 | W61: 0 | X61: 15078 | Y61: 0 | Z61: 0 | AA61: 0.54 | AB61: 0 | AC61: 1 | AD61: 1.2063432e-16 | AE61: 9 | AF61: 01. 01-02 Apr
A62: Ranchi | B62: 01-02 Apr | C62: BMC Code :2006 | D62: 20060002 | E62: MANDRO | F62: MPG | G62: Direct | H62: 52.12 | I62: 2056.33 | J62: 49.92 | K62: 1861.49 | L62: 0 | M62: 0 | N62: 49.92 | O62: 1861.49 | P62: 1861.49 | Q62: 0 | R62: 0 | S62: 0 | T62: 0 | U62: 0 | V62: 0 | W62: 0 | X62: 1862 | Y62: 0 | Z62: 0 | AA62: 194.33 | AB62: 0 | AC62: -1 | AD62: -0.094751329 | AE62: 5 | AF62: 01. 01-02 Apr
A63: Ranchi | B63: 01-02 Apr | C63: BMC Code :2006 | D63: 20060003 | E63: DUMARDAGA | F63: MPG | G63: Direct | H63: 336.24 | I63: 13018.28 | J63: 343.79 | K63: 13292.31 | L63: 0 | M63: 0 | N63: 343.79 | O63: 13292.31 | P63: 13018.28 | Q63: 0 | R63: 0 | S63: 274.03 | T63: 0 | U63: 0 | V63: 0 | W63: 0 | X63: 13018 | Y63: 0 | Z63: 0 | AA63: 0.28 | AB63: 0 | AC63: 0 | AD63: 0.021049632 | AE63: 1 | AF63: 01. 01-02 Apr
A64: Ranchi | B64: 01-02 Apr | C64: BMC Code :2006 | D64: 20060004 | E64: CHUTTU | F64: MPG | G64: Direct | H64: 465.06 | I64: 17570.26 | J64: 470.62 | K64: 17893.89 | L64: 0 | M64: 0 | N64: 470.62 | O64: 17893.89 | P64: 17570.26 | Q64: 0 | R64: 0 | S64: 323.63 | T64: 0 | U64: 0 | V64: 0 | W64: 0 | X64: 17570 | Y64: 0 | Z64: 0 | AA64: 0.26 | AB64: 0 | AC64: 0 | AD64: 0.018419192 | AE64: 23 | AF64: 01. 01-02 Apr
A65: Ranchi | B65: 01-02 Apr | C65: BMC Code :2006 | D65: 20060005 | E65: JIRABAR | F65: MPG | G65: Direct | H65: 153.08 | I65: 5905.38 | J65: 153.92 | K65: 5863.98 | L65: 0 | M65: 0 | N65: 153.92 | O65: 5863.98 | P65: 5863.98 | Q65: 0 | R65: 0 | S65: 0 | T65: 0 | U65: 0 | V65: 0 | W65: 0 | X65: 5865 | Y65: 0 | Z65: 0 | AA65: 40.38 | AB65: 0 | AC65: -1 | AD65: -0.0070105565 | AE65: 7 | AF65: 01. 01-02 Apr
A66: Ranchi | B66: 01-02 Apr | C66: BMC Code :2006 | D66: 20060007 | E66: HOCHAR | F66: MPG | G66: Direct | H66: 397.87 | I66: 15751.05 | J66: 363 | K66: 14168.47 | L66: 33.75 | M66: 1388.73 | N66: 396.75 | O66: 15557.2 | P66: 15557.2 | Q66: 0 | R66: 0 | S66: 0 | T66: 0 | U66: 0 | V66: 0 | W66: 0 | X66: 14169 | Y66: 1389 | Z66: 0 | AA66: 193.05 | AB66: 0 | AC66: -1 | AD66: -0.012307116 | AE66: 12 | AF66: 01. 01-02 Apr
A67: Ranchi | B67: 01-02 Apr | C67: BMC Code :2006 | D67: 20060008 | E67: ADELHATU | F67: VLC | G67: Direct | H67: 600.81 | I67: 23840.42 | J67: 598.03 | K67: 23352.42 | L67: 0 | M67: 0 | N67: 598.03 | O67: 23352.42 | P67: 23352.42 | Q67: 0 | R67: 0 | S67: 0 | T67: 0 | U67: 0 | V67: 0 | W67: 0 | X67: 23352 | Y67: 0 | Z67: 0 | AA67: 488.42 | AB67: 0 | AC67: 0 | AD67: -0.020469438 | AE67: 1 | AF67: 01. 01-02 Apr
A68: Ranchi | B68: 01-02 Apr | C68: BMC Code :2006 | D68: 20060009 | E68: KUCHU | F68: MPG | G68: Direct | H68: 82.87 | I68: 3381.14 | J68: 80.72 | K68: 3372.59 | L68: 0 | M68: 0 | N68: 80.72 | O68: 3372.59 | P68: 3372.59 | Q68: 0 | R68: 0 | S68: 0 | T68: 0 | U68: 0 | V68: 0 | W68: 0 | X68: 3373 | Y68: 0 | Z68: 0 | AA68: 8.14 | AB68: 0 | AC68: 0 | AD68: -0.0025287329 | AE68: 9 | AF68: 01. 01-02 Apr
... A84: Ranchi | B84: 01-02 Apr | C84: BMC Code :2007 | D84: 20070010 | E84: KURALU | F84: MPG | G84: Direct | H84: 112.89 | I84: 4561.23 | J84: 113.5 | K84: 4520.44 | L84: 0 | M84: 0 | N84: 113.5 | O84: 4520.44 | P84: 4520.44 | Q84: 0 | R84: 0 | S84: 0 | T84: 0 | U84: 0 | V84: 0 | W84: 0 | X84: 4521 | Y84: 0 | Z84: 0 | AA84: 40.23 | AB84: 0 | AC84: -1 | AD84: -0.0089427632 | AE84: 12 | AF84: 01. 01-02 Apr
A85: Ranchi | B85: 01-02 Apr | C85: BMC Code :2007 | D85: 20070016 | E85: MAYAPUR | F85: MPG | G85: Direct | H85: 55.92 | I85: 2090.14 | J85: 72.98 | K85: 2791.37 | L85: 0 | M85: 0 | N85: 72.98 | O85: 2791.37 | P85: 2090.14 | Q85: 0 | R85: 0 | S85: 701.23 | T85: 0 | U85: 0 | V85: 0 | W85: 0 | X85: 2090 | Y85: 0 | Z85: 0 | AA85: 0.14 | AB85: Release2 | AC85: 0 | AD85: 0.33549427 | AE85: 2 | AF85: 01. 01-02 Apr | AG85: Letter not received
A86: Ranchi | B86: 01-02 Apr | C86: BMC Code :2007 | D86: 20070018 | E86: MAKKA | F86: MPG | G86: Direct | H86: 105.36 | I86: 4598.78 | J86: 120.54 | K86: 5161.62 | L86: 0 | M86: 0 | N86: 120.54 | O86: 5161.62 | P86: 4598.78 | Q86: 0 | R86: 0 | S86: 562.84 | T86: 0 | U86: 0 | V86: 0 | W86: 0 | X86: 4599 | Y86: 0 | Z86: 0 | AA86: -0.22 | AB86: 0 | AC86: 0 | AD86: 0.12238898 | AE86: 2 | AF86: 01. 01-02 Apr
A87: Ranchi | B87: 01-02 Apr | C87: BMC Code :2007 | D87: 20070019 | E87: CHORA | F87: MPG | G87: Direct | H87: 80.82 | I87: 3340.84 | J87: 82.06 | K87: 3296.33 | L87: 0 | M87: 0 | N87: 82.06 | O87: 3296.33 | P87: 3296.33 | Q87: 0 | R87: 0 | S87: 0 | T87: 0 | U87: 0 | V87: 0 | W87: 0 | X87: 3298 | Y87: 0 | Z87: 0 | AA87: 42.84 | AB87: 0 | AC87: -2 | AD87: -0.013322997 | AE87: 6 | AF87: 01. 01-02 Apr
A88: Ranchi | B88: 01-02 Apr | C88: BMC Code :2007 | D88: 20070020 | E88: ULATU | F88: MPG | G88: Direct | H88: 172.05 | I88: 7476.6 | J88: 178.57 | K88: 7780.67 | L88: 0 | M88: 0 | N88: 178.57 | O88: 7780.67 | P88: 7476.6 | Q88: 0 | R88: 0 | S88: 304.07 | T88: 0 | U88: 0 | V88: 0 | W88: 0 | X88: 7477 | Y88: 0 | Z88: 0 | AA88: -0.4 | AB88: 0 | AC88: 0 | AD88: 0.040669556 | AE88: 2 | AF88: 01. 01-02 Apr
...

Sheet Sheet4
A3: Sum of Net Amount
A4: ID | B4: Farmers Account Name | C4: Accont no | D4: IFSC code | E4: Total
A5: 200100010002 | B5: AMIT KUMAR TIWARI | C5: 7125658980 | D5: IDIB000I021 | E5: 1319566
A6: 200100010005 | B6: ROPANI KUMARI KERKETTA | C6: 358702010602626 | D6: UBIN0535877 | E6: 3731
A7: 200100010010 | B7: SHANTI DEVI | C7: 6496430309 | D7: IDIB000I021 | E7: 12311
A8: 200100010017 | B8: Bikram Gope | C8: 358702010006937 | D8: UBIN0535877 | E8: 3009
A9: 200100010019 | B9: Hiramani Kachhap | C9: 494310110016645 | D9: BKID0004943 | E9: 6421
A10: 200100010033 | B10: Rahila Tirkey | C10: 22011269637 | D10: SBIN0RRVCGB | E10: 2883
A11: 200100010048 | B11: Anil Tirki | C11: 358702010004453 | D11: UBIN0535877 | E11: 4651
A12: 200100010050 | B12: SABITA TIWARI | C12: 762901500038 | D12: ICIC0007629 | E12: 21948
A13: 200100010051 | B13: SAHIL RAJ | C13: 40723769931 | D13: SBIN0000081 | E13: 11464
A14: 200100010064 | B14: SOHEL ANSARI | C14: 358702120002626 | D14: UBIN0535877 | E14: 33133
A15: 200100010066 | B15: SUJIT KUMAR ACHARYA | C15: 07591530000649 | D15: HDFC0000759 | E15: 9891
A16: 200100010067 | B16: SAJJAD ANSARI | C16: 358702010624724 | D16: UBIN0535877 | E16: 16381
... A23: 200100010082 | B23: CHANDRA CHUDAMANI PATHAK | C23: 59103904965996 | D23: HDFC0008691 | E23: 15636
A24: 200100030001 | B24: 0 | C24: 0 | D24: 0 | E24: 6536
A25: 200100030003 | B25: PINKI DEVI | C25: 4895101003786 | D25: CNRB0004895 | E25: 57521
A26: 200100030010 | B26: SURENDRA TIWARI | C26: 30852105546 | D26: SBIN0012618 | E26: 2844
A27: 200100030013 | B27: JOSEF LAKRA | C27: 495910510003202 | D27: BKID0004959 | E27: 1145
A28: 200100030023 | B28: SUSHMA DEVI | C28: 495910510006527 | D28: BKID0004959 | E28: 6307
A29: 200100030044 | B29: Manju Devi | C29: 08030100922544 | D29: UCBA0000803 | E29: 3827
A30: 200100030079 | B30: BIRSA ORAON | C30: 495910110009738 | D30: BKID0004959 | E30: 0
A31: 200100030080 | B31: GEETA TANA BHAGTAIN | C31: 08033211029311 | D31: UCBA0000803 | E31: 1181
A32: 200100030101 | B32: SAROJ KHAKHA | C32: 590610110010522 | D32: BKID0005906 | E32: 0
A33: 200100030105 | B33: SUKA TANA BHAGAT | C33: 08030100921195 | D33: UCBA0000803 | E33: 1926
A34: 200100030109 | B34: SOMRA BHAGAT | C34: 08030100922406 | D34: UCBA0000803 | E34: 2457
A35: 200100030112 | B35: BANDE ORAON | C35: 495910510003218 | D35: BKID0004959 | E35: 6488
A36: 200100050005 | B36: MUNEJA KHATUN | C36: 494318210006630 | D36: BKID0004943 | E36: 1230
... A191: 200100230069 | B191: CHHOTI PUJA KACHHAP | C191: 7606001700003640 | D191: PUNB0760600 | E191: 275
A192: 200100230070 | B192: 0 | C192: 0 | D192: 0 | E192: 337
B193: UPENDRA | C193: 50341671865 | D193: IDIB000R588 | E193: 6602
A194: 200100270002 | B194: Beena Kumari | C194: 9760000100053735 | D194: PUNB0976000 | E194: 35216
A195: 200100270004 | B195: Surji Devi | C195: 4895108005356 | D195: CNRB0004895 | E195: 4856
A196: 200100270018 | B196: Ramdev Mahto | C196: 22010404475 | D196: SBIN0RRVCGB | E196: 22684
A197: 200100270022 | B197: Usha Devi | C197: 4895108006665 | D197: CNRB0004895 | E197: 3670
A198: 200100270026 | B198: Bishu Oraon | C198: 22010432378 | D198: SBIN0RRVCGB | E198: 2330
A199: 200100270027 | B199: Bandhani Urain | C199: 31085333882 | D199: SBIN0012618 | E199: 1980
A200: 200100270030 | B200: Guindi Bhagat | C200: 22010415217 | D200: SBIN0RRVCGB | E200: 2658
A201: 200100270031 | B201: Buda Tigga | C201: 495910110003049 | D201: BKID0004959 | E201: 1483
A202: 200100270037 | B202: KARN KUMAR | C202: 4895108011970 | D202: CNRB0004895 | E202: 702
...

Sheet Direct Farmer Payment 
A2: Cycle | B2: ID | C2: BMC Area | D2: MPG Name | E2: Code | F2: Farmers Code | G2: No of Shift | H2: Vol_L | I2: Amount | J2: TS Loss | K2: Deduction for excess payment | L2: Milk Short | M2: CF Deduction | N2: Vet Deduction | O2: Stop Payment | P2: Net Amount | Q2: Category | R2: Farmers Account Name | S2: Accont no | T2: IFSC code | U2: Bank Name | V2: Date of Enrollment | W2: Count | X2: Account Details | Y2: Cycle | Z2: Sample
A3: 01-02 Apr | B3: 200100010002 | C3: BMC Code :2001 | D3: Itki | E3: 20010001 | F3: 0002 | G3: 4 | H3: 8801.6 | I3: 370783.15 | J3: 6564 | K3: 0 | L3: 1360.78 | M3: 0 | N3: 0 | O3: 0 | P3: 362858 | Q3: Direct | R3: AMIT KUMAR TIWARI | S3: 7125658980 | T3: IDIB000I021 | U3: Indian bank | V3: 27/03/2024 | W3: 1 | X3: Available | Y3: 01.01-02 Apr | Z3: 8.4253579
A4: 01-02 Apr | B4: 200100010005 | C4: BMC Code :2001 | D4: Itki | E4: 20010001 | F4: 0005 | G4: 2 | H4: 5.48 | I4: 213.11 | J4: 0 | K4: 0 | L4: 0 | M4: 0 | N4: 0 | O4: 0 | P4: 213 | Q4: Direct | R4: ROPANI KUMARI KERKETTA | S4: 358702010602626 | T4: UBIN0535877 | U4: UNION BANK OF INDIA | V4: 45183 | W4: 1 | X4: Available | Y4: 01.01-02 Apr | Z4: 3.8888686
A5: 01-02 Apr | B5: 200100010010 | C5: BMC Code :2001 | D5: Itki | E5: 20010001 | F5: 0010 | G5: 4 | H5: 19.04 | I5: 851.65 | J5: 0 | K5: 0 | L5: 0 | M5: 0 | N5: 0 | O5: 0 | P5: 852 | Q5: Direct | R5: SHANTI DEVI | S5: 6496430309 | T5: IDIB000I021 | U5: INDIAN BANK | V5: 45206 | W5: 1 | X5: Available | Y5: 01.01-02 Apr | Z5: 8.9459034
A6: 01-02 Apr | B6: 200100010017 | C6: BMC Code :2001 | D6: Itki | E6: 20010001 | F6: 0017 | G6: 2 | H6: 4.98 | I6: 185.94 | J6: 0 | K6: 0 | L6: 0 | M6: 0 | N6: 0 | O6: 0 | P6: 186 | Q6: Direct | R6: Bikram Gope | S6: 358702010006937 | T6: UBIN0535877 | U6: UNION BANK OF INDIA | V6: 45255 | W6: 1 | X6: Available | Y6: 01.01-02 Apr | Z6: 3.7337349
A7: 01-02 Apr | B7: 200100010019 | C7: BMC Code :2001 | D7: Itki | E7: 20010001 | F7: 0019 | G7: 3 | H7: 14.84 | I7: 588.57 | J7: 0 | K7: 0 | L7: 0 | M7: 0 | N7: 0 | O7: 0 | P7: 589 | Q7: Direct | R7: Hiramani Kachhap | S7: 494310110016645 | T7: BKID0004943 | U7: BANK OF INDIA | V7: 45262 | W7: 1 | X7: Available | Y7: 01.01-02 Apr | Z7: 5.9491577
A8: 01-02 Apr | B8: 200100010033 | C8: BMC Code :2001 | D8: Itki | E8: 20010001 | F8: 0033 | G8: 4 | H8: 7.18 | I8: 259.75 | J8: 0 | K8: 0 | L8: 0 | M8: 0 | N8: 0 | O8: 0 | P8: 260 | Q8: Direct | R8: Rahila Tirkey | S8: 22011269637 | T8: SBIN0RRVCGB | U8: STATE BANK OF INDIA | V8: 45481 | W8: 1 | X8: Available | Y8: 01.01-02 Apr | Z8: 7.235376
A9: 01-02 Apr | B9: 200100010050 | C9: BMC Code :2001 | D9: Itki | E9: 20010001 | F9: 0050 | G9: 2 | H9: 41.32 | I9: 1468.48 | J9: 0 | K9: 0 | L9: 0 | M9: 0 | N9: 0 | O9: 0 | P9: 1468 | Q9: Direct | R9: SABITA TIWARI | S9: 762901500038 | T9: ICIC0007629 | U9: ICICI BANK | V9: 45600 | W9: 1 | X9: Available | Y9: 01.01-02 Apr | Z9: 3.5539206
A10: 01-02 Apr | B10: 200100010051 | C10: BMC Code :2001 | D10: Itki | E10: 20010001 | F10: 0051 | G10: 2 | H10: 18.7 | I10: 703.83 | J10: 0 | K10: 0 | L10: 0 | M10: 0 | N10: 0 | O10: 0 | P10: 704 | Q10: Direct | R10: SAHIL RAJ | S10: 40723769931 | T10: SBIN0000081 | U10: STATE BANK OF INDIA | V10: 45600 | W10: 1 | X10: Available | Y10: 01.01-02 Apr | Z10: 3.7637968
A11: 01-02 Apr | B11: 200100010064 | C11: BMC Code :2001 | D11: Itki | E11: 20010001 | F11: 0064 | G11: 4 | H11: 52.88 | I11: 2155.61 | J11: 0 | K11: 0 | L11: 0 | M11: 0 | N11: 0 | O11: 0 | P11: 2156 | Q11: Direct | R11: SOHEL ANSARI | S11: 358702120002626 | T11: UBIN0535877 | U11: 0 | V11: 45853 | W11: 1 | X11: Available | Y11: 01.01-02 Apr | Z11: 8.1528366
A12: 01-02 Apr | B12: 200100010066 | C12: BMC Code :2001 | D12: Itki | E12: 20010001 | F12: 0066 | G12: 2 | H12: 18.7 | I12: 703.83 | J12: 0 | K12: 0 | L12: 0 | M12: 0 | N12: 0 | O12: 0 | P12: 704 | Q12: Direct | R12: SUJIT KUMAR ACHARYA | S12: 07591530000649 | T12: HDFC0000759 | U12: 0 | V12: 45881 | W12: 1 | X12: Available | Y12: 01.01-02 Apr | Z12: 3.7637968
A13: 01-02 Apr | B13: 200100010067 | C13: BMC Code :2001 | D13: Itki | E13: 20010001 | F13: 0067 | G13: 4 | H13: 19.74 | I13: 838.11 | J13: 0 | K13: 0 | L13: 0 | M13: 0 | N13: 0 | O13: 0 | P13: 838 | Q13: Direct | R13: SAJJAD ANSARI | S13: 358702010624724 | T13: UBIN0535877 | U13: 0 | V13: 45881 | W13: 1 | X13: Available | Y13: 01.01-02 Apr | Z13: 8.4914894
A14: 01-02 Apr | B14: 200100010072 | C14: BMC Code :2001 | D14: Itki | E14: 20010001 | F14: 0072 | G14: 4 | H14: 32.84 | I14: 1231.05 | J14: 0 | K14: 0 | L14: 0 | M14: 0 | N14: 0 | O14: 0 | P14: 1231 | Q14: Direct | R14: MARIYAM GORETI TIRKEY | S14: 22010734628 | T14: SBIN0RRVCGB | U14: 0 | V14: 45978 | W14: 1 | X14: Available | Y14: 01.01-02 Apr | Z14: 7.4972594
A15: 01-02 Apr | B15: 200100010073 | C15: BMC Code :2001 | D15: Itki | E15: 20010001 | F15: 0073 | G15: 4 | H15: 24.02 | I15: 909.68 | J15: 0 | K15: 0 | L15: 0 | M15: 0 | N15: 0 | O15: 0 | P15: 910 | Q15: Direct | R15: PRAVEEN TIRKEY | S15: 22010796040 | T15: SBIN0RRVCGB | U15: 0 | V15: 45978 | W15: 1 | X15: Available | Y15: 01.01-02 Apr | Z15: 7.5743547
A16: 01-02 Apr | B16: 200100010074 | C16: BMC Code :2001 | D16: Itki | E16: 20010001 | F16: 0074 | G16: 2 | H16: 3.54 | I16: 143.87 | J16: 0 | K16: 0 | L16: 0 | M16: 0 | N16: 0 | O16: 0 | P16: 144 | Q16: Direct | R16: SUKHDEV GOP | S16: 34698843331 | T16: SBIN0015346 | U16: 0 | V16: 45999 | W16: 1 | X16: Available | Y16: 01.01-02 Apr | Z16: 4.0641243
A17: 01-02 Apr | B17: 200100010077 | C17: BMC Code :2001 | D17: Itki | E17: 20010001 | F17: 0077 | G17: 2 | H17: 3.38 | I17: 126.11 | J17: 0 | K17: 0 | L17: 0 | M17: 0 | N17: 0 | O17: 0 | P17: 126 | Q17: Direct | R17: RAVINA KHATUN | S17: 358702120002654 | T17: UBIN0535877 | U17: 0 | V17: 46013 | W17: 1 | X17: Available | Y17: 01.01-02 Apr | Z17: 3.7310651
A18: 01-02 Apr | B18: 200100010080 | C18: BMC Code :2001 | D18: Itki | E18: 20010001 | F18: 0080 | G18: 2 | H18: 6.1 | I18: 266.93 | J18: 0 | K18: 0 | L18: 0 | M18: 0 | N18: 0 | O18: 0 | P18: 267 | Q18: Direct | R18: RUPAN TIGGA | S18: 358702010634588 | T18: UBIN0535877 | U18: 0 | V18: 46049 | W18: 1 | X18: Available | Y18: 01.01-02 Apr | Z18: 4.3759016
A19: 01-02 Apr | B19: 200100030003 | C19: BMC Code :2001 | D19: Bero | E19: 20010003 | F19: 0003 | G19: 4 | H19: 338.72 | I19: 12990.2 | J19: 0 | K19: 0 | L19: 0 | M19: 0 | N19: 0 | O19: 0 | P19: 12990 | Q19: Direct | R19: PINKI DEVI | S19: 4895101003786 | T19: CNRB0004895 | U19: 0 | V19: 45867 | W19: 1 | X19: Available | Y19: 01.01-02 Apr | Z19: 7.6701701
A20: 01-02 Apr | B20: 200100030013 | C20: BMC Code :2001 | D20: Bero | E20: 20010003 | F20: 0013 | G20: 2 | H20: 2.64 | I20: 104.15 | J20: 0 | K20: 0 | L20: 0 | M20: 0 | N20: 0 | O20: 0 | P20: 104 | Q20: Direct | R20: JOSEF LAKRA | S20: 495910510003202 | T20: BKID0004959 | U20: BANK OF INDIA | V20: 45213 | W20: 1 | X20: Available | Y20: 01.01-02 Apr | Z20: 3.9450758
A21: 01-02 Apr | B21: 200100030044 | C21: BMC Code :2001 | D21: Bero | E21: 20010003 | F21: 0044 | G21: 1 | H21: 4.21 | I21: 152.07 | J21: 0 | K21: 0 | L21: 0 | M21: 0 | N21: 0 | O21: 0 | P21: 152 | Q21: Direct | R21: Manju Devi | S21: 08030100922544 | T21: UCBA0000803 | U21: UCO BANK | V21: 45509 | W21: 1 | X21: Available | Y21: 01.01-02 Apr | Z21: 1.806057
A22: 01-02 Apr | B22: 200100030109 | C22: BMC Code :2001 | D22: Bero | E22: 20010003 | F22: 0109 | G22: 2 | H22: 5.62 | I22: 220.44 | J22: 0 | K22: 0 | L22: 0 | M22: 0 | N22: 0 | O22: 0 | P22: 220 | Q22: Direct | R22: SOMRA BHAGAT | S22: 08030100922406 | T22: UCBA0000803 | U22: 0 | V22: 46020 | W22: 1 | X22: Available | Y22: 01.01-02 Apr | Z22: 3.9224199
A23: 01-02 Apr | B23: 200100030112 | C23: BMC Code :2001 | D23: Bero | E23: 20010003 | F23: 0112 | G23: 2 | H23: 14.53 | I23: 536.6 | J23: 0 | K23: 0 | L23: 0 | M23: 0 | N23: 0 | O23: 0 | P23: 537 | Q23: Direct | R23: BANDE ORAON | S23: 495910510003218 | T23: BKID0004959 | U23: 0 | V23: 46062 | W23: 1 | X23: Available | Y23: 01.01-02 Apr | Z23: 3.6930489
A24: 01-02 Apr | B24: 200100050005 | C24: BMC Code :2001 | D24: Basila | E24: 20010005 | F24: 0005 | G24: 2 | H24: 3.28 | I24: 174.22 | J24: 0 | K24: 0 | L24: 0 | M24: 0 | N24: 0 | O24: 0 | P24: 174 | Q24: Direct | R24: MUNEJA KHATUN | S24: 494318210006630 | T24: BKID0004943 | U24: BANK OF INDIA | V24: 45262 | W24: 1 | X24: Available | Y24: 01.01-02 Apr | Z24: 5.3115854
A25: 01-02 Apr | B25: 200100050007 | C25: BMC Code :2001 | D25: Basila | E25: 20010005 | F25: 0007 | G25: 4 | H25: 35.31 | I25: 1363.12 | J25: 0 | K25: 0 | L25: 0 | M25: 0 | N25: 0 | O25: 0 | P25: 1363 | Q25: Direct | R25: SHAMIMA KHATOON | S25: 494310110007746 | T25: BKID0004943 | U25: BANK OF INDIA | V25: 45183 | W25: 1 | X25: Available | Y25: 01.01-02 Apr | Z25: 7.7208723
A26: 01-02 Apr | B26: 200100050008 | C26: BMC Code :2001 | D26: Basila | E26: 20010005 | F26: 0008 | G26: 4 | H26: 28.96 | I26: 1128.57 | J26: 0 | K26: 0 | L26: 0 | M26: 0 | N26: 0 | O26: 0 | P26: 1129 | Q26: Direct | R26: ANISA KHATUN | S26: 50370873265 | T26: IDIB000N518 | U26: Allahabad Bank | V26: 45206 | W26: 1 | X26: Available | Y26: 01.01-02 Apr | Z26: 7.7939917
A27: 01-02 Apr | B27: 200100050009 | C27: BMC Code :2001 | D27: Basila | E27: 20010005 | F27: 0009 | G27: 4 | H27: 30.85 | I27: 1181.95 | J27: 0 | K27: 0 | L27: 0 | M27: 0 | N27: 0 | O27: 0 | P27: 1182 | Q27: Direct | R27: RABUL ANSARI | S27: 494318210000448 | T27: BKID0004943 | U27: BANK OF INDIA | V27: 45183 | W27: 1 | X27: Available | Y27: 01.01-02 Apr | Z27: 7.6625608
A28: 01-02 Apr | B28: 200100050010 | C28: BMC Code :2001 | D28: Basila | E28: 20010005 | F28: 0010 | G28: 1 | H28: 1.35 | I28: 55.86 | J28: 0 | K28: 0 | L28: 0 | M28: 0 | N28: 0 | O28: 0 | P28: 56 | Q28: Direct | R28: SAHIDA KHATUN | S28: 494318210002593 | T28: BKID0004943 | U28: BANK OF INDIA | V28: 45199 | W28: 1 | X28: Available | Y28: 01.01-02 Apr | Z28: 2.0688889
A29: 01-02 Apr | B29: 200100050013 | C29: BMC Code :2001 | D29: Basila | E29: 20010005 | F29: 0013 | G29: 4 | H29: 10.79 | I29: 418.12 | J29: 0 | K29: 0 | L29: 0 | M29: 0 | N29: 0 | O29: 0 | P29: 418 | Q29: Direct | R29: NIKHAT PERWEEN | S29: 494318210006908 | T29: BKID0004943 | U29: BANK OF INDIA | V29: 45183 | W29: 1 | X29: Available | Y29: 01.01-02 Apr | Z29: 7.750139
A30: 01-02 Apr | B30: 200100050014 | C30: BMC Code :2001 | D30: Basila | E30: 20010005 | F30: 0014 | G30: 4 | H30: 27.49 | I30: 1175.41 | J30: 0 | K30: 0 | L30: 0 | M30: 0 | N30: 0 | O30: 0 | P30: 1175 | Q30: Direct | R30: SALIM ANSARI | S30: 494310110018804 | T30: BKID0004943 | U30: BANK OF INDIA | V30: 45183 | W30: 1 | X30: Available | Y30: 01.01-02 Apr | Z30: 8.551546
A31: 01-02 Apr | B31: 200100050015 | C31: BMC Code :2001 | D31: Basila | E31: 20010005 | F31: 0015 | G31: 4 | H31: 11.12 | I31: 433.16 | J31: 0 | K31: 0 | L31: 0 | M31: 0 | N31: 0 | O31: 0 | P31: 433 | Q31: Direct | R31: RAJAK ANSARI | S31: 494310100006470 | T31: BKID0004943 | U31: BANK OF INDIA | V31: 45183 | W31: 1 | X31: Available | Y31: 01.01-02 Apr | Z31: 7.7906475
A32: 01-02 Apr | B32: 200100050016 | C32: BMC Code :2001 | D32: Basila | E32: 20010005 | F32: 0016 | G32: 1 | H32: 2.68 | I32: 107.55 | J32: 0 | K32: 0 | L32: 0 | M32: 0 | N32: 0 | O32: 0 | P32: 108 | Q32: Direct | R32: ASIYA KHATOON | S32: 494318210006966 | T32: BKID0004943 | U32: BANK OF INDIA | V32: 45183 | W32: 1 | X32: Available | Y32: 01.01-02 Apr | Z32: 2.0065299
A33: 01-02 Apr | B33: 200100050022 | C33: BMC Code :2001 | D33: Basila | E33: 20010005 | F33: 0022 | G33: 2 | H33: 2.5 | I33: 90.42 | J33: 0 | K33: 0 | L33: 0 | M33: 0 | N33: 0 | O33: 0 | P33: 90 | Q33: Direct | R33: SHEIKH SAFIQUE | S33: 494310100000875 | T33: BKID0004943 | U33: BANK OF INDIA | V33: 45199 | W33: 1 | X33: Available | Y33: 01.01-02 Apr | Z33: 3.6168
A34: 01-02 Apr | B34: 200100050025 | C34: BMC Code :2001 | D34: Basila | E34: 20010005 | F34: 0025 | G34: 4 | H34: 18.57 | I34: 754.36 | J34: 0 | K34: 0 | L34: 0 | M34: 0 | N34: 0 | O34: 0 | P34: 754 | Q34: Direct | R34: RUKHSHANA KHATUN | S34: 7473342026 | T34: IDIB000N518 | U34: INDIAN BANK | V34: 45183 | W34: 1 | X34: Available | Y34: 01.01-02 Apr | Z34: 8.1245019
A35: 01-02 Apr | B35: 200100050029 | C35: BMC Code :2001 | D35: Basila | E35: 20010005 | F35: 0029 | G35: 4 | H35: 8.94 | I35: 338.62 | J35: 0 | K35: 0 | L35: 0 | M35: 0 | N35: 0 | O35: 0 | P35: 339 | Q35: Direct | R35: IMAM ANSARI | S35: 494318210005769 | T35: BKID0004943 | U35: BANK OF INDIA | V35: 45234 | W35: 1 | X35: Available | Y35: 01.01-02 Apr | Z35: 7.5753915
... A37: 01-02 Apr | B37: 200100050033 | C37: BMC Code :2001 | D37: Basila | E37: 20010005 | F37: 0033 | G37: 4 | H37: 15.37 | I37: 562.44 | J37: 0 | K37: 0 | L37: 0 | M37: 0 | N37: 0 | O37: 0 | P37: 562 | Q37: Direct | R37: Hamida Khatoon | S37: 39470934026 | T37: SBIN0014340 | U37: STATE BANK OF INDIA | V37: 45304 | W37: 1 | X37: Available | Y37: 01.01-02 Apr | Z37: 7.3186727
A38: 01-02 Apr | B38: 200100050036 | C38: BMC Code :2001 | D38: Basila | E38: 20010005 | F38: 0036 | G38: 2 | H38: 6.32 | I38: 247.08 | J38: 0 | K38: 0 | L38: 0 | M38: 0 | N38: 0 | O38: 0 | P38: 247 | Q38: Direct | R38: Sunita Oraon | S38: 22016761454 | T38: SBIN0RRVCGB | U38: STATE BANK OF INDIA | V38: 19/03/2024 | W38: 1 | X38: Available | Y38: 01.01-02 Apr | Z38: 3.9094937
A39: 01-02 Apr | B39: 200100050040 | C39: BMC Code :2001 | D39: Basila | E39: 20010005 | F39: 0040 | G39: 2 | H39: 3.58 | I39: 235.98 | J39: 0 | K39: 0 | L39: 0 | M39: 0 | N39: 0 | O39: 0 | P39: 236 | Q39: Direct | R39: Soniya Oraon | S39: 22016761476 | T39: SBIN0RRVCGB | U39: STATE BANK OF INDIA | V39: 45531 | W39: 1 | X39: Available | Y39: 01.01-02 Apr | Z39: 6.5916201
A40: 01-02 Apr | B40: 200100050042 | C40: BMC Code :2001 | D40: Basila | E40: 20010005 | F40: 0042 | G40: 4 | H40: 45.66 | I40: 1760.94 | J40: 0 | K40: 0 | L40: 0 | M40: 0 | N40: 0 | O40: 0 | P40: 1761 | Q40: Direct | R40: PARWEJ ANSARI | S40: 494318210003823 | T40: BKID0004943 | U40: BANK OF INDIA | V40: 45565 | W40: 1 | X40: Available | Y40: 01.01-02 Apr | Z40: 7.713272
A41: 01-02 Apr | B41: 200100050047 | C41: BMC Code :2001 | D41: Basila | E41: 20010005 | F41: 0047 | G41: 1 | H41: 1.13 | I41: 52.05 | J41: 0 | K41: 0 | L41: 0 | M41: 0 | N41: 0 | O41: 0 | P41: 52 | Q41: Direct | R41: RUBY PARWEEN | S41: 494318210005871 | T41: BKID0004943 | U41: 0 | V41: 45846 | W41: 1 | X41: Available | Y41: 01.01-02 Apr | Z41: 2.3030973
A42: 01-02 Apr | B42: 200100050048 | C42: BMC Code :2001 | D42: Basila | E42: 20010005 | F42: 0048 | G42: 2 | H42: 5.42 | I42: 252.2 | J42: 0 | K42: 0 | L42: 0 | M42: 0 | N42: 0 | O42: 0 | P42: 252 | Q42: Direct | R42: JAMIL ANSARI | S42: 494318210005828 | T42: BKID0004943 | U42: 0 | V42: 45846 | W42: 1 | X42: Available | Y42: 01.01-02 Apr | Z42: 4.6531365
...

Sheet Bank Details
B1: MPG Code | C1: Farmer Code | D1: I'D | E1: IFSC Code | F1: Bank A/C No | G1: Farmer Name | H1: Amount
B2: 20010001 | C2: 0002 | D2: =CONCATENATE(B2,C2) -> 200100010002 | E2: IDIB000I021 | F2: 7125658980 | G2: AMIT KUMAR TIWARI | H2: =VLOOKUP(B2,'Shayak Income '!$A$3:$L$141,11,0) -> #N/A
B3: 20010002 | C3: 0002 | D3: =CONCATENATE(B3,C3) -> 200100020002 | E3: PUNB0976000 | F3: 9760000100025121 | G3: Ravindra Gope | H3: =VLOOKUP(B3,'Shayak Income '!$A$3:$L$141,11,0) -> #N/A
B4: 20010003 | C4: 0002 | D4: =CONCATENATE(B4,C4) -> 200100030002 | E4: BKID0004959 | F4: 495910110002327 | G4: Ganesh Mahtha | H4: =VLOOKUP(B4,'Shayak Income '!$A$3:$L$141,11,0) -> #N/A
B5: 20010004 | C5: 0002 | D5: =CONCATENATE(B5,C5) -> 200100040002 | E5: HDFC0001470 | F5: 50100185889935 | G5: TETRI DEVI | H5: =VLOOKUP(B5,'Shayak Income '!$A$3:$L$141,11,0) -> #N/A
B6: 20010005 | C6: 0002 | D6: =CONCATENATE(B6,C6) -> 200100050002 | E6: SBIN0014340 | F6: 20421406720 | G6: SAJJAD ANSARI | H6: =VLOOKUP(B6,'Shayak Income '!$A$3:$L$141,11,0) -> #N/A
B7: 20010008 | C7: 0002 | D7: =CONCATENATE(B7,C7) -> 200100080002 | E7: SBIN0RRVCGB | F7: 84029601618 | G7: Vikash Sahu | H7: =VLOOKUP(B7,'Shayak Income '!$A$3:$L$141,11,0) -> #N/A
B8: 20010009 | C8: 0002 | D8: =CONCATENATE(B8,C8) -> 200100090002 | E8: UBIN0535877 | F8: 358702010009142 | G8: BAL KISHORE TIWARI | H8: =VLOOKUP(B8,'Shayak Income '!$A$3:$L$141,11,0) -> #N/A
B9: 20010012 | C9: 0002 | D9: =CONCATENATE(B9,C9) -> 200100120002 | E9: BKID0004943 | F9: 494320110000192 | G9: NASIM ANSARI | H9: =VLOOKUP(B9,'Shayak Income '!$A$3:$L$141,11,0) -> #N/A
B10: 20010013 | C10: 0002 | D10: =CONCATENATE(B10,C10) -> 200100130002 | E10: IDIB000I021 | F10: 621880295 | G10: Aftab Ansari | H10: =VLOOKUP(B10,'Shayak Income '!$A$3:$L$141,11,0) -> #N/A
B11: 20010015 | C11: 0002 | D11: =CONCATENATE(B11,C11) -> 200100150002 | E11: IDIB000I021 | F11: 7172200582 | G11: Tahir Ansari | H11: =VLOOKUP(B11,'Shayak Income '!$A$3:$L$141,11,0) -> #N/A
B12: 20010016 | C12: 0002 | D12: =CONCATENATE(B12,C12) -> 200100160002 | E12: BKID0004959 | F12: 495918210002785 | G12: Sanju Devi | H12: =VLOOKUP(B12,'Shayak Income '!$A$3:$L$141,11,0) -> #N/A
B13: 20010017 | C13: 0002 | D13: =CONCATENATE(B13,C13) -> 200100170002 | E13: PUNB0976000 | F13: 9760000100022416 | G13: Suhail Hussain | H13: =VLOOKUP(B13,'Shayak Income '!$A$3:$L$141,11,0) -> #N/A
... B67: 20020014 | C67: 0002 | D67: =CONCATENATE(B67,C67) -> 200200140002 | E67: CNRB0004904 | F67: 4904101003080 | G67: MAGAN MAHTO | H67: =VLOOKUP(B67,'Shayak Income '!$A$3:$L$141,11,0) -> #N/A
H68: =SUM(H2:H67) -> #N/A | I68: =H68-'Shayak Income '!L142 -> #N/A
