Workbook
Name Account_Details: '[1]Farmer Payment Calc'!$V$2:$V$1048576
Name Amount: '[1]Farmer Payment Calc'!$I$2:$I$1048576
Name CF_Recovery: '[1]Farmer Payment Calc'!$M$2:$M$1048576
Name Code: '[1]Farmer Payment Calc'!$E$2:$E$1048576
Name Net_Amount: '[1]Farmer Payment Calc'!$P$2:$P$1048576
Name Other_Ded: '[1]Farmer Payment Calc'!$J$2:$J$1048576
Name Sample_Milk: '[1]Farmer Payment Calc'!$K$2:$K$1048576
Name Vol_L: '[1]Farmer Payment Calc'!$H$2:$H$1048576

Sheet Sheet2
A3: Sum of Final Amount
A4: Type | B4: MPG Code | C4: Farmer code | D4: Total | G4: Id | H4: Type | I4: MPG Code | J4: Farmer code | K4: Total | L4: Deduction | P4: Type | Q4: MPG Code | R4: Farmer code | S4: Total | T4: Deduction
A5: Direct | B5: 10020027 | C5: 0002 | D5: 3835.3 | G5: =CONCATENATE(I5,J5) -> 100200270002 | H5: Direct | I5: 10020027 | J5: 0002 | K5: 3835.3 | L5: 3835.3 | P5: Indirect | Q5: 10030069 | R5: 0002 | S5: 0.5 | T5: 0.5
A6: Direct | B6: 10060027 | C6: 0012 | D6: 309.75 | G6: =CONCATENATE(I6,J6) -> 100600270012 | H6: Direct | I6: 10060027 | J6: 0012 | K6: 309.75 | L6: 212 | P6: Indirect | Q6: 10110008 | R6: 0002 | S6: 144000 | T6: 144000
A7: Direct | B7: 10060027 | C7: 0080 | D7: 360 | G7: =CONCATENATE(I7,J7) -> 100600270080 | H7: Direct | I7: 10060027 | J7: 0080 | K7: 360 | L7: 360 | P7: Indirect | Q7: 10110153 | R7: 0002 | S7: 1350 | T7: 1350
A8: Direct | B8: 10060027 | C8: 0150 | D8: 500.25 | G8: =CONCATENATE(I8,J8) -> 100600270150 | H8: Direct | I8: 10060027 | J8: 0150 | K8: 500.25 | L8: 500.25 | P8: Indirect | Q8: 10110161 | R8: 0002 | S8: 1350 | T8: 1350
A9: Direct | B9: 10060027 | C9: 0282 | D9: 3600 | G9: =CONCATENATE(I9,J9) -> 100600270282 | H9: Direct | I9: 10060027 | J9: 0282 | K9: 3600 | L9: 3600 | P9: Indirect | Q9: 10110183 | R9: 0002 | S9: 1350 | T9: 1350
A10: Direct | B10: 10060027 | C10: 0294 | D10: 885 | G10: =CONCATENATE(I10,J10) -> 100600270294 | H10: Direct | I10: 10060027 | J10: 0294 | K10: 885 | L10: 749 | P10: Indirect | Q10: 10120010 | R10: 0002 | S10: 2800 | T10: 2800
A11: Direct | B11: 10060027 | C11: 0306 | D11: 346.5 | G11: =CONCATENATE(I11,J11) -> 100600270306 | H11: Direct | I11: 10060027 | J11: 0306 | K11: 346.5 | L11: 346.5 | P11: Indirect | Q11: 10120011 | R11: 0002 | S11: 4650 | T11: 4650
A12: Direct | B12: 10060069 | C12: 0009 | D12: 2700 | G12: =CONCATENATE(I12,J12) -> 100600690009 | H12: Direct | I12: 10060069 | J12: 0009 | K12: 2700 | L12: 2700 | P12: Indirect | Q12: 10120013 | R12: 0002 | S12: 2800 | T12: 2800
A13: Direct | B13: 10060090 | C13: 0018 | D13: 2700 | G13: =CONCATENATE(I13,J13) -> 100600900018 | H13: Direct | I13: 10060090 | J13: 0018 | K13: 2700 | L13: 2700 | P13: Indirect | Q13: 10120022 | R13: 0002 | S13: 640 | T13: 640
A14: Direct | B14: 10110001 | C14: 0002 | D14: 2700 | G14: =CONCATENATE(I14,J14) -> 101100010002 | H14: Direct | I14: 10110001 | J14: 0002 | K14: 2700 | L14: 2700 | P14: Indirect | Q14: 10120049 | R14: 0002 | S14: 3100 | T14: 3100
A15: Direct | B15: 10110021 | C15: 0030 | D15: 2700 | G15: =CONCATENATE(I15,J15) -> 101100210030 | H15: Direct | I15: 10110021 | J15: 0030 | K15: 2700 | L15: 2700 | P15: Indirect | Q15: 10130005 | R15: 0002 | S15: 1400 | T15: 1400
A16: Direct | B16: 10110076 | C16: 0004 | D16: 9100 | G16: =CONCATENATE(I16,J16) -> 101100760004 | H16: Direct | I16: 10110076 | J16: 0004 | K16: 9100 | L16: 9100 | P16: Indirect | Q16: 10130018 | R16: 0002 | S16: 1400 | T16: 1400
... A25: Direct | B25: 10120007 | C25: 0014 | D25: 588 | G25: =CONCATENATE(I25,J25) -> 101200070014 | H25: Direct | I25: 10120007 | J25: 0014 | K25: 588 | L25: 588 | P25: Indirect | Q25: 10660010 | R25: 0010 | S25: 1001 | T25: 1001
A26: Direct | B26: 10120007 | C26: 0038 | D26: 1400 | G26: =CONCATENATE(I26,J26) -> 101200070038 | H26: Direct | I26: 10120007 | J26: 0038 | K26: 1400 | L26: 1400 | P26: Indirect Total | S26: 203223.5 | T26: =SUM(T5:T25) -> 203223.5
A27: Direct | B27: 10120007 | C27: 0079 | D27: 347 | G27: =CONCATENATE(I27,J27) -> 101200070079 | H27: Direct | I27: 10120007 | J27: 0079 | K27: 347 | L27: 347
A28: Direct | B28: 10120007 | C28: 0105 | D28: 1400 | G28: =CONCATENATE(I28,J28) -> 101200070105 | H28: Direct | I28: 10120007 | J28: 0105 | K28: 1400 | L28: 1400
A29: Direct | B29: 10120007 | C29: 0107 | D29: 1400 | G29: =CONCATENATE(I29,J29) -> 101200070107 | H29: Direct | I29: 10120007 | J29: 0107 | K29: 1400 | L29: 1400
A30: Direct | B30: 10120007 | C30: 0127 | D30: 1400 | G30: =CONCATENATE(I30,J30) -> 101200070127 | H30: Direct | I30: 10120007 | J30: 0127 | K30: 1400 | L30: 1166
A31: Direct | B31: 10120007 | C31: 0149 | D31: 1400 | G31: =CONCATENATE(I31,J31) -> 101200070149 | H31: Direct | I31: 10120007 | J31: 0149 | K31: 1400 | L31: 1305
A32: Direct | B32: 10120017 | C32: 0002 | D32: 9148 | G32: =CONCATENATE(I32,J32) -> 101200170002 | H32: Direct | I32: 10120017 | J32: 0002 | K32: 9148 | L32: 9148
A33: Direct | B33: 10120031 | C33: 0002 | D33: 2800 | G33: =CONCATENATE(I33,J33) -> 101200310002 | H33: Direct | I33: 10120031 | J33: 0002 | K33: 2800 | L33: 2800
A34: Direct | B34: 10120034 | C34: 0002 | D34: 4200 | G34: =CONCATENATE(I34,J34) -> 101200340002 | H34: Direct | I34: 10120034 | J34: 0002 | K34: 4200 | L34: 1483
A35: Direct | B35: 10120052 | C35: 0002 | D35: 2800 | G35: =CONCATENATE(I35,J35) -> 101200520002 | H35: Direct | I35: 10120052 | J35: 0002 | K35: 2800 | L35: 2800
A36: Direct | B36: 10120089 | C36: 0002 | D36: 1400 | G36: =CONCATENATE(I36,J36) -> 101200890002 | H36: Direct | I36: 10120089 | J36: 0002 | K36: 1400 | L36: 1400
A37: Direct | B37: 10120094 | C37: 0002 | D37: 7000 | G37: =CONCATENATE(I37,J37) -> 101200940002 | H37: Direct | I37: 10120094 | J37: 0002 | K37: 7000 | L37: 5077
A38: Direct | B38: 10120104 | C38: 0002 | D38: 1400 | G38: =CONCATENATE(I38,J38) -> 101201040002 | H38: Direct | I38: 10120104 | J38: 0002 | K38: 1400 | L38: 1400
... A157: Direct | B157: 10660028 | C157: 0002 | D157: 2590 | G157: =CONCATENATE(I157,J157) -> 106600280002 | H157: Direct | I157: 10660028 | J157: 0002 | K157: 2590 | L157: 2590
A158: Direct Total | D158: 342671.09 | G158: Direct Total | K158: 342671.09 | L158: =SUM(L5:L157) -> 293456.8
A159: Indirect | B159: 10030069 | C159: 0002 | D159: 0.5
A160: Indirect | B160: 10110008 | C160: 0002 | D160: 144000
A161: Indirect | B161: 10110153 | C161: 0002 | D161: 1350
A162: Indirect | B162: 10110161 | C162: 0002 | D162: 1350
A163: Indirect | B163: 10110183 | C163: 0002 | D163: 1350
A164: Indirect | B164: 10120010 | C164: 0002 | D164: 2800
A165: Indirect | B165: 10120011 | C165: 0002 | D165: 4650
A166: Indirect | B166: 10120013 | C166: 0002 | D166: 2800
A167: Indirect | B167: 10120022 | C167: 0002 | D167: 640
A168: Indirect | B168: 10120049 | C168: 0002 | D168: 3100
...

Sheet Indent
A1: Timestamp | B1: User Name | C1: Order Date | D1: Deduction Cycle | E1: Item Name | F1: ID | G1: MPG Code | H1: Type | I1: MPG Name | J1: Farmer code | K1: BMC Name | L1: CSP | M1: Qty | N1: Rate | O1: Total Amount | P1: Other Due Amt | Q1: Total Amount (Proposed) | R1: Final Qty | S1: Final Amount | T1: Milk Amonnt | U1: Deduction | V1: Remarks
A2: 46235.45 | B2: Bittu kumar | C2: 46235 | D2: 31-07-2026 to 06-08-2026 | E2: Gold 50 Kg | F2: =CONCATENATE(Table7[[#This Row],[MPG Code]],Table7[[#This Row],[Farmer code]]) -> 101100760004 | G2: 10110076 | H2: Direct | I2: GOMUKH SRINAGAR | J2: 0004 | K2: Sahibpur Kamal | L2: Daya Society | M2: 7 | N2: 1300 | O2: 9100 | P2: 0 | Q2: 9100 | R2: 7 | S2: 9100 | U2: 9100
A3: 46235.45 | B3: Bittu kumar | C3: 46235 | D3: 31-07-2026 to 06-08-2026 | E3: Gold 50 Kg | F3: =CONCATENATE(Table7[[#This Row],[MPG Code]],Table7[[#This Row],[Farmer code]]) -> 101100760008 | G3: 10110076 | H3: Direct | I3: GOMUKH SRINAGAR | J3: 0008 | K3: Sahibpur Kamal | L3: Daya Society | M3: 8 | N3: 1300 | O3: 10400 | P3: 0 | Q3: 10400 | R3: 8 | S3: 10400 | U3: 10400 | V3: all code se | X3: =Table7[[#This Row],[Final Amount]]-Table7[[#This Row],[Deduction]] -> 0
A4: 46235.453 | B4: Bittu kumar | C4: 46235 | D4: 31-07-2026 to 06-08-2026 | E4: Gold 50 Kg | F4: =CONCATENATE(Table7[[#This Row],[MPG Code]],Table7[[#This Row],[Farmer code]]) -> 101100860002 | G4: 10110086 | H4: Direct | I4: Gomukh Durgapur | J4: 0002 | K4: Sahibpur Kamal | L4: Daya Society | M4: 9 | N4: 1350 | O4: 12150 | P4: 0 | Q4: 12150 | R4: 9 | S4: 12150 | U4: 8637 | V4: all code se | X4: =Table7[[#This Row],[Final Amount]]-Table7[[#This Row],[Deduction]] -> 3513
A5: 46236.395 | B5: Saroj kumar | C5: 46236 | D5: 31-07-2026 to 06-08-2026 | E5: Gold 50 Kg | F5: =CONCATENATE(Table7[[#This Row],[MPG Code]],Table7[[#This Row],[Farmer code]]) -> 106100180018 | G5: 10610018 | H5: Direct | I5: GOMUKH SUPOLTARIYA | J5: 0018 | K5: Mahua BMC | L5: Daya Society | M5: 0 | N5: 1376 | O5: 0 | P5: 1376 | Q5: 1376 | R5: 0 | S5: 1376 | U5: 1319
A6: 46237.994 | B6: Saroj kumar | C6: 46237 | D6: 31-07-2026 to 06-08-2026 | E6: Gold 50 Kg | F6: =CONCATENATE(Table7[[#This Row],[MPG Code]],Table7[[#This Row],[Farmer code]]) -> 106100090079 | G6: 10610009 | H6: Direct | I6: GOMUKH Khanpatti | J6: 0079 | K6: Mahua BMC | L6: Daya Society | M6: 0 | N6: 1400 | O6: 0 | P6: 0 | Q6: 0 | R6: 0 | S6: 0 | U6: 0
A7: 46239.492 | B7: Bittu kumar | C7: 46239 | D7: 31-07-2026 to 06-08-2026 | E7: Gold 50 Kg | F7: =CONCATENATE(Table7[[#This Row],[MPG Code]],Table7[[#This Row],[Farmer code]]) -> 104300010002 | G7: 10430001 | H7: Direct | I7: Gomukh Bariyarpur | J7: 0002 | K7: Sahibpur Kamal | L7: Daya Society | M7: 1 | N7: 1350 | O7: 1350 | P7: 0 | Q7: 1350 | R7: 1 | S7: 1350 | U7: 0
A8: 46239.493 | B8: Bittu kumar | C8: 46239 | D8: 31-07-2026 to 06-08-2026 | E8: Gold 50 Kg | F8: =CONCATENATE(Table7[[#This Row],[MPG Code]],Table7[[#This Row],[Farmer code]]) -> 101101680002 | G8: 10110168 | H8: Direct | I8: GOMUKH BARBIGHI | J8: 0002 | K8: Sahibpur Kamal | L8: Daya Society | M8: 8 | N8: 1350 | O8: 10800 | P8: 0 | Q8: 10800 | R8: 8 | S8: 10800 | U8: 10800 | V8: 2 all code se | X8: =Table7[[#This Row],[Final Amount]]-Table7[[#This Row],[Deduction]] -> 0
A9: 46239.493 | B9: Bittu kumar | C9: 46239 | D9: 31-07-2026 to 06-08-2026 | E9: Gold 50 Kg | F9: =CONCATENATE(Table7[[#This Row],[MPG Code]],Table7[[#This Row],[Farmer code]]) -> 101100210030 | G9: 10110021 | H9: Direct | I9: GOMUKH Mathar | J9: 0030 | K9: Sahibpur Kamal | L9: Daya Society | M9: 2 | N9: 1350 | O9: 2700 | P9: 0 | Q9: 2700 | R9: 2 | S9: 2700 | U9: 2700
A10: 46240.385 | B10: Kunal Kumar | C10: 46240 | D10: 31-07-2026 to 06-08-2026 | E10: Gold 50 Kg | F10: =CONCATENATE(Table7[[#This Row],[MPG Code]],Table7[[#This Row],[Farmer code]]) -> 105900120002 | G10: 10590012 | H10: Direct | I10: LAKHAPUR | J10: 0002 | K10: Gopalpur Bmc | L10: Daya Society | M10: 1 | N10: 1350 | O10: =Table7[[#This Row],[Rate]]*Table7[[#This Row],[Qty]] -> 1350 | P10: 0 | Q10: =Table7[[#This Row],[Rate]]*Table7[[#This Row],[Qty]] -> 1350 | R10: 1 | S10: =Table7[[#This Row],[Rate]]*Table7[[#This Row],[Qty]] -> 1350 | U10: 1350
A11: 46240.386 | B11: Kunal Kumar | C11: 46240 | D11: 31-07-2026 to 06-08-2026 | E11: Gold 50 Kg | F11: =CONCATENATE(Table7[[#This Row],[MPG Code]],Table7[[#This Row],[Farmer code]]) -> 105900040009 | G11: 10590004 | H11: Direct | I11: PRATAPUR | J11: 0009 | K11: Gopalpur Bmc | L11: Daya Society | M11: 5 | N11: 1350 | O11: =Table7[[#This Row],[Rate]]*Table7[[#This Row],[Qty]] -> 6750 | P11: 0 | Q11: =Table7[[#This Row],[Rate]]*Table7[[#This Row],[Qty]] -> 6750 | R11: 5 | S11: =Table7[[#This Row],[Rate]]*Table7[[#This Row],[Qty]] -> 6750 | U11: 6750
A12: 46240.387 | B12: Kunal Kumar | C12: 46240 | D12: 31-07-2026 to 06-08-2026 | E12: Gold 50 Kg | F12: =CONCATENATE(Table7[[#This Row],[MPG Code]],Table7[[#This Row],[Farmer code]]) -> 105900010002 | G12: 10590001 | H12: Direct | I12: MISHRBIGHA | J12: 0002 | K12: Gopalpur Bmc | L12: Daya Society | M12: 3 | N12: 1350 | O12: =Table7[[#This Row],[Rate]]*Table7[[#This Row],[Qty]] -> 4050 | P12: 0 | Q12: =Table7[[#This Row],[Rate]]*Table7[[#This Row],[Qty]] -> 4050 | R12: 3 | S12: =Table7[[#This Row],[Rate]]*Table7[[#This Row],[Qty]] -> 4050 | U12: 4050
A13: 46240.388 | B13: Kunal Kumar | C13: 46240 | D13: 31-07-2026 to 06-08-2026 | E13: Gold 50 Kg | F13: =CONCATENATE(Table7[[#This Row],[MPG Code]],Table7[[#This Row],[Farmer code]]) -> 100600690009 | G13: 10060069 | H13: Direct | I13: BHANDAR | J13: 0009 | K13: Gopalpur Bmc | L13: Daya Society | M13: 2 | N13: 1350 | O13: =Table7[[#This Row],[Rate]]*Table7[[#This Row],[Qty]] -> 2700 | P13: 0 | Q13: =Table7[[#This Row],[Rate]]*Table7[[#This Row],[Qty]] -> 2700 | R13: 2 | S13: =Table7[[#This Row],[Rate]]*Table7[[#This Row],[Qty]] -> 2700 | U13: 2700
A14: 46240.389 | B14: Kunal Kumar | C14: 46240 | D14: 31-07-2026 to 06-08-2026 | E14: Gold 50 Kg | F14: =CONCATENATE(Table7[[#This Row],[MPG Code]],Table7[[#This Row],[Farmer code]]) -> 100600900018 | G14: 10060090 | H14: Direct | I14: SANGRAMPUR | J14: 0018 | K14: Gopalpur Bmc | L14: Daya Society | M14: 2 | N14: 1350 | O14: =Table7[[#This Row],[Rate]]*Table7[[#This Row],[Qty]] -> 2700 | P14: 0 | Q14: =Table7[[#This Row],[Rate]]*Table7[[#This Row],[Qty]] -> 2700 | R14: 2 | S14: =Table7[[#This Row],[Rate]]*Table7[[#This Row],[Qty]] -> 2700 | U14: 2700
A15: 46240.389 | B15: Kunal Kumar | C15: 46240 | D15: 31-07-2026 to 06-08-2026 | E15: Gold 50 Kg | F15: =CONCATENATE(Table7[[#This Row],[MPG Code]],Table7[[#This Row],[Farmer code]]) -> 105900090002 | G15: 10590009 | H15: Direct | I15: LAKHANPUR | J15: 0002 | K15: Gopalpur Bmc | L15: Daya Society | M15: 2 | N15: 1350 | O15: =Table7[[#This Row],[Rate]]*Table7[[#This Row],[Qty]] -> 2700 | P15: 0 | Q15: =Table7[[#This Row],[Rate]]*Table7[[#This Row],[Qty]] -> 2700 | R15: 2 | S15: =Table7[[#This Row],[Rate]]*Table7[[#This Row],[Qty]] -> 2700 | U15: 2700
A16: 46240.39 | B16: Kunal Kumar | C16: 46240 | D16: 31-07-2026 to 06-08-2026 | E16: Gold 50 Kg | F16: =CONCATENATE(Table7[[#This Row],[MPG Code]],Table7[[#This Row],[Farmer code]]) -> 105900130002 | G16: 10590013 | H16: Direct | I16: BARIYARPUR | J16: 0002 | K16: Gopalpur Bmc | L16: Daya Society | M16: 1 | N16: 1350 | O16: =Table7[[#This Row],[Rate]]*Table7[[#This Row],[Qty]] -> 1350 | P16: 0 | Q16: =Table7[[#This Row],[Rate]]*Table7[[#This Row],[Qty]] -> 1350 | R16: 1 | S16: =Table7[[#This Row],[Rate]]*Table7[[#This Row],[Qty]] -> 1350 | U16: 1350
A17: 46240.433 | B17: Saroj kumar | C17: 46240 | D17: 31-07-2026 to 06-08-2026 | E17: Buff Spl 50 Kg | F17: =CONCATENATE(Table7[[#This Row],[MPG Code]],Table7[[#This Row],[Farmer code]]) -> 106100050002 | G17: 10610005 | H17: Direct | I17: Gomukh Paharpur | J17: 0002 | K17: Mahua BMC | L17: Daya Society | M17: 2 | N17: 1550 | O17: 3100 | P17: 0 | Q17: 3100 | R17: 2 | S17: 3100 | U17: 3100
A18: 46240.482 | B18: Saroj kumar | C18: 46240 | D18: 31-07-2026 to 06-08-2026 | E18: Gold 50 Kg | F18: =CONCATENATE(Table7[[#This Row],[MPG Code]],Table7[[#This Row],[Farmer code]]) -> 106100180002 | G18: 10610018 | H18: Direct | I18: GOMUKH SUPOLTARIYA | J18: 0002 | K18: Mahua BMC | L18: Daya Society | M18: 4 | N18: 1400 | O18: 5600 | P18: 0 | Q18: 5600 | R18: 4 | S18: 5600 | U18: 5600
A19: 46240.482 | B19: Saroj kumar | C19: 46240 | D19: 31-07-2026 to 06-08-2026 | E19: Gold 50 Kg | F19: =CONCATENATE(Table7[[#This Row],[MPG Code]],Table7[[#This Row],[Farmer code]]) -> 106100180006 | G19: 10610018 | H19: Direct | I19: GOMUKH SUPOLTARIYA | J19: 0006 | K19: Mahua BMC | L19: Daya Society | M19: 1 | N19: 1400 | O19: 1400 | P19: 0 | Q19: 1400 | R19: 1 | S19: 1400 | U19: 1238
A20: 46241.562 | B20: Mithun Kumar | C20: 46241 | D20: 31-07-2026 to 06-08-2026 | E20: Gold 50 Kg | F20: =CONCATENATE(Table7[[#This Row],[MPG Code]],Table7[[#This Row],[Farmer code]]) -> 101200520002 | G20: 10120052 | H20: Direct | I20: Mordiba | J20: 0002 | K20: DalsinghSarai | L20: Daya Society | M20: 2 | N20: 1400 | O20: 2800 | P20: 0 | Q20: 2800 | R20: 2 | S20: 2800 | U20: 2800 | V20: 2 and unregistered farmer code | X20: =Table7[[#This Row],[Final Amount]]-Table7[[#This Row],[Deduction]] -> 0
A21: 46241.563 | B21: Mithun Kumar | C21: 46241 | D21: 31-07-2026 to 06-08-2026 | E21: Gold 50 Kg | F21: =CONCATENATE(Table7[[#This Row],[MPG Code]],Table7[[#This Row],[Farmer code]]) -> 101200310002 | G21: 10120031 | H21: Direct | I21: DESUA | J21: 0002 | K21: DalsinghSarai | L21: Daya Society | M21: 2 | N21: 1400 | O21: 2800 | P21: 0 | Q21: 2800 | R21: 2 | S21: 2800 | U21: 2800 | V21: 2 and unregistered farmer code | X21: =Table7[[#This Row],[Final Amount]]-Table7[[#This Row],[Deduction]] -> 0
A22: 46241.564 | B22: Mithun Kumar | C22: 46241 | D22: 31-07-2026 to 06-08-2026 | E22: Gold 50 Kg | F22: =CONCATENATE(Table7[[#This Row],[MPG Code]],Table7[[#This Row],[Farmer code]]) -> 101200890002 | G22: 10120089 | H22: Direct | I22: Gomukh Jhaura Tabhka | J22: 0002 | K22: DalsinghSarai | L22: Daya Society | M22: 1 | N22: 1400 | O22: 1400 | P22: 0 | Q22: 1400 | R22: 1 | S22: 1400 | U22: 1400
A23: 46241.564 | B23: Mithun Kumar | C23: 46241 | D23: 31-07-2026 to 06-08-2026 | E23: Gold 50 Kg | F23: =CONCATENATE(Table7[[#This Row],[MPG Code]],Table7[[#This Row],[Farmer code]]) -> 101201040002 | G23: 10120104 | H23: Direct | I23: Gomukh Mordiwa East | J23: 0002 | K23: DalsinghSarai | L23: Daya Society | M23: 1 | N23: 1400 | O23: 1400 | P23: 0 | Q23: 1400 | R23: 1 | S23: 1400 | U23: 1400
A24: 46241.948 | B24: Mukesh kumar | C24: 46241 | D24: 31-07-2026 to 06-08-2026 | E24: Gold 50 Kg | F24: =CONCATENATE(Table7[[#This Row],[MPG Code]],Table7[[#This Row],[Farmer code]]) -> 101101240009 | G24: 10110124 | H24: Direct | I24: GOMUKH ASHRAPHA DIYARA | J24: 0009 | K24: Matihani | L24: Daya Society | M24: 1 | N24: 1400 | O24: 1400 | P24: 0 | Q24: 1400 | R24: 1 | S24: 1400 | U24: 1400
A25: 46241.949 | B25: Mukesh kumar | C25: 46241 | D25: 31-07-2026 to 06-08-2026 | E25: Gold 50 Kg | F25: =CONCATENATE(Table7[[#This Row],[MPG Code]],Table7[[#This Row],[Farmer code]]) -> 101100010002 | G25: 10110001 | H25: Direct | I25: Gomukh Mahendrapur | J25: 0002 | K25: Matihani | L25: Daya Society | M25: 2 | N25: 1350 | O25: 2700 | P25: 0 | Q25: 2700 | R25: 2 | S25: 2700 | U25: 2700
A26: 46242.283 | B26: RAMJEEVAN SHANDILYA | C26: 46242 | D26: 31-07-2026 to 06-08-2026 | E26: Buff Spl 50 Kg | F26: =CONCATENATE(Table7[[#This Row],[MPG Code]],Table7[[#This Row],[Farmer code]]) -> 105301030006 | G26: 10530103 | H26: Direct | I26: GOMUKH JHAHURI | J26: 0006 | K26: Kalyanpur | L26: Daya Society | M26: 1 | N26: 1550 | O26: 1550 | P26: 0 | Q26: 1550 | R26: 1 | S26: 1550 | U26: 1550
A27: 46242.283 | B27: RAMJEEVAN SHANDILYA | C27: 46242 | D27: 31-07-2026 to 06-08-2026 | E27: Buff Spl 50 Kg | F27: =CONCATENATE(Table7[[#This Row],[MPG Code]],Table7[[#This Row],[Farmer code]]) -> 105301030030 | G27: 10530103 | H27: Direct | I27: GOMUKH JHAHURI | J27: 0030 | K27: Kalyanpur | L27: Daya Society | M27: 2 | N27: 1550 | O27: 3100 | P27: 0 | Q27: 3100 | R27: 2 | S27: 3100 | U27: 3100
A28: 46242.284 | B28: RAMJEEVAN SHANDILYA | C28: 46242 | D28: 31-07-2026 to 06-08-2026 | E28: Buff Spl 50 Kg | F28: =CONCATENATE(Table7[[#This Row],[MPG Code]],Table7[[#This Row],[Farmer code]]) -> 105301030002 | G28: 10530103 | H28: Direct | I28: GOMUKH JHAHURI | J28: 0002 | K28: Kalyanpur | L28: Daya Society | M28: 4 | N28: 1550 | O28: 6200 | P28: 0 | Q28: 6200 | R28: 4 | S28: 6200 | U28: 6200
A29: 46242.284 | B29: RAMJEEVAN SHANDILYA | C29: 46242 | D29: 31-07-2026 to 06-08-2026 | E29: Buff Spl 50 Kg | F29: =CONCATENATE(Table7[[#This Row],[MPG Code]],Table7[[#This Row],[Farmer code]]) -> 105301030004 | G29: 10530103 | H29: Direct | I29: GOMUKH JHAHURI | J29: 0004 | K29: Kalyanpur | L29: Daya Society | M29: 3 | N29: 1550 | O29: 4650 | P29: 0 | Q29: 4650 | R29: 3 | S29: 4650 | U29: 4650
A30: 46242.284 | B30: RAMJEEVAN SHANDILYA | C30: 46242 | D30: 31-07-2026 to 06-08-2026 | E30: Buff Spl 50 Kg | F30: =CONCATENATE(Table7[[#This Row],[MPG Code]],Table7[[#This Row],[Farmer code]]) -> 105300760038 | G30: 10530076 | H30: Direct | I30: GOMUKH Madanpur W-3 | J30: 0038 | K30: Kalyanpur | L30: Daya Society | M30: 1 | N30: 1550 | O30: 1550 | P30: 0 | Q30: 1550 | R30: 1 | S30: 1550 | U30: 1550
A31: 46242.285 | B31: RAMJEEVAN SHANDILYA | C31: 46242 | D31: 31-07-2026 to 06-08-2026 | E31: Buff Spl 50 Kg | F31: =CONCATENATE(Table7[[#This Row],[MPG Code]],Table7[[#This Row],[Farmer code]]) -> 105300760003 | G31: 10530076 | H31: Direct | I31: GOMUKH Madanpur W-3 | J31: 0003 | K31: Kalyanpur | L31: Daya Society | M31: 1 | N31: 1550 | O31: 1550 | P31: 0 | Q31: 1550 | R31: 1 | S31: 1550 | U31: 1550
A32: 46242.285 | B32: RAMJEEVAN SHANDILYA | C32: 46242 | D32: 31-07-2026 to 06-08-2026 | E32: Bestmin Gold 6 KG | F32: =CONCATENATE(Table7[[#This Row],[MPG Code]],Table7[[#This Row],[Farmer code]]) -> 105300760002 | G32: 10530076 | H32: Direct | I32: GOMUKH Madanpur W-3 | J32: 0002 | K32: Kalyanpur | L32: Daya Society | M32: 1 | N32: 1238 | O32: 1238 | P32: 0 | Q32: 1238 | R32: 1 | S32: 1238 | U32: 1238
A33: 46242.286 | B33: RAMJEEVAN SHANDILYA | C33: 46242 | D33: 31-07-2026 to 06-08-2026 | E33: Bestmin Gold 6 KG | F33: =CONCATENATE(Table7[[#This Row],[MPG Code]],Table7[[#This Row],[Farmer code]]) -> 105300760023 | G33: 10530076 | H33: Direct | I33: GOMUKH Madanpur W-3 | J33: 0023 | K33: Kalyanpur | L33: Daya Society | M33: 1 | N33: 1238 | O33: 1238 | P33: 0 | Q33: 1238 | R33: 1 | S33: 1238 | U33: 1238
... A49: 46242.299 | B49: RAMJEEVAN SHANDILYA | C49: 46242 | D49: 31-07-2026 to 06-08-2026 | E49: Liveferol 500 ml | F49: =CONCATENATE(Table7[[#This Row],[MPG Code]],Table7[[#This Row],[Farmer code]]) -> 105300350097 | G49: 10530035 | H49: Direct | I49: Gomukh Birauli Khurd | J49: 0097 | K49: Kalyanpur | L49: Daya Society | M49: 1 | N49: 165 | O49: 165 | P49: 0 | Q49: 165 | R49: 1 | S49: 165 | U49: 0
A50: 46242.301 | B50: ANSHU KUMAR | C50: 46242 | D50: 31-07-2026 to 06-08-2026 | E50: Gold 50 Kg | F50: =CONCATENATE(Table7[[#This Row],[MPG Code]],Table7[[#This Row],[Farmer code]]) -> 101201220002 | G50: 10120122 | H50: Direct | I50: GOMUKH BHASINGPUR | J50: 0002 | K50: DalsinghSarai | L50: Daya Society | M50: 0 | N50: 1400 | O50: 0 | P50: 6892 | Q50: 6892 | R50: 0 | S50: 6892 | U50: 6892 | V50: (oll coood 💯%Dedection | X50: =Table7[[#This Row],[Final Amount]]-Table7[[#This Row],[Deduction]] -> 0
A51: 46242.303 | B51: ANSHU KUMAR | C51: 46242 | D51: 31-07-2026 to 06-08-2026 | E51: Gold 50 Kg | F51: =CONCATENATE(Table7[[#This Row],[MPG Code]],Table7[[#This Row],[Farmer code]]) -> 101201220002 | G51: 10120122 | H51: Direct | I51: GOMUKH BHASINGPUR | J51: 0002 | K51: DalsinghSarai | L51: Daya Society | M51: 3 | N51: 1400 | O51: 4200 | P51: 0 | Q51: 4200 | R51: 3 | S51: 4200 | U51: 4200 | V51: 0002(oll cood) | X51: =Table7[[#This Row],[Final Amount]]-Table7[[#This Row],[Deduction]] -> 0
A52: 46242.303 | B52: ANSHU KUMAR | C52: 46242 | D52: 31-07-2026 to 06-08-2026 | E52: Gold 50 Kg | F52: =CONCATENATE(Table7[[#This Row],[MPG Code]],Table7[[#This Row],[Farmer code]]) -> 101200170002 | G52: 10120017 | H52: Direct | I52: Gomukh Dumduma | J52: 0002 | K52: DalsinghSarai | L52: Daya Society | M52: 0 | N52: 1400 | O52: 0 | P52: 1398 | Q52: 1398 | R52: 0 | S52: 1398 | U52: 1398 | V52: 0002(oll cood) | X52: =Table7[[#This Row],[Final Amount]]-Table7[[#This Row],[Deduction]] -> 0
A53: 46242.304 | B53: ANSHU KUMAR | C53: 46242 | D53: 31-07-2026 to 06-08-2026 | E53: Gold 50 Kg | F53: =CONCATENATE(Table7[[#This Row],[MPG Code]],Table7[[#This Row],[Farmer code]]) -> 101200340002 | G53: 10120034 | H53: Direct | I53: Matior | J53: 0002 | K53: DalsinghSarai | L53: Daya Society | M53: 0 | N53: 1400 | O53: 0 | P53: 4200 | Q53: 4200 | R53: 0 | S53: 4200 | U53: 4200 | V53: 0002(oll cood defection | X53: =Table7[[#This Row],[Final Amount]]-Table7[[#This Row],[Deduction]] -> 0
A54: 46242.304 | B54: RAMJEEVAN SHANDILYA | C54: 46242 | D54: 31-07-2026 to 06-08-2026 | E54: Liveferol 1LTR | F54: =CONCATENATE(Table7[[#This Row],[MPG Code]],Table7[[#This Row],[Farmer code]]) -> 105300350013 | G54: 10530035 | H54: Direct | I54: Gomukh Birauli Khurd | J54: 0013 | K54: Kalyanpur | L54: Daya Society | M54: 1 | N54: 259 | O54: 259 | P54: 0 | Q54: 259 | R54: 1 | S54: 259 | U54: 259
A55: 46242.304 | B55: ANSHU KUMAR | C55: 46242 | D55: 31-07-2026 to 06-08-2026 | E55: Gold 50 Kg | F55: =CONCATENATE(Table7[[#This Row],[MPG Code]],Table7[[#This Row],[Farmer code]]) -> 101201200002 | G55: 10120120 | H55: Direct | I55: GOMUKH BALTHARA | J55: 0002 | K55: DalsinghSarai | L55: Daya Society | M55: 5 | N55: 1400 | O55: 7000 | P55: 0 | Q55: 7000 | R55: 5 | S55: 7000 | U55: 7000 | V55: 0002(an rajister farmer | X55: =Table7[[#This Row],[Final Amount]]-Table7[[#This Row],[Deduction]] -> 0
...

Sheet Summary
A1: BMC Code | B1: MCC Name | C1: Code | D1: MPG NAME | E1: Type | F1: Farmer Payment | G1: BMC Volume | H1: BMC Amount | I1: Vet Deduction | J1: CF Deduction | K1: Other | L1: Advance | M1: Closing Reserve | N1: Stop Payment | O1: Stop Amount | P1: Loss Remarks | Q1: Cycle | S1: loss/gain | T1: Nos.Of farmer | U1: CF OS | V1: Deduction | W1: Balance | X1: Blank | Y1: EMI Recovery | Z1: Sample milk | AA1: Inward Penalty | AB1: Total | AC1: Recovered | AD1: Pending | AE1: Total Adj Pending | AF1: Payment month
A2: 1001 | B2: Majhaul | C2: 10010013 | D2: Gomukh Kumbhi | E2: MPG | F2: Direct | G2: 372.9 | H2: 14111.21 | I2: 0 | J2: 0 | K2: 0 | L2: 0 | M2: 18 | N2: 0 | O2: 0 | Q2: 19. 31-06 Aug | S2: 0.0012529046 | T2: 12 | U2: 0 | V2: 0 | W2: 0 | Y2: 0 | Z2: 0 | AA2: 0 | AB2: 0 | AC2: 0 | AD2: 0 | AE2: 0 | AF2: 46265
A3: 1001 | B3: Majhaul | C3: 10010019 | D3: Gomukh Jagdar | E3: MPG | F3: Direct | G3: 822.2 | H3: 33186.89 | I3: 0 | J3: 0 | K3: 0 | L3: 0 | M3: 0 | N3: 0 | O3: 0 | Q3: 19. 31-06 Aug | S3: -0.00061379659 | T3: 12 | U3: 0 | V3: 0 | W3: 0 | Y3: 0 | Z3: 0 | AA3: 0 | AB3: 0 | AC3: 0 | AD3: 0 | AE3: 0 | AF3: 46265
A4: 1058 | B4: Hasanpur | C4: 10010038 | D4: Gomukh Goriyari | E4: MPG | F4: Direct | G4: 763.02 | H4: 31772.25 | I4: 0 | J4: 0 | K4: 0 | L4: 0 | M4: 0 | N4: 0 | O4: 0 | Q4: 19. 31-06 Aug | S4: -0.0021811486 | T4: 7 | U4: 0 | V4: 0 | W4: 0 | Y4: 0 | Z4: 0 | AA4: 0 | AB4: 0 | AC4: 0 | AD4: 0 | AE4: 0 | AF4: 46265
A5: 1058 | B5: Hasanpur | C5: 10010044 | D5: Gomukh Kanausi | E5: MPG | F5: Direct | G5: 255.44 | H5: 10525.36 | I5: 0 | J5: 0 | K5: 0 | L5: 0 | M5: 32 | N5: 0 | O5: 0 | Q5: 19. 31-06 Aug | S5: 0.003050727 | T5: 1 | U5: 0 | V5: 0 | W5: 0 | Y5: 0 | Z5: 0 | AA5: 0 | AB5: 0 | AC5: 0 | AD5: 0 | AE5: 0 | AF5: 46265
A6: 1001 | B6: Majhaul | C6: 10010047 | D6: Mohanpur - Chandan | E6: VLC | F6: Indirect | G6: 28.13 | H6: 1106.63 | I6: 0 | J6: 0 | K6: 0 | L6: 0 | M6: 0 | N6: 0 | O6: 0 | Q6: 19. 31-06 Aug | S6: 0 | T6: 0 | U6: 0 | V6: 0 | W6: 0 | Y6: 0 | Z6: 0 | AA6: 0 | AB6: 0 | AC6: 0 | AD6: 0 | AE6: 0 | AF6: 46265
A7: 1058 | B7: Hasanpur | C7: 10010050 | D7: Ekamba - Ashutosh | E7: MPG | F7: Indirect | G7: 977.33 | H7: 43491.5 | I7: 0 | J7: 0 | K7: 0 | L7: 0 | M7: 0 | N7: 0 | O7: 0 | Q7: 19. 31-06 Aug | S7: 0 | T7: 0 | U7: 0 | V7: 0 | W7: 0 | Y7: 0 | Z7: 0 | AA7: 0 | AB7: 0 | AC7: 0 | AD7: 0 | AE7: 0 | AF7: 46265
A8: 1058 | B8: Hasanpur | C8: 10010051 | D8: Gomukh Dunahi | E8: MPG | F8: Direct | G8: 155.27 | H8: 6770.81 | I8: 0 | J8: 0 | K8: 0 | L8: 0 | M8: 117 | N8: 0 | O8: 2 | Q8: 19. 31-06 Aug | S8: 0.016968428 | T8: 7 | U8: 0 | V8: 0 | W8: 0 | Y8: 0 | Z8: 0 | AA8: 0 | AB8: 0 | AC8: 0 | AD8: 0 | AE8: 0 | AF8: 46265
A9: 1001 | B9: Majhaul | C9: 10010055 | D9: GOMUKH BIRPUR PASCHIM | E9: MPG | F9: Direct | G9: 93.83 | H9: 4071.09 | I9: 0 | J9: 0 | K9: 500 | L9: 0 | M9: 0 | N9: 0 | O9: 0 | Q9: 19. 31-06 Aug | S9: -0.019336345 | T9: 2 | U9: 0 | V9: 0 | W9: 0 | Y9: 500 | Z9: 0 | AA9: 0 | AB9: 500 | AC9: 500 | AD9: 0 | AE9: 0 | AF9: 46265
A10: 1001 | B10: Majhaul | C10: 10010057 | D10: Manish Dairy | E10: VLC | F10: Indirect | G10: 6216 | H10: 242414.2 | I10: 0 | J10: 0 | K10: 0 | L10: 0 | M10: 0 | N10: 0 | O10: 0 | Q10: 19. 31-06 Aug | S10: 0 | T10: 0 | U10: 0 | V10: 0 | W10: 0 | Y10: 0 | Z10: 0 | AA10: 0 | AB10: 0 | AC10: 0 | AD10: 0 | AE10: 0 | AF10: 46265
A11: 1001 | B11: Majhaul | C11: 10010076 | D11: Gomukh Bhith-02 | E11: MPG | F11: Direct | G11: 722.58 | H11: 31793.32 | I11: 0 | J11: 0 | K11: 0 | L11: 0 | M11: 248 | N11: 0 | O11: 0 | Q11: 19. 31-06 Aug | S11: 0.0077931465 | T11: 9 | U11: 0 | V11: 0 | W11: 0 | Y11: 0 | Z11: 0 | AA11: 0 | AB11: 0 | AC11: 0 | AD11: 0 | AE11: 0 | AF11: 46265
A12: 1058 | B12: Hasanpur | C12: 10010079 | D12: Chandan Dairy | E12: VLC | F12: Indirect | G12: 40.25 | H12: 1600.34 | I12: 0 | J12: 0 | K12: 0 | L12: 0 | M12: 0 | N12: 0 | O12: 0 | Q12: 19. 31-06 Aug | S12: 0 | T12: 0 | U12: 0 | V12: 0 | W12: 0 | Y12: 0 | Z12: 0 | AA12: 0 | AB12: 0 | AC12: 0 | AD12: 0 | AE12: 0 | AF12: 46265
A13: 1001 | B13: Majhaul | C13: 10010082 | D13: Gomukh Sharmatola Sahuri | E13: MPG | F13: Direct | G13: 1160.54 | H13: 45606.15 | I13: 0 | J13: 0 | K13: 0 | L13: 0 | M13: 0 | N13: 0 | O13: 0 | Q13: 19. 31-06 Aug | S13: -0.0046438912 | T13: 8 | U13: 0 | V13: 0 | W13: 0 | Y13: 0 | Z13: 0 | AA13: 0 | AB13: 0 | AC13: 0 | AD13: 0 | AE13: 0 | AF13: 46265
A14: 1001 | B14: Majhaul | C14: 10010084 | D14: Sangat- Sanjeev Kumar | E14: VLC | F14: Indirect | G14: 156.3 | H14: 5692.49 | I14: 0 | J14: 0 | K14: 0 | L14: 0 | M14: 0 | N14: 0 | O14: 0 | Q14: 19. 31-06 Aug | S14: 0 | T14: 0 | U14: 0 | V14: 0 | W14: 0 | Y14: 0 | Z14: 0 | AA14: 0 | AB14: 0 | AC14: 0 | AD14: 0 | AE14: 0 | AF14: 46265
A15: 1058 | B15: Hasanpur | C15: 10010086 | D15: Gomukh Garhi Bisanpur | E15: MPG | F15: Direct | G15: 58.25 | H15: 2785.97 | I15: 0 | J15: 0 | K15: 0 | L15: 0 | M15: 2742 | N15: Yes | O15: 2742 | P15: Letter not received | Q15: 19. 31-06 Aug | S15: -0.51316418 | T15: 5 | U15: 0 | V15: 0 | W15: 0 | Y15: 500 | Z15: 0 | AA15: 0 | AB15: 500 | AC15: 0 | AD15: -500 | AE15: -500 | AF15: 46265
A16: 1058 | B16: Hasanpur | C16: 10010089 | D16: Gomukh Barkurwa | E16: MPG | F16: Direct | G16: 468.17 | H16: 20680.11 | I16: 0 | J16: 0 | K16: 0 | L16: 0 | M16: 0 | N16: 0 | O16: 0 | Q16: 19. 31-06 Aug | S16: -0.062946957 | T16: 19 | U16: 0 | V16: 0 | W16: 0 | Y16: 0 | Z16: 0 | AA16: 0 | AB16: 0 | AC16: 0 | AD16: 0 | AE16: 0 | AF16: 46265
A17: 1001 | B17: Majhaul | C17: 10010092 | D17: Kamla- Amarjeet | E17: VLC | F17: Indirect | G17: 406.9 | H17: 12884.99 | I17: 0 | J17: 0 | K17: 0 | L17: 0 | M17: 0 | N17: 0 | O17: 0 | Q17: 19. 31-06 Aug | S17: 0 | T17: 0 | U17: 0 | V17: 0 | W17: 0 | Y17: 0 | Z17: 0 | AA17: 0 | AB17: 0 | AC17: 0 | AD17: 0 | AE17: 0 | AF17: 46265
A18: 1058 | B18: Hasanpur | C18: 10010095 | D18: Gomukh Goha-02 | E18: MPG | F18: Direct | G18: 201.57 | H18: 8605.49 | I18: 0 | J18: 0 | K18: 0 | L18: 0 | M18: 1 | N18: 0 | O18: 1 | Q18: 19. 31-06 Aug | S18: -0.0035825967 | T18: 3 | U18: 0 | V18: 0 | W18: 0 | Y18: 0 | Z18: 0 | AA18: 0 | AB18: 0 | AC18: 0 | AD18: 0 | AE18: 0 | AF18: 46265
A19: 1001 | B19: Majhaul | C19: 10010097 | D19: Gomukh Cheria Bariarpur | E19: MPG | F19: Direct | G19: 973.6 | H19: 38535.09 | I19: 0 | J19: 0 | K19: 0 | L19: 0 | M19: 0 | N19: 0 | O19: 0 | Q19: 19. 31-06 Aug | S19: -0.042741304 | T19: 11 | U19: 0 | V19: 0 | W19: 0 | Y19: 0 | Z19: 0 | AA19: 0 | AB19: 0 | AC19: 0 | AD19: 0 | AE19: 0 | AF19: 46265
A20: 1058 | B20: Hasanpur | C20: 10010099 | D20: Gomukh Bagraha-01 | E20: MPG | F20: Direct | G20: 125.19 | H20: 5267.08 | I20: 0 | J20: 0 | K20: 500 | L20: 0 | M20: 0 | N20: 0 | O20: 0 | Q20: 19. 31-06 Aug | S20: -0.0084107323 | T20: 2 | U20: 0 | V20: 0 | W20: 0 | Y20: 500 | Z20: 0 | AA20: 0 | AB20: 500 | AC20: 500 | AD20: 0 | AE20: 0 | AF20: 46265
A21: 1001 | B21: Majhaul | C21: 10010108 | D21: Gomukh Pirauna | E21: MPG | F21: Direct | G21: 106.57 | H21: 3624.39 | I21: 0 | J21: 0 | K21: 500 | L21: 0 | M21: 0 | N21: 0 | O21: 0 | Q21: 19. 31-06 Aug | S21: -0.029411846 | T21: 2 | U21: 0 | V21: 0 | W21: 0 | Y21: 500 | Z21: 0 | AA21: 0 | AB21: 500 | AC21: 500 | AD21: 0 | AE21: 0 | AF21: 46265
A22: 1001 | B22: Majhaul | C22: 10010109 | D22: Parra- Nagendra Kumar | E22: VLC | F22: Indirect | G22: 244.63 | H22: 8204.53 | I22: 0 | J22: 0 | K22: 0 | L22: 0 | M22: 0 | N22: 0 | O22: 0 | Q22: 19. 31-06 Aug | S22: 0 | T22: 0 | U22: 0 | V22: 0 | W22: 0 | Y22: 0 | Z22: 0 | AA22: 0 | AB22: 0 | AC22: 0 | AD22: 0 | AE22: 0 | AF22: 46265
A23: 1001 | B23: Majhaul | C23: 10010113 | D23: Gomukh Basahi | E23: MPG | F23: Direct | G23: 696.2 | H23: 28089.65 | I23: 0 | J23: 0 | K23: 0 | L23: 0 | M23: 0 | N23: 0 | O23: 0 | Q23: 19. 31-06 Aug | S23: -0.016102372 | T23: 28 | U23: 0 | V23: 0 | W23: 0 | Y23: 0 | Z23: 0 | AA23: 0 | AB23: 0 | AC23: 0 | AD23: 0 | AE23: 0 | AF23: 46265
A24: 1001 | B24: Majhaul | C24: 10010121 | D24: Gomukh Sawantpur | E24: MPG | F24: Direct | G24: 1080.5 | H24: 42181.29 | I24: 0 | J24: 0 | K24: 0 | L24: 0 | M24: 0 | N24: 0 | O24: 0 | Q24: 19. 31-06 Aug | S24: -0.054033672 | T24: 17 | U24: 0 | V24: 0 | W24: 0 | Y24: 0 | Z24: 0 | AA24: 0 | AB24: 0 | AC24: 0 | AD24: 0 | AE24: 0 | AF24: 46265
A25: 1001 | B25: Majhaul | C25: 10010125 | D25: Maida- Ram Kumar | E25: VLC | F25: Indirect | G25: 317.6 | H25: 14589.77 | I25: 0 | J25: 0 | K25: 0 | L25: 0 | M25: 0 | N25: 0 | O25: 0 | Q25: 19. 31-06 Aug | S25: 0 | T25: 0 | U25: 0 | V25: 0 | W25: 0 | Y25: 0 | Z25: 0 | AA25: 0 | AB25: 0 | AC25: 0 | AD25: 0 | AE25: 0 | AF25: 46265
A26: 1001 | B26: Majhaul | C26: 10010128 | D26: Gomukh Aure Bikrampur | E26: MPG | F26: Direct | G26: 1227.4 | H26: 54687.24 | I26: 10700 | J26: 0 | K26: 0 | L26: 0 | M26: 115 | N26: 0 | O26: -1 | P26: PCB Deduction | Q26: 19. 31-06 Aug | S26: 0.0021270044 | T26: 4 | U26: 0 | V26: 0 | W26: 0 | Y26: 0 | Z26: 0 | AA26: 0 | AB26: 0 | AC26: 0 | AD26: 0 | AE26: 0 | AF26: 46265
A27: 1001 | B27: Majhaul | C27: 10010129 | D27: Manjhaul- Gulshan Kumar | E27: VLC | F27: Indirect | G27: 452.7 | H27: 20925.81 | I27: 0 | J27: 0 | K27: 0 | L27: 0 | M27: 0 | N27: 0 | O27: 0 | Q27: 19. 31-06 Aug | S27: 0 | T27: 0 | U27: 0 | V27: 0 | W27: 0 | Y27: 0 | Z27: 0 | AA27: 0 | AB27: 0 | AC27: 0 | AD27: 0 | AE27: 0 | AF27: 46265
A28: 1001 | B28: Majhaul | C28: 10010130 | D28: Khaira Manjhaul | E28: VLC | F28: Indirect | G28: 345.1 | H28: 12635.9 | I28: 0 | J28: 0 | K28: 0 | L28: 0 | M28: 0 | N28: 0 | O28: 0 | Q28: 19. 31-06 Aug | S28: 0 | T28: 0 | U28: 0 | V28: 0 | W28: 0 | Y28: 0 | Z28: 0 | AA28: 0 | AB28: 0 | AC28: 0 | AD28: 0 | AE28: 0 | AF28: 46265
A29: 1001 | B29: Majhaul | C29: 10010131 | D29: Mehda Shahpur | E29: VLC | F29: Indirect | G29: 324.6 | H29: 14476.53 | I29: 0 | J29: 0 | K29: 0 | L29: 0 | M29: 0 | N29: 0 | O29: 0 | Q29: 19. 31-06 Aug | S29: 0 | T29: 0 | U29: 0 | V29: 0 | W29: 0 | Y29: 0 | Z29: 0 | AA29: 0 | AB29: 0 | AC29: 0 | AD29: 0 | AE29: 0 | AF29: 46265
A30: 1001 | B30: Majhaul | C30: 10010140 | D30: Shri Bhairav Laxmipur | E30: MPG | F30: Direct | G30: 197.7 | H30: 8266.06 | I30: 0 | J30: 0 | K30: 0 | L30: 0 | M30: 0 | N30: 0 | O30: 0 | Q30: 19. 31-06 Aug | S30: -0.066509316 | T30: 5 | U30: 0 | V30: 0 | W30: 0 | Y30: 0 | Z30: 0 | AA30: 0 | AB30: 0 | AC30: 0 | AD30: 0 | AE30: 0 | AF30: 46265
A31: 1001 | B31: Majhaul | C31: 10010143 | D31: Gomukh Akaha | E31: MPG | F31: Direct | G31: 154.41 | H31: 5290.8 | I31: 0 | J31: 0 | K31: 0 | L31: 0 | M31: 0 | N31: 0 | O31: 0 | Q31: 19. 31-06 Aug | S31: -0.018585091 | T31: 3 | U31: 0 | V31: 0 | W31: 0 | Y31: 0 | Z31: 0 | AA31: 0 | AB31: 0 | AC31: 0 | AD31: 0 | AE31: 0 | AF31: 46265
A32: 1001 | B32: Majhaul | C32: 10010144 | D32: Gomukh Rajakpur | E32: MPG | F32: Direct | G32: 131.4 | H32: 4704.28 | I32: 0 | J32: 0 | K32: 0 | L32: 0 | M32: 13 | N32: 0 | O32: 1 | Q32: 19. 31-06 Aug | S32: 0.0026103888 | T32: 4 | U32: 0 | V32: 0 | W32: 0 | Y32: 0 | Z32: 0 | AA32: 0 | AB32: 0 | AC32: 0 | AD32: 0 | AE32: 0 | AF32: 46265
A33: 1001 | B33: Majhaul | C33: 10010145 | D33: Gomukh Mohanpur | E33: MPG | F33: Direct | G33: 248.65 | H33: 10634.52 | I33: 0 | J33: 0 | K33: 0 | L33: 0 | M33: 0 | N33: 0 | O33: 0 | Q33: 19. 31-06 Aug | S33: -0.028523149 | T33: 6 | U33: 0 | V33: 0 | W33: 0 | Y33: 0 | Z33: 0 | AA33: 0 | AB33: 0 | AC33: 0 | AD33: 0 | AE33: 0 | AF33: 46265
A34: 1001 | B34: Majhaul | C34: 10010146 | D34: Gomukh Chakka | E34: MPG | F34: Direct | G34: 166.65 | H34: 6647.25 | I34: 0 | J34: 0 | K34: 0 | L34: 0 | M34: 0 | N34: 0 | O34: 0 | Q34: 19. 31-06 Aug | S34: -0.012435218 | T34: 3 | U34: 0 | V34: 0 | W34: 0 | Y34: 0 | Z34: 0 | AA34: 0 | AB34: 0 | AC34: 0 | AD34: 0 | AE34: 0 | AF34: 46265
A35: 1001 | B35: Majhaul | C35: 10010147 | D35: Gamharia | E35: VLC | F35: Indirect | G35: 61.28 | H35: 3001.58 | I35: 0 | J35: 0 | K35: 0 | L35: 0 | M35: 0 | N35: 0 | O35: 0 | Q35: 19. 31-06 Aug | S35: 0 | T35: 0 | U35: 0 | V35: 0 | W35: 0 | Y35: 0 | Z35: 0 | AA35: 0 | AB35: 0 | AC35: 0 | AD35: 0 | AE35: 0 | AF35: 46265
A36: 1001 | B36: Majhaul | C36: 10010148 | D36: Gomukh Meghaul-02 | E36: MPG | F36: Direct | G36: 225.7 | H36: 8955.64 | I36: 0 | J36: 0 | K36: 0 | L36: 0 | M36: 0 | N36: 0 | O36: 0 | Q36: 19. 31-06 Aug | S36: -0.020161596 | T36: 8 | U36: 0 | V36: 0 | W36: 0 | Y36: 0 | Z36: 0 | AA36: 0 | AB36: 0 | AC36: 0 | AD36: 0 | AE36: 0 | AF36: 46265
A37: 1001 | B37: Majhaul | C37: 10010149 | D37: Gomukh Meida | E37: MPG | F37: Direct | G37: 185.01 | H37: 7307.36 | I37: 0 | J37: 0 | K37: 0 | L37: 0 | M37: 0 | N37: 0 | O37: 0 | Q37: 19. 31-06 Aug | S37: -0.018885069 | T37: 5 | U37: 0 | V37: 0 | W37: 0 | Y37: 0 | Z37: 0 | AA37: 0 | AB37: 0 | AC37: 0 | AD37: 0 | AE37: 0 | AF37: 46265
A38: 1001 | B38: Majhaul | C38: 10010151 | D38: Kamla Nagar | E38: VLC | F38: Indirect | G38: 290.2 | H38: 9976.17 | I38: 0 | J38: 0 | K38: 0 | L38: 0 | M38: 0 | N38: 0 | O38: 0 | Q38: 19. 31-06 Aug | S38: 0 | T38: 0 | U38: 0 | V38: 0 | W38: 0 | Y38: 0 | Z38: 0 | AA38: 0 | AB38: 0 | AC38: 0 | AD38: 0 | AE38: 0 | AF38: 46265
... A50: 1002 | B50: Laldiyara | C50: 10020023 | D50: Juwas | E50: MPG | F50: Direct | G50: 753.3 | H50: 30066.44 | I50: 0 | J50: 0 | K50: 0 | L50: 0 | M50: 578 | N50: 0 | O50: 2 | Q50: 19. 31-06 Aug | S50: 0.019167218 | T50: 21 | U50: 0 | V50: 0 | W50: 0 | Y50: 0 | Z50: 0 | AA50: 0 | AB50: 0 | AC50: 0 | AD50: 0 | AE50: 0 | AF50: 46265
A51: 1002 | B51: Laldiyara | C51: 10020024 | D51: Morwariya | E51: MPG | F51: Direct | G51: 2708.2 | H51: 111632.09 | I51: 0 | J51: 0 | K51: 0 | L51: 0 | M51: -233 | N51: Release2 | O51: -233 | P51: Letter not received | Q51: 19. 31-06 Aug | S51: -0.036679507 | T51: 63 | U51: 0 | V51: 0 | W51: 0 | Y51: 0 | Z51: 0 | AA51: 0 | AB51: 0 | AC51: 0 | AD51: 0 | AE51: -233 | AF51: 46265
...
