Workbook

Sheet Sheet2
D3: Values
A4: ref_code | B4: name | C4: Type | D4: Sum of qty | E4: Sum of amount
A5: 10010013 | B5: Gomukh Kumbhi | C5: MPG | D5: 142.8 | E5: 5463.94 | H5: =_xlfn.XLOOKUP(A5,Sheet1!D:D,Sheet1!A:A) -> Majhaul | I5: =_xlfn.XLOOKUP(H5,'[1]MCC-BMC'!$D:$D,'[1]MCC-BMC'!$C:$C) -> 1001
A6: 10010017 | B6: Gomukh Amba | C6: MPG | D6: 17.35 | E6: 602.49 | H6: =_xlfn.XLOOKUP(A6,Sheet1!D:D,Sheet1!A:A) -> Teghra | I6: =_xlfn.XLOOKUP(H6,'[1]MCC-BMC'!$D:$D,'[1]MCC-BMC'!$C:$C) -> 1008
A7: 10010019 | B7: Gomukh Jagdar | C7: MPG | D7: 330.6 | E7: 12783.8 | H7: =_xlfn.XLOOKUP(A7,Sheet1!D:D,Sheet1!A:A) -> Majhaul | I7: =_xlfn.XLOOKUP(H7,'[1]MCC-BMC'!$D:$D,'[1]MCC-BMC'!$C:$C) -> 1001
A8: 10010038 | B8: Gomukh Goriyari | C8: MPG | D8: 328.6 | E8: 12828.68 | H8: =_xlfn.XLOOKUP(A8,Sheet1!D:D,Sheet1!A:A) -> Hasanpur | I8: =_xlfn.XLOOKUP(H8,'[1]MCC-BMC'!$D:$D,'[1]MCC-BMC'!$C:$C) -> 1058
A9: 10010044 | B9: Gomukh Kanausi | C9: MPG | D9: 135.7 | E9: 5187.3 | H9: =_xlfn.XLOOKUP(A9,Sheet1!D:D,Sheet1!A:A) -> Hasanpur | I9: =_xlfn.XLOOKUP(H9,'[1]MCC-BMC'!$D:$D,'[1]MCC-BMC'!$C:$C) -> 1058
A10: 10010049 | B10: Birpur-2 - Pankaj | C10: vlc | D10: 1282.1 | E10: 44428.76 | H10: =_xlfn.XLOOKUP(A10,Sheet1!D:D,Sheet1!A:A) -> Majhaul | I10: =_xlfn.XLOOKUP(H10,'[1]MCC-BMC'!$D:$D,'[1]MCC-BMC'!$C:$C) -> 1001
A11: 10010050 | B11: Ekamba - Ashutosh | C11: vlc | D11: 289.2 | E11: 10794.96 | H11: =_xlfn.XLOOKUP(A11,Sheet1!D:D,Sheet1!A:A) -> Hasanpur | I11: =_xlfn.XLOOKUP(H11,'[1]MCC-BMC'!$D:$D,'[1]MCC-BMC'!$C:$C) -> 1058
A12: 10010051 | B12: Gomukh Dunahi | C12: MPG | D12: 359.7 | E12: 13122.55 | H12: =_xlfn.XLOOKUP(A12,Sheet1!D:D,Sheet1!A:A) -> Hasanpur | I12: =_xlfn.XLOOKUP(H12,'[1]MCC-BMC'!$D:$D,'[1]MCC-BMC'!$C:$C) -> 1058
A13: 10010055 | B13: GOMUKH BIRPUR PASCHIM | C13: MPG | D13: 38.7 | E13: 1600.6 | H13: =_xlfn.XLOOKUP(A13,Sheet1!D:D,Sheet1!A:A) -> Majhaul | I13: =_xlfn.XLOOKUP(H13,'[1]MCC-BMC'!$D:$D,'[1]MCC-BMC'!$C:$C) -> 1001
A14: 10010056 | B14: Gomukh Harigiridham | C14: MPG | D14: 642.8 | E14: 22247.31 | H14: =_xlfn.XLOOKUP(A14,Sheet1!D:D,Sheet1!A:A) -> Hasanpur | I14: =_xlfn.XLOOKUP(H14,'[1]MCC-BMC'!$D:$D,'[1]MCC-BMC'!$C:$C) -> 1058
A15: 10010057 | B15: Manish Dairy | C15: vlc | D15: 4492 | E15: 159441.59 | H15: =_xlfn.XLOOKUP(A15,Sheet1!D:D,Sheet1!A:A) -> Majhaul | I15: =_xlfn.XLOOKUP(H15,'[1]MCC-BMC'!$D:$D,'[1]MCC-BMC'!$C:$C) -> 1001
A16: 10010076 | B16: Gomukh Bhith-02 | C16: MPG | D16: 275.9 | E16: 12048.95 | H16: =_xlfn.XLOOKUP(A16,Sheet1!D:D,Sheet1!A:A) -> Majhaul | I16: =_xlfn.XLOOKUP(H16,'[1]MCC-BMC'!$D:$D,'[1]MCC-BMC'!$C:$C) -> 1001
... A958: 10650010 | B958: Sakh Mohan | C958: vlc | D958: 40.6 | E958: 1356.85 | H958: =_xlfn.XLOOKUP(A958,Sheet1!D:D,Sheet1!A:A) -> Bachhwara BMC | I958: =_xlfn.XLOOKUP(H958,'[1]MCC-BMC'!$D:$D,'[1]MCC-BMC'!$C:$C) -> 1065
A959: Grand Total | D959: 333659.53 | E959: 12989594

Sheet Sheet3
D3: Values
A4: ref_code | B4: name | C4: Type | D4: Sum of qty | E4: Sum of amount
A5: 10010013 | B5: Gomukh Kumbhi | C5: MPG | D5: 142.8 | E5: 5463.94
A6: 10010017 | B6: Gomukh Amba | C6: MPG | D6: 17.35 | E6: 602.49
A7: 10010019 | B7: Gomukh Jagdar | C7: MPG | D7: 330.6 | E7: 12783.8
A8: 10010038 | B8: Gomukh Goriyari | C8: MPG | D8: 328.6 | E8: 12828.68
A9: 10010044 | B9: Gomukh Kanausi | C9: MPG | D9: 135.7 | E9: 5187.3
A10: 10010049 | B10: Birpur-2 - Pankaj | C10: vlc | D10: 1282.1 | E10: 44428.76
A11: 10010050 | B11: Ekamba - Ashutosh | C11: vlc | D11: 289.2 | E11: 10794.96
A12: 10010051 | B12: Gomukh Dunahi | C12: MPG | D12: 359.7 | E12: 13122.55
A13: 10010055 | B13: GOMUKH BIRPUR PASCHIM | C13: MPG | D13: 38.7 | E13: 1600.6
A14: 10010056 | B14: Gomukh Harigiridham | C14: MPG | D14: 642.8 | E14: 22247.31
A15: 10010057 | B15: Manish Dairy | C15: vlc | D15: 4492 | E15: 159441.59
A16: 10010076 | B16: Gomukh Bhith-02 | C16: MPG | D16: 275.9 | E16: 12048.95
... A958: 10650010 | B958: Sakh Mohan | C958: vlc | D958: 40.6 | E958: 1356.85
A959: Grand Total | D959: 333659.53 | E959: 12989594

Sheet Sheet1
A1: bmc_name | B1: route_code | C1: route_name | D1: ref_code | E1: name | F1: collection_date | G1: Shift | H1: Type | I1: animal_type_name | J1: qty | K1: fat | L1: snf | M1: rate | N1: amount | O1: qlty_auto
A2: Majhaul | B2: 100103 | C2: Birpur | D2: 10010082 | E2: Gomukh Sharmatola Sahuri | F2: 46113 | G2: Morning | H2: MPG | I2: Cow | J2: 97.6 | K2: 3.8 | L2: 7.9 | M2: 34.86 | N2: 3402.34 | O2: A
A3: Majhaul | B3: 100103 | C3: Birpur | D3: 10010116 | E3: Mohanpur- Mukesh Kumar | F3: 46113 | G3: Morning | H3: vlc | I3: Cow | J3: 78.7 | K3: 4.4 | L3: 8.4 | M3: 39.6 | N3: 3116.52 | O3: A
A4: Majhaul | B4: 100103 | C4: Birpur | D4: 10010076 | E4: Gomukh Bhith-02 | F4: 46113 | G4: Morning | H4: MPG | I4: Mix | J4: 66.2 | K4: 5.9 | L4: 8.7 | M4: 46.33 | N4: 3067.05 | O4: A
A5: Majhaul | B5: 100103 | C5: Birpur | D5: 10010019 | E5: Gomukh Jagdar | F5: 46113 | G5: Morning | H5: MPG | I5: Cow | J5: 83.3 | K5: 4.6 | L5: 8.7 | M5: 40.66 | N5: 3386.98 | O5: A
A6: Majhaul | B6: 100103 | C6: Birpur | D6: 10010109 | E6: Parra- Nagendra Kumar | F6: 46113 | G6: Morning | H6: vlc | I6: Cow | J6: 20.5 | K6: 3.8 | L6: 8 | M6: 36.17 | N6: 741.49 | O6: A
A7: Majhaul | B7: 100103 | C7: Birpur | D7: 10010108 | E7: Gomukh Pirauna | F7: 46113 | G7: Morning | H7: MPG | I7: Cow | J7: 13 | K7: 4.2 | L7: 8.4 | M7: 38.81 | N7: 504.53 | O7: A
A8: Majhaul | B8: 100103 | C8: Birpur | D8: 10010055 | E8: GOMUKH BIRPUR PASCHIM | F8: 46113 | G8: Morning | H8: MPG | I8: Mix | J8: 8.5 | K8: 5.2 | L8: 8.2 | M8: 42.24 | N8: 359.04 | O8: A
A9: Majhaul | B9: 100103 | C9: Birpur | D9: 10010145 | E9: Gomukh Mohanpur | F9: 46113 | G9: Morning | H9: MPG | I9: Mix | J9: 9.6 | K9: 6.1 | L9: 8.8 | M9: 46.88 | N9: 450.05 | O9: A
A10: Majhaul | B10: 100103 | C10: Birpur | D10: 10010144 | E10: Gomukh Rajakpur | F10: 46113 | G10: Morning | H10: MPG | I10: Cow | J10: 4.4 | K10: 3.9 | L10: 7.9 | M10: 35.26 | N10: 155.14 | O10: A
A11: Majhaul | B11: 100103 | C11: Birpur | D11: 10010146 | E11: Gomukh Chakka | F11: 46113 | G11: Morning | H11: MPG | I11: Cow | J11: 8.8 | K11: 4.3 | L11: 8.4 | M11: 39.21 | N11: 345.05 | O11: A
A12: Majhaul | B12: 100103 | C12: Birpur | D12: 10010143 | E12: Gomukh Akaha | F12: 46113 | G12: Morning | H12: MPG | I12: Cow | J12: 8.1 | K12: 4.1 | L12: 8.3 | M12: 38.15 | N12: 309.02 | O12: A
A13: Majhaul | B13: 100102 | C13: Paroria | D13: 10010084 | E13: Sangat- Sanjeev Kumar | F13: 46113 | G13: Morning | H13: vlc | I13: Cow | J13: 14.4 | K13: 4.2 | L13: 8.1 | M13: 38.02 | N13: 547.49 | O13: A
... A2447: MAHADAT PUR 2 | B2447: 103601 | C2447: RMC | D2447: 10360001 | E2447: MAHADAT PUR 2 | F2447: 46114 | G2447: Evening | H2447: RMC | I2447: Cow | J2447: 165.5 | K2447: 4 | L2447: 8.2 | M2447: 37.25 | N2447: 6165.35 | O2447: A
A2448: Dumraon | D2448: 10510002 | E2448: Diyaman | F2448: 46113 | G2448: Morning | H2448: MPG | I2448: Cow | J2448: 143.7 | K2448: 4.3 | L2448: 8.3 | M2448: 38.94 | N2448: 5595.68 | O2448: A
A2449: Dumraon | D2449: 10510004 | E2449: HENHA | F2449: 46113 | G2449: Morning | H2449: MPG | I2449: Cow | J2449: 222 | K2449: 4.1 | L2449: 8 | M2449: 37.36 | N2449: 8293.92 | O2449: A
A2450: Dumraon | D2450: 10510001 | E2450: ARAK | F2450: 46113 | G2450: Morning | H2450: MPG | I2450: Cow | J2450: 187.6 | K2450: 3.9 | L2450: 8.3 | M2450: 37.36 | N2450: 7008.74 | O2450: A
A2451: Dumraon | D2451: 10510004 | E2451: HENHA | F2451: 46113 | G2451: Evening | H2451: MPG | I2451: Cow | J2451: 149.6 | K2451: 4 | L2451: 8.2 | M2451: 37.49 | N2451: 5608.5 | O2451: A
A2452: Dumraon | D2452: 10510002 | E2452: Diyaman | F2452: 46113 | G2452: Evening | H2452: MPG | I2452: Cow | J2452: 97.2 | K2452: 4.4 | L2452: 8.3 | M2452: 39.34 | N2452: 3823.85 | O2452: A
A2453: Dumraon | D2453: 10510001 | E2453: ARAK | F2453: 46113 | G2453: Evening | H2453: MPG | I2453: Cow | J2453: 129.1 | K2453: 4 | L2453: 8.2 | M2453: 37.49 | N2453: 4839.96 | O2453: A
A2454: Dumraon | D2454: 10510002 | E2454: Diyaman | F2454: 46114 | G2454: Morning | H2454: MPG | I2454: Cow | J2454: 127.6 | K2454: 4.4 | L2454: 8.3 | M2454: 39.34 | N2454: 5019.78 | O2454: A
A2455: Dumraon | D2455: 10510004 | E2455: HENHA | F2455: 46114 | G2455: Morning | H2455: MPG | I2455: Cow | J2455: 221 | K2455: 4.1 | L2455: 8.1 | M2455: 37.62 | N2455: 8314.02 | O2455: A
A2456: Dumraon | D2456: 10510001 | E2456: ARAK | F2456: 46114 | G2456: Morning | H2456: MPG | I2456: Cow | J2456: 163 | K2456: 4 | L2456: 8 | M2456: 36.96 | N2456: 6024.48 | O2456: A
A2457: Dumraon | D2457: 10510004 | E2457: HENHA | F2457: 46114 | G2457: Evening | H2457: MPG | I2457: Cow | J2457: 138 | K2457: 3.9 | L2457: 8.1 | M2457: 36.83 | N2457: 5082.54 | O2457: A
A2458: Dumraon | D2458: 10510002 | E2458: Diyaman | F2458: 46114 | G2458: Evening | H2458: MPG | I2458: Cow | J2458: 100 | K2458: 4.4 | L2458: 8.2 | M2458: 39.07 | N2458: 3907 | O2458: A
A2459: Dumraon | D2459: 10510001 | E2459: ARAK | F2459: 46114 | G2459: Evening | H2459: MPG | I2459: Cow | J2459: 134.1 | K2459: 4 | L2459: 8.1 | M2459: 37.23 | N2459: 4992.54 | O2459: A
A2460: 3P Network | D2460: 10520003 | E2460: Nova Bihar Dairy | F2460: 46113 | G2460: Morning | H2460: vlc | I2460: Mix | J2460: 10699 | K2460: 5.2 | L2460: 8.5 | M2460: 43.03 | N2460: 460377.97 | O2460: M
A2461: 3P Network | B2461: 105201 | C2461: 3p | D2461: 10520005 | E2461: Rakesh Dairy | F2461: 46113 | G2461: Morning | H2461: vlc | I2461: Cow | J2461: 2252 | K2461: 3.3 | L2461: 8.1 | M2461: 34.45 | N2461: 77581.4 | O2461: M
A2462: 3P Network | D2462: 10520003 | E2462: Nova Bihar Dairy | F2462: 46113 | G2462: Evening | H2462: vlc | I2462: Mix | J2462: 8291 | K2462: 5.2 | L2462: 8.3 | M2462: 42.51 | N2462: 352450.41 | O2462: M
A2463: 3P Network | B2463: 105201 | C2463: 3p | D2463: 10520005 | E2463: Rakesh Dairy | F2463: 46113 | G2463: Evening | H2463: vlc | I2463: Cow | J2463: 2748 | K2463: 3.7 | L2463: 8.2 | M2463: 36.3 | N2463: 99752.4 | O2463: M
A2464: 3P Network | B2464: 105201 | C2464: 3p | D2464: 10520005 | E2464: Rakesh Dairy | F2464: 46114 | G2464: Morning | H2464: vlc | I2464: Cow | J2464: 2359 | K2464: 3.6 | L2464: 8.3 | M2464: 36.17 | N2464: 85325.03 | O2464: M
A2465: Kalyanpur | B2465: 105301 | C2465: Hattha | D2465: 10530013 | E2465: Gomukh Kalyanpur 2 | F2465: 46113 | G2465: Morning | H2465: vlc | I2465: Mix | J2465: 14.6 | K2465: 6.5 | L2465: 9 | M2465: 50.51 | N2465: 737.45 | O2465: A
A2466: Kalyanpur | B2466: 105301 | C2466: Hattha | D2466: 10530013 | E2466: Gomukh Kalyanpur 2 | F2466: 46113 | G2466: Morning | H2466: vlc | I2466: Mix | J2466: 18.05 | K2466: 5.2 | L2466: 8.2 | M2466: 42.24 | N2466: 762.43 | O2466: A
A2467: Kalyanpur | B2467: 105301 | C2467: Hattha | D2467: 10530060 | E2467: Gomukh Ranitola | F2467: 46113 | G2467: Morning | H2467: vlc | I2467: Mix | J2467: 18.45 | K2467: 7.8 | L2467: 9 | M2467: 60.61 | N2467: 1118.25 | O2467: A
A2468: Kalyanpur | B2468: 105301 | C2468: Hattha | D2468: 10530060 | E2468: Gomukh Ranitola | F2468: 46113 | G2468: Morning | H2468: vlc | I2468: Cow | J2468: 28.95 | K2468: 3.7 | L2468: 8 | M2468: 35.77 | N2468: 1035.54 | O2468: A
A2469: Kalyanpur | B2469: 105301 | C2469: Hattha | D2469: 10530029 | E2469: Gomukh Belsandi East | F2469: 46113 | G2469: Morning | H2469: vlc | I2469: Cow | J2469: 80.1 | K2469: 3.4 | L2469: 8.1 | M2469: 34.85 | N2469: 2791.49 | O2469: A
A2470: Kalyanpur | B2470: 105301 | C2470: Hattha | D2470: 10530029 | E2470: Gomukh Belsandi East | F2470: 46113 | G2470: Morning | H2470: vlc | I2470: Mix | J2470: 49.55 | K2470: 6.5 | L2470: 9 | M2470: 50.51 | N2470: 2502.77 | O2470: A
A2471: Kalyanpur | B2471: 105301 | C2471: Hattha | D2471: 10530063 | E2471: GOMUKH Singhiya Ward 11 | F2471: 46113 | G2471: Morning | H2471: vlc | I2471: Mix | J2471: 36.65 | K2471: 6.8 | L2471: 8.6 | M2471: 51.74 | N2471: 1896.27 | O2471: A
A2472: Kalyanpur | B2472: 105301 | C2472: Hattha | D2472: 10530063 | E2472: GOMUKH Singhiya Ward 11 | F2472: 46113 | G2472: Morning | H2472: vlc | I2472: Cow | J2472: 17.3 | K2472: 4.3 | L2472: 8 | M2472: 38.15 | N2472: 660 | O2472: A
A2473: Kalyanpur | B2473: 105301 | C2473: Hattha | D2473: 10530072 | E2473: KAMARGAMA | F2473: 46113 | G2473: Morning | H2473: vlc | I2473: Mix | J2473: 51.7 | K2473: 7.8 | L2473: 9 | M2473: 60.61 | N2473: 3133.54 | O2473: A
...
