Workbook
Name Code: #REF!

Sheet MPG PIVOT
A1: BMC Code | B1: (All)
A2: For the period of 08-14 Nov'24
E3: Values
A4: Code | B4: MPG NAME | C4: Type | D4: Farmer Payment | E4: BMC Volume | F4: BMC Amount | G4: Reg Vol | H4: reg Amt | I4: Unreg Vol | J4: Unreg Amt | K4: Total Vol | L4: Total Amt | M4: Payable | N4: Loss Apportion | O4: Advance | P4: Others | Q4: Payment to Farmer A/c | R4: Unreg. Farmer payment | S4: Payment to MPGs A/c
A5: (blank) | B5: Total: | C5: (blank) | D5: 117 | E5: 0 | F5: 0 | G5: 0 | H5: 0 | I5: 0 | J5: 0 | K5: 0 | L5: 0 | M5: 0 | N5: 0 | O5: 0 | P5: 0 | Q5: 0 | R5: 0 | S5: 0
B6: (blank) | C6: MPG | D6: Indirect | G6: 0 | H6: 0 | I6: 0 | J6: 0 | K6: 0 | L6: 0 | M6: 0 | N6: 0 | O6: 0 | P6: 0 | Q6: 0 | R6: 0 | S6: 0
C7: RMC | D7: Indirect | G7: 0 | H7: 0 | I7: 0 | J7: 0 | K7: 0 | L7: 0 | M7: 0 | N7: 0 | O7: 0 | P7: 0 | Q7: 0 | R7: 0 | S7: 0
C8: VLC | D8: Indirect | G8: 0 | H8: 0 | I8: 0 | J8: 0 | K8: 0 | L8: 0 | M8: 0 | N8: 0 | O8: 0 | P8: 0 | Q8: 0 | R8: 0 | S8: 0
A9: (blank) Total | E9: 0 | F9: 0 | G9: 0 | H9: 0 | I9: 0 | J9: 0 | K9: 0 | L9: 0 | M9: 0 | N9: 0 | O9: 0 | P9: 0 | Q9: 0 | R9: 0 | S9: 0
A10: Grand Total | E10: 0 | F10: 0 | G10: 0 | H10: 0 | I10: 0 | J10: 0 | K10: 0 | L10: 0 | M10: 0 | N10: 0 | O10: 0 | P10: 0 | Q10: 0 | R10: 0 | S10: 0

Sheet MGP PDF
A1: BMC Code | B1: BMC Code :2008
D2: Payment cycle-08th to 14th May'26
E3: Values
A4: Code | B4: MPG NAME | C4: Type | D4: Farmer Payment | E4: BMC Volume | F4: BMC Amount | G4: Reg Vol | H4: reg Amt | I4: Unreg Vol | J4: Unreg Amt | K4: Total Vol | L4: Total Amt | M4: Payable | N4: TS Loss | O4: Loss Apportion | P4: CF Deduction | Q4: Deduction for excess payment | R4: Vet Deduction | S4: Advance | T4: Others | U4: Payment to Farmer A/c | V4: Unreg. Farmer payment | W4: Payment to MPGs A/c
A5: 20080001 | B5: CHATTI BHANDRA | C5: RMC | D5: Direct | E5: 2319.32 | F5: 90847.83 | G5: 2321.28 | H5: 90924.52 | I5: 0 | J5: 0 | K5: 2321.28 | L5: 90924.52 | M5: 90847.83 | N5: 0 | O5: 76.69 | P5: 0 | Q5: 0 | R5: 0 | S5: 0 | T5: 0 | U5: 90848 | V5: 0 | W5: 0
A6: 20080002 | B6: BHITTA | C6: MPG | D6: Direct | E6: 716.42 | F6: 26490 | G6: 667.83 | H6: 26368.88 | I6: 0 | J6: 0 | K6: 667.83 | L6: 26368.88 | M6: 26368.88 | N6: 0 | O6: 0 | P6: 0 | Q6: 0 | R6: 0 | S6: 0 | T6: 0 | U6: 26368 | V6: 0 | W6: 0
A7: 20080004 | B7: Guri | C7: MPG | D7: Direct | E7: 1078.76 | F7: 41168.59 | G7: 1070.32 | H7: 41879.62 | I7: 0 | J7: 0 | K7: 1070.32 | L7: 41879.62 | M7: 41168.59 | N7: 0 | O7: 711.03 | P7: 0 | Q7: 0 | R7: 0 | S7: 0 | T7: 0 | U7: 41169 | V7: 0 | W7: 0
A8: 20080006 | B8: Chitri Ambatoli | C8: MPG | D8: Direct | E8: 1319 | F8: 50885.38 | G8: 1315.65 | H8: 50184.82 | I8: 0 | J8: 0 | K8: 1315.65 | L8: 50184.82 | M8: 50184.82 | N8: 0 | O8: 0 | P8: 0 | Q8: 0 | R8: 0 | S8: 0 | T8: 0 | U8: 50185 | V8: 0 | W8: 0
A9: 20080007 | B9: Rampur | C9: MPG | D9: Direct | E9: 3167.38 | F9: 117245.44 | G9: 3074.06 | H9: 119687.25 | I9: 0 | J9: 0 | K9: 3074.06 | L9: 119687.25 | M9: 117245.44 | N9: 0 | O9: 2441.81 | P9: 0 | Q9: 0 | R9: 0 | S9: 0 | T9: 0 | U9: 117245 | V9: 0 | W9: 0
A10: 20080009 | B10: MASHMANO | C10: MPG | D10: Direct | E10: 572.62 | F10: 21331.24 | G10: 555.01 | H10: 21280.09 | I10: 0 | J10: 0 | K10: 555.01 | L10: 21280.09 | M10: 21280.09 | N10: 0 | O10: 0 | P10: 0 | Q10: 0 | R10: 0 | S10: 0 | T10: 0 | U10: 21280 | V10: 0 | W10: 0
A11: 20080010 | B11: PAHARKESA | C11: MPG | D11: Direct | E11: 527.34 | F11: 22181.72 | G11: 527.59 | H11: 22590.77 | I11: 0 | J11: 0 | K11: 527.59 | L11: 22590.77 | M11: 22181.72 | N11: 0 | O11: 409.05 | P11: 0 | Q11: 0 | R11: 0 | S11: 0 | T11: 0 | U11: 22182 | V11: 0 | W11: 0
A12: 20080014 | B12: BHUJANIYA | C12: MPG | D12: Indirect | E12: 440.56 | F12: 15917.16 | G12: 0 | H12: 0 | I12: 0 | J12: 0 | K12: 0 | L12: 0 | M12: 15917.16 | N12: 0 | O12: 0 | P12: 0 | Q12: 0 | R12: 0 | S12: 0 | T12: 0 | U12: 0 | V12: 0 | W12: 15917.16
A13: 20080025 | B13: DAARU | C13: MPG | D13: Indirect | E13: 480.88 | F13: 16849.43 | G13: 0 | H13: 0 | I13: 0 | J13: 0 | K13: 0 | L13: 0 | M13: 16849.43 | N13: 0 | O13: 0 | P13: 0 | Q13: 0 | R13: 0 | S13: 0 | T13: 0 | U13: 0 | V13: 0 | W13: 16849.43
A14: 20080026 | B14: CHHARDA | C14: MPG | D14: Direct | E14: 259.18 | F14: 9779.77 | G14: 266.52 | H14: 10129.94 | I14: 0 | J14: 0 | K14: 266.52 | L14: 10129.94 | M14: 9779.77 | N14: 0 | O14: 350.17 | P14: 0 | Q14: 0 | R14: 0 | S14: 0 | T14: 0 | U14: 9780 | V14: 0 | W14: 0
A15: 20080008 | B15: Ningni | C15: MPG | D15: Direct | E15: 863.96 | F15: 32771.31 | G15: 868.77 | H15: 32717.48 | I15: 0 | J15: 0 | K15: 868.77 | L15: 32717.48 | M15: 32717.48 | N15: 0 | O15: 0 | P15: 0 | Q15: 0 | R15: 0 | S15: 0 | T15: 0 | U15: 32717 | V15: 0 | W15: 0
A16: 20080028 | B16: BASRI NAGRA | C16: MPG | D16: Direct | E16: 211.42 | F16: 8947.19 | G16: 211.99 | H16: 8854.91 | I16: 0 | J16: 0 | K16: 211.99 | L16: 8854.91 | M16: 8854.91 | N16: 0 | O16: 0 | P16: 0 | Q16: 0 | R16: 0 | S16: 0 | T16: 0 | U16: 8855 | V16: 0 | W16: 0
... A27: 20080050 | B27: KACHMACHI 2 | C27: MPG | D27: Direct | E27: 225.04 | F27: 8504 | G27: 225.09 | H27: 8457.55 | I27: 0 | J27: 0 | K27: 225.09 | L27: 8457.55 | M27: 8457.55 | N27: 0 | O27: 0 | P27: 0 | Q27: 0 | R27: 0 | S27: 0 | T27: 0 | U27: 8457 | V27: 0 | W27: 0
A28: Grand Total | E28: 16523.04 | F28: 634420.81 | G28: 14367.58 | H28: 566072.16 | I28: 0 | J28: 0 | K28: 14367.58 | L28: 566072.16 | M28: 633161.89 | N28: 0 | O28: 16977.26 | P28: 0 | Q28: 0 | R28: 0 | S28: 0 | T28: 0 | U28: 549094 | V28: 0 | W28: 84066.99

Sheet Farmer PDF
A1: BMC Area | B1: (All)
A2: Category | B2: Direct | C2: Payment cycle-08th to 14th May'26
F4: Values
A5: Code | B5: Farmers Code | C5: Farmers Account Name | D5: Accont no | E5: IFSC code | F5: Vol_L | G5: Amount | H5: TS Loss | I5: CF Deduction | J5: Vet Deduction | K5: Deduction for excess Payment | L5: Milk Short | M5: Net Amount
A6: 20010001 | B6: 0002 | C6: AMIT KUMAR TIWARI | D6: 7125658980 | E6: IDIB000I021 | F6: 9769 | G6: 417636.15 | H6: 14964 | I6: 0 | J6: 0 | K6: 0 | L6: 0 | M6: 402672
A7: 20010001 | B7: 0004 | C7: BIRSA ORAON | D7: 358702010006943 | E7: UBIN0535877 | F7: 21.58 | G7: 1026.4586 | H7: 0 | I7: 0 | J7: 0 | K7: 0 | L7: 0 | M7: 1026
A8: 20010001 | B8: 0010 | C8: SHANTI DEVI | D8: 6496430309 | E8: IDIB000I021 | F8: 58.76 | G8: 2666.0376 | H8: 0 | I8: 0 | J8: 0 | K8: 0 | L8: 0 | M8: 2666
A9: 20010001 | B9: 0016 | C9: Suko Tirki | D9: 7100914953 | E9: IDIB000I021 | F9: 27.04 | G9: 1148.0662 | H9: 0 | I9: 0 | J9: 0 | K9: 0 | L9: 0 | M9: 1148
A10: 20010001 | B10: 0017 | C10: Bikram Gope | D10: 358702010006937 | E10: UBIN0535877 | F10: 17.98 | G10: 769.6052 | H10: 0 | I10: 0 | J10: 0 | K10: 0 | L10: 0 | M10: 770
A11: 20010001 | B11: 0019 | C11: Hiramani Kachhap | D11: 494310110016645 | E11: BKID0004943 | F11: 37.3 | G11: 1471.0452 | H11: 0 | I11: 0 | J11: 0 | K11: 0 | L11: 0 | M11: 1471
A12: 20010001 | B12: 0046 | C12: DHANI MAHALI | D12: 358702010628606 | E12: UBIN0535877 | F12: 53.26 | G12: 2076.4026 | H12: 0 | I12: 0 | J12: 0 | K12: 0 | L12: 0 | M12: 2076
A13: 20010001 | B13: 0047 | C13: Kusum Tirki | D13: 6511075905 | E13: IDIB000I021 | F13: 27.6 | G13: 1065.9122 | H13: 0 | I13: 0 | J13: 0 | K13: 0 | L13: 0 | M13: 1066
A14: 20010001 | B14: 0048 | C14: Anil Tirki | D14: 358702010004453 | E14: UBIN0535877 | F14: 37.54 | G14: 1563.155 | H14: 0 | I14: 0 | J14: 0 | K14: 0 | L14: 0 | M14: 1563
A15: 20010001 | B15: 0050 | C15: SABITA TIWARI | D15: 762901500038 | E15: ICIC0007629 | F15: 140 | G15: 5681.6 | H15: 0 | I15: 0 | J15: 0 | K15: 0 | L15: 0 | M15: 5682
A16: 20010001 | B16: 0051 | C16: SAHIL RAJ | D16: 40723769931 | E16: SBIN0000081 | F16: 72 | G16: 2923.55 | H16: 0 | I16: 0 | J16: 0 | K16: 0 | L16: 0 | M16: 2924
A17: 20010001 | B17: 0064 | C17: SOHEL ANSARI | D17: 358702120002626 | E17: UBIN0535877 | F17: 54.8 | G17: 2449.294 | H17: 0 | I17: 0 | J17: 0 | K17: 0 | L17: 0 | M17: 2449
... A26: 20010001 | B26: 0082 | C26: CHANDRA CHUDAMANI PATHAK | D26: 59103904965996 | E26: HDFC0008691 | F26: 804.94 | G26: 32214.236 | H26: 0 | I26: 0 | J26: 0 | K26: 0 | L26: 0 | M26: 32214
A27: 20010001 Total | F27: 11528.02 | G27: 489944.47 | H27: 14964 | I27: 0 | J27: 0 | K27: 0 | L27: 0 | M27: 474980
A28: 20010003 | B28: 0003 | C28: PINKI DEVI | D28: 4895101003786 | E28: CNRB0004895 | F28: 1183.71 | G28: 47883.822 | H28: 0 | I28: 7620 | J28: 0 | K28: 0 | L28: 20 | M28: 40244
A29: 20010003 | B29: 0013 | C29: JOSEF LAKRA | D29: 495910510003202 | E29: BKID0004959 | F29: 38.9 | G29: 1877.992 | H29: 0 | I29: 0 | J29: 0 | K29: 0 | L29: 500 | M29: 1378
A30: 20010003 | B30: 0026 | C30: Pankaj Tigga | D30: 41383270689 | E30: SBIN0012618 | F30: 31.96 | G30: 1303.1576 | H30: 0 | I30: 1270 | J30: 0 | K30: 0 | L30: 33 | M30: 0
A31: 20010003 | B31: 0044 | C31: Manju Devi | D31: 08030100922544 | E31: UCBA0000803 | F31: 23.45 | G31: 1011.0627 | H31: 0 | I31: 0 | J31: 0 | K31: 0 | L31: 200 | M31: 811
A32: 20010003 | B32: 0077 | C32: PUNAM SINHA | D32: 495910100000166 | E32: BKID0004959 | F32: 5.35 | G32: 242.203 | H32: 0 | I32: 0 | J32: 0 | K32: 0 | L32: 0 | M32: 242
A33: 20010003 | B33: 0080 | C33: GEETA TANA BHAGTAIN | D33: 08033211029311 | E33: UCBA0000803 | F33: 8.22 | G33: 447.5265 | H33: 0 | I33: 0 | J33: 0 | K33: 0 | L33: 0 | M33: 448
A34: 20010003 | B34: 0105 | C34: SUKA TANA BHAGAT | D34: 08030100921195 | E34: UCBA0000803 | F34: 11.73 | G34: 569.2787 | H34: 0 | I34: 0 | J34: 0 | K34: 0 | L34: 426 | M34: 143
A35: 20010003 | B35: 0112 | C35: BANDE ORAON | D35: 495910510003218 | E35: BKID0004959 | F35: 40.63 | G35: 2002.2369 | H35: 0 | I35: 0 | J35: 0 | K35: 0 | L35: 300 | M35: 1702
A36: 20010003 | B36: 0116 | C36: ANITA DEVI | D36: 495918210005225 | E36: BKID0004959 | F36: 37.32 | G36: 1602.0912 | H36: 0 | I36: 1270 | J36: 0 | K36: 0 | L36: 0 | M36: 332
A37: 20010003 | B37: 0115 | C37: SUNITA KUMARI | D37: 110048432290 | E37: CNRB0004895 | F37: 15.77 | G37: 717.9342 | H37: 0 | I37: 0 | J37: 0 | K37: 0 | L37: 0 | M37: 718
A38: 20010003 Total | F38: 1397.04 | G38: 57657.305 | H38: 0 | I38: 10160 | J38: 0 | K38: 0 | L38: 1479 | M38: 46018
A39: 20010005 | B39: 0002 | C39: SAJJAD ANSARI | D39: 20421406720 | E39: SBIN0014340 | F39: 89.5 | G39: 3691.875 | H39: 0 | I39: 0 | J39: 0 | K39: 0 | L39: 0 | M39: 3692
A40: 20010005 | B40: 0005 | C40: MUNEJA KHATUN | D40: 494318210006630 | E40: BKID0004943 | F40: 47.37 | G40: 1864.3849 | H40: 0 | I40: 0 | J40: 0 | K40: 0 | L40: 0 | M40: 1864
A41: 20010005 | B41: 0008 | C41: ANISA KHATUN | D41: 50370873265 | E41: IDIB000N518 | F41: 35.21 | G41: 1504.7457 | H41: 0 | I41: 0 | J41: 0 | K41: 0 | L41: 0 | M41: 1505
A42: 20010005 | B42: 0009 | C42: RABUL ANSARI | D42: 494318210000448 | E42: BKID0004943 | F42: 51.19 | G42: 2129.8845 | H42: 0 | I42: 0 | J42: 0 | K42: 0 | L42: 0 | M42: 2130
A43: 20010005 | B43: 0011 | C43: EYASIN ANSARI | D43: 50363172838 | E43: IDIB000N518 | F43: 42.23 | G43: 2046.4712 | H43: 0 | I43: 0 | J43: 0 | K43: 0 | L43: 0 | M43: 2046
A44: 20010005 | B44: 0012 | C44: TAIRUN NISHA | D44: 371101000005005 | E44: IOBA0003711 | F44: 10.77 | G44: 513.242 | H44: 0 | I44: 0 | J44: 0 | K44: 0 | L44: 0 | M44: 513
A45: 20010005 | B45: 0014 | C45: SALIM ANSARI | D45: 494310110018804 | E45: BKID0004943 | F45: 52.81 | G45: 2472.5713 | H45: 0 | I45: 0 | J45: 0 | K45: 0 | L45: 0 | M45: 2473
A46: 20010005 | B46: 0016 | C46: ASIYA KHATOON | D46: 494318210006966 | E46: BKID0004943 | F46: 1.63 | G46: 64.5397 | H46: 0 | I46: 0 | J46: 0 | K46: 0 | L46: 0 | M46: 65
A47: 20010005 | B47: 0022 | C47: SHEIKH SAFIQUE | D47: 494310100000875 | E47: BKID0004943 | F47: 7.64 | G47: 278.2609 | H47: 0 | I47: 0 | J47: 0 | K47: 0 | L47: 0 | M47: 278
A48: 20010005 | B48: 0023 | C48: JOHRA KHATOON | D48: 50369500332 | E48: IDIB000N518 | F48: 24.88 | G48: 1007.5236 | H48: 0 | I48: 0 | J48: 0 | K48: 0 | L48: 0 | M48: 1008
A49: 20010005 | B49: 0029 | C49: IMAM ANSARI | D49: 494318210005769 | E49: BKID0004943 | F49: 19.35 | G49: 795.6549 | H49: 0 | I49: 0 | J49: 0 | K49: 0 | L49: 0 | M49: 796
...

Sheet MPG Performance
I1: 8 | O1: -0.1 | P1: -0.03 | S1: 201
A2: BMC Code | B2: MPG Code | C2: MPG NAME | D2: Type | E2: Farmer Payment | F2: MPG Start Date | G2: Vol Ltr/Day | H2: Nos Of Farmer | I2: Avg pouring/farmer | J2: Total MPG Pouring Shift | K2: Manual Shift | L2: Assets Value | M2: Ideal Sample | N2: Actual Sample | O2: Sample Diff % | P2: MPG Loss/Gain% | Q2: CF Sales | R2: MPG Cow% | S2: BMC Cow% | T2: Diff
A3: ='MPG Payment'!A4 -> BMC Code :2001 | B3: ='MPG Payment'!B4 -> 20010001 | C3: ='MPG Payment'!C4 -> Itki | D3: ='MPG Payment'!D4 -> RMC | E3: ='MPG Payment'!E4 -> Direct | G3: ='MPG Payment'!F4/3 -> 3842.6533 | H3: =COUNTIF('Farmer Payment Calc'!D:D,'MPG Performance'!B3) -> 21 | I3: =IFERROR(G3/J3/H3*2,0) -> 26.140499 | J3: 14 | K3: 0 | L3: ='MPG Payment'!#REF! -> #REF! | M3: =SUMIF('Farmer Payment Calc'!D:D,'MPG Performance'!B3,'Farmer Payment Calc'!Y:Y) -> 414.68119 | N3: ='MPG Payment'!P4 -> 0 | O3: =IFERROR(N3-M3/M3,0) -> -1 | P3: ='MPG Payment'!AB4 -> -5.6474231e-05 | Q3: ='MPG Payment'!R4 -> 0 | R3: 0.6416872 | S3: 0.63564064 | T3: =R3-S3 -> 0.0060465611
A4: ='MPG Payment'!A5 -> BMC Code :2001 | B4: ='MPG Payment'!B5 -> 20010002 | C4: ='MPG Payment'!C5 -> Jamtoli | D4: ='MPG Payment'!D5 -> MPG | E4: ='MPG Payment'!E5 -> Direct | G4: ='MPG Payment'!F5/3 -> 4.3933333 | H4: =COUNTIF('Farmer Payment Calc'!D:D,'MPG Performance'!B4) -> 1 | I4: =IFERROR(G4/J4/H4*2,0) -> 0.9762963 | J4: 9 | K4: 0 | L4: ='MPG Payment'!#REF! -> #REF! | M4: =SUMIF('Farmer Payment Calc'!D:D,'MPG Performance'!B4,'Farmer Payment Calc'!Y:Y) -> 2.0625 | N4: ='MPG Payment'!P5 -> 0 | O4: =IFERROR(N4-M4/M4,0) -> -1 | P4: ='MPG Payment'!AB5 -> -0.0067421141 | Q4: ='MPG Payment'!R5 -> 0 | R4: 0.74174054 | S4: 1 | T4: =R4-S4 -> -0.25825946
A5: ='MPG Payment'!A6 -> BMC Code :2001 | B5: ='MPG Payment'!B6 -> 20010003 | C5: ='MPG Payment'!C6 -> Bero | D5: ='MPG Payment'!D6 -> MPG | E5: ='MPG Payment'!E6 -> Direct | G5: ='MPG Payment'!F6/3 -> 462.39 | H5: =COUNTIF('Farmer Payment Calc'!D:D,'MPG Performance'!B5) -> 10 | I5: =IFERROR(G5/J5/H5*2,0) -> 6.6055714 | J5: 14 | K5: 0 | L5: ='MPG Payment'!#REF! -> #REF! | M5: =SUMIF('Farmer Payment Calc'!D:D,'MPG Performance'!B5,'Farmer Payment Calc'!Y:Y) -> 135.28572 | N5: ='MPG Payment'!P6 -> 0 | O5: =IFERROR(N5-M5/M5,0) -> -1 | P5: ='MPG Payment'!AB6 -> 0.026332821 | Q5: ='MPG Payment'!R6 -> 10160 | R5: 0.6664974 | S5: 0.79953999 | T5: =R5-S5 -> -0.13304259
A6: ='MPG Payment'!A7 -> BMC Code :2001 | B6: ='MPG Payment'!B7 -> 20010005 | C6: ='MPG Payment'!C7 -> Basila | D6: ='MPG Payment'!D7 -> MPG | E6: ='MPG Payment'!E7 -> Direct | G6: ='MPG Payment'!F7/3 -> 458.14 | H6: =COUNTIF('Farmer Payment Calc'!D:D,'MPG Performance'!B6) -> 23 | I6: =IFERROR(G6/J6/H6*2,0) -> 2.8455901 | J6: 14 | K6: 0 | L6: ='MPG Payment'!#REF! -> #REF! | M6: =SUMIF('Farmer Payment Calc'!D:D,'MPG Performance'!B6,'Farmer Payment Calc'!Y:Y) -> 458.55773 | N6: ='MPG Payment'!P7 -> 0 | O6: =IFERROR(N6-M6/M6,0) -> -1 | P6: ='MPG Payment'!AB7 -> -0.00029442448 | Q6: ='MPG Payment'!R7 -> 0 | R6: 0.89433589 | S6: 1 | T6: =R6-S6 -> -0.10566411
A7: ='MPG Payment'!A8 -> BMC Code :2001 | B7: ='MPG Payment'!B8 -> 20010008 | C7: ='MPG Payment'!C8 -> Erchoro | D7: ='MPG Payment'!D8 -> MPG | E7: ='MPG Payment'!E8 -> Direct | G7: ='MPG Payment'!F8/3 -> 405.30667 | H7: =COUNTIF('Farmer Payment Calc'!D:D,'MPG Performance'!B7) -> 14 | I7: =IFERROR(G7/J7/H7*2,0) -> 4.8250794 | J7: 12 | K7: 0 | L7: ='MPG Payment'!#REF! -> #REF! | M7: =SUMIF('Farmer Payment Calc'!D:D,'MPG Performance'!B7,'Farmer Payment Calc'!Y:Y) -> 270.92325 | N7: ='MPG Payment'!P8 -> 0 | O7: =IFERROR(N7-M7/M7,0) -> -1 | P7: ='MPG Payment'!AB8 -> -0.0010467041 | Q7: ='MPG Payment'!R8 -> 0 | R7: 0.5160694 | S7: 0.61848838 | T7: =R7-S7 -> -0.10241898
A8: ='MPG Payment'!A9 -> BMC Code :2001 | B8: ='MPG Payment'!B9 -> 20010009 | C8: ='MPG Payment'!C9 -> Makunda | D8: ='MPG Payment'!D9 -> MPG | E8: ='MPG Payment'!E9 -> Direct | G8: ='MPG Payment'!F9/3 -> 214.81333 | H8: =COUNTIF('Farmer Payment Calc'!D:D,'MPG Performance'!B8) -> 7 | I8: =IFERROR(G8/J8/H8*2,0) -> 4.7211722 | J8: 13 | K8: 0 | L8: ='MPG Payment'!#REF! -> #REF! | M8: =SUMIF('Farmer Payment Calc'!D:D,'MPG Performance'!B8,'Farmer Payment Calc'!Y:Y) -> 147.59644 | N8: ='MPG Payment'!P9 -> 0 | O8: =IFERROR(N8-M8/M8,0) -> -1 | P8: ='MPG Payment'!AB9 -> -0.0016325476 | Q8: ='MPG Payment'!R9 -> 0 | R8: 0 | S8: 0.88561644 | T8: =R8-S8 -> -0.88561644
A9: ='MPG Payment'!A10 -> BMC Code :2001 | B9: ='MPG Payment'!B10 -> 20010012 | C9: ='MPG Payment'!C10 -> NAGRI | D9: ='MPG Payment'!D10 -> VLC | E9: ='MPG Payment'!E10 -> Indirect | G9: ='MPG Payment'!F10/3 -> 92.166667 | H9: =COUNTIF('Farmer Payment Calc'!D:D,'MPG Performance'!B9) -> 0 | I9: =IFERROR(G9/J9/H9*2,0) -> 0 | J9: 14 | K9: 0 | L9: ='MPG Payment'!#REF! -> #REF! | M9: =SUMIF('Farmer Payment Calc'!D:D,'MPG Performance'!B9,'Farmer Payment Calc'!Y:Y) -> 0 | N9: ='MPG Payment'!P10 -> 0 | O9: =IFERROR(N9-M9/M9,0) -> 0 | P9: ='MPG Payment'!AB10 -> -1 | Q9: ='MPG Payment'!R10 -> 0 | R9: 0.82014661 | S9: 0.957239 | T9: =R9-S9 -> -0.13709239
A10: ='MPG Payment'!A11 -> BMC Code :2001 | B10: ='MPG Payment'!B11 -> 20010015 | C10: ='MPG Payment'!C11 -> BOREYA | D10: ='MPG Payment'!D11 -> MPG | E10: ='MPG Payment'!E11 -> Direct | G10: ='MPG Payment'!F11/3 -> 887.1 | H10: =COUNTIF('Farmer Payment Calc'!D:D,'MPG Performance'!B10) -> 53 | I10: =IFERROR(G10/J10/H10*2,0) -> 4.7822102 | J10: 7 | K10: 0 | L10: ='MPG Payment'!#REF! -> #REF! | M10: =SUMIF('Farmer Payment Calc'!D:D,'MPG Performance'!B10,'Farmer Payment Calc'!Y:Y) -> 1123.5397 | N10: ='MPG Payment'!P11 -> 0 | O10: =IFERROR(N10-M10/M10,0) -> -1 | P10: ='MPG Payment'!AB11 -> -0.0029764747 | Q10: ='MPG Payment'!R11 -> 0 | R10: 0.6066686 | S10: 0.86905567 | T10: =R10-S10 -> -0.26238707
A11: ='MPG Payment'!A12 -> BMC Code :2001 | B11: ='MPG Payment'!B12 -> 20010017 | C11: ='MPG Payment'!C12 -> DIGHIYA | D11: ='MPG Payment'!D12 -> MPG | E11: ='MPG Payment'!E12 -> Direct | G11: ='MPG Payment'!F12/3 -> 107.75333 | H11: =COUNTIF('Farmer Payment Calc'!D:D,'MPG Performance'!B11) -> 9 | I11: =IFERROR(G11/J11/H11*2,0) -> 1.7103704 | J11: 14 | K11: 0 | L11: ='MPG Payment'!#REF! -> #REF! | M11: =SUMIF('Farmer Payment Calc'!D:D,'MPG Performance'!B11,'Farmer Payment Calc'!Y:Y) -> 137.90864 | N11: ='MPG Payment'!P12 -> 0 | O11: =IFERROR(N11-M11/M11,0) -> -1 | P11: ='MPG Payment'!AB12 -> 0.028762405 | Q11: ='MPG Payment'!R12 -> 0 | R11: 0.80666745 | S11: 1 | T11: =R11-S11 -> -0.19333255
A12: ='MPG Payment'!A13 -> BMC Code :2001 | B12: ='MPG Payment'!B13 -> 20010023 | C12: ='MPG Payment'!C13 -> KATARPA | D12: ='MPG Payment'!D13 -> MPG | E12: ='MPG Payment'!E13 -> Direct | G12: ='MPG Payment'!F13/3 -> 272.72667 | H12: =COUNTIF('Farmer Payment Calc'!D:D,'MPG Performance'!B12) -> 22 | I12: =IFERROR(G12/J12/H12*2,0) -> 1.7709524 | J12: 14 | K12: 0 | L12: ='MPG Payment'!#REF! -> #REF! | M12: =SUMIF('Farmer Payment Calc'!D:D,'MPG Performance'!B12,'Farmer Payment Calc'!Y:Y) -> 488.37975 | N12: ='MPG Payment'!P13 -> 0 | O12: =IFERROR(N12-M12/M12,0) -> -1 | P12: ='MPG Payment'!AB13 -> -0.00092754711 | Q12: ='MPG Payment'!R13 -> 0 | R12: 0.41330465 | S12: 0.3946809 | T12: =R12-S12 -> 0.018623749
A13: ='MPG Payment'!A14 -> BMC Code :2001 | B13: ='MPG Payment'!B14 -> 20010027 | C13: ='MPG Payment'!C14 -> MURTO | D13: ='MPG Payment'!D14 -> MPG | E13: ='MPG Payment'!E14 -> Direct | G13: ='MPG Payment'!F14/3 -> 101.16667 | H13: =COUNTIF('Farmer Payment Calc'!D:D,'MPG Performance'!B13) -> 10 | I13: =IFERROR(G13/J13/H13*2,0) -> 1.4452381 | J13: 14 | K13: 0 | L13: ='MPG Payment'!#REF! -> #REF! | M13: =SUMIF('Farmer Payment Calc'!D:D,'MPG Performance'!B13,'Farmer Payment Calc'!Y:Y) -> 186.32317 | N13: ='MPG Payment'!P14 -> 0 | O13: =IFERROR(N13-M13/M13,0) -> -1 | P13: ='MPG Payment'!AB14 -> -0.002747345 | Q13: ='MPG Payment'!R14 -> 0 | R13: 0.43230464 | S13: 0.022246663 | T13: =R13-S13 -> 0.41005798
A14: ='MPG Payment'!A15 -> BMC Code :2001 | B14: ='MPG Payment'!B15 -> 20010033 | C14: ='MPG Payment'!C15 -> KHATRIKHATANGA | D14: ='MPG Payment'!D15 -> MPG | E14: ='MPG Payment'!E15 -> Direct | G14: ='MPG Payment'!F15/3 -> 123.14667 | H14: =COUNTIF('Farmer Payment Calc'!D:D,'MPG Performance'!B14) -> 2 | I14: =IFERROR(G14/J14/H14*2,0) -> 8.7961905 | J14: 14 | K14: 0 | L14: ='MPG Payment'!#REF! -> #REF! | M14: =SUMIF('Farmer Payment Calc'!D:D,'MPG Performance'!B14,'Farmer Payment Calc'!Y:Y) -> 66.261054 | N14: ='MPG Payment'!P15 -> 0 | O14: =IFERROR(N14-M14/M14,0) -> -1 | P14: ='MPG Payment'!AB15 -> 0.021549177 | Q14: ='MPG Payment'!R15 -> 0 | R14: 0.64557696 | S14: 0.65580318 | T14: =R14-S14 -> -0.010226216
... A113: ='MPG Payment'!A114 -> BMC Code :2008 | B113: ='MPG Payment'!B114 -> 20080043 | C113: ='MPG Payment'!C114 -> JATARGARI | D113: ='MPG Payment'!D114 -> MPG | E113: ='MPG Payment'!E114 -> Direct | G113: ='MPG Payment'!F114/3 -> 173.79333 | H113: =COUNTIF('Farmer Payment Calc'!D:D,'MPG Performance'!B113) -> 6 | I113: =IFERROR(G113/J113/H113*2,0) -> 4.1379365 | J113: 14 | K113: 0 | L113: ='MPG Payment'!#REF! -> #REF! | M113: =SUMIF('Farmer Payment Calc'!D:D,'MPG Performance'!B113,'Farmer Payment Calc'!Y:Y) -> 90.181117 | N113: ='MPG Payment'!P114 -> 0 | O113: =IFERROR(N113-M113/M113,0) -> -1 | P113: ='MPG Payment'!AB114 -> -0.013117846 | Q113: ='MPG Payment'!R114 -> 0 | R113: 0.96104746 | S113: 0.96104746 | T113: =R113-S113 -> 0
A114: ='MPG Payment'!A120 -> BMC Code :2009 | B114: ='MPG Payment'!B120 -> 20090010 | C114: ='MPG Payment'!C120 -> CHATWAL | D114: ='MPG Payment'!D120 -> VLC | E114: ='MPG Payment'!E120 -> Indirect | G114: ='MPG Payment'!F120/3 -> 140.9 | H114: =COUNTIF('Farmer Payment Calc'!D:D,'MPG Performance'!B114) -> 0 | I114: =IFERROR(G114/J114/H114*2,0) -> 0 | J114: 14 | K114: 0 | L114: ='MPG Payment'!#REF! -> #REF! | M114: =SUMIF('Farmer Payment Calc'!D:D,'MPG Performance'!B114,'Farmer Payment Calc'!Y:Y) -> 0 | N114: ='MPG Payment'!P120 -> 0 | O114: =IFERROR(N114-M114/M114,0) -> 0 | P114: ='MPG Payment'!AB120 -> -1 | Q114: ='MPG Payment'!R120 -> 0 | R114: 0.91697902 | S114: 1 | T114: =R114-S114 -> -0.083020981
A115: ='MPG Payment'!#REF! -> #REF! | B115: ='MPG Payment'!#REF! -> #REF! | C115: ='MPG Payment'!#REF! -> #REF! | D115: ='MPG Payment'!#REF! -> #REF! | E115: ='MPG Payment'!#REF! -> #REF! | G115: ='MPG Payment'!#REF!/3 -> #REF! | H115: =COUNTIF('Farmer Payment Calc'!D:D,'MPG Performance'!B115) -> 0 | I115: =IFERROR(G115/J115/H115*2,0) -> 0 | J115: 14 | K115: 0 | L115: ='MPG Payment'!#REF! -> #REF! | M115: =SUMIF('Farmer Payment Calc'!D:D,'MPG Performance'!B115,'Farmer Payment Calc'!Y:Y) -> 0 | N115: ='MPG Payment'!#REF! -> #REF! | O115: =IFERROR(N115-M115/M115,0) -> 0 | P115: ='MPG Payment'!#REF! -> #REF! | Q115: ='MPG Payment'!#REF! -> #REF! | R115: 0.57014451 | S115: 0.92219629 | T115: =R115-S115 -> -0.35205178
A116: ='MPG Payment'!#REF! -> #REF! | B116: ='MPG Payment'!#REF! -> #REF! | C116: ='MPG Payment'!#REF! -> #REF! | D116: ='MPG Payment'!#REF! -> #REF! | E116: ='MPG Payment'!#REF! -> #REF! | G116: ='MPG Payment'!#REF!/3 -> #REF! | H116: =COUNTIF('Farmer Payment Calc'!D:D,'MPG Performance'!B116) -> 0 | I116: =IFERROR(G116/J116/H116*2,0) -> 0 | J116: 14 | K116: 0 | L116: ='MPG Payment'!#REF! -> #REF! | M116: =SUMIF('Farmer Payment Calc'!D:D,'MPG Performance'!B116,'Farmer Payment Calc'!Y:Y) -> 0 | N116: ='MPG Payment'!#REF! -> #REF! | O116: =IFERROR(N116-M116/M116,0) -> 0 | P116: ='MPG Payment'!#REF! -> #REF! | Q116: ='MPG Payment'!#REF! -> #REF! | R116: 0.48514731 | S116: 1 | T116: =R116-S116 -> -0.51485269
A117: ='MPG Payment'!#REF! -> #REF! | B117: ='MPG Payment'!#REF! -> #REF! | C117: ='MPG Payment'!#REF! -> #REF! | D117: ='MPG Payment'!#REF! -> #REF! | E117: ='MPG Payment'!#REF! -> #REF! | G117: ='MPG Payment'!#REF!/3 -> #REF! | H117: =COUNTIF('Farmer Payment Calc'!D:D,'MPG Performance'!B117) -> 0 | I117: =IFERROR(G117/J117/H117*2,0) -> 0 | J117: 14 | K117: 0 | L117: ='MPG Payment'!#REF! -> #REF! | M117: =SUMIF('Farmer Payment Calc'!D:D,'MPG Performance'!B117,'Farmer Payment Calc'!Y:Y) -> 0 | N117: ='MPG Payment'!#REF! -> #REF! | O117: =IFERROR(N117-M117/M117,0) -> 0 | P117: ='MPG Payment'!#REF! -> #REF! | Q117: ='MPG Payment'!#REF! -> #REF! | R117: 0.58519403 | S117: 1 | T117: =R117-S117 -> -0.41480597
A118: ='MPG Payment'!#REF! -> #REF! | B118: ='MPG Payment'!#REF! -> #REF! | C118: ='MPG Payment'!#REF! -> #REF! | D118: ='MPG Payment'!#REF! -> #REF! | E118: ='MPG Payment'!#REF! -> #REF! | G118: ='MPG Payment'!#REF!/3 -> #REF! | H118: =COUNTIF('Farmer Payment Calc'!D:D,'MPG Performance'!B118) -> 0 | I118: =IFERROR(G118/J118/H118*2,0) -> 0 | J118: 14 | K118: 0 | L118: ='MPG Payment'!#REF! -> #REF! | M118: =SUMIF('Farmer Payment Calc'!D:D,'MPG Performance'!B118,'Farmer Payment Calc'!Y:Y) -> 0 | N118: ='MPG Payment'!#REF! -> #REF! | O118: =IFERROR(N118-M118/M118,0) -> 0 | P118: ='MPG Payment'!#REF! -> #REF! | Q118: ='MPG Payment'!#REF! -> #REF! | R118: 0.81362344 | S118: 0.90685313 | T118: =R118-S118 -> -0.093229695
A119: ='MPG Payment'!#REF! -> #REF! | B119: ='MPG Payment'!#REF! -> #REF! | C119: ='MPG Payment'!#REF! -> #REF! | D119: ='MPG Payment'!#REF! -> #REF! | E119: ='MPG Payment'!#REF! -> #REF! | G119: ='MPG Payment'!#REF!/3 -> #REF! | H119: =COUNTIF('Farmer Payment Calc'!D:D,'MPG Performance'!B119) -> 0 | I119: =IFERROR(G119/J119/H119*2,0) -> 0 | J119: 14 | K119: 0 | L119: ='MPG Payment'!#REF! -> #REF! | M119: =SUMIF('Farmer Payment Calc'!D:D,'MPG Performance'!B119,'Farmer Payment Calc'!Y:Y) -> 0 | N119: ='MPG Payment'!#REF! -> #REF! | O119: =IFERROR(N119-M119/M119,0) -> 0 | P119: ='MPG Payment'!#REF! -> #REF! | Q119: ='MPG Payment'!#REF! -> #REF! | R119: 0.62761286 | S119: 0.74330461 | T119: =R119-S119 -> -0.11569175
A120: ='MPG Payment'!#REF! -> #REF! | B120: ='MPG Payment'!#REF! -> #REF! | C120: ='MPG Payment'!#REF! -> #REF! | D120: ='MPG Payment'!#REF! -> #REF! | E120: ='MPG Payment'!#REF! -> #REF! | G120: ='MPG Payment'!#REF!/3 -> #REF! | H120: =COUNTIF('Farmer Payment Calc'!D:D,'MPG Performance'!B120) -> 0 | I120: =IFERROR(G120/J120/H120*2,0) -> 0 | J120: 14 | K120: 0 | L120: ='MPG Payment'!#REF! -> #REF! | M120: =SUMIF('Farmer Payment Calc'!D:D,'MPG Performance'!B120,'Farmer Payment Calc'!Y:Y) -> 0 | N120: ='MPG Payment'!#REF! -> #REF! | O120: =IFERROR(N120-M120/M120,0) -> 0 | P120: ='MPG Payment'!#REF! -> #REF! | Q120: ='MPG Payment'!#REF! -> #REF! | R120: 0.9699317 | S120: 1 | T120: =R120-S120 -> -0.030068299
A121: ='MPG Payment'!#REF! -> #REF! | B121: ='MPG Payment'!#REF! -> #REF! | C121: ='MPG Payment'!#REF! -> #REF! | D121: ='MPG Payment'!#REF! -> #REF! | E121: ='MPG Payment'!#REF! -> #REF! | G121: ='MPG Payment'!#REF!/3 -> #REF! | H121: =COUNTIF('Farmer Payment Calc'!D:D,'MPG Performance'!B121) -> 0 | I121: =IFERROR(G121/J121/H121*2,0) -> 0 | J121: 14 | K121: 0 | L121: ='MPG Payment'!#REF! -> #REF! | M121: =SUMIF('Farmer Payment Calc'!D:D,'MPG Performance'!B121,'Farmer Payment Calc'!Y:Y) -> 0 | N121: ='MPG Payment'!#REF! -> #REF! | O121: =IFERROR(N121-M121/M121,0) -> 0 | P121: ='MPG Payment'!#REF! -> #REF! | Q121: ='MPG Payment'!#REF! -> #REF! | R121: 0.69273009 | S121: 1 | T121: =R121-S121 -> -0.30726991
A122: ='MPG Payment'!#REF! -> #REF! | B122: ='MPG Payment'!#REF! -> #REF! | C122: ='MPG Payment'!#REF! -> #REF! | D122: ='MPG Payment'!#REF! -> #REF! | E122: ='MPG Payment'!#REF! -> #REF! | G122: ='MPG Payment'!#REF!/3 -> #REF! | H122: =COUNTIF('Farmer Payment Calc'!D:D,'MPG Performance'!B122) -> 0 | I122: =IFERROR(G122/J122/H122*2,0) -> 0 | J122: 14 | K122: 0 | L122: ='MPG Payment'!#REF! -> #REF! | M122: =SUMIF('Farmer Payment Calc'!D:D,'MPG Performance'!B122,'Farmer Payment Calc'!Y:Y) -> 0 | N122: ='MPG Payment'!#REF! -> #REF! | O122: =IFERROR(N122-M122/M122,0) -> 0 | P122: ='MPG Payment'!#REF! -> #REF! | Q122: ='MPG Payment'!#REF! -> #REF! | R122: 0.6652476 | S122: 0.89087743 | T122: =R122-S122 -> -0.22562983
A123: ='MPG Payment'!#REF! -> #REF! | B123: ='MPG Payment'!#REF! -> #REF! | C123: ='MPG Payment'!#REF! -> #REF! | D123: ='MPG Payment'!#REF! -> #REF! | E123: ='MPG Payment'!#REF! -> #REF! | G123: ='MPG Payment'!#REF!/3 -> #REF! | H123: =COUNTIF('Farmer Payment Calc'!D:D,'MPG Performance'!B123) -> 0 | I123: =IFERROR(G123/J123/H123*2,0) -> 0 | J123: 14 | K123: 0 | L123: ='MPG Payment'!#REF! -> #REF! | M123: =SUMIF('Farmer Payment Calc'!D:D,'MPG Performance'!B123,'Farmer Payment Calc'!Y:Y) -> 0 | N123: ='MPG Payment'!#REF! -> #REF! | O123: =IFERROR(N123-M123/M123,0) -> 0 | P123: ='MPG Payment'!#REF! -> #REF! | Q123: ='MPG Payment'!#REF! -> #REF! | R123: 0.99672113 | S123: 1 | T123: =R123-S123 -> -0.0032788714
A124: ='MPG Payment'!#REF! -> #REF! | B124: ='MPG Payment'!#REF! -> #REF! | C124: ='MPG Payment'!#REF! -> #REF! | D124: ='MPG Payment'!#REF! -> #REF! | E124: ='MPG Payment'!#REF! -> #REF! | G124: ='MPG Payment'!#REF!/3 -> #REF! | H124: =COUNTIF('Farmer Payment Calc'!D:D,'MPG Performance'!B124) -> 0 | I124: =IFERROR(G124/J124/H124*2,0) -> 0 | J124: 14 | K124: 0 | L124: ='MPG Payment'!#REF! -> #REF! | M124: =SUMIF('Farmer Payment Calc'!D:D,'MPG Performance'!B124,'Farmer Payment Calc'!Y:Y) -> 0 | N124: ='MPG Payment'!#REF! -> #REF! | O124: =IFERROR(N124-M124/M124,0) -> 0 | P124: ='MPG Payment'!#REF! -> #REF! | Q124: ='MPG Payment'!#REF! -> #REF! | R124: 0 | S124: 1 | T124: =R124-S124 -> -1
A125: ='MPG Payment'!#REF! -> #REF! | B125: ='MPG Payment'!#REF! -> #REF! | C125: ='MPG Payment'!#REF! -> #REF! | D125: ='MPG Payment'!#REF! -> #REF! | E125: ='MPG Payment'!#REF! -> #REF! | G125: ='MPG Payment'!#REF!/3 -> #REF! | H125: =COUNTIF('Farmer Payment Calc'!D:D,'MPG Performance'!B125) -> 0 | I125: =IFERROR(G125/J125/H125*2,0) -> 0 | J125: 14 | K125: 0 | L125: ='MPG Payment'!#REF! -> #REF! | M125: =SUMIF('Farmer Payment Calc'!D:D,'MPG Performance'!B125,'Farmer Payment Calc'!Y:Y) -> 0 | N125: ='MPG Payment'!#REF! -> #REF! | O125: =IFERROR(N125-M125/M125,0) -> 0 | P125: ='MPG Payment'!#REF! -> #REF! | Q125: ='MPG Payment'!#REF! -> #REF! | R125: 1 | S125: 1 | T125: =R125-S125 -> 0
A126: ='MPG Payment'!#REF! -> #REF! | B126: ='MPG Payment'!#REF! -> #REF! | C126: ='MPG Payment'!#REF! -> #REF! | D126: ='MPG Payment'!#REF! -> #REF! | E126: ='MPG Payment'!#REF! -> #REF! | G126: ='MPG Payment'!#REF!/3 -> #REF! | H126: =COUNTIF('Farmer Payment Calc'!D:D,'MPG Performance'!B126) -> 0 | I126: =IFERROR(G126/J126/H126*2,0) -> 0 | J126: 14 | K126: 0 | L126: ='MPG Payment'!#REF! -> #REF! | M126: =SUMIF('Farmer Payment Calc'!D:D,'MPG Performance'!B126,'Farmer Payment Calc'!Y:Y) -> 0 | N126: ='MPG Payment'!#REF! -> #REF! | O126: =IFERROR(N126-M126/M126,0) -> 0 | P126: ='MPG Payment'!#REF! -> #REF! | Q126: ='MPG Payment'!#REF! -> #REF! | R126: 0.89358765 | S126: 0.95163859 | T126: =R126-S126 -> -0.058050936
... A128: ='MPG Payment'!#REF! -> #REF! | B128: ='MPG Payment'!#REF! -> #REF! | C128: ='MPG Payment'!#REF! -> #REF! | D128: ='MPG Payment'!#REF! -> #REF! | E128: ='MPG Payment'!#REF! -> #REF! | G128: ='MPG Payment'!#REF!/3 -> #REF! | H128: =COUNTIF('Farmer Payment Calc'!D:D,'MPG Performance'!B128) -> 0 | I128: =IFERROR(G128/J128/H128*2,0) -> 0 | J128: 14 | K128: 0 | L128: ='MPG Payment'!#REF! -> #REF! | M128: =SUMIF('Farmer Payment Calc'!D:D,'MPG Performance'!B128,'Farmer Payment Calc'!Y:Y) -> 0 | N128: ='MPG Payment'!#REF! -> #REF! | O128: =IFERROR(N128-M128/M128,0) -> 0 | P128: ='MPG Payment'!#REF! -> #REF! | Q128: ='MPG Payment'!#REF! -> #REF! | R128: 0.7136421 | S128: 1 | T128: =R128-S128 -> -0.2863579

Sheet FAR PIVOT
A1: BMC Area | B1: (All)
A2: For the period of 02-08'Feb-24
F3: Values
A4: Code | B4: Farmers Code | C4: Farmers Account Name | D4: Accont no | E4: IFSC code | F4: Vol_L | G4: Amount | H4: Net Amount | I4: Sum of Milk Short
A5: 20010001 | B5: 0002 | C5: AMIT KUMAR TIWARI | D5: 7125658980 | E5: IDIB000I021 | F5: 9769 | G5: 417636.15 | H5: 402672 | I5: 0
A6: 20010001 | B6: 0004 | C6: BIRSA ORAON | D6: 358702010006943 | E6: UBIN0535877 | F6: 21.58 | G6: 1026.4586 | H6: 1026 | I6: 0
A7: 20010001 | B7: 0010 | C7: SHANTI DEVI | D7: 6496430309 | E7: IDIB000I021 | F7: 58.76 | G7: 2666.0376 | H7: 2666 | I7: 0
A8: 20010001 | B8: 0016 | C8: Suko Tirki | D8: 7100914953 | E8: IDIB000I021 | F8: 27.04 | G8: 1148.0662 | H8: 1148 | I8: 0
A9: 20010001 | B9: 0017 | C9: Bikram Gope | D9: 358702010006937 | E9: UBIN0535877 | F9: 17.98 | G9: 769.6052 | H9: 770 | I9: 0
A10: 20010001 | B10: 0019 | C10: Hiramani Kachhap | D10: 494310110016645 | E10: BKID0004943 | F10: 37.3 | G10: 1471.0452 | H10: 1471 | I10: 0
A11: 20010001 | B11: 0046 | C11: DHANI MAHALI | D11: 358702010628606 | E11: UBIN0535877 | F11: 53.26 | G11: 2076.4026 | H11: 2076 | I11: 0
A12: 20010001 | B12: 0047 | C12: Kusum Tirki | D12: 6511075905 | E12: IDIB000I021 | F12: 27.6 | G12: 1065.9122 | H12: 1066 | I12: 0
A13: 20010001 | B13: 0048 | C13: Anil Tirki | D13: 358702010004453 | E13: UBIN0535877 | F13: 37.54 | G13: 1563.155 | H13: 1563 | I13: 0
A14: 20010001 | B14: 0050 | C14: SABITA TIWARI | D14: 762901500038 | E14: ICIC0007629 | F14: 140 | G14: 5681.6 | H14: 5682 | I14: 0
A15: 20010001 | B15: 0064 | C15: SOHEL ANSARI | D15: 358702120002626 | E15: UBIN0535877 | F15: 54.8 | G15: 2449.294 | H15: 2449 | I15: 0
A16: 20010001 | B16: 0066 | C16: SUJIT KUMAR ACHARYA | D16: 07591530000649 | E16: HDFC0000759 | F16: 63 | G16: 2556.72 | H16: 2557 | I16: 0
... A25: 20010001 | B25: 0082 | C25: CHANDRA CHUDAMANI PATHAK | D25: 59103904965996 | E25: HDFC0008691 | F25: 804.94 | G25: 32214.236 | H25: 32214 | I25: 0
A26: 20010001 Total | F26: 11528.02 | G26: 489944.47 | H26: 474980 | I26: 0
A27: 20010003 | B27: 0003 | C27: PINKI DEVI | D27: 4895101003786 | E27: CNRB0004895 | F27: 1183.71 | G27: 47883.822 | H27: 40244 | I27: 20
A28: 20010003 | B28: 0013 | C28: JOSEF LAKRA | D28: 495910510003202 | E28: BKID0004959 | F28: 38.9 | G28: 1877.992 | H28: 1378 | I28: 500
A29: 20010003 | B29: 0026 | C29: Pankaj Tigga | D29: 41383270689 | E29: SBIN0012618 | F29: 31.96 | G29: 1303.1576 | H29: 0 | I29: 33
A30: 20010003 | B30: 0044 | C30: Manju Devi | D30: 08030100922544 | E30: UCBA0000803 | F30: 23.45 | G30: 1011.0627 | H30: 811 | I30: 200
A31: 20010003 | B31: 0077 | C31: PUNAM SINHA | D31: 495910100000166 | E31: BKID0004959 | F31: 5.35 | G31: 242.203 | H31: 242 | I31: 0
A32: 20010003 | B32: 0080 | C32: GEETA TANA BHAGTAIN | D32: 08033211029311 | E32: UCBA0000803 | F32: 8.22 | G32: 447.5265 | H32: 448 | I32: 0
A33: 20010003 | B33: 0105 | C33: SUKA TANA BHAGAT | D33: 08030100921195 | E33: UCBA0000803 | F33: 11.73 | G33: 569.2787 | H33: 143 | I33: 426
A34: 20010003 | B34: 0112 | C34: BANDE ORAON | D34: 495910510003218 | E34: BKID0004959 | F34: 40.63 | G34: 2002.2369 | H34: 1702 | I34: 300
A35: 20010003 | B35: 0116 | C35: ANITA DEVI | D35: 495918210005225 | E35: BKID0004959 | F35: 37.32 | G35: 1602.0912 | H35: 332 | I35: 0
A36: 20010003 | B36: 0115 | C36: SUNITA KUMARI | D36: 110048432290 | E36: CNRB0004895 | F36: 15.77 | G36: 717.9342 | H36: 718 | I36: 0
A37: 20010003 Total | F37: 1397.04 | G37: 57657.305 | H37: 46018 | I37: 1479
A38: 20010005 | B38: 0002 | C38: SAJJAD ANSARI | D38: 20421406720 | E38: SBIN0014340 | F38: 89.5 | G38: 3691.875 | H38: 3692 | I38: 0
A39: 20010005 | B39: 0005 | C39: MUNEJA KHATUN | D39: 494318210006630 | E39: BKID0004943 | F39: 47.37 | G39: 1864.3849 | H39: 1864 | I39: 0
A40: 20010005 | B40: 0008 | C40: ANISA KHATUN | D40: 50370873265 | E40: IDIB000N518 | F40: 35.21 | G40: 1504.7457 | H40: 1505 | I40: 0
A41: 20010005 | B41: 0009 | C41: RABUL ANSARI | D41: 494318210000448 | E41: BKID0004943 | F41: 51.19 | G41: 2129.8845 | H41: 2130 | I41: 0
A42: 20010005 | B42: 0011 | C42: EYASIN ANSARI | D42: 50363172838 | E42: IDIB000N518 | F42: 42.23 | G42: 2046.4712 | H42: 2046 | I42: 0
A43: 20010005 | B43: 0012 | C43: TAIRUN NISHA | D43: 371101000005005 | E43: IOBA0003711 | F43: 10.77 | G43: 513.242 | H43: 513 | I43: 0
A44: 20010005 | B44: 0014 | C44: SALIM ANSARI | D44: 494310110018804 | E44: BKID0004943 | F44: 52.81 | G44: 2472.5713 | H44: 2473 | I44: 0
A45: 20010005 | B45: 0016 | C45: ASIYA KHATOON | D45: 494318210006966 | E45: BKID0004943 | F45: 1.63 | G45: 64.5397 | H45: 65 | I45: 0
A46: 20010005 | B46: 0022 | C46: SHEIKH SAFIQUE | D46: 494310100000875 | E46: BKID0004943 | F46: 7.64 | G46: 278.2609 | H46: 278 | I46: 0
A47: 20010005 | B47: 0023 | C47: JOHRA KHATOON | D47: 50369500332 | E47: IDIB000N518 | F47: 24.88 | G47: 1007.5236 | H47: 1008 | I47: 0
A48: 20010005 | B48: 0029 | C48: IMAM ANSARI | D48: 494318210005769 | E48: BKID0004943 | F48: 19.35 | G48: 795.6549 | H48: 796 | I48: 0
...

Sheet FARMER
A1: BMC Area | B1: (All)
A2: For the period of 08-14 Nov'24
F3: Values
A4: Code | B4: Farmers Code | C4: Farmers Account Name | D4: Accont no | E4: IFSC code | F4: Sum of Vol_L | G4: Sum of Amount | H4: Sum of Milk Short | I4: Sum of Net Amount
A5: 20010001 | B5: 0002 | C5: AMIT KUMAR TIWARI | D5: 7125658980 | E5: IDIB000I021 | F5: 9769 | G5: 417636.15 | H5: 0 | I5: 402672
A6: 20010001 | B6: 0004 | C6: BIRSA ORAON | D6: 358702010006943 | E6: UBIN0535877 | F6: 21.58 | G6: 1026.4586 | H6: 0 | I6: 1026
A7: 20010001 | B7: 0010 | C7: SHANTI DEVI | D7: 6496430309 | E7: IDIB000I021 | F7: 58.76 | G7: 2666.0376 | H7: 0 | I7: 2666
A8: 20010001 | B8: 0016 | C8: Suko Tirki | D8: 7100914953 | E8: IDIB000I021 | F8: 27.04 | G8: 1148.0662 | H8: 0 | I8: 1148
A9: 20010001 | B9: 0017 | C9: Bikram Gope | D9: 358702010006937 | E9: UBIN0535877 | F9: 17.98 | G9: 769.6052 | H9: 0 | I9: 770
A10: 20010001 | B10: 0019 | C10: Hiramani Kachhap | D10: 494310110016645 | E10: BKID0004943 | F10: 37.3 | G10: 1471.0452 | H10: 0 | I10: 1471
A11: 20010001 | B11: 0046 | C11: DHANI MAHALI | D11: 358702010628606 | E11: UBIN0535877 | F11: 53.26 | G11: 2076.4026 | H11: 0 | I11: 2076
A12: 20010001 | B12: 0047 | C12: Kusum Tirki | D12: 6511075905 | E12: IDIB000I021 | F12: 27.6 | G12: 1065.9122 | H12: 0 | I12: 1066
A13: 20010001 | B13: 0048 | C13: Anil Tirki | D13: 358702010004453 | E13: UBIN0535877 | F13: 37.54 | G13: 1563.155 | H13: 0 | I13: 1563
A14: 20010001 | B14: 0050 | C14: SABITA TIWARI | D14: 762901500038 | E14: ICIC0007629 | F14: 140 | G14: 5681.6 | H14: 0 | I14: 5682
A15: 20010001 | B15: 0051 | C15: SAHIL RAJ | D15: 40723769931 | E15: SBIN0000081 | F15: 72 | G15: 2923.55 | H15: 0 | I15: 2924
A16: 20010001 | B16: 0064 | C16: SOHEL ANSARI | D16: 358702120002626 | E16: UBIN0535877 | F16: 54.8 | G16: 2449.294 | H16: 0 | I16: 2449
... A25: 20010001 | B25: 0082 | C25: CHANDRA CHUDAMANI PATHAK | D25: 59103904965996 | E25: HDFC0008691 | F25: 804.94 | G25: 32214.236 | H25: 0 | I25: 32214
A26: 20010001 Total | F26: 11528.02 | G26: 489944.47 | H26: 0 | I26: 474980
A27: 20010003 | B27: 0003 | C27: PINKI DEVI | D27: 4895101003786 | E27: CNRB0004895 | F27: 1183.71 | G27: 47883.822 | H27: 20 | I27: 40244
A28: 20010003 | B28: 0013 | C28: JOSEF LAKRA | D28: 495910510003202 | E28: BKID0004959 | F28: 38.9 | G28: 1877.992 | H28: 500 | I28: 1378
A29: 20010003 | B29: 0026 | C29: Pankaj Tigga | D29: 41383270689 | E29: SBIN0012618 | F29: 31.96 | G29: 1303.1576 | H29: 33 | I29: 0
A30: 20010003 | B30: 0044 | C30: Manju Devi | D30: 08030100922544 | E30: UCBA0000803 | F30: 23.45 | G30: 1011.0627 | H30: 200 | I30: 811
A31: 20010003 | B31: 0077 | C31: PUNAM SINHA | D31: 495910100000166 | E31: BKID0004959 | F31: 5.35 | G31: 242.203 | H31: 0 | I31: 242
A32: 20010003 | B32: 0080 | C32: GEETA TANA BHAGTAIN | D32: 08033211029311 | E32: UCBA0000803 | F32: 8.22 | G32: 447.5265 | H32: 0 | I32: 448
A33: 20010003 | B33: 0105 | C33: SUKA TANA BHAGAT | D33: 08030100921195 | E33: UCBA0000803 | F33: 11.73 | G33: 569.2787 | H33: 426 | I33: 143
A34: 20010003 | B34: 0112 | C34: BANDE ORAON | D34: 495910510003218 | E34: BKID0004959 | F34: 40.63 | G34: 2002.2369 | H34: 300 | I34: 1702
A35: 20010003 | B35: 0116 | C35: ANITA DEVI | D35: 495918210005225 | E35: BKID0004959 | F35: 37.32 | G35: 1602.0912 | H35: 0 | I35: 332
A36: 20010003 | B36: 0115 | C36: SUNITA KUMARI | D36: 110048432290 | E36: CNRB0004895 | F36: 15.77 | G36: 717.9342 | H36: 0 | I36: 718
A37: 20010003 Total | F37: 1397.04 | G37: 57657.305 | H37: 1479 | I37: 46018
A38: 20010005 | B38: 0002 | C38: SAJJAD ANSARI | D38: 20421406720 | E38: SBIN0014340 | F38: 89.5 | G38: 3691.875 | H38: 0 | I38: 3692
A39: 20010005 | B39: 0005 | C39: MUNEJA KHATUN | D39: 494318210006630 | E39: BKID0004943 | F39: 47.37 | G39: 1864.3849 | H39: 0 | I39: 1864
A40: 20010005 | B40: 0008 | C40: ANISA KHATUN | D40: 50370873265 | E40: IDIB000N518 | F40: 35.21 | G40: 1504.7457 | H40: 0 | I40: 1505
A41: 20010005 | B41: 0009 | C41: RABUL ANSARI | D41: 494318210000448 | E41: BKID0004943 | F41: 51.19 | G41: 2129.8845 | H41: 0 | I41: 2130
A42: 20010005 | B42: 0011 | C42: EYASIN ANSARI | D42: 50363172838 | E42: IDIB000N518 | F42: 42.23 | G42: 2046.4712 | H42: 0 | I42: 2046
A43: 20010005 | B43: 0012 | C43: TAIRUN NISHA | D43: 371101000005005 | E43: IOBA0003711 | F43: 10.77 | G43: 513.242 | H43: 0 | I43: 513
A44: 20010005 | B44: 0014 | C44: SALIM ANSARI | D44: 494310110018804 | E44: BKID0004943 | F44: 52.81 | G44: 2472.5713 | H44: 0 | I44: 2473
A45: 20010005 | B45: 0016 | C45: ASIYA KHATOON | D45: 494318210006966 | E45: BKID0004943 | F45: 1.63 | G45: 64.5397 | H45: 0 | I45: 65
A46: 20010005 | B46: 0022 | C46: SHEIKH SAFIQUE | D46: 494310100000875 | E46: BKID0004943 | F46: 7.64 | G46: 278.2609 | H46: 0 | I46: 278
A47: 20010005 | B47: 0023 | C47: JOHRA KHATOON | D47: 50369500332 | E47: IDIB000N518 | F47: 24.88 | G47: 1007.5236 | H47: 0 | I47: 1008
A48: 20010005 | B48: 0029 | C48: IMAM ANSARI | D48: 494318210005769 | E48: BKID0004943 | F48: 19.35 | G48: 795.6549 | H48: 0 | I48: 796
...

Sheet MPG Payment
F2: New Format | H2: Reg. Farmers | J2: Unreg. Farmers | L2: Total farmer
A3: BMC Code | B3: Code | C3: MPG NAME | D3: Type | E3: Farmer Payment | F3: BMC Volume | G3: BMC Amount | H3: Reg Vol | I3: reg Amt | J3: Unreg Vol | K3: Unreg Amt | L3: Total Vol | M3: Total Amt | N3: Payable | O3: TS Loss | P3: Deduction for excess payment | Q3: Loss Apportion | R3: CF Deduction | S3: Vet Deduction | T3: Advance | U3: Others | V3: Payment to Farmer A/c | W3: Unreg. Farmer payment | X3: Payment to MPGs A/c | Y3: Closing Reserve | Z3: Stop Payment | AA3: Diff | AB3: loss/gain | AC3: No of Farmers | AD3: Cycle | AE3: Remarks | AF3: CF OS | AG3: Deduction | AH3: Balance | AI3: CF OS Aging in Days
A4: BMC Code :2001 | B4: 20010001 | C4: Itki | D4: RMC | E4: =IFERROR(VLOOKUP(B4,Table2[[Code]:[Category]],13,0),"Indirect") -> Direct | F4: 11527.96 | G4: 489972.14 | H4: =SUMIFS(Table2[Vol_L],Table2[Code],'MPG Payment'!$B4,Table2[Account Details],"Available") -> 11528.02 | I4: =SUMIFS(Table2[Amount],Table2[Code],'MPG Payment'!$B4,Table2[Account Details],"Available") -> 489944.47 | J4: =IF(E4="direct",SUMIFS(Table2[Vol_L],Table2[Code],'MPG Payment'!$B4,Table2[Account Details],"Not Available"),0) -> 0 | K4: =IF(E4="direct",SUMIFS(Table2[Amount],Table2[Code],'MPG Payment'!$B4,Table2[Account Details],"Not Available"),0) -> 0 | L4: =H4+J4 -> 11528.02 | M4: =I4+K4 -> 489944.47 | N4: =IF(E4="indirect",G4,MIN(G4,M4)) -> 489944.47 | O4: =SUMIFS(Table2[TS Loss],Table2[Code],'MPG Payment'!$B4) -> 14964 | P4: =SUMIFS(Table2[Deduction for excess payment],Table2[Code],'MPG Payment'!$B4) -> 0 | Q4: =IF(M4>G4,(M4-G4),0) -> 0 | R4: =SUMIF(Table2[Code],'MPG Payment'!$B4,Table2[CF Deduction]) -> 0 | S4: =SUMIF('Farmer Payment Calc'!D:D,'MPG Payment'!B4,'Farmer Payment Calc'!M:M) -> 0 | T4: 0 | U4: 0 | V4: =IF(E4="direct",SUMIFS(Table2[Net Amount],Table2[Code],'MPG Payment'!$B4,Table2[Account Details],"Available"),0) -> 474980 | W4: =IF(E4="direct",SUMIFS(Table2[Net Amount],Table2[Code],'MPG Payment'!$B4,Table2[Account Details],"Not Available"),0) -> 0 | X4: =IF(Z4="Yes",0,IF(E4="indirect",(G4-O4-P4-R4-T4-U4-S4),0)) -> 0 | Y4: =IF(E4="direct",(G4-O4-P4-V4-X4-R4-S4-T4-U4),0)-W4 -> 28.14 | Z4: 0 | AA4: =ROUND(+N4-O4-P4-R4-T4-V4-W4-X4-S4,0)-U4 -> 0 | AB4: =(M4-G4)/G4 -> -5.6474231e-05 | AC4: =COUNTIF(Table2[Code],'MPG Payment'!B4) -> 21 | AD4: {=SUBSTITUTE(SUBSTITUTE(MID(CELL("filename"),FIND("[",CELL("filename"))+1,FIND("]",CELL("filename"))-FIND("[",CELL("filename"))-1),"JH Farmer Payment-",""),".xlsx","")} -> Indent | AF4: 0 | AG4: 0 | AH4: =AF4-AG4 -> 0 | AI4: 0
A5: BMC Code :2001 | B5: 20010002 | C5: Jamtoli | D5: MPG | E5: =IFERROR(VLOOKUP(B5,Table2[[Code]:[Category]],13,0),"Indirect") -> Direct | F5: 13.18 | G5: 498.36 | H5: =SUMIFS(Table2[Vol_L],Table2[Code],'MPG Payment'!$B5,Table2[Account Details],"Available") -> 12 | I5: =SUMIFS(Table2[Amount],Table2[Code],'MPG Payment'!$B5,Table2[Account Details],"Available") -> 495 | J5: =IF(E5="direct",SUMIFS(Table2[Vol_L],Table2[Code],'MPG Payment'!$B5,Table2[Account Details],"Not Available"),0) -> 0 | K5: =IF(E5="direct",SUMIFS(Table2[Amount],Table2[Code],'MPG Payment'!$B5,Table2[Account Details],"Not Available"),0) -> 0 | L5: =H5+J5 -> 12 | M5: =I5+K5 -> 495 | N5: =IF(E5="indirect",G5,MIN(G5,M5)) -> 495 | O5: =SUMIFS(Table2[TS Loss],Table2[Code],'MPG Payment'!$B5) -> 0 | P5: =SUMIFS(Table2[Deduction for excess payment],Table2[Code],'MPG Payment'!$B5) -> 0 | Q5: =IF(M5>G5,(M5-G5),0) -> 0 | R5: =SUMIF(Table2[Code],'MPG Payment'!$B5,Table2[CF Deduction]) -> 0 | S5: =SUMIF('Farmer Payment Calc'!D:D,'MPG Payment'!B5,'Farmer Payment Calc'!M:M) -> 0 | T5: 0 | U5: 0 | V5: =IF(E5="direct",SUMIFS(Table2[Net Amount],Table2[Code],'MPG Payment'!$B5,Table2[Account Details],"Available"),0) -> 495 | W5: =IF(E5="direct",SUMIFS(Table2[Net Amount],Table2[Code],'MPG Payment'!$B5,Table2[Account Details],"Not Available"),0) -> 0 | X5: =IF(Z5="Yes",0,IF(E5="indirect",(G5-O5-P5-R5-T5-U5-S5),0)) -> 0 | Y5: =IF(E5="direct",(G5-O5-P5-V5-X5-R5-S5-T5-U5),0)-W5 -> 3.36 | Z5: 0 | AA5: =ROUND(+N5-O5-P5-R5-T5-V5-W5-X5-S5,0)-U5 -> 0 | AB5: =(M5-G5)/G5 -> -0.0067421141 | AC5: =COUNTIF(Table2[Code],'MPG Payment'!B5) -> 1 | AD5: {=SUBSTITUTE(SUBSTITUTE(MID(CELL("filename"),FIND("[",CELL("filename"))+1,FIND("]",CELL("filename"))-FIND("[",CELL("filename"))-1),"JH Farmer Payment-",""),".xlsx","")} -> Indent | AF5: 0 | AG5: 0 | AH5: =AF5-AG5 -> 0 | AI5: 0
A6: BMC Code :2001 | B6: 20010003 | C6: Bero | D6: MPG | E6: =IFERROR(VLOOKUP(B6,Table2[[Code]:[Category]],13,0),"Indirect") -> Direct | F6: 1387.17 | G6: 56177.98 | H6: =SUMIFS(Table2[Vol_L],Table2[Code],'MPG Payment'!$B6,Table2[Account Details],"Available") -> 1397.04 | I6: =SUMIFS(Table2[Amount],Table2[Code],'MPG Payment'!$B6,Table2[Account Details],"Available") -> 57657.305 | J6: =IF(E6="direct",SUMIFS(Table2[Vol_L],Table2[Code],'MPG Payment'!$B6,Table2[Account Details],"Not Available"),0) -> 0 | K6: =IF(E6="direct",SUMIFS(Table2[Amount],Table2[Code],'MPG Payment'!$B6,Table2[Account Details],"Not Available"),0) -> 0 | L6: =H6+J6 -> 1397.04 | M6: =I6+K6 -> 57657.305 | N6: =IF(E6="indirect",G6,MIN(G6,M6)) -> 56177.98 | O6: =SUMIFS(Table2[TS Loss],Table2[Code],'MPG Payment'!$B6) -> 0 | P6: =SUMIFS(Table2[Deduction for excess payment],Table2[Code],'MPG Payment'!$B6) -> 0 | Q6: =IF(M6>G6,(M6-G6),0) -> 1479.3247 | R6: =SUMIF(Table2[Code],'MPG Payment'!$B6,Table2[CF Deduction]) -> 10160 | S6: =SUMIF('Farmer Payment Calc'!D:D,'MPG Payment'!B6,'Farmer Payment Calc'!M:M) -> 0 | T6: 0 | U6: 0 | V6: =IF(E6="direct",SUMIFS(Table2[Net Amount],Table2[Code],'MPG Payment'!$B6,Table2[Account Details],"Available"),0) -> 46018 | W6: =IF(E6="direct",SUMIFS(Table2[Net Amount],Table2[Code],'MPG Payment'!$B6,Table2[Account Details],"Not Available"),0) -> 0 | X6: =IF(Z6="Yes",0,IF(E6="indirect",(G6-O6-P6-R6-T6-U6-S6),0)) -> 0 | Y6: =IF(E6="direct",(G6-O6-P6-V6-X6-R6-S6-T6-U6),0)-W6 -> -0.02 | Z6: Release1 | AA6: =ROUND(+N6-O6-P6-R6-T6-V6-W6-X6-S6,0)-U6 -> 0 | AB6: =(M6-G6)/G6 -> 0.026332821 | AC6: =COUNTIF(Table2[Code],'MPG Payment'!B6) -> 10 | AD6: {=SUBSTITUTE(SUBSTITUTE(MID(CELL("filename"),FIND("[",CELL("filename"))+1,FIND("]",CELL("filename"))-FIND("[",CELL("filename"))-1),"JH Farmer Payment-",""),".xlsx","")} -> Indent | AE6: Letter not received | AF6: 0 | AG6: 0 | AH6: =AF6-AG6 -> 0 | AI6: 0
A7: BMC Code :2001 | B7: 20010005 | C7: Basila | D7: MPG | E7: =IFERROR(VLOOKUP(B7,Table2[[Code]:[Category]],13,0),"Indirect") -> Direct | F7: 1374.42 | G7: 54973.01 | H7: =SUMIFS(Table2[Vol_L],Table2[Code],'MPG Payment'!$B7,Table2[Account Details],"Available") -> 1352.05 | I7: =SUMIFS(Table2[Amount],Table2[Code],'MPG Payment'!$B7,Table2[Account Details],"Available") -> 54956.825 | J7: =IF(E7="direct",SUMIFS(Table2[Vol_L],Table2[Code],'MPG Payment'!$B7,Table2[Account Details],"Not Available"),0) -> 0 | K7: =IF(E7="direct",SUMIFS(Table2[Amount],Table2[Code],'MPG Payment'!$B7,Table2[Account Details],"Not Available"),0) -> 0 | L7: =H7+J7 -> 1352.05 | M7: =I7+K7 -> 54956.825 | N7: =IF(E7="indirect",G7,MIN(G7,M7)) -> 54956.825 | O7: =SUMIFS(Table2[TS Loss],Table2[Code],'MPG Payment'!$B7) -> 0 | P7: =SUMIFS(Table2[Deduction for excess payment],Table2[Code],'MPG Payment'!$B7) -> 0 | Q7: =IF(M7>G7,(M7-G7),0) -> 0 | R7: =SUMIF(Table2[Code],'MPG Payment'!$B7,Table2[CF Deduction]) -> 0 | S7: =SUMIF('Farmer Payment Calc'!D:D,'MPG Payment'!B7,'Farmer Payment Calc'!M:M) -> 0 | T7: 0 | U7: 0 | V7: =IF(E7="direct",SUMIFS(Table2[Net Amount],Table2[Code],'MPG Payment'!$B7,Table2[Account Details],"Available"),0) -> 54958 | W7: =IF(E7="direct",SUMIFS(Table2[Net Amount],Table2[Code],'MPG Payment'!$B7,Table2[Account Details],"Not Available"),0) -> 0 | X7: =IF(Z7="Yes",0,IF(E7="indirect",(G7-O7-P7-R7-T7-U7-S7),0)) -> 0 | Y7: =IF(E7="direct",(G7-O7-P7-V7-X7-R7-S7-T7-U7),0)-W7 -> 15.01 | Z7: 0 | AA7: =ROUND(+N7-O7-P7-R7-T7-V7-W7-X7-S7,0)-U7 -> -1 | AB7: =(M7-G7)/G7 -> -0.00029442448 | AC7: =COUNTIF(Table2[Code],'MPG Payment'!B7) -> 23 | AD7: {=SUBSTITUTE(SUBSTITUTE(MID(CELL("filename"),FIND("[",CELL("filename"))+1,FIND("]",CELL("filename"))-FIND("[",CELL("filename"))-1),"JH Farmer Payment-",""),".xlsx","")} -> Indent | AF7: 0 | AG7: 0 | AH7: =AF7-AG7 -> 0 | AI7: 0
A8: BMC Code :2001 | B8: 20010008 | C8: Erchoro | D8: MPG | E8: =IFERROR(VLOOKUP(B8,Table2[[Code]:[Category]],13,0),"Indirect") -> Direct | F8: 1215.92 | G8: 48622.24 | H8: =SUMIFS(Table2[Vol_L],Table2[Code],'MPG Payment'!$B8,Table2[Account Details],"Available") -> 1185.43 | I8: =SUMIFS(Table2[Amount],Table2[Code],'MPG Payment'!$B8,Table2[Account Details],"Available") -> 48571.347 | J8: =IF(E8="direct",SUMIFS(Table2[Vol_L],Table2[Code],'MPG Payment'!$B8,Table2[Account Details],"Not Available"),0) -> 0 | K8: =IF(E8="direct",SUMIFS(Table2[Amount],Table2[Code],'MPG Payment'!$B8,Table2[Account Details],"Not Available"),0) -> 0 | L8: =H8+J8 -> 1185.43 | M8: =I8+K8 -> 48571.347 | N8: =IF(E8="indirect",G8,MIN(G8,M8)) -> 48571.347 | O8: =SUMIFS(Table2[TS Loss],Table2[Code],'MPG Payment'!$B8) -> 0 | P8: =SUMIFS(Table2[Deduction for excess payment],Table2[Code],'MPG Payment'!$B8) -> 0 | Q8: =IF(M8>G8,(M8-G8),0) -> 0 | R8: =SUMIF(Table2[Code],'MPG Payment'!$B8,Table2[CF Deduction]) -> 0 | S8: =SUMIF('Farmer Payment Calc'!D:D,'MPG Payment'!B8,'Farmer Payment Calc'!M:M) -> 0 | T8: 0 | U8: 0 | V8: =IF(E8="direct",SUMIFS(Table2[Net Amount],Table2[Code],'MPG Payment'!$B8,Table2[Account Details],"Available"),0) -> 48571 | W8: =IF(E8="direct",SUMIFS(Table2[Net Amount],Table2[Code],'MPG Payment'!$B8,Table2[Account Details],"Not Available"),0) -> 0 | X8: =IF(Z8="Yes",0,IF(E8="indirect",(G8-O8-P8-R8-T8-U8-S8),0)) -> 0 | Y8: =IF(E8="direct",(G8-O8-P8-V8-X8-R8-S8-T8-U8),0)-W8 -> 51.24 | Z8: 0 | AA8: =ROUND(+N8-O8-P8-R8-T8-V8-W8-X8-S8,0)-U8 -> 0 | AB8: =(M8-G8)/G8 -> -0.0010467041 | AC8: =COUNTIF(Table2[Code],'MPG Payment'!B8) -> 14 | AD8: {=SUBSTITUTE(SUBSTITUTE(MID(CELL("filename"),FIND("[",CELL("filename"))+1,FIND("]",CELL("filename"))-FIND("[",CELL("filename"))-1),"JH Farmer Payment-",""),".xlsx","")} -> Indent | AF8: 0 | AG8: 0 | AH8: =AF8-AG8 -> 0 | AI8: 0
A9: BMC Code :2001 | B9: 20010009 | C9: Makunda | D9: MPG | E9: =IFERROR(VLOOKUP(B9,Table2[[Code]:[Category]],13,0),"Indirect") -> Direct | F9: 644.44 | G9: 27222.79 | H9: =SUMIFS(Table2[Vol_L],Table2[Code],'MPG Payment'!$B9,Table2[Account Details],"Available") -> 651.48 | I9: =SUMIFS(Table2[Amount],Table2[Code],'MPG Payment'!$B9,Table2[Account Details],"Available") -> 27178.347 | J9: =IF(E9="direct",SUMIFS(Table2[Vol_L],Table2[Code],'MPG Payment'!$B9,Table2[Account Details],"Not Available"),0) -> 0 | K9: =IF(E9="direct",SUMIFS(Table2[Amount],Table2[Code],'MPG Payment'!$B9,Table2[Account Details],"Not Available"),0) -> 0 | L9: =H9+J9 -> 651.48 | M9: =I9+K9 -> 27178.347 | N9: =IF(E9="indirect",G9,MIN(G9,M9)) -> 27178.347 | O9: =SUMIFS(Table2[TS Loss],Table2[Code],'MPG Payment'!$B9) -> 0 | P9: =SUMIFS(Table2[Deduction for excess payment],Table2[Code],'MPG Payment'!$B9) -> 0 | Q9: =IF(M9>G9,(M9-G9),0) -> 0 | R9: =SUMIF(Table2[Code],'MPG Payment'!$B9,Table2[CF Deduction]) -> 0 | S9: =SUMIF('Farmer Payment Calc'!D:D,'MPG Payment'!B9,'Farmer Payment Calc'!M:M) -> 0 | T9: 0 | U9: 0 | V9: =IF(E9="direct",SUMIFS(Table2[Net Amount],Table2[Code],'MPG Payment'!$B9,Table2[Account Details],"Available"),0) -> 27179 | W9: =IF(E9="direct",SUMIFS(Table2[Net Amount],Table2[Code],'MPG Payment'!$B9,Table2[Account Details],"Not Available"),0) -> 0 | X9: =IF(Z9="Yes",0,IF(E9="indirect",(G9-O9-P9-R9-T9-U9-S9),0)) -> 0 | Y9: =IF(E9="direct",(G9-O9-P9-V9-X9-R9-S9-T9-U9),0)-W9 -> 43.79 | Z9: 0 | AA9: =ROUND(+N9-O9-P9-R9-T9-V9-W9-X9-S9,0)-U9 -> -1 | AB9: =(M9-G9)/G9 -> -0.0016325476 | AC9: =COUNTIF(Table2[Code],'MPG Payment'!B9) -> 7 | AD9: {=SUBSTITUTE(SUBSTITUTE(MID(CELL("filename"),FIND("[",CELL("filename"))+1,FIND("]",CELL("filename"))-FIND("[",CELL("filename"))-1),"JH Farmer Payment-",""),".xlsx","")} -> Indent | AF9: 0 | AG9: 0 | AH9: =AF9-AG9 -> 0 | AI9: 0
A10: BMC Code :2001 | B10: 20010012 | C10: NAGRI | D10: VLC | E10: =IFERROR(VLOOKUP(B10,Table2[[Code]:[Category]],13,0),"Indirect") -> Indirect | F10: 276.5 | G10: 8623.76 | H10: =SUMIFS(Table2[Vol_L],Table2[Code],'MPG Payment'!$B10,Table2[Account Details],"Available") -> 0 | I10: =SUMIFS(Table2[Amount],Table2[Code],'MPG Payment'!$B10,Table2[Account Details],"Available") -> 0 | J10: =IF(E10="direct",SUMIFS(Table2[Vol_L],Table2[Code],'MPG Payment'!$B10,Table2[Account Details],"Not Available"),0) -> 0 | K10: =IF(E10="direct",SUMIFS(Table2[Amount],Table2[Code],'MPG Payment'!$B10,Table2[Account Details],"Not Available"),0) -> 0 | L10: =H10+J10 -> 0 | M10: =I10+K10 -> 0 | N10: =IF(E10="indirect",G10,MIN(G10,M10)) -> 8623.76 | O10: =SUMIFS(Table2[TS Loss],Table2[Code],'MPG Payment'!$B10) -> 0 | P10: =SUMIFS(Table2[Deduction for excess payment],Table2[Code],'MPG Payment'!$B10) -> 0 | Q10: =IF(M10>G10,(M10-G10),0) -> 0 | R10: =SUMIF(Table2[Code],'MPG Payment'!$B10,Table2[CF Deduction]) -> 0 | S10: =SUMIF('Farmer Payment Calc'!D:D,'MPG Payment'!B10,'Farmer Payment Calc'!M:M) -> 0 | T10: 0 | U10: 0 | V10: =IF(E10="direct",SUMIFS(Table2[Net Amount],Table2[Code],'MPG Payment'!$B10,Table2[Account Details],"Available"),0) -> 0 | W10: =IF(E10="direct",SUMIFS(Table2[Net Amount],Table2[Code],'MPG Payment'!$B10,Table2[Account Details],"Not Available"),0) -> 0 | X10: =IF(Z10="Yes",0,IF(E10="indirect",(G10-O10-P10-R10-T10-U10-S10),0)) -> 8623.76 | Y10: =IF(E10="direct",(G10-O10-P10-V10-X10-R10-S10-T10-U10),0)-W10 -> 0 | Z10: 0 | AA10: =ROUND(+N10-O10-P10-R10-T10-V10-W10-X10-S10,0)-U10 -> 0 | AB10: =(M10-G10)/G10 -> -1 | AC10: =COUNTIF(Table2[Code],'MPG Payment'!B10) -> 0 | AD10: {=SUBSTITUTE(SUBSTITUTE(MID(CELL("filename"),FIND("[",CELL("filename"))+1,FIND("]",CELL("filename"))-FIND("[",CELL("filename"))-1),"JH Farmer Payment-",""),".xlsx","")} -> Indent | AF10: 0 | AG10: 0 | AH10: =AF10-AG10 -> 0 | AI10: 0
A11: BMC Code :2001 | B11: 20010015 | C11: BOREYA | D11: MPG | E11: =IFERROR(VLOOKUP(B11,Table2[[Code]:[Category]],13,0),"Indirect") -> Direct | F11: 2661.3 | G11: 108173.94 | H11: =SUMIFS(Table2[Vol_L],Table2[Code],'MPG Payment'!$B11,Table2[Account Details],"Available") -> 2579.38 | I11: =SUMIFS(Table2[Amount],Table2[Code],'MPG Payment'!$B11,Table2[Account Details],"Available") -> 107851.96 | J11: =IF(E11="direct",SUMIFS(Table2[Vol_L],Table2[Code],'MPG Payment'!$B11,Table2[Account Details],"Not Available"),0) -> 0 | K11: =IF(E11="direct",SUMIFS(Table2[Amount],Table2[Code],'MPG Payment'!$B11,Table2[Account Details],"Not Available"),0) -> 0 | L11: =H11+J11 -> 2579.38 | M11: =I11+K11 -> 107851.96 | N11: =IF(E11="indirect",G11,MIN(G11,M11)) -> 107851.96 | O11: =SUMIFS(Table2[TS Loss],Table2[Code],'MPG Payment'!$B11) -> 0 | P11: =SUMIFS(Table2[Deduction for excess payment],Table2[Code],'MPG Payment'!$B11) -> 0 | Q11: =IF(M11>G11,(M11-G11),0) -> 0 | R11: =SUMIF(Table2[Code],'MPG Payment'!$B11,Table2[CF Deduction]) -> 0 | S11: =SUMIF('Farmer Payment Calc'!D:D,'MPG Payment'!B11,'Farmer Payment Calc'!M:M) -> 0 | T11: 0 | U11: 0 | V11: =IF(E11="direct",SUMIFS(Table2[Net Amount],Table2[Code],'MPG Payment'!$B11,Table2[Account Details],"Available"),0) -> 107853 | W11: =IF(E11="direct",SUMIFS(Table2[Net Amount],Table2[Code],'MPG Payment'!$B11,Table2[Account Details],"Not Available"),0) -> 0 | X11: =IF(Z11="Yes",0,IF(E11="indirect",(G11-O11-P11-R11-T11-U11-S11),0)) -> 0 | Y11: =IF(E11="direct",(G11-O11-P11-V11-X11-R11-S11-T11-U11),0)-W11 -> 320.94 | Z11: 0 | AA11: =ROUND(+N11-O11-P11-R11-T11-V11-W11-X11-S11,0)-U11 -> -1 | AB11: =(M11-G11)/G11 -> -0.0029764747 | AC11: =COUNTIF(Table2[Code],'MPG Payment'!B11) -> 53 | AD11: {=SUBSTITUTE(SUBSTITUTE(MID(CELL("filename"),FIND("[",CELL("filename"))+1,FIND("]",CELL("filename"))-FIND("[",CELL("filename"))-1),"JH Farmer Payment-",""),".xlsx","")} -> Indent | AF11: 0 | AG11: 0 | AH11: =AF11-AG11 -> 0 | AI11: 0
A12: BMC Code :2001 | B12: 20010017 | C12: DIGHIYA | D12: MPG | E12: =IFERROR(VLOOKUP(B12,Table2[[Code]:[Category]],13,0),"Indirect") -> Direct | F12: 323.26 | G12: 13720.72 | H12: =SUMIFS(Table2[Vol_L],Table2[Code],'MPG Payment'!$B12,Table2[Account Details],"Available") -> 314.54 | I12: =SUMIFS(Table2[Amount],Table2[Code],'MPG Payment'!$B12,Table2[Account Details],"Available") -> 14115.361 | J12: =IF(E12="direct",SUMIFS(Table2[Vol_L],Table2[Code],'MPG Payment'!$B12,Table2[Account Details],"Not Available"),0) -> 0 | K12: =IF(E12="direct",SUMIFS(Table2[Amount],Table2[Code],'MPG Payment'!$B12,Table2[Account Details],"Not Available"),0) -> 0 | L12: =H12+J12 -> 314.54 | M12: =I12+K12 -> 14115.361 | N12: =IF(E12="indirect",G12,MIN(G12,M12)) -> 13720.72 | O12: =SUMIFS(Table2[TS Loss],Table2[Code],'MPG Payment'!$B12) -> 0 | P12: =SUMIFS(Table2[Deduction for excess payment],Table2[Code],'MPG Payment'!$B12) -> 0 | Q12: =IF(M12>G12,(M12-G12),0) -> 394.6409 | R12: =SUMIF(Table2[Code],'MPG Payment'!$B12,Table2[CF Deduction]) -> 0 | S12: =SUMIF('Farmer Payment Calc'!D:D,'MPG Payment'!B12,'Farmer Payment Calc'!M:M) -> 0 | T12: 0 | U12: 0 | V12: =IF(E12="direct",SUMIFS(Table2[Net Amount],Table2[Code],'MPG Payment'!$B12,Table2[Account Details],"Available"),0) -> 13721 | W12: =IF(E12="direct",SUMIFS(Table2[Net Amount],Table2[Code],'MPG Payment'!$B12,Table2[Account Details],"Not Available"),0) -> 0 | X12: =IF(Z12="Yes",0,IF(E12="indirect",(G12-O12-P12-R12-T12-U12-S12),0)) -> 0 | Y12: =IF(E12="direct",(G12-O12-P12-V12-X12-R12-S12-T12-U12),0)-W12 -> -0.28 | Z12: 0 | AA12: =ROUND(+N12-O12-P12-R12-T12-V12-W12-X12-S12,0)-U12 -> 0 | AB12: =(M12-G12)/G12 -> 0.028762405 | AC12: =COUNTIF(Table2[Code],'MPG Payment'!B12) -> 9 | AD12: {=SUBSTITUTE(SUBSTITUTE(MID(CELL("filename"),FIND("[",CELL("filename"))+1,FIND("]",CELL("filename"))-FIND("[",CELL("filename"))-1),"JH Farmer Payment-",""),".xlsx","")} -> Indent | AF12: 0 | AG12: 0 | AH12: =AF12-AG12 -> 0 | AI12: 0
