Workbook

Sheet PDF
A1: MCC | B1: Mahua BMC | C1: Sahayak Comission Month Of May'26
C3: Values
A4: Code | B4: MPG NAME | C4: BMC Volume | D4: BMC Amount | E4: Sahayak Comission @ 0.75/- | F4: Std gain @ 0.95/- | G4: Farmer Sample Milk | H4: AMC from MPG @ 0.10/- | I4: Actual Volume Penalty | J4: Net Sahayak Income | K4: New Assets EMI | L4: Can Deduction | M4: PCB Ded | N4: Other | O4: Consumables | P4: Payble to Sahyak | Q4: Hold | R4: Net Payble
A5: 10130101 | B5: Gomukh Karhatiya Bujurg | C5: 340.4 | D5: 13995.795 | E5: 255.3 | F5: 323.38 | G5: 0 | H5: 34.04 | I5: 544.60774 | J5: 0 | K5: 0 | L5: 0 | M5: 0 | N5: 0 | O5: 0 | P5: 0 | Q5: 0 | R5: 0
A6: 10130101 Total | C6: 340.4 | D6: 13995.795 | E6: 255.3 | F6: 323.38 | G6: 0 | H6: 34.04 | I6: 544.60774 | J6: 0 | K6: 0 | L6: 0 | M6: 0 | N6: 0 | O6: 0 | P6: 0 | Q6: 0 | R6: 0
A8: 10610002 | B8: GOMUKH CHEHRAKALA | C8: 1358.2 | D8: 63779.783 | E8: 1018.65 | F8: 1290.29 | G8: 0 | H8: 135.82 | I8: 1352.1841 | J8: 821 | K8: 821 | L8: 0 | M8: 0 | N8: 0 | O8: 0 | P8: 0 | Q8: 0 | R8: 0
A9: 10610002 Total | C9: 1358.2 | D9: 63779.783 | E9: 1018.65 | F9: 1290.29 | G9: 0 | H9: 135.82 | I9: 1352.1841 | J9: 821 | K9: 821 | L9: 0 | M9: 0 | N9: 0 | O9: 0 | P9: 0 | Q9: 0 | R9: 0
A11: 10610006 | B11: GOMUKH PREMRAJ | C11: 1421.9 | D11: 67545.511 | E11: 1066.425 | F11: 1350.805 | G11: 507.52766 | H11: 142.19 | I11: 1310.7516 | J11: 1472 | K11: 1472 | L11: 0 | M11: 0 | N11: 0 | O11: 0 | P11: 0 | Q11: 0 | R11: 0
A12: 10610006 Total | C12: 1421.9 | D12: 67545.511 | E12: 1066.425 | F12: 1350.805 | G12: 507.52766 | H12: 142.19 | I12: 1310.7516 | J12: 1472 | K12: 1472 | L12: 0 | M12: 0 | N12: 0 | O12: 0 | P12: 0 | Q12: 0 | R12: 0
A14: 10610007 | B14: GOMUKH MAGURAHI | C14: 1142.1 | D14: 58621.038 | E14: 856.575 | F14: 1084.995 | G14: 1309.3328 | H14: 114.21 | I14: 1702.7384 | J14: 0 | K14: 0 | L14: 0 | M14: 0 | N14: 0 | O14: 0 | P14: 0 | Q14: 0 | R14: 0
A15: 10610007 Total | C15: 1142.1 | D15: 58621.038 | E15: 856.575 | F15: 1084.995 | G15: 1309.3328 | H15: 114.21 | I15: 1702.7384 | J15: 0 | K15: 0 | L15: 0 | M15: 0 | N15: 0 | O15: 0 | P15: 0 | Q15: 0 | R15: 0
A17: 10610008 | B17: GOMUKH GANGATI | C17: 2003.5 | D17: 87514.05 | E17: 1502.625 | F17: 1903.325 | G17: 0 | H17: 200.35 | I17: 693.56796 | J17: 2512 | K17: 1861 | L17: 0 | M17: 0 | N17: 0 | O17: 0 | P17: 651 | Q17: 0 | R17: 651
A18: 10610008 Total | C18: 2003.5 | D18: 87514.05 | E18: 1502.625 | F18: 1903.325 | G18: 0 | H18: 200.35 | I18: 693.56796 | J18: 2512 | K18: 1861 | L18: 0 | M18: 0 | N18: 0 | O18: 0 | P18: 651 | Q18: 0 | R18: 651
A20: 10610010 | B20: GOMUKH Bhagwatpur | C20: 1837.6 | D20: 77916.535 | E20: 1378.2 | F20: 1745.72 | G20: 0 | H20: 183.76 | I20: 831.62846 | J20: 2109 | K20: 1861 | L20: 0 | M20: 0 | N20: 0 | O20: 0 | P20: 248 | Q20: 0 | R20: 248
A21: 10610010 Total | C21: 1837.6 | D21: 77916.535 | E21: 1378.2 | F21: 1745.72 | G21: 0 | H21: 183.76 | I21: 831.62846 | J21: 2109 | K21: 1861 | L21: 0 | M21: 0 | N21: 0 | O21: 0 | P21: 248 | Q21: 0 | R21: 248
A23: 10610009 | B23: GOMUKH Khanpatti | C23: 3795.06 | D23: 170116.62 | E23: 2846.295 | F23: 3605.307 | G23: 979.39073 | H23: 379.506 | I23: 0 | J23: 7051 | K23: 3402.3324 | L23: 0 | M23: 0 | N23: 0 | O23: 0 | P23: 3649 | Q23: 0 | R23: 3649
A24: 10610009 Total | C24: 3795.06 | D24: 170116.62 | E24: 2846.295 | F24: 3605.307 | G24: 979.39073 | H24: 379.506 | I24: 0 | J24: 7051 | K24: 3402.3324 | L24: 0 | M24: 0 | N24: 0 | O24: 0 | P24: 3649 | Q24: 0 | R24: 3649
A26: 10610001 | B26: GOMUKH BHATOLIYA | C26: 3502.2 | D26: 152429.46 | E26: 2626.65 | F26: 3327.09 | G26: 1130.4825 | H26: 350.22 | I26: 0 | J26: 6734 | K26: 0 | L26: 0 | M26: 0 | N26: 0 | O26: 0 | P26: 6734 | Q26: 0 | R26: 6734
A27: 10610001 Total | C27: 3502.2 | D27: 152429.46 | E27: 2626.65 | F27: 3327.09 | G27: 1130.4825 | H27: 350.22 | I27: 0 | J27: 6734 | K27: 0 | L27: 0 | M27: 0 | N27: 0 | O27: 0 | P27: 6734 | Q27: 0 | R27: 6734
A29: 10610003 | B29: GOMUKH KHAJECHAND | C29: 1637.5 | D29: 64818.105 | E29: 1228.125 | F29: 1555.625 | G29: 0 | H29: 163.75 | I29: 0 | J29: 2620 | K29: 0 | L29: 0 | M29: 0 | N29: 0 | O29: 0 | P29: 2620 | Q29: 0 | R29: 2620
A30: 10610003 Total | C30: 1637.5 | D30: 64818.105 | E30: 1228.125 | F30: 1555.625 | G30: 0 | H30: 163.75 | I30: 0 | J30: 2620 | K30: 0 | L30: 0 | M30: 0 | N30: 0 | O30: 0 | P30: 2620 | Q30: 0 | R30: 2620
A32: 10610004 | B32: GOMUKH SALEMPUR | C32: 651.9 | D32: 27768.049 | E32: 488.925 | F32: 619.305 | G32: 609.17569 | H32: 65.19 | I32: 0 | J32: 1652 | K32: 0 | L32: 0 | M32: 0 | N32: 0 | O32: 0 | P32: 1652 | Q32: 0 | R32: 1652
A33: 10610004 Total | C33: 651.9 | D33: 27768.049 | E33: 488.925 | F33: 619.305 | G33: 609.17569 | H33: 65.19 | I33: 0 | J33: 1652 | K33: 0 | L33: 0 | M33: 0 | N33: 0 | O33: 0 | P33: 1652 | Q33: 0 | R33: 1652
A35: 10610005 | B35: Gomukh Paharpur | C35: 1786 | D35: 75963.545 | E35: 1339.5 | F35: 1696.7 | G35: 0 | H35: 178.6 | I35: 0 | J35: 2858 | K35: 0 | L35: 0 | M35: 0 | N35: 0 | O35: 0 | P35: 2858 | Q35: 0 | R35: 2858
A36: 10610005 Total | C36: 1786 | D36: 75963.545 | E36: 1339.5 | F36: 1696.7 | G36: 0 | H36: 178.6 | I36: 0 | J36: 2858 | K36: 0 | L36: 0 | M36: 0 | N36: 0 | O36: 0 | P36: 2858 | Q36: 0 | R36: 2858
A38: 10610011 | B38: GOMUKH JIRWARA | C38: 1217.6 | D38: 48086.769 | E38: 913.2 | F38: 1156.72 | G38: 0 | H38: 121.76 | I38: 0 | J38: 1948 | K38: 0 | L38: 0 | M38: 0 | N38: 0 | O38: 0 | P38: 1948 | Q38: 0 | R38: 1948
A39: 10610011 Total | C39: 1217.6 | D39: 48086.769 | E39: 913.2 | F39: 1156.72 | G39: 0 | H39: 121.76 | I39: 0 | J39: 1948 | K39: 0 | L39: 0 | M39: 0 | N39: 0 | O39: 0 | P39: 1948 | Q39: 0 | R39: 1948
A41: 10610013 | B41: GOMUKH Karhatiya | C41: 1083.8 | D41: 39638.404 | E41: 812.85 | F41: 1029.61 | G41: 0 | H41: 108.38 | I41: 0 | J41: 1734 | K41: 0 | L41: 0 | M41: 0 | N41: 0 | O41: 0 | P41: 1734 | Q41: 0 | R41: 1734
A42: 10610013 Total | C42: 1083.8 | D42: 39638.404 | E42: 812.85 | F42: 1029.61 | G42: 0 | H42: 108.38 | I42: 0 | J42: 1734 | K42: 0 | L42: 0 | M42: 0 | N42: 0 | O42: 0 | P42: 1734 | Q42: 0 | R42: 1734
A44: 10610015 | B44: Gomukh Karhatiya Bujurg | C44: 1024.6 | D44: 36365.174 | E44: 768.45 | F44: 973.37 | G44: 0 | H44: 102.46 | I44: 0 | J44: 1639 | K44: 0 | L44: 0 | M44: 0 | N44: 0 | O44: 0 | P44: 1639 | Q44: 0 | R44: 1639
A45: 10610015 Total | C45: 1024.6 | D45: 36365.174 | E45: 768.45 | F45: 973.37 | G45: 0 | H45: 102.46 | I45: 0 | J45: 1639 | K45: 0 | L45: 0 | M45: 0 | N45: 0 | O45: 0 | P45: 1639 | Q45: 0 | R45: 1639
A47: 10610017 | B47: GOMUKH Bheraukhara | C47: 810.2 | D47: 32818.885 | E47: 607.65 | F47: 769.69 | G47: 0 | H47: 81.02 | I47: 0 | J47: 1296 | K47: 0 | L47: 0 | M47: 0 | N47: 0 | O47: 0 | P47: 1296 | Q47: 0 | R47: 1296
A48: 10610017 Total | C48: 810.2 | D48: 32818.885 | E48: 607.65 | F48: 769.69 | G48: 0 | H48: 81.02 | I48: 0 | J48: 1296 | K48: 0 | L48: 0 | M48: 0 | N48: 0 | O48: 0 | P48: 1296 | Q48: 0 | R48: 1296
A50: 10610018 | B50: GOMUKH SUPOLTARIYA | C50: 1931.5 | D50: 85431.684 | E50: 1448.625 | F50: 1834.925 | G50: 0 | H50: 193.15 | I50: 0 | J50: 3090 | K50: 0 | L50: 0 | M50: 0 | N50: 0 | O50: 0 | P50: 3090 | Q50: 0 | R50: 3090
A51: 10610018 Total | C51: 1931.5 | D51: 85431.684 | E51: 1448.625 | F51: 1834.925 | G51: 0 | H51: 193.15 | I51: 0 | J51: 3090 | K51: 0 | L51: 0 | M51: 0 | N51: 0 | O51: 0 | P51: 3090 | Q51: 0 | R51: 3090
A53: 10610020 | B53: GOMUKH Jilwara | C53: 1607.5 | D53: 65022.825 | E53: 1205.625 | F53: 1527.125 | G53: 0 | H53: 160.75 | I53: 0 | J53: 2572 | K53: 0 | L53: 0 | M53: 0 | N53: 0 | O53: 0 | P53: 2572 | Q53: 0 | R53: 2572
A54: 10610020 Total | C54: 1607.5 | D54: 65022.825 | E54: 1205.625 | F54: 1527.125 | G54: 0 | H54: 160.75 | I54: 0 | J54: 2572 | K54: 0 | L54: 0 | M54: 0 | N54: 0 | O54: 0 | P54: 2572 | Q54: 0 | R54: 2572
A56: 10610022 | B56: GOMUKH ABBUCHAK | C56: 924.9 | D56: 39161.727 | E56: 693.675 | F56: 878.655 | G56: 0 | H56: 92.49 | I56: 0 | J56: 1480 | K56: 0 | L56: 0 | M56: 0 | N56: 0 | O56: 0 | P56: 1480 | Q56: 0 | R56: 1480
A57: 10610022 Total | C57: 924.9 | D57: 39161.727 | E57: 693.675 | F57: 878.655 | G57: 0 | H57: 92.49 | I57: 0 | J57: 1480 | K57: 0 | L57: 0 | M57: 0 | N57: 0 | O57: 0 | P57: 1480 | Q57: 0 | R57: 1480
A59: 10610025 | B59: Gomukh Dumari | C59: 153.2 | D59: 5588.22 | E59: 114.9 | F59: 145.54 | G59: 0 | H59: 15.32 | I59: 0 | J59: 245 | K59: 0 | L59: 0 | M59: 0 | N59: 0 | O59: 0 | P59: 245 | Q59: 0 | R59: 245
...

Sheet Shayak Income 
M1: MPG Payment | Q1: MPG Sheet | R1: Internal | T1: MPG Deduction | W1: Other Security Deduction | AG1: -1
A2: Opening Balance ____ | M2: =SUBTOTAL(9,M4:M1036) -> 3651113.1 | N2: =SUBTOTAL(9,N4:N1036) -> 1.4131596e+08 | O2: Income | W2: =SUBTOTAL(9,W4:W1036) -> 667970.21 | X2: =SUBTOTAL(9,X4:X1036) -> 74053.738 | Y2: =SUBTOTAL(9,Y4:Y1036) -> 34928 | Z2: =SUBTOTAL(9,Z4:Z1036) -> 17372 | AA2: =SUBTOTAL(9,AA4:AA1036) -> 27705.3 | AB2: =SUBTOTAL(9,AB4:AB1036) -> 5051093 | AC2: =SUBTOTAL(9,AC4:AC1036) -> 406958 | AD2: =SUBTOTAL(9,AD4:AD1036) -> 4644135 | AG2: -1 | AN2: =SUBTOTAL(9,AN4:AN1036) -> 1146908.2 | AO2: =SUBTOTAL(9,AO4:AO1036) -> 37196 | AP2: =SUBTOTAL(9,AP4:AP1036) -> 667970.21 | AQ2: =SUBTOTAL(9,AQ4:AQ1036) -> 705166.21
A3: AMCU | B3: Milk Cans | C3: Assets Value | D3: Code | E3: MPG NAME | F3: Amcu type | G3: VLC Type | H3: Farmer Payment | I3: BMC Code | J3: MCC | K3: status | L3: Start Date | M3: BMC Volume | N3: BMC Amount | O3: Sahayak Comission @ 0.75/- | P3: Std gain @ 0.95/- | Q3: Farmer Sample Milk | R3: Std Gain @ 3% | S3: Reserve from Std Gain | T3: AMC from MPG @ 0.10/- | U3: Actual Volume Penalty | V3: Net Sahayak Income | W3: New Assets EMI | X3: Can Deduction | Y3: PCB Ded | Z3: Other | AA3: Consumables | AB3: Payble to Sahyak | AC3: Hold | AD3: Net Payble | AE3: Payment relase | AG3: Stop Payment | AH3: Remarks | AI3: Pending Down Payment | AJ3: Recommendation | AK3: 29-04 Jun | AL3: Irregular Pourer | AM3: No of pouring shift | AN3: EMI | AO3: Recovery from Milk | AP3: Recovery from Com | AQ3: Net Recovered | AT3: HDFC | AU3: OTHER | AV3: Remarks
A4: =IFERROR(VLOOKUP(D4,'Monthly Deduction'!$I$3:$J$957,2,0),0) -> 24146.671 | B4: =IFERROR(VLOOKUP(D4,'Monthly Deduction'!$E$3:$F$957,2,0),0) -> 12800 | C4: =A4+B4 -> 36946.671 | D4: 10010013 | E4: =VLOOKUP(D4,'MPG Payment '!$E$3:$G$498218,2,0) -> Gomukh Kumbhi | F4: =IFERROR(_xlfn.XLOOKUP(D4,'Monthly Deduction'!$I$3:$I$957,'Monthly Deduction'!$H$3:$H$957),0) -> 0 | G4: =VLOOKUP(D4,'MPG Payment '!$E$3:$G$334579,3,0) -> MPG | H4: =VLOOKUP(D4,'MPG Payment '!$E$3:$H$334579,4,0) -> Direct | I4: =INDEX('MPG Payment '!$C:$C,MATCH('Shayak Income '!D4,'MPG Payment '!E:E,0)) -> 1001 | J4: =INDEX('MPG Payment '!$D:$D,MATCH('Shayak Income '!D4,'MPG Payment '!E:E,0)) -> Majhaul | K4: Old | L4: 45013 | M4: =SUMIF('MPG Payment '!$E$3:$E$34579,'Shayak Income '!D4,'MPG Payment '!$I$3:$I$34579) -> 2891 | N4: =SUMIF('MPG Payment '!$E$3:$E$34579,'Shayak Income '!D4,'MPG Payment '!$J$3:$J$34579) -> 109798.24 | O4: =+M4*0.75 -> 2168.25 | P4: =+M4*0.95 -> 2746.45 | Q4: =SUMIF('MPG Payment '!$E$3:$E$34579,'Shayak Income '!D4,'MPG Payment '!$S$3:$S$34579) -> 795.52465 | R4: =+N4*3% -> 3293.9472 | S4: =R4-P4 -> 547.4972 | T4: =M4*0.1 -> 289.1 | U4: =(((IF(K4="New",0,SUMIF('MPG Payment '!$E$3:$E$34579,'Shayak Income '!D4,'MPG Payment '!$AC$3:$AC$34579))))+0)+0 -> 15.305181 | V4: =ROUND((SUM(O4:Q4)-SUM(T4:U4)),0) -> 5406 | W4: =(((AN4-AO4)))+0 -> 2195.9648 | X4: 0 | Y4: =IFERROR(VLOOKUP(D4,'Monthly Deduction'!$M$2:$N$64,2,0),0) -> 0 | Z4: 0 | AA4: =IFERROR(VLOOKUP(D4,'Monthly Deduction'!A:B,2,0),0) -> 0 | AB4: =ROUND(IFERROR(V4-SUM(W4:AA4),0),0) -> 3210 | AC4: 0 | AD4: =ROUND(AB4-AC4,0) -> 3210 | AE4: =IF(AC4<>0,"Yes","Release") -> Release | AG4: 0 | AI4: 0 | AK4: 720.9 | AL4: =COUNTIF(AK4:AK4,"=NA") -> 0 | AN4: =((MIN(IF(A4>0,MAX(N4*2%,1861),0),A4)))+0 -> 2195.9648 | AO4: =SUMIF('MPG Payment '!E:E,'Shayak Income '!D4,'MPG Payment '!AJ:AJ) -> 0 | AP4: =W4 -> 2195.9648 | AQ4: =AO4+AP4 -> 2195.9648 | AS4: =B4-X4 -> 12800
A5: =IFERROR(VLOOKUP(D5,'Monthly Deduction'!$I$3:$J$957,2,0),0) -> 64838 | B5: =IFERROR(VLOOKUP(D5,'Monthly Deduction'!$E$3:$F$957,2,0),0) -> 6400 | C5: =A5+B5 -> 71238 | D5: 10010017 | E5: =VLOOKUP(D5,'MPG Payment '!$E$3:$G$498218,2,0) -> Gomukh Amba | F5: =IFERROR(_xlfn.XLOOKUP(D5,'Monthly Deduction'!$I$3:$I$957,'Monthly Deduction'!$H$3:$H$957),0) -> 0 | G5: =VLOOKUP(D5,'MPG Payment '!$E$3:$G$334579,3,0) -> MPG | H5: =VLOOKUP(D5,'MPG Payment '!$E$3:$H$334579,4,0) -> Direct | I5: =INDEX('MPG Payment '!$C:$C,MATCH('Shayak Income '!D5,'MPG Payment '!E:E,0)) -> 1008 | J5: =INDEX('MPG Payment '!$D:$D,MATCH('Shayak Income '!D5,'MPG Payment '!E:E,0)) -> Teghra | K5: Old | L5: 45016 | M5: =SUMIF('MPG Payment '!$E$3:$E$34579,'Shayak Income '!D5,'MPG Payment '!$I$3:$I$34579) -> 158.25 | N5: =SUMIF('MPG Payment '!$E$3:$E$34579,'Shayak Income '!D5,'MPG Payment '!$J$3:$J$34579) -> 5257.6122 | O5: =+M5*0.75 -> 118.6875 | P5: =+M5*0.95 -> 150.3375 | Q5: =SUMIF('MPG Payment '!$E$3:$E$34579,'Shayak Income '!D5,'MPG Payment '!$S$3:$S$34579) -> 0 | R5: =+N5*3% -> 157.72836 | S5: =R5-P5 -> 7.3908645 | T5: =M5*0.1 -> 15.825 | U5: =(((IF(K5="New",0,SUMIF('MPG Payment '!$E$3:$E$34579,'Shayak Income '!D5,'MPG Payment '!$AC$3:$AC$34579))))+0)+-1481 -> 252.76736 | V5: =ROUND((SUM(O5:Q5)-SUM(T5:U5)),0) -> 0 | W5: 0 | X5: 0 | Y5: =IFERROR(VLOOKUP(D5,'Monthly Deduction'!$M$2:$N$64,2,0),0) -> 0 | Z5: 0 | AA5: =IFERROR(VLOOKUP(D5,'Monthly Deduction'!A:B,2,0),0) -> 0 | AB5: =ROUND(IFERROR(V5-SUM(W5:AA5),0),0) -> 0 | AC5: 0 | AD5: =ROUND(AB5-AC5,0) -> 0 | AE5: =IF(AC5<>0,"Yes","Release") -> Release | AG5: 0 | AI5: 0 | AK5: 28.5 | AL5: =COUNTIF(AK5:AK5,"=NA") -> 0 | AN5: =((MIN(IF(A5>0,MAX(N5*2%,1861),0),A5)))+0 -> 1861 | AO5: =SUMIF('MPG Payment '!E:E,'Shayak Income '!D5,'MPG Payment '!AJ:AJ) -> 500 | AP5: =W5 -> 0 | AQ5: =AO5+AP5 -> 500 | AS5: =B5-X5 -> 6400
A6: =IFERROR(VLOOKUP(D6,'Monthly Deduction'!$I$3:$J$957,2,0),0) -> 30537.325 | B6: =IFERROR(VLOOKUP(D6,'Monthly Deduction'!$E$3:$F$957,2,0),0) -> 6400 | C6: =A6+B6 -> 36937.325 | D6: 10010019 | E6: =VLOOKUP(D6,'MPG Payment '!$E$3:$G$498218,2,0) -> Gomukh Jagdar | F6: =IFERROR(_xlfn.XLOOKUP(D6,'Monthly Deduction'!$I$3:$I$957,'Monthly Deduction'!$H$3:$H$957),0) -> 0 | G6: =VLOOKUP(D6,'MPG Payment '!$E$3:$G$334579,3,0) -> MPG | H6: =VLOOKUP(D6,'MPG Payment '!$E$3:$H$334579,4,0) -> Direct | I6: =INDEX('MPG Payment '!$C:$C,MATCH('Shayak Income '!D6,'MPG Payment '!E:E,0)) -> 1001 | J6: =INDEX('MPG Payment '!$D:$D,MATCH('Shayak Income '!D6,'MPG Payment '!E:E,0)) -> Majhaul | K6: Old | L6: 45040 | M6: =SUMIF('MPG Payment '!$E$3:$E$34579,'Shayak Income '!D6,'MPG Payment '!$I$3:$I$34579) -> 3099.7 | N6: =SUMIF('MPG Payment '!$E$3:$E$34579,'Shayak Income '!D6,'MPG Payment '!$J$3:$J$34579) -> 122858.96 | O6: =+M6*0.75 -> 2324.775 | P6: =+M6*0.95 -> 2944.715 | Q6: =SUMIF('MPG Payment '!$E$3:$E$34579,'Shayak Income '!D6,'MPG Payment '!$S$3:$S$34579) -> 1681.2057 | R6: =+N6*3% -> 3685.7689 | S6: =R6-P6 -> 741.05391 | T6: =M6*0.1 -> 309.97 | U6: =(((IF(K6="New",0,SUMIF('MPG Payment '!$E$3:$E$34579,'Shayak Income '!D6,'MPG Payment '!$AC$3:$AC$34579))))+0)+0 -> 0 | V6: =ROUND((SUM(O6:Q6)-SUM(T6:U6)),0) -> 6641 | W6: =(((AN6-AO6)))+0 -> 2457.1793 | X6: 0 | Y6: =IFERROR(VLOOKUP(D6,'Monthly Deduction'!$M$2:$N$64,2,0),0) -> 0 | Z6: 0 | AA6: =IFERROR(VLOOKUP(D6,'Monthly Deduction'!A:B,2,0),0) -> 0 | AB6: =ROUND(IFERROR(V6-SUM(W6:AA6),0),0) -> 4184 | AC6: 0 | AD6: =ROUND(AB6-AC6,0) -> 4184 | AE6: =IF(AC6<>0,"Yes","Release") -> Release | AG6: 0 | AI6: 0 | AK6: 1007.2 | AL6: =COUNTIF(AK6:AK6,"=NA") -> 0 | AN6: =((MIN(IF(A6>0,MAX(N6*2%,1861),0),A6)))+0 -> 2457.1793 | AO6: =SUMIF('MPG Payment '!E:E,'Shayak Income '!D6,'MPG Payment '!AJ:AJ) -> 0 | AP6: =W6 -> 2457.1793 | AQ6: =AO6+AP6 -> 2457.1793 | AS6: =B6-X6 -> 6400
A7: =IFERROR(VLOOKUP(D7,'Monthly Deduction'!$I$3:$J$957,2,0),0) -> 38140.006 | B7: =IFERROR(VLOOKUP(D7,'Monthly Deduction'!$E$3:$F$957,2,0),0) -> 5744.916 | C7: =A7+B7 -> 43884.922 | D7: 10010038 | E7: =VLOOKUP(D7,'MPG Payment '!$E$3:$G$498218,2,0) -> Gomukh Goriyari | F7: =IFERROR(_xlfn.XLOOKUP(D7,'Monthly Deduction'!$I$3:$I$957,'Monthly Deduction'!$H$3:$H$957),0) -> 0 | G7: =VLOOKUP(D7,'MPG Payment '!$E$3:$G$334579,3,0) -> MPG | H7: =VLOOKUP(D7,'MPG Payment '!$E$3:$H$334579,4,0) -> Direct | I7: =INDEX('MPG Payment '!$C:$C,MATCH('Shayak Income '!D7,'MPG Payment '!E:E,0)) -> 1058 | J7: =INDEX('MPG Payment '!$D:$D,MATCH('Shayak Income '!D7,'MPG Payment '!E:E,0)) -> Hasanpur | K7: Old | L7: 45128 | M7: =SUMIF('MPG Payment '!$E$3:$E$34579,'Shayak Income '!D7,'MPG Payment '!$I$3:$I$34579) -> 4882.3 | N7: =SUMIF('MPG Payment '!$E$3:$E$34579,'Shayak Income '!D7,'MPG Payment '!$J$3:$J$34579) -> 189127.27 | O7: =+M7*0.75 -> 3661.725 | P7: =+M7*0.95 -> 4638.185 | Q7: =SUMIF('MPG Payment '!$E$3:$E$34579,'Shayak Income '!D7,'MPG Payment '!$S$3:$S$34579) -> 830.22511 | R7: =+N7*3% -> 5673.818 | S7: =R7-P7 -> 1035.633 | T7: =M7*0.1 -> 488.23 | U7: =(((IF(K7="New",0,SUMIF('MPG Payment '!$E$3:$E$34579,'Shayak Income '!D7,'MPG Payment '!$AC$3:$AC$34579))))+0)+0 -> 0 | V7: =ROUND((SUM(O7:Q7)-SUM(T7:U7)),0) -> 8642 | W7: =(((AN7-AO7)))+0 -> 3782.5453 | X7: 0 | Y7: =IFERROR(VLOOKUP(D7,'Monthly Deduction'!$M$2:$N$64,2,0),0) -> 0 | Z7: 0 | AA7: =IFERROR(VLOOKUP(D7,'Monthly Deduction'!A:B,2,0),0) -> 0 | AB7: =ROUND(IFERROR(V7-SUM(W7:AA7),0),0) -> 4859 | AC7: 0 | AD7: =ROUND(AB7-AC7,0) -> 4859 | AE7: =IF(AC7<>0,"Yes","Release") -> Release | AG7: 0 | AI7: 0 | AK7: 1382.3 | AL7: =COUNTIF(AK7:AK7,"=NA") -> 0 | AN7: =((MIN(IF(A7>0,MAX(N7*2%,1861),0),A7)))+0 -> 3782.5453 | AO7: =SUMIF('MPG Payment '!E:E,'Shayak Income '!D7,'MPG Payment '!AJ:AJ) -> 0 | AP7: =W7 -> 3782.5453 | AQ7: =AO7+AP7 -> 3782.5453 | AS7: =B7-X7 -> 5744.916
A8: =IFERROR(VLOOKUP(D8,'Monthly Deduction'!$I$3:$J$957,2,0),0) -> 0 | B8: =IFERROR(VLOOKUP(D8,'Monthly Deduction'!$E$3:$F$957,2,0),0) -> 0 | C8: =A8+B8 -> 0 | D8: 10010047 | E8: =VLOOKUP(D8,'MPG Payment '!$E$3:$G$498218,2,0) -> Mohanpur - Chandan | F8: =IFERROR(_xlfn.XLOOKUP(D8,'Monthly Deduction'!$I$3:$I$957,'Monthly Deduction'!$H$3:$H$957),0) -> 0 | G8: =VLOOKUP(D8,'MPG Payment '!$E$3:$G$334579,3,0) -> vlc | H8: =VLOOKUP(D8,'MPG Payment '!$E$3:$H$334579,4,0) -> Indirect | I8: =INDEX('MPG Payment '!$C:$C,MATCH('Shayak Income '!D8,'MPG Payment '!E:E,0)) -> 1001 | J8: =INDEX('MPG Payment '!$D:$D,MATCH('Shayak Income '!D8,'MPG Payment '!E:E,0)) -> Majhaul | K8: Old | L8: 45121 | M8: =SUMIF('MPG Payment '!$E$3:$E$34579,'Shayak Income '!D8,'MPG Payment '!$I$3:$I$34579) -> 325 | N8: =SUMIF('MPG Payment '!$E$3:$E$34579,'Shayak Income '!D8,'MPG Payment '!$J$3:$J$34579) -> 13308.744 | O8: =+M8*0.75 -> 243.75 | P8: =+M8*0.95 -> 308.75 | Q8: =SUMIF('MPG Payment '!$E$3:$E$34579,'Shayak Income '!D8,'MPG Payment '!$S$3:$S$34579) -> 0 | R8: =+N8*3% -> 399.26232 | S8: =R8-P8 -> 90.512321 | T8: =M8*0.1 -> 32.5 | U8: =(((IF(K8="New",0,SUMIF('MPG Payment '!$E$3:$E$34579,'Shayak Income '!D8,'MPG Payment '!$AC$3:$AC$34579))))+0)+-1591 -> 520.48048 | V8: =ROUND((SUM(O8:Q8)-SUM(T8:U8)),0) -> 0 | W8: 0 | X8: 0 | Y8: =IFERROR(VLOOKUP(D8,'Monthly Deduction'!$M$2:$N$64,2,0),0) -> 0 | Z8: 0 | AA8: =IFERROR(VLOOKUP(D8,'Monthly Deduction'!A:B,2,0),0) -> 0 | AB8: =ROUND(IFERROR(V8-SUM(W8:AA8),0),0) -> 0 | AC8: 0 | AD8: =ROUND(AB8-AC8,0) -> 0 | AE8: =IF(AC8<>0,"Yes","Release") -> Release | AG8: 0 | AI8: 0 | AK8: 115.9 | AL8: =COUNTIF(AK8:AK8,"=NA") -> 0 | AN8: =((MIN(IF(A8>0,MAX(N8*2%,1861),0),A8)))+0 -> 0 | AO8: =SUMIF('MPG Payment '!E:E,'Shayak Income '!D8,'MPG Payment '!AJ:AJ) -> 0 | AP8: =W8 -> 0 | AQ8: =AO8+AP8 -> 0 | AS8: =B8-X8 -> 0
A9: =IFERROR(VLOOKUP(D9,'Monthly Deduction'!$I$3:$J$957,2,0),0) -> 36739.688 | B9: =IFERROR(VLOOKUP(D9,'Monthly Deduction'!$E$3:$F$957,2,0),0) -> 0 | C9: =A9+B9 -> 36739.688 | D9: 10010050 | E9: =VLOOKUP(D9,'MPG Payment '!$E$3:$G$498218,2,0) -> Ekamba - Ashutosh | F9: =IFERROR(_xlfn.XLOOKUP(D9,'Monthly Deduction'!$I$3:$I$957,'Monthly Deduction'!$H$3:$H$957),0) -> 0 | G9: =VLOOKUP(D9,'MPG Payment '!$E$3:$G$334579,3,0) -> vlc | H9: =VLOOKUP(D9,'MPG Payment '!$E$3:$H$334579,4,0) -> Indirect | I9: =INDEX('MPG Payment '!$C:$C,MATCH('Shayak Income '!D9,'MPG Payment '!E:E,0)) -> 1058 | J9: =INDEX('MPG Payment '!$D:$D,MATCH('Shayak Income '!D9,'MPG Payment '!E:E,0)) -> Hasanpur | K9: Old | L9: 45098 | M9: =SUMIF('MPG Payment '!$E$3:$E$34579,'Shayak Income '!D9,'MPG Payment '!$I$3:$I$34579) -> 3298.4 | N9: =SUMIF('MPG Payment '!$E$3:$E$34579,'Shayak Income '!D9,'MPG Payment '!$J$3:$J$34579) -> 123601.22 | O9: =+M9*0.75 -> 2473.8 | P9: =+M9*0.95 -> 3133.48 | Q9: =SUMIF('MPG Payment '!$E$3:$E$34579,'Shayak Income '!D9,'MPG Payment '!$S$3:$S$34579) -> 0 | R9: =+N9*3% -> 3708.0365 | S9: =R9-P9 -> 574.5565 | T9: =M9*0.1 -> 329.84 | U9: =(((IF(K9="New",0,SUMIF('MPG Payment '!$E$3:$E$34579,'Shayak Income '!D9,'MPG Payment '!$AC$3:$AC$34579))))+0)+0 -> 40.707069 | V9: =ROUND((SUM(O9:Q9)-SUM(T9:U9)),0) -> 5237 | W9: =(((AN9-AO9)))+0 -> 2472.0243 | X9: 0 | Y9: =IFERROR(VLOOKUP(D9,'Monthly Deduction'!$M$2:$N$64,2,0),0) -> 0 | Z9: 0 | AA9: =IFERROR(VLOOKUP(D9,'Monthly Deduction'!A:B,2,0),0) -> 0 | AB9: =ROUND(IFERROR(V9-SUM(W9:AA9),0),0) -> 2765 | AC9: 0 | AD9: =ROUND(AB9-AC9,0) -> 2765 | AE9: =IF(AC9<>0,"Yes","Release") -> Release | AG9: 0 | AI9: 0 | AK9: 1008.9 | AL9: =COUNTIF(AK9:AK9,"=NA") -> 0 | AN9: =((MIN(IF(A9>0,MAX(N9*2%,1861),0),A9)))+0 -> 2472.0243 | AO9: =SUMIF('MPG Payment '!E:E,'Shayak Income '!D9,'MPG Payment '!AJ:AJ) -> 0 | AP9: =W9 -> 2472.0243 | AQ9: =AO9+AP9 -> 2472.0243 | AS9: =B9-X9 -> 0
A10: =IFERROR(VLOOKUP(D10,'Monthly Deduction'!$I$3:$J$957,2,0),0) -> 27138.825 | B10: =IFERROR(VLOOKUP(D10,'Monthly Deduction'!$E$3:$F$957,2,0),0) -> 570.1518 | C10: =A10+B10 -> 27708.977 | D10: 10010051 | E10: =VLOOKUP(D10,'MPG Payment '!$E$3:$G$498218,2,0) -> Gomukh Dunahi | F10: =IFERROR(_xlfn.XLOOKUP(D10,'Monthly Deduction'!$I$3:$I$957,'Monthly Deduction'!$H$3:$H$957),0) -> 0 | G10: =VLOOKUP(D10,'MPG Payment '!$E$3:$G$334579,3,0) -> MPG | H10: =VLOOKUP(D10,'MPG Payment '!$E$3:$H$334579,4,0) -> Direct | I10: =INDEX('MPG Payment '!$C:$C,MATCH('Shayak Income '!D10,'MPG Payment '!E:E,0)) -> 1058 | J10: =INDEX('MPG Payment '!$D:$D,MATCH('Shayak Income '!D10,'MPG Payment '!E:E,0)) -> Hasanpur | K10: Old | L10: 45219 | M10: =SUMIF('MPG Payment '!$E$3:$E$34579,'Shayak Income '!D10,'MPG Payment '!$I$3:$I$34579) -> 2234.8 | N10: =SUMIF('MPG Payment '!$E$3:$E$34579,'Shayak Income '!D10,'MPG Payment '!$J$3:$J$34579) -> 83104.667 | O10: =+M10*0.75 -> 1676.1 | P10: =+M10*0.95 -> 2123.06 | Q10: =SUMIF('MPG Payment '!$E$3:$E$34579,'Shayak Income '!D10,'MPG Payment '!$S$3:$S$34579) -> 618.92895 | R10: =+N10*3% -> 2493.14 | S10: =R10-P10 -> 370.08001 | T10: =M10*0.1 -> 223.48 | U10: =(((IF(K10="New",0,SUMIF('MPG Payment '!$E$3:$E$34579,'Shayak Income '!D10,'MPG Payment '!$AC$3:$AC$34579))))+0)+0 -> 213.3474 | V10: =ROUND((SUM(O10:Q10)-SUM(T10:U10)),0) -> 3981 | W10: =(((AN10-AO10)))+0 -> 1861 | X10: 0 | Y10: =IFERROR(VLOOKUP(D10,'Monthly Deduction'!$M$2:$N$64,2,0),0) -> 0 | Z10: 0 | AA10: =IFERROR(VLOOKUP(D10,'Monthly Deduction'!A:B,2,0),0) -> 0 | AB10: =ROUND(IFERROR(V10-SUM(W10:AA10),0),0) -> 2120 | AC10: 0 | AD10: =ROUND(AB10-AC10,0) -> 2120 | AE10: =IF(AC10<>0,"Yes","Release") -> Release | AG10: 0 | AI10: 0 | AK10: 1132.6 | AL10: =COUNTIF(AK10:AK10,"=NA") -> 0 | AN10: =((MIN(IF(A10>0,MAX(N10*2%,1861),0),A10)))+0 -> 1861 | AO10: =SUMIF('MPG Payment '!E:E,'Shayak Income '!D10,'MPG Payment '!AJ:AJ) -> 0 | AP10: =W10 -> 1861 | AQ10: =AO10+AP10 -> 1861 | AS10: =B10-X10 -> 570.1518
A11: =IFERROR(VLOOKUP(D11,'Monthly Deduction'!$I$3:$J$957,2,0),0) -> 82375.427 | B11: =IFERROR(VLOOKUP(D11,'Monthly Deduction'!$E$3:$F$957,2,0),0) -> 6400 | C11: =A11+B11 -> 88775.427 | D11: 10010055 | E11: =VLOOKUP(D11,'MPG Payment '!$E$3:$G$498218,2,0) -> GOMUKH BIRPUR PASCHIM | F11: =IFERROR(_xlfn.XLOOKUP(D11,'Monthly Deduction'!$I$3:$I$957,'Monthly Deduction'!$H$3:$H$957),0) -> 0 | G11: =VLOOKUP(D11,'MPG Payment '!$E$3:$G$334579,3,0) -> MPG | H11: =VLOOKUP(D11,'MPG Payment '!$E$3:$H$334579,4,0) -> Direct | I11: =INDEX('MPG Payment '!$C:$C,MATCH('Shayak Income '!D11,'MPG Payment '!E:E,0)) -> 1001 | J11: =INDEX('MPG Payment '!$D:$D,MATCH('Shayak Income '!D11,'MPG Payment '!E:E,0)) -> Majhaul | K11: Old | L11: 45231 | M11: =SUMIF('MPG Payment '!$E$3:$E$34579,'Shayak Income '!D11,'MPG Payment '!$I$3:$I$34579) -> 526.7 | N11: =SUMIF('MPG Payment '!$E$3:$E$34579,'Shayak Income '!D11,'MPG Payment '!$J$3:$J$34579) -> 21545.007 | O11: =+M11*0.75 -> 395.025 | P11: =+M11*0.95 -> 500.365 | Q11: =SUMIF('MPG Payment '!$E$3:$E$34579,'Shayak Income '!D11,'MPG Payment '!$S$3:$S$34579) -> 0 | R11: =+N11*3% -> 646.3502 | S11: =R11-P11 -> 145.9852 | T11: =M11*0.1 -> 52.67 | U11: =(((IF(K11="New",0,SUMIF('MPG Payment '!$E$3:$E$34579,'Shayak Income '!D11,'MPG Payment '!$AC$3:$AC$34579))))+0)+-1018 -> 842.25604 | V11: =ROUND((SUM(O11:Q11)-SUM(T11:U11)),0) -> 0 | W11: 0 | X11: 0 | Y11: =IFERROR(VLOOKUP(D11,'Monthly Deduction'!$M$2:$N$64,2,0),0) -> 0 | Z11: 0 | AA11: =IFERROR(VLOOKUP(D11,'Monthly Deduction'!A:B,2,0),0) -> 0 | AB11: =ROUND(IFERROR(V11-SUM(W11:AA11),0),0) -> 0 | AC11: 0 | AD11: =ROUND(AB11-AC11,0) -> 0 | AE11: =IF(AC11<>0,"Yes","Release") -> Release | AG11: 0 | AI11: 0 | AK11: 115.8 | AL11: =COUNTIF(AK11:AK11,"=NA") -> 0 | AN11: =((MIN(IF(A11>0,MAX(N11*2%,1861),0),A11)))+0 -> 1861 | AO11: =SUMIF('MPG Payment '!E:E,'Shayak Income '!D11,'MPG Payment '!AJ:AJ) -> 500 | AP11: =W11 -> 0 | AQ11: =AO11+AP11 -> 500 | AS11: =B11-X11 -> 6400
A12: =IFERROR(VLOOKUP(D12,'Monthly Deduction'!$I$3:$J$957,2,0),0) -> 39104.976 | B12: =IFERROR(VLOOKUP(D12,'Monthly Deduction'!$E$3:$F$957,2,0),0) -> 0 | C12: =A12+B12 -> 39104.976 | D12: 10010056 | E12: =VLOOKUP(D12,'MPG Payment '!$E$3:$G$498218,2,0) -> Gomukh Harigiridham | F12: =IFERROR(_xlfn.XLOOKUP(D12,'Monthly Deduction'!$I$3:$I$957,'Monthly Deduction'!$H$3:$H$957),0) -> 0 | G12: =VLOOKUP(D12,'MPG Payment '!$E$3:$G$334579,3,0) -> MPG | H12: =VLOOKUP(D12,'MPG Payment '!$E$3:$H$334579,4,0) -> Direct | I12: =INDEX('MPG Payment '!$C:$C,MATCH('Shayak Income '!D12,'MPG Payment '!E:E,0)) -> 1058 | J12: =INDEX('MPG Payment '!$D:$D,MATCH('Shayak Income '!D12,'MPG Payment '!E:E,0)) -> Hasanpur | K12: Old | L12: 45297 | M12: =SUMIF('MPG Payment '!$E$3:$E$34579,'Shayak Income '!D12,'MPG Payment '!$I$3:$I$34579) -> 310.5 | N12: =SUMIF('MPG Payment '!$E$3:$E$34579,'Shayak Income '!D12,'MPG Payment '!$J$3:$J$34579) -> 10255.82 | O12: =+M12*0.75 -> 232.875 | P12: =+M12*0.95 -> 294.975 | Q12: =SUMIF('MPG Payment '!$E$3:$E$34579,'Shayak Income '!D12,'MPG Payment '!$S$3:$S$34579) -> 181.65058 | R12: =+N12*3% -> 307.6746 | S12: =R12-P12 -> 12.6996 | T12: =M12*0.1 -> 31.05 | U12: =(((IF(K12="New",0,SUMIF('MPG Payment '!$E$3:$E$34579,'Shayak Income '!D12,'MPG Payment '!$AC$3:$AC$34579))))+0)+0 -> 257.30383 | V12: =ROUND((SUM(O12:Q12)-SUM(T12:U12)),0) -> 421 | W12: 421 | X12: 0 | Y12: =IFERROR(VLOOKUP(D12,'Monthly Deduction'!$M$2:$N$64,2,0),0) -> 0 | Z12: 0 | AA12: =IFERROR(VLOOKUP(D12,'Monthly Deduction'!A:B,2,0),0) -> 0 | AB12: =ROUND(IFERROR(V12-SUM(W12:AA12),0),0) -> 0 | AC12: =AB12 -> 0 | AD12: =ROUND(AB12-AC12,0) -> 0 | AE12: =IF(AC12<>0,"Yes","Release") -> Release | AG12: 0 | AH12: Non pouring | AI12: 0 | AK12: 0 | AL12: =COUNTIF(AK12:AK12,"=NA") -> 0 | AN12: =((MIN(IF(A12>0,MAX(N12*2%,1861),0),A12)))+0 -> 1861 | AO12: =SUMIF('MPG Payment '!E:E,'Shayak Income '!D12,'MPG Payment '!AJ:AJ) -> 0 | AP12: =W12 -> 421 | AQ12: =AO12+AP12 -> 421 | AS12: =B12-X12 -> 0
A13: =IFERROR(VLOOKUP(D13,'Monthly Deduction'!$I$3:$J$957,2,0),0) -> 0 | B13: =IFERROR(VLOOKUP(D13,'Monthly Deduction'!$E$3:$F$957,2,0),0) -> 0 | C13: =A13+B13 -> 0 | D13: 10010057 | E13: =VLOOKUP(D13,'MPG Payment '!$E$3:$G$498218,2,0) -> Manish Dairy | F13: =IFERROR(_xlfn.XLOOKUP(D13,'Monthly Deduction'!$I$3:$I$957,'Monthly Deduction'!$H$3:$H$957),0) -> 0 | G13: =VLOOKUP(D13,'MPG Payment '!$E$3:$G$334579,3,0) -> vlc | H13: =VLOOKUP(D13,'MPG Payment '!$E$3:$H$334579,4,0) -> Indirect | I13: =INDEX('MPG Payment '!$C:$C,MATCH('Shayak Income '!D13,'MPG Payment '!E:E,0)) -> 1001 | J13: =INDEX('MPG Payment '!$D:$D,MATCH('Shayak Income '!D13,'MPG Payment '!E:E,0)) -> Majhaul | K13: Old | L13: 45000 | M13: =SUMIF('MPG Payment '!$E$3:$E$34579,'Shayak Income '!D13,'MPG Payment '!$I$3:$I$34579) -> 43651.7 | N13: =SUMIF('MPG Payment '!$E$3:$E$34579,'Shayak Income '!D13,'MPG Payment '!$J$3:$J$34579) -> 1561069.5 | O13: =+M13*0.75 -> 32738.775 | P13: =+M13*0.95 -> 41469.115 | Q13: =SUMIF('MPG Payment '!$E$3:$E$34579,'Shayak Income '!D13,'MPG Payment '!$S$3:$S$34579) -> 0 | R13: =+N13*3% -> 46832.086 | S13: =R13-P13 -> 5362.9713 | T13: =M13*0.1 -> 4365.17 | U13: =(((IF(K13="New",0,SUMIF('MPG Payment '!$E$3:$E$34579,'Shayak Income '!D13,'MPG Payment '!$AC$3:$AC$34579))))+0)+0 -> 0 | V13: =ROUND((SUM(O13:Q13)-SUM(T13:U13)),0) -> 69843 | W13: =(((AN13-AO13)))+0 -> 0 | X13: =((MIN(IF(B13>0,MAX(N13*2%),0),B13)))+0 -> 0 | Y13: =IFERROR(VLOOKUP(D13,'Monthly Deduction'!$M$2:$N$64,2,0),0) -> 0 | Z13: 0 | AA13: =IFERROR(VLOOKUP(D13,'Monthly Deduction'!A:B,2,0),0) -> 0 | AB13: =ROUND(IFERROR(V13-SUM(W13:AA13),0),0) -> 69843 | AC13: 0 | AD13: =ROUND(AB13-AC13,0) -> 69843 | AE13: =IF(AC13<>0,"Yes","Release") -> Release | AG13: 0 | AI13: 0 | AK13: 15240.5 | AL13: =COUNTIF(AK13:AK13,"=NA") -> 0 | AN13: =((MIN(IF(A13>0,MAX(N13*2%,1861),0),A13)))+0 -> 0 | AO13: =SUMIF('MPG Payment '!E:E,'Shayak Income '!D13,'MPG Payment '!AJ:AJ) -> 0 | AP13: =W13 -> 0 | AQ13: =AO13+AP13 -> 0 | AS13: =B13-X13 -> 0
A14: =IFERROR(VLOOKUP(D14,'Monthly Deduction'!$I$3:$J$957,2,0),0) -> 46072.587 | B14: =IFERROR(VLOOKUP(D14,'Monthly Deduction'!$E$3:$F$957,2,0),0) -> 16599 | C14: =A14+B14 -> 62671.587 | D14: 10010076 | E14: =VLOOKUP(D14,'MPG Payment '!$E$3:$G$498218,2,0) -> Gomukh Bhith-02 | F14: =IFERROR(_xlfn.XLOOKUP(D14,'Monthly Deduction'!$I$3:$I$957,'Monthly Deduction'!$H$3:$H$957),0) -> 0 | G14: =VLOOKUP(D14,'MPG Payment '!$E$3:$G$334579,3,0) -> MPG | H14: =VLOOKUP(D14,'MPG Payment '!$E$3:$H$334579,4,0) -> Direct | I14: =INDEX('MPG Payment '!$C:$C,MATCH('Shayak Income '!D14,'MPG Payment '!E:E,0)) -> 1001 | J14: =INDEX('MPG Payment '!$D:$D,MATCH('Shayak Income '!D14,'MPG Payment '!E:E,0)) -> Majhaul | K14: Old | L14: 45471 | M14: =SUMIF('MPG Payment '!$E$3:$E$34579,'Shayak Income '!D14,'MPG Payment '!$I$3:$I$34579) -> 1377.5 | N14: =SUMIF('MPG Payment '!$E$3:$E$34579,'Shayak Income '!D14,'MPG Payment '!$J$3:$J$34579) -> 56156.066 | O14: =+M14*0.75 -> 1033.125 | P14: =+M14*0.95 -> 1308.625 | Q14: =SUMIF('MPG Payment '!$E$3:$E$34579,'Shayak Income '!D14,'MPG Payment '!$S$3:$S$34579) -> 0 | R14: =+N14*3% -> 1684.682 | S14: =R14-P14 -> 376.05698 | T14: =M14*0.1 -> 137.75 | U14: =(((IF(K14="New",0,SUMIF('MPG Payment '!$E$3:$E$34579,'Shayak Income '!D14,'MPG Payment '!$AC$3:$AC$34579))))+0)+0 -> 1086.5227 | V14: =ROUND((SUM(O14:Q14)-SUM(T14:U14)),0) -> 1117 | W14: 1117 | X14: 0 | Y14: 0 | Z14: 0 | AA14: =IFERROR(VLOOKUP(D14,'Monthly Deduction'!A:B,2,0),0) -> 0 | AB14: =ROUND(IFERROR(V14-SUM(W14:AA14),0),0) -> 0 | AC14: 0 | AD14: =ROUND(AB14-AC14,0) -> 0 | AE14: =IF(AC14<>0,"Yes","Release") -> Release | AG14: 0 | AI14: 0 | AK14: 721.2 | AL14: =COUNTIF(AK14:AK14,"=NA") -> 0 | AN14: =((MIN(IF(A14>0,MAX(N14*2%,1861),0),A14)))+0 -> 1861 | AO14: =SUMIF('MPG Payment '!E:E,'Shayak Income '!D14,'MPG Payment '!AJ:AJ) -> 0 | AP14: =W14 -> 1117 | AQ14: =AO14+AP14 -> 1117 | AS14: =B14-X14 -> 16599
A15: =IFERROR(VLOOKUP(D15,'Monthly Deduction'!$I$3:$J$957,2,0),0) -> 24636.831 | B15: =IFERROR(VLOOKUP(D15,'Monthly Deduction'!$E$3:$F$957,2,0),0) -> 25600 | C15: =A15+B15 -> 50236.831 | D15: 10010082 | E15: =VLOOKUP(D15,'MPG Payment '!$E$3:$G$498218,2,0) -> Gomukh Sharmatola Sahuri | F15: =IFERROR(_xlfn.XLOOKUP(D15,'Monthly Deduction'!$I$3:$I$957,'Monthly Deduction'!$H$3:$H$957),0) -> 0 | G15: =VLOOKUP(D15,'MPG Payment '!$E$3:$G$334579,3,0) -> MPG | H15: =VLOOKUP(D15,'MPG Payment '!$E$3:$H$334579,4,0) -> Direct | I15: =INDEX('MPG Payment '!$C:$C,MATCH('Shayak Income '!D15,'MPG Payment '!E:E,0)) -> 1001 | J15: =INDEX('MPG Payment '!$D:$D,MATCH('Shayak Income '!D15,'MPG Payment '!E:E,0)) -> Majhaul | K15: Old | L15: 45568 | M15: =SUMIF('MPG Payment '!$E$3:$E$34579,'Shayak Income '!D15,'MPG Payment '!$I$3:$I$34579) -> 4217.7 | N15: =SUMIF('MPG Payment '!$E$3:$E$34579,'Shayak Income '!D15,'MPG Payment '!$J$3:$J$34579) -> 161653.62 | O15: =+M15*0.75 -> 3163.275 | P15: =+M15*0.95 -> 4006.815 | Q15: =SUMIF('MPG Payment '!$E$3:$E$34579,'Shayak Income '!D15,'MPG Payment '!$S$3:$S$34579) -> 0 | R15: =+N15*3% -> 4849.6085 | S15: =R15-P15 -> 842.79346 | T15: =M15*0.1 -> 421.77 | U15: =(((IF(K15="New",0,SUMIF('MPG Payment '!$E$3:$E$34579,'Shayak Income '!D15,'MPG Payment '!$AC$3:$AC$34579))))+0)+0 -> 0 | V15: =ROUND((SUM(O15:Q15)-SUM(T15:U15)),0) -> 6748 | W15: =(((AN15-AO15)))+0 -> 3233.0723 | X15: 0 | Y15: =IFERROR(VLOOKUP(D15,'Monthly Deduction'!$M$2:$N$64,2,0),0) -> 0 | Z15: 0 | AA15: =IFERROR(VLOOKUP(D15,'Monthly Deduction'!A:B,2,0),0) -> 0 | AB15: =ROUND(IFERROR(V15-SUM(W15:AA15),0),0) -> 3515 | AC15: 0 | AD15: =ROUND(AB15-AC15,0) -> 3515 | AE15: =IF(AC15<>0,"Yes","Release") -> Release | AG15: 0 | AI15: 0 | AK15: 1098.4 | AL15: =COUNTIF(AK15:AK15,"=NA") -> 0 | AN15: =((MIN(IF(A15>0,MAX(N15*2%,1861),0),A15)))+0 -> 3233.0723 | AO15: =SUMIF('MPG Payment '!E:E,'Shayak Income '!D15,'MPG Payment '!AJ:AJ) -> 0 | AP15: =W15 -> 3233.0723 | AQ15: =AO15+AP15 -> 3233.0723 | AS15: =B15-X15 -> 25600
A16: =IFERROR(VLOOKUP(D16,'Monthly Deduction'!$I$3:$J$957,2,0),0) -> 0 | B16: =IFERROR(VLOOKUP(D16,'Monthly Deduction'!$E$3:$F$957,2,0),0) -> 0 | C16: =A16+B16 -> 0 | D16: 10010084 | E16: =VLOOKUP(D16,'MPG Payment '!$E$3:$G$498218,2,0) -> Sangat- Sanjeev Kumar | F16: =IFERROR(_xlfn.XLOOKUP(D16,'Monthly Deduction'!$I$3:$I$957,'Monthly Deduction'!$H$3:$H$957),0) -> 0 | G16: =VLOOKUP(D16,'MPG Payment '!$E$3:$G$334579,3,0) -> vlc | H16: =VLOOKUP(D16,'MPG Payment '!$E$3:$H$334579,4,0) -> Indirect | I16: =INDEX('MPG Payment '!$C:$C,MATCH('Shayak Income '!D16,'MPG Payment '!E:E,0)) -> 1001 | J16: =INDEX('MPG Payment '!$D:$D,MATCH('Shayak Income '!D16,'MPG Payment '!E:E,0)) -> Majhaul | K16: Old | L16: 45567 | M16: =SUMIF('MPG Payment '!$E$3:$E$34579,'Shayak Income '!D16,'MPG Payment '!$I$3:$I$34579) -> 695.8 | N16: =SUMIF('MPG Payment '!$E$3:$E$34579,'Shayak Income '!D16,'MPG Payment '!$J$3:$J$34579) -> 24056.155 | O16: =+M16*0.75 -> 521.85 | P16: =+M16*0.95 -> 661.01 | Q16: =SUMIF('MPG Payment '!$E$3:$E$34579,'Shayak Income '!D16,'MPG Payment '!$S$3:$S$34579) -> 0 | R16: =+N16*3% -> 721.68464 | S16: =R16-P16 -> 60.674641 | T16: =M16*0.1 -> 69.58 | U16: =(((IF(K16="New",0,SUMIF('MPG Payment '!$E$3:$E$34579,'Shayak Income '!D16,'MPG Payment '!$AC$3:$AC$34579))))+0)+-348 -> 1113.7438 | V16: =ROUND((SUM(O16:Q16)-SUM(T16:U16)),0) -> 0 | W16: 0 | X16: 0 | Y16: =IFERROR(VLOOKUP(D16,'Monthly Deduction'!$M$2:$N$64,2,0),0) -> 0 | Z16: 0 | AA16: =IFERROR(VLOOKUP(D16,'Monthly Deduction'!A:B,2,0),0) -> 0 | AB16: =ROUND(IFERROR(V16-SUM(W16:AA16),0),0) -> 0 | AC16: 0 | AD16: =ROUND(AB16-AC16,0) -> 0 | AE16: =IF(AC16<>0,"Yes","Release") -> Release | AG16: 0 | AI16: 0 | AK16: 212.4 | AL16: =COUNTIF(AK16:AK16,"=NA") -> 0 | AN16: =((MIN(IF(A16>0,MAX(N16*2%,1861),0),A16)))+0 -> 0 | AO16: =SUMIF('MPG Payment '!E:E,'Shayak Income '!D16,'MPG Payment '!AJ:AJ) -> 0 | AP16: =W16 -> 0 | AQ16: =AO16+AP16 -> 0 | AS16: =B16-X16 -> 0
A17: =IFERROR(VLOOKUP(D17,'Monthly Deduction'!$I$3:$J$957,2,0),0) -> 69596 | B17: =IFERROR(VLOOKUP(D17,'Monthly Deduction'!$E$3:$F$957,2,0),0) -> 6400 | C17: =A17+B17 -> 75996 | D17: 10010086 | E17: =VLOOKUP(D17,'MPG Payment '!$E$3:$G$498218,2,0) -> Gomukh Garhi Bisanpur | F17: =IFERROR(_xlfn.XLOOKUP(D17,'Monthly Deduction'!$I$3:$I$957,'Monthly Deduction'!$H$3:$H$957),0) -> 0 | G17: =VLOOKUP(D17,'MPG Payment '!$E$3:$G$334579,3,0) -> MPG | H17: =VLOOKUP(D17,'MPG Payment '!$E$3:$H$334579,4,0) -> Direct | I17: =INDEX('MPG Payment '!$C:$C,MATCH('Shayak Income '!D17,'MPG Payment '!E:E,0)) -> 1058 | J17: =INDEX('MPG Payment '!$D:$D,MATCH('Shayak Income '!D17,'MPG Payment '!E:E,0)) -> Hasanpur | K17: Old | L17: 45631 | M17: =SUMIF('MPG Payment '!$E$3:$E$34579,'Shayak Income '!D17,'MPG Payment '!$I$3:$I$34579) -> 667.8 | N17: =SUMIF('MPG Payment '!$E$3:$E$34579,'Shayak Income '!D17,'MPG Payment '!$J$3:$J$34579) -> 27120.529 | O17: =+M17*0.75 -> 500.85 | P17: =+M17*0.95 -> 634.41 | Q17: =SUMIF('MPG Payment '!$E$3:$E$34579,'Shayak Income '!D17,'MPG Payment '!$S$3:$S$34579) -> 687.72875 | R17: =+N17*3% -> 813.61586 | S17: =R17-P17 -> 179.20586 | T17: =M17*0.1 -> 66.78 | U17: =(((IF(K17="New",0,SUMIF('MPG Payment '!$E$3:$E$34579,'Shayak Income '!D17,'MPG Payment '!$AC$3:$AC$34579))))+0)+0 -> 1730.2541 | V17: =ROUND((SUM(O17:Q17)-SUM(T17:U17)),0) -> 26 | W17: 26 | X17: 0 | Y17: =IFERROR(VLOOKUP(D17,'Monthly Deduction'!$M$2:$N$64,2,0),0) -> 0 | Z17: 0 | AA17: =IFERROR(VLOOKUP(D17,'Monthly Deduction'!A:B,2,0),0) -> 0 | AB17: =ROUND(IFERROR(V17-SUM(W17:AA17),0),0) -> 0 | AC17: 0 | AD17: =ROUND(AB17-AC17,0) -> 0 | AE17: =IF(AC17<>0,"Yes","Release") -> Release | AG17: 0 | AI17: 0 | AK17: 171.9 | AL17: =COUNTIF(AK17:AK17,"=NA") -> 0 | AN17: =((MIN(IF(A17>0,MAX(N17*2%,1861),0),A17)))+0 -> 1861 | AO17: =SUMIF('MPG Payment '!E:E,'Shayak Income '!D17,'MPG Payment '!AJ:AJ) -> 500 | AP17: =W17 -> 26 | AQ17: =AO17+AP17 -> 526 | AS17: =B17-X17 -> 6400
A18: =IFERROR(VLOOKUP(D18,'Monthly Deduction'!$I$3:$J$957,2,0),0) -> 0 | B18: =IFERROR(VLOOKUP(D18,'Monthly Deduction'!$E$3:$F$957,2,0),0) -> 0 | C18: =A18+B18 -> 0 | D18: 10010087 | E18: =VLOOKUP(D18,'MPG Payment '!$E$3:$G$498218,2,0) -> Bagaraha-Gopal Yadav | F18: =IFERROR(_xlfn.XLOOKUP(D18,'Monthly Deduction'!$I$3:$I$957,'Monthly Deduction'!$H$3:$H$957),0) -> 0 | G18: =VLOOKUP(D18,'MPG Payment '!$E$3:$G$334579,3,0) -> vlc | H18: =VLOOKUP(D18,'MPG Payment '!$E$3:$H$334579,4,0) -> Indirect | I18: =INDEX('MPG Payment '!$C:$C,MATCH('Shayak Income '!D18,'MPG Payment '!E:E,0)) -> 1058 | J18: =INDEX('MPG Payment '!$D:$D,MATCH('Shayak Income '!D18,'MPG Payment '!E:E,0)) -> Hasanpur | K18: Old | L18: 45597 | M18: =SUMIF('MPG Payment '!$E$3:$E$34579,'Shayak Income '!D18,'MPG Payment '!$I$3:$I$34579) -> 369.2 | N18: =SUMIF('MPG Payment '!$E$3:$E$34579,'Shayak Income '!D18,'MPG Payment '!$J$3:$J$34579) -> 11256.47 | O18: =+M18*0.75 -> 276.9 | P18: =+M18*0.95 -> 350.74 | Q18: =SUMIF('MPG Payment '!$E$3:$E$34579,'Shayak Income '!D18,'MPG Payment '!$S$3:$S$34579) -> 0 | R18: =+N18*3% -> 337.6941 | S18: =R18-P18 -> -13.0459 | T18: =M18*0.1 -> 36.92 | U18: =(((IF(K18="New",0,SUMIF('MPG Payment '!$E$3:$E$34579,'Shayak Income '!D18,'MPG Payment '!$AC$3:$AC$34579))))+0)+-459 -> 590.61245 | V18: =ROUND((SUM(O18:Q18)-SUM(T18:U18)),0) -> 0 | W18: 0 | X18: 0 | Y18: =IFERROR(VLOOKUP(D18,'Monthly Deduction'!$M$2:$N$64,2,0),0) -> 0 | Z18: 0 | AA18: =IFERROR(VLOOKUP(D18,'Monthly Deduction'!A:B,2,0),0) -> 0 | AB18: =ROUND(IFERROR(V18-SUM(W18:AA18),0),0) -> 0 | AC18: =AB18 -> 0 | AD18: =ROUND(AB18-AC18,0) -> 0 | AE18: =IF(AC18<>0,"Yes","Release") -> Release | AG18: 0 | AH18: Non pouring | AI18: 0 | AK18: 0 | AL18: =COUNTIF(AK18:AK18,"=NA") -> 0 | AN18: =((MIN(IF(A18>0,MAX(N18*2%,1861),0),A18)))+0 -> 0 | AO18: =SUMIF('MPG Payment '!E:E,'Shayak Income '!D18,'MPG Payment '!AJ:AJ) -> 0 | AP18: =W18 -> 0 | AQ18: =AO18+AP18 -> 0 | AS18: =B18-X18 -> 0
A19: =IFERROR(VLOOKUP(D19,'Monthly Deduction'!$I$3:$J$957,2,0),0) -> 76509.047 | B19: =IFERROR(VLOOKUP(D19,'Monthly Deduction'!$E$3:$F$957,2,0),0) -> 12099 | C19: =A19+B19 -> 88608.047 | D19: 10010089 | E19: =VLOOKUP(D19,'MPG Payment '!$E$3:$G$498218,2,0) -> Gomukh Barkurwa | F19: =IFERROR(_xlfn.XLOOKUP(D19,'Monthly Deduction'!$I$3:$I$957,'Monthly Deduction'!$H$3:$H$957),0) -> 0 | G19: =VLOOKUP(D19,'MPG Payment '!$E$3:$G$334579,3,0) -> MPG | H19: =VLOOKUP(D19,'MPG Payment '!$E$3:$H$334579,4,0) -> Direct | I19: =INDEX('MPG Payment '!$C:$C,MATCH('Shayak Income '!D19,'MPG Payment '!E:E,0)) -> 1058 | J19: =INDEX('MPG Payment '!$D:$D,MATCH('Shayak Income '!D19,'MPG Payment '!E:E,0)) -> Hasanpur | K19: Old | L19: 45627 | M19: =SUMIF('MPG Payment '!$E$3:$E$34579,'Shayak Income '!D19,'MPG Payment '!$I$3:$I$34579) -> 1480.6 | N19: =SUMIF('MPG Payment '!$E$3:$E$34579,'Shayak Income '!D19,'MPG Payment '!$J$3:$J$34579) -> 54697.528 | O19: =+M19*0.75 -> 1110.45 | P19: =+M19*0.95 -> 1406.57 | Q19: =SUMIF('MPG Payment '!$E$3:$E$34579,'Shayak Income '!D19,'MPG Payment '!$S$3:$S$34579) -> 1025.9872 | R19: =+N19*3% -> 1640.9258 | S19: =R19-P19 -> 234.35584 | T19: =M19*0.1 -> 148.06 | U19: =(((IF(K19="New",0,SUMIF('MPG Payment '!$E$3:$E$34579,'Shayak Income '!D19,'MPG Payment '!$AC$3:$AC$34579))))+0)+0 -> 970.92356 | V19: =ROUND((SUM(O19:Q19)-SUM(T19:U19)),0) -> 2424 | W19: =(((AN19-AO19)))+0 -> 1861 | X19: 0 | Y19: =IFERROR(VLOOKUP(D19,'Monthly Deduction'!$M$2:$N$64,2,0),0) -> 0 | Z19: 0 | AA19: =IFERROR(VLOOKUP(D19,'Monthly Deduction'!A:B,2,0),0) -> 0 | AB19: =ROUND(IFERROR(V19-SUM(W19:AA19),0),0) -> 563 | AC19: 0 | AD19: =ROUND(AB19-AC19,0) -> 563 | AE19: =IF(AC19<>0,"Yes","Release") -> Release | AG19: 0 | AI19: 0 | AK19: 385 | AL19: =COUNTIF(AK19:AK19,"=NA") -> 0 | AN19: =((MIN(IF(A19>0,MAX(N19*2%,1861),0),A19)))+0 -> 1861 | AO19: =SUMIF('MPG Payment '!E:E,'Shayak Income '!D19,'MPG Payment '!AJ:AJ) -> 0 | AP19: =W19 -> 1861 | AQ19: =AO19+AP19 -> 1861 | AS19: =B19-X19 -> 12099
A20: =IFERROR(VLOOKUP(D20,'Monthly Deduction'!$I$3:$J$957,2,0),0) -> 0 | B20: =IFERROR(VLOOKUP(D20,'Monthly Deduction'!$E$3:$F$957,2,0),0) -> 0 | C20: =A20+B20 -> 0 | D20: 10010092 | E20: =VLOOKUP(D20,'MPG Payment '!$E$3:$G$498218,2,0) -> Kamla- Amarjeet | F20: =IFERROR(_xlfn.XLOOKUP(D20,'Monthly Deduction'!$I$3:$I$957,'Monthly Deduction'!$H$3:$H$957),0) -> 0 | G20: =VLOOKUP(D20,'MPG Payment '!$E$3:$G$334579,3,0) -> vlc | H20: =VLOOKUP(D20,'MPG Payment '!$E$3:$H$334579,4,0) -> Indirect | I20: =INDEX('MPG Payment '!$C:$C,MATCH('Shayak Income '!D20,'MPG Payment '!E:E,0)) -> 1001 | J20: =INDEX('MPG Payment '!$D:$D,MATCH('Shayak Income '!D20,'MPG Payment '!E:E,0)) -> Majhaul | K20: Old | L20: 45689 | M20: =SUMIF('MPG Payment '!$E$3:$E$34579,'Shayak Income '!D20,'MPG Payment '!$I$3:$I$34579) -> 2502.7 | N20: =SUMIF('MPG Payment '!$E$3:$E$34579,'Shayak Income '!D20,'MPG Payment '!$J$3:$J$34579) -> 80861.315 | O20: =+M20*0.75 -> 1877.025 | P20: =+M20*0.95 -> 2377.565 | Q20: =SUMIF('MPG Payment '!$E$3:$E$34579,'Shayak Income '!D20,'MPG Payment '!$S$3:$S$34579) -> 0 | R20: =+N20*3% -> 2425.8395 | S20: =R20-P20 -> 48.274456 | T20: =M20*0.1 -> 250.27 | U20: =(((IF(K20="New",0,SUMIF('MPG Payment '!$E$3:$E$34579,'Shayak Income '!D20,'MPG Payment '!$AC$3:$AC$34579))))+0)+0 -> 398.6475 | V20: =ROUND((SUM(O20:Q20)-SUM(T20:U20)),0) -> 3606 | W20: =(((AN20-AO20)))+0 -> 0 | X20: =((MIN(IF(B20>0,MAX(N20*2%),0),B20)))+0 -> 0 | Y20: =IFERROR(VLOOKUP(D20,'Monthly Deduction'!$M$2:$N$64,2,0),0) -> 0 | Z20: 0 | AA20: =IFERROR(VLOOKUP(D20,'Monthly Deduction'!A:B,2,0),0) -> 0 | AB20: =ROUND(IFERROR(V20-SUM(W20:AA20),0),0) -> 3606 | AC20: 0 | AD20: =ROUND(AB20-AC20,0) -> 3606 | AE20: =IF(AC20<>0,"Yes","Release") -> Release | AG20: 0 | AI20: 0 | AK20: 924.6 | AL20: =COUNTIF(AK20:AK20,"=NA") -> 0 | AN20: =((MIN(IF(A20>0,MAX(N20*2%,1861),0),A20)))+0 -> 0 | AO20: =SUMIF('MPG Payment '!E:E,'Shayak Income '!D20,'MPG Payment '!AJ:AJ) -> 0 | AP20: =W20 -> 0 | AQ20: =AO20+AP20 -> 0 | AS20: =B20-X20 -> 0
A21: =IFERROR(VLOOKUP(D21,'Monthly Deduction'!$I$3:$J$957,2,0),0) -> 74949 | B21: =IFERROR(VLOOKUP(D21,'Monthly Deduction'!$E$3:$F$957,2,0),0) -> 3016.2028 | C21: =A21+B21 -> 77965.203 | D21: 10010095 | E21: =VLOOKUP(D21,'MPG Payment '!$E$3:$G$498218,2,0) -> Gomukh Goha-02 | F21: =IFERROR(_xlfn.XLOOKUP(D21,'Monthly Deduction'!$I$3:$I$957,'Monthly Deduction'!$H$3:$H$957),0) -> 0 | G21: =VLOOKUP(D21,'MPG Payment '!$E$3:$G$334579,3,0) -> MPG | H21: =VLOOKUP(D21,'MPG Payment '!$E$3:$H$334579,4,0) -> Direct | I21: =INDEX('MPG Payment '!$C:$C,MATCH('Shayak Income '!D21,'MPG Payment '!E:E,0)) -> 1058 | J21: =INDEX('MPG Payment '!$D:$D,MATCH('Shayak Income '!D21,'MPG Payment '!E:E,0)) -> Hasanpur | K21: Old | L21: 45700 | M21: =SUMIF('MPG Payment '!$E$3:$E$34579,'Shayak Income '!D21,'MPG Payment '!$I$3:$I$34579) -> 1413.8 | N21: =SUMIF('MPG Payment '!$E$3:$E$34579,'Shayak Income '!D21,'MPG Payment '!$J$3:$J$34579) -> 56374.5 | O21: =+M21*0.75 -> 1060.35 | P21: =+M21*0.95 -> 1343.11 | Q21: =SUMIF('MPG Payment '!$E$3:$E$34579,'Shayak Income '!D21,'MPG Payment '!$S$3:$S$34579) -> 613.81683 | R21: =+N21*3% -> 1691.235 | S21: =R21-P21 -> 348.12501 | T21: =M21*0.1 -> 141.38 | U21: =(((IF(K21="New",0,SUMIF('MPG Payment '!$E$3:$E$34579,'Shayak Income '!D21,'MPG Payment '!$AC$3:$AC$34579))))+0)+0 -> 1108.3637 | V21: =ROUND((SUM(O21:Q21)-SUM(T21:U21)),0) -> 1768 | W21: 1768 | X21: 0 | Y21: =IFERROR(VLOOKUP(D21,'Monthly Deduction'!$M$2:$N$64,2,0),0) -> 0 | Z21: 0 | AA21: =IFERROR(VLOOKUP(D21,'Monthly Deduction'!A:B,2,0),0) -> 0 | AB21: =ROUND(IFERROR(V21-SUM(W21:AA21),0),0) -> 0 | AC21: 0 | AD21: =ROUND(AB21-AC21,0) -> 0 | AE21: =IF(AC21<>0,"Yes","Release") -> Release | AG21: 0 | AI21: 0 | AK21: 364.8 | AL21: =COUNTIF(AK21:AK21,"=NA") -> 0 | AN21: =((MIN(IF(A21>0,MAX(N21*2%,1861),0),A21)))+0 -> 1861 | AO21: =SUMIF('MPG Payment '!E:E,'Shayak Income '!D21,'MPG Payment '!AJ:AJ) -> 0 | AP21: =W21 -> 1768 | AQ21: =AO21+AP21 -> 1768 | AS21: =B21-X21 -> 3016.2028
A22: =IFERROR(VLOOKUP(D22,'Monthly Deduction'!$I$3:$J$957,2,0),0) -> 53294.033 | B22: =IFERROR(VLOOKUP(D22,'Monthly Deduction'!$E$3:$F$957,2,0),0) -> 1290.9666 | C22: =A22+B22 -> 54584.999 | D22: 10010097 | E22: =VLOOKUP(D22,'MPG Payment '!$E$3:$G$498218,2,0) -> Gomukh Cheria Bariarpur | F22: =IFERROR(_xlfn.XLOOKUP(D22,'Monthly Deduction'!$I$3:$I$957,'Monthly Deduction'!$H$3:$H$957),0) -> 0 | G22: =VLOOKUP(D22,'MPG Payment '!$E$3:$G$334579,3,0) -> MPG | H22: =VLOOKUP(D22,'MPG Payment '!$E$3:$H$334579,4,0) -> Direct | I22: =INDEX('MPG Payment '!$C:$C,MATCH('Shayak Income '!D22,'MPG Payment '!E:E,0)) -> 1001 | J22: =INDEX('MPG Payment '!$D:$D,MATCH('Shayak Income '!D22,'MPG Payment '!E:E,0)) -> Majhaul | K22: Old | L22: 45708 | M22: =SUMIF('MPG Payment '!$E$3:$E$34579,'Shayak Income '!D22,'MPG Payment '!$I$3:$I$34579) -> 5359.2 | N22: =SUMIF('MPG Payment '!$E$3:$E$34579,'Shayak Income '!D22,'MPG Payment '!$J$3:$J$34579) -> 202797.15 | O22: =+M22*0.75 -> 4019.4 | P22: =+M22*0.95 -> 5091.24 | Q22: =SUMIF('MPG Payment '!$E$3:$E$34579,'Shayak Income '!D22,'MPG Payment '!$S$3:$S$34579) -> 268.4937 | R22: =+N22*3% -> 6083.9145 | S22: =R22-P22 -> 992.67455 | T22: =M22*0.1 -> 535.92 | U22: =(((IF(K22="New",0,SUMIF('MPG Payment '!$E$3:$E$34579,'Shayak Income '!D22,'MPG Payment '!$AC$3:$AC$34579))))+0)+0 -> 0 | V22: =ROUND((SUM(O22:Q22)-SUM(T22:U22)),0) -> 8843 | W22: =(((AN22-AO22)))+0 -> 4055.943 | X22: 0 | Y22: =IFERROR(VLOOKUP(D22,'Monthly Deduction'!$M$2:$N$64,2,0),0) -> 0 | Z22: 0 | AA22: =IFERROR(VLOOKUP(D22,'Monthly Deduction'!A:B,2,0),0) -> 0 | AB22: =ROUND(IFERROR(V22-SUM(W22:AA22),0),0) -> 4787 | AC22: 0 | AD22: =ROUND(AB22-AC22,0) -> 4787 | AE22: =IF(AC22<>0,"Yes","Release") -> Release | AG22: 0 | AI22: 0 | AK22: 1354.1 | AL22: =COUNTIF(AK22:AK22,"=NA") -> 0 | AN22: =((MIN(IF(A22>0,MAX(N22*2%,1861),0),A22)))+0 -> 4055.943 | AO22: =SUMIF('MPG Payment '!E:E,'Shayak Income '!D22,'MPG Payment '!AJ:AJ) -> 0 | AP22: =W22 -> 4055.943 | AQ22: =AO22+AP22 -> 4055.943 | AS22: =B22-X22 -> 1290.9666
A23: =IFERROR(VLOOKUP(D23,'Monthly Deduction'!$I$3:$J$957,2,0),0) -> 65590.14 | B23: =IFERROR(VLOOKUP(D23,'Monthly Deduction'!$E$3:$F$957,2,0),0) -> 4832.8168 | C23: =A23+B23 -> 70422.957 | D23: 10010098 | E23: =VLOOKUP(D23,'MPG Payment '!$E$3:$G$498218,2,0) -> Gomukh Rahul Nagar | F23: =IFERROR(_xlfn.XLOOKUP(D23,'Monthly Deduction'!$I$3:$I$957,'Monthly Deduction'!$H$3:$H$957),0) -> 0 | G23: =VLOOKUP(D23,'MPG Payment '!$E$3:$G$334579,3,0) -> MPG | H23: =VLOOKUP(D23,'MPG Payment '!$E$3:$H$334579,4,0) -> Direct | I23: =INDEX('MPG Payment '!$C:$C,MATCH('Shayak Income '!D23,'MPG Payment '!E:E,0)) -> 1058 | J23: =INDEX('MPG Payment '!$D:$D,MATCH('Shayak Income '!D23,'MPG Payment '!E:E,0)) -> Hasanpur | K23: Old | L23: 45700 | M23: =SUMIF('MPG Payment '!$E$3:$E$34579,'Shayak Income '!D23,'MPG Payment '!$I$3:$I$34579) -> 1460.8 | N23: =SUMIF('MPG Payment '!$E$3:$E$34579,'Shayak Income '!D23,'MPG Payment '!$J$3:$J$34579) -> 54507.871 | O23: =+M23*0.75 -> 1095.6 | P23: =+M23*0.95 -> 1387.76 | Q23: =SUMIF('MPG Payment '!$E$3:$E$34579,'Shayak Income '!D23,'MPG Payment '!$S$3:$S$34579) -> 918.93757 | R23: =+N23*3% -> 1635.2361 | S23: =R23-P23 -> 247.47614 | T23: =M23*0.1 -> 146.08 | U23: =(((IF(K23="New",0,SUMIF('MPG Payment '!$E$3:$E$34579,'Shayak Income '!D23,'MPG Payment '!$AC$3:$AC$34579))))+0)+0 -> 999.94029 | V23: =ROUND((SUM(O23:Q23)-SUM(T23:U23)),0) -> 2256 | W23: =(((AN23-AO23)))+0 -> 1861 | X23: 0 | Y23: =IFERROR(VLOOKUP(D23,'Monthly Deduction'!$M$2:$N$64,2,0),0) -> 0 | Z23: 0 | AA23: =IFERROR(VLOOKUP(D23,'Monthly Deduction'!A:B,2,0),0) -> 0 | AB23: =ROUND(IFERROR(V23-SUM(W23:AA23),0),0) -> 395 | AC23: =AB23 -> 395 | AD23: =ROUND(AB23-AC23,0) -> 0 | AE23: =IF(AC23<>0,"Yes","Release") -> Yes | AG23: 0 | AH23: Non pouring | AI23: 0 | AK23: 0 | AL23: =COUNTIF(AK23:AK23,"=NA") -> 0 | AN23: =((MIN(IF(A23>0,MAX(N23*2%,1861),0),A23)))+0 -> 1861 | AO23: =SUMIF('MPG Payment '!E:E,'Shayak Income '!D23,'MPG Payment '!AJ:AJ) -> 0 | AP23: =W23 -> 1861 | AQ23: =AO23+AP23 -> 1861 | AS23: =B23-X23 -> 4832.8168
A24: =IFERROR(VLOOKUP(D24,'Monthly Deduction'!$I$3:$J$957,2,0),0) -> 71985 | B24: =IFERROR(VLOOKUP(D24,'Monthly Deduction'!$E$3:$F$957,2,0),0) -> 0 | C24: =A24+B24 -> 71985 | D24: 10010099 | E24: =VLOOKUP(D24,'MPG Payment '!$E$3:$G$498218,2,0) -> Gomukh Bagraha-01 | F24: =IFERROR(_xlfn.XLOOKUP(D24,'Monthly Deduction'!$I$3:$I$957,'Monthly Deduction'!$H$3:$H$957),0) -> 0 | G24: =VLOOKUP(D24,'MPG Payment '!$E$3:$G$334579,3,0) -> MPG | H24: =VLOOKUP(D24,'MPG Payment '!$E$3:$H$334579,4,0) -> Direct | I24: =INDEX('MPG Payment '!$C:$C,MATCH('Shayak Income '!D24,'MPG Payment '!E:E,0)) -> 1058 | J24: =INDEX('MPG Payment '!$D:$D,MATCH('Shayak Income '!D24,'MPG Payment '!E:E,0)) -> Hasanpur | K24: Old | L24: 45736 | M24: =SUMIF('MPG Payment '!$E$3:$E$34579,'Shayak Income '!D24,'MPG Payment '!$I$3:$I$34579) -> 465.4 | N24: =SUMIF('MPG Payment '!$E$3:$E$34579,'Shayak Income '!D24,'MPG Payment '!$J$3:$J$34579) -> 20751.825 | O24: =+M24*0.75 -> 349.05 | P24: =+M24*0.95 -> 442.13 | Q24: =SUMIF('MPG Payment '!$E$3:$E$34579,'Shayak Income '!D24,'MPG Payment '!$S$3:$S$34579) -> 205.92554 | R24: =+N24*3% -> 622.55476 | S24: =R24-P24 -> 180.42476 | T24: =M24*0.1 -> 46.54 | U24: =(((IF(K24="New",0,SUMIF('MPG Payment '!$E$3:$E$34579,'Shayak Income '!D24,'MPG Payment '!$AC$3:$AC$34579))))+0)+-1146 -> 951.06353 | V24: =ROUND((SUM(O24:Q24)-SUM(T24:U24)),0) -> 0 | W24: 0 | X24: 0 | Y24: =IFERROR(VLOOKUP(D24,'Monthly Deduction'!$M$2:$N$64,2,0),0) -> 0 | Z24: 0 | AA24: =IFERROR(VLOOKUP(D24,'Monthly Deduction'!A:B,2,0),0) -> 0 | AB24: =ROUND(IFERROR(V24-SUM(W24:AA24),0),0) -> 0 | AC24: 0 | AD24: =ROUND(AB24-AC24,0) -> 0 | AE24: =IF(AC24<>0,"Yes","Release") -> Release | AG24: 0 | AI24: 0 | AK24: 201.8 | AL24: =COUNTIF(AK24:AK24,"=NA") -> 0 | AN24: =((MIN(IF(A24>0,MAX(N24*2%,1861),0),A24)))+0 -> 1861 | AO24: =SUMIF('MPG Payment '!E:E,'Shayak Income '!D24,'MPG Payment '!AJ:AJ) -> 500 | AP24: =W24 -> 0 | AQ24: =AO24+AP24 -> 500 | AS24: =B24-X24 -> 0
A25: =IFERROR(VLOOKUP(D25,'Monthly Deduction'!$I$3:$J$957,2,0),0) -> 67263.302 | B25: =IFERROR(VLOOKUP(D25,'Monthly Deduction'!$E$3:$F$957,2,0),0) -> 6400 | C25: =A25+B25 -> 73663.302 | D25: 10010103 | E25: =VLOOKUP(D25,'MPG Payment '!$E$3:$G$498218,2,0) -> Gomukh Shobhaipura | F25: =IFERROR(_xlfn.XLOOKUP(D25,'Monthly Deduction'!$I$3:$I$957,'Monthly Deduction'!$H$3:$H$957),0) -> 0 | G25: =VLOOKUP(D25,'MPG Payment '!$E$3:$G$334579,3,0) -> MPG | H25: =VLOOKUP(D25,'MPG Payment '!$E$3:$H$334579,4,0) -> Direct | I25: =INDEX('MPG Payment '!$C:$C,MATCH('Shayak Income '!D25,'MPG Payment '!E:E,0)) -> 1058 | J25: =INDEX('MPG Payment '!$D:$D,MATCH('Shayak Income '!D25,'MPG Payment '!E:E,0)) -> Hasanpur | K25: Old | L25: 45737 | M25: =SUMIF('MPG Payment '!$E$3:$E$34579,'Shayak Income '!D25,'MPG Payment '!$I$3:$I$34579) -> 20.3 | N25: =SUMIF('MPG Payment '!$E$3:$E$34579,'Shayak Income '!D25,'MPG Payment '!$J$3:$J$34579) -> 753.82 | O25: =+M25*0.75 -> 15.225 | P25: =+M25*0.95 -> 19.285 | Q25: =SUMIF('MPG Payment '!$E$3:$E$34579,'Shayak Income '!D25,'MPG Payment '!$S$3:$S$34579) -> 0 | R25: =+N25*3% -> 22.6146 | S25: =R25-P25 -> 3.3296 | T25: =M25*0.1 -> 2.03 | U25: =(((IF(K25="New",0,SUMIF('MPG Payment '!$E$3:$E$34579,'Shayak Income '!D25,'MPG Payment '!$AC$3:$AC$34579))))+0)+-472 -> 32.799462 | V25: =ROUND((SUM(O25:Q25)-SUM(T25:U25)),0) -> 0 | W25: 0 | X25: 0 | Y25: =IFERROR(VLOOKUP(D25,'Monthly Deduction'!$M$2:$N$64,2,0),0) -> 0 | Z25: 0 | AA25: =IFERROR(VLOOKUP(D25,'Monthly Deduction'!A:B,2,0),0) -> 0 | AB25: =ROUND(IFERROR(V25-SUM(W25:AA25),0),0) -> 0 | AC25: =AB25 -> 0 | AD25: =ROUND(AB25-AC25,0) -> 0 | AE25: =IF(AC25<>0,"Yes","Release") -> Release | AG25: 0 | AH25: Non pouring | AI25: 0 | AK25: 0 | AL25: =COUNTIF(AK25:AK25,"=NA") -> 0 | AN25: =((MIN(IF(A25>0,MAX(N25*2%,1861),0),A25)))+0 -> 1861 | AO25: =SUMIF('MPG Payment '!E:E,'Shayak Income '!D25,'MPG Payment '!AJ:AJ) -> 0 | AP25: =W25 -> 0 | AQ25: =AO25+AP25 -> 0 | AS25: =B25-X25 -> 6400
A26: =IFERROR(VLOOKUP(D26,'Monthly Deduction'!$I$3:$J$957,2,0),0) -> 91249 | B26: =IFERROR(VLOOKUP(D26,'Monthly Deduction'!$E$3:$F$957,2,0),0) -> 0 | C26: =A26+B26 -> 91249 | D26: 10010108 | E26: =VLOOKUP(D26,'MPG Payment '!$E$3:$G$498218,2,0) -> Gomukh Pirauna | F26: =IFERROR(_xlfn.XLOOKUP(D26,'Monthly Deduction'!$I$3:$I$957,'Monthly Deduction'!$H$3:$H$957),0) -> 0 | G26: =VLOOKUP(D26,'MPG Payment '!$E$3:$G$334579,3,0) -> MPG | H26: =VLOOKUP(D26,'MPG Payment '!$E$3:$H$334579,4,0) -> Direct | I26: =INDEX('MPG Payment '!$C:$C,MATCH('Shayak Income '!D26,'MPG Payment '!E:E,0)) -> 1001 | J26: =INDEX('MPG Payment '!$D:$D,MATCH('Shayak Income '!D26,'MPG Payment '!E:E,0)) -> Majhaul | K26: Old | L26: 45777 | M26: =SUMIF('MPG Payment '!$E$3:$E$34579,'Shayak Income '!D26,'MPG Payment '!$I$3:$I$34579) -> 619.2 | N26: =SUMIF('MPG Payment '!$E$3:$E$34579,'Shayak Income '!D26,'MPG Payment '!$J$3:$J$34579) -> 22612.027 | O26: =+M26*0.75 -> 464.4 | P26: =+M26*0.95 -> 588.24 | Q26: =SUMIF('MPG Payment '!$E$3:$E$34579,'Shayak Income '!D26,'MPG Payment '!$S$3:$S$34579) -> 249.45331 | R26: =+N26*3% -> 678.36081 | S26: =R26-P26 -> 90.120806 | T26: =M26*0.1 -> 61.92 | U26: =(((IF(K26="New",0,SUMIF('MPG Payment '!$E$3:$E$34579,'Shayak Income '!D26,'MPG Payment '!$AC$3:$AC$34579))))+0)+-332 -> 1240.5158 | V26: =ROUND((SUM(O26:Q26)-SUM(T26:U26)),0) -> 0 | W26: 0 | X26: 0 | Y26: =IFERROR(VLOOKUP(D26,'Monthly Deduction'!$M$2:$N$64,2,0),0) -> 0 | Z26: 0 | AA26: 0 | AB26: =ROUND(IFERROR(V26-SUM(W26:AA26),0),0) -> 0 | AC26: =AB26 -> 0 | AD26: =ROUND(AB26-AC26,0) -> 0 | AE26: =IF(AC26<>0,"Yes","Release") -> Release | AG26: 0 | AH26: Down Payment / Agreement issue | AI26: 9803 | AK26: 280.3 | AL26: =COUNTIF(AK26:AK26,"=NA") -> 0 | AN26: =((MIN(IF(A26>0,MAX(N26*2%,1861),0),A26)))+0 -> 1861 | AO26: =SUMIF('MPG Payment '!E:E,'Shayak Income '!D26,'MPG Payment '!AJ:AJ) -> 500 | AP26: =W26 -> 0 | AQ26: =AO26+AP26 -> 500 | AS26: =B26-X26 -> 0
A27: =IFERROR(VLOOKUP(D27,'Monthly Deduction'!$I$3:$J$957,2,0),0) -> 0 | B27: =IFERROR(VLOOKUP(D27,'Monthly Deduction'!$E$3:$F$957,2,0),0) -> 0 | C27: =A27+B27 -> 0 | D27: 10010109 | E27: =VLOOKUP(D27,'MPG Payment '!$E$3:$G$498218,2,0) -> Parra- Nagendra Kumar | F27: =IFERROR(_xlfn.XLOOKUP(D27,'Monthly Deduction'!$I$3:$I$957,'Monthly Deduction'!$H$3:$H$957),0) -> 0 | G27: =VLOOKUP(D27,'MPG Payment '!$E$3:$G$334579,3,0) -> vlc | H27: =VLOOKUP(D27,'MPG Payment '!$E$3:$H$334579,4,0) -> Indirect | I27: =INDEX('MPG Payment '!$C:$C,MATCH('Shayak Income '!D27,'MPG Payment '!E:E,0)) -> 1001 | J27: =INDEX('MPG Payment '!$D:$D,MATCH('Shayak Income '!D27,'MPG Payment '!E:E,0)) -> Majhaul | K27: Old | L27: 45777 | M27: =SUMIF('MPG Payment '!$E$3:$E$34579,'Shayak Income '!D27,'MPG Payment '!$I$3:$I$34579) -> 1161 | N27: =SUMIF('MPG Payment '!$E$3:$E$34579,'Shayak Income '!D27,'MPG Payment '!$J$3:$J$34579) -> 39071.586 | O27: =+M27*0.75 -> 870.75 | P27: =+M27*0.95 -> 1102.95 | Q27: =SUMIF('MPG Payment '!$E$3:$E$34579,'Shayak Income '!D27,'MPG Payment '!$S$3:$S$34579) -> 0 | R27: =+N27*3% -> 1172.1476 | S27: =R27-P27 -> 69.197579 | T27: =M27*0.1 -> 116.1 | U27: =(((IF(K27="New",0,SUMIF('MPG Payment '!$E$3:$E$34579,'Shayak Income '!D27,'MPG Payment '!$AC$3:$AC$34579))))+0)+0 -> 1102.2143 | V27: =ROUND((SUM(O27:Q27)-SUM(T27:U27)),0) -> 755 | W27: =(((AN27-AO27)))+0 -> 0 | X27: =((MIN(IF(B27>0,MAX(N27*2%),0),B27)))+0 -> 0 | Y27: =IFERROR(VLOOKUP(D27,'Monthly Deduction'!$M$2:$N$64,2,0),0) -> 0 | Z27: 0 | AA27: =IFERROR(VLOOKUP(D27,'Monthly Deduction'!A:B,2,0),0) -> 0 | AB27: =ROUND(IFERROR(V27-SUM(W27:AA27),0),0) -> 755 | AC27: 0 | AD27: =ROUND(AB27-AC27,0) -> 755 | AE27: =IF(AC27<>0,"Yes","Release") -> Release | AG27: 0 | AI27: 0 | AK27: 285.5 | AL27: =COUNTIF(AK27:AK27,"=NA") -> 0 | AN27: =((MIN(IF(A27>0,MAX(N27*2%,1861),0),A27)))+0 -> 0 | AO27: =SUMIF('MPG Payment '!E:E,'Shayak Income '!D27,'MPG Payment '!AJ:AJ) -> 0 | AP27: =W27 -> 0 | AQ27: =AO27+AP27 -> 0 | AS27: =B27-X27 -> 0
A28: =IFERROR(VLOOKUP(D28,'Monthly Deduction'!$I$3:$J$957,2,0),0) -> 83878.195 | B28: =IFERROR(VLOOKUP(D28,'Monthly Deduction'!$E$3:$F$957,2,0),0) -> 0 | C28: =A28+B28 -> 83878.195 | D28: 10010113 | E28: =VLOOKUP(D28,'MPG Payment '!$E$3:$G$498218,2,0) -> Gomukh Basahi | F28: =IFERROR(_xlfn.XLOOKUP(D28,'Monthly Deduction'!$I$3:$I$957,'Monthly Deduction'!$H$3:$H$957),0) -> 0 | G28: =VLOOKUP(D28,'MPG Payment '!$E$3:$G$334579,3,0) -> MPG | H28: =VLOOKUP(D28,'MPG Payment '!$E$3:$H$334579,4,0) -> Direct | I28: =INDEX('MPG Payment '!$C:$C,MATCH('Shayak Income '!D28,'MPG Payment '!E:E,0)) -> 1001 | J28: =INDEX('MPG Payment '!$D:$D,MATCH('Shayak Income '!D28,'MPG Payment '!E:E,0)) -> Majhaul | K28: Old | L28: 45810 | M28: =SUMIF('MPG Payment '!$E$3:$E$34579,'Shayak Income '!D28,'MPG Payment '!$I$3:$I$34579) -> 3226.1 | N28: =SUMIF('MPG Payment '!$E$3:$E$34579,'Shayak Income '!D28,'MPG Payment '!$J$3:$J$34579) -> 127677.23 | O28: =+M28*0.75 -> 2419.575 | P28: =+M28*0.95 -> 3064.795 | Q28: =SUMIF('MPG Payment '!$E$3:$E$34579,'Shayak Income '!D28,'MPG Payment '!$S$3:$S$34579) -> 997.33556 | R28: =+N28*3% -> 3830.3169 | S28: =R28-P28 -> 765.52186 | T28: =M28*0.1 -> 322.61 | U28: =(((IF(K28="New",0,SUMIF('MPG Payment '!$E$3:$E$34579,'Shayak Income '!D28,'MPG Payment '!$AC$3:$AC$34579))))+0)+0 -> 0 | V28: =ROUND((SUM(O28:Q28)-SUM(T28:U28)),0) -> 6159 | W28: =(((AN28-AO28)))+0 -> 2553.5446 | X28: 0 | Y28: =IFERROR(VLOOKUP(D28,'Monthly Deduction'!$M$2:$N$64,2,0),0) -> 0 | Z28: 0 | AA28: =IFERROR(VLOOKUP(D28,'Monthly Deduction'!A:B,2,0),0) -> 0 | AB28: =ROUND(IFERROR(V28-SUM(W28:AA28),0),0) -> 3605 | AC28: 0 | AD28: =ROUND(AB28-AC28,0) -> 3605 | AE28: =IF(AC28<>0,"Yes","Release") -> Release | AG28: 0 | AI28: 0 | AK28: 858.7 | AL28: =COUNTIF(AK28:AK28,"=NA") -> 0 | AN28: =((MIN(IF(A28>0,MAX(N28*2%,1861),0),A28)))+0 -> 2553.5446 | AO28: =SUMIF('MPG Payment '!E:E,'Shayak Income '!D28,'MPG Payment '!AJ:AJ) -> 0 | AP28: =W28 -> 2553.5446 | AQ28: =AO28+AP28 -> 2553.5446 | AS28: =B28-X28 -> 0
