Workbook
Name Account_Details: #REF!
Name Amount: #REF!
Name CF_Recovery: #REF!
Name Code: #REF!
Name FAT_Range: #REF!
Name Net_Amount: #REF!
Name Other_Ded: #REF!
Name Rate_Chart_Kaimur: #REF!
Name Sample_Milk: #REF!
Name SNF_Range: #REF!
Name Vol_L: #REF!

Sheet MPG Payment
A2: BMC Code | B2: MCC Name | C2: Code | D2: Old Code | E2: MPG NAME | F2: Type | G2: Farmer Payment | H2: BMC Volume | I2: BMC Amount | J2: Payable | K2: Vet Deduction | L2: CF Deduction | M2: Other | N2: Advance | O2: Payable to MPG | P2: Hold Amount | Q2: Final Payment | R2: Stop Payment | S2: Hold Reason | T2: Cycle | V2: Sahayak Comm @ 1.75% | W2: Retain Comm @ 0.25% | X2: Payable Commission | Y2: Other Deduction | Z2: Net payable | AB2: beneficiary_name | AC2: bank_account_no | AD2: IFSC | AE2: u | AF2: am | AG2: Diff | AI2: BMC Volume | AJ2: BMC Amount
A3: 1062 | B3: Ramgarh | C3: 10620002 | D3: =VLOOKUP(C3,DSC_Master!$C$1:D101,2,0) -> 64592 | E3: =VLOOKUP(C3,DSC_Master!$C$1:$K$200,4,0) -> UDHAPURA DSK | F3: MPG | G3: Indirect | H3: 587 | I3: 22783.939 | J3: =I3 -> 22783.939 | M3: 0 | O3: =J3-SUM(K3:N3) -> 22783.939 | P3: =IF(R3="Yes",O3,0) -> 0 | Q3: =O3-P3 -> 22783.939 | R3: 0 | T3: {=SUBSTITUTE(SUBSTITUTE(MID(CELL("filename"),FIND("[",CELL("filename"))+1,FIND("]",CELL("filename"))-FIND("[",CELL("filename"))-1),"Farmer Payment-",""),".xlsb","")} -> Ramgarh Kaimur_Farmer Payment_22-28 May-diff.xlsx | V3: =I3*1.75% -> 398.71893 | W3: =I3*0.25% -> 56.959846 | X3: =V3-W3 -> 341.75908 | Y3: 0 | Z3: =X3-Y3 -> 341.75908 | AB3: =VLOOKUP(C3,DSC_Master!$C$1:$K$200,9,0) -> BAL GOPAL YADAV | AC3: =VLOOKUP(C3,DSC_Master!$C$1:$J$201,8,0) -> 37483995547 | AD3: =VLOOKUP(C3,DSC_Master!$C$1:$J$201,7,0) -> SBIN0000076 | AF3: 22382.97 | AG3: =Q3-AF3 -> 400.96859 | AI3: 587 | AJ3: 22382.14 | AK3: =AI3-H3 -> 0 | AL3: =AJ3-I3 -> -401.79817
A4: 1062 | B4: Ramgarh | C4: 10620004 | D4: =VLOOKUP(C4,DSC_Master!$C$1:D102,2,0) -> 64600 | E4: =VLOOKUP(C4,DSC_Master!$C$1:$K$200,4,0) -> BHAMBHHOR DSK | F4: MPG | G4: Indirect | H4: 407 | I4: 16386.236 | J4: =I4 -> 16386.236 | M4: 0 | O4: =J4-SUM(K4:N4) -> 16386.236 | P4: =IF(R4="Yes",O4,0) -> 0 | Q4: =O4-P4 -> 16386.236 | R4: 0 | T4: {=SUBSTITUTE(SUBSTITUTE(MID(CELL("filename"),FIND("[",CELL("filename"))+1,FIND("]",CELL("filename"))-FIND("[",CELL("filename"))-1),"Farmer Payment-",""),".xlsb","")} -> Ramgarh Kaimur_Farmer Payment_22-28 May-diff.xlsx | V4: =I4*1.75% -> 286.75914 | W4: =I4*0.25% -> 40.965591 | X4: =V4-W4 -> 245.79355 | Y4: 0 | Z4: =X4-Y4 -> 245.79355 | AB4: =VLOOKUP(C4,DSC_Master!$C$1:$K$200,9,0) -> DEEPAK KUMAR YADAV | AC4: =VLOOKUP(C4,DSC_Master!$C$1:$J$201,8,0) -> 924010010956816 | AD4: =VLOOKUP(C4,DSC_Master!$C$1:$J$201,7,0) -> UTIB0001632 | AF4: 16284.49 | AG4: =Q4-AF4 -> 101.74644 | AI4: 407 | AJ4: 16284.313 | AK4: =AI4-H4 -> 0 | AL4: =AJ4-I4 -> -101.92321
A5: 1062 | B5: Ramgarh | C5: 10620005 | D5: =VLOOKUP(C5,DSC_Master!$C$1:D103,2,0) -> 64505 | E5: =VLOOKUP(C5,DSC_Master!$C$1:$K$200,4,0) -> MAHUWARIYA DSK | F5: MPG | G5: Indirect | H5: 656 | I5: 38144.526 | J5: =I5 -> 38144.526 | M5: 0 | O5: =J5-SUM(K5:N5) -> 38144.526 | P5: =IF(R5="Yes",O5,0) -> 0 | Q5: =O5-P5 -> 38144.526 | R5: 0 | T5: {=SUBSTITUTE(SUBSTITUTE(MID(CELL("filename"),FIND("[",CELL("filename"))+1,FIND("]",CELL("filename"))-FIND("[",CELL("filename"))-1),"Farmer Payment-",""),".xlsb","")} -> Ramgarh Kaimur_Farmer Payment_22-28 May-diff.xlsx | V5: =I5*1.75% -> 667.5292 | W5: =I5*0.25% -> 95.361314 | X5: =V5-W5 -> 572.16789 | Y5: 0 | Z5: =X5-Y5 -> 572.16789 | AB5: =VLOOKUP(C5,DSC_Master!$C$1:$K$200,9,0) -> DINESH KUMAR | AC5: =VLOOKUP(C5,DSC_Master!$C$1:$J$201,8,0) -> 20315506501 | AD5: =VLOOKUP(C5,DSC_Master!$C$1:$J$201,7,0) -> SBIN0014328 | AF5: 37918.21 | AG5: =Q5-AF5 -> 226.3158 | AI5: 656 | AJ5: 37917.537 | AK5: =AI5-H5 -> 0 | AL5: =AJ5-I5 -> -226.9884
A6: 1062 | B6: Ramgarh | C6: 10620009 | D6: =VLOOKUP(C6,DSC_Master!$C$1:D104,2,0) -> 64571 | E6: =VLOOKUP(C6,DSC_Master!$C$1:$K$200,4,0) -> JAVRI DSK | F6: MPG | G6: Indirect | H6: 815 | I6: 39288.109 | J6: =I6 -> 39288.109 | M6: 0 | O6: =J6-SUM(K6:N6) -> 39288.109 | P6: =IF(R6="Yes",O6,0) -> 0 | Q6: =O6-P6 -> 39288.109 | R6: 0 | T6: {=SUBSTITUTE(SUBSTITUTE(MID(CELL("filename"),FIND("[",CELL("filename"))+1,FIND("]",CELL("filename"))-FIND("[",CELL("filename"))-1),"Farmer Payment-",""),".xlsb","")} -> Ramgarh Kaimur_Farmer Payment_22-28 May-diff.xlsx | V6: =I6*1.75% -> 687.54191 | W6: =I6*0.25% -> 98.220273 | X6: =V6-W6 -> 589.32164 | Y6: 0 | Z6: =X6-Y6 -> 589.32164 | AB6: =VLOOKUP(C6,DSC_Master!$C$1:$K$200,9,0) -> KANHAIYA YADAV | AC6: =VLOOKUP(C6,DSC_Master!$C$1:$J$201,8,0) -> 42108869535 | AD6: =VLOOKUP(C6,DSC_Master!$C$1:$J$201,7,0) -> SBIN0014328 | AF6: 39006.01 | AG6: =Q6-AF6 -> 282.09937 | AI6: 815 | AJ6: 39005.273 | AK6: =AI6-H6 -> 0 | AL6: =AJ6-I6 -> -282.83632
A7: 1062 | B7: Ramgarh | C7: 10620010 | D7: =VLOOKUP(C7,DSC_Master!$C$1:D105,2,0) -> 64508 | E7: =VLOOKUP(C7,DSC_Master!$C$1:$K$200,4,0) -> LARMA DSK | F7: MPG | G7: Indirect | H7: 523 | I7: 28162.815 | J7: =I7 -> 28162.815 | M7: 0 | O7: =J7-SUM(K7:N7) -> 28162.815 | P7: =IF(R7="Yes",O7,0) -> 0 | Q7: =O7-P7 -> 28162.815 | R7: 0 | T7: {=SUBSTITUTE(SUBSTITUTE(MID(CELL("filename"),FIND("[",CELL("filename"))+1,FIND("]",CELL("filename"))-FIND("[",CELL("filename"))-1),"Farmer Payment-",""),".xlsb","")} -> Ramgarh Kaimur_Farmer Payment_22-28 May-diff.xlsx | V7: =I7*1.75% -> 492.84926 | W7: =I7*0.25% -> 70.407037 | X7: =V7-W7 -> 422.44222 | Y7: 0 | Z7: =X7-Y7 -> 422.44222 | AB7: =VLOOKUP(C7,DSC_Master!$C$1:$K$200,9,0) -> KHUSHABU YADAV | AC7: =VLOOKUP(C7,DSC_Master!$C$1:$J$201,8,0) -> 2367000100137224 | AD7: =VLOOKUP(C7,DSC_Master!$C$1:$J$201,7,0) -> PUNB0236700 | AF7: 27976.38 | AG7: =Q7-AF7 -> 186.43491 | AI7: 523 | AJ7: 27975.378 | AK7: =AI7-H7 -> 0 | AL7: =AJ7-I7 -> -187.43737
A8: 1062 | B8: Ramgarh | C8: 10620011 | D8: =VLOOKUP(C8,DSC_Master!$C$1:D106,2,0) -> 64556 | E8: =VLOOKUP(C8,DSC_Master!$C$1:$K$200,4,0) -> KABILASPUR DSK | F8: MPG | G8: Indirect | H8: 472 | I8: 27552.206 | J8: =I8 -> 27552.206 | M8: 0 | O8: =J8-SUM(K8:N8) -> 27552.206 | P8: =IF(R8="Yes",O8,0) -> 0 | Q8: =O8-P8 -> 27552.206 | R8: 0 | T8: {=SUBSTITUTE(SUBSTITUTE(MID(CELL("filename"),FIND("[",CELL("filename"))+1,FIND("]",CELL("filename"))-FIND("[",CELL("filename"))-1),"Farmer Payment-",""),".xlsb","")} -> Ramgarh Kaimur_Farmer Payment_22-28 May-diff.xlsx | V8: =I8*1.75% -> 482.16361 | W8: =I8*0.25% -> 68.880516 | X8: =V8-W8 -> 413.2831 | Y8: 0 | Z8: =X8-Y8 -> 413.2831 | AB8: =VLOOKUP(C8,DSC_Master!$C$1:$K$200,9,0) -> MALTI DEVI | AC8: =VLOOKUP(C8,DSC_Master!$C$1:$J$201,8,0) -> 2374002100002492 | AD8: =VLOOKUP(C8,DSC_Master!$C$1:$J$201,7,0) -> PUNB0237400 | AF8: 27487.54 | AG8: =Q8-AF8 -> 64.666473 | AI8: 472 | AJ8: 27486.992 | AK8: =AI8-H8 -> 0 | AL8: =AJ8-I8 -> -65.213988
A9: 1062 | B9: Ramgarh | C9: 10620012 | D9: =VLOOKUP(C9,DSC_Master!$C$1:D107,2,0) -> 64515 | E9: =VLOOKUP(C9,DSC_Master!$C$1:$K$200,4,0) -> DHARHARA DSK | F9: MPG | G9: Indirect | H9: 919 | I9: 44244.896 | J9: =I9 -> 44244.896 | M9: 0 | O9: =J9-SUM(K9:N9) -> 44244.896 | P9: =IF(R9="Yes",O9,0) -> 0 | Q9: =O9-P9 -> 44244.896 | R9: 0 | T9: {=SUBSTITUTE(SUBSTITUTE(MID(CELL("filename"),FIND("[",CELL("filename"))+1,FIND("]",CELL("filename"))-FIND("[",CELL("filename"))-1),"Farmer Payment-",""),".xlsb","")} -> Ramgarh Kaimur_Farmer Payment_22-28 May-diff.xlsx | V9: =I9*1.75% -> 774.28569 | W9: =I9*0.25% -> 110.61224 | X9: =V9-W9 -> 663.67345 | Y9: 0 | Z9: =X9-Y9 -> 663.67345 | AB9: =VLOOKUP(C9,DSC_Master!$C$1:$K$200,9,0) -> SHREE NIWAS YADAV | AC9: =VLOOKUP(C9,DSC_Master!$C$1:$J$201,8,0) -> 37905177514 | AD9: =VLOOKUP(C9,DSC_Master!$C$1:$J$201,7,0) -> SBIN0006137 | AF9: 44012.33 | AG9: =Q9-AF9 -> 232.5664 | AI9: 919 | AJ9: 44011.804 | AK9: =AI9-H9 -> 0 | AL9: =AJ9-I9 -> -233.0929
A10: 1062 | B10: Ramgarh | C10: 10620013 | D10: =VLOOKUP(C10,DSC_Master!$C$1:D108,2,0) -> 64523 | E10: =VLOOKUP(C10,DSC_Master!$C$1:$K$200,4,0) -> KHADSARA DSK | F10: MPG | G10: Indirect | H10: 276 | I10: 15437.831 | J10: =I10 -> 15437.831 | M10: 0 | O10: =J10-SUM(K10:N10) -> 15437.831 | P10: =IF(R10="Yes",O10,0) -> 0 | Q10: =O10-P10 -> 15437.831 | R10: 0 | T10: {=SUBSTITUTE(SUBSTITUTE(MID(CELL("filename"),FIND("[",CELL("filename"))+1,FIND("]",CELL("filename"))-FIND("[",CELL("filename"))-1),"Farmer Payment-",""),".xlsb","")} -> Ramgarh Kaimur_Farmer Payment_22-28 May-diff.xlsx | V10: =I10*1.75% -> 270.16205 | W10: =I10*0.25% -> 38.594578 | X10: =V10-W10 -> 231.56747 | Y10: 0 | Z10: =X10-Y10 -> 231.56747 | AB10: =VLOOKUP(C10,DSC_Master!$C$1:$K$200,9,0) -> SONU KUMAR | AC10: =VLOOKUP(C10,DSC_Master!$C$1:$J$201,8,0) -> 20421372063 | AD10: =VLOOKUP(C10,DSC_Master!$C$1:$J$201,7,0) -> SBIN0014328 | AF10: 15356.86 | AG10: =Q10-AF10 -> 80.971311 | AI10: 276 | AJ10: 15357.868 | AK10: =AI10-H10 -> 0 | AL10: =AJ10-I10 -> -79.963311
A11: 1062 | B11: Ramgarh | C11: 10620014 | D11: =VLOOKUP(C11,DSC_Master!$C$1:D109,2,0) -> 60628 | E11: =VLOOKUP(C11,DSC_Master!$C$1:$K$200,4,0) -> BAIJNATH DSK | F11: MPG | G11: Indirect | H11: 410 | I11: 18398.607 | J11: =I11 -> 18398.607 | M11: 0 | O11: =J11-SUM(K11:N11) -> 18398.607 | P11: =IF(R11="Yes",O11,0) -> 0 | Q11: =O11-P11 -> 18398.607 | R11: 0 | T11: {=SUBSTITUTE(SUBSTITUTE(MID(CELL("filename"),FIND("[",CELL("filename"))+1,FIND("]",CELL("filename"))-FIND("[",CELL("filename"))-1),"Farmer Payment-",""),".xlsb","")} -> Ramgarh Kaimur_Farmer Payment_22-28 May-diff.xlsx | V11: =I11*1.75% -> 321.97563 | W11: =I11*0.25% -> 45.996518 | X11: =V11-W11 -> 275.97911 | Y11: 0 | Z11: =X11-Y11 -> 275.97911 | AB11: =VLOOKUP(C11,DSC_Master!$C$1:$K$200,9,0) -> PARASH SINGH | AC11: =VLOOKUP(C11,DSC_Master!$C$1:$J$201,8,0) -> 2784000100175715 | AD11: =VLOOKUP(C11,DSC_Master!$C$1:$J$201,7,0) -> PUNB0278400 | AF11: 18162.4 | AG11: =Q11-AF11 -> 236.20723 | AI11: 410 | AJ11: 18162.105 | AK11: =AI11-H11 -> 0 | AL11: =AJ11-I11 -> -236.50178
A12: 1062 | B12: Ramgarh | C12: 10620015 | D12: =VLOOKUP(C12,DSC_Master!$C$1:D110,2,0) -> 64537 | E12: =VLOOKUP(C12,DSC_Master!$C$1:$K$200,4,0) -> KASTHARI DSK | F12: MPG | G12: Indirect | H12: 626 | I12: 27445.259 | J12: =I12 -> 27445.259 | M12: 0 | O12: =J12-SUM(K12:N12) -> 27445.259 | P12: =IF(R12="Yes",O12,0) -> 0 | Q12: =O12-P12 -> 27445.259 | R12: 0 | T12: {=SUBSTITUTE(SUBSTITUTE(MID(CELL("filename"),FIND("[",CELL("filename"))+1,FIND("]",CELL("filename"))-FIND("[",CELL("filename"))-1),"Farmer Payment-",""),".xlsb","")} -> Ramgarh Kaimur_Farmer Payment_22-28 May-diff.xlsx | V12: =I12*1.75% -> 480.29204 | W12: =I12*0.25% -> 68.613148 | X12: =V12-W12 -> 411.67889 | Y12: 0 | Z12: =X12-Y12 -> 411.67889 | AB12: =VLOOKUP(C12,DSC_Master!$C$1:$K$200,9,0) -> PAWAN KUMAR SINGH | AC12: =VLOOKUP(C12,DSC_Master!$C$1:$J$201,8,0) -> 2374001500005364 | AD12: =VLOOKUP(C12,DSC_Master!$C$1:$J$201,7,0) -> PUNB0237400 | AF12: 27091.78 | AG12: =Q12-AF12 -> 353.47934 | AI12: 626 | AJ12: 27090.825 | AK12: =AI12-H12 -> 0 | AL12: =AJ12-I12 -> -354.43467
A13: 1062 | B13: Ramgarh | C13: 10620016 | D13: =VLOOKUP(C13,DSC_Master!$C$1:D111,2,0) -> 64522 | E13: =VLOOKUP(C13,DSC_Master!$C$1:$K$200,4,0) -> MADANPURA DSK | F13: MPG | G13: Indirect | H13: 258 | I13: 13245.18 | J13: =I13 -> 13245.18 | M13: 0 | O13: =J13-SUM(K13:N13) -> 13245.18 | P13: =IF(R13="Yes",O13,0) -> 0 | Q13: =O13-P13 -> 13245.18 | R13: 0 | T13: {=SUBSTITUTE(SUBSTITUTE(MID(CELL("filename"),FIND("[",CELL("filename"))+1,FIND("]",CELL("filename"))-FIND("[",CELL("filename"))-1),"Farmer Payment-",""),".xlsb","")} -> Ramgarh Kaimur_Farmer Payment_22-28 May-diff.xlsx | V13: =I13*1.75% -> 231.79065 | W13: =I13*0.25% -> 33.11295 | X13: =V13-W13 -> 198.6777 | Y13: 0 | Z13: =X13-Y13 -> 198.6777 | AB13: =VLOOKUP(C13,DSC_Master!$C$1:$K$200,9,0) -> RAM CHARAN RAI | AC13: =VLOOKUP(C13,DSC_Master!$C$1:$J$201,8,0) -> 2374000100165377 | AD13: =VLOOKUP(C13,DSC_Master!$C$1:$J$201,7,0) -> PUNB0237400 | AF13: 13156.58 | AG13: =Q13-AF13 -> 88.599925 | AI13: 258 | AJ13: 13156.452 | AK13: =AI13-H13 -> 0 | AL13: =AJ13-I13 -> -88.727467
A14: 1062 | B14: Ramgarh | C14: 10620017 | D14: =VLOOKUP(C14,DSC_Master!$C$1:D112,2,0) -> 64555 | E14: =VLOOKUP(C14,DSC_Master!$C$1:$K$200,4,0) -> DEHWALIYA DSK | F14: MPG | G14: Indirect | H14: 255 | I14: 8733.7569 | J14: =I14 -> 8733.7569 | M14: 0 | O14: =J14-SUM(K14:N14) -> 8733.7569 | P14: =IF(R14="Yes",O14,0) -> 0 | Q14: =O14-P14 -> 8733.7569 | R14: 0 | T14: {=SUBSTITUTE(SUBSTITUTE(MID(CELL("filename"),FIND("[",CELL("filename"))+1,FIND("]",CELL("filename"))-FIND("[",CELL("filename"))-1),"Farmer Payment-",""),".xlsb","")} -> Ramgarh Kaimur_Farmer Payment_22-28 May-diff.xlsx | V14: =I14*1.75% -> 152.84075 | W14: =I14*0.25% -> 21.834392 | X14: =V14-W14 -> 131.00635 | Y14: 0 | Z14: =X14-Y14 -> 131.00635 | AB14: =VLOOKUP(C14,DSC_Master!$C$1:$K$200,9,0) -> SATENDRA YADAV | AC14: =VLOOKUP(C14,DSC_Master!$C$1:$J$201,8,0) -> 14462413000951 | AD14: =VLOOKUP(C14,DSC_Master!$C$1:$J$201,7,0) -> PUNB0269600 | AF14: 8532.27 | AG14: =Q14-AF14 -> 201.48691 | AI14: 255 | AJ14: 8532.3536 | AK14: =AI14-H14 -> 0 | AL14: =AJ14-I14 -> -201.40334
... A52: 1062 | B52: Ramgarh | C52: 10620072 | D52: =VLOOKUP(C52,DSC_Master!$C$1:D150,2,0) -> 60526 | E52: =VLOOKUP(C52,DSC_Master!$C$1:$K$200,4,0) -> CHANDESH DSK | F52: MPG | G52: Indirect | H52: 71 | I52: 3400.4469 | J52: =I52 -> 3400.4469 | M52: 0 | O52: =J52-SUM(K52:N52) -> 3400.4469 | P52: =IF(R52="Yes",O52,0) -> 0 | Q52: =O52-P52 -> 3400.4469 | R52: 0 | T52: {=SUBSTITUTE(SUBSTITUTE(MID(CELL("filename"),FIND("[",CELL("filename"))+1,FIND("]",CELL("filename"))-FIND("[",CELL("filename"))-1),"Farmer Payment-",""),".xlsb","")} -> Ramgarh Kaimur_Farmer Payment_22-28 May-diff.xlsx | V52: =I52*1.75% -> 59.507821 | W52: =I52*0.25% -> 8.5011173 | X52: =V52-W52 -> 51.006704 | Y52: 0 | Z52: =X52-Y52 -> 51.006704 | AB52: =VLOOKUP(C52,DSC_Master!$C$1:$K$200,9,0) -> RAVISHANKAR RAI | AC52: =VLOOKUP(C52,DSC_Master!$C$1:$J$201,8,0) -> 20348864069 | AD52: =VLOOKUP(C52,DSC_Master!$C$1:$J$201,7,0) -> SBIN0017163 | AF52: 3385.82 | AG52: =Q52-AF52 -> 14.626934 | AI52: 71 | AJ52: 3385.7465 | AK52: =AI52-H52 -> 0 | AL52: =AJ52-I52 -> -14.700462
A53: 1062 | B53: Ramgarh | C53: 10620075 | D53: =VLOOKUP(C53,DSC_Master!$C$1:D151,2,0) -> 64542 | E53: =VLOOKUP(C53,DSC_Master!$C$1:$K$200,4,0) -> KUCHHALA DSK | F53: MPG | G53: Indirect | H53: 369 | I53: 21650.035 | J53: =I53 -> 21650.035 | M53: 0 | O53: =J53-SUM(K53:N53) -> 21650.035 | P53: =IF(R53="Yes",O53,0) -> 0 | Q53: =O53-P53 -> 21650.035 | R53: Release1 | T53: {=SUBSTITUTE(SUBSTITUTE(MID(CELL("filename"),FIND("[",CELL("filename"))+1,FIND("]",CELL("filename"))-FIND("[",CELL("filename"))-1),"Farmer Payment-",""),".xlsb","")} -> Ramgarh Kaimur_Farmer Payment_22-28 May-diff.xlsx | V53: =I53*1.75% -> 378.8756 | W53: =I53*0.25% -> 54.125086 | X53: =V53-W53 -> 324.75052 | Y53: 0 | Z53: =X53-Y53 -> 324.75052 | AB53: =VLOOKUP(C53,DSC_Master!$C$1:$K$200,9,0) -> SUNITA DEVI | AC53: =VLOOKUP(C53,DSC_Master!$C$1:$J$201,8,0) -> 579410110012870 | AD53: =VLOOKUP(C53,DSC_Master!$C$1:$J$201,7,0) -> BKID0005794 | AF53: 21442.07 | AG53: =Q53-AF53 -> 207.96451 | AI53: 369 | AJ53: 21441.036 | AK53: =AI53-H53 -> 0 | AL53: =AJ53-I53 -> -208.99807
A54: 1062 | B54: Ramgarh | C54: 10620076 | D54: =VLOOKUP(C54,DSC_Master!$C$1:D152,2,0) -> 60604 | E54: =VLOOKUP(C54,DSC_Master!$C$1:$K$200,4,0) -> SANISARAI DSK | F54: MPG | G54: Indirect | H54: 223 | I54: 8833.5614 | J54: =I54 -> 8833.5614 | M54: 0 | O54: =J54-SUM(K54:N54) -> 8833.5614 | P54: =IF(R54="Yes",O54,0) -> 0 | Q54: =O54-P54 -> 8833.5614 | R54: 0 | T54: {=SUBSTITUTE(SUBSTITUTE(MID(CELL("filename"),FIND("[",CELL("filename"))+1,FIND("]",CELL("filename"))-FIND("[",CELL("filename"))-1),"Farmer Payment-",""),".xlsb","")} -> Ramgarh Kaimur_Farmer Payment_22-28 May-diff.xlsx | V54: =I54*1.75% -> 154.58732 | W54: =I54*0.25% -> 22.083903 | X54: =V54-W54 -> 132.50342 | Y54: 0 | Z54: =X54-Y54 -> 132.50342 | AB54: =VLOOKUP(C54,DSC_Master!$C$1:$K$200,9,0) -> SURESH SINGH | AC54: =VLOOKUP(C54,DSC_Master!$C$1:$J$201,8,0) -> 2784001700140817 | AD54: =VLOOKUP(C54,DSC_Master!$C$1:$J$201,7,0) -> PUNB0278400 | AF54: 8735.9 | AG54: =Q54-AF54 -> 97.661354 | AI54: 223 | AJ54: 8735.4746 | AK54: =AI54-H54 -> 0 | AL54: =AJ54-I54 -> -98.086712
A55: 1062 | B55: Ramgarh | C55: 10620077 | D55: =VLOOKUP(C55,DSC_Master!$C$1:D153,2,0) -> 60627 | E55: =VLOOKUP(C55,DSC_Master!$C$1:$K$200,4,0) -> KHANATI DSK | F55: MPG | G55: Indirect | H55: 475 | I55: 20711.476 | J55: =I55 -> 20711.476 | M55: 0 | O55: =J55-SUM(K55:N55) -> 20711.476 | P55: =IF(R55="Yes",O55,0) -> 0 | Q55: =O55-P55 -> 20711.476 | R55: 0 | T55: {=SUBSTITUTE(SUBSTITUTE(MID(CELL("filename"),FIND("[",CELL("filename"))+1,FIND("]",CELL("filename"))-FIND("[",CELL("filename"))-1),"Farmer Payment-",""),".xlsb","")} -> Ramgarh Kaimur_Farmer Payment_22-28 May-diff.xlsx | V55: =I55*1.75% -> 362.45082 | W55: =I55*0.25% -> 51.778689 | X55: =V55-W55 -> 310.67214 | Y55: 0 | Z55: =X55-Y55 -> 310.67214 | AB55: =VLOOKUP(C55,DSC_Master!$C$1:$K$200,9,0) -> SUSHIL YADAV | AC55: =VLOOKUP(C55,DSC_Master!$C$1:$J$201,8,0) -> 2784001700136197 | AD55: =VLOOKUP(C55,DSC_Master!$C$1:$J$201,7,0) -> PUNB0278400 | AF55: 20530.41 | AG55: =Q55-AF55 -> 181.06567 | AI55: 475 | AJ55: 20544.612 | AK55: =AI55-H55 -> 0 | AL55: =AJ55-I55 -> -166.86399
A56: 1062 | B56: Ramgarh | C56: 10620099 | D56: =VLOOKUP(C56,DSC_Master!$C$1:D154,2,0) -> 64504 | E56: =VLOOKUP(C56,DSC_Master!$C$1:$K$200,4,0) -> NONAR DSK | F56: MPG | G56: Indirect | H56: 420 | I56: 14860.16 | J56: =I56 -> 14860.16 | M56: 0 | O56: =J56-SUM(K56:N56) -> 14860.16 | P56: =IF(R56="Yes",O56,0) -> 0 | Q56: =O56-P56 -> 14860.16 | R56: 0 | T56: {=SUBSTITUTE(SUBSTITUTE(MID(CELL("filename"),FIND("[",CELL("filename"))+1,FIND("]",CELL("filename"))-FIND("[",CELL("filename"))-1),"Farmer Payment-",""),".xlsb","")} -> Ramgarh Kaimur_Farmer Payment_22-28 May-diff.xlsx | V56: =I56*1.75% -> 260.05279 | W56: =I56*0.25% -> 37.150399 | X56: =V56-W56 -> 222.90239 | Y56: 0 | Z56: =X56-Y56 -> 222.90239 | AB56: =VLOOKUP(C56,DSC_Master!$C$1:$K$200,9,0) -> SURESH KHARWAR | AC56: =VLOOKUP(C56,DSC_Master!$C$1:$J$201,8,0) -> 2784000100286464 | AD56: =VLOOKUP(C56,DSC_Master!$C$1:$J$201,7,0) -> PUNB0278400 | AF56: 14469.29 | AG56: =Q56-AF56 -> 390.86961 | AI56: 420 | AJ56: 14469.232 | AK56: =AI56-H56 -> 0 | AL56: =AJ56-I56 -> -390.92723
A57: 1062 | B57: Ramgarh | C57: 10620100 | D57: =VLOOKUP(C57,DSC_Master!$C$1:D155,2,0) -> 60646 | E57: =VLOOKUP(C57,DSC_Master!$C$1:$K$200,4,0) -> RAMGARH DSK | F57: MPG | G57: Indirect | H57: 953 | I57: 50325.604 | J57: =I57 -> 50325.604 | M57: 0 | O57: =J57-SUM(K57:N57) -> 50325.604 | P57: =IF(R57="Yes",O57,0) -> 0 | Q57: =O57-P57 -> 50325.604 | R57: 0 | T57: {=SUBSTITUTE(SUBSTITUTE(MID(CELL("filename"),FIND("[",CELL("filename"))+1,FIND("]",CELL("filename"))-FIND("[",CELL("filename"))-1),"Farmer Payment-",""),".xlsb","")} -> Ramgarh Kaimur_Farmer Payment_22-28 May-diff.xlsx | V57: =I57*1.75% -> 880.69807 | W57: =I57*0.25% -> 125.81401 | X57: =V57-W57 -> 754.88406 | Y57: 0 | Z57: =X57-Y57 -> 754.88406 | AB57: =VLOOKUP(C57,DSC_Master!$C$1:$K$200,9,0) -> SHRI SHYAM DAIRY CO | AC57: =VLOOKUP(C57,DSC_Master!$C$1:$J$201,8,0) -> 579420110000403 | AD57: =VLOOKUP(C57,DSC_Master!$C$1:$J$201,7,0) -> BKID0005794 | AF57: 50326.39 | AG57: =Q57-AF57 -> -0.78616 | AI57: 953 | AJ57: 50325.604 | AK57: =AI57-H57 -> 0 | AL57: =AJ57-I57 -> 0
A58: 1062 | B58: Ramgarh | C58: 10620101 | D58: =VLOOKUP(C58,DSC_Master!$C$1:D156,2,0) -> 20101 | E58: =VLOOKUP(C58,DSC_Master!$C$1:$K$200,4,0) -> JABURNA DSK | F58: MPG | G58: Indirect | H58: 144 | I58: 6640.168 | J58: =I58 -> 6640.168 | M58: 0 | O58: =J58-SUM(K58:N58) -> 6640.168 | P58: =IF(R58="Yes",O58,0) -> 0 | Q58: =O58-P58 -> 6640.168 | R58: 0 | T58: {=SUBSTITUTE(SUBSTITUTE(MID(CELL("filename"),FIND("[",CELL("filename"))+1,FIND("]",CELL("filename"))-FIND("[",CELL("filename"))-1),"Farmer Payment-",""),".xlsb","")} -> Ramgarh Kaimur_Farmer Payment_22-28 May-diff.xlsx | V58: =I58*1.75% -> 116.20294 | W58: =I58*0.25% -> 16.60042 | X58: =V58-W58 -> 99.602521 | Y58: 0 | Z58: =X58-Y58 -> 99.602521 | AB58: =VLOOKUP(C58,DSC_Master!$C$1:$K$200,9,0) -> MD IMRAN KHAN | AC58: =VLOOKUP(C58,DSC_Master!$C$1:$J$201,8,0) -> 43620100017275 | AD58: =VLOOKUP(C58,DSC_Master!$C$1:$J$201,7,0) -> BARB0DILDAR | AF58: 6602.31 | AG58: =Q58-AF58 -> 37.858047 | AI58: 144 | AJ58: 6602.241 | AK58: =AI58-H58 -> 0 | AL58: =AJ58-I58 -> -37.927046
A59: 1062 | B59: Ramgarh | C59: 10620102 | D59: =VLOOKUP(C59,DSC_Master!$C$1:D157,2,0) -> 20102 | E59: =VLOOKUP(C59,DSC_Master!$C$1:$K$200,4,0) -> KALANI DSK | F59: MPG | G59: Indirect | H59: 695 | I59: 31418.174 | J59: =I59 -> 31418.174 | M59: 0 | O59: =J59-SUM(K59:N59) -> 31418.174 | P59: =IF(R59="Yes",O59,0) -> 0 | Q59: =O59-P59 -> 31418.174 | R59: 0 | T59: {=SUBSTITUTE(SUBSTITUTE(MID(CELL("filename"),FIND("[",CELL("filename"))+1,FIND("]",CELL("filename"))-FIND("[",CELL("filename"))-1),"Farmer Payment-",""),".xlsb","")} -> Ramgarh Kaimur_Farmer Payment_22-28 May-diff.xlsx | V59: =I59*1.75% -> 549.81805 | W59: =I59*0.25% -> 78.545436 | X59: =V59-W59 -> 471.27261 | Y59: 0 | Z59: =X59-Y59 -> 471.27261 | AB59: =VLOOKUP(C59,DSC_Master!$C$1:$K$200,9,0) -> MAYA KUMARI | AC59: =VLOOKUP(C59,DSC_Master!$C$1:$J$201,8,0) -> 461110110010454 | AD59: =VLOOKUP(C59,DSC_Master!$C$1:$J$201,7,0) -> BKID0004611 | AF59: 31256.72 | AG59: =Q59-AF59 -> 161.45423 | AI59: 695 | AJ59: 31285.744 | AK59: =AI59-H59 -> 0 | AL59: =AJ59-I59 -> -132.4302
A60: 1062 | B60: Ramgarh | C60: 10620104 | D60: =VLOOKUP(C60,DSC_Master!$C$1:D158,2,0) -> 20104 | E60: =VLOOKUP(C60,DSC_Master!$C$1:$K$200,4,0) -> PANAPUR - PURVY DSK | F60: MPG | G60: Indirect | H60: 299 | I60: 10729.41 | J60: =I60 -> 10729.41 | M60: 0 | O60: =J60-SUM(K60:N60) -> 10729.41 | P60: =IF(R60="Yes",O60,0) -> 0 | Q60: =O60-P60 -> 10729.41 | R60: 0 | T60: {=SUBSTITUTE(SUBSTITUTE(MID(CELL("filename"),FIND("[",CELL("filename"))+1,FIND("]",CELL("filename"))-FIND("[",CELL("filename"))-1),"Farmer Payment-",""),".xlsb","")} -> Ramgarh Kaimur_Farmer Payment_22-28 May-diff.xlsx | V60: =I60*1.75% -> 187.76468 | W60: =I60*0.25% -> 26.823526 | X60: =V60-W60 -> 160.94115 | Y60: 0 | Z60: =X60-Y60 -> 160.94115 | AB60: =VLOOKUP(C60,DSC_Master!$C$1:$K$200,9,0) -> NEERAJ KUMAR | AC60: =VLOOKUP(C60,DSC_Master!$C$1:$J$201,8,0) -> 20200123940927 | AD60: =VLOOKUP(C60,DSC_Master!$C$1:$J$201,7,0) -> BDBL0001544 | AF60: 10555.2 | AG60: =Q60-AF60 -> 174.21033 | AI60: 299 | AJ60: 10554.979 | AK60: =AI60-H60 -> 0 | AL60: =AJ60-I60 -> -174.43121
A61: 1062 | B61: Ramgarh | C61: 10620106 | D61: =VLOOKUP(C61,DSC_Master!$C$1:D156,2,0) -> 20106 | E61: =VLOOKUP(C61,DSC_Master!$C$1:$K$200,4,0) -> MACHHANHATA DSK | F61: MPG | G61: Indirect | H61: 307 | I61: 12288.853 | J61: =I61 -> 12288.853 | M61: 0 | O61: =J61-SUM(K61:N61) -> 12288.853 | P61: =IF(R61="Yes",O61,0) -> 0 | Q61: =O61-P61 -> 12288.853 | R61: 0 | T61: {=SUBSTITUTE(SUBSTITUTE(MID(CELL("filename"),FIND("[",CELL("filename"))+1,FIND("]",CELL("filename"))-FIND("[",CELL("filename"))-1),"Farmer Payment-",""),".xlsb","")} -> Ramgarh Kaimur_Farmer Payment_22-28 May-diff.xlsx | V61: =I61*1.75% -> 215.05493 | W61: =I61*0.25% -> 30.722132 | X61: =V61-W61 -> 184.33279 | Y61: 0 | Z61: =X61-Y61 -> 184.33279 | AB61: =VLOOKUP(C61,DSC_Master!$C$1:$K$200,9,0) -> PARASNATH SINGH | AC61: =VLOOKUP(C61,DSC_Master!$C$1:$J$201,8,0) -> 924010067199253 | AD61: =VLOOKUP(C61,DSC_Master!$C$1:$J$201,7,0) -> UTIB0005542 | AF61: 12036.92 | AG61: =Q61-AF61 -> 251.93287 | AI61: 307 | AJ61: 12037.21 | AK61: =AI61-H61 -> 0 | AL61: =AJ61-I61 -> -251.64332
A62: 1062 | B62: Ramgarh | C62: 10620107 | D62: =VLOOKUP(C62,DSC_Master!$C$1:D157,2,0) -> 20107 | E62: =VLOOKUP(C62,DSC_Master!$C$1:$K$200,4,0) -> DANDAWAS DSK | F62: MPG | G62: Indirect | H62: 121 | I62: 5040.538 | J62: =I62 -> 5040.538 | M62: 0 | O62: =J62-SUM(K62:N62) -> 5040.538 | P62: =IF(R62="Yes",O62,0) -> 0 | Q62: =O62-P62 -> 5040.538 | R62: 0 | T62: {=SUBSTITUTE(SUBSTITUTE(MID(CELL("filename"),FIND("[",CELL("filename"))+1,FIND("]",CELL("filename"))-FIND("[",CELL("filename"))-1),"Farmer Payment-",""),".xlsb","")} -> Ramgarh Kaimur_Farmer Payment_22-28 May-diff.xlsx | V62: =I62*1.75% -> 88.209416 | W62: =I62*0.25% -> 12.601345 | X62: =V62-W62 -> 75.608071 | Y62: 0 | Z62: =X62-Y62 -> 75.608071 | AB62: =VLOOKUP(C62,DSC_Master!$C$1:$K$200,9,0) -> DHANANJAY SINGH | AC62: =VLOOKUP(C62,DSC_Master!$C$1:$J$201,8,0) -> 110291410255 | AD62: =VLOOKUP(C62,DSC_Master!$C$1:$J$201,7,0) -> CNRB0007689 | AF62: 4945.18 | AG62: =Q62-AF62 -> 95.358039 | AI62: 121 | AJ62: 4945.0134 | AK62: =AI62-H62 -> 0 | AL62: =AJ62-I62 -> -95.52459
A63: 1062 | B63: Ramgarh | C63: 10620109 | D63: =VLOOKUP(C63,DSC_Master!$C$1:D158,2,0) -> 20109 | E63: =VLOOKUP(C63,DSC_Master!$C$1:$K$200,4,0) -> YUVRAJPUR DSK | F63: MPG | G63: Indirect | H63: 16140 | I63: 721551.03 | J63: =I63 -> 721551.03 | M63: 0 | O63: =J63-SUM(K63:N63) -> 721551.03 | P63: =IF(R63="Yes",O63,0) -> 0 | Q63: =O63-P63 -> 721551.03 | R63: 0 | T63: {=SUBSTITUTE(SUBSTITUTE(MID(CELL("filename"),FIND("[",CELL("filename"))+1,FIND("]",CELL("filename"))-FIND("[",CELL("filename"))-1),"Farmer Payment-",""),".xlsb","")} -> Ramgarh Kaimur_Farmer Payment_22-28 May-diff.xlsx | V63: =I63*1.75% -> 12627.143 | W63: =I63*0.25% -> 1803.8776 | X63: =V63-W63 -> 10823.265 | Y63: 0 | Z63: =X63-Y63 -> 10823.265 | AB63: =VLOOKUP(C63,DSC_Master!$C$1:$K$200,9,0) -> PRIYANKA PANDEY | AC63: =VLOOKUP(C63,DSC_Master!$C$1:$J$201,8,0) -> 0662001500012630 | AD63: =VLOOKUP(C63,DSC_Master!$C$1:$J$201,7,0) -> PUNB0066200 | AF63: 622454.8 | AG63: =Q63-AF63 -> 99096.225 | AI63: 14010 | AJ63: 622419.65 | AK63: =AI63-H63 -> -2130 | AL63: =AJ63-I63 -> -99131.38
A64: 1062 | B64: Ramgarh | C64: 10620111 | D64: =VLOOKUP(C64,DSC_Master!$C$1:D159,2,0) -> 20111 | E64: =VLOOKUP(C64,DSC_Master!$C$1:$K$200,4,0) -> SUHWAL | F64: MPG | G64: Indirect | H64: 1500 | I64: 56365.63 | J64: =I64 -> 56365.63 | M64: 0 | O64: =J64-SUM(K64:N64) -> 56365.63 | P64: =IF(R64="Yes",O64,0) -> 0 | Q64: =O64-P64 -> 56365.63 | R64: 0 | T64: {=SUBSTITUTE(SUBSTITUTE(MID(CELL("filename"),FIND("[",CELL("filename"))+1,FIND("]",CELL("filename"))-FIND("[",CELL("filename"))-1),"Farmer Payment-",""),".xlsb","")} -> Ramgarh Kaimur_Farmer Payment_22-28 May-diff.xlsx | V64: =I64*1.75% -> 986.39853 | W64: =I64*0.25% -> 140.91408 | X64: =V64-W64 -> 845.48445 | Y64: 0 | Z64: =X64-Y64 -> 845.48445 | AB64: =VLOOKUP(C64,DSC_Master!$C$1:$K$200,9,0) -> PRIYA PANDEY | AC64: =VLOOKUP(C64,DSC_Master!$C$1:$J$201,8,0) -> 43605915887 | AD64: =VLOOKUP(C64,DSC_Master!$C$1:$J$201,7,0) -> SBIN0003683 | AF64: 56370 | AG64: =Q64-AF64 -> -4.3698 | AI64: 1500 | AJ64: 56365.63 | AK64: =AI64-H64 -> 0 | AL64: =AJ64-I64 -> 0
A65: 1062 | B65: Ramgarh | C65: 10620112 | D65: =VLOOKUP(C65,DSC_Master!$C$1:D160,2,0) -> 20112 | E65: =VLOOKUP(C65,DSC_Master!$C$1:$K$200,4,0) -> PARSATHUA DSK | F65: MPG | G65: Indirect | H65: 115 | I65: 4660.5018 | J65: =I65 -> 4660.5018 | M65: 0 | O65: =J65-SUM(K65:N65) -> 4660.5018 | P65: =IF(R65="Yes",O65,0) -> 0 | Q65: =O65-P65 -> 4660.5018 | R65: 0 | T65: {=SUBSTITUTE(SUBSTITUTE(MID(CELL("filename"),FIND("[",CELL("filename"))+1,FIND("]",CELL("filename"))-FIND("[",CELL("filename"))-1),"Farmer Payment-",""),".xlsb","")} -> Ramgarh Kaimur_Farmer Payment_22-28 May-diff.xlsx | V65: =I65*1.75% -> 81.558782 | W65: =I65*0.25% -> 11.651255 | X65: =V65-W65 -> 69.907527 | Y65: 0 | Z65: =X65-Y65 -> 69.907527 | AB65: =VLOOKUP(C65,DSC_Master!$C$1:$K$200,9,0) -> ANJU DEVI | AC65: =VLOOKUP(C65,DSC_Master!$C$1:$J$201,8,0) -> 50100615862671 | AD65: =VLOOKUP(C65,DSC_Master!$C$1:$J$201,7,0) -> HDFC0002625 | AF65: 4570.57 | AG65: =Q65-AF65 -> 89.931822 | AI65: 115 | AJ65: 4570.5212 | AK65: =AI65-H65 -> 0 | AL65: =AJ65-I65 -> -89.980638
A66: 1062 | B66: Ramgarh | C66: 10620115 | D66: =VLOOKUP(C66,DSC_Master!$C$1:D161,2,0) -> 20115 | E66: =VLOOKUP(C66,DSC_Master!$C$1:$K$200,4,0) -> BADAKI KULHARIA DSK | F66: MPG | G66: Indirect | H66: 550 | I66: 20766.752 | J66: =I66 -> 20766.752 | M66: 0 | O66: =J66-SUM(K66:N66) -> 20766.752 | P66: =IF(R66="Yes",O66,0) -> 0 | Q66: =O66-P66 -> 20766.752 | R66: 0 | T66: {=SUBSTITUTE(SUBSTITUTE(MID(CELL("filename"),FIND("[",CELL("filename"))+1,FIND("]",CELL("filename"))-FIND("[",CELL("filename"))-1),"Farmer Payment-",""),".xlsb","")} -> Ramgarh Kaimur_Farmer Payment_22-28 May-diff.xlsx | V66: =I66*1.75% -> 363.41817 | W66: =I66*0.25% -> 51.916881 | X66: =V66-W66 -> 311.50129 | Y66: 0 | Z66: =X66-Y66 -> 311.50129 | AB66: =VLOOKUP(C66,DSC_Master!$C$1:$K$200,9,0) -> AJAY KUMAR SINGH | AC66: =VLOOKUP(C66,DSC_Master!$C$1:$J$201,8,0) -> 41684045867 | AD66: =VLOOKUP(C66,DSC_Master!$C$1:$J$201,7,0) -> SBIN0017163 | AF66: 20304.56 | AG66: =Q66-AF66 -> 462.19247 | AI66: 550 | AJ66: 20308.841 | AK66: =AI66-H66 -> 0 | AL66: =AJ66-I66 -> -457.91144
A67: 1062 | B67: Ramgarh | C67: 10620116 | D67: =VLOOKUP(C67,DSC_Master!$C$1:D162,2,0) -> 20116 | E67: =VLOOKUP(C67,DSC_Master!$C$1:$K$200,4,0) -> ARANG DSK | F67: MPG | G67: Indirect | H67: 5220 | I67: 223484.81 | J67: =I67 -> 223484.81 | M67: 0 | O67: =J67-SUM(K67:N67) -> 223484.81 | P67: =IF(R67="Yes",O67,0) -> 0 | Q67: =O67-P67 -> 223484.81 | R67: 0 | T67: {=SUBSTITUTE(SUBSTITUTE(MID(CELL("filename"),FIND("[",CELL("filename"))+1,FIND("]",CELL("filename"))-FIND("[",CELL("filename"))-1),"Farmer Payment-",""),".xlsb","")} -> Ramgarh Kaimur_Farmer Payment_22-28 May-diff.xlsx | V67: =I67*1.75% -> 3910.9841 | W67: =I67*0.25% -> 558.71202 | X67: =V67-W67 -> 3352.2721 | Y67: 0 | Z67: =X67-Y67 -> 3352.2721 | AB67: =VLOOKUP(C67,DSC_Master!$C$1:$K$200,9,0) -> BIRENDRA KUMAR | AC67: =VLOOKUP(C67,DSC_Master!$C$1:$J$201,8,0) -> 579120110000273 | AD67: =VLOOKUP(C67,DSC_Master!$C$1:$J$201,7,0) -> BKID0005791 | AF67: 115474.4 | AG67: =Q67-AF67 -> 108010.41 | AI67: 2840 | AJ67: 115466.23 | AK67: =AI67-H67 -> -2380 | AL67: =AJ67-I67 -> -108018.58
A68: 1062 | B68: Ramgarh | C68: 10620119 | D68: =VLOOKUP(C68,DSC_Master!$C$1:D163,2,0) -> 20119 | E68: =VLOOKUP(C68,DSC_Master!$C$1:$K$200,4,0) -> KURRA NEW DSK | F68: MPG | G68: Indirect | H68: 6050 | I68: 265541.67 | J68: =I68 -> 265541.67 | M68: 0 | O68: =J68-SUM(K68:N68) -> 265541.67 | P68: =IF(R68="Yes",O68,0) -> 0 | Q68: =O68-P68 -> 265541.67 | R68: 0 | T68: {=SUBSTITUTE(SUBSTITUTE(MID(CELL("filename"),FIND("[",CELL("filename"))+1,FIND("]",CELL("filename"))-FIND("[",CELL("filename"))-1),"Farmer Payment-",""),".xlsb","")} -> Ramgarh Kaimur_Farmer Payment_22-28 May-diff.xlsx | V68: =I68*1.75% -> 4646.9792 | W68: =I68*0.25% -> 663.85417 | X68: =V68-W68 -> 3983.125 | Y68: 0 | Z68: =X68-Y68 -> 3983.125 | AB68: =VLOOKUP(C68,DSC_Master!$C$1:$K$200,9,0) -> DIVYANSHI DAIRY MILK | AC68: =VLOOKUP(C68,DSC_Master!$C$1:$J$201,8,0) -> 8136244333 | AD68: =VLOOKUP(C68,DSC_Master!$C$1:$J$201,7,0) -> IDIB000M430 | AF68: 257289.2 | AG68: =Q68-AF68 -> 8252.4665 | AI68: 6050 | AJ68: 258684.43 | AK68: =AI68-H68 -> 0 | AL68: =AJ68-I68 -> -6857.2389
A69: 1062 | B69: Ramgarh | C69: 10620120 | D69: =VLOOKUP(C69,DSC_Master!$C$1:D163,2,0) -> 20120 | E69: =VLOOKUP(C69,DSC_Master!$C$1:$K$200,4,0) -> TIYARA DSK | F69: MPG | G69: Indirect | H69: 242 | I69: 12911.8 | J69: =I69 -> 12911.8 | M69: 0 | O69: =J69-SUM(K69:N69) -> 12911.8 | P69: =IF(R69="Yes",O69,0) -> 0 | Q69: =O69-P69 -> 12911.8 | R69: 0 | T69: {=SUBSTITUTE(SUBSTITUTE(MID(CELL("filename"),FIND("[",CELL("filename"))+1,FIND("]",CELL("filename"))-FIND("[",CELL("filename"))-1),"Farmer Payment-",""),".xlsb","")} -> Ramgarh Kaimur_Farmer Payment_22-28 May-diff.xlsx | V69: =I69*1.75% -> 225.9565 | W69: =I69*0.25% -> 32.279501 | X69: =V69-W69 -> 193.677 | Y69: 0 | Z69: =X69-Y69 -> 193.677 | AB69: =VLOOKUP(C69,DSC_Master!$C$1:$K$200,9,0) -> NIRMAL SINGH | AC69: =VLOOKUP(C69,DSC_Master!$C$1:$J$201,8,0) -> 2784000100110417 | AD69: =VLOOKUP(C69,DSC_Master!$C$1:$J$201,7,0) -> PUNB0278400 | AF69: 12867.18 | AG69: =Q69-AF69 -> 44.620213 | AI69: 242 | AJ69: 12866.859 | AK69: =AI69-H69 -> 0 | AL69: =AJ69-I69 -> -44.941228
A70: 1062 | B70: Ramgarh | C70: 10620121 | D70: =VLOOKUP(C70,DSC_Master!$C$1:D164,2,0) -> 20121 | E70: =VLOOKUP(C70,DSC_Master!$C$1:$K$200,4,0) -> DUMDUMA DSK | F70: MPG | G70: Indirect | H70: 1136 | I70: 45855.072 | J70: =I70 -> 45855.072 | M70: 0 | O70: =J70-SUM(K70:N70) -> 45855.072 | P70: =IF(R70="Yes",O70,0) -> 0 | Q70: =O70-P70 -> 45855.072 | R70: 0 | T70: {=SUBSTITUTE(SUBSTITUTE(MID(CELL("filename"),FIND("[",CELL("filename"))+1,FIND("]",CELL("filename"))-FIND("[",CELL("filename"))-1),"Farmer Payment-",""),".xlsb","")} -> Ramgarh Kaimur_Farmer Payment_22-28 May-diff.xlsx | V70: =I70*1.75% -> 802.46375 | W70: =I70*0.25% -> 114.63768 | X70: =V70-W70 -> 687.82608 | Y70: 0 | Z70: =X70-Y70 -> 687.82608 | AB70: =VLOOKUP(C70,DSC_Master!$C$1:$K$200,9,0) -> CHANDRA MANI RAI | AC70: =VLOOKUP(C70,DSC_Master!$C$1:$J$201,8,0) -> 625310110008012 | AD70: =VLOOKUP(C70,DSC_Master!$C$1:$J$201,7,0) -> BKID0006253 | AF70: 45122.77 | AG70: =Q70-AF70 -> 732.30171 | AI70: 1136 | AJ70: 45122.108 | AK70: =AI70-H70 -> 0 | AL70: =AJ70-I70 -> -732.96389
A71: 1062 | B71: Ramgarh | C71: 10620122 | D71: =VLOOKUP(C71,DSC_Master!$C$1:D165,2,0) -> 20122 | E71: =VLOOKUP(C71,DSC_Master!$C$1:$K$200,4,0) -> NOUAN DSK | F71: MPG | G71: Indirect | H71: 124 | I71: 4183.1339 | J71: =I71 -> 4183.1339 | M71: 0 | O71: =J71-SUM(K71:N71) -> 4183.1339 | P71: =IF(R71="Yes",O71,0) -> 0 | Q71: =O71-P71 -> 4183.1339 | R71: 0 | T71: {=SUBSTITUTE(SUBSTITUTE(MID(CELL("filename"),FIND("[",CELL("filename"))+1,FIND("]",CELL("filename"))-FIND("[",CELL("filename"))-1),"Farmer Payment-",""),".xlsb","")} -> Ramgarh Kaimur_Farmer Payment_22-28 May-diff.xlsx | V71: =I71*1.75% -> 73.204842 | W71: =I71*0.25% -> 10.457835 | X71: =V71-W71 -> 62.747008 | Y71: 0 | Z71: =X71-Y71 -> 62.747008 | AB71: =VLOOKUP(C71,DSC_Master!$C$1:$K$200,9,0) -> JAISHANKAR JAISWAL | AC71: =VLOOKUP(C71,DSC_Master!$C$1:$J$201,8,0) -> 461110110007555 | AD71: =VLOOKUP(C71,DSC_Master!$C$1:$J$201,7,0) -> BKID0004611 | AF71: 4092 | AG71: =Q71-AF71 -> 91.133856 | AI71: 124 | AJ71: 4092.1309 | AK71: =AI71-H71 -> 0 | AL71: =AJ71-I71 -> -91.002912
A72: 1062 | B72: Ramgarh | C72: 10620123 | D72: =VLOOKUP(C72,DSC_Master!$C$1:D166,2,0) -> 20123 | E72: =VLOOKUP(C72,DSC_Master!$C$1:$K$200,4,0) -> SAKRAULI DSK | F72: MPG | G72: Indirect | H72: 177 | I72: 6577.9162 | J72: =I72 -> 6577.9162 | M72: 0 | O72: =J72-SUM(K72:N72) -> 6577.9162 | P72: =IF(R72="Yes",O72,0) -> 0 | Q72: =O72-P72 -> 6577.9162 | R72: 0 | T72: {=SUBSTITUTE(SUBSTITUTE(MID(CELL("filename"),FIND("[",CELL("filename"))+1,FIND("]",CELL("filename"))-FIND("[",CELL("filename"))-1),"Farmer Payment-",""),".xlsb","")} -> Ramgarh Kaimur_Farmer Payment_22-28 May-diff.xlsx | V72: =I72*1.75% -> 115.11353 | W72: =I72*0.25% -> 16.44479 | X72: =V72-W72 -> 98.668742 | Y72: 0 | Z72: =X72-Y72 -> 98.668742 | AB72: =VLOOKUP(C72,DSC_Master!$C$1:$K$200,9,0) -> BECHU PASSI | AC72: =VLOOKUP(C72,DSC_Master!$C$1:$J$201,8,0) -> 2696000100200761 | AD72: =VLOOKUP(C72,DSC_Master!$C$1:$J$201,7,0) -> PUNB0269600 | AF72: 0 | AG72: =Q72-AF72 -> 6577.9162 | AI72: 177 | AJ72: 6426.8728 | AK72: =AI72-H72 -> 0 | AL72: =AJ72-I72 -> -151.04339
F73: Total: | G73: =COUNTA(G3:G72) -> 70 | H73: =SUBTOTAL(109,H3:H72) -> 105725 | I73: =SUBTOTAL(109,I3:I72) -> 4429919.6 | J73: =SUBTOTAL(109,J3:J72) -> 4429919.6 | K73: =SUBTOTAL(109,K3:K72) -> 0 | L73: =SUBTOTAL(109,L3:L72) -> 0 | M73: =SUBTOTAL(109,M3:M72) -> 0 | N73: =SUBTOTAL(109,N3:N72) -> 0 | O73: =SUBTOTAL(109,O3:O72) -> 4429919.6 | ... Q73: =SUBTOTAL(109,Q3:Q72) -> 4429919.6 | R73: =COUNTIF(R2:R72,"Yes") -> 0 | V73: =SUM(V3:V72) -> 77523.593 | W73: =SUM(W3:W72) -> 11074.799 | X73: =SUM(X3:X72) -> 66448.794 | Y73: =SUM(Y3:Y72) -> 0 | Z73: =SUM(Z3:Z72) -> 66448.794 | AF73: =SUM(AF3:AF72) -> 3874849.8 | AG73: =SUM(AG3:AG72) -> 555069.79 | AI73: =SUBTOTAL(109,AI3:AI72) -> 93955 | AJ73: =SUBTOTAL(109,AJ3:AJ72) -> 3886202.1 | AK73: =AI73-H73 -> -11770 | AL73: =AJ73-I73 -> -543717.49
E75: Particulars | F75: Value
E76: No of MPGs | F76: =G73 -> 70
E77: BMC Volume | F77: =H73 -> 105725
E78: BMC Receipt Amount | F78: =I73 -> 4429919.6
E79: Payable Amount (Min) | F79: =J73 -> 4429919.6
...

Sheet Sheet1
A1: union_code | B1: bmc_code | C1: dcs_code | D1: society_code_ex | E1: dcs_short_name | F1: Mobile No | G1: ifsc | H1: bank_account_no | I1: beneficiary_name | J1: Balance Payable/Recoverable | K1: Remarks | L1: Recovery in 06-12 Feb | M1: Balance
A2: 001 | B2: 1062 | C2: 10620001 | D2: 64540 | E2: KARARI DSK | F2: 9934591684 | G2: HDFC0002625 | H2: 50100615862020 | I2: AKHILESH PANDEY | J2: 23.246194 | K2: Recovery from cycle | L2: =VLOOKUP(C2,'MPG Payment'!$C$3:$N$72,12,0) -> #N/A | M2: =J2-L2 -> #N/A
A3: 001 | B3: 1062 | C3: 10620012 | D3: 64515 | E3: DHARHARA DSK | F3: 7783847657 | G3: SBIN0006137 | H3: 37905177514 | I3: SHREE NIWAS YADAV | J3: 354.68346 | K3: Recovery from cycle | L3: =VLOOKUP(C3,'MPG Payment'!$C$3:$N$72,12,0) -> 0 | M3: =J3-L3 -> 354.68346
A4: 001 | B4: 1062 | C4: 10620015 | D4: 64537 | E4: KASTHARI DSK | F4: 9905909472 | G4: PUNB0237400 | H4: 2374001500005364 | I4: PAWAN KUMAR SINGH | J4: 13702.66 | K4: Recovery from cycle | L4: =VLOOKUP(C4,'MPG Payment'!$C$3:$N$72,12,0) -> 0 | M4: =J4-L4 -> 13702.66
A5: 001 | B5: 1062 | C5: 10620018 | D5: 64591 | E5: LURPURWA DSK | F5: 8002591740 | G5: UBIN0560308 | H5: 603002010018335 | I5: SAVARU SINGH | J5: 19750.367 | K5: Recovery from cycle | L5: =VLOOKUP(C5,'MPG Payment'!$C$3:$N$72,12,0) -> #N/A | M5: =J5-L5 -> #N/A
A6: 001 | B6: 1062 | C6: 10620020 | D6: 64552 | E6: KRAPALPUR DSK | F6: 7739708957 | G6: PUNB0237400 | H6: 2374000100170476 | I6: VIJAY NARAYAN SINGH | J6: 27305.976 | K6: Recovery from cycle | L6: =VLOOKUP(C6,'MPG Payment'!$C$3:$N$72,12,0) -> 0 | M6: =J6-L6 -> 27305.976
A7: 001 | B7: 1062 | C7: 10620022 | D7: 64545 | E7: SURYAPURA DSK | F7: 9199217582 | G7: BKID0004611 | H7: 461110110009490 | I7: AJAY KUMAR SINGH | J7: 3356.0228 | K7: Recovery from cycle | L7: =VLOOKUP(C7,'MPG Payment'!$C$3:$N$72,12,0) -> #N/A | M7: =J7-L7 -> #N/A
A8: 001 | B8: 1062 | C8: 10620024 | D8: 60610 | E8: KARIRAM DSK | F8: 9199729020 | G8: PUNB0600800 | H8: 6008001700141624 | I8: BHARAT SINGH | J8: 3070.7935 | K8: Recovery from cycle | L8: =VLOOKUP(C8,'MPG Payment'!$C$3:$N$72,12,0) -> 0 | M8: =J8-L8 -> 3070.7935
A9: 001 | B9: 1062 | C9: 10620026 | D9: 64528 | E9: TARITHA DSK | F9: 9135981264 | G9: BKID0004611 | H9: 461118210002964 | I9: MANOJ KUMAR SINGH | J9: 3272.5795 | K9: Recovery from cycle | L9: =VLOOKUP(C9,'MPG Payment'!$C$3:$N$72,12,0) -> 0 | M9: =J9-L9 -> 3272.5795
A10: 001 | B10: 1062 | C10: 10620034 | D10: 64509 | E10: CHHOTKI KULHARIYA | F10: 7250947683 | G10: HDFC0002625 | H10: 50100492904593 | I10: ABHIMANYU KUMAR SINGH | J10: 4658.6176 | K10: Recovery from cycle | L10: =VLOOKUP(C10,'MPG Payment'!$C$3:$N$72,12,0) -> 0 | M10: =J10-L10 -> 4658.6176
A11: 001 | B11: 1062 | C11: 10620061 | D11: 60605 | E11: BADORA DSK | F11: 9170623981 | G11: SBIN0011251 | H11: 40819491150 | I11: SUMAN DEVI | J11: 46684.153 | K11: Recovery from cycle | L11: =VLOOKUP(C11,'MPG Payment'!$C$3:$N$72,12,0) -> 0 | M11: =J11-L11 -> 46684.153
A12: 001 | B12: 1062 | C12: 10620062 | D12: 64590 | E12: CHATRA DSK | F12: 9934761888 | G12: SBIN0002964 | H12: 39981585891 | I12: USHA DEVI | J12: 22196.225 | K12: Recovery from cycle | L12: =VLOOKUP(C12,'MPG Payment'!$C$3:$N$72,12,0) -> 0 | M12: =J12-L12 -> 22196.225
A13: 001 | B13: 1062 | C13: 10620065 | D13: 64589 | E13: NIPURAN DSK | F13: 7763028752 | G13: PUNB0237400 | H13: 2374000100181126 | I13: NITESH KUMAR YADAV | J13: 4097.9232 | K13: Recovery from cycle | L13: =VLOOKUP(C13,'MPG Payment'!$C$3:$N$72,12,0) -> #N/A | M13: =J13-L13 -> #N/A
... A17: 001 | B17: 1062 | C17: 10620094 | D17: 64572 | E17: MATHURADERA DSK | F17: 7061423987 | G17: PUNB0154700 | H17: 1547000100166038 | I17: SURENDRA YADAV | J17: 9307.5261 | K17: Recovery from cycle | L17: =VLOOKUP(C17,'MPG Payment'!$C$3:$N$72,12,0) -> #N/A | M17: =J17-L17 -> #N/A
J18: =SUM(J2:J17) -> 172704.2 | L18: =SUM(L2:L17) -> #N/A | M18: =J18-L18 -> #N/A

Sheet TS Loss Gain
B1: Ramgarh Bmc | AP1: 436.77 | AQ1: 291.18
B2: Date | C2: Shift | D2: OB | I2: Milk from MPG in Kg | M2: Transfer from other BMC/RMC | R2: Total Milk Receipt in Kg | U2: Tanker Dispatch Details | AC2: Plant Receipt | AH2: CB | AM2: Loss/(Gain)
D3: Qty KG | E3: Fat% | F3: Snf% | G3: FAT Kg | H3: SNF Kg | I3: Qty Kg | J3: Qty Kg | K3: Fat% | L3: Snf% | M3: From | N3: Tanker No | O3: Qty Kg | P3: Fat% | Q3: Snf% | R3: Qty Kg | S3: FAT Kg | T3: SNF Kg | U3: Tanker | V3: Challan | W3: To | X3: Qty KG | Y3: Fat% | Z3: Snf% | AA3: FAT Kg | AB3: SNF Kg | AC3: Qty KG | AD3: Fat% | AE3: Snf% | AF3: FAT Kg | AG3: SNF Kg | AH3: Qty KG | AI3: Fat% | AJ3: Snf% | AK3: FAT Kg | AL3: SNF Kg | AM3: Qty KG | AN3: FAT Kg | AO3: SNF Kg | AP3: TS Loss% | AQ3: Amount
B4: 46054 | C4: M | D4: 0 | E4: 0 | F4: 0 | G4: =+D4*E4% -> 0 | H4: =+D4*F4% -> 0 | I4: 20910 | J4: 20910 | K4: 5.3178001 | L4: 8.3824582 | R4: =O4+J4 -> 20910 | S4: =(J4*K4%)+(O4*P4%) -> 1111.952 | T4: =(J4*L4%)+(O4*Q4%) -> 1752.772 | U4: 5280 | V4: KMR 01 | W4: Hajipur | X4: 14940 | Y4: 5.3 | Z4: 8.3 | AA4: =X4*Y4% -> 791.82 | AB4: =X4*Z4% -> 1240.02 | AC4: 14940 | AD4: 5.3 | AE4: 8.3 | AF4: =AC4*AD4% -> 791.82 | AG4: =AC4*AE4% -> 1240.02 | AH4: 5970 | AI4: 5.36 | AJ4: 8.59 | AK4: =AH4*AI4% -> 319.992 | AL4: =AH4*AJ4% -> 512.823 | AM4: =+D4+R4-AC4-AH4 -> 0 | AN4: =+G4+S4-AF4-AK4 -> 0.14 | AO4: =+H4+T4-AG4-AL4 -> -0.071 | AP4: =(AN4+AO4)/(S4+T4) -> 2.408609e-05 | AQ4: =($AP$1*AN4+$AQ$1*AO4) -> 40.47402 | AR4: =(D4+J4+O4)-(X4+AH4) -> 0
B5: =+B4 -> 46054 | C5: E | D5: 5970 | E5: 5.36 | F5: 8.59 | G5: =+D5*E5% -> 319.992 | H5: =+D5*F5% -> 512.823 | I5: 8469 | J5: 8469 | K5: 5.4522376 | L5: 8.5376077 | R5: =O5+J5 -> 8469 | S5: =(J5*K5%)+(O5*P5%) -> 461.75 | T5: =(J5*L5%)+(O5*Q5%) -> 723.05 | U5: 0 | V5: 0 | W5: 0 | X5: 0 | Y5: 0 | Z5: 0 | AA5: =X5*Y5% -> 0 | AB5: =X5*Z5% -> 0 | AF5: =AC5*AD5% -> 0 | AG5: =AC5*AE5% -> 0 | AH5: 14459 | AI5: 5.41 | AJ5: 8.55 | AK5: =AH5*AI5% -> 782.2319 | AL5: =AH5*AJ5% -> 1236.2445 | AM5: =+D5+R5-AC5-AH5 -> -20 | AN5: =+G5+S5-AF5-AK5 -> -0.4899 | AO5: =+H5+T5-AG5-AL5 -> -0.3715 | AP5: =(AN5+AO5)/(S5+T5) -> -0.00072704254 | AQ5: =($AP$1*AN5+$AQ$1*AO5) -> -322.14699 | AR5: =(D5+J5+O5)-(X5+AH5) -> -20
B6: =+B4+1 -> 46055 | C6: M | D6: 14459 | E6: 5.41 | F6: 8.55 | G6: =+D6*E6% -> 782.2319 | H6: =+D6*F6% -> 1236.2445 | I6: 8285 | J6: 8285 | K6: 5.5487628 | L6: 8.6249849 | R6: =O6+J6 -> 8285 | S6: =(J6*K6%)+(O6*P6%) -> 459.715 | T6: =(J6*L6%)+(O6*Q6%) -> 714.58 | U6: 5280 | V6: KMR 02 | W6: Hajipur | X6: 18830 | Y6: 5.35 | Z6: 8.6 | AA6: =X6*Y6% -> 1007.405 | AB6: =X6*Z6% -> 1619.38 | AC6: 18760 | AD6: 5.35 | AE6: 8.41 | AF6: =AC6*AD6% -> 1003.66 | AG6: =AC6*AE6% -> 1577.716 | AH6: 3934 | AI6: 5.45 | AJ6: 8.57 | AK6: =AH6*AI6% -> 214.403 | AL6: =AH6*AJ6% -> 337.1438 | AM6: =+D6+R6-AC6-AH6 -> 50 | AN6: =+G6+S6-AF6-AK6 -> 23.8839 | AO6: =+H6+T6-AG6-AL6 -> 35.9647 | AP6: =(AN6+AO6)/(S6+T6) -> 0.050965558 | AQ6: =($AP$1*AN6+$AQ$1*AO6) -> 20903.972 | AR6: =(D6+J6+O6)-(X6+AH6) -> -20
B7: =+B5+1 -> 46055 | C7: E | D7: 3934 | E7: 5.45 | F7: 8.57 | G7: =+D7*E7% -> 214.403 | H7: =+D7*F7% -> 337.1438 | I7: 5624 | J7: 5624 | K7: 5.5403983 | L7: 8.4842105 | R7: =O7+J7 -> 5624 | S7: =(J7*K7%)+(O7*P7%) -> 311.592 | T7: =(J7*L7%)+(O7*Q7%) -> 477.152 | U7: 0 | V7: 0 | W7: 0 | X7: 0 | Y7: 0 | Z7: 0 | AA7: =X7*Y7% -> 0 | AB7: =X7*Z7% -> 0 | AF7: =AC7*AD7% -> 0 | AG7: =AC7*AE7% -> 0 | AH7: 9558 | AI7: 5.5 | AJ7: 8.52 | AK7: =AH7*AI7% -> 525.69 | AL7: =AH7*AJ7% -> 814.3416 | AM7: =+D7+R7-AC7-AH7 -> 0 | AN7: =+G7+S7-AF7-AK7 -> 0.305 | AO7: =+H7+T7-AG7-AL7 -> -0.0458 | AP7: =(AN7+AO7)/(S7+T7) -> 0.00032862374 | AQ7: =($AP$1*AN7+$AQ$1*AO7) -> 119.87881 | AR7: =(D7+J7+O7)-(X7+AH7) -> 0
B8: =+B6+1 -> 46056 | C8: M | D8: 9558 | E8: 5.5 | F8: 8.52 | G8: =+D8*E8% -> 525.69 | H8: =+D8*F8% -> 814.3416 | I8: 6861 | J8: 6861 | K8: 5.5343827 | L8: 8.596808 | R8: =O8+J8 -> 6861 | S8: =(J8*K8%)+(O8*P8%) -> 379.714 | T8: =(J8*L8%)+(O8*Q8%) -> 589.827 | U8: 00 | V8: 0 | W8: 0 | X8: 0 | Y8: 0 | Z8: 0 | AA8: =X8*Y8% -> 0 | AB8: =X8*Z8% -> 0 | AF8: =AC8*AD8% -> 0 | AG8: =AC8*AE8% -> 0 | AH8: 16429 | AI8: 5.51 | AJ8: 8.55 | AK8: =AH8*AI8% -> 905.2379 | AL8: =AH8*AJ8% -> 1404.6795 | AM8: =+D8+R8-AC8-AH8 -> -10 | AN8: =+G8+S8-AF8-AK8 -> 0.1661 | AO8: =+H8+T8-AG8-AL8 -> -0.5109 | AP8: =(AN8+AO8)/(S8+T8) -> -0.0003556322 | AQ8: =($AP$1*AN8+$AQ$1*AO8) -> -76.216365 | AR8: =(D8+J8+O8)-(X8+AH8) -> -10
B9: =+B7+1 -> 46056 | C9: E | D9: 16429 | E9: 5.51 | F9: 8.55 | G9: =+D9*E9% -> 905.2379 | H9: =+D9*F9% -> 1404.6795 | I9: 7190 | J9: 7190 | K9: 5.3776078 | L9: 8.5348679 | R9: =O9+J9 -> 7190 | S9: =(J9*K9%)+(O9*P9%) -> 386.65 | T9: =(J9*L9%)+(O9*Q9%) -> 613.657 | U9: 5280 | V9: KMR 03 | W9: Hajipur | X9: 18800 | Y9: 5.2 | Z9: 8.2 | AA9: =X9*Y9% -> 977.6 | AB9: =X9*Z9% -> 1541.6 | AC9: 18780 | AD9: 5.15 | AE9: 8.12 | AF9: =AC9*AD9% -> 967.17 | AG9: =AC9*AE9% -> 1524.936 | AH9: 4829 | AI9: 5.47 | AJ9: 8.54 | AK9: =AH9*AI9% -> 264.1463 | AL9: =AH9*AJ9% -> 412.3966 | AM9: =+D9+R9-AC9-AH9 -> 10 | AN9: =+G9+S9-AF9-AK9 -> 60.5716 | AO9: =+H9+T9-AG9-AL9 -> 81.0039 | AP9: =(AN9+AO9)/(S9+T9) -> 0.14153205 | AQ9: =($AP$1*AN9+$AQ$1*AO9) -> 50042.573 | AR9: =(D9+J9+O9)-(X9+AH9) -> -10
B10: =+B8+1 -> 46057 | C10: M | D10: 4829 | E10: 5.47 | F10: 8.54 | G10: =+D10*E10% -> 264.1463 | H10: =+D10*F10% -> 412.3966 | I10: 4601 | J10: 4601 | K10: 5.3553141 | L10: 8.6052597 | R10: =O10+J10 -> 4601 | S10: =(J10*K10%)+(O10*P10%) -> 246.398 | T10: =(J10*L10%)+(O10*Q10%) -> 395.928 | U10: 0 | V10: 0 | W10: 0 | X10: 0 | Y10: 0 | Z10: 0 | AA10: =X10*Y10% -> 0 | AB10: =X10*Z10% -> 0 | AF10: =AC10*AD10% -> 0 | AG10: =AC10*AE10% -> 0 | AH10: 9440 | AI10: 5.39 | AJ10: 8.53 | AK10: =AH10*AI10% -> 508.816 | AL10: =AH10*AJ10% -> 805.232 | AM10: =+D10+R10-AC10-AH10 -> -10 | AN10: =+G10+S10-AF10-AK10 -> 1.7283 | AO10: =+H10+T10-AG10-AL10 -> 3.0926 | AP10: =(AN10+AO10)/(S10+T10) -> 0.0075053789 | AQ10: =($AP$1*AN10+$AQ$1*AO10) -> 1655.3729 | AR10: =(D10+J10+O10)-(X10+AH10) -> -10
B11: =+B9+1 -> 46057 | C11: E | D11: 9440 | E11: 5.39 | F11: 8.53 | G11: =+D11*E11% -> 508.816 | H11: =+D11*F11% -> 805.232 | I11: 4919 | J11: 4919 | K11: 5.3969913 | L11: 8.4898353 | R11: =O11+J11 -> 4919 | S11: =(J11*K11%)+(O11*P11%) -> 265.478 | T11: =(J11*L11%)+(O11*Q11%) -> 417.615 | U11: 0 | V11: 0 | W11: 0 | X11: 0 | Y11: 0 | Z11: 0 | AA11: =X11*Y11% -> 0 | AB11: =X11*Z11% -> 0 | AF11: =AC11*AD11% -> 0 | AG11: =AC11*AE11% -> 0 | AH11: 14379 | AI11: 5.38 | AJ11: 8.5 | AK11: =AH11*AI11% -> 773.5902 | AL11: =AH11*AJ11% -> 1222.215 | AM11: =+D11+R11-AC11-AH11 -> -20 | AN11: =+G11+S11-AF11-AK11 -> 0.7038 | AO11: =+H11+T11-AG11-AL11 -> 0.632 | AP11: =(AN11+AO11)/(S11+T11) -> 0.001955517 | AQ11: =($AP$1*AN11+$AQ$1*AO11) -> 491.42449 | AR11: =(D11+J11+O11)-(X11+AH11) -> -20
B12: =+B10+1 -> 46058 | C12: M | D12: 14379 | E12: 5.38 | F12: 8.5 | G12: =+D12*E12% -> 773.5902 | H12: =+D12*F12% -> 1222.215 | I12: 5240 | J12: 5240 | K12: 5.6366794 | L12: 8.6313168 | R12: =O12+J12 -> 5240 | S12: =(J12*K12%)+(O12*P12%) -> 295.362 | T12: =(J12*L12%)+(O12*Q12%) -> 452.281 | U12: 5280 | V12: KMR 04 | W12: Hajipur | X12: 18780 | Y12: 5.55 | Z12: 8.65 | AA12: =X12*Y12% -> 1042.29 | AB12: =X12*Z12% -> 1624.47 | AC12: 18840 | AD12: 5.55 | AE12: 8.52 | AF12: =AC12*AD12% -> 1045.62 | AG12: =AC12*AE12% -> 1605.168 | AH12: 879 | AI12: 5.44 | AJ12: 8.52 | AK12: =AH12*AI12% -> 47.8176 | AL12: =AH12*AJ12% -> 74.8908 | AM12: =+D12+R12-AC12-AH12 -> -100 | AN12: =+G12+S12-AF12-AK12 -> -24.4854 | AO12: =+H12+T12-AG12-AL12 -> -5.5628 | AP12: =(AN12+AO12)/(S12+T12) -> -0.040190572 | AQ12: =($AP$1*AN12+$AQ$1*AO12) -> -12314.264 | AR12: =(D12+J12+O12)-(X12+AH12) -> -40
B13: =+B11+1 -> 46058 | C13: E | D13: 879 | E13: 5.44 | F13: 8.52 | G13: =+D13*E13% -> 47.8176 | H13: =+D13*F13% -> 74.8908 | I13: 5430 | J13: 5430 | K13: 5.1667956 | L13: 8.5652855 | R13: =O13+J13 -> 5430 | S13: =(J13*K13%)+(O13*P13%) -> 280.557 | T13: =(J13*L13%)+(O13*Q13%) -> 465.095 | U13: 0 | V13: 0 | W13: 0 | X13: 0 | Y13: 0 | Z13: 0 | AA13: =X13*Y13% -> 0 | AB13: =X13*Z13% -> 0 | AF13: =AC13*AD13% -> 0 | AG13: =AC13*AE13% -> 0 | AH13: 6319 | AI13: 5.2 | AJ13: 8.55 | AK13: =AH13*AI13% -> 328.588 | AL13: =AH13*AJ13% -> 540.2745 | AM13: =+D13+R13-AC13-AH13 -> -10 | AN13: =+G13+S13-AF13-AK13 -> -0.2134 | AO13: =+H13+T13-AG13-AL13 -> -0.2887 | AP13: =(AN13+AO13)/(S13+T13) -> -0.00067337042 | AQ13: =($AP$1*AN13+$AQ$1*AO13) -> -177.27038 | AR13: =(D13+J13+O13)-(X13+AH13) -> -10 | AS13: =SUM(AQ4:AQ13) -> 60363.798
B14: =+B12+1 -> 46059 | C14: M | D14: 6319 | E14: 5.2 | F14: 8.55 | G14: =+D14*E14% -> 328.588 | H14: =+D14*F14% -> 540.2745 | I14: 5637 | J14: 5637 | K14: 5.5152386 | L14: 8.6147064 | R14: =O14+J14 -> 5637 | S14: =(J14*K14%)+(O14*P14%) -> 310.894 | T14: =(J14*L14%)+(O14*Q14%) -> 485.611 | U14: 0 | V14: 0 | W14: 0 | X14: 0 | Y14: 0 | Z14: 0 | AA14: =X14*Y14% -> 0 | AB14: =X14*Z14% -> 0 | AF14: =AC14*AD14% -> 0 | AG14: =AC14*AE14% -> 0 | AH14: 11966 | AI14: 5.35 | AJ14: 8.57 | AK14: =AH14*AI14% -> 640.181 | AL14: =AH14*AJ14% -> 1025.4862 | AM14: =+D14+R14-AC14-AH14 -> -10 | AN14: =+G14+S14-AF14-AK14 -> -0.699 | AO14: =+H14+T14-AG14-AL14 -> 0.3993 | AP14: =(AN14+AO14)/(S14+T14) -> -0.00037626882 | AQ14: =($AP$1*AN14+$AQ$1*AO14) -> -189.03406 | AR14: =(D14+J14+O14)-(X14+AH14) -> -10
B15: =+B13+1 -> 46059 | C15: E | D15: 11966 | E15: 5.35 | F15: 8.57 | G15: =+D15*E15% -> 640.181 | H15: =+D15*F15% -> 1025.4862 | I15: 4761 | J15: 4761 | K15: 5.4387314 | L15: 8.5452636 | R15: =O15+J15 -> 4761 | S15: =(J15*K15%)+(O15*P15%) -> 258.938 | T15: =(J15*L15%)+(O15*Q15%) -> 406.84 | U15: 0 | V15: 0 | W15: 0 | X15: 0 | Y15: 0 | Z15: 0 | AA15: =X15*Y15% -> 0 | AB15: =X15*Z15% -> 0 | AF15: =AC15*AD15% -> 0 | AG15: =AC15*AE15% -> 0 | AH15: 16737 | AI15: 5.37 | AJ15: 8.56 | AK15: =AH15*AI15% -> 898.7769 | AL15: =AH15*AJ15% -> 1432.6872 | AM15: =+D15+R15-AC15-AH15 -> -10 | AN15: =+G15+S15-AF15-AK15 -> 0.3421 | AO15: =+H15+T15-AG15-AL15 -> -0.361 | AP15: =(AN15+AO15)/(S15+T15) -> -2.8387841e-05 | AQ15: =($AP$1*AN15+$AQ$1*AO15) -> 44.303037 | AR15: =(D15+J15+O15)-(X15+AH15) -> -10
B16: =+B14+1 -> 46060 | C16: M | D16: 16737 | E16: 5.37 | F16: 8.56 | G16: =+D16*E16% -> 898.7769 | H16: =+D16*F16% -> 1432.6872 | I16: 7868 | J16: 7868 | K16: 5.2064692 | L16: 8.4920564 | R16: =O16+J16 -> 7868 | S16: =(J16*K16%)+(O16*P16%) -> 409.645 | T16: =(J16*L16%)+(O16*Q16%) -> 668.155 | U16: 0 | V16: 0 | W16: 0 | X16: 0 | Y16: 0 | Z16: 0 | AA16: =X16*Y16% -> 0 | AB16: =X16*Z16% -> 0 | AF16: =AC16*AD16% -> 0 | AG16: =AC16*AE16% -> 0 | AH16: 24615 | AI16: 5.32 | AJ16: 8.53 | AK16: =AH16*AI16% -> 1309.518 | AL16: =AH16*AJ16% -> 2099.6595 | AM16: =+D16+R16-AC16-AH16 -> -10 | AN16: =+G16+S16-AF16-AK16 -> -1.0961 | AO16: =+H16+T16-AG16-AL16 -> 1.1827 | AP16: =(AN16+AO16)/(S16+T16) -> 8.0348859e-05 | AQ16: =($AP$1*AN16+$AQ$1*AO16) -> -134.36501 | AR16: =(D16+J16+O16)-(X16+AH16) -> -10
B17: =+B15+1 -> 46060 | C17: E | D17: 24615 | E17: 5.32 | F17: 8.53 | G17: =+D17*E17% -> 1309.518 | H17: =+D17*F17% -> 2099.6595 | I17: 6349 | J17: 6349 | K17: 5.4990392 | L17: 8.6212947 | R17: =O17+J17 -> 6349 | S17: =(J17*K17%)+(O17*P17%) -> 349.134 | T17: =(J17*L17%)+(O17*Q17%) -> 547.366 | U17: 00 | V17: 0 | W17: 0 | X17: 0 | Y17: 0 | Z17: 0 | AA17: =X17*Y17% -> 0 | AB17: =X17*Z17% -> 0 | AF17: =AC17*AD17% -> 0 | AG17: =AC17*AE17% -> 0 | AH17: 30974 | AI17: 5.35 | AJ17: 8.55 | AK17: =AH17*AI17% -> 1657.109 | AL17: =AH17*AJ17% -> 2648.277 | AM17: =+D17+R17-AC17-AH17 -> -10 | AN17: =+G17+S17-AF17-AK17 -> 1.543 | AO17: =+H17+T17-AG17-AL17 -> -1.2515 | AP17: =(AN17+AO17)/(S17+T17) -> 0.00032515337 | AQ17: =($AP$1*AN17+$AQ$1*AO17) -> 309.52434 | AR17: =(D17+J17+O17)-(X17+AH17) -> -10
B18: =+B16+1 -> 46061 | C18: M | D18: 30974 | E18: 5.35 | F18: 8.55 | G18: =+D18*E18% -> 1657.109 | H18: =+D18*F18% -> 2648.277 | I18: 6100 | J18: 6100 | K18: 5.5326393 | L18: 8.5830984 | R18: =O18+J18 -> 6100 | S18: =(J18*K18%)+(O18*P18%) -> 337.491 | T18: =(J18*L18%)+(O18*Q18%) -> 523.569 | U18: 5280 | V18: 82005 | W18: Hajipur | X18: 18750 | Y18: 5.55 | Z18: 8.65 | AA18: =X18*Y18% -> 1040.625 | AB18: =X18*Z18% -> 1621.875 | AC18: 18760 | AD18: 5.35 | AE18: 8.35 | AF18: =AC18*AD18% -> 1003.66 | AG18: =AC18*AE18% -> 1566.46 | AH18: 18334 | AI18: 5.38 | AJ18: 8.55 | AK18: =AH18*AI18% -> 986.3692 | AL18: =AH18*AJ18% -> 1567.557 | AM18: =+D18+R18-AC18-AH18 -> -20 | AN18: =+G18+S18-AF18-AK18 -> 4.5708 | AO18: =+H18+T18-AG18-AL18 -> 37.829 | AP18: =(AN18+AO18)/(S18+T18) -> 0.0492414 | AQ18: =($AP$1*AN18+$AQ$1*AO18) -> 13011.437 | AR18: =(D18+J18+O18)-(X18+AH18) -> -10
B19: =+B17+1 -> 46061 | C19: E | D19: 18334 | E19: 5.38 | F19: 8.55 | G19: =+D19*E19% -> 986.3692 | H19: =+D19*F19% -> 1567.557 | I19: 7022 | J19: 7022 | K19: 5.3281401 | L19: 8.495685 | R19: =O19+J19 -> 7022 | S19: =(J19*K19%)+(O19*P19%) -> 374.142 | T19: =(J19*L19%)+(O19*Q19%) -> 596.567 | U19: 0 | V19: 0 | W19: 0 | X19: 0 | Y19: 0 | Z19: 0 | AA19: =X19*Y19% -> 0 | AB19: =X19*Z19% -> 0 | AF19: =AC19*AD19% -> 0 | AG19: =AC19*AE19% -> 0 | AH19: 25366 | AI19: 5.36 | AJ19: 8.53 | AK19: =AH19*AI19% -> 1359.6176 | AL19: =AH19*AJ19% -> 2163.7198 | AM19: =+D19+R19-AC19-AH19 -> -10 | AN19: =+G19+S19-AF19-AK19 -> 0.8936 | AO19: =+H19+T19-AG19-AL19 -> 0.4042 | AP19: =(AN19+AO19)/(S19+T19) -> 0.0013369609 | AQ19: =($AP$1*AN19+$AQ$1*AO19) -> 507.99263 | AR19: =(D19+J19+O19)-(X19+AH19) -> -10
B20: =+B18+1 -> 46062 | C20: M | D20: 25366 | E20: 5.36 | F20: 8.53 | G20: =+D20*E20% -> 1359.6176 | H20: =+D20*F20% -> 2163.7198 | I20: 6305 | J20: 6305 | K20: 5.2935289 | L20: 8.5433783 | R20: =O20+J20 -> 6305 | S20: =(J20*K20%)+(O20*P20%) -> 333.757 | T20: =(J20*L20%)+(O20*Q20%) -> 538.66 | U20: 5280 | V20: 82007 | W20: Hajipur | X20: 18790 | Y20: 5.15 | Z20: 8.19 | AA20: =X20*Y20% -> 967.685 | AB20: =X20*Z20% -> 1538.901 | AC20: 18690 | AD20: 5.35 | AE20: 8.48 | AF20: =AC20*AD20% -> 999.915 | AG20: =AC20*AE20% -> 1584.912 | AH20: 12891 | AI20: 5.35 | AJ20: 8.53 | AK20: =AH20*AI20% -> 689.6685 | AL20: =AH20*AJ20% -> 1099.6023 | AM20: =+D20+R20-AC20-AH20 -> 90 | AN20: =+G20+S20-AF20-AK20 -> 3.7911 | AO20: =+H20+T20-AG20-AL20 -> 17.8655 | AP20: =(AN20+AO20)/(S20+T20) -> 0.02482368 | AQ20: =($AP$1*AN20+$AQ$1*AO20) -> 6857.915 | AR20: =(D20+J20+O20)-(X20+AH20) -> -10
B21: =+B19+1 -> 46062 | C21: E | D21: 12891 | E21: 5.35 | F21: 8.53 | G21: =+D21*E21% -> 689.6685 | H21: =+D21*F21% -> 1099.6023 | I21: 7560 | J21: 7560 | K21: 5.4646693 | L21: 8.557791 | R21: =O21+J21 -> 7560 | S21: =(J21*K21%)+(O21*P21%) -> 413.129 | T21: =(J21*L21%)+(O21*Q21%) -> 646.969 | U21: 0 | V21: 0 | W21: 0 | X21: 0 | Y21: 0 | Z21: 0 | AA21: =X21*Y21% -> 0 | AB21: =X21*Z21% -> 0 | AF21: =AC21*AD21% -> 0 | AG21: =AC21*AE21% -> 0 | AH21: 20461 | AI21: 5.39 | AJ21: 8.54 | AK21: =AH21*AI21% -> 1102.8479 | AL21: =AH21*AJ21% -> 1747.3694 | AM21: =+D21+R21-AC21-AH21 -> -10 | AN21: =+G21+S21-AF21-AK21 -> -0.0504 | AO21: =+H21+T21-AG21-AL21 -> -0.7981 | AP21: =(AN21+AO21)/(S21+T21) -> -0.0008003977 | AQ21: =($AP$1*AN21+$AQ$1*AO21) -> -254.40397 | AR21: =(D21+J21+O21)-(X21+AH21) -> -10
B22: =+B20+1 -> 46063 | C22: M | D22: 20461 | E22: 5.39 | F22: 8.54 | G22: =+D22*E22% -> 1102.8479 | H22: =+D22*F22% -> 1747.3694 | I22: 6363 | J22: 6363 | K22: 5.4041961 | L22: 8.5608047 | R22: =O22+J22 -> 6363 | S22: =(J22*K22%)+(O22*P22%) -> 343.869 | T22: =(J22*L22%)+(O22*Q22%) -> 544.724 | U22: 5280 | V22: 82008 | W22: Hajipur | X22: 18790 | Y22: 5.35 | Z22: 8.48 | AA22: =X22*Y22% -> 1005.265 | AB22: =X22*Z22% -> 1593.392 | AC22: 18710 | AD22: 5.25 | AE22: 8.33 | AF22: =AC22*AD22% -> 982.275 | AG22: =AC22*AE22% -> 1558.543 | AH22: 8044 | AI22: 5.39 | AJ22: 8.54 | AK22: =AH22*AI22% -> 433.5716 | AL22: =AH22*AJ22% -> 686.9576 | AM22: =+D22+R22-AC22-AH22 -> 70 | AN22: =+G22+S22-AF22-AK22 -> 30.8703 | AO22: =+H22+T22-AG22-AL22 -> 46.5928 | AP22: =(AN22+AO22)/(S22+T22) -> 0.087175006 | AQ22: =($AP$1*AN22+$AQ$1*AO22) -> 27050.112 | AR22: =(D22+J22+O22)-(X22+AH22) -> -10
B23: =+B21+1 -> 46063 | C23: E | D23: 8044 | E23: 5.39 | F23: 8.54 | G23: =+D23*E23% -> 433.5716 | H23: =+D23*F23% -> 686.9576 | I23: 6735 | J23: 6735 | K23: 5.4001336 | L23: 8.46049 | R23: =O23+J23 -> 6735 | S23: =(J23*K23%)+(O23*P23%) -> 363.699 | T23: =(J23*L23%)+(O23*Q23%) -> 569.814 | U23: 0 | V23: 0 | W23: 0 | X23: 0 | Y23: 0 | Z23: 0 | AA23: =X23*Y23% -> 0 | AB23: =X23*Z23% -> 0 | AF23: =AC23*AD23% -> 0 | AG23: =AC23*AE23% -> 0 | AH23: 14789 | AI23: 5.39 | AJ23: 8.5 | AK23: =AH23*AI23% -> 797.1271 | AL23: =AH23*AJ23% -> 1257.065 | AM23: =+D23+R23-AC23-AH23 -> -10 | AN23: =+G23+S23-AF23-AK23 -> 0.1435 | AO23: =+H23+T23-AG23-AL23 -> -0.2934 | AP23: =(AN23+AO23)/(S23+T23) -> -0.00016057623 | AQ23: =($AP$1*AN23+$AQ$1*AO23) -> -22.755717 | AR23: =(D23+J23+O23)-(X23+AH23) -> -10
B24: =+B22+1 -> 46064 | C24: M | D24: 14789 | E24: 5.39 | F24: 8.5 | G24: =+D24*E24% -> 797.1271 | H24: =+D24*F24% -> 1257.065 | I24: 5703 | J24: 5703 | K24: 5.3567245 | L24: 8.5889181 | R24: =O24+J24 -> 5703 | S24: =(J24*K24%)+(O24*P24%) -> 305.494 | T24: =(J24*L24%)+(O24*Q24%) -> 489.826 | U24: 0 | V24: 0 | W24: 0 | X24: 0 | Y24: 0 | Z24: 0 | AA24: =X24*Y24% -> 0 | AB24: =X24*Z24% -> 0 | AF24: =AC24*AD24% -> 0 | AG24: =AC24*AE24% -> 0 | AH24: 20502 | AI24: 5.38 | AJ24: 8.52 | AK24: =AH24*AI24% -> 1103.0076 | AL24: =AH24*AJ24% -> 1746.7704 | AM24: =+D24+R24-AC24-AH24 -> -10 | AN24: =+G24+S24-AF24-AK24 -> -0.3865 | AO24: =+H24+T24-AG24-AL24 -> 0.1206 | AP24: =(AN24+AO24)/(S24+T24) -> -0.00033433084 | AQ24: =($AP$1*AN24+$AQ$1*AO24) -> -133.6953 | AR24: =(D24+J24+O24)-(X24+AH24) -> -10
B25: =+B23+1 -> 46064 | C25: E | D25: 20502 | E25: 5.38 | F25: 8.52 | G25: =+D25*E25% -> 1103.0076 | H25: =+D25*F25% -> 1746.7704 | I25: 7060 | J25: 7060 | K25: 5.3508782 | L25: 8.5414306 | R25: =O25+J25 -> 7060 | S25: =(J25*K25%)+(O25*P25%) -> 377.772 | T25: =(J25*L25%)+(O25*Q25%) -> 603.025 | U25: 5280 | V25: 82009 | W25: Hajipur | X25: 18500 | Y25: 5.45 | Z25: 8.63 | AA25: =X25*Y25% -> 1008.25 | AB25: =X25*Z25% -> 1596.55 | AC25: 18540 | AD25: 5.4 | AE25: 8.43 | AF25: =AC25*AD25% -> 1001.16 | AG25: =AC25*AE25% -> 1562.922 | AH25: 9072 | AI25: 5.37 | AJ25: 8.52 | AK25: =AH25*AI25% -> 487.1664 | AL25: =AH25*AJ25% -> 772.9344 | AM25: =+D25+R25-AC25-AH25 -> -50 | AN25: =+G25+S25-AF25-AK25 -> -7.5468 | AO25: =+H25+T25-AG25-AL25 -> 13.939 | AP25: =(AN25+AO25)/(S25+T25) -> 0.0065173527 | AQ25: =($AP$1*AN25+$AQ$1*AO25) -> 762.54218 | AR25: =(D25+J25+O25)-(X25+AH25) -> -10
B26: =+B24+1 -> 46065 | C26: M | D26: 9072 | E26: 5.37 | F26: 8.52 | G26: =+D26*E26% -> 487.1664 | H26: =+D26*F26% -> 772.9344 | I26: 5669 | J26: 5669 | K26: 5.4099312 | L26: 8.5826601 | R26: =O26+J26 -> 5669 | S26: =(J26*K26%)+(O26*P26%) -> 306.689 | T26: =(J26*L26%)+(O26*Q26%) -> 486.551 | U26: 0 | V26: 0 | W26: 0 | X26: 0 | Y26: 0 | Z26: 0 | AA26: =X26*Y26% -> 0 | AB26: =X26*Z26% -> 0 | AF26: =AC26*AD26% -> 0 | AG26: =AC26*AE26% -> 0 | AH26: 14751 | AI26: 5.38 | AJ26: 8.54 | AK26: =AH26*AI26% -> 793.6038 | AL26: =AH26*AJ26% -> 1259.7354 | AM26: =+D26+R26-AC26-AH26 -> -10 | AN26: =+G26+S26-AF26-AK26 -> 0.2516 | AO26: =+H26+T26-AG26-AL26 -> -0.25 | AP26: =(AN26+AO26)/(S26+T26) -> 2.017044e-06 | AQ26: =($AP$1*AN26+$AQ$1*AO26) -> 37.096332 | AR26: =(D26+J26+O26)-(X26+AH26) -> -10
B27: =+B25+1 -> 46065 | C27: E | D27: 14751 | E27: 5.38 | F27: 8.54 | G27: =+D27*E27% -> 793.6038 | H27: =+D27*F27% -> 1259.7354 | I27: 6898 | J27: 6898 | K27: 5.133546 | L27: 8.4471731 | R27: =O27+J27 -> 6898 | S27: =(J27*K27%)+(O27*P27%) -> 354.112 | T27: =(J27*L27%)+(O27*Q27%) -> 582.686 | U27: 5280 | V27: 82010 | W27: Hajipur | X27: 18700 | Y27: 5.35 | Z27: 8.54 | AA27: =X27*Y27% -> 1000.45 | AB27: =X27*Z27% -> 1596.98 | AC27: 18730 | AD27: 5.3 | AE27: 8.34 | AF27: =AC27*AD27% -> 992.69 | AG27: =AC27*AE27% -> 1562.082 | AH27: 2959 | AI27: 5.3 | AJ27: 8.51 | AK27: =AH27*AI27% -> 156.827 | AL27: =AH27*AJ27% -> 251.8109 | AM27: =+D27+R27-AC27-AH27 -> -40 | AN27: =+G27+S27-AF27-AK27 -> -1.8012 | AO27: =+H27+T27-AG27-AL27 -> 28.5285 | AP27: =(AN27+AO27)/(S27+T27) -> 0.028530484 | AQ27: =($AP$1*AN27+$AQ$1*AO27) -> 7520.2185 | AR27: =(D27+J27+O27)-(X27+AH27) -> -10 | AS27: =SUM(AQ14:AQ27) -> 55366.887
