Workbook

Sheet Sheet3
A1: State | B1: Bihar
A2: Recovery Remark | B2: REcovery
A4: Sum of Total
A5: VLCC_Code | B5: Total | E5: VLCC_Code | F5: Total
A6: 10010038 | B6: 413 | E6: 10010038 | F6: 413
A7: 10020005 | B7: 1062 | E7: 10020005 | F7: 1062
A8: 10020023 | B8: 413 | E8: 10020023 | F8: 413
A9: 10020025 | B9: 165.2 | E9: 10020025 | F9: 165.2
A10: 10020026 | B10: 973.5 | E10: 10020026 | F10: 973.5
A11: 10020029 | B11: 165.2 | E11: 10020029 | F11: 165.2
A12: 10020042 | B12: 2454.4 | E12: 10020042 | F12: 2454.4
A13: 10020059 | B13: 2454.4 | E13: 10020059 | F13: 2454.4
A14: 10030003 | B14: 2336.4 | E14: 10030003 | F14: 2336.4
A15: 10030034 | B15: 165.2 | E15: 10030034 | F15: 165.2
A16: 10030059 | B16: 99.12 | E16: 10030059 | F16: 99.12
A17: 10060026 | B17: 2454.4 | E17: 10060026 | F17: 2454.4
... A70: 10480001 | B70: 2454.4 | E70: 10480001 | F70: 2454.4
A71: Grand Total | B71: 81051.84 | E71: Grand Total | F71: 81051.84

Sheet Sheet1
A2: Complaint_Datetime | B2: Month | C2: State | D2: Type | E2: VLCC_Code | F2: MPG Start Dste | G2: Ageing | H2: VLCC_Name | I2: BMC Name | J2: Contact_Person | K2: Contact_Person_No | L2: machine | M2: serial_no | N2: Replace Parts | O2: SAP Code | P2: Invoice No | Q2: Invoice Date | R2: Rate | S2: Basic | T2: GST | U2: Total | V2: Recoverable | W2: Remarks2 | X2: Recovery Remark
A3: 31-01-2026 15:41:26 | B3: =TEXT(A3,"mmm-yy") -> Jan-26 | C3: Bihar | D3: MPG | E3: 10130115 | F3: 46053 | G3: =+A3-F3 -> 0.65377315 | H3: GOMUKH MISROLIYA | J3: vinay kumar | K3: 7082651043 | L3: EKOMILK ULTRA PRO ANALYSER | M3: 277509 | N3: Ekomilk Sieringe With Plunger | O3: RM00530 | P3: AR2526E4580 | Q3: 46099 | R3: 70 | S3: 70 | T3: 12.6 | U3: 82.6 | V3: Running | W3: Running | X3: Yes
A4: 31-01-2026 15:41:26 | B4: =TEXT(A4,"mmm-yy") -> Jan-26 | C4: Bihar | D4: MPG | E4: 10130115 | F4: 46053 | G4: =+A4-F4 -> 0.65377315 | H4: GOMUKH MISROLIYA | J4: vinay kumar | K4: 7082651043 | L4: EKOMILK ULTRA PRO ANALYSER | M4: 277509 | N4: Ekomilk Sieringe With Plunger | O4: RM00530 | P4: AR2526E4580 | Q4: 46099 | R4: 70 | S4: 70 | T4: 12.6 | U4: 82.6 | V4: Running | W4: Running | X4: Yes
A5: 29-01-2026 17:26:08 | B5: =TEXT(A5,"mmm-yy") -> Jan-26 | C5: Bihar | D5: BMC | E5: 1013 | F5: =IF(D5="MPG",_xlfn.XLOOKUP(E5,Sheet2!$A$2:$A$2104,Sheet2!$B$2:$B$2104,""),"") | H5: musrigharai store | I5: Musrigharari | J5: prakash | K5: 9608956246 | L5: WEIGHING SCALE 60 KG | M5: E-17127304 | N5: EWS Battery Backup SMPS (BBLC) | O5: RM00241 | P5: AR2526E4580 | Q5: 46099 | R5: 825 | S5: 825 | T5: 148.5 | U5: 973.5 | V5: NA | W5: NA | X5: Yes
A6: 29-01-2026 17:26:08 | B6: =TEXT(A6,"mmm-yy") -> Jan-26 | C6: Bihar | D6: BMC | E6: 1013 | F6: =IF(D6="MPG",_xlfn.XLOOKUP(E6,Sheet2!$A$2:$A$2104,Sheet2!$B$2:$B$2104,""),"") | H6: musrigharai store | I6: Musrigharari | J6: prakash | K6: 9608956246 | L6: WEIGHING SCALE 60 KG | M6: E-17127304 | N6: Connector 5 Pin Metal M/F | O6: RM00727 | P6: AR2526E4580 | Q6: 46099 | R6: 225 | S6: 225 | T6: 40.5 | U6: 265.5 | V6: NA | W6: NA | X6: Yes
A7: 29-01-2026 16:40:42 | B7: =TEXT(A7,"mmm-yy") -> Jan-26 | C7: Bihar | D7: BMC | E7: 1013 | F7: =IF(D7="MPG",_xlfn.XLOOKUP(E7,Sheet2!$A$2:$A$2104,Sheet2!$B$2:$B$2104,""),"") | H7: musrigharai store | I7: Musrigharari | J7: prakash | K7: 9608956246 | L7: Everest Smart Tab-based Android Terminal (Table-top) with Inbuilt Printer | M7: GTD-23060367 | N7: DPU DC To DC Converter 12V To 5V | O7: RM00493 | P7: AR2526E4580 | Q7: 46099 | R7: 780 | S7: 780 | T7: 140.4 | U7: 920.4 | V7: NA | W7: NA | X7: Yes
A8: 29-01-2026 16:40:42 | B8: =TEXT(A8,"mmm-yy") -> Jan-26 | C8: Bihar | D8: BMC | E8: 1013 | F8: =IF(D8="MPG",_xlfn.XLOOKUP(E8,Sheet2!$A$2:$A$2104,Sheet2!$B$2:$B$2104,""),"") | H8: musrigharai store | I8: Musrigharari | J8: prakash | K8: 9608956246 | L8: Everest Smart Tab-based Android Terminal (Table-top) with Inbuilt Printer | M8: GTD-23060367 | N8: Battery 3.7V/2600Mah | O8: RM00980 | P8: AR2526E4580 | Q8: 46099 | R8: 350 | S8: 350 | T8: 63 | U8: 413 | V8: NA | W8: NA | X8: Yes
A9: 27-01-2026 14:29:49 | B9: =TEXT(A9,"mmm-yy") -> Jan-26 | C9: Bihar | D9: MPG | E9: 10120094 | F9: =IF(D9="MPG",_xlfn.XLOOKUP(E9,Sheet2!$A$2:$A$2104,Sheet2!$B$2:$B$2104,""),"") -> 45666 | G9: =+A9-F9 -> 383.60404 | H9: Gomukh Bochaha | I9: DalsinghSarai | J9: sopander ray | K9: 9939074043 | L9: WEIGHING SCALE 60 KG | M9: GE-19122123 | N9: Connector 5 Pin Metal M/F | O9: RM00727 | P9: AR2526E4580 | Q9: 46099 | R9: 225 | S9: 225 | T9: 40.5 | U9: 265.5 | V9: Running | W9: Running | X9: REcovery
A10: 27-01-2026 15:47:34 | B10: =TEXT(A10,"mmm-yy") -> Jan-26 | C10: Jharkhand | D10: MPG | E10: 20020004 | F10: =IF(D10="MPG",_xlfn.XLOOKUP(E10,Sheet2!$A$2:$A$2104,Sheet2!$B$2:$B$2104,""),"") | H10: Pandra | J10: Ravi Gop | K10: 6206527757 | L10: Everest Smart Tab-based Android Terminal (Table-top) with Inbuilt Printer | M10: GTD-23060338 | N10: Battery 3.7V/2600Mah | O10: RM00980 | P10: AR2526E4579 | Q10: 46099 | R10: 350 | S10: 350 | T10: 63 | U10: 413 | V10: Running | W10: Running | X10: Yes
A11: 24-01-2026 16:09:31 | B11: =TEXT(A11,"mmm-yy") -> Jan-26 | C11: Jharkhand | D11: MPG | E11: 2001 | F11: =IF(D11="MPG",_xlfn.XLOOKUP(E11,Sheet2!$A$2:$A$2104,Sheet2!$B$2:$B$2104,""),"") | H11: Itki | J11: Amit Tiwari | K11: 8210761749 | L11: Everest Smart Tab-based Android Terminal (Table-top) with Inbuilt Printer | M11: GTD-23060345 | N11: Battery 3.7V/2600Mah | O11: RM00980 | P11: AR2526E4579 | Q11: 46099 | R11: 350 | S11: 350 | T11: 63 | U11: 413 | V11: Running | W11: Running | X11: Yes
A12: 21-01-2026 13:53:34 | B12: =TEXT(A12,"mmm-yy") -> Jan-26 | C12: Bihar | D12: MPG | E12: 1050 | F12: =IF(D12="MPG",_xlfn.XLOOKUP(E12,Sheet2!$A$2:$A$2104,Sheet2!$B$2:$B$2104,""),"") | H12: aure | J12: Raushan Kumar | K12: 8877986410 | L12: EKOMILK ULTRA PRO ANALYSER | M12: 362915 | N12: Fatscan Motor Pump Pipe | O12: SF00147 | P12: AR2526E4580 | Q12: 46099 | R12: 125 | S12: 125 | T12: 22.5 | U12: 147.5 | V12: Running | W12: Running | X12: Yes
A13: 21-01-2026 13:53:34 | B13: =TEXT(A13,"mmm-yy") -> Jan-26 | C13: Bihar | D13: MPG | E13: 1050 | F13: =IF(D13="MPG",_xlfn.XLOOKUP(E13,Sheet2!$A$2:$A$2104,Sheet2!$B$2:$B$2104,""),"") | H13: aure | J13: Raushan Kumar | K13: 8877986410 | L13: EKOMILK ULTRA PRO ANALYSER | M13: 362915 | N13: Fatscan Motor Pump Pipe | O13: SF00147 | P13: AR2526E4580 | Q13: 46099 | R13: 125 | S13: 125 | T13: 22.5 | U13: 147.5 | V13: Running | W13: Running | X13: Yes
A14: 19-01-2026 16:00:35 | B14: =TEXT(A14,"mmm-yy") -> Jan-26 | C14: Bihar | D14: MPG | E14: 10120022 | F14: =IF(D14="MPG",_xlfn.XLOOKUP(E14,Sheet2!$A$2:$A$2104,Sheet2!$B$2:$B$2104,""),"") -> 44184 | G14: =+A14-F14 -> 1857.6671 | H14: Jounapur | I14: DalsinghSarai | J14: Lalan singh | K14: 9973808926 | L14: EKOMILK ULTRA PRO ANALYSER | M14: 322529 | N14: Ekomilk Keyboard | O14: RM00512 | P14: AR2526E4580 | Q14: 46099 | R14: 770 | S14: 770 | T14: 138.6 | U14: 908.6 | V14: Running | W14: Running | X14: REcovery
A15: 19-01-2026 10:30:18 | B15: =TEXT(A15,"mmm-yy") -> Jan-26 | C15: Bihar | D15: MPG | E15: 10130001 | F15: =IF(D15="MPG",_xlfn.XLOOKUP(E15,Sheet2!$A$2:$A$2104,Sheet2!$B$2:$B$2104,""),"") -> 43622 | G15: =+A15-F15 -> 2419.4377 | H15: kishanpur | J15: surendu bhaskar | K15: 9504393173 | L15: WEIGHING SCALE 60 KG | M15: E-17116790 | N15: Keyboard For Weighing Scale (Repaired) | O15: SF00048 | P15: AR2526E4580 | Q15: 46099 | R15: 360 | S15: 360 | T15: 64.8 | U15: 424.8 | V15: Running | W15: Running | X15: REcovery
A16: 19-01-2026 15:55:34 | B16: =TEXT(A16,"mmm-yy") -> Jan-26 | C16: Bihar | D16: MPG | E16: 10030080 | F16: =IF(D16="MPG",_xlfn.XLOOKUP(E16,Sheet2!$A$2:$A$2104,Sheet2!$B$2:$B$2104,""),"") -> 45987 | G16: =+A16-F16 -> 54.663588 | H16: pahlampur | J16: bhavesh kumar | K16: 9546351286 | L16: STIRRER UNIT EV5600 | M16: GS-23104583 | N16: Stirrer Timer PCB | O16: RM00478 | P16: AR2526E4580 | Q16: 46099 | R16: 900 | S16: 900 | T16: 162 | U16: 1062 | V16: Running | W16: Running | X16: Yes
A17: 17-01-2026 14:32:26 | B17: =TEXT(A17,"mmm-yy") -> Jan-26 | C17: Bihar | D17: MPG | E17: 10060049 | F17: =IF(D17="MPG",_xlfn.XLOOKUP(E17,Sheet2!$A$2:$A$2104,Sheet2!$B$2:$B$2104,""),"") -> 45267 | G17: =+A17-F17 -> 772.60586 | H17: maliya | I17: Sonvarsha | J17: Ram bachan yadav | K17: 9693036091 | L17: EKOMILK ULTRA PRO ANALYSER | M17: SN/E00384723 | N17: Fatscan Sensor to Syringe Pipe | O17: SF00146 | P17: AR2526E4580 | Q17: 46099 | R17: 44 | S17: 44 | T17: 7.92 | U17: 51.92 | V17: Running | W17: Running | X17: REcovery
A18: 17-01-2026 14:32:26 | B18: =TEXT(A18,"mmm-yy") -> Jan-26 | C18: Bihar | D18: MPG | E18: 10060049 | F18: =IF(D18="MPG",_xlfn.XLOOKUP(E18,Sheet2!$A$2:$A$2104,Sheet2!$B$2:$B$2104,""),"") -> 45267 | G18: =+A18-F18 -> 772.60586 | H18: maliya | I18: Sonvarsha | J18: Ram bachan yadav | K18: 9693036091 | L18: EKOMILK ULTRA PRO ANALYSER | M18: SN/E00384723 | N18: Fatscan Sensor to Syringe Pipe | O18: SF00146 | P18: AR2526E4580 | Q18: 46099 | R18: 44 | S18: 44 | T18: 7.92 | U18: 51.92 | V18: Running | W18: Running | X18: REcovery
A19: 17-01-2026 14:01:41 | B19: =TEXT(A19,"mmm-yy") -> Jan-26 | C19: Bihar | D19: MPG | E19: 10130077 | F19: =IF(D19="MPG",_xlfn.XLOOKUP(E19,Sheet2!$A$2:$A$2104,Sheet2!$B$2:$B$2104,""),"") -> 45631 | G19: =+A19-F19 -> 408.5845 | H19: Gomukh Akaha | J19: chandan | K19: 9891852345 | L19: STIRRER UNIT EV5600 | M19: s-17095698 | N19: Stirrer Timer PCB | O19: RM00478 | P19: AR2526E4580 | Q19: 46099 | R19: 900 | S19: 900 | T19: 162 | U19: 1062 | V19: Running | W19: Running | X19: REcovery
A20: 16-01-2026 16:18:19 | B20: =TEXT(A20,"mmm-yy") -> Jan-26 | C20: Bihar | D20: MPG | E20: 10120029 | F20: =IF(D20="MPG",_xlfn.XLOOKUP(E20,Sheet2!$A$2:$A$2104,Sheet2!$B$2:$B$2104,""),"") -> 44729 | G20: =+A20-F20 -> 1309.6794 | H20: Ramanath pur | I20: DalsinghSarai | J20: Birjnandan thakur | K20: 9304265355 | L20: WEIGHING SCALE 60 KG | M20: GNE-22102070 | N20: Connector 5 Pin Metal M/F | O20: RM00727 | P20: AR2526E4580 | Q20: 46099 | R20: 225 | S20: 225 | T20: 40.5 | U20: 265.5 | V20: Running | W20: Running | X20: REcovery
A21: 13-01-2026 13:36:23 | B21: =TEXT(A21,"mmm-yy") -> Jan-26 | C21: Jharkhand | D21: MPG | E21: 20010017 | F21: =IF(D21="MPG",_xlfn.XLOOKUP(E21,Sheet2!$A$2:$A$2104,Sheet2!$B$2:$B$2104,""),"") | H21: Dighiya | J21: Sohel Ansari | K21: 8709453609 | L21: EKOMILK ULTRA PRO ANALYSER | M21: 390572 | N21: Ekomilk Sieringe With Plunger | O21: RM00530 | P21: AR2526E4579 | Q21: 46099 | R21: 70 | S21: 70 | T21: 12.6 | U21: 82.6 | V21: Running | W21: Running | X21: Yes
A22: 12-01-2026 16:50:04 | B22: =TEXT(A22,"mmm-yy") -> Jan-26 | C22: Bihar | D22: MPG | E22: 10120089 | F22: =IF(D22="MPG",_xlfn.XLOOKUP(E22,Sheet2!$A$2:$A$2104,Sheet2!$B$2:$B$2104,""),"") -> 45649 | G22: =+A22-F22 -> 385.70144 | H22: jhaura tabhak | I22: DalsinghSarai | J22: Adita Kumar | K22: 8340433254 | L22: EKOMILK ULTRA PRO ANALYSER | M22: 310512 | N22: Fatscan " Y " Pipe | O22: SF00145 | P22: AR2526E4580 | Q22: 46099 | R22: 84 | S22: 84 | T22: 15.12 | U22: 99.12 | V22: Running | W22: Running | X22: REcovery
A23: 12-01-2026 16:50:04 | B23: =TEXT(A23,"mmm-yy") -> Jan-26 | C23: Bihar | D23: MPG | E23: 10120089 | F23: =IF(D23="MPG",_xlfn.XLOOKUP(E23,Sheet2!$A$2:$A$2104,Sheet2!$B$2:$B$2104,""),"") -> 45649 | G23: =+A23-F23 -> 385.70144 | H23: jhaura tabhak | I23: DalsinghSarai | J23: Adita Kumar | K23: 8340433254 | L23: EKOMILK ULTRA PRO ANALYSER | M23: 310512 | N23: Ekomilk Air Bubble | O23: RM00509 | P23: AR2526E4580 | Q23: 46099 | R23: 62 | S23: 62 | T23: 11.16 | U23: 73.16 | V23: Running | W23: Running | X23: REcovery
A24: 12-01-2026 10:37:50 | B24: =TEXT(A24,"mmm-yy") -> Jan-26 | C24: Bihar | D24: MPG | E24: 10020026 | F24: =IF(D24="MPG",_xlfn.XLOOKUP(E24,Sheet2!$A$2:$A$2104,Sheet2!$B$2:$B$2104,""),"") -> 44866 | G24: =+A24-F24 -> 1168.4429 | H24: jakhaur | J24: Niraj Singh | K24: 6202734219 | L24: WEIGHING SCALE 60 KG | M24: E-17116788 | N24: EWS Battery Backup SMPS (BBLC) | O24: RM00241 | P24: AR2526E4580 | Q24: 46099 | R24: 825 | S24: 825 | T24: 148.5 | U24: 973.5 | V24: Running | W24: Running | X24: REcovery
A25: 07-01-2026 16:22:20 | B25: =TEXT(A25,"mmm-yy") -> Jan-26 | C25: Bihar | D25: MPG | E25: 10120001 | F25: =IF(D25="MPG",_xlfn.XLOOKUP(E25,Sheet2!$A$2:$A$2104,Sheet2!$B$2:$B$2104,""),"") -> 43622 | G25: =+A25-F25 -> 2407.6822 | H25: Subhanipur | J25: Anik kumar | K25: 7545865422 | L25: STIRRER UNIT EV5600 | M25: S-17106422 | N25: Stirrer Timer PCB | O25: RM00478 | P25: AR2526E4580 | Q25: 46099 | R25: 900 | S25: 900 | T25: 162 | U25: 1062 | V25: Running | W25: Running | X25: REcovery
A26: 07-01-2026 17:16:52 | B26: =TEXT(A26,"mmm-yy") -> Jan-26 | C26: Bihar | D26: BMC | E26: 005 | F26: =IF(D26="MPG",_xlfn.XLOOKUP(E26,Sheet2!$A$2:$A$2104,Sheet2!$B$2:$B$2104,""),"") | H26: BMC asarganj | J26: Dheeraj Kumar | K26: 6201859567 | L26: EKOMILK ULTRA PRO ANALYSER | M26: 183572 | N26: Ekomilk Transformer | O26: RM00508 | P26: AR2526E4580 | Q26: 46099 | R26: 2850 | S26: 2850 | T26: 513 | U26: 3363 | V26: NA | W26: NA | X26: Yes
A27: 07-01-2026 16:29:42 | B27: =TEXT(A27,"mmm-yy") -> Jan-26 | C27: Bihar | D27: MPG | E27: 10120121 | F27: =IF(D27="MPG",_xlfn.XLOOKUP(E27,Sheet2!$A$2:$A$2104,Sheet2!$B$2:$B$2104,""),"") -> 46029 | G27: =+A27-F27 -> 0.68729167 | H27: GOMUKH BANGHARA | I27: DalsinghSarai | J27: DHARAMVIR | K27: 9004074976 | L27: WEIGHING SCALE 60 KG | M27: e-17127306 | N27: EWS Battery Backup SMPS (BBLC) | O27: RM00241 | P27: AR2526E4580 | Q27: 46099 | R27: 825 | S27: 825 | T27: 148.5 | U27: 973.5 | V27: Running | W27: Running | X27: Yes
A28: 07-01-2026 21:25:50 | B28: =TEXT(A28,"mmm-yy") -> Jan-26 | C28: Bihar | D28: MPG | E28: 10110140 | F28: =IF(D28="MPG",_xlfn.XLOOKUP(E28,Sheet2!$A$2:$A$2104,Sheet2!$B$2:$B$2104,""),"") -> 45786 | G28: =+A28-F28 -> 243.89294 | H28: GAMHARIYA | J28: BHUSAN KUMAR | K28: 9570352603 | L28: EKOMILK ULTRA PRO ANALYSER | M28: 277504 | N28: Ekomilk Sieringe With Plunger | O28: RM00530 | P28: AR2526E4580 | Q28: 46099 | R28: 70 | S28: 70 | T28: 12.6 | U28: 82.6 | V28: Status not confirmed | W28: Status not confirmed
A29: 05-01-2026 17:13:45 | B29: =TEXT(A29,"mmm-yy") -> Jan-26 | C29: Bihar | D29: MPG | E29: 10030034 | F29: =IF(D29="MPG",_xlfn.XLOOKUP(E29,Sheet2!$A$2:$A$2104,Sheet2!$B$2:$B$2104,""),"") -> 45082 | G29: =+A29-F29 -> 945.71788 | H29: gomukh Muskipur | J29: Bablu yadav | K29: 7050069650 | L29: EKOMILK ULTRA PRO ANALYSER | M29: 388118 | N29: Ekomilk Sieringe With Plunger | O29: RM00530 | P29: AR2526E4580 | Q29: 46099 | R29: 70 | S29: 70 | T29: 12.6 | U29: 82.6 | V29: Running | W29: Running | X29: REcovery
A30: 05-01-2026 17:13:45 | B30: =TEXT(A30,"mmm-yy") -> Jan-26 | C30: Bihar | D30: MPG | E30: 10030034 | F30: =IF(D30="MPG",_xlfn.XLOOKUP(E30,Sheet2!$A$2:$A$2104,Sheet2!$B$2:$B$2104,""),"") -> 45082 | G30: =+A30-F30 -> 945.71788 | H30: gomukh Muskipur | J30: Bablu yadav | K30: 7050069650 | L30: EKOMILK ULTRA PRO ANALYSER | M30: 388118 | N30: Ekomilk Sieringe With Plunger | O30: RM00530 | P30: AR2526E4580 | Q30: 46099 | R30: 70 | S30: 70 | T30: 12.6 | U30: 82.6 | V30: Running | W30: Running | X30: REcovery
A31: 05-01-2026 16:00:45 | B31: =TEXT(A31,"mmm-yy") -> Jan-26 | C31: Bihar | D31: MPG | E31: 10120012 | F31: =IF(D31="MPG",_xlfn.XLOOKUP(E31,Sheet2!$A$2:$A$2104,Sheet2!$B$2:$B$2104,""),"") -> 43924 | G31: =+A31-F31 -> 2103.6672 | H31: Satogachi | I31: DalsinghSarai | J31: Mithun Kumar | K31: 8651295402 | L31: WEIGHING SCALE 60 KG | M31: E-17127228 | N31: Connector 5 Pin Metal M/F | O31: RM00727 | P31: AR2526E4580 | Q31: 46099 | R31: 225 | S31: 225 | T31: 40.5 | U31: 265.5 | V31: Running | W31: Running | X31: REcovery
A32: 05-01-2026 16:00:45 | B32: =TEXT(A32,"mmm-yy") -> Jan-26 | C32: Bihar | D32: MPG | E32: 10120012 | F32: =IF(D32="MPG",_xlfn.XLOOKUP(E32,Sheet2!$A$2:$A$2104,Sheet2!$B$2:$B$2104,""),"") -> 43924 | G32: =+A32-F32 -> 2103.6672 | H32: Satogachi | I32: DalsinghSarai | J32: Mithun Kumar | K32: 8651295402 | L32: WEIGHING SCALE 60 KG | M32: E-17127228 | N32: EWS Battery Backup SMPS (BBLC) | O32: RM00241 | P32: AR2526E4580 | Q32: 46099 | R32: 825 | S32: 825 | T32: 148.5 | U32: 973.5 | V32: Running | W32: Running | X32: REcovery
A33: 05-01-2026 16:05:54 | B33: =TEXT(A33,"mmm-yy") -> Jan-26 | C33: Jharkhand | D33: MPG | E33: 20020002 | F33: =IF(D33="MPG",_xlfn.XLOOKUP(E33,Sheet2!$A$2:$A$2104,Sheet2!$B$2:$B$2104,""),"") | H33: Jaadi | J33: shushila devi | K33: 7061476343 | L33: Everest Smart Tab-based Android Terminal (Table-top) with Inbuilt Printer | M33: GTD-23060341 | N33: Battery 3.7V/2600Mah | O33: RM00980 | P33: AR2526E4579 | Q33: 46099 | R33: 350 | S33: 350 | T33: 63 | U33: 413 | V33: Running | W33: Running | X33: Yes
A34: 05-01-2026 16:03:28 | B34: =TEXT(A34,"mmm-yy") -> Jan-26 | C34: Bihar | D34: MPG | E34: 10120114 | F34: =IF(D34="MPG",_xlfn.XLOOKUP(E34,Sheet2!$A$2:$A$2104,Sheet2!$B$2:$B$2104,""),"") -> 45939 | G34: =+A34-F34 -> 88.669074 | H34: GOMUKH PATHAKTOL | I34: DalsinghSarai | J34: chandan | K34: 9631389655 | L34: Everest Smart Tab-based Android Terminal (Table-top) with Inbuilt Printer | M34: GTD-23060369 | N34: DPU Thermal Printer EPM 207 | O34: RM00282 | P34: AR2526E4580 | Q34: 46099 | R34: 2800 | S34: 2800 | T34: 504 | U34: 3304 | V34: Running | W34: Running | X34: Yes
A35: 05-01-2026 16:10:29 | B35: =TEXT(A35,"mmm-yy") -> Jan-26 | C35: Bihar | D35: MPG | E35: 10120006 | F35: =IF(D35="MPG",_xlfn.XLOOKUP(E35,Sheet2!$A$2:$A$2104,Sheet2!$B$2:$B$2104,""),"") -> 43731 | G35: =+A35-F35 -> 2296.6739 | H35: Khajuri | I35: DalsinghSarai | J35: Anuj Kumar Singh | K35: 7033197978 | L35: WEIGHING SCALE 60 KG | M35: E-17127324 | N35: Keyboard For Weighing Scale (Repaired) | O35: SF00048 | P35: AR2526E4580 | Q35: 46099 | R35: 360 | S35: 360 | T35: 64.8 | U35: 424.8 | V35: Running | W35: Running | X35: REcovery
A36: 03-01-2026 16:10:54 | B36: =TEXT(A36,"mmm-yy") -> Jan-26 | C36: Bihar | D36: BMC | E36: 1054 | F36: =IF(D36="MPG",_xlfn.XLOOKUP(E36,Sheet2!$A$2:$A$2104,Sheet2!$B$2:$B$2104,""),"") | H36: ALAULI BMC | J36: AMIT KUMAR | K36: 9155273222 | L36: Everest Smart Tab-based Android Terminal (Table-top) with Inbuilt Printer | M36: GTD-23111293 | N36: WI-FI SERIAL DEVICE WITH EXTERNAL POWER SUPPLY (WI-SENSE) | O36: SF00082 | P36: AR2526E4580 | Q36: 46099 | R36: 925 | S36: 925 | T36: 166.5 | U36: 1091.5 | V36: NA | W36: NA | X36: Yes
A37: 28-02-2026 11:13:12 | B37: =TEXT(A37,"mmm-yy") -> Feb-26 | C37: Jharkhand | D37: MPG | E37: 20010016 | F37: =IF(D37="MPG",_xlfn.XLOOKUP(E37,Sheet2!$A$2:$A$2104,Sheet2!$B$2:$B$2104,""),"") | H37: Etachildri | J37: Sanju devi | K37: 9263601995 | L37: Everest Smart Tab-based Android Terminal (Table-top) with Inbuilt Printer | M37: GTD-23060317 | N37: Battery 3.7V/2600Mah | O37: RM00980 | P37: AR2526E5034 | Q37: 46109 | R37: 350 | S37: 350 | T37: 63 | U37: 413 | V37: Running | W37: Running | X37: Yes
A38: 27-02-2026 20:07:06 | B38: =TEXT(A38,"mmm-yy") -> Feb-26 | C38: Bihar | D38: MPG | E38: 10110099 | F38: =IF(D38="MPG",_xlfn.XLOOKUP(E38,Sheet2!$A$2:$A$2104,Sheet2!$B$2:$B$2104,""),"") -> 45653 | G38: =+A38-F38 -> 427.83826 | H38: Gomukh Icharua | J38: Ram Ratan Prasad | K38: 8678086831 | L38: WEIGHING SCALE 60 KG | M38: GNE-23114076 | N38: SWS Motherboard (Version 1.1) | O38: RM00973 | P38: AR2526E5065 | Q38: 46109 | R38: 2080 | S38: 2080 | T38: 374.4 | U38: 2454.4 | V38: Status not confirmed | W38: Status not confirmed
A39: 27-02-2026 18:27:19 | B39: =TEXT(A39,"mmm-yy") -> Feb-26 | C39: Bihar | D39: MPG | E39: 10080086 | F39: =IF(D39="MPG",_xlfn.XLOOKUP(E39,Sheet2!$A$2:$A$2104,Sheet2!$B$2:$B$2104,""),"") -> 45716 | G39: =+A39-F39 -> 364.76897 | H39: gomukh fateha salempur | J39: Ramesh kumar | K39: 7631461027 | L39: STIRRER UNIT EV5600 | M39: GS-23033782 | N39: Stirrer Timer PCB | O39: RM00478 | P39: AR2526E5065 | Q39: 46109 | R39: 900 | S39: 900 | T39: 162 | U39: 1062 | V39: Running | W39: Running | X39: Yes
A40: 27-02-2026 18:27:19 | B40: =TEXT(A40,"mmm-yy") -> Feb-26 | C40: Bihar | D40: MPG | E40: 10080086 | F40: =IF(D40="MPG",_xlfn.XLOOKUP(E40,Sheet2!$A$2:$A$2104,Sheet2!$B$2:$B$2104,""),"") -> 45716 | G40: =+A40-F40 -> 364.76897 | H40: gomukh fateha salempur | J40: Ramesh kumar | K40: 7631461027 | L40: STIRRER UNIT EV5600 | M40: GS-23033782 | N40: Stirrer Power Board | O40: RM00477 | P40: AR2526E5065 | Q40: 46109 | R40: 1750 | S40: 1750 | T40: 315 | U40: 2065 | V40: Running | W40: Running | X40: Yes
A41: 27-02-2026 17:21:16 | B41: =TEXT(A41,"mmm-yy") -> Feb-26 | C41: Bihar | D41: MPG | E41: 10010142 | F41: 46080 | G41: =+A41-F41 -> 0.72310185 | H41: Mahida sahpur | J41: Aaryan kumar | K41: 8271775736 | L41: WEIGHING SCALE 60 KG | M41: GNE-23024408 | N41: Keyboard For Weighing Scale New Design | O41: RM01176 | P41: AR2526E5065 | Q41: 46109 | R41: 1266 | S41: 1266 | T41: 227.88 | U41: 1493.88 | V41: Status not confirmed | W41: Status not confirmed
...

Sheet Sheet2
A1: New Code | B1: Start Date
A2: 10520001 | B2: 43388
A3: 10520002 | B3: 43736
A4: 10520003 | B4: 45050
A5: 10520004 | B5: 45197
A6: 10520005 | B6: 45681
A7: 10520008 | B7: 45766
A8: 10520007 | B8: 45768
A9: 10520009 | B9: 45831
A10: 10520012 | B10: 46199
A11: 10520014 | B11: 46235
A12: 10110141 | B12: 45786
A13: 10110140 | B13: 45786
... A2104: 10570073 | B2104: 46233
