Workbook
Name Account_Details: #REF!
Name Amount: #REF!
Name CF_Recovery: #REF!
Name Code: #REF!
Name FAT_Range: #REF!
Name Net_Amount: #REF!
Name Other_Ded: #REF!
Name Rate_Chart_Kaimur: #REF!
Name Sample_Milk: #REF!
Name SNF_Range: #REF!
Name Vol_L: #REF!

Sheet MPG Payment
A2: BMC Code | B2: MCC Name | C2: Code | D2: Old Code | E2: MPG NAME | F2: Type | G2: Farmer Payment | H2: BMC Volume | I2: BMC Amount | J2: Payable | K2: Vet Deduction | L2: CF Deduction | M2: Can | N2: Advance | O2: Payable to MPG | P2: Hold Amount | Q2: Final Payment | R2: Stop Payment | S2: Hold Reason | T2: Cycle | V2: Sahayak Comm @ 1.75% | W2: Retain Comm @ 0.25% | X2: Payable Commission | Y2: Other Deduction | Z2: Net payable | AB2: beneficiary_name | AC2: bank_account_no | AD2: IFSC | AE2: u | AF2: am | AG2: Diff | AK2: Opening Can Balance
A3: 1062 | B3: Ramgarh | C3: 10620002 | D3: =VLOOKUP(C3,DSC_Master!$C$1:D101,2,0) -> 64592 | E3: =VLOOKUP(C3,DSC_Master!$C$1:$K$201,4,0) -> UDHAPURA DSK | F3: MPG | G3: Indirect | H3: 464 | I3: 20166.57 | J3: =I3 -> 20166.57 | M3: =IF(AK3>0,MAX(IF(AK3>0,J3*2%),300),0) -> 0 | O3: =J3-SUM(K3:N3) -> 20166.57 | P3: =IF(R3="Yes",O3,0) -> 0 | Q3: =O3-P3 -> 20166.57 | R3: 0 | T3: {=SUBSTITUTE(SUBSTITUTE(MID(CELL("filename"),FIND("[",CELL("filename"))+1,FIND("]",CELL("filename"))-FIND("[",CELL("filename"))-1),"Farmer Payment-",""),".xlsb","")} -> Ramgarh Kaimur_Farmer Payment_28-03 Aug.xlsx | V3: =I3*1.75% -> 352.91498 | W3: =I3*0.25% -> 50.416426 | X3: =V3-W3 -> 302.49855 | Y3: 0 | Z3: =X3-Y3 -> 302.49855 | AB3: =VLOOKUP(C3,DSC_Master!$C$1:$K$201,9,0) -> BAL GOPAL YADAV | AC3: =VLOOKUP(C3,DSC_Master!$C$1:$J$202,8,0) -> 37483995547 | AD3: =VLOOKUP(C3,DSC_Master!$C$1:$J$202,7,0) -> SBIN0000076 | AF3: 20168.36 | AG3: =Q3-AF3 -> -1.789793 | AK3: =IFERROR(VLOOKUP(D3,'Milk Can'!D:U,18,0),0) -> 0
A4: 1062 | B4: Ramgarh | C4: 10620004 | D4: =VLOOKUP(C4,DSC_Master!$C$1:D102,2,0) -> 64600 | E4: =VLOOKUP(C4,DSC_Master!$C$1:$K$201,4,0) -> BHAMBHHOR DSK | F4: MPG | G4: Indirect | H4: 767 | I4: 32671.052 | J4: =I4 -> 32671.052 | M4: =IF(AK4>0,MAX(IF(AK4>0,J4*2%),300),0) -> 653.42105 | O4: =J4-SUM(K4:N4) -> 32017.631 | P4: =IF(R4="Yes",O4,0) -> 0 | Q4: =O4-P4 -> 32017.631 | R4: 0 | T4: {=SUBSTITUTE(SUBSTITUTE(MID(CELL("filename"),FIND("[",CELL("filename"))+1,FIND("]",CELL("filename"))-FIND("[",CELL("filename"))-1),"Farmer Payment-",""),".xlsb","")} -> Ramgarh Kaimur_Farmer Payment_28-03 Aug.xlsx | V4: =I4*1.75% -> 571.74342 | W4: =I4*0.25% -> 81.677631 | X4: =V4-W4 -> 490.06579 | Y4: 0 | Z4: =X4-Y4 -> 490.06579 | AB4: =VLOOKUP(C4,DSC_Master!$C$1:$K$201,9,0) -> DEEPAK KUMAR YADAV | AC4: =VLOOKUP(C4,DSC_Master!$C$1:$J$202,8,0) -> 924010010956816 | AD4: =VLOOKUP(C4,DSC_Master!$C$1:$J$202,7,0) -> UTIB0001632 | AF4: 32672.54 | AG4: =Q4-AF4 -> -654.90862 | AK4: =IFERROR(VLOOKUP(D4,'Milk Can'!D:U,18,0),0) -> 2895.1583
A5: 1062 | B5: Ramgarh | C5: 10620005 | D5: =VLOOKUP(C5,DSC_Master!$C$1:D103,2,0) -> 64505 | E5: =VLOOKUP(C5,DSC_Master!$C$1:$K$201,4,0) -> MAHUWARIYA DSK | F5: MPG | G5: Indirect | H5: 548 | I5: 32729.775 | J5: =I5 -> 32729.775 | M5: =IF(AK5>0,MAX(IF(AK5>0,J5*2%),300),0) -> 0 | O5: =J5-SUM(K5:N5) -> 32729.775 | P5: =IF(R5="Yes",O5,0) -> 0 | Q5: =O5-P5 -> 32729.775 | R5: 0 | T5: {=SUBSTITUTE(SUBSTITUTE(MID(CELL("filename"),FIND("[",CELL("filename"))+1,FIND("]",CELL("filename"))-FIND("[",CELL("filename"))-1),"Farmer Payment-",""),".xlsb","")} -> Ramgarh Kaimur_Farmer Payment_28-03 Aug.xlsx | V5: =I5*1.75% -> 572.77105 | W5: =I5*0.25% -> 81.824436 | X5: =V5-W5 -> 490.94662 | Y5: 0 | Z5: =X5-Y5 -> 490.94662 | AB5: =VLOOKUP(C5,DSC_Master!$C$1:$K$201,9,0) -> DINESH KUMAR | AC5: =VLOOKUP(C5,DSC_Master!$C$1:$J$202,8,0) -> 20315506501 | AD5: =VLOOKUP(C5,DSC_Master!$C$1:$J$202,7,0) -> SBIN0014328 | AF5: 32730.76 | AG5: =Q5-AF5 -> -0.9854856 | AK5: =IFERROR(VLOOKUP(D5,'Milk Can'!D:U,18,0),0) -> 0
A6: 1062 | B6: Ramgarh | C6: 10620008 | D6: =VLOOKUP(C6,DSC_Master!$C$1:D104,2,0) -> 64544 | E6: =VLOOKUP(C6,DSC_Master!$C$1:$K$201,4,0) -> ASHUDHA DSK | F6: MPG | G6: Indirect | H6: 361 | I6: 19264.285 | J6: =I6 -> 19264.285 | M6: =IF(AK6>0,MAX(IF(AK6>0,J6*2%),300),0) -> 0 | O6: =J6-SUM(K6:N6) -> 19264.285 | P6: =IF(R6="Yes",O6,0) -> 0 | Q6: =O6-P6 -> 19264.285 | R6: 0 | T6: {=SUBSTITUTE(SUBSTITUTE(MID(CELL("filename"),FIND("[",CELL("filename"))+1,FIND("]",CELL("filename"))-FIND("[",CELL("filename"))-1),"Farmer Payment-",""),".xlsb","")} -> Ramgarh Kaimur_Farmer Payment_28-03 Aug.xlsx | V6: =I6*1.75% -> 337.12499 | W6: =I6*0.25% -> 48.160713 | X6: =V6-W6 -> 288.96428 | Y6: 0 | Z6: =X6-Y6 -> 288.96428 | AB6: =VLOOKUP(C6,DSC_Master!$C$1:$K$201,9,0) -> KAMLESH SINGH | AC6: =VLOOKUP(C6,DSC_Master!$C$1:$J$202,8,0) -> 20100077569381 | AD6: =VLOOKUP(C6,DSC_Master!$C$1:$J$202,7,0) -> BDBL0001544 | AF6: 19264.87 | AG6: =Q6-AF6 -> -0.585 | AK6: =IFERROR(VLOOKUP(D6,'Milk Can'!D:U,18,0),0) -> 0
A7: 1062 | B7: Ramgarh | C7: 10620009 | D7: =VLOOKUP(C7,DSC_Master!$C$1:D105,2,0) -> 64571 | E7: =VLOOKUP(C7,DSC_Master!$C$1:$K$201,4,0) -> JAVRI DSK | F7: MPG | G7: Indirect | H7: 819 | I7: 37592.412 | J7: =I7 -> 37592.412 | M7: =IF(AK7>0,MAX(IF(AK7>0,J7*2%),300),0) -> 0 | O7: =J7-SUM(K7:N7) -> 37592.412 | P7: =IF(R7="Yes",O7,0) -> 0 | Q7: =O7-P7 -> 37592.412 | R7: 0 | T7: {=SUBSTITUTE(SUBSTITUTE(MID(CELL("filename"),FIND("[",CELL("filename"))+1,FIND("]",CELL("filename"))-FIND("[",CELL("filename"))-1),"Farmer Payment-",""),".xlsb","")} -> Ramgarh Kaimur_Farmer Payment_28-03 Aug.xlsx | V7: =I7*1.75% -> 657.8672 | W7: =I7*0.25% -> 93.981029 | X7: =V7-W7 -> 563.88618 | Y7: 0 | Z7: =X7-Y7 -> 563.88618 | AB7: =VLOOKUP(C7,DSC_Master!$C$1:$K$201,9,0) -> KANHAIYA YADAV | AC7: =VLOOKUP(C7,DSC_Master!$C$1:$J$202,8,0) -> 42108869535 | AD7: =VLOOKUP(C7,DSC_Master!$C$1:$J$202,7,0) -> SBIN0014328 | AF7: 37593.96 | AG7: =Q7-AF7 -> -1.5483109 | AK7: =IFERROR(VLOOKUP(D7,'Milk Can'!D:U,18,0),0) -> 0
A8: 1062 | B8: Ramgarh | C8: 10620010 | D8: =VLOOKUP(C8,DSC_Master!$C$1:D106,2,0) -> 64508 | E8: =VLOOKUP(C8,DSC_Master!$C$1:$K$201,4,0) -> LARMA DSK | F8: MPG | G8: Indirect | H8: 405 | I8: 22184.014 | J8: =I8 -> 22184.014 | M8: =IF(AK8>0,MAX(IF(AK8>0,J8*2%),300),0) -> 0 | O8: =J8-SUM(K8:N8) -> 22184.014 | P8: =IF(R8="Yes",O8,0) -> 0 | Q8: =O8-P8 -> 22184.014 | R8: 0 | T8: {=SUBSTITUTE(SUBSTITUTE(MID(CELL("filename"),FIND("[",CELL("filename"))+1,FIND("]",CELL("filename"))-FIND("[",CELL("filename"))-1),"Farmer Payment-",""),".xlsb","")} -> Ramgarh Kaimur_Farmer Payment_28-03 Aug.xlsx | V8: =I8*1.75% -> 388.22024 | W8: =I8*0.25% -> 55.460034 | X8: =V8-W8 -> 332.76021 | Y8: 0 | Z8: =X8-Y8 -> 332.76021 | AB8: =VLOOKUP(C8,DSC_Master!$C$1:$K$201,9,0) -> KHUSHABU YADAV | AC8: =VLOOKUP(C8,DSC_Master!$C$1:$J$202,8,0) -> 2367000100137224 | AD8: =VLOOKUP(C8,DSC_Master!$C$1:$J$202,7,0) -> PUNB0236700 | AF8: 22184.89 | AG8: =Q8-AF8 -> -0.8763055 | AK8: =IFERROR(VLOOKUP(D8,'Milk Can'!D:U,18,0),0) -> 0
A9: 1062 | B9: Ramgarh | C9: 10620012 | D9: =VLOOKUP(C9,DSC_Master!$C$1:D107,2,0) -> 64515 | E9: =VLOOKUP(C9,DSC_Master!$C$1:$K$201,4,0) -> DHARHARA DSK | F9: MPG | G9: Indirect | H9: 679 | I9: 32742.796 | J9: =I9 -> 32742.796 | M9: =IF(AK9>0,MAX(IF(AK9>0,J9*2%),300),0) -> 0 | O9: =J9-SUM(K9:N9) -> 32742.796 | P9: =IF(R9="Yes",O9,0) -> 0 | Q9: =O9-P9 -> 32742.796 | R9: 0 | T9: {=SUBSTITUTE(SUBSTITUTE(MID(CELL("filename"),FIND("[",CELL("filename"))+1,FIND("]",CELL("filename"))-FIND("[",CELL("filename"))-1),"Farmer Payment-",""),".xlsb","")} -> Ramgarh Kaimur_Farmer Payment_28-03 Aug.xlsx | V9: =I9*1.75% -> 572.99892 | W9: =I9*0.25% -> 81.856989 | X9: =V9-W9 -> 491.14194 | Y9: 0 | Z9: =X9-Y9 -> 491.14194 | AB9: =VLOOKUP(C9,DSC_Master!$C$1:$K$201,9,0) -> SHREE NIWAS YADAV | AC9: =VLOOKUP(C9,DSC_Master!$C$1:$J$202,8,0) -> 37905177514 | AD9: =VLOOKUP(C9,DSC_Master!$C$1:$J$202,7,0) -> SBIN0006137 | AF9: 32743.12 | AG9: =Q9-AF9 -> -0.3242995 | AK9: =IFERROR(VLOOKUP(D9,'Milk Can'!D:U,18,0),0) -> 0
A10: 1062 | B10: Ramgarh | C10: 10620013 | D10: =VLOOKUP(C10,DSC_Master!$C$1:D108,2,0) -> 64523 | E10: =VLOOKUP(C10,DSC_Master!$C$1:$K$201,4,0) -> KHADSARA DSK | F10: MPG | G10: Indirect | H10: 166 | I10: 10827.445 | J10: =I10 -> 10827.445 | M10: =IF(AK10>0,MAX(IF(AK10>0,J10*2%),300),0) -> 300 | O10: =J10-SUM(K10:N10) -> 10527.445 | P10: =IF(R10="Yes",O10,0) -> 0 | Q10: =O10-P10 -> 10527.445 | R10: 0 | T10: {=SUBSTITUTE(SUBSTITUTE(MID(CELL("filename"),FIND("[",CELL("filename"))+1,FIND("]",CELL("filename"))-FIND("[",CELL("filename"))-1),"Farmer Payment-",""),".xlsb","")} -> Ramgarh Kaimur_Farmer Payment_28-03 Aug.xlsx | V10: =I10*1.75% -> 189.48029 | W10: =I10*0.25% -> 27.068613 | X10: =V10-W10 -> 162.41168 | Y10: 0 | Z10: =X10-Y10 -> 162.41168 | AB10: =VLOOKUP(C10,DSC_Master!$C$1:$K$201,9,0) -> SONU KUMAR | AC10: =VLOOKUP(C10,DSC_Master!$C$1:$J$202,8,0) -> 20421372063 | AD10: =VLOOKUP(C10,DSC_Master!$C$1:$J$202,7,0) -> SBIN0014328 | AF10: 10827.91 | AG10: =Q10-AF10 -> -300.465 | AK10: =IFERROR(VLOOKUP(D10,'Milk Can'!D:U,18,0),0) -> 9600
A11: 1062 | B11: Ramgarh | C11: 10620014 | D11: =VLOOKUP(C11,DSC_Master!$C$1:D109,2,0) -> 60628 | E11: =VLOOKUP(C11,DSC_Master!$C$1:$K$201,4,0) -> BAIJNATH DSK | F11: MPG | G11: Indirect | H11: 142 | I11: 6284.0504 | J11: =I11 -> 6284.0504 | M11: =IF(AK11>0,MAX(IF(AK11>0,J11*2%),300),0) -> 0 | O11: =J11-SUM(K11:N11) -> 6284.0504 | P11: =IF(R11="Yes",O11,0) -> 0 | Q11: =O11-P11 -> 6284.0504 | R11: 0 | T11: {=SUBSTITUTE(SUBSTITUTE(MID(CELL("filename"),FIND("[",CELL("filename"))+1,FIND("]",CELL("filename"))-FIND("[",CELL("filename"))-1),"Farmer Payment-",""),".xlsb","")} -> Ramgarh Kaimur_Farmer Payment_28-03 Aug.xlsx | V11: =I11*1.75% -> 109.97088 | W11: =I11*0.25% -> 15.710126 | X11: =V11-W11 -> 94.260756 | Y11: 0 | Z11: =X11-Y11 -> 94.260756 | AB11: =VLOOKUP(C11,DSC_Master!$C$1:$K$201,9,0) -> PARASH SINGH | AC11: =VLOOKUP(C11,DSC_Master!$C$1:$J$202,8,0) -> 2784000100175715 | AD11: =VLOOKUP(C11,DSC_Master!$C$1:$J$202,7,0) -> PUNB0278400 | AF11: 6284.24 | AG11: =Q11-AF11 -> -0.189573 | AK11: =IFERROR(VLOOKUP(D11,'Milk Can'!D:U,18,0),0) -> 0
A12: 1062 | B12: Ramgarh | C12: 10620015 | D12: =VLOOKUP(C12,DSC_Master!$C$1:D110,2,0) -> 64537 | E12: =VLOOKUP(C12,DSC_Master!$C$1:$K$201,4,0) -> KASTHARI DSK | F12: MPG | G12: Indirect | H12: 497 | I12: 22849.183 | J12: =I12 -> 22849.183 | M12: =IF(AK12>0,MAX(IF(AK12>0,J12*2%),300),0) -> 0 | O12: =J12-SUM(K12:N12) -> 22849.183 | P12: =IF(R12="Yes",O12,0) -> 0 | Q12: =O12-P12 -> 22849.183 | R12: 0 | T12: {=SUBSTITUTE(SUBSTITUTE(MID(CELL("filename"),FIND("[",CELL("filename"))+1,FIND("]",CELL("filename"))-FIND("[",CELL("filename"))-1),"Farmer Payment-",""),".xlsb","")} -> Ramgarh Kaimur_Farmer Payment_28-03 Aug.xlsx | V12: =I12*1.75% -> 399.8607 | W12: =I12*0.25% -> 57.122956 | X12: =V12-W12 -> 342.73774 | Y12: 0 | Z12: =X12-Y12 -> 342.73774 | AB12: =VLOOKUP(C12,DSC_Master!$C$1:$K$201,9,0) -> PAWAN KUMAR SINGH | AC12: =VLOOKUP(C12,DSC_Master!$C$1:$J$202,8,0) -> 2374001500005364 | AD12: =VLOOKUP(C12,DSC_Master!$C$1:$J$202,7,0) -> PUNB0237400 | AF12: 22849.64 | AG12: =Q12-AF12 -> -0.4574058 | AK12: =IFERROR(VLOOKUP(D12,'Milk Can'!D:U,18,0),0) -> 0
A13: 1062 | B13: Ramgarh | C13: 10620016 | D13: =VLOOKUP(C13,DSC_Master!$C$1:D111,2,0) -> 64522 | E13: =VLOOKUP(C13,DSC_Master!$C$1:$K$201,4,0) -> MADANPURA DSK | F13: MPG | G13: Indirect | H13: 396 | I13: 21290.396 | J13: =I13 -> 21290.396 | M13: =IF(AK13>0,MAX(IF(AK13>0,J13*2%),300),0) -> 0 | O13: =J13-SUM(K13:N13) -> 21290.396 | P13: =IF(R13="Yes",O13,0) -> 0 | Q13: =O13-P13 -> 21290.396 | R13: 0 | T13: {=SUBSTITUTE(SUBSTITUTE(MID(CELL("filename"),FIND("[",CELL("filename"))+1,FIND("]",CELL("filename"))-FIND("[",CELL("filename"))-1),"Farmer Payment-",""),".xlsb","")} -> Ramgarh Kaimur_Farmer Payment_28-03 Aug.xlsx | V13: =I13*1.75% -> 372.58193 | W13: =I13*0.25% -> 53.225989 | X13: =V13-W13 -> 319.35594 | Y13: 0 | Z13: =X13-Y13 -> 319.35594 | AB13: =VLOOKUP(C13,DSC_Master!$C$1:$K$201,9,0) -> RAM CHARAN RAI | AC13: =VLOOKUP(C13,DSC_Master!$C$1:$J$202,8,0) -> 2374000100165377 | AD13: =VLOOKUP(C13,DSC_Master!$C$1:$J$202,7,0) -> PUNB0237400 | AF13: 21291.21 | AG13: =Q13-AF13 -> -0.8142 | AK13: =IFERROR(VLOOKUP(D13,'Milk Can'!D:U,18,0),0) -> 0
A14: 1062 | B14: Ramgarh | C14: 10620017 | D14: =VLOOKUP(C14,DSC_Master!$C$1:D112,2,0) -> 64555 | E14: =VLOOKUP(C14,DSC_Master!$C$1:$K$201,4,0) -> DEHWALIYA DSK | F14: MPG | G14: Indirect | H14: 281 | I14: 11103.225 | J14: =I14 -> 11103.225 | M14: =IF(AK14>0,MAX(IF(AK14>0,J14*2%),300),0) -> 300 | O14: =J14-SUM(K14:N14) -> 10803.225 | P14: =IF(R14="Yes",O14,0) -> 0 | Q14: =O14-P14 -> 10803.225 | R14: 0 | T14: {=SUBSTITUTE(SUBSTITUTE(MID(CELL("filename"),FIND("[",CELL("filename"))+1,FIND("]",CELL("filename"))-FIND("[",CELL("filename"))-1),"Farmer Payment-",""),".xlsb","")} -> Ramgarh Kaimur_Farmer Payment_28-03 Aug.xlsx | V14: =I14*1.75% -> 194.30644 | W14: =I14*0.25% -> 27.758062 | X14: =V14-W14 -> 166.54837 | Y14: 0 | Z14: =X14-Y14 -> 166.54837 | AB14: =VLOOKUP(C14,DSC_Master!$C$1:$K$201,9,0) -> SATENDRA YADAV | AC14: =VLOOKUP(C14,DSC_Master!$C$1:$J$202,8,0) -> 14462413000951 | AD14: =VLOOKUP(C14,DSC_Master!$C$1:$J$202,7,0) -> PUNB0269600 | AF14: 11103.13 | AG14: =Q14-AF14 -> -299.90502 | AK14: =IFERROR(VLOOKUP(D14,'Milk Can'!D:U,18,0),0) -> 6300
... A16: 1062 | B16: Ramgarh | C16: 10620020 | D16: =VLOOKUP(C16,DSC_Master!$C$1:D114,2,0) -> 64552 | E16: =VLOOKUP(C16,DSC_Master!$C$1:$K$201,4,0) -> KRAPALPUR DSK | F16: MPG | G16: Indirect | H16: 169 | I16: 8950.365 | J16: =I16 -> 8950.365 | M16: =IF(AK16>0,MAX(IF(AK16>0,J16*2%),300),0) -> 0 | O16: =J16-SUM(K16:N16) -> 8950.365 | P16: =IF(R16="Yes",O16,0) -> 0 | Q16: =O16-P16 -> 8950.365 | R16: 0 | T16: {=SUBSTITUTE(SUBSTITUTE(MID(CELL("filename"),FIND("[",CELL("filename"))+1,FIND("]",CELL("filename"))-FIND("[",CELL("filename"))-1),"Farmer Payment-",""),".xlsb","")} -> Ramgarh Kaimur_Farmer Payment_28-03 Aug.xlsx | V16: =I16*1.75% -> 156.63139 | W16: =I16*0.25% -> 22.375912 | X16: =V16-W16 -> 134.25548 | Y16: 0 | Z16: =X16-Y16 -> 134.25548 | AB16: =VLOOKUP(C16,DSC_Master!$C$1:$K$201,9,0) -> VIJAY NARAYAN SINGH | AC16: =VLOOKUP(C16,DSC_Master!$C$1:$J$202,8,0) -> 2374000100170476 | AD16: =VLOOKUP(C16,DSC_Master!$C$1:$J$202,7,0) -> PUNB0237400 | AF16: 8950.67 | AG16: =Q16-AF16 -> -0.305 | AK16: =IFERROR(VLOOKUP(D16,'Milk Can'!D:U,18,0),0) -> 0
A17: 1062 | B17: Ramgarh | C17: 10620023 | D17: =VLOOKUP(C17,DSC_Master!$C$1:D116,2,0) -> 60606 | E17: =VLOOKUP(C17,DSC_Master!$C$1:$K$201,4,0) -> SISODA DSK | F17: MPG | G17: Indirect | H17: 101 | I17: 5382.9891 | J17: =I17 -> 5382.9891 | M17: =IF(AK17>0,MAX(IF(AK17>0,J17*2%),300),0) -> 0 | O17: =J17-SUM(K17:N17) -> 5382.9891 | P17: =IF(R17="Yes",O17,0) -> 0 | Q17: =O17-P17 -> 5382.9891 | R17: 0 | T17: {=SUBSTITUTE(SUBSTITUTE(MID(CELL("filename"),FIND("[",CELL("filename"))+1,FIND("]",CELL("filename"))-FIND("[",CELL("filename"))-1),"Farmer Payment-",""),".xlsb","")} -> Ramgarh Kaimur_Farmer Payment_28-03 Aug.xlsx | V17: =I17*1.75% -> 94.202309 | W17: =I17*0.25% -> 13.457473 | X17: =V17-W17 -> 80.744836 | Y17: 0 | Z17: =X17-Y17 -> 80.744836 | AB17: =VLOOKUP(C17,DSC_Master!$C$1:$K$201,9,0) -> ARVIND SINGH | AC17: =VLOOKUP(C17,DSC_Master!$C$1:$J$202,8,0) -> 461110510000144 | AD17: =VLOOKUP(C17,DSC_Master!$C$1:$J$202,7,0) -> BKID0004611 | AF17: 5383.03 | AG17: =Q17-AF17 -> -0.0409187 | AK17: =IFERROR(VLOOKUP(D17,'Milk Can'!D:U,18,0),0) -> 0
A18: 1062 | B18: Ramgarh | C18: 10620024 | D18: =VLOOKUP(C18,DSC_Master!$C$1:D117,2,0) -> 60610 | E18: =VLOOKUP(C18,DSC_Master!$C$1:$K$201,4,0) -> KARIRAM DSK | F18: MPG | G18: Indirect | H18: 155 | I18: 5918.9337 | J18: =I18 -> 5918.9337 | M18: =IF(AK18>0,MAX(IF(AK18>0,J18*2%),300),0) -> 0 | O18: =J18-SUM(K18:N18) -> 5918.9337 | P18: =IF(R18="Yes",O18,0) -> 0 | Q18: =O18-P18 -> 5918.9337 | R18: 0 | T18: {=SUBSTITUTE(SUBSTITUTE(MID(CELL("filename"),FIND("[",CELL("filename"))+1,FIND("]",CELL("filename"))-FIND("[",CELL("filename"))-1),"Farmer Payment-",""),".xlsb","")} -> Ramgarh Kaimur_Farmer Payment_28-03 Aug.xlsx | V18: =I18*1.75% -> 103.58134 | W18: =I18*0.25% -> 14.797334 | X18: =V18-W18 -> 88.784005 | Y18: 0 | Z18: =X18-Y18 -> 88.784005 | AB18: =VLOOKUP(C18,DSC_Master!$C$1:$K$201,9,0) -> BHARAT SINGH | AC18: =VLOOKUP(C18,DSC_Master!$C$1:$J$202,8,0) -> 6008001700141624 | AD18: =VLOOKUP(C18,DSC_Master!$C$1:$J$202,7,0) -> PUNB0600800 | AF18: 5918.86 | AG18: =Q18-AF18 -> 0.0736952 | AK18: =IFERROR(VLOOKUP(D18,'Milk Can'!D:U,18,0),0) -> 0
A19: 1062 | B19: Ramgarh | C19: 10620025 | D19: =VLOOKUP(C19,DSC_Master!$C$1:D118,2,0) -> 60612 | E19: =VLOOKUP(C19,DSC_Master!$C$1:$K$201,4,0) -> DAVWARIYA DSK | F19: MPG | G19: Indirect | H19: 285 | I19: 13801.69 | J19: =I19 -> 13801.69 | M19: =IF(AK19>0,MAX(IF(AK19>0,J19*2%),300),0) -> 0 | O19: =J19-SUM(K19:N19) -> 13801.69 | P19: =IF(R19="Yes",O19,0) -> 0 | Q19: =O19-P19 -> 13801.69 | R19: 0 | T19: {=SUBSTITUTE(SUBSTITUTE(MID(CELL("filename"),FIND("[",CELL("filename"))+1,FIND("]",CELL("filename"))-FIND("[",CELL("filename"))-1),"Farmer Payment-",""),".xlsb","")} -> Ramgarh Kaimur_Farmer Payment_28-03 Aug.xlsx | V19: =I19*1.75% -> 241.52958 | W19: =I19*0.25% -> 34.504225 | X19: =V19-W19 -> 207.02535 | Y19: 0 | Z19: =X19-Y19 -> 207.02535 | AB19: =VLOOKUP(C19,DSC_Master!$C$1:$K$201,9,0) -> DINESH SINGH | AC19: =VLOOKUP(C19,DSC_Master!$C$1:$J$202,8,0) -> 6008000100136180 | AD19: =VLOOKUP(C19,DSC_Master!$C$1:$J$202,7,0) -> PUNB0600800 | AF19: 13802.4 | AG19: =Q19-AF19 -> -0.7099735 | AK19: =IFERROR(VLOOKUP(D19,'Milk Can'!D:U,18,0),0) -> 0
A20: 1062 | B20: Ramgarh | C20: 10620026 | D20: =VLOOKUP(C20,DSC_Master!$C$1:D119,2,0) -> 64528 | E20: =VLOOKUP(C20,DSC_Master!$C$1:$K$201,4,0) -> TARITHA DSK | F20: MPG | G20: Indirect | H20: 449 | I20: 22837.642 | J20: =I20 -> 22837.642 | M20: =IF(AK20>0,MAX(IF(AK20>0,J20*2%),300),0) -> 456.75284 | O20: =J20-SUM(K20:N20) -> 22380.889 | P20: =IF(R20="Yes",O20,0) -> 0 | Q20: =O20-P20 -> 22380.889 | R20: 0 | T20: {=SUBSTITUTE(SUBSTITUTE(MID(CELL("filename"),FIND("[",CELL("filename"))+1,FIND("]",CELL("filename"))-FIND("[",CELL("filename"))-1),"Farmer Payment-",""),".xlsb","")} -> Ramgarh Kaimur_Farmer Payment_28-03 Aug.xlsx | V20: =I20*1.75% -> 399.65873 | W20: =I20*0.25% -> 57.094105 | X20: =V20-W20 -> 342.56463 | Y20: 0 | Z20: =X20-Y20 -> 342.56463 | AB20: =VLOOKUP(C20,DSC_Master!$C$1:$K$201,9,0) -> MANOJ KUMAR SINGH | AC20: =VLOOKUP(C20,DSC_Master!$C$1:$J$202,8,0) -> 461118210002964 | AD20: =VLOOKUP(C20,DSC_Master!$C$1:$J$202,7,0) -> BKID0004611 | AF20: 22951.75 | AG20: =Q20-AF20 -> -570.86096 | AK20: =IFERROR(VLOOKUP(D20,'Milk Can'!D:U,18,0),0) -> 2843.0428
A21: 1062 | B21: Ramgarh | C21: 10620028 | D21: =VLOOKUP(C21,DSC_Master!$C$1:D120,2,0) -> 60611 | E21: =VLOOKUP(C21,DSC_Master!$C$1:$K$201,4,0) -> AKHOLI DSK | F21: MPG | G21: Indirect | H21: 72 | I21: 3124.943 | J21: =I21 -> 3124.943 | M21: =IF(AK21>0,MAX(IF(AK21>0,J21*2%),300),0) -> 0 | O21: =J21-SUM(K21:N21) -> 3124.943 | P21: =IF(R21="Yes",O21,0) -> 0 | Q21: =O21-P21 -> 3124.943 | R21: 0 | T21: {=SUBSTITUTE(SUBSTITUTE(MID(CELL("filename"),FIND("[",CELL("filename"))+1,FIND("]",CELL("filename"))-FIND("[",CELL("filename"))-1),"Farmer Payment-",""),".xlsb","")} -> Ramgarh Kaimur_Farmer Payment_28-03 Aug.xlsx | V21: =I21*1.75% -> 54.686502 | W21: =I21*0.25% -> 7.8123575 | X21: =V21-W21 -> 46.874145 | Y21: 0 | Z21: =X21-Y21 -> 46.874145 | AB21: =VLOOKUP(C21,DSC_Master!$C$1:$K$201,9,0) -> RAJU JAISWAL | AC21: =VLOOKUP(C21,DSC_Master!$C$1:$J$202,8,0) -> 6008000100017669 | AD21: =VLOOKUP(C21,DSC_Master!$C$1:$J$202,7,0) -> PUNB0600800 | AF21: 3125 | AG21: =Q21-AF21 -> -0.0570023 | AK21: =IFERROR(VLOOKUP(D21,'Milk Can'!D:U,18,0),0) -> 0
A22: 1062 | B22: Ramgarh | C22: 10620029 | D22: =VLOOKUP(C22,DSC_Master!$C$1:D121,2,0) -> 64547 | E22: =VLOOKUP(C22,DSC_Master!$C$1:$K$201,4,0) -> TIWAY DSK | F22: MPG | G22: Indirect | H22: 1783 | I22: 88551.629 | J22: =I22 -> 88551.629 | M22: =IF(AK22>0,MAX(IF(AK22>0,J22*2%),300),0) -> 1771.0326 | O22: =J22-SUM(K22:N22) -> 86780.596 | P22: =IF(R22="Yes",O22,0) -> 0 | Q22: =O22-P22 -> 86780.596 | R22: 0 | T22: {=SUBSTITUTE(SUBSTITUTE(MID(CELL("filename"),FIND("[",CELL("filename"))+1,FIND("]",CELL("filename"))-FIND("[",CELL("filename"))-1),"Farmer Payment-",""),".xlsb","")} -> Ramgarh Kaimur_Farmer Payment_28-03 Aug.xlsx | V22: =I22*1.75% -> 1549.6535 | W22: =I22*0.25% -> 221.37907 | X22: =V22-W22 -> 1328.2744 | Y22: 0 | Z22: =X22-Y22 -> 1328.2744 | AB22: =VLOOKUP(C22,DSC_Master!$C$1:$K$201,9,0) -> RAKESH GUPTA | AC22: =VLOOKUP(C22,DSC_Master!$C$1:$J$202,8,0) -> 6008001700240518 | AD22: =VLOOKUP(C22,DSC_Master!$C$1:$J$202,7,0) -> PUNB0600800 | AF22: 88553.53 | AG22: =Q22-AF22 -> -1772.934 | AK22: =IFERROR(VLOOKUP(D22,'Milk Can'!D:U,18,0),0) -> 5764.9564
A23: 1062 | B23: Ramgarh | C23: 10620030 | D23: =VLOOKUP(C23,DSC_Master!$C$1:D122,2,0) -> 64514 | E23: =VLOOKUP(C23,DSC_Master!$C$1:$K$201,4,0) -> PAJRAWN DSK | F23: MPG | G23: Indirect | H23: 964 | I23: 47615.492 | J23: =I23 -> 47615.492 | M23: =IF(AK23>0,MAX(IF(AK23>0,J23*2%),300),0) -> 952.30983 | O23: =J23-SUM(K23:N23) -> 46663.182 | P23: =IF(R23="Yes",O23,0) -> 0 | Q23: =O23-P23 -> 46663.182 | R23: 0 | T23: {=SUBSTITUTE(SUBSTITUTE(MID(CELL("filename"),FIND("[",CELL("filename"))+1,FIND("]",CELL("filename"))-FIND("[",CELL("filename"))-1),"Farmer Payment-",""),".xlsb","")} -> Ramgarh Kaimur_Farmer Payment_28-03 Aug.xlsx | V23: =I23*1.75% -> 833.2711 | W23: =I23*0.25% -> 119.03873 | X23: =V23-W23 -> 714.23237 | Y23: 0 | Z23: =X23-Y23 -> 714.23237 | AB23: =VLOOKUP(C23,DSC_Master!$C$1:$K$201,9,0) -> RAKESH KUMAR YADAV | AC23: =VLOOKUP(C23,DSC_Master!$C$1:$J$202,8,0) -> 6008001700156088 | AD23: =VLOOKUP(C23,DSC_Master!$C$1:$J$202,7,0) -> PUNB0600800 | AF23: 47617.13 | AG23: =Q23-AF23 -> -953.94821 | AK23: =IFERROR(VLOOKUP(D23,'Milk Can'!D:U,18,0),0) -> 3000
A24: 1062 | B24: Ramgarh | C24: 10620031 | D24: =VLOOKUP(C24,DSC_Master!$C$1:D123,2,0) -> 64553 | E24: =VLOOKUP(C24,DSC_Master!$C$1:$K$201,4,0) -> GAJDHARA DSK | F24: MPG | G24: Indirect | H24: 88 | I24: 4043.5794 | J24: =I24 -> 4043.5794 | M24: =IF(AK24>0,MAX(IF(AK24>0,J24*2%),300),0) -> 300 | O24: =J24-SUM(K24:N24) -> 3743.5794 | P24: =IF(R24="Yes",O24,0) -> 0 | Q24: =O24-P24 -> 3743.5794 | R24: 0 | T24: {=SUBSTITUTE(SUBSTITUTE(MID(CELL("filename"),FIND("[",CELL("filename"))+1,FIND("]",CELL("filename"))-FIND("[",CELL("filename"))-1),"Farmer Payment-",""),".xlsb","")} -> Ramgarh Kaimur_Farmer Payment_28-03 Aug.xlsx | V24: =I24*1.75% -> 70.762639 | W24: =I24*0.25% -> 10.108948 | X24: =V24-W24 -> 60.65369 | Y24: 0 | Z24: =X24-Y24 -> 60.65369 | AB24: =VLOOKUP(C24,DSC_Master!$C$1:$K$201,9,0) -> RAM MOHAN SINGH | AC24: =VLOOKUP(C24,DSC_Master!$C$1:$J$202,8,0) -> 3005000100091168 | AD24: =VLOOKUP(C24,DSC_Master!$C$1:$J$202,7,0) -> PUNB0300500 | AF24: 4043.54 | AG24: =Q24-AF24 -> -299.96064 | AK24: =IFERROR(VLOOKUP(D24,'Milk Can'!D:U,18,0),0) -> 12900
A25: 1062 | B25: Ramgarh | C25: 10620032 | D25: =VLOOKUP(C25,DSC_Master!$C$1:D124,2,0) -> 64594 | E25: =VLOOKUP(C25,DSC_Master!$C$1:$K$201,4,0) -> AKHOLI DSK | F25: MPG | G25: Indirect | H25: 468 | I25: 20671.62 | J25: =I25 -> 20671.62 | M25: =IF(AK25>0,MAX(IF(AK25>0,J25*2%),300),0) -> 413.4324 | O25: =J25-SUM(K25:N25) -> 20258.188 | P25: =IF(R25="Yes",O25,0) -> 0 | Q25: =O25-P25 -> 20258.188 | R25: 0 | T25: {=SUBSTITUTE(SUBSTITUTE(MID(CELL("filename"),FIND("[",CELL("filename"))+1,FIND("]",CELL("filename"))-FIND("[",CELL("filename"))-1),"Farmer Payment-",""),".xlsb","")} -> Ramgarh Kaimur_Farmer Payment_28-03 Aug.xlsx | V25: =I25*1.75% -> 361.75335 | W25: =I25*0.25% -> 51.67905 | X25: =V25-W25 -> 310.0743 | Y25: 0 | Z25: =X25-Y25 -> 310.0743 | AB25: =VLOOKUP(C25,DSC_Master!$C$1:$K$201,9,0) -> RAMESH KUMAR YADAV | AC25: =VLOOKUP(C25,DSC_Master!$C$1:$J$202,8,0) -> 6008001700173623 | AD25: =VLOOKUP(C25,DSC_Master!$C$1:$J$202,7,0) -> PUNB0600800 | AF25: 20671.98 | AG25: =Q25-AF25 -> -413.79232 | AK25: =IFERROR(VLOOKUP(D25,'Milk Can'!D:U,18,0),0) -> 3300
A26: 1062 | B26: Ramgarh | C26: 10620034 | D26: =VLOOKUP(C26,DSC_Master!$C$1:D125,2,0) -> 64509 | E26: =VLOOKUP(C26,DSC_Master!$C$1:$K$201,4,0) -> CHHOTKI KULHARIYA | F26: MPG | G26: Indirect | H26: 422 | I26: 15867.063 | J26: =I26 -> 15867.063 | M26: =IF(AK26>0,MAX(IF(AK26>0,J26*2%),300),0) -> 317.34127 | O26: =J26-SUM(K26:N26) -> 15549.722 | P26: =IF(R26="Yes",O26,0) -> 0 | Q26: =O26-P26 -> 15549.722 | R26: 0 | T26: {=SUBSTITUTE(SUBSTITUTE(MID(CELL("filename"),FIND("[",CELL("filename"))+1,FIND("]",CELL("filename"))-FIND("[",CELL("filename"))-1),"Farmer Payment-",""),".xlsb","")} -> Ramgarh Kaimur_Farmer Payment_28-03 Aug.xlsx | V26: =I26*1.75% -> 277.67361 | W26: =I26*0.25% -> 39.667658 | X26: =V26-W26 -> 238.00595 | Y26: 0 | Z26: =X26-Y26 -> 238.00595 | AB26: =VLOOKUP(C26,DSC_Master!$C$1:$K$201,9,0) -> ABHIMANYU KUMAR SINGH | AC26: =VLOOKUP(C26,DSC_Master!$C$1:$J$202,8,0) -> 50100492904593 | AD26: =VLOOKUP(C26,DSC_Master!$C$1:$J$202,7,0) -> HDFC0002625 | AF26: 15876.74 | AG26: =Q26-AF26 -> -327.01791 | AK26: =IFERROR(VLOOKUP(D26,'Milk Can'!D:U,18,0),0) -> 12871.476
A27: 1062 | B27: Ramgarh | C27: 10620037 | D27: =VLOOKUP(C27,DSC_Master!$C$1:D126,2,0) -> 64506 | E27: =VLOOKUP(C27,DSC_Master!$C$1:$K$201,4,0) -> KRESOPUR DSK | F27: MPG | G27: Indirect | H27: 826 | I27: 37586.911 | J27: =I27 -> 37586.911 | M27: =IF(AK27>0,MAX(IF(AK27>0,J27*2%),300),0) -> 0 | O27: =J27-SUM(K27:N27) -> 37586.911 | P27: =IF(R27="Yes",O27,0) -> 0 | Q27: =O27-P27 -> 37586.911 | R27: 0 | T27: {=SUBSTITUTE(SUBSTITUTE(MID(CELL("filename"),FIND("[",CELL("filename"))+1,FIND("]",CELL("filename"))-FIND("[",CELL("filename"))-1),"Farmer Payment-",""),".xlsb","")} -> Ramgarh Kaimur_Farmer Payment_28-03 Aug.xlsx | V27: =I27*1.75% -> 657.77094 | W27: =I27*0.25% -> 93.967277 | X27: =V27-W27 -> 563.80366 | Y27: 0 | Z27: =X27-Y27 -> 563.80366 | AB27: =VLOOKUP(C27,DSC_Master!$C$1:$K$201,9,0) -> BRIJESH KUMAR | AC27: =VLOOKUP(C27,DSC_Master!$C$1:$J$202,8,0) -> 50100615862711 | AD27: =VLOOKUP(C27,DSC_Master!$C$1:$J$202,7,0) -> HDFC0002625 | AF27: 37592.28 | AG27: =Q27-AF27 -> -5.3691246 | AK27: =IFERROR(VLOOKUP(D27,'Milk Can'!D:U,18,0),0) -> 0
A28: 1062 | B28: Ramgarh | C28: 10620038 | D28: =VLOOKUP(C28,DSC_Master!$C$1:D127,2,0) -> 64534 | E28: =VLOOKUP(C28,DSC_Master!$C$1:$K$201,4,0) -> MIRCHA DSK | F28: MPG | G28: Indirect | H28: 320 | I28: 15062.439 | J28: =I28 -> 15062.439 | M28: =IF(AK28>0,MAX(IF(AK28>0,J28*2%),300),0) -> 0 | O28: =J28-SUM(K28:N28) -> 15062.439 | P28: =IF(R28="Yes",O28,0) -> 0 | Q28: =O28-P28 -> 15062.439 | R28: 0 | T28: {=SUBSTITUTE(SUBSTITUTE(MID(CELL("filename"),FIND("[",CELL("filename"))+1,FIND("]",CELL("filename"))-FIND("[",CELL("filename"))-1),"Farmer Payment-",""),".xlsb","")} -> Ramgarh Kaimur_Farmer Payment_28-03 Aug.xlsx | V28: =I28*1.75% -> 263.59268 | W28: =I28*0.25% -> 37.656097 | X28: =V28-W28 -> 225.93658 | Y28: 0 | Z28: =X28-Y28 -> 225.93658 | AB28: =VLOOKUP(C28,DSC_Master!$C$1:$K$201,9,0) -> CHANDAN YADAV | AC28: =VLOOKUP(C28,DSC_Master!$C$1:$J$202,8,0) -> 40043294718 | AD28: =VLOOKUP(C28,DSC_Master!$C$1:$J$202,7,0) -> SBIN0006137 | AF28: 15062.98 | AG28: =Q28-AF28 -> -0.5410606 | AK28: =IFERROR(VLOOKUP(D28,'Milk Can'!D:U,18,0),0) -> 0
... A62: 1062 | B62: Ramgarh | C62: 10620112 | D62: =VLOOKUP(C62,DSC_Master!$C$1:D161,2,0) -> 20112 | E62: =VLOOKUP(C62,DSC_Master!$C$1:$K$201,4,0) -> PARSATHUA DSK | F62: MPG | G62: Indirect | H62: 127 | I62: 5051.4063 | J62: =I62 -> 5051.4063 | M62: =IF(AK62>0,MAX(IF(AK62>0,J62*2%),300),0) -> 0 | O62: =J62-SUM(K62:N62) -> 5051.4063 | P62: =IF(R62="Yes",O62,0) -> 0 | Q62: =O62-P62 -> 5051.4063 | R62: 0 | T62: {=SUBSTITUTE(SUBSTITUTE(MID(CELL("filename"),FIND("[",CELL("filename"))+1,FIND("]",CELL("filename"))-FIND("[",CELL("filename"))-1),"Farmer Payment-",""),".xlsb","")} -> Ramgarh Kaimur_Farmer Payment_28-03 Aug.xlsx | V62: =I62*1.75% -> 88.39961 | W62: =I62*0.25% -> 12.628516 | X62: =V62-W62 -> 75.771094 | Y62: 0 | Z62: =X62-Y62 -> 75.771094 | AB62: =VLOOKUP(C62,DSC_Master!$C$1:$K$201,9,0) -> ANJU DEVI | AC62: =VLOOKUP(C62,DSC_Master!$C$1:$J$202,8,0) -> 50100615862671 | AD62: =VLOOKUP(C62,DSC_Master!$C$1:$J$202,7,0) -> HDFC0002625 | AF62: 5051.61 | AG62: =Q62-AF62 -> -0.2037303 | AK62: =IFERROR(VLOOKUP(D62,'Milk Can'!D:U,18,0),0) -> 0
A63: 1062 | B63: Ramgarh | C63: 10620115 | D63: =VLOOKUP(C63,DSC_Master!$C$1:D159,2,0) -> 20115 | E63: =VLOOKUP(C63,DSC_Master!$C$1:$K$201,4,0) -> BADAKI KULHARIA DSK | F63: MPG | G63: Indirect | H63: 389 | I63: 15693.97 | J63: =I63 -> 15693.97 | M63: =IF(AK63>0,MAX(IF(AK63>0,J63*2%),300),0) -> 313.8794 | O63: =J63-SUM(K63:N63) -> 15380.09 | P63: =IF(R63="Yes",O63,0) -> 0 | Q63: =O63-P63 -> 15380.09 | R63: 0 | T63: {=SUBSTITUTE(SUBSTITUTE(MID(CELL("filename"),FIND("[",CELL("filename"))+1,FIND("]",CELL("filename"))-FIND("[",CELL("filename"))-1),"Farmer Payment-",""),".xlsb","")} -> Ramgarh Kaimur_Farmer Payment_28-03 Aug.xlsx | V63: =I63*1.75% -> 274.64447 | W63: =I63*0.25% -> 39.234925 | X63: =V63-W63 -> 235.40955 | Y63: 0 | Z63: =X63-Y63 -> 235.40955 | AB63: =VLOOKUP(C63,DSC_Master!$C$1:$K$201,9,0) -> AJAY KUMAR SINGH | AC63: =VLOOKUP(C63,DSC_Master!$C$1:$J$202,8,0) -> 41684045867 | AD63: =VLOOKUP(C63,DSC_Master!$C$1:$J$202,7,0) -> SBIN0017163 | AF63: 15694.46 | AG63: =Q63-AF63 -> -314.36959 | AK63: =IFERROR(VLOOKUP(D63,'Milk Can'!D:U,18,0),0) -> 19472.515
A64: 1062 | B64: Ramgarh | C64: 10620119 | D64: =VLOOKUP(C64,DSC_Master!$C$1:D160,2,0) -> 20119 | E64: =VLOOKUP(C64,DSC_Master!$C$1:$K$201,4,0) -> KURRA NEW DSK | F64: MPG | G64: Indirect | H64: 3250 | I64: 141169.29 | J64: =I64 -> 141169.29 | M64: =IF(AK64>0,MAX(IF(AK64>0,J64*2%),300),0) -> 2823.3858 | O64: =J64-SUM(K64:N64) -> 138345.9 | P64: =IF(R64="Yes",O64,0) -> 0 | Q64: =O64-P64 -> 138345.9 | R64: 0 | T64: {=SUBSTITUTE(SUBSTITUTE(MID(CELL("filename"),FIND("[",CELL("filename"))+1,FIND("]",CELL("filename"))-FIND("[",CELL("filename"))-1),"Farmer Payment-",""),".xlsb","")} -> Ramgarh Kaimur_Farmer Payment_28-03 Aug.xlsx | V64: =I64*1.75% -> 2470.4626 | W64: =I64*0.25% -> 352.92323 | X64: =V64-W64 -> 2117.5394 | Y64: 0 | Z64: =X64-Y64 -> 2117.5394 | AB64: =VLOOKUP(C64,DSC_Master!$C$1:$K$201,9,0) -> DIVYANSHI DAIRY MILK | AC64: =VLOOKUP(C64,DSC_Master!$C$1:$J$202,8,0) -> 8136244333 | AD64: =VLOOKUP(C64,DSC_Master!$C$1:$J$202,7,0) -> IDIB000M430 | AF64: 140915.4 | AG64: =Q64-AF64 -> -2569.4956 | AK64: =IFERROR(VLOOKUP(D64,'Milk Can'!D:U,18,0),0) -> 21635.596
A65: 1062 | B65: Ramgarh | C65: 10620120 | D65: =VLOOKUP(C65,DSC_Master!$C$1:D159,2,0) -> 20120 | E65: =VLOOKUP(C65,DSC_Master!$C$1:$K$201,4,0) -> TIYARA DSK | F65: MPG | G65: Indirect | H65: 139 | I65: 8077.79 | J65: =I65 -> 8077.79 | M65: =IF(AK65>0,MAX(IF(AK65>0,J65*2%),300),0) -> 0 | O65: =J65-SUM(K65:N65) -> 8077.79 | P65: =IF(R65="Yes",O65,0) -> 0 | Q65: =O65-P65 -> 8077.79 | R65: 0 | T65: {=SUBSTITUTE(SUBSTITUTE(MID(CELL("filename"),FIND("[",CELL("filename"))+1,FIND("]",CELL("filename"))-FIND("[",CELL("filename"))-1),"Farmer Payment-",""),".xlsb","")} -> Ramgarh Kaimur_Farmer Payment_28-03 Aug.xlsx | V65: =I65*1.75% -> 141.36132 | W65: =I65*0.25% -> 20.194475 | X65: =V65-W65 -> 121.16685 | Y65: 0 | Z65: =X65-Y65 -> 121.16685 | AB65: =VLOOKUP(C65,DSC_Master!$C$1:$K$201,9,0) -> NIRMAL SINGH | AC65: =VLOOKUP(C65,DSC_Master!$C$1:$J$202,8,0) -> 2784000100110417 | AD65: =VLOOKUP(C65,DSC_Master!$C$1:$J$202,7,0) -> PUNB0278400 | AF65: 8078.17 | AG65: =Q65-AF65 -> -0.38 | AK65: =IFERROR(VLOOKUP(D65,'Milk Can'!D:U,18,0),0) -> 0
A66: 1062 | B66: Ramgarh | C66: 10620121 | D66: =VLOOKUP(C66,DSC_Master!$C$1:D157,2,0) -> 20121 | E66: =VLOOKUP(C66,DSC_Master!$C$1:$K$201,4,0) -> DUMDUMA DSK | F66: MPG | G66: Indirect | H66: 661 | I66: 28951.868 | J66: =I66 -> 28951.868 | M66: =IF(AK66>0,MAX(IF(AK66>0,J66*2%),300),0) -> 0 | O66: =J66-SUM(K66:N66) -> 28951.868 | P66: =IF(R66="Yes",O66,0) -> 0 | Q66: =O66-P66 -> 28951.868 | R66: 0 | T66: {=SUBSTITUTE(SUBSTITUTE(MID(CELL("filename"),FIND("[",CELL("filename"))+1,FIND("]",CELL("filename"))-FIND("[",CELL("filename"))-1),"Farmer Payment-",""),".xlsb","")} -> Ramgarh Kaimur_Farmer Payment_28-03 Aug.xlsx | V66: =I66*1.75% -> 506.6577 | W66: =I66*0.25% -> 72.379671 | X66: =V66-W66 -> 434.27803 | Y66: 0 | Z66: =X66-Y66 -> 434.27803 | AB66: =VLOOKUP(C66,DSC_Master!$C$1:$K$201,9,0) -> CHANDRA MANI RAI | AC66: =VLOOKUP(C66,DSC_Master!$C$1:$J$202,8,0) -> 625310110008012 | AD66: =VLOOKUP(C66,DSC_Master!$C$1:$J$202,7,0) -> BKID0006253 | AF66: 28952.39 | AG66: =Q66-AF66 -> -0.5216238 | AK66: =IFERROR(VLOOKUP(D66,'Milk Can'!D:U,18,0),0) -> 0
A67: 1062 | B67: Ramgarh | C67: 10620122 | D67: =VLOOKUP(C67,DSC_Master!$C$1:D158,2,0) -> 20122 | E67: =VLOOKUP(C67,DSC_Master!$C$1:$K$201,4,0) -> NOUAN DSK | F67: MPG | G67: Indirect | H67: 11 | I67: 382.26223 | J67: =I67 -> 382.26223 | M67: =IF(AK67>0,MAX(IF(AK67>0,J67*2%),300),0) -> 0 | O67: =J67-SUM(K67:N67) -> 382.26223 | P67: =IF(R67="Yes",O67,0) -> 0 | Q67: =O67-P67 -> 382.26223 | R67: 0 | T67: {=SUBSTITUTE(SUBSTITUTE(MID(CELL("filename"),FIND("[",CELL("filename"))+1,FIND("]",CELL("filename"))-FIND("[",CELL("filename"))-1),"Farmer Payment-",""),".xlsb","")} -> Ramgarh Kaimur_Farmer Payment_28-03 Aug.xlsx | V67: =I67*1.75% -> 6.6895891 | W67: =I67*0.25% -> 0.95565558 | X67: =V67-W67 -> 5.7339335 | Y67: 0 | Z67: =X67-Y67 -> 5.7339335 | AB67: =VLOOKUP(C67,DSC_Master!$C$1:$K$201,9,0) -> JAISHANKAR JAISWAL | AC67: =VLOOKUP(C67,DSC_Master!$C$1:$J$202,8,0) -> 461110110007555 | AD67: =VLOOKUP(C67,DSC_Master!$C$1:$J$202,7,0) -> BKID0004611 | AF67: 382.25 | AG67: =Q67-AF67 -> 0.012232 | AK67: =IFERROR(VLOOKUP(D67,'Milk Can'!D:U,18,0),0) -> 0
A68: 1062 | B68: Ramgarh | C68: 10620123 | D68: =VLOOKUP(C68,DSC_Master!$C$1:D159,2,0) -> 20123 | E68: =VLOOKUP(C68,DSC_Master!$C$1:$K$201,4,0) -> SAKRAULI DSK | F68: MPG | G68: Indirect | H68: 323 | I68: 13467.111 | J68: =I68 -> 13467.111 | M68: =IF(AK68>0,MAX(IF(AK68>0,J68*2%),300),0) -> 0 | O68: =J68-SUM(K68:N68) -> 13467.111 | P68: =IF(R68="Yes",O68,0) -> 0 | Q68: =O68-P68 -> 13467.111 | R68: 0 | T68: {=SUBSTITUTE(SUBSTITUTE(MID(CELL("filename"),FIND("[",CELL("filename"))+1,FIND("]",CELL("filename"))-FIND("[",CELL("filename"))-1),"Farmer Payment-",""),".xlsb","")} -> Ramgarh Kaimur_Farmer Payment_28-03 Aug.xlsx | V68: =I68*1.75% -> 235.67444 | W68: =I68*0.25% -> 33.667777 | X68: =V68-W68 -> 202.00666 | Y68: 0 | Z68: =X68-Y68 -> 202.00666 | AB68: =VLOOKUP(C68,DSC_Master!$C$1:$K$201,9,0) -> BECHU PASSI | AC68: =VLOOKUP(C68,DSC_Master!$C$1:$J$202,8,0) -> 2696000100200761 | AD68: =VLOOKUP(C68,DSC_Master!$C$1:$J$202,7,0) -> PUNB0269600 | AF68: 13467.44 | AG68: =Q68-AF68 -> -0.3293402 | AK68: =IFERROR(VLOOKUP(D68,'Milk Can'!D:U,18,0),0) -> 0
A69: 1062 | B69: Ramgarh | C69: 10620124 | D69: =VLOOKUP(C69,DSC_Master!$C$1:D160,2,0) -> 20124 | E69: =VLOOKUP(C69,DSC_Master!$C$1:$K$201,4,0) -> ISARI DSK | F69: MPG | G69: Indirect | H69: 569 | I69: 24427.322 | J69: =I69 -> 24427.322 | M69: =IF(AK69>0,MAX(IF(AK69>0,J69*2%),300),0) -> 488.54643 | O69: =J69-SUM(K69:N69) -> 23938.775 | P69: =IF(R69="Yes",O69,0) -> 0 | Q69: =O69-P69 -> 23938.775 | R69: 0 | T69: {=SUBSTITUTE(SUBSTITUTE(MID(CELL("filename"),FIND("[",CELL("filename"))+1,FIND("]",CELL("filename"))-FIND("[",CELL("filename"))-1),"Farmer Payment-",""),".xlsb","")} -> Ramgarh Kaimur_Farmer Payment_28-03 Aug.xlsx | V69: =I69*1.75% -> 427.47813 | W69: =I69*0.25% -> 61.068304 | X69: =V69-W69 -> 366.40983 | Y69: 0 | Z69: =X69-Y69 -> 366.40983 | AB69: =VLOOKUP(C69,DSC_Master!$C$1:$K$201,9,0) -> KUMAR ARJUN SINGH | AC69: =VLOOKUP(C69,DSC_Master!$C$1:$J$202,8,0) -> 42013101468 | AD69: =VLOOKUP(C69,DSC_Master!$C$1:$J$202,7,0) -> SBIN0017163 | AF69: 24428.15 | AG69: =Q69-AF69 -> -489.3747 | AK69: =IFERROR(VLOOKUP(D69,'Milk Can'!D:U,18,0),0) -> 12871.611
A70: 1062 | B70: Ramgarh | C70: 10620125 | D70: =VLOOKUP(C70,DSC_Master!$C$1:D161,2,0) -> 20125 | E70: =VLOOKUP(C70,DSC_Master!$C$1:$K$201,4,0) -> KUCHHILA DSK | F70: MPG | G70: Indirect | H70: 392 | I70: 17425.327 | J70: =I70 -> 17425.327 | M70: =IF(AK70>0,MAX(IF(AK70>0,J70*2%),300),0) -> 0 | O70: =J70-SUM(K70:N70) -> 17425.327 | P70: =IF(R70="Yes",O70,0) -> 0 | Q70: =O70-P70 -> 17425.327 | R70: 0 | T70: {=SUBSTITUTE(SUBSTITUTE(MID(CELL("filename"),FIND("[",CELL("filename"))+1,FIND("]",CELL("filename"))-FIND("[",CELL("filename"))-1),"Farmer Payment-",""),".xlsb","")} -> Ramgarh Kaimur_Farmer Payment_28-03 Aug.xlsx | V70: =I70*1.75% -> 304.94321 | W70: =I70*0.25% -> 43.563316 | X70: =V70-W70 -> 261.3799 | Y70: 0 | Z70: =X70-Y70 -> 261.3799 | AB70: =VLOOKUP(C70,DSC_Master!$C$1:$K$201,9,0) -> DINBANDHU RAI | AC70: =VLOOKUP(C70,DSC_Master!$C$1:$J$202,8,0) -> 2397000100605573 | AD70: =VLOOKUP(C70,DSC_Master!$C$1:$J$202,7,0) -> PUNB0239700 | AF70: 17423.78 | AG70: =Q70-AF70 -> 1.5465447 | AK70: =IFERROR(VLOOKUP(D70,'Milk Can'!D:U,18,0),0) -> 0
A71: 1062 | B71: Ramgarh | C71: 10620126 | D71: =VLOOKUP(C71,DSC_Master!$C$1:D162,2,0) -> 20126 | E71: =VLOOKUP(C71,DSC_Master!$C$1:$K$201,4,0) -> GAURA DSK | F71: MPG | G71: Indirect | H71: 269 | I71: 10198.885 | J71: =I71 -> 10198.885 | M71: =IF(AK71>0,MAX(IF(AK71>0,J71*2%),300),0) -> 300 | O71: =J71-SUM(K71:N71) -> 9898.8848 | P71: =IF(R71="Yes",O71,0) -> 0 | Q71: =O71-P71 -> 9898.8848 | R71: 0 | T71: {=SUBSTITUTE(SUBSTITUTE(MID(CELL("filename"),FIND("[",CELL("filename"))+1,FIND("]",CELL("filename"))-FIND("[",CELL("filename"))-1),"Farmer Payment-",""),".xlsb","")} -> Ramgarh Kaimur_Farmer Payment_28-03 Aug.xlsx | V71: =I71*1.75% -> 178.48048 | W71: =I71*0.25% -> 25.497212 | X71: =V71-W71 -> 152.98327 | Y71: 0 | Z71: =X71-Y71 -> 152.98327 | AB71: =VLOOKUP(C71,DSC_Master!$C$1:$K$201,9,0) -> TEJBAHADUR SINGH | AC71: =VLOOKUP(C71,DSC_Master!$C$1:$J$202,8,0) -> 625310110002788 | AD71: =VLOOKUP(C71,DSC_Master!$C$1:$J$202,7,0) -> BKID0006253 | AF71: 10198.93 | AG71: =Q71-AF71 -> -300.04525 | AK71: =IFERROR(VLOOKUP(D71,'Milk Can'!D:U,18,0),0) -> 19500
A72: 1062 | B72: Ramgarh | C72: 10620127 | D72: =VLOOKUP(C72,DSC_Master!$C$1:D163,2,0) -> 20127 | E72: =VLOOKUP(C72,DSC_Master!$C$1:$K$201,4,0) -> PHUPHUWAN DSK | F72: MPG | G72: Indirect | H72: 479 | I72: 18509.755 | J72: =I72 -> 18509.755 | M72: =IF(AK72>0,MAX(IF(AK72>0,J72*2%),300),0) -> 0 | O72: =J72-SUM(K72:N72) -> 18509.755 | P72: =IF(R72="Yes",O72,0) -> 0 | Q72: =O72-P72 -> 18509.755 | R72: 0 | T72: {=SUBSTITUTE(SUBSTITUTE(MID(CELL("filename"),FIND("[",CELL("filename"))+1,FIND("]",CELL("filename"))-FIND("[",CELL("filename"))-1),"Farmer Payment-",""),".xlsb","")} -> Ramgarh Kaimur_Farmer Payment_28-03 Aug.xlsx | V72: =I72*1.75% -> 323.92071 | W72: =I72*0.25% -> 46.274387 | X72: =V72-W72 -> 277.64632 | Y72: 0 | Z72: =X72-Y72 -> 277.64632 | AB72: =VLOOKUP(C72,DSC_Master!$C$1:$K$201,9,0) -> MEENU DEVI | AC72: =VLOOKUP(C72,DSC_Master!$C$1:$J$202,8,0) -> 750802010002939 | AD72: =VLOOKUP(C72,DSC_Master!$C$1:$J$202,7,0) -> UBIN0575089 | AF72: 18510.16 | AG72: =Q72-AF72 -> -0.405151 | AK72: =IFERROR(VLOOKUP(D72,'Milk Can'!D:U,18,0),0) -> 0
A73: 1062 | B73: Ramgarh | C73: 10620129 | D73: =VLOOKUP(C73,DSC_Master!$C$1:D163,2,0) -> 20129 | E73: =VLOOKUP(C73,DSC_Master!$C$1:$K$201,4,0) -> DEWAITHA DSK | F73: MPG | G73: Indirect | H73: 101 | I73: 5420.2504 | J73: =I73 -> 5420.2504 | M73: =IF(AK73>0,MAX(IF(AK73>0,J73*2%),300),0) -> 0 | O73: =J73-SUM(K73:N73) -> 5420.2504 | P73: =IF(R73="Yes",O73,0) -> 0 | Q73: =O73-P73 -> 5420.2504 | R73: 0 | T73: {=SUBSTITUTE(SUBSTITUTE(MID(CELL("filename"),FIND("[",CELL("filename"))+1,FIND("]",CELL("filename"))-FIND("[",CELL("filename"))-1),"Farmer Payment-",""),".xlsb","")} -> Ramgarh Kaimur_Farmer Payment_28-03 Aug.xlsx | V73: =I73*1.75% -> 94.854382 | W73: =I73*0.25% -> 13.550626 | X73: =V73-W73 -> 81.303756 | Y73: 0 | Z73: =X73-Y73 -> 81.303756 | AB73: =VLOOKUP(C73,DSC_Master!$C$1:$K$201,9,0) -> SUDHAR SINGH | AC73: =VLOOKUP(C73,DSC_Master!$C$1:$J$202,8,0) -> 466302010012219 | AD73: =VLOOKUP(C73,DSC_Master!$C$1:$J$202,7,0) -> UBIN0546631 | AF73: 5420.14 | AG73: =Q73-AF73 -> 0.11039 | AK73: =IFERROR(VLOOKUP(D73,'Milk Can'!D:U,18,0),0) -> 0
F74: Total: | G74: =COUNTA(G3:G73) -> 71 | H74: =SUBTOTAL(109,H3:H73) -> 47892 | I74: =SUBTOTAL(109,I3:I73) -> 2188524.7 | J74: =SUBTOTAL(109,J3:J73) -> 2188524.7 | K74: =SUBTOTAL(109,K3:K73) -> 0 | L74: =SUBTOTAL(109,L3:L73) -> 0 | M74: =SUBTOTAL(109,M3:M73) -> 18601.337 | N74: =SUBTOTAL(109,N3:N73) -> 0 | O74: =SUBTOTAL(109,O3:O73) -> 2169923.3 | ... Q74: =SUBTOTAL(109,Q3:Q73) -> 2169923.3 | R74: =COUNTIF(R2:R73,"Yes") -> 0 | V74: =SUM(V3:V73) -> 38299.182 | W74: =SUM(W3:W73) -> 5471.3117 | X74: =SUM(X3:X73) -> 32827.87 | Y74: =SUM(Y3:Y73) -> 0 | Z74: =SUM(Z3:Z73) -> 32827.87 | AF74: =SUM(AF3:AF73) -> 2188433.1 | AG74: =SUM(AG3:AG73) -> -18509.791 | AK74: =IFERROR(VLOOKUP(D74,'Milk Can'!D:U,18,0),0) -> 0
E76: Particulars | F76: Value
...

Sheet Sheet1
A1: union_code | B1: bmc_code | C1: dcs_code | D1: society_code_ex | E1: dcs_short_name | F1: Mobile No | G1: ifsc | H1: bank_account_no | I1: beneficiary_name | J1: Balance Payable/Recoverable | K1: Remarks | L1: Recovery in 06-12 Feb | M1: Balance
A2: 001 | B2: 1062 | C2: 10620001 | D2: 64540 | E2: KARARI DSK | F2: 9934591684 | G2: HDFC0002625 | H2: 50100615862020 | I2: AKHILESH PANDEY | J2: 23.246194 | K2: Recovery from cycle | L2: =VLOOKUP(C2,'MPG Payment'!$C$3:$N$73,12,0) -> #N/A | M2: =J2-L2 -> #N/A
A3: 001 | B3: 1062 | C3: 10620012 | D3: 64515 | E3: DHARHARA DSK | F3: 7783847657 | G3: SBIN0006137 | H3: 37905177514 | I3: SHREE NIWAS YADAV | J3: 354.68346 | K3: Recovery from cycle | L3: =VLOOKUP(C3,'MPG Payment'!$C$3:$N$73,12,0) -> 0 | M3: =J3-L3 -> 354.68346
A4: 001 | B4: 1062 | C4: 10620015 | D4: 64537 | E4: KASTHARI DSK | F4: 9905909472 | G4: PUNB0237400 | H4: 2374001500005364 | I4: PAWAN KUMAR SINGH | J4: 13702.66 | K4: Recovery from cycle | L4: =VLOOKUP(C4,'MPG Payment'!$C$3:$N$73,12,0) -> 0 | M4: =J4-L4 -> 13702.66
A5: 001 | B5: 1062 | C5: 10620018 | D5: 64591 | E5: LURPURWA DSK | F5: 8002591740 | G5: UBIN0560308 | H5: 603002010018335 | I5: SAVARU SINGH | J5: 19750.367 | K5: Recovery from cycle | L5: =VLOOKUP(C5,'MPG Payment'!$C$3:$N$73,12,0) -> #N/A | M5: =J5-L5 -> #N/A
A6: 001 | B6: 1062 | C6: 10620020 | D6: 64552 | E6: KRAPALPUR DSK | F6: 7739708957 | G6: PUNB0237400 | H6: 2374000100170476 | I6: VIJAY NARAYAN SINGH | J6: 27305.976 | K6: Recovery from cycle | L6: =VLOOKUP(C6,'MPG Payment'!$C$3:$N$73,12,0) -> 0 | M6: =J6-L6 -> 27305.976
A7: 001 | B7: 1062 | C7: 10620022 | D7: 64545 | E7: SURYAPURA DSK | F7: 9199217582 | G7: BKID0004611 | H7: 461110110009490 | I7: AJAY KUMAR SINGH | J7: 3356.0228 | K7: Recovery from cycle | L7: =VLOOKUP(C7,'MPG Payment'!$C$3:$N$73,12,0) -> #N/A | M7: =J7-L7 -> #N/A
A8: 001 | B8: 1062 | C8: 10620024 | D8: 60610 | E8: KARIRAM DSK | F8: 9199729020 | G8: PUNB0600800 | H8: 6008001700141624 | I8: BHARAT SINGH | J8: 3070.7935 | K8: Recovery from cycle | L8: =VLOOKUP(C8,'MPG Payment'!$C$3:$N$73,12,0) -> 0 | M8: =J8-L8 -> 3070.7935
A9: 001 | B9: 1062 | C9: 10620026 | D9: 64528 | E9: TARITHA DSK | F9: 9135981264 | G9: BKID0004611 | H9: 461118210002964 | I9: MANOJ KUMAR SINGH | J9: 3272.5795 | K9: Recovery from cycle | L9: =VLOOKUP(C9,'MPG Payment'!$C$3:$N$73,12,0) -> 0 | M9: =J9-L9 -> 3272.5795
A10: 001 | B10: 1062 | C10: 10620034 | D10: 64509 | E10: CHHOTKI KULHARIYA | F10: 7250947683 | G10: HDFC0002625 | H10: 50100492904593 | I10: ABHIMANYU KUMAR SINGH | J10: 4658.6176 | K10: Recovery from cycle | L10: =VLOOKUP(C10,'MPG Payment'!$C$3:$N$73,12,0) -> 0 | M10: =J10-L10 -> 4658.6176
A11: 001 | B11: 1062 | C11: 10620061 | D11: 60605 | E11: BADORA DSK | F11: 9170623981 | G11: SBIN0011251 | H11: 40819491150 | I11: SUMAN DEVI | J11: 46684.153 | K11: Recovery from cycle | L11: =VLOOKUP(C11,'MPG Payment'!$C$3:$N$73,12,0) -> 0 | M11: =J11-L11 -> 46684.153
A12: 001 | B12: 1062 | C12: 10620062 | D12: 64590 | E12: CHATRA DSK | F12: 9934761888 | G12: SBIN0002964 | H12: 39981585891 | I12: USHA DEVI | J12: 22196.225 | K12: Recovery from cycle | L12: =VLOOKUP(C12,'MPG Payment'!$C$3:$N$73,12,0) -> 0 | M12: =J12-L12 -> 22196.225
A13: 001 | B13: 1062 | C13: 10620065 | D13: 64589 | E13: NIPURAN DSK | F13: 7763028752 | G13: PUNB0237400 | H13: 2374000100181126 | I13: NITESH KUMAR YADAV | J13: 4097.9232 | K13: Recovery from cycle | L13: =VLOOKUP(C13,'MPG Payment'!$C$3:$N$73,12,0) -> #N/A | M13: =J13-L13 -> #N/A
... A17: 001 | B17: 1062 | C17: 10620094 | D17: 64572 | E17: MATHURADERA DSK | F17: 7061423987 | G17: PUNB0154700 | H17: 1547000100166038 | I17: SURENDRA YADAV | J17: 9307.5261 | K17: Recovery from cycle | L17: =VLOOKUP(C17,'MPG Payment'!$C$3:$N$73,12,0) -> #N/A | M17: =J17-L17 -> #N/A
J18: =SUM(J2:J17) -> 172704.2 | L18: =SUM(L2:L17) -> #N/A | M18: =J18-L18 -> #N/A

Sheet TS Loss Gain
B1: Ramgarh Bmc | AP1: 436.77 | AQ1: 291.18
B2: Date | C2: Shift | D2: OB | I2: Milk from MPG in Kg | M2: Transfer from other BMC/RMC | R2: Total Milk Receipt in Kg | U2: Tanker Dispatch Details | AC2: Plant Receipt | AH2: CB | AM2: Loss/(Gain)
D3: Qty KG | E3: Fat% | F3: Snf% | G3: FAT Kg | H3: SNF Kg | I3: Qty Kg | J3: Qty Kg | K3: Fat% | L3: Snf% | M3: From | N3: Tanker No | O3: Qty Kg | P3: Fat% | Q3: Snf% | R3: Qty Kg | S3: FAT Kg | T3: SNF Kg | U3: Tanker | V3: Challan | W3: To | X3: Qty KG | Y3: Fat% | Z3: Snf% | AA3: FAT Kg | AB3: SNF Kg | AC3: Qty KG | AD3: Fat% | AE3: Snf% | AF3: FAT Kg | AG3: SNF Kg | AH3: Qty KG | AI3: Fat% | AJ3: Snf% | AK3: FAT Kg | AL3: SNF Kg | AM3: Qty KG | AN3: FAT Kg | AO3: SNF Kg | AP3: TS Loss% | AQ3: Amount
B4: 46054 | C4: M | D4: 0 | E4: 0 | F4: 0 | G4: =+D4*E4% -> 0 | H4: =+D4*F4% -> 0 | I4: 20910 | J4: 20910 | K4: 5.3178001 | L4: 8.3824582 | R4: =O4+J4 -> 20910 | S4: =(J4*K4%)+(O4*P4%) -> 1111.952 | T4: =(J4*L4%)+(O4*Q4%) -> 1752.772 | U4: 5280 | V4: KMR 01 | W4: Hajipur | X4: 14940 | Y4: 5.3 | Z4: 8.3 | AA4: =X4*Y4% -> 791.82 | AB4: =X4*Z4% -> 1240.02 | AC4: 14940 | AD4: 5.3 | AE4: 8.3 | AF4: =AC4*AD4% -> 791.82 | AG4: =AC4*AE4% -> 1240.02 | AH4: 5970 | AI4: 5.36 | AJ4: 8.59 | AK4: =AH4*AI4% -> 319.992 | AL4: =AH4*AJ4% -> 512.823 | AM4: =+D4+R4-AC4-AH4 -> 0 | AN4: =+G4+S4-AF4-AK4 -> 0.14 | AO4: =+H4+T4-AG4-AL4 -> -0.071 | AP4: =(AN4+AO4)/(S4+T4) -> 2.408609e-05 | AQ4: =($AP$1*AN4+$AQ$1*AO4) -> 40.47402 | AR4: =(D4+J4+O4)-(X4+AH4) -> 0
B5: =+B4 -> 46054 | C5: E | D5: 5970 | E5: 5.36 | F5: 8.59 | G5: =+D5*E5% -> 319.992 | H5: =+D5*F5% -> 512.823 | I5: 8469 | J5: 8469 | K5: 5.4522376 | L5: 8.5376077 | R5: =O5+J5 -> 8469 | S5: =(J5*K5%)+(O5*P5%) -> 461.75 | T5: =(J5*L5%)+(O5*Q5%) -> 723.05 | U5: 0 | V5: 0 | W5: 0 | X5: 0 | Y5: 0 | Z5: 0 | AA5: =X5*Y5% -> 0 | AB5: =X5*Z5% -> 0 | AF5: =AC5*AD5% -> 0 | AG5: =AC5*AE5% -> 0 | AH5: 14459 | AI5: 5.41 | AJ5: 8.55 | AK5: =AH5*AI5% -> 782.2319 | AL5: =AH5*AJ5% -> 1236.2445 | AM5: =+D5+R5-AC5-AH5 -> -20 | AN5: =+G5+S5-AF5-AK5 -> -0.4899 | AO5: =+H5+T5-AG5-AL5 -> -0.3715 | AP5: =(AN5+AO5)/(S5+T5) -> -0.00072704254 | AQ5: =($AP$1*AN5+$AQ$1*AO5) -> -322.14699 | AR5: =(D5+J5+O5)-(X5+AH5) -> -20
B6: =+B4+1 -> 46055 | C6: M | D6: 14459 | E6: 5.41 | F6: 8.55 | G6: =+D6*E6% -> 782.2319 | H6: =+D6*F6% -> 1236.2445 | I6: 8285 | J6: 8285 | K6: 5.5487628 | L6: 8.6249849 | R6: =O6+J6 -> 8285 | S6: =(J6*K6%)+(O6*P6%) -> 459.715 | T6: =(J6*L6%)+(O6*Q6%) -> 714.58 | U6: 5280 | V6: KMR 02 | W6: Hajipur | X6: 18830 | Y6: 5.35 | Z6: 8.6 | AA6: =X6*Y6% -> 1007.405 | AB6: =X6*Z6% -> 1619.38 | AC6: 18760 | AD6: 5.35 | AE6: 8.41 | AF6: =AC6*AD6% -> 1003.66 | AG6: =AC6*AE6% -> 1577.716 | AH6: 3934 | AI6: 5.45 | AJ6: 8.57 | AK6: =AH6*AI6% -> 214.403 | AL6: =AH6*AJ6% -> 337.1438 | AM6: =+D6+R6-AC6-AH6 -> 50 | AN6: =+G6+S6-AF6-AK6 -> 23.8839 | AO6: =+H6+T6-AG6-AL6 -> 35.9647 | AP6: =(AN6+AO6)/(S6+T6) -> 0.050965558 | AQ6: =($AP$1*AN6+$AQ$1*AO6) -> 20903.972 | AR6: =(D6+J6+O6)-(X6+AH6) -> -20
B7: =+B5+1 -> 46055 | C7: E | D7: 3934 | E7: 5.45 | F7: 8.57 | G7: =+D7*E7% -> 214.403 | H7: =+D7*F7% -> 337.1438 | I7: 5624 | J7: 5624 | K7: 5.5403983 | L7: 8.4842105 | R7: =O7+J7 -> 5624 | S7: =(J7*K7%)+(O7*P7%) -> 311.592 | T7: =(J7*L7%)+(O7*Q7%) -> 477.152 | U7: 0 | V7: 0 | W7: 0 | X7: 0 | Y7: 0 | Z7: 0 | AA7: =X7*Y7% -> 0 | AB7: =X7*Z7% -> 0 | AF7: =AC7*AD7% -> 0 | AG7: =AC7*AE7% -> 0 | AH7: 9558 | AI7: 5.5 | AJ7: 8.52 | AK7: =AH7*AI7% -> 525.69 | AL7: =AH7*AJ7% -> 814.3416 | AM7: =+D7+R7-AC7-AH7 -> 0 | AN7: =+G7+S7-AF7-AK7 -> 0.305 | AO7: =+H7+T7-AG7-AL7 -> -0.0458 | AP7: =(AN7+AO7)/(S7+T7) -> 0.00032862374 | AQ7: =($AP$1*AN7+$AQ$1*AO7) -> 119.87881 | AR7: =(D7+J7+O7)-(X7+AH7) -> 0
B8: =+B6+1 -> 46056 | C8: M | D8: 9558 | E8: 5.5 | F8: 8.52 | G8: =+D8*E8% -> 525.69 | H8: =+D8*F8% -> 814.3416 | I8: 6861 | J8: 6861 | K8: 5.5343827 | L8: 8.596808 | R8: =O8+J8 -> 6861 | S8: =(J8*K8%)+(O8*P8%) -> 379.714 | T8: =(J8*L8%)+(O8*Q8%) -> 589.827 | U8: 00 | V8: 0 | W8: 0 | X8: 0 | Y8: 0 | Z8: 0 | AA8: =X8*Y8% -> 0 | AB8: =X8*Z8% -> 0 | AF8: =AC8*AD8% -> 0 | AG8: =AC8*AE8% -> 0 | AH8: 16429 | AI8: 5.51 | AJ8: 8.55 | AK8: =AH8*AI8% -> 905.2379 | AL8: =AH8*AJ8% -> 1404.6795 | AM8: =+D8+R8-AC8-AH8 -> -10 | AN8: =+G8+S8-AF8-AK8 -> 0.1661 | AO8: =+H8+T8-AG8-AL8 -> -0.5109 | AP8: =(AN8+AO8)/(S8+T8) -> -0.0003556322 | AQ8: =($AP$1*AN8+$AQ$1*AO8) -> -76.216365 | AR8: =(D8+J8+O8)-(X8+AH8) -> -10
B9: =+B7+1 -> 46056 | C9: E | D9: 16429 | E9: 5.51 | F9: 8.55 | G9: =+D9*E9% -> 905.2379 | H9: =+D9*F9% -> 1404.6795 | I9: 7190 | J9: 7190 | K9: 5.3776078 | L9: 8.5348679 | R9: =O9+J9 -> 7190 | S9: =(J9*K9%)+(O9*P9%) -> 386.65 | T9: =(J9*L9%)+(O9*Q9%) -> 613.657 | U9: 5280 | V9: KMR 03 | W9: Hajipur | X9: 18800 | Y9: 5.2 | Z9: 8.2 | AA9: =X9*Y9% -> 977.6 | AB9: =X9*Z9% -> 1541.6 | AC9: 18780 | AD9: 5.15 | AE9: 8.12 | AF9: =AC9*AD9% -> 967.17 | AG9: =AC9*AE9% -> 1524.936 | AH9: 4829 | AI9: 5.47 | AJ9: 8.54 | AK9: =AH9*AI9% -> 264.1463 | AL9: =AH9*AJ9% -> 412.3966 | AM9: =+D9+R9-AC9-AH9 -> 10 | AN9: =+G9+S9-AF9-AK9 -> 60.5716 | AO9: =+H9+T9-AG9-AL9 -> 81.0039 | AP9: =(AN9+AO9)/(S9+T9) -> 0.14153205 | AQ9: =($AP$1*AN9+$AQ$1*AO9) -> 50042.573 | AR9: =(D9+J9+O9)-(X9+AH9) -> -10
B10: =+B8+1 -> 46057 | C10: M | D10: 4829 | E10: 5.47 | F10: 8.54 | G10: =+D10*E10% -> 264.1463 | H10: =+D10*F10% -> 412.3966 | I10: 4601 | J10: 4601 | K10: 5.3553141 | L10: 8.6052597 | R10: =O10+J10 -> 4601 | S10: =(J10*K10%)+(O10*P10%) -> 246.398 | T10: =(J10*L10%)+(O10*Q10%) -> 395.928 | U10: 0 | V10: 0 | W10: 0 | X10: 0 | Y10: 0 | Z10: 0 | AA10: =X10*Y10% -> 0 | AB10: =X10*Z10% -> 0 | AF10: =AC10*AD10% -> 0 | AG10: =AC10*AE10% -> 0 | AH10: 9440 | AI10: 5.39 | AJ10: 8.53 | AK10: =AH10*AI10% -> 508.816 | AL10: =AH10*AJ10% -> 805.232 | AM10: =+D10+R10-AC10-AH10 -> -10 | AN10: =+G10+S10-AF10-AK10 -> 1.7283 | AO10: =+H10+T10-AG10-AL10 -> 3.0926 | AP10: =(AN10+AO10)/(S10+T10) -> 0.0075053789 | AQ10: =($AP$1*AN10+$AQ$1*AO10) -> 1655.3729 | AR10: =(D10+J10+O10)-(X10+AH10) -> -10
B11: =+B9+1 -> 46057 | C11: E | D11: 9440 | E11: 5.39 | F11: 8.53 | G11: =+D11*E11% -> 508.816 | H11: =+D11*F11% -> 805.232 | I11: 4919 | J11: 4919 | K11: 5.3969913 | L11: 8.4898353 | R11: =O11+J11 -> 4919 | S11: =(J11*K11%)+(O11*P11%) -> 265.478 | T11: =(J11*L11%)+(O11*Q11%) -> 417.615 | U11: 0 | V11: 0 | W11: 0 | X11: 0 | Y11: 0 | Z11: 0 | AA11: =X11*Y11% -> 0 | AB11: =X11*Z11% -> 0 | AF11: =AC11*AD11% -> 0 | AG11: =AC11*AE11% -> 0 | AH11: 14379 | AI11: 5.38 | AJ11: 8.5 | AK11: =AH11*AI11% -> 773.5902 | AL11: =AH11*AJ11% -> 1222.215 | AM11: =+D11+R11-AC11-AH11 -> -20 | AN11: =+G11+S11-AF11-AK11 -> 0.7038 | AO11: =+H11+T11-AG11-AL11 -> 0.632 | AP11: =(AN11+AO11)/(S11+T11) -> 0.001955517 | AQ11: =($AP$1*AN11+$AQ$1*AO11) -> 491.42449 | AR11: =(D11+J11+O11)-(X11+AH11) -> -20
B12: =+B10+1 -> 46058 | C12: M | D12: 14379 | E12: 5.38 | F12: 8.5 | G12: =+D12*E12% -> 773.5902 | H12: =+D12*F12% -> 1222.215 | I12: 5240 | J12: 5240 | K12: 5.6366794 | L12: 8.6313168 | R12: =O12+J12 -> 5240 | S12: =(J12*K12%)+(O12*P12%) -> 295.362 | T12: =(J12*L12%)+(O12*Q12%) -> 452.281 | U12: 5280 | V12: KMR 04 | W12: Hajipur | X12: 18780 | Y12: 5.55 | Z12: 8.65 | AA12: =X12*Y12% -> 1042.29 | AB12: =X12*Z12% -> 1624.47 | AC12: 18840 | AD12: 5.55 | AE12: 8.52 | AF12: =AC12*AD12% -> 1045.62 | AG12: =AC12*AE12% -> 1605.168 | AH12: 879 | AI12: 5.44 | AJ12: 8.52 | AK12: =AH12*AI12% -> 47.8176 | AL12: =AH12*AJ12% -> 74.8908 | AM12: =+D12+R12-AC12-AH12 -> -100 | AN12: =+G12+S12-AF12-AK12 -> -24.4854 | AO12: =+H12+T12-AG12-AL12 -> -5.5628 | AP12: =(AN12+AO12)/(S12+T12) -> -0.040190572 | AQ12: =($AP$1*AN12+$AQ$1*AO12) -> -12314.264 | AR12: =(D12+J12+O12)-(X12+AH12) -> -40
B13: =+B11+1 -> 46058 | C13: E | D13: 879 | E13: 5.44 | F13: 8.52 | G13: =+D13*E13% -> 47.8176 | H13: =+D13*F13% -> 74.8908 | I13: 5430 | J13: 5430 | K13: 5.1667956 | L13: 8.5652855 | R13: =O13+J13 -> 5430 | S13: =(J13*K13%)+(O13*P13%) -> 280.557 | T13: =(J13*L13%)+(O13*Q13%) -> 465.095 | U13: 0 | V13: 0 | W13: 0 | X13: 0 | Y13: 0 | Z13: 0 | AA13: =X13*Y13% -> 0 | AB13: =X13*Z13% -> 0 | AF13: =AC13*AD13% -> 0 | AG13: =AC13*AE13% -> 0 | AH13: 6319 | AI13: 5.2 | AJ13: 8.55 | AK13: =AH13*AI13% -> 328.588 | AL13: =AH13*AJ13% -> 540.2745 | AM13: =+D13+R13-AC13-AH13 -> -10 | AN13: =+G13+S13-AF13-AK13 -> -0.2134 | AO13: =+H13+T13-AG13-AL13 -> -0.2887 | AP13: =(AN13+AO13)/(S13+T13) -> -0.00067337042 | AQ13: =($AP$1*AN13+$AQ$1*AO13) -> -177.27038 | AR13: =(D13+J13+O13)-(X13+AH13) -> -10 | AS13: =SUM(AQ4:AQ13) -> 60363.798
B14: =+B12+1 -> 46059 | C14: M | D14: 6319 | E14: 5.2 | F14: 8.55 | G14: =+D14*E14% -> 328.588 | H14: =+D14*F14% -> 540.2745 | I14: 5637 | J14: 5637 | K14: 5.5152386 | L14: 8.6147064 | R14: =O14+J14 -> 5637 | S14: =(J14*K14%)+(O14*P14%) -> 310.894 | T14: =(J14*L14%)+(O14*Q14%) -> 485.611 | U14: 0 | V14: 0 | W14: 0 | X14: 0 | Y14: 0 | Z14: 0 | AA14: =X14*Y14% -> 0 | AB14: =X14*Z14% -> 0 | AF14: =AC14*AD14% -> 0 | AG14: =AC14*AE14% -> 0 | AH14: 11966 | AI14: 5.35 | AJ14: 8.57 | AK14: =AH14*AI14% -> 640.181 | AL14: =AH14*AJ14% -> 1025.4862 | AM14: =+D14+R14-AC14-AH14 -> -10 | AN14: =+G14+S14-AF14-AK14 -> -0.699 | AO14: =+H14+T14-AG14-AL14 -> 0.3993 | AP14: =(AN14+AO14)/(S14+T14) -> -0.00037626882 | AQ14: =($AP$1*AN14+$AQ$1*AO14) -> -189.03406 | AR14: =(D14+J14+O14)-(X14+AH14) -> -10
B15: =+B13+1 -> 46059 | C15: E | D15: 11966 | E15: 5.35 | F15: 8.57 | G15: =+D15*E15% -> 640.181 | H15: =+D15*F15% -> 1025.4862 | I15: 4761 | J15: 4761 | K15: 5.4387314 | L15: 8.5452636 | R15: =O15+J15 -> 4761 | S15: =(J15*K15%)+(O15*P15%) -> 258.938 | T15: =(J15*L15%)+(O15*Q15%) -> 406.84 | U15: 0 | V15: 0 | W15: 0 | X15: 0 | Y15: 0 | Z15: 0 | AA15: =X15*Y15% -> 0 | AB15: =X15*Z15% -> 0 | AF15: =AC15*AD15% -> 0 | AG15: =AC15*AE15% -> 0 | AH15: 16737 | AI15: 5.37 | AJ15: 8.56 | AK15: =AH15*AI15% -> 898.7769 | AL15: =AH15*AJ15% -> 1432.6872 | AM15: =+D15+R15-AC15-AH15 -> -10 | AN15: =+G15+S15-AF15-AK15 -> 0.3421 | AO15: =+H15+T15-AG15-AL15 -> -0.361 | AP15: =(AN15+AO15)/(S15+T15) -> -2.8387841e-05 | AQ15: =($AP$1*AN15+$AQ$1*AO15) -> 44.303037 | AR15: =(D15+J15+O15)-(X15+AH15) -> -10
B16: =+B14+1 -> 46060 | C16: M | D16: 16737 | E16: 5.37 | F16: 8.56 | G16: =+D16*E16% -> 898.7769 | H16: =+D16*F16% -> 1432.6872 | I16: 7868 | J16: 7868 | K16: 5.2064692 | L16: 8.4920564 | R16: =O16+J16 -> 7868 | S16: =(J16*K16%)+(O16*P16%) -> 409.645 | T16: =(J16*L16%)+(O16*Q16%) -> 668.155 | U16: 0 | V16: 0 | W16: 0 | X16: 0 | Y16: 0 | Z16: 0 | AA16: =X16*Y16% -> 0 | AB16: =X16*Z16% -> 0 | AF16: =AC16*AD16% -> 0 | AG16: =AC16*AE16% -> 0 | AH16: 24615 | AI16: 5.32 | AJ16: 8.53 | AK16: =AH16*AI16% -> 1309.518 | AL16: =AH16*AJ16% -> 2099.6595 | AM16: =+D16+R16-AC16-AH16 -> -10 | AN16: =+G16+S16-AF16-AK16 -> -1.0961 | AO16: =+H16+T16-AG16-AL16 -> 1.1827 | AP16: =(AN16+AO16)/(S16+T16) -> 8.0348859e-05 | AQ16: =($AP$1*AN16+$AQ$1*AO16) -> -134.36501 | AR16: =(D16+J16+O16)-(X16+AH16) -> -10
B17: =+B15+1 -> 46060 | C17: E | D17: 24615 | E17: 5.32 | F17: 8.53 | G17: =+D17*E17% -> 1309.518 | H17: =+D17*F17% -> 2099.6595 | I17: 6349 | J17: 6349 | K17: 5.4990392 | L17: 8.6212947 | R17: =O17+J17 -> 6349 | S17: =(J17*K17%)+(O17*P17%) -> 349.134 | T17: =(J17*L17%)+(O17*Q17%) -> 547.366 | U17: 00 | V17: 0 | W17: 0 | X17: 0 | Y17: 0 | Z17: 0 | AA17: =X17*Y17% -> 0 | AB17: =X17*Z17% -> 0 | AF17: =AC17*AD17% -> 0 | AG17: =AC17*AE17% -> 0 | AH17: 30974 | AI17: 5.35 | AJ17: 8.55 | AK17: =AH17*AI17% -> 1657.109 | AL17: =AH17*AJ17% -> 2648.277 | AM17: =+D17+R17-AC17-AH17 -> -10 | AN17: =+G17+S17-AF17-AK17 -> 1.543 | AO17: =+H17+T17-AG17-AL17 -> -1.2515 | AP17: =(AN17+AO17)/(S17+T17) -> 0.00032515337 | AQ17: =($AP$1*AN17+$AQ$1*AO17) -> 309.52434 | AR17: =(D17+J17+O17)-(X17+AH17) -> -10
B18: =+B16+1 -> 46061 | C18: M | D18: 30974 | E18: 5.35 | F18: 8.55 | G18: =+D18*E18% -> 1657.109 | H18: =+D18*F18% -> 2648.277 | I18: 6100 | J18: 6100 | K18: 5.5326393 | L18: 8.5830984 | R18: =O18+J18 -> 6100 | S18: =(J18*K18%)+(O18*P18%) -> 337.491 | T18: =(J18*L18%)+(O18*Q18%) -> 523.569 | U18: 5280 | V18: 82005 | W18: Hajipur | X18: 18750 | Y18: 5.55 | Z18: 8.65 | AA18: =X18*Y18% -> 1040.625 | AB18: =X18*Z18% -> 1621.875 | AC18: 18760 | AD18: 5.35 | AE18: 8.35 | AF18: =AC18*AD18% -> 1003.66 | AG18: =AC18*AE18% -> 1566.46 | AH18: 18334 | AI18: 5.38 | AJ18: 8.55 | AK18: =AH18*AI18% -> 986.3692 | AL18: =AH18*AJ18% -> 1567.557 | AM18: =+D18+R18-AC18-AH18 -> -20 | AN18: =+G18+S18-AF18-AK18 -> 4.5708 | AO18: =+H18+T18-AG18-AL18 -> 37.829 | AP18: =(AN18+AO18)/(S18+T18) -> 0.0492414 | AQ18: =($AP$1*AN18+$AQ$1*AO18) -> 13011.437 | AR18: =(D18+J18+O18)-(X18+AH18) -> -10
B19: =+B17+1 -> 46061 | C19: E | D19: 18334 | E19: 5.38 | F19: 8.55 | G19: =+D19*E19% -> 986.3692 | H19: =+D19*F19% -> 1567.557 | I19: 7022 | J19: 7022 | K19: 5.3281401 | L19: 8.495685 | R19: =O19+J19 -> 7022 | S19: =(J19*K19%)+(O19*P19%) -> 374.142 | T19: =(J19*L19%)+(O19*Q19%) -> 596.567 | U19: 0 | V19: 0 | W19: 0 | X19: 0 | Y19: 0 | Z19: 0 | AA19: =X19*Y19% -> 0 | AB19: =X19*Z19% -> 0 | AF19: =AC19*AD19% -> 0 | AG19: =AC19*AE19% -> 0 | AH19: 25366 | AI19: 5.36 | AJ19: 8.53 | AK19: =AH19*AI19% -> 1359.6176 | AL19: =AH19*AJ19% -> 2163.7198 | AM19: =+D19+R19-AC19-AH19 -> -10 | AN19: =+G19+S19-AF19-AK19 -> 0.8936 | AO19: =+H19+T19-AG19-AL19 -> 0.4042 | AP19: =(AN19+AO19)/(S19+T19) -> 0.0013369609 | AQ19: =($AP$1*AN19+$AQ$1*AO19) -> 507.99263 | AR19: =(D19+J19+O19)-(X19+AH19) -> -10
B20: =+B18+1 -> 46062 | C20: M | D20: 25366 | E20: 5.36 | F20: 8.53 | G20: =+D20*E20% -> 1359.6176 | H20: =+D20*F20% -> 2163.7198 | I20: 6305 | J20: 6305 | K20: 5.2935289 | L20: 8.5433783 | R20: =O20+J20 -> 6305 | S20: =(J20*K20%)+(O20*P20%) -> 333.757 | T20: =(J20*L20%)+(O20*Q20%) -> 538.66 | U20: 5280 | V20: 82007 | W20: Hajipur | X20: 18790 | Y20: 5.15 | Z20: 8.19 | AA20: =X20*Y20% -> 967.685 | AB20: =X20*Z20% -> 1538.901 | AC20: 18690 | AD20: 5.35 | AE20: 8.48 | AF20: =AC20*AD20% -> 999.915 | AG20: =AC20*AE20% -> 1584.912 | AH20: 12891 | AI20: 5.35 | AJ20: 8.53 | AK20: =AH20*AI20% -> 689.6685 | AL20: =AH20*AJ20% -> 1099.6023 | AM20: =+D20+R20-AC20-AH20 -> 90 | AN20: =+G20+S20-AF20-AK20 -> 3.7911 | AO20: =+H20+T20-AG20-AL20 -> 17.8655 | AP20: =(AN20+AO20)/(S20+T20) -> 0.02482368 | AQ20: =($AP$1*AN20+$AQ$1*AO20) -> 6857.915 | AR20: =(D20+J20+O20)-(X20+AH20) -> -10
B21: =+B19+1 -> 46062 | C21: E | D21: 12891 | E21: 5.35 | F21: 8.53 | G21: =+D21*E21% -> 689.6685 | H21: =+D21*F21% -> 1099.6023 | I21: 7560 | J21: 7560 | K21: 5.4646693 | L21: 8.557791 | R21: =O21+J21 -> 7560 | S21: =(J21*K21%)+(O21*P21%) -> 413.129 | T21: =(J21*L21%)+(O21*Q21%) -> 646.969 | U21: 0 | V21: 0 | W21: 0 | X21: 0 | Y21: 0 | Z21: 0 | AA21: =X21*Y21% -> 0 | AB21: =X21*Z21% -> 0 | AF21: =AC21*AD21% -> 0 | AG21: =AC21*AE21% -> 0 | AH21: 20461 | AI21: 5.39 | AJ21: 8.54 | AK21: =AH21*AI21% -> 1102.8479 | AL21: =AH21*AJ21% -> 1747.3694 | AM21: =+D21+R21-AC21-AH21 -> -10 | AN21: =+G21+S21-AF21-AK21 -> -0.0504 | AO21: =+H21+T21-AG21-AL21 -> -0.7981 | AP21: =(AN21+AO21)/(S21+T21) -> -0.0008003977 | AQ21: =($AP$1*AN21+$AQ$1*AO21) -> -254.40397 | AR21: =(D21+J21+O21)-(X21+AH21) -> -10
