Workbook

Sheet Sheet1
B2: Union Code | C2: BMC Code | D2: MPG Code | E2: Route Code | F2: Farmer Code
B3: 1 Digit | C3: 4 Digit | D3: 8 Digit | E3: 6 Digit | F3: 12 digit
B4: State | C4: State+ 3 digit BMC | D4: BMC code +3 digit mpg code | E4: BMC+2 digit route | F4: MPG code + 4 digit existing Farmer
B5: 1 | C5: 1001 | D5: =C5&"001" -> 1001001 | E5: =C5&"01" -> 100101 | F5: =D5&"XXXX" -> 1001001XXXX

Sheet BMC Master
B1: BMC Master
A2: State | B2: BMC Name | C2: BMC Code (Old) | D2: MCC | E2: New BMC Code | F2: Type | G2: Address | H2: Region | I2: Service Provider Name | J2: Service Provider Contact | K2: Owner Name | L2: Owner Contact Number | M2: Bank Name | N2: Bank Account Number | O2: Bank Branch Name | P2: Bank IFSC Code | Q2: Tank1 Cap(Ltrs) | R2: Tank2 Cap(Ltrs) | S2: Tank3 Cap(Ltrs) | T2: Operated By | U2: Status
A3: Bihar | B3: Majhaul | C3: BMC Code : 0001 | D3: BMC Code : 0001 | E3: 1001 | F3: BMC | G3: C/O REENA KUMARI, W/O LATE SANJEEV KUMAR,VILL + P.O. :MOHANPUR,P.S.: MUFASSIL, BLOCK: BEGUSARAI,DIST: BEGUSARAI, PIN: 851131 | H3: Bihar | I3: Daya Society | J3: 7004176432 | K3: Daya Society | L3: =J3 -> 7004176432 | M3: HDFC BANK LTD | N3: 50100063899098 | O3: Munger | P3: HDFC0002684 | Q3: 5000 | R3: N/A | S3: N/A | T3: Daya Society | U3: Active
A4: Bihar | B4: Laldiyara | C4: BMC Code : 0003 | D4: BMC Code : 0003 | E4: 1002 | F4: BMC | G4: C/O AKASH KUMAR, S/O Indredev PD. Singh,VILL: LALDIARA,P.O.: KHUTAH,P.S.: PIPARIYA,BLOCK: BARHAIYA, DIST : LAKHISARAI , PIN : 811302. | H4: Bihar | I4: Akash Kumar | J4: 8298681512 | K4: AKASH KUMAR | L4: 8298681512 | M4: IDBI Bank | N4: 2066102000000170 | O4: LAKHISARAI | P4: IBKL0002066 | Q4: 5000 | R4: 2000 | S4: NA | T4: Akash Kumar | U4: Active
A5: Bihar | B5: Asarganj | C5: BMC Code : 0005 | D5: BMC Code : 0005 | E5: 1003 | F5: BMC | G5: C/O RENU CHOWDURY, W/O JAY SHANKAR KUMAR,VILL + P.O.:Chatmadih,Asarganj, BLOCK: Sultanganj,DIST: Bhagalpur, PIN: 813213 | H5: Bihar | I5: Akash Kumar | J5: 8298681512 | K5: AKASH KUMAR | L5: 8298681512 | M5: IDBI Bank | N5: 2066102000000170 | O5: LAKHISARAI | P5: IBKL0002066 | Q5: 5000 | R5: 2000 | S5: NA | T5: Akash Kumar | U5: Active
A6: Bihar | B6: Tofir | C6: BMC Code : 0006 | D6: BMC Code : 0006 | E6: 1004 | F6: BMC | G6: Pramod Yadav | H6: Bihar | I6: Pramod Yadav | J6: 7667356614 | K6: Pramod Yadav | L6: 7667356614 | M6: NA | N6: NA | O6: NA | P6: NA | Q6: 2000 | R6: NA | S6: NA | T6: Pramod Yadav | U6: Active
A7: Bihar | B7: Jhandapur | C7: BMC Code : 0007 | D7: BMC Code : 0007 | E7: 1005 | F7: BMC | G7: C/O RENU CHOWDURY, W/O JAY SHANKAR KUMAR,VILL + P.O. :JHANDAPUR,P.S.: BIHPUR, BLOCK: BIHPUR,DIST: BHAGALPUR, PIN: 853201 | H7: Bihar | I7: Daya Society | J7: 7004176432 | K7: Daya Society | L7: =J7 -> 7004176432 | M7: HDFC BANK LTD | N7: 50100063899098 | O7: Munger | P7: HDFC0002684 | Q7: 5000 | R7: N/A | S7: N/A | T7: Daya Society | U7: Active
A8: Bihar | B8: Sonvarsha | C8: BMC Code : 0009 | D8: BMC Code : 0009 | E8: 1006 | F8: BMC | G8: C/O SRI NARAYAN SINGH ,VILL: SON VARSHA,P.O. AKAH KURHA,P.S.: SAMBHO,BLOCK:MATIHANI,DIST: BEGUSARAI,PIN: 811106 | H8: Bihar | I8: Narayan Singh | J8: 8051560453 | K8: Narayan Singh | L8: 8051560453 | M8: State Bank of India | N8: 35425786740 | O8: SURYAGARHA | P8: SBIN0012593 | Q8: 5000 | R8: 2000 | S8: NA | T8: Narayan Singh | U8: Active
A9: Bihar | B9: Araria | C9: BMC Code : 0011 | D9: BMC Code : 0011 | E9: 1007 | F9: BMC | G9: C/O Shyam Nanadan, Village English Tola, Maheshkhunt | H9: Bihar | I9: Ankesh Kumar | J9: 9110950521 | K9: ANKESH KUMAR | L9: 9110950521 | M9: Central Bank of India | N9: 3182104680 | O9: MAHESHKHUNT | P9: CBIN0283921 | Q9: 2000 | R9: NA | S9: NA | T9: Ankesh Kumar | U9: Active
A10: Bihar | B10: Teghra | C10: BMC Code : 0012 | D10: BMC Code : 0012 | E10: 1008 | F10: BMC | G10: C/O RAJIV CHOWDHARY,VILL: MERSHITI, P.O. :TEGHRA,P.S.: + BLOCK: SAHIBPUR KAMAL,DIST: BEGUSARAI, PIN: 851133 | H10: Bihar | I10: Maa Katyani tradres | J10: 9113108485 | K10: AVIJIT KUMAR | L10: 9113108485 | M10: Bihar Gramin Bank | N10: 38310210001090 | O10: Sultanganj | P10: UCBA0RRBBKG | Q10: 5000 | R10: 2000 | S10: NA | T10: Maa Katyani tradres | U10: Active
A11: Bihar | B11: Halsi | C11: BMC Code : 0013 | D11: BMC Code : 0013 | E11: 1009 | F11: BMC | G11: C/O NITESH KUMAR, S/O Sudhir Singh,VILL: AURE,P.O.: AURE,P.S.: RAMGARH,BLOCK: RAMGARH, DIST : LAKHISARAI , PIN : 811311. | H11: Bihar | I11: Nitesh Kumar | J11: 8877443654 | K11: NITESH KUMAR | L11: 8877443654 | M11: State Bank of India | N11: 10889828369 | O11: Barauni | P11: SBIN0002912 | Q11: 5000 | R11: 2000 | S11: NA | T11: Nitesh Kumar | U11: Active
A12: Bihar | B12: Parbatta | C12: BMC Code : 0015 | D12: BMC Code : 0015 | E12: 1010 | F12: BMC | G12: C/O RENU CHOWDURY, W/O JAY SHANKAR KUMAR,VILL + P.O. :JHANDAPUR,P.S.: BIHPUR, BLOCK: BIHPUR,DIST: BHAGALPUR, PIN: 853201 | H12: Bihar | I12: Daya Society | J12: 7004176432 | K12: Daya Society | L12: =J12 -> 7004176432 | M12: HDFC BANK LTD | N12: 50100063899098 | O12: Munger | P12: HDFC0002684 | Q12: 5000 | R12: N/A | S12: N/A | T12: Daya Society | U12: Active
A13: Bihar | B13: Sahibpur Kamal | C13: BMC Code : 0016 | D13: BMC Code : 0016 | E13: 1011 | F13: BMC | G13: C/O MONORAMA DEVI, W/O SUDHIR YADAV,VILL + P.O. :SAHIBPUR KAMAL,P.S.: + BLOCK: SAHIBPUR KAMAL,DIST: BEGUSARAI, PIN: 851217 | H13: Bihar | I13: Daya Society | J13: 7004176432 | K13: Daya Society | L13: =J13 -> 7004176432 | M13: HDFC BANK LTD | N13: 50100063899098 | O13: Munger | P13: HDFC0002684 | Q13: 10000 | R13: 2000 | S13: N/A | T13: Daya Society | U13: Active
A14: Bihar | B14: DalsinghSarai | C14: BMC Code : 0017 | D14: BMC Code : 0017 | E14: 1012 | F14: BMC | G14: Jai Hanuman Agrotech Pvt Ltd, PO-Madhaipur, Dalsinghsarai, Samastipur, Bihar - 848503 | H14: Bihar | I14: Daya Society | J14: 7004176432 | K14: Daya Society | L14: =J14 -> 7004176432 | M14: HDFC BANK LTD | N14: 50100063899098 | O14: Munger | P14: HDFC0002684 | Q14: 5000 | R14: N/A | S14: N/A | T14: Daya Society | U14: Active
A15: Bihar | B15: Musrigharari | C15: BMC Code : 0018 | D15: BMC Code : 0018 | E15: 1013 | F15: BMC | G15: C/O Vijay Kumar Sharma, Bandhua Bujurg, dihvarni, P.O Bandhua, Musrigharari,Samastipur, Bihar, PIN : 848101 | H15: Bihar | I15: Daya Society | J15: 7004176432 | K15: Daya Society | L15: =J15 -> 7004176432 | M15: HDFC BANK LTD | N15: 50100063899098 | O15: Munger | P15: HDFC0002684 | Q15: 5000 | R15: 2000 | S15: N/A | T15: Daya Society | U15: Active
A16: Bihar | B16: Dumraon | C16: BMC Code : 0024 | D16: BMC Code : 0024 | E16: 1014 | F16: BMC | G16: C/O Kumari Anar Pari, Mohanpur, Samastipur, Bihar, PIN :848506 | H16: Bihar | I16: Daya Society | J16: 7004176432 | K16: Daya Society | L16: =J16 -> 7004176432 | M16: HDFC BANK LTD | N16: 50100063899098 | O16: Munger | P16: HDFC0002684 | Q16: 5000 | R16: 2000 | S16: N/A | T16: Daya Society | U16: Active
A17: Bihar | B17: WALIPUR-4 | C17: RMC Code : 1028 | D17: BMC Code : 0003 | E17: 1015 | F17: RMC | G17: =B17 -> WALIPUR-4 | H17: Bihar | I17: Papu Yadav | J17: 9534389898 | K17: =I17 -> Papu Yadav | L17: 9534389898 | M17: PUNJAB NATIONAL BANK | N17: 6489000100022237 | O17: PIPARIA | P17: PUNB0648900 | Q17: 1000 | R17: No | S17: No | T17: =K17 -> Papu Yadav | U17: Active
A18: Bihar | B18: REHUA | C18: RMC Code : 1030 | D18: BMC Code : 0003 | E18: 1016 | F18: RMC | G18: =B18 -> REHUA | H18: =H17 -> Bihar | I18: Shubodh Singh | J18: 7324849044 | K18: =I18 -> Shubodh Singh | L18: 7324849044 | M18: PUNJAB NATIONAL BANK, NEFT CENTRALIZED PROCESSING CENTRE FOR MADHYA BIHAR GRAMIN BANK | N18: 31210110004732 | O18: NEFT NODAL BRANCH MBGB RRB | P18: PUNB0MBGB06 | Q18: 1000 | R18: No | S18: No | T18: =K18 -> Shubodh Singh | U18: Active
A19: Bihar | B19: ADARSH LAKSHMIPUR | C19: RMC Code : 1032 | D19: BMC Code : 0003 | E19: 1017 | F19: RMC | G19: =B19 -> ADARSH LAKSHMIPUR | H19: =H18 -> Bihar | I19: Ashok Yadav | J19: 7644976160 | K19: =I19 -> Ashok Yadav | L19: 7644976160 | M19: PUNJAB NATIONAL BANK, NEFT CENTRALIZED PROCESSING CENTRE FOR MADHYA BIHAR GRAMIN BANK | N19: 31110110008068 | O19: NEFT NODAL BRANCH MBGB RRB | P19: PUNB0MBGB06 | Q19: 1000 | R19: No | S19: No | T19: =K19 -> Ashok Yadav | U19: Active
A20: Bihar | B20: Gaachhi tola | C20: RMC Code : 1034 | D20: BMC Code : 0003 | E20: 1018 | F20: RMC | G20: =B20 -> Gaachhi tola | H20: =H19 -> Bihar | I20: Niraj Kumar | J20: 8238681512 | K20: =I20 -> Niraj Kumar | L20: 8238681512 | M20: ALLAHABAD BANK | N20: 50402121788 | O20: LAKHISARAI | P20: ALLA0213239 | Q20: 1000 | R20: No | S20: No | T20: =K20 -> Niraj Kumar | U20: Active
A21: Bihar | B21: GOMUKH WALIPUR | C21: RMC Code : 1165 | D21: BMC Code : 0003 | E21: 1019 | F21: RMC | G21: =B21 -> GOMUKH WALIPUR | H21: =H20 -> Bihar | I21: Saket Bihari | J21: 9304548632 | K21: =I21 -> Saket Bihari | L21: 9304548632 | M21: PUNJAB NATIONAL BANK, NEFT CENTRALIZED PROCESSING CENTRE FOR MADHYA BIHAR GRAMIN BANK | N21: 31310110024259 | O21: NEFT NODAL BRANCH MBGB RRB | P21: PUNB0MBGB06 | Q21: 1000 | R21: No | S21: No | T21: =K21 -> Saket Bihari | U21: Active
A22: Bihar | B22: SHIVNAR-2 | C22: RMC Code : 8025 | D22: BMC Code : 0003 | E22: 1020 | F22: RMC | G22: =B22 -> SHIVNAR-2 | H22: =H21 -> Bihar | I22: Chandan Singh | J22: 8935911924 | K22: =I22 -> Chandan Singh | L22: 8935911924 | M22: BANK OF BARODA | N22: 12180100014660 | O22: MOKAMEH, DIST PATNA | P22: BARB0MOKAME | Q22: 1000 | R22: No | S22: No | T22: =K22 -> Chandan Singh | U22: Active
A23: Bihar | B23: CHAWKI DAFA DUMRA | C23: RMC Code : 8063 | D23: BMC Code : 0003 | E23: 1021 | F23: RMC | G23: =B23 -> CHAWKI DAFA DUMRA | H23: =H22 -> Bihar | I23: Sanjeev Singh | J23: 9572088246 | K23: =I23 -> Sanjeev Singh | L23: 9572088246 | M23: PUNJAB NATIONAL BANK | N23: 2560000100105433 | O23: MARANCHI | P23: PUNB0256000 | Q23: 1000 | R23: No | S23: No | T23: =K23 -> Sanjeev Singh | U23: Active
A24: Bihar | B24: VISHWASHPUR | C24: RMC Code : 4023 | D24: BMC Code : 0005 | E24: 1022 | F24: RMC | G24: =B24 -> VISHWASHPUR | H24: =H23 -> Bihar | I24: Balkrishna Sharma | J24: 8298910551 | K24: =I24 -> Balkrishna Sharma | L24: 8298910551 | M24: HDFC BANK LTD | N24: 50200021210356 | O24: BHAGALPUR - BIHAR | P24: HDFC0000765 | Q24: 1000 | R24: No | S24: No | T24: =K24 -> Balkrishna Sharma | U24: Active
A25: Bihar | B25: KHARIYA | C25: RMC Code : 4036 | D25: BMC Code : 0005 | E25: 1023 | F25: RMC | G25: =B25 -> KHARIYA | H25: =H24 -> Bihar | I25: Rinku Kumar | J25: 8521112911 | K25: =I25 -> Rinku Kumar | L25: 8521112911 | M25: UCO BANK | N25: 12470110024881 | O25: KARHARIA | P25: UCBA0001247 | Q25: 1000 | R25: No | S25: No | T25: =K25 -> Rinku Kumar | U25: Active
A26: Bihar | B26: KUMARPUIR KATHARA | C26: RMC Code : 4039 | D26: BMC Code : 0005 | E26: 1024 | F26: RMC | G26: =B26 -> KUMARPUIR KATHARA | H26: =H25 -> Bihar | I26: Sudhanshu Singh | J26: 9006475690 | K26: =I26 -> Sudhanshu Singh | L26: 9006475690 | M26: HDFC BANK LTD | N26: 50200023079752 | O26: BHAGALPUR - BIHAR | P26: HDFC0000765 | Q26: 1000 | R26: No | S26: No | T26: =K26 -> Sudhanshu Singh | U26: Active
A27: Bihar | B27: KUDHIYA MPG | C27: RMC Code : 4080 | D27: BMC Code : 0005 | E27: 1025 | F27: RMC | G27: =B27 -> KUDHIYA MPG | H27: =H26 -> Bihar | I27: Davesh Kumar | J27: 8292786040 | K27: =I27 -> Davesh Kumar | L27: 8292786040 | M27: HDFC BANK LTD | N27: 50200022297181 | O27: BHAGALPUR - BIHAR | P27: HDFC0000765 | Q27: 1000 | R27: No | S27: No | T27: =K27 -> Davesh Kumar | U27: Active
A28: Bihar | B28: SHAHJADPUR MPG | C28: RMC Code : 4094 | D28: BMC Code : 0005 | E28: 1026 | F28: RMC | G28: =B28 -> SHAHJADPUR MPG | H28: =H27 -> Bihar | I28: Nirpesh Singh | J28: 9934008772 | K28: =I28 -> Nirpesh Singh | L28: 9934008772 | M28: PUNJAB NATIONAL BANK, NEFT CENTRALIZED PROCESSING CENTRE FOR MADHYA BIHAR GRAMIN BANK | N28: 36060110023375 | O28: NEFT NODAL BRANCH MBGB RRB | P28: PUNB0MBGB06 | Q28: 1000 | R28: No | S28: No | T28: =K28 -> Nirpesh Singh | U28: Active
A29: Bihar | B29: KHARAYA | C29: RMC Code : 5027 | D29: BMC Code : 0005 | E29: 1027 | F29: RMC | G29: =B29 -> KHARAYA | H29: =H28 -> Bihar | I29: Uday Singh | J29: 9709633563 | K29: =I29 -> Uday Singh | L29: 9709633563 | M29: UCO BANK | N29: 12710110022276 | O29: AKBARNAGAR | P29: UCBA0001271 | Q29: 1000 | R29: No | S29: No | T29: =K29 -> Uday Singh | U29: Active
A30: Bihar | B30: Pachgachiya Tola | C30: RMC Code : 7101 | D30: BMC Code : 0007 | E30: 1028 | F30: RMC | G30: =B30 -> Pachgachiya Tola | H30: =H29 -> Bihar | I30: Anil Kumar Singh | J30: 9931098422 | K30: =I30 -> Anil Kumar Singh | L30: 9931098422 | M30: Punjab National Bank | N30: 36350110035671 | O30: NEFT NODAL BRANCH MBGB RRB | P30: PUNB0MBGB06 | Q30: 1000 | R30: No | S30: No | T30: =K30 -> Anil Kumar Singh | U30: Active
A31: Bihar | B31: FARDA - 3 | C31: RMC Code : 0006 | D31: BMC Code : 0009 | E31: 1029 | F31: RMC | G31: =B31 -> FARDA - 3 | H31: =H30 -> Bihar | I31: Pankaj Kumar Thakur | J31: 9507082150 | K31: =I31 -> Pankaj Kumar Thakur | L31: 9507082150 | M31: PUNJAB NATIONAL BANK, NEFT CENTRALIZED PROCESSING CENTRE FOR MADHYA BIHAR GRAMIN BANK | N31: 32300110007597 | O31: NEFT NODAL BRANCH MBGB RRB | P31: PUNB0MBGB06 | Q31: 1000 | R31: No | S31: No | T31: =K31 -> Pankaj Kumar Thakur | U31: Active
A32: Bihar | B32: CHANDANPURA | C32: RMC Code : 0033 | D32: BMC Code : 0009 | E32: 1030 | F32: RMC | G32: =B32 -> CHANDANPURA | H32: =H31 -> Bihar | I32: Dharmraj Kumar | J32: 7050165761 | K32: =I32 -> Dharmraj Kumar | L32: 7050165761 | M32: PUNJAB NATIONAL BANK, NEFT CENTRALIZED PROCESSING CENTRE FOR MADHYA BIHAR GRAMIN BANK | N32: 31310110031055 | O32: NEFT NODAL BRANCH MBGB RRB | P32: PUNB0MBGB06 | Q32: 1000 | R32: No | S32: No | T32: =K32 -> Dharmraj Kumar | U32: Active
A33: Bihar | B33: MANIKPUR | C33: RMC Code : 0056 | D33: BMC Code : 0009 | E33: 1031 | F33: RMC | G33: =B33 -> MANIKPUR | H33: =H32 -> Bihar | I33: Ashok Mahto | J33: 7488720757 | K33: =I33 -> Ashok Mahto | L33: 7488720757 | M33: PUNJAB NATIONAL BANK, NEFT CENTRALIZED PROCESSING CENTRE FOR MADHYA BIHAR GRAMIN BANK | N33: 31200110023287 | O33: NEFT NODAL BRANCH MBGB RRB | P33: PUNB0MBGB06 | Q33: 1000 | R33: No | S33: No | T33: =K33 -> Ashok Mahto | U33: Active
... A37: Bihar | B37: NOWAGADHI | C37: RMC Code : 5046 | D37: BMC Code : 0009 | E37: 1035 | F37: RMC | G37: =B37 -> NOWAGADHI | H37: =H36 -> Bihar | I37: Rajeev Ranjan | J37: 9955524132 | K37: =I37 -> Rajeev Ranjan | L37: 9955524132 | M37: HDFC BANK LTD | N37: 50200004092945 | O37: JAMALPUR | P37: HDFC0002531 | Q37: 1000 | R37: No | S37: No | T37: =K37 -> Rajeev Ranjan | U37: Active
A38: Bihar | B38: MAHADAT PUR 2 | C38: RMC Code : 7014 | D38: BMC Code : 0007 | E38: 1036 | F38: RMC | G38: =B38 -> MAHADAT PUR 2 | H38: =H37 -> Bihar | I38: Sunil KR | J38: 9199843014 | K38: =I38 -> Sunil KR | L38: 9199843014 | M38: HDFC BANK LTD | N38: 50200024326702 | O38: KHAGARIA | P38: HDFC0002127 | Q38: 1000 | R38: No | S38: No | T38: =K38 -> Sunil KR | U38: Active
A39: Bihar | B39: KATHELA TOLA TELDHI | C39: RMC Code : 7022 | D39: BMC Code : 0007 | E39: 1037 | F39: RMC | G39: =B39 -> KATHELA TOLA TELDHI | H39: =H38 -> Bihar | I39: Prem Krishan Murari | J39: 9709351270 | K39: =I39 -> Prem Krishan Murari | L39: 9709351270 | M39: PUNJAB NATIONAL BANK, NEFT CENTRALIZED PROCESSING CENTRE FOR MADHYA BIHAR GRAMIN BANK | N39: 36160110050689 | O39: NEFT NODAL BRANCH MBGB RRB | P39: PUNB0MBGB06 | Q39: 1000 | R39: No | S39: No | T39: =K39 -> Prem Krishan Murari | U39: Active
A40: Bihar | B40: SONBARSHA 1 | C40: RMC Code : 7031 | D40: BMC Code : 0007 | E40: 1038 | F40: RMC | G40: =B40 -> SONBARSHA 1 | H40: =H39 -> Bihar | I40: Mani Kant Kumar | J40: 8298977539 | K40: =I40 -> Mani Kant Kumar | L40: 8298977539 | M40: ALLAHABAD BANK | N40: 50240238674 | O40: THANA BIHPUR | P40: ALLA0210225 | Q40: 1000 | R40: No | S40: No | T40: =K40 -> Mani Kant Kumar | U40: Active
A41: Bihar | B41: GANOUL | C41: RMC Code : 7070 | D41: BMC Code : 0007 | E41: 1039 | F41: RMC | G41: =B41 -> GANOUL | H41: =H40 -> Bihar | I41: Ram Pravesh Mishra | J41: 9771620411 | K41: =I41 -> Ram Pravesh Mishra | L41: 9771620411 | M41: PUNJAB NATIONAL BANK, NEFT CENTRALIZED PROCESSING CENTRE FOR MADHYA BIHAR GRAMIN BANK | N41: 36200110047171 | O41: NEFT NODAL BRANCH MBGB RRB | P41: PUNB0MBGB06 | Q41: 1000 | R41: No | S41: No | T41: =K41 -> Ram Pravesh Mishra | U41: Active
A42: Bihar | B42: Gauripur | C42: RMC Code : 7078 | D42: BMC Code : 0007 | E42: 1040 | F42: RMC | G42: =B42 -> Gauripur | H42: =H41 -> Bihar | I42: Chandan Kumar | J42: 9534770675 | K42: =I42 -> Chandan Kumar | L42: 9534770675 | M42: CENTRAL BANK OF INDIA | N42: 3598331075 | O42: GAURIPUR | P42: CBIN0282011 | Q42: 1000 | R42: No | S42: No | T42: =K42 -> Chandan Kumar | U42: Active
A43: Bihar | B43: Bhramarpur | C43: RMC Code : 7088 | D43: BMC Code : 0007 | E43: 1041 | F43: RMC | G43: =B43 -> Bhramarpur | H43: =H42 -> Bihar | I43: Chandan Kumar Singh | J43: 7634979693 | K43: =I43 -> Chandan Kumar Singh | L43: 7634979693 | M43: UNITED BANK OF INDIA | N43: 0963010092825 | O43: JAIRAMPUR | P43: UTBI0JRPJ42 | Q43: 1000 | R43: No | S43: No | T43: =K43 -> Chandan Kumar Singh | U43: Active
...

Sheet MPG Master
A1: MPG Master | I1: 1+3+3
A2: Sl. No. | B2: State | C2: Approved By | D2: MPG Name | E2: DOC | F2: EIPL Code | I2: New MPG Code | J2: Old Code | K2: Payment Type | L2: Address | M2: Connected BMC /RMC | N2: New BMC Code | O2: Sahayak Name | P2: Sahayak DOB | Q2: Sahayak's Father Name | R2: Sahayak Contact No | S2: Bank Account Number | T2: Bank Name | U2: Bank IFSC Code | V2: Branch Name | W2: Supervisor Name | X2: Route | Y2: Route Code
A3: 1 | B3: Bihar | C3: Jayant Sir | D3: Gomukh Haiwatpur | E3: 45450 | F3: New | G3: 73 | H3: =TEXT(G3,"0000") -> 0073 | I3: =CONCATENATE(N3,H3) -> 10010073 | K3: Direct | L3: Haiwatpur, Koria, Begusarai | M3: BMC Code : 0001 | N3: =VLOOKUP(M3,'BMC Master'!$C$3:$E$100,3,0) -> 1001 | O3: Vijay Shankar Singh | P3: 27941 | Q3: Rameshwar Singh | R3: 7549435287 | S3: 42979044329 | T3: SBI | U3: SBIN0005858 | V3: Manjhaul | W3: Gopal Kumar | X3: Birpur | Y3: 3
B4: Bihar | C4: Jayant Sir | D4: Gomukh Meghaul | E4: 45450 | F4: New | G4: 74 | H4: =TEXT(G4,"0000") -> 0074 | I4: =CONCATENATE(N4,H4) -> 10010074 | K4: Direct | L4: Ward no. 5, Meghaul, Begusarai, 848202 | M4: BMC Code : 0001 | N4: =VLOOKUP(M4,'BMC Master'!$C$3:$E$100,3,0) -> 1001 | O4: Shanti Kumari | P4: 28126 | Q4: W/O Amit Prasad | R4: 9534887216 | S4: 09990110090459 | T4: UCO Bank | U4: UCBA0000999 | V4: Khodabandpur | W4: Gopal Kumar | X4: Garhpura | Y4: 1
B5: Bihar | C5: Jayant Sir | D5: Gomukh Dudhpura | E5: 45450 | F5: New | G5: 75 | H5: =TEXT(G5,"0000") -> 0075 | I5: =CONCATENATE(N5,H5) -> 10010075 | K5: Direct | L5: Ward no. 5, Dudhpura, Samastipur, Bihar | M5: BMC Code : 0001 | N5: =VLOOKUP(M5,'BMC Master'!$C$3:$E$100,3,0) -> 1001 | O5: Ranjit Kumar Yadav | P5: 29963 | Q5: Yugdev Yadav | R5: 6201132827 | S5: 11787606219 | T5: SBI | U5: SBIN0005904 | V5: Mangalgarh | W5: Gopal Kumar | X5: Garhpura-Paroria | Y5: 2
B6: Bihar | C6: Jayant Sir | D6: Gomukh Bhith-02 | E6: 45469 | F6: New | G6: 76 | H6: =TEXT(G6,"0000") -> 0076 | I6: =CONCATENATE(N6,H6) -> 10010076 | K6: Direct | L6: Ward No. 13,Bhith, Begusarai | M6: BMC Code : 0001 | N6: =VLOOKUP(M6,'BMC Master'!$C$3:$E$100,3,0) -> 1001 | O6: Dharmveer Kumar | P6: 35431 | Q6: Shivchandra Sah | R6: 7808020360 | S6: 15970110117729 | T6: UCO Bank | U6: UCBA0001597 | V6: Muzaffara | W6: Gopal Kumar | X6: Birpur | Y6: 100103
B7: Bihar | C7: Jayant Sir | D7: Pansalla-02 | E7: 45469 | F7: New | G7: 77 | H7: =TEXT(G7,"0000") -> 0077 | I7: =CONCATENATE(N7,H7) -> 10010077 | K7: Indirect | L7: Pansalla, Pansalla, Begusarai | M7: BMC Code : 0001 | N7: =VLOOKUP(M7,'BMC Master'!$C$3:$E$100,3,0) -> 1001 | O7: Sujeet Kumar Sahni | P7: 33739 | Q7: Suresh Sahni | R7: 8051102195 | S7: 11260110061558 | T7: UCO Bank | U7: UCBA0001126 | V7: Chaurahi | W7: Gopal Kumar | X7: Garhpura | Y7: 100101
B8: Bihar | C8: Jayant Sir | D8: Amit Kumar-Manjhaul | E8: 45469 | F8: New | G8: 78 | H8: =TEXT(G8,"0000") -> 0078 | I8: =CONCATENATE(N8,H8) -> 10010078 | K8: Indirect | L8: Manjhaul-02, Manjhaul, Cheria Bariarpur, Begusarai | M8: BMC Code : 0001 | N8: =VLOOKUP(M8,'BMC Master'!$C$3:$E$100,3,0) -> 1001 | O8: Amit Kumar | P8: 27030 | Q8: Ram Babu Singh | R8: 9608617997 | S8: 734001001022 | T8: Begusarai Central Cooperative Bank | U8: IBKL01077BD | V8: Manjhaul | W8: Gopal Kumar | X8: Garhpura | Y8: 100101
B9: Bihar | C9: Jayant Sir | D9: Chandan Dairy | E9: 45469 | F9: New | G9: 79 | H9: =TEXT(G9,"0000") -> 0079 | I9: =CONCATENATE(N9,H9) -> 10010079 | K9: Indirect | L9: Ward no. 11, Bagraha,Ahilwara, Samastipur | M9: BMC Code : 0001 | N9: =VLOOKUP(M9,'BMC Master'!$C$3:$E$100,3,0) -> 1001 | O9: Chandan Kumar | P9: 34252 | Q9: Jayanarayan Yadav | R9: 9031975695 | S9: 24690210002100 | T9: UCO Bank | U9: UCBA0002469 | V9: Garhpura | W9: Gopal Kumar | X9: Garhpura | Y9: 100101
B10: Bihar | C10: Jayant Sir | D10: Gomukh Paguraha | E10: 45499 | F10: New | G10: =IF(M10=M9,G9+1,1) -> 80 | H10: =TEXT(G10,"0000") -> 0080 | I10: =CONCATENATE(N10,H10) -> 10010080 | K10: Direct | L10: Ward no. 3, Paguraha, Kuriawan, Begusarai | M10: BMC Code : 0001 | N10: =VLOOKUP(M10,'BMC Master'!$C$3:$E$100,3,0) -> 1001 | O10: Sujeet Kumar | P10: 36802 | Q10: Arvind Yadav | R10: 9113187070 | S10: 38167744234 | T10: SBI | U10: SBIN0006369 | V10: Garhpura | W10: Gopal Kumar | X10: Garhpura | Y10: 100101
B11: Bihar | C11: Jayant Sir | D11: Gomukh Dharampur | E11: 45499 | F11: New | G11: =IF(M11=M10,G10+1,1) -> 81 | H11: =TEXT(G11,"0000") -> 0081 | I11: =CONCATENATE(N11,H11) -> 10010081 | K11: Direct | L11: Dharampur, Begusarai | M11: BMC Code : 0001 | N11: =VLOOKUP(M11,'BMC Master'!$C$3:$E$100,3,0) -> 1001 | O11: Ramdev Singh | P11: 24473 | Q11: Lakhan Singh | R11: 8936846745 | S11: 33739601259 | T11: SBI | U11: SBIN0008311 | V11: Bikrampur | W11: Gopal Kumar | X11: Birpur Route | Y11: 100103
B12: Bihar | C12: Jayant Sir | D12: Gomukh Sharmatola Sahuri | E12: 45566 | F12: New | G12: =IF(M12=M11,G11+1,1) -> 82 | H12: =TEXT(G12,"0000") -> 0082 | I12: =CONCATENATE(N12,H12) -> 10010082 | K12: Direct | L12: Sahuri, Ward no. 08, Sahuri, Begusarai | M12: BMC Code : 0001 | N12: =VLOOKUP(M12,'BMC Master'!$C$3:$E$100,3,0) -> 1001 | O12: Manju Devi | P12: 29952 | Q12: Udaysankar Sharma | R12: 7634894581 | S12: 38020100000534 | T12: Bihar Gramin Bank | U12: PUNB0MBGB06 | V12: Babhanganwan | W12: Rishu Raj | X12: Birpur | Y12: 100103
B13: Bihar | C13: Jayant Sir | D13: Bakhri- Rajaram Mahto | E13: 45566 | F13: New | G13: =IF(M13=M12,G12+1,1) -> 83 | H13: =TEXT(G13,"0000") -> 0083 | I13: =CONCATENATE(N13,H13) -> 10010083 | K13: Indirect | L13: Madhua, Ghaghra Bakhri, Ghaghra, Begusarai | M13: BMC Code : 0001 | N13: =VLOOKUP(M13,'BMC Master'!$C$3:$E$100,3,0) -> 1001 | O13: Rajaram Mahto | P13: 27760 | Q13: Parbhu Mahto | R13: 9155339445 | S13: 14910100003014 | T13: UCO Bank | U13: UCBA0001491 | V13: Gangraho | W13: Gopal Kumar | X13: Paroria | Y13: 100102
B14: Bihar | C14: Jayant Sir | D14: Sangat- Sanjeev Kumar | E14: 45566 | F14: New | G14: =IF(M14=M13,G13+1,1) -> 84 | H14: =TEXT(G14,"0000") -> 0084 | I14: =CONCATENATE(N14,H14) -> 10010084 | K14: Indirect | L14: Ward no. 10, Manjhaul-2, Manjhaul, Begusarai | M14: BMC Code : 0001 | N14: =VLOOKUP(M14,'BMC Master'!$C$3:$E$100,3,0) -> 1001 | O14: Sanjeev Kumar | P14: 28550 | Q14: Binod Prashad Singh | R14: 7549528547 | S14: 11602848785 | T14: State Bank of India | U14: SBIN0005858 | V14: ADB Manjhaul | W14: Rishu Raj | X14: Birpur Route | Y14: 100103
B15: Bihar | C15: Jayant Sir | D15: Pustakalay Chowk Manjhaul- Amit Kumar | E15: 45566 | F15: New | G15: =IF(M15=M14,G14+1,1) -> 85 | H15: =TEXT(G15,"0000") -> 0085 | I15: =CONCATENATE(N15,H15) -> 10010085 | K15: Indirect | L15: Near Pustakalay Chowk, Manjhaul-01, Manjhaul, Begusarai | M15: BMC Code : 0001 | N15: =VLOOKUP(M15,'BMC Master'!$C$3:$E$100,3,0) -> 1001 | O15: Amit Kumar | P15: 33608 | Q15: Mahesh Prasad Singh | R15: 9570916452 | S15: 11990110025918 | T15: UCO Bank | U15: UCBA0001199 | V15: Manjhaul | W15: Rishu Raj | X15: Birpur Route | Y15: 100103
B16: Bihar | C16: Jayant Sir | D16: Gomukh Garhi Bisanpur | E16: 45596 | F16: New | G16: =IF(M16=M15,G15+1,1) -> 86 | H16: =TEXT(G16,"0000") -> 0086 | I16: =CONCATENATE(N16,H16) -> 10010086 | K16: Direct | L16: Ward no. 06, Garhi Bisanpur,Samastipur | M16: BMC Code : 0001 | N16: =VLOOKUP(M16,'BMC Master'!$C$3:$E$100,3,0) -> 1001 | O16: Ramuday Ranjan | P16: 29077 | Q16: Rajaram Yadav | R16: 9818426802 | S16: 30634963956 | T16: SBI | U16: SBIN0002944 | V16: Hasanpur | W16: Gopal Kumar | X16: Kumbhi | Y16: 100101
B17: Bihar | C17: Jayant Sir | D17: Bagaraha-Gopal Yadav | E17: 45596 | F17: New | G17: =IF(M17=M16,G16+1,1) -> 87 | H17: =TEXT(G17,"0000") -> 0087 | I17: =CONCATENATE(N17,H17) -> 10010087 | K17: Indirect | L17: Bagaraha, ward no. 11, Ahilwara | M17: BMC Code : 0001 | N17: =VLOOKUP(M17,'BMC Master'!$C$3:$E$100,3,0) -> 1001 | O17: Gopal Yadav | P17: 19360 | Q17: Ramautar Yadav | R17: 7857839214 | S17: 30624256826 | T17: SBI | U17: SBIN0002944 | V17: Hasanpur | W17: Gopal Kumar | X17: Kumbhi | Y17: 100101
B18: Bihar | C18: Jayant Sir | D18: Gomukh Gudaar | E18: 45619 | F18: New | G18: =IF(M18=M17,G17+1,1) -> 88 | H18: =TEXT(G18,"0000") -> 0088 | I18: =CONCATENATE(N18,H18) -> 10010088 | K18: Direct | L18: Gudaar, Ward No. 7, Shitalrampur, Mauji Harisingh, Garhpura | M18: BMC Code : 0001 | N18: =VLOOKUP(M18,'BMC Master'!$C$3:$E$100,3,0) -> 1001 | O18: Savita Kumari | P18: 34717 | Q18: Ranjeet Kumar | R18: 7645082681 | S18: 2288000100136409 | T18: PNB | U18: PUNB0228800 | V18: Bakhri | W18: Gopal Kumar | X18: Kumbhi | Y18: 100101
B19: Bihar | C19: Jayant Sir | D19: Gomukh Barkurwa | E19: 45619 | F19: New | G19: =IF(M19=M18,G18+1,1) -> 89 | H19: =TEXT(G19,"0000") -> 0089 | I19: =CONCATENATE(N19,H19) -> 10010089 | K19: Direct | L19: Barkurwa, Ward no. 7, Garhpura, Begusarai | M19: BMC Code : 0001 | N19: =VLOOKUP(M19,'BMC Master'!$C$3:$E$100,3,0) -> 1001 | O19: Laxmi Devi | P19: 29587 | Q19: Suresh Yadav | R19: 9570260022 | S19: 38100110055347 | T19: Bihar Gramin Bank | U19: PUNB0MBGB06 | V19: Garhpura | W19: Gopal Kumar | X19: Kumbhi | Y19: 100101
B20: Bihar | C20: Jayant Sir | D20: Sonma- Khushilal Yadav | E20: 45637 | F20: New | G20: =IF(M20=M19,G19+1,1) -> 90 | H20: =TEXT(G20,"0000") -> 0090 | I20: =CONCATENATE(N20,H20) -> 10010090 | K20: Indirect | L20: Ward No. 1, Badiya, Semri, Sonma | M20: BMC Code : 0001 | N20: =VLOOKUP(M20,'BMC Master'!$C$3:$E$100,3,0) -> 1001 | O20: Khushilal Yadav | P20: 28491 | Q20: Rambadan Yadav | R20: 9878428919 | S20: 38040131046510 | T20: Bihar Gramin Bank | U20: PUNBOMBGB06 | V20: Bakhri Bazar | W20: Gopal Kumar | X20: Kumbhi | Y20: 100101
B21: Bihar | C21: Jayant Sir | D21: Baraipura Dairy | E21: 45637 | F21: New | G21: =IF(M21=M20,G20+1,1) -> 91 | H21: =TEXT(G21,"0000") -> 0091 | I21: =CONCATENATE(N21,H21) -> 10010091 | K21: Indirect | L21: Ward no. 39, Chanakya Nagar, Bishunpur, Banduar | M21: BMC Code : 0001 | N21: =VLOOKUP(M21,'BMC Master'!$C$3:$E$100,3,0) -> 1001 | O21: Abhishek Kumar | P21: 37531 | Q21: Abadh Kishor Singh | R21: 7368097388 | S21: 20408305401 | T21: State Bank of India | U21: SBIN0005455 | V21: ADB Begusarai | W21: Gopal Kumar | X21: Kumbhi | Y21: 100101
... B81: Bihar | C81: Jayant Sir | D81: Kamla Nagar | E81: 46226 | F81: New | G81: =IF(M81=M80,G80+1,1) -> 151 | H81: =TEXT(G81,"0000") -> 0151 | I81: =CONCATENATE(N81,H81) -> 10010151 | K81: Indirect | L81: Ward no. 13, Kamla Nagar, Manjhaul, Begusarai | M81: BMC Code : 0001 | N81: =VLOOKUP(M81,'BMC Master'!$C$3:$E$100,3,0) -> 1001 | O81: Ajit Kumar | P81: 35856 | Q81: Ram Sah | R81: 9905691497 | S81: 45009978351 | T81: State Bank of India | U81: SBIN0005858 | V81: Manjhaul | W81: Gopal Kumar | X81: Birpur Route | Y81: 100103
A82: =A3+1 -> 2 | B82: Bihar | C82: Jayant Sir | D82: ADARSH LAXMIPUR-2 | E82: 45423 | F82: New | G82: 67 | H82: =TEXT(G82,"0000") -> 0067 | I82: =CONCATENATE(N82,H82) -> 10020067 | J82: 1163 | K82: Indirect | L82: VILL-lALDIYARA,P.S-KHUTATA,DISTT-LAKHISARAI | M82: BMC Code : 0003 | N82: =VLOOKUP(M82,'BMC Master'!$C$3:$E$100,3,0) -> 1002 | O82: Beachan Singh | P82: 27030 | Q82: Aniruddh Singh | R82: 7488828958 | S82: 35649980946 | T82: SBI | U82: SBIN0002916 | V82: Lakhisarai | W82: Goutam Kumar | X82: Paroria | Y82: 100102
B83: Bihar | C83: Jayant Sir | D83: SABIKPUR | E83: 45477 | F83: New | G83: 68 | H83: =TEXT(G83,"0000") -> 0068 | I83: =CONCATENATE(N83,H83) -> 10020068 | K83: Direct | L83: VILL-SABIKPUR,P.O-SABIKPUR,P.S-LAKHISARAI,DISTT-LAKHISARAI | M83: BMC Code : 0003 | N83: =VLOOKUP(M83,'BMC Master'!$C$3:$E$100,3,0) -> 1002 | O83: VIKASH KUMAR | P83: 34769 | Q83: RAMASHISH SINGH | R83: 7764922168 | S83: 31210110031790 | T83: DAKSHIN BIHAR GRAMIN BANK | U83: PUNB0MBGB06 | V83: VIDYAPITH,LAKHISARAI | W83: GAUTAM KUMAR | X83: SABIKPUR | Y83: 100202
A84: =A82+1 -> 3 | B84: Bihar | C84: Jayant Sir | D84: CHETAN-TOLA-KHUTHA | E84: 45477 | F84: New | G84: 69 | H84: =TEXT(G84,"0000") -> 0069 | I84: =CONCATENATE(N84,H84) -> 10020069 | K84: Direct | L84: VILL-CHETAN TOLA,P.O-KHUTHA,P.S-BARHIYA,DISTT-LAKHISARAI | M84: BMC Code : 0003 | N84: =VLOOKUP(M84,'BMC Master'!$C$3:$E$100,3,0) -> 1002 | O84: RAMADHAR SINGH | P84: 28169 | Q84: RAMBALAK SINGH | R84: 9661211265 | S84: 41970435465 | T84: SBI | U84: SBIN0002968 | V84: LAKHISARAI | W84: GAUTAM KUMAR | X84: SABIKPUR | Y84: 100202
B85: Bihar | C85: Jayant Sir | D85: LAXMIPUR | E85: 45573 | F85: New | G85: 70 | H85: =TEXT(G85,"0000") -> 0070 | I85: =CONCATENATE(N85,H85) -> 10020070 | K85: Direct | L85: VILL-GARH LAXMIPUR, P.O.-LACHHMIPUR,P.S.-BARAHIYA,DIST-LAKHISARAI | M85: BMC Code : 0003 | N85: =VLOOKUP(M85,'BMC Master'!$C$3:$E$100,3,0) -> 1002 | O85: DOLI DEVI | P85: 32874 | Q85: MOTI SINGH | R85: 8409231693 | S85: 31110131150765 | T85: DAKSHIN BIHAR GRAMIN BANK | U85: PUNB0MBG806 | V85: LAKHISARAI | W85: GAUTAM KUMAR | X85: SABIKPUR | Y85: 100202
B86: Bihar | C86: Jayant Sir | D86: PAIJUNA | E86: 45638 | F86: New | G86: 71 | H86: =TEXT(G86,"0000") -> 0071 | I86: =CONCATENATE(N86,H86) -> 10020071 | K86: Indirect | L86: vill-paijna,post-paijna,block-GOSWARI,DIST-LAKHISARAI,PINCODE-8033302 | M86: BMC Code : 0003 | N86: =VLOOKUP(M86,'BMC Master'!$C$3:$E$100,3,0) -> 1002 | O86: SURAJKUMAR | P86: 33239 | Q86: CHANDESWAR YADAV | R86: 7091926955 | S86: 39132123616 | T86: SBI | U86: SBIN0012585 | V86: GHOSWARI | W86: PRASHANTH KUMAR | X86: SABIKPUR | Y86: 100202
B87: Bihar | C87: Jayant Sir | D87: PAHLADPUR | E87: 45638 | F87: New | G87: 72 | H87: =TEXT(G87,"0000") -> 0072 | I87: =CONCATENATE(N87,H87) -> 10020072 | K87: Indirect | L87: VILL-VILASH YADAV,POST-PAHLADPUR,BLOCK-GHOSWARI,DIST-PATNA,PINCODE-803302 | M87: BMC Code : 0003 | N87: =VLOOKUP(M87,'BMC Master'!$C$3:$E$100,3,0) -> 1002 | O87: VILASH YADAV | P87: 32509 | Q87: suraj yadav | R87: 9771033438 | S87: 1290001700067739 | T87: PNB | U87: PUNB012900 | V87: PRAHLADPUR | W87: PRASHANTH KUMAR | X87: SABIKPUR | Y87: 100202
B88: Bihar | C88: Jayant Sir | D88: REHUA RK | E88: 45638 | F88: New | G88: 73 | H88: =TEXT(G88,"0000") -> 0073 | I88: =CONCATENATE(N88,H88) -> 10020073 | K88: Indirect | L88: VILL-REHUA,POST-REHUA,DIST-LAKHISARAI,PINCIDE-811310 | M88: BMC Code : 0003 | N88: =VLOOKUP(M88,'BMC Master'!$C$3:$E$100,3,0) -> 1002 | O88: pawan kumar | P88: 36474 | Q88: ashok yadav | R88: 7352417205 | S88: 31210110070461 | T88: dakshin bihar gramin bank | U88: PUNB0MBGBD6 | V88: REHUA | W88: GAUTAM KUMAR | X88: SABIKPUR | Y88: 100202
B89: Bihar | C89: Jayant Sir | D89: NEW KARARI PIPARIYA | E89: 45706 | F89: New | G89: 74 | H89: =TEXT(G89,"0000") -> 0074 | I89: =CONCATENATE(N89,H89) -> 10020074 | K89: Direct | L89: Vill-Diayara pipariya, post-Pipariya, block-Pipariya, Dist-lakhisarai, ps-pipariya, pincode-811302 | M89: BMC Code : 0003 | N89: =VLOOKUP(M89,'BMC Master'!$C$3:$E$100,3,0) -> 1002 | O89: SAMIR KUMAR | P89: 31052 | Q89: VIJAY PRASAD SINGH | R89: 9113345842 | S89: 6489000100020503 | T89: PNB | U89: PUNB0648900 | V89: PIPARIYA | W89: GAUTAM | X89: SABIKPUR | Y89: 100202
B90: Bihar | C90: Jayant Sir | D90: RAMNAGAR | E90: 45852 | F90: New | G90: 75 | H90: =TEXT(G90,"0000") -> 0075 | I90: =CONCATENATE(N90,H90) -> 10020075 | K90: Direct | L90: Vill-ramnagar,post-Bannubagicha, ps-bannubagicha,dist-lakhisarai | M90: BMC Code : 0003 | N90: =VLOOKUP(M90,'BMC Master'!$C$3:$E$100,3,0) -> 1002 | O90: Ravish kumar | P90: 35496 | Q90: yogesh sharma | R90: 7870410195 | S90: 31010110029290 | T90: GRAMIN BANK | U90: PUNB0MBGB06 | V90: LAKHISARAI | W90: KUNAL | X90: Bansipur | Y90: 100206
B91: Bihar | C91: Jayant Sir | D91: PACHAM | E91: 45852 | F91: New | G91: 76 | H91: =TEXT(G91,"0000") -> 0076 | I91: =CONCATENATE(N91,H91) -> 10020076 | K91: Direct | L91: VILL-PACHAM,POST-PACHAM,BLOCK-CHANAN,DIST-LAKHISARAI | M91: BMC Code : 0003 | N91: =VLOOKUP(M91,'BMC Master'!$C$3:$E$100,3,0) -> 1002 | O91: RAM DYAL YADAV | P91: 27795 | Q91: PRABHU YADAV | R91: 7870410196 | S91: 30727480589 | T91: SBI | U91: SBIN0002968 | V91: LAKHISARAI | W91: KUNAL | X91: Bansipur | Y91: 100206
B92: Bihar | C92: Jayant Sir | D92: BANSIPUR | E92: 45852 | F92: New | G92: 77 | H92: =TEXT(G92,"0000") -> 0077 | I92: =CONCATENATE(N92,H92) -> 10020077 | K92: Direct | L92: VILL-BANSIPUR,POST-PACGHAM,PS-KIUL,DIST-LAKHISARAI | M92: BMC Code : 0003 | N92: =VLOOKUP(M92,'BMC Master'!$C$3:$E$100,3,0) -> 1002 | O92: MUKESH KUMAR | P92: 35961 | Q92: RAJ KUMAR YADAV | R92: 8104126303 | S92: 464710110009280 | T92: BOI | U92: BKID0004647 | V92: LAKHISARAI | W92: KUNAL | X92: Bansipur | Y92: 100206
B93: Bihar | C93: Jayant Sir | D93: GODIH | E93: 45852 | F93: New | G93: 78 | H93: =TEXT(G93,"0000") -> 0078 | I93: =CONCATENATE(N93,H93) -> 10020078 | K93: Direct | L93: vill-Goddih,post-Kiul,ps-Gurdih,dist-lakhisarai | M93: BMC Code : 0003 | N93: =VLOOKUP(M93,'BMC Master'!$C$3:$E$100,3,0) -> 1002 | O93: Ajit Kumar | P93: 31954 | Q93: Bhola Ram | R93: 8804360388 | S93: 30430100004375 | T93: BOI | U93: BKID0004647 | V93: LAKHISARAI | W93: PRASHANTJ | X93: Bansipur | Y93: 100206
B94: Bihar | C94: Jayant Sir | D94: SINGARPUR | E94: 45852 | F94: New | G94: 79 | H94: =TEXT(G94,"0000") -> 0079 | I94: =CONCATENATE(N94,H94) -> 10020079 | K94: Direct | L94: vill-Sitarampur,post-Sahur,ps-Surajgadha,dist-lakhisarai | M94: BMC Code : 0003 | N94: =VLOOKUP(M94,'BMC Master'!$C$3:$E$100,3,0) -> 1002 | O94: Kundan Kumar | P94: 31700 | Q94: Niranjan Singh | R94: 9113404461 | S94: 9312000100016096 | T94: PNB | U94: PUNB0931200 | V94: LAKHISARAI | W94: PRASHANTJ | X94: Bansipur | Y94: 100206
B95: Bihar | C95: Jayant Sir | D95: ADARSH PULPAR | E95: 45882 | F95: New | G95: 80 | H95: =TEXT(G95,"0000") -> 0080 | I95: =CONCATENATE(N95,H95) -> 10020080 | K95: Direct | L95: VILL-ADARSHPULL PAR,POST-ADARSH LAXMIPUR,PS-BARHAIYA,DIST-LAKHISARAI | M95: BMC Code : 0003 | N95: =VLOOKUP(M95,'BMC Master'!$C$3:$E$100,3,0) -> 1002 | O95: UDAY YADAV | P95: 27395 | Q95: GANGU YADAV | R95: 8102487776 | S95: 34342960403 | T95: SBI | U95: SBIN0002916 | V95: BARHAIYA | W95: GAUTAM | X95: BARHAIYA | Y95: 100204
B96: Bihar | C96: Jayant Sir | D96: G WOLIPUR | E96: 45909 | F96: New | G96: 81 | H96: =TEXT(G96,"0000") -> 0081 | I96: =CONCATENATE(N96,H96) -> 10020081 | K96: Indirect | L96: VILL-OLIPUR,POST-MOHANPUR,PS-PIPARIYA, | M96: BMC Code : 0003 | N96: =VLOOKUP(M96,'BMC Master'!$C$3:$E$100,3,0) -> 1002 | O96: SAKET BIHARI | P96: 33239 | Q96: RAMNARESH SINGH | R96: 9765432454 | S96: 9312000100016272 | T96: PNB | U96: PUNB0931200 | V96: RAMPUR | W96: GAUTAM | X96: SABIKPUR | Y96: 100202
B97: Bihar | C97: Jayant Sir | D97: REHUA 3 | E97: 45909 | F97: New | G97: 82 | H97: =TEXT(G97,"0000") -> 0082 | I97: =CONCATENATE(N97,H97) -> 10020082 | K97: Indirect | L97: VILL-REHUA, POST-REHUA, PS-LAKHISARAI | M97: BMC Code : 0003 | N97: =VLOOKUP(M97,'BMC Master'!$C$3:$E$100,3,0) -> 1002 | O97: SUBODH SINGH | P97: 28581 | Q97: RAJBALLABH SINGH | R97: 7899876767 | S97: 31210110004732 | T97: DAKSHIN BIHAR GRAMIN BANK | U97: PUNB0MBGB06 | V97: VIDYAPITH | W97: GAUTAM | X97: SABIKPUR | Y97: 100202
B98: Bihar | C98: Jayant Sir | D98: BICHWAY | E98: 45926 | F98: New | G98: 83 | H98: =TEXT(G98,"0000") -> 0083 | I98: =CONCATENATE(N98,H98) -> 10020083 | K98: Direct | L98: VILL-BICHWAY,POST-BICHWAY,PS-KIUL,BLOCK-MANANPUR | M98: BMC Code : 0003 | N98: =VLOOKUP(M98,'BMC Master'!$C$3:$E$100,3,0) -> 1002 | O98: VIVEK KUMAR | P98: 28045 | Q98: BABULAL | R98: 9798832127 | S98: 001334001102265 | T98: MUNGER CENTRAL BANK CO OPERATIVE | U98: IBKL01078MJ | V98: LAKHISARAI | W98: PRASHANTJ | X98: Bansipur | Y98: 100206
B99: Bihar | C99: Jayant Sir | D99: MANOHARPUR | E99: 45961 | F99: New | G99: 84 | H99: =TEXT(G99,"0000") -> 0084 | I99: =CONCATENATE(N99,H99) -> 10020084 | K99: Direct | L99: VILL-MANOHARPUR,POST-SADAIBIGHA,DIST-LAKHISARAI | M99: BMC Code : 0003 | N99: =VLOOKUP(M99,'BMC Master'!$C$3:$E$100,3,0) -> 1002 | O99: SHIVAM KUMAR | P99: 39087 | Q99: RANJIT KUMAR | R99: 9065268837 | S99: 9065268837 | T99: AIRTEL PAYMENT | U99: AIRP0000001 | V99: MANOHARPUR | W99: PRASHANTJ | X99: Bansipur | Y99: 100206
...

Sheet Farmer Master
A1: ID | B1: State | C1: BMC Name | D1: MPG Code | E1: New MPG Code | F1: MPG Name | G1: Farmer Code | H1: New Farmer Code | I1: Farmer Name | J1: Father Name | K1: DOB | L1: Gender | M1: Gender Code | N1: Contact No | O1: No of Buff | P1: No of Cows | Q1: Bank Name | R1: Bank Account No | S1: Branch | T1: Bank IFSC Code | U1: Address | V1: Local Address | W1: Pincode | X1: PAN Card | Y1: Aadhar Card | Z1: Voter Card | AA1: Potential (Ltrs) | AB1: Remarks | AC1: Status
A2: =CONCATENATE(D2,G2) -> 40230025 | B2: Bihar | C2: ASARGANJ | D2: 4023 | E2: =VLOOKUP(D2,'MPG Master'!$C$3:$I$724,7,0) -> #N/A | F2: =VLOOKUP(D2,'MPG Master'!$C$3:$D$724,2,0) -> #N/A | G2: 0025 | H2: =E2&G2 -> #N/A | I2: RAKESH KUMAR | J2: 0 | N2: 0 | Q2: HDFC BANK LTD | R2: 50100154317303 | T2: HDFC0000765 | AC2: Old | AD2: Direct
A3: =CONCATENATE(D3,G3) -> 40230034 | B3: Bihar | C3: ASARGANJ | D3: 4023 | E3: =VLOOKUP(D3,'MPG Master'!$C$3:$I$724,7,0) -> #N/A | F3: =VLOOKUP(D3,'MPG Master'!$C$3:$D$724,2,0) -> #N/A | G3: 0034 | H3: =E3&G3 -> #N/A | I3: BRAJ KISHOR | J3: 0 | N3: 0 | Q3: HDFC BANK LTD | R3: 50100168491992 | T3: HDFC0002895 | AC3: Old | AD3: Direct
A4: =CONCATENATE(D4,G4) -> 40230035 | B4: Bihar | C4: ASARGANJ | D4: 4023 | E4: =VLOOKUP(D4,'MPG Master'!$C$3:$I$724,7,0) -> #N/A | F4: =VLOOKUP(D4,'MPG Master'!$C$3:$D$724,2,0) -> #N/A | G4: 0035 | H4: =E4&G4 -> #N/A | I4: RUBI DEVI | J4: 0 | N4: 0 | Q4: HDFC BANK LTD | R4: 50100154881086 | T4: HDFC0000765 | AC4: Old | AD4: Direct
A5: =CONCATENATE(D5,G5) -> 40230047 | B5: Bihar | C5: ASARGANJ | D5: 4023 | E5: =VLOOKUP(D5,'MPG Master'!$C$3:$I$724,7,0) -> #N/A | F5: =VLOOKUP(D5,'MPG Master'!$C$3:$D$724,2,0) -> #N/A | G5: 0047 | H5: =E5&G5 -> #N/A | I5: RAM SEVAK | J5: 0 | N5: 0 | Q5: HDFC BANK LTD | R5: 50100154884362 | T5: HDFC0000765 | AC5: Old | AD5: Direct
A6: =CONCATENATE(D6,G6) -> 40230051 | B6: Bihar | C6: ASARGANJ | D6: 4023 | E6: =VLOOKUP(D6,'MPG Master'!$C$3:$I$724,7,0) -> #N/A | F6: =VLOOKUP(D6,'MPG Master'!$C$3:$D$724,2,0) -> #N/A | G6: 0051 | H6: =E6&G6 -> #N/A | I6: MANOJ KUMAR | J6: 0 | N6: 0 | Q6: HDFC BANK LTD | R6: 50100197156409 | T6: HDFC0002895 | AC6: Old | AD6: Direct
A7: =CONCATENATE(D7,G7) -> 40230055 | B7: Bihar | C7: ASARGANJ | D7: 4023 | E7: =VLOOKUP(D7,'MPG Master'!$C$3:$I$724,7,0) -> #N/A | F7: =VLOOKUP(D7,'MPG Master'!$C$3:$D$724,2,0) -> #N/A | G7: 0055 | H7: =E7&G7 -> #N/A | I7: GYAN DEV SHARMA | J7: 0 | N7: 0 | Q7: HDFC BANK LTD | R7: 50100155781661 | T7: HDFC0002895 | AC7: Old | AD7: Direct
A8: =CONCATENATE(D8,G8) -> 40230057 | B8: Bihar | C8: ASARGANJ | D8: 4023 | E8: =VLOOKUP(D8,'MPG Master'!$C$3:$I$724,7,0) -> #N/A | F8: =VLOOKUP(D8,'MPG Master'!$C$3:$D$724,2,0) -> #N/A | G8: 0057 | H8: =E8&G8 -> #N/A | I8: AJAY KUMAR | J8: 0 | N8: 0 | Q8: HDFC BANK LTD | R8: 50100154880991 | T8: HDFC0000765 | AC8: Old | AD8: Direct
A9: =CONCATENATE(D9,G9) -> 40230058 | B9: Bihar | C9: ASARGANJ | D9: 4023 | E9: =VLOOKUP(D9,'MPG Master'!$C$3:$I$724,7,0) -> #N/A | F9: =VLOOKUP(D9,'MPG Master'!$C$3:$D$724,2,0) -> #N/A | G9: 0058 | H9: =E9&G9 -> #N/A | I9: SUNITA | J9: 0 | N9: 0 | Q9: HDFC BANK LTD | R9: 50100245358022 | T9: HDFC0002108 | AC9: Old | AD9: Direct
A10: =CONCATENATE(D10,G10) -> 40230065 | B10: Bihar | C10: ASARGANJ | D10: 4023 | E10: =VLOOKUP(D10,'MPG Master'!$C$3:$I$724,7,0) -> #N/A | F10: =VLOOKUP(D10,'MPG Master'!$C$3:$D$724,2,0) -> #N/A | G10: 0065 | H10: =E10&G10 -> #N/A | I10: BYUTI | J10: 0 | N10: 0 | Q10: HDFC BANK LTD | R10: 50100219844443 | T10: HDFC0002895 | AC10: Old | AD10: Direct
A11: =CONCATENATE(D11,G11) -> 40230066 | B11: Bihar | C11: ASARGANJ | D11: 4023 | E11: =VLOOKUP(D11,'MPG Master'!$C$3:$I$724,7,0) -> #N/A | F11: =VLOOKUP(D11,'MPG Master'!$C$3:$D$724,2,0) -> #N/A | G11: 0066 | H11: =E11&G11 -> #N/A | I11: RAJHANSH KUMAR | J11: 0 | N11: 0 | Q11: HDFC BANK LTD | R11: 50100191605145 | T11: HDFC0002895 | AC11: Old | AD11: Direct
A12: =CONCATENATE(D12,G12) -> 40230089 | B12: Bihar | C12: ASARGANJ | D12: 4023 | E12: =VLOOKUP(D12,'MPG Master'!$C$3:$I$724,7,0) -> #N/A | F12: =VLOOKUP(D12,'MPG Master'!$C$3:$D$724,2,0) -> #N/A | G12: 0089 | H12: =E12&G12 -> #N/A | I12: GUDDI DEVI | J12: 0 | N12: 0 | Q12: HDFC BANK LTD | R12: 50100280448742 | T12: HDFC0009287 | AC12: Old | AD12: Direct
A13: =CONCATENATE(D13,G13) -> 40230094 | B13: Bihar | C13: ASARGANJ | D13: 4023 | E13: =VLOOKUP(D13,'MPG Master'!$C$3:$I$724,7,0) -> #N/A | F13: =VLOOKUP(D13,'MPG Master'!$C$3:$D$724,2,0) -> #N/A | G13: 0094 | H13: =E13&G13 -> #N/A | I13: SHIV SHANKAR | J13: 0 | N13: 0 | Q13: HDFC BANK LTD | R13: 50100191606697 | T13: HDFC0002895 | AC13: Old | AD13: Direct
... A21: =CONCATENATE(D21,G21) -> 40390043 | B21: Bihar | C21: ASARGANJ | D21: 4039 | E21: =VLOOKUP(D21,'MPG Master'!$C$3:$I$724,7,0) -> #N/A | F21: =VLOOKUP(D21,'MPG Master'!$C$3:$D$724,2,0) -> #N/A | G21: 0043 | H21: =E21&G21 -> #N/A | I21: PRABHA DEVI | J21: 0 | N21: 0 | Q21: AIRTEL PAYMENTS BANK | R21: 7634016906 | T21: AIRP0000001 | AC21: Old | AD21: Direct
A22: =CONCATENATE(D22,G22) -> 40390046 | B22: Bihar | C22: ASARGANJ | D22: 4039 | E22: =VLOOKUP(D22,'MPG Master'!$C$3:$I$724,7,0) -> #N/A | F22: =VLOOKUP(D22,'MPG Master'!$C$3:$D$724,2,0) -> #N/A | G22: 0046 | H22: =E22&G22 -> #N/A | I22: Mahendra mandal | J22: Ishwar Mandal | K22: 19360 | N22: 6287230604 | Q22: AIRTEL PAYMENTS BANK | R22: 39208651915 | T22: SBIN0003009 | AC22: Old | AD22: Direct
A23: =CONCATENATE(D23,G23) -> 40390048 | B23: Bihar | C23: ASARGANJ | D23: 4039 | E23: =VLOOKUP(D23,'MPG Master'!$C$3:$I$724,7,0) -> #N/A | F23: =VLOOKUP(D23,'MPG Master'!$C$3:$D$724,2,0) -> #N/A | G23: 0048 | H23: =E23&G23 -> #N/A | I23: RAJESH MANDAL | J23: 0 | N23: 0 | Q23: AIRTEL PAYMENTS BANK | R23: 9572352946 | T23: AIRP0000001 | AC23: Old | AD23: Direct
A24: =CONCATENATE(D24,G24) -> 40390059 | B24: Bihar | C24: ASARGANJ | D24: 4039 | E24: =VLOOKUP(D24,'MPG Master'!$C$3:$I$724,7,0) -> #N/A | F24: =VLOOKUP(D24,'MPG Master'!$C$3:$D$724,2,0) -> #N/A | G24: 0059 | H24: =E24&G24 -> #N/A | I24: Subham Kumar | J24: lalit Kumar Singh | K24: 38229 | N24: 6200028817 | Q24: AIRTEL PAYMENTS BANK | R24: 37101342039 | T24: SBIN0003009 | AC24: Old | AD24: Direct
A25: =CONCATENATE(D25,G25) -> 40390063 | B25: Bihar | C25: ASARGANJ | D25: 4039 | E25: =VLOOKUP(D25,'MPG Master'!$C$3:$I$724,7,0) -> #N/A | F25: =VLOOKUP(D25,'MPG Master'!$C$3:$D$724,2,0) -> #N/A | G25: 0063 | H25: =E25&G25 -> #N/A | I25: GEETA PRASAD SINGH | J25: 0 | N25: 0 | Q25: HDFC BANK LTD | R25: 50100162028426 | T25: HDFC0002895 | AC25: Old | AD25: Direct
A26: =CONCATENATE(D26,G26) -> 40390089 | B26: Bihar | C26: ASARGANJ | D26: 4039 | E26: =VLOOKUP(D26,'MPG Master'!$C$3:$I$724,7,0) -> #N/A | F26: =VLOOKUP(D26,'MPG Master'!$C$3:$D$724,2,0) -> #N/A | G26: 0089 | H26: =E26&G26 -> #N/A | I26: DILIP KUMAR SINGH | J26: 0 | N26: 0 | Q26: HDFC BANK LTD | R26: 50100196018062 | T26: HDFC0002895 | AC26: Old | AD26: Direct
A27: =CONCATENATE(D27,G27) -> 40390095 | B27: Bihar | C27: ASARGANJ | D27: 4039 | E27: =VLOOKUP(D27,'MPG Master'!$C$3:$I$724,7,0) -> #N/A | F27: =VLOOKUP(D27,'MPG Master'!$C$3:$D$724,2,0) -> #N/A | G27: 0095 | H27: =E27&G27 -> #N/A | I27: GUNJAN KUMARI | J27: 0 | N27: 0 | Q27: HDFC BANK LTD | R27: 50100251904931 | T27: HDFC0009287 | AC27: Old | AD27: Direct
A28: =CONCATENATE(D28,G28) -> 40390121 | B28: Bihar | C28: ASARGANJ | D28: 4039 | E28: =VLOOKUP(D28,'MPG Master'!$C$3:$I$724,7,0) -> #N/A | F28: =VLOOKUP(D28,'MPG Master'!$C$3:$D$724,2,0) -> #N/A | G28: 0121 | H28: =E28&G28 -> #N/A | I28: RAJ KUMAR SINGH | J28: 0 | N28: 0 | Q28: AIRTEL PAYMENTS BANK | R28: 9523655865 | T28: AIRP0000001 | AC28: Old | AD28: Direct
A29: =CONCATENATE(D29,G29) -> 40390129 | B29: Bihar | C29: ASARGANJ | D29: 4039 | E29: =VLOOKUP(D29,'MPG Master'!$C$3:$I$724,7,0) -> #N/A | F29: =VLOOKUP(D29,'MPG Master'!$C$3:$D$724,2,0) -> #N/A | G29: 0129 | H29: =E29&G29 -> #N/A | I29: MANISH KR | J29: 0 | N29: 0 | Q29: AIRTEL PAYMENTS BANK | R29: 7368906672 | T29: AIRP0000001 | AC29: Old | AD29: Direct
A30: =CONCATENATE(D30,G30) -> 40390157 | B30: Bihar | C30: ASARGANJ | D30: 4039 | E30: =VLOOKUP(D30,'MPG Master'!$C$3:$I$724,7,0) -> #N/A | F30: =VLOOKUP(D30,'MPG Master'!$C$3:$D$724,2,0) -> #N/A | G30: 0157 | H30: =E30&G30 -> #N/A | I30: JITENDRA Kumar | J30: 0 | N30: 0 | Q30: HDFC BANK LTD | R30: 50100155585680 | T30: HDFC0002895 | AC30: Old | AD30: Direct
A31: =CONCATENATE(D31,G31) -> 40390219 | B31: Bihar | C31: ASARGANJ | D31: 4039 | E31: =VLOOKUP(D31,'MPG Master'!$C$3:$I$724,7,0) -> #N/A | F31: =VLOOKUP(D31,'MPG Master'!$C$3:$D$724,2,0) -> #N/A | G31: 0219 | H31: =E31&G31 -> #N/A | I31: DILIP KUMAR SINGH | J31: 0 | N31: 0 | Q31: AIRTEL PAYMENTS BANK | R31: 9631366478 | T31: AIRP0000001 | AC31: Old | AD31: Direct
A32: =CONCATENATE(D32,G32) -> 40390225 | B32: Bihar | C32: ASARGANJ | D32: 4039 | E32: =VLOOKUP(D32,'MPG Master'!$C$3:$I$724,7,0) -> #N/A | F32: =VLOOKUP(D32,'MPG Master'!$C$3:$D$724,2,0) -> #N/A | G32: 0225 | H32: =E32&G32 -> #N/A | I32: BECHAN VIIND | J32: 0 | N32: 0 | Q32: HDFC BANK LTD | R32: 50100164032252 | T32: HDFC0002895 | AC32: Old | AD32: Direct
A33: =CONCATENATE(D33,G33) -> 40390235 | B33: Bihar | C33: ASARGANJ | D33: 4039 | E33: =VLOOKUP(D33,'MPG Master'!$C$3:$I$724,7,0) -> #N/A | F33: =VLOOKUP(D33,'MPG Master'!$C$3:$D$724,2,0) -> #N/A | G33: 0235 | H33: =E33&G33 -> #N/A | I33: AKHILESH KUMAR SINGH | J33: 0 | N33: 0 | Q33: AIRTEL PAYMENTS BANK | R33: 8252073565 | T33: AIRP0000001 | AC33: Old | AD33: Direct
A34: =CONCATENATE(D34,G34) -> 40390254 | B34: Bihar | C34: ASARGANJ | D34: 4039 | E34: =VLOOKUP(D34,'MPG Master'!$C$3:$I$724,7,0) -> #N/A | F34: =VLOOKUP(D34,'MPG Master'!$C$3:$D$724,2,0) -> #N/A | G34: 0254 | H34: =E34&G34 -> #N/A | I34: DILIP YADAV | J34: 0 | N34: 0 | Q34: AIRTEL PAYMENTS BANK | R34: 9973265381 | T34: AIRP0000001 | AC34: Old | AD34: Direct
A35: =CONCATENATE(D35,G35) -> 40390259 | B35: Bihar | C35: ASARGANJ | D35: 4039 | E35: =VLOOKUP(D35,'MPG Master'!$C$3:$I$724,7,0) -> #N/A | F35: =VLOOKUP(D35,'MPG Master'!$C$3:$D$724,2,0) -> #N/A | G35: 0259 | H35: =E35&G35 -> #N/A | I35: VINDU DEVI | J35: 0 | N35: 0 | Q35: HDFC BANK LTD | R35: 50100270745522 | T35: HDFC0009287 | AC35: Old | AD35: Direct
A36: =CONCATENATE(D36,G36) -> 40390297 | B36: Bihar | C36: ASARGANJ | D36: 4039 | E36: =VLOOKUP(D36,'MPG Master'!$C$3:$I$724,7,0) -> #N/A | F36: =VLOOKUP(D36,'MPG Master'!$C$3:$D$724,2,0) -> #N/A | G36: 0297 | H36: =E36&G36 -> #N/A | I36: RAJKUMAR MAHTO | J36: 0 | N36: 0 | Q36: AIRTEL PAYMENTS BANK | R36: 9572245260 | T36: AIRP0000001 | AC36: Old | AD36: Direct
... A40: =CONCATENATE(D40,G40) -> 40390393 | B40: Bihar | C40: ASARGANJ | D40: 4039 | E40: =VLOOKUP(D40,'MPG Master'!$C$3:$I$724,7,0) -> #N/A | F40: =VLOOKUP(D40,'MPG Master'!$C$3:$D$724,2,0) -> #N/A | G40: 0393 | H40: =E40&G40 -> #N/A | I40: DHANESHWAR SAH | J40: 0 | N40: 0 | Q40: AIRTEL PAYMENTS BANK | R40: 7840864419 | T40: AIRP0000001 | AC40: Old | AD40: Direct
A41: =CONCATENATE(D41,G41) -> 40390399 | B41: Bihar | C41: ASARGANJ | D41: 4039 | E41: =VLOOKUP(D41,'MPG Master'!$C$3:$I$724,7,0) -> #N/A | F41: =VLOOKUP(D41,'MPG Master'!$C$3:$D$724,2,0) -> #N/A | G41: 0399 | H41: =E41&G41 -> #N/A | I41: NIRAJ KUMAR SINGH | J41: Binay Kumar Singh | K41: 29956 | N41: 9507982067 | Q41: HDFC BANK LTD | R41: 50100463512225 | T41: HDFC0009287 | AC41: Old | AD41: Direct
A42: =CONCATENATE(D42,G42) -> 40390400 | B42: Bihar | C42: ASARGANJ | D42: 4039 | E42: =VLOOKUP(D42,'MPG Master'!$C$3:$I$724,7,0) -> #N/A | F42: =VLOOKUP(D42,'MPG Master'!$C$3:$D$724,2,0) -> #N/A | G42: 0400 | H42: =E42&G42 -> #N/A | I42: PINKI DEVI | J42: 0 | N42: 0 | Q42: AIRTEL PAYMENTS BANK | R42: 8228886548 | T42: AIRP0000001 | AC42: Old | AD42: Direct
A43: =CONCATENATE(D43,G43) -> 40390401 | B43: Bihar | C43: ASARGANJ | D43: 4039 | E43: =VLOOKUP(D43,'MPG Master'!$C$3:$I$724,7,0) -> #N/A | F43: =VLOOKUP(D43,'MPG Master'!$C$3:$D$724,2,0) -> #N/A | G43: 0401 | H43: =E43&G43 -> #N/A | I43: NARESH SINGH | J43: 0 | N43: 0 | Q43: AIRTEL PAYMENTS BANK | R43: 9973687985 | T43: AIRP0000001 | AC43: Old | AD43: Direct
A44: =CONCATENATE(D44,G44) -> 40800002 | B44: Bihar | C44: ASARGANJ | D44: 4080 | E44: =VLOOKUP(D44,'MPG Master'!$C$3:$I$724,7,0) -> #N/A | F44: =VLOOKUP(D44,'MPG Master'!$C$3:$D$724,2,0) -> #N/A | G44: 0002 | H44: =E44&G44 -> #N/A | I44: DIVESH KUMAR | J44: 0 | N44: 0 | Q44: HDFC BANK LTD | R44: 50100180745763 | T44: HDFC0002684 | AC44: Old | AD44: Direct
A45: =CONCATENATE(D45,G45) -> 40800006 | B45: Bihar | C45: ASARGANJ | D45: 4080 | E45: =VLOOKUP(D45,'MPG Master'!$C$3:$I$724,7,0) -> #N/A | F45: =VLOOKUP(D45,'MPG Master'!$C$3:$D$724,2,0) -> #N/A | G45: 0006 | H45: =E45&G45 -> #N/A | I45: BASUKI YADAV | J45: 0 | N45: 0 | Q45: HDFC BANK LTD | R45: 50100206311393 | T45: HDFC0002684 | AC45: Old | AD45: Direct
A46: =CONCATENATE(D46,G46) -> 40800016 | B46: Bihar | C46: ASARGANJ | D46: 4080 | E46: =VLOOKUP(D46,'MPG Master'!$C$3:$I$724,7,0) -> #N/A | F46: =VLOOKUP(D46,'MPG Master'!$C$3:$D$724,2,0) -> #N/A | G46: 0016 | H46: =E46&G46 -> #N/A | I46: NANDAN KUMAR | J46: 0 | N46: 0 | Q46: HDFC BANK LTD | R46: 50100180746918 | T46: HDFC0002684 | AC46: Old | AD46: Direct
A47: =CONCATENATE(D47,G47) -> 40800018 | B47: Bihar | C47: ASARGANJ | D47: 4080 | E47: =VLOOKUP(D47,'MPG Master'!$C$3:$I$724,7,0) -> #N/A | F47: =VLOOKUP(D47,'MPG Master'!$C$3:$D$724,2,0) -> #N/A | G47: 0018 | H47: =E47&G47 -> #N/A | I47: SANGITA KUMARI | J47: 0 | N47: 0 | Q47: HDFC BANK LTD | R47: 50100180746944 | T47: HDFC0002684 | AC47: Old | AD47: Direct
A48: =CONCATENATE(D48,G48) -> 40800022 | B48: Bihar | C48: ASARGANJ | D48: 4080 | E48: =VLOOKUP(D48,'MPG Master'!$C$3:$I$724,7,0) -> #N/A | F48: =VLOOKUP(D48,'MPG Master'!$C$3:$D$724,2,0) -> #N/A | G48: 0022 | H48: =E48&G48 -> #N/A | I48: SADANAND YADAV | J48: 0 | N48: 0 | Q48: HDFC BANK LTD | R48: 50100228751450 | T48: HDFC0002684 | AC48: Old | AD48: Direct
A49: =CONCATENATE(D49,G49) -> 40800023 | B49: Bihar | C49: ASARGANJ | D49: 4080 | E49: =VLOOKUP(D49,'MPG Master'!$C$3:$I$724,7,0) -> #N/A | F49: =VLOOKUP(D49,'MPG Master'!$C$3:$D$724,2,0) -> #N/A | G49: 0023 | H49: =E49&G49 -> #N/A | I49: MANOJ KUMAR SINGH | J49: 0 | N49: 0 | Q49: HDFC BANK LTD | R49: 50100219908578 | T49: HDFC0002684 | AC49: Old | AD49: Direct
A50: =CONCATENATE(D50,G50) -> 40800032 | B50: Bihar | C50: ASARGANJ | D50: 4080 | E50: =VLOOKUP(D50,'MPG Master'!$C$3:$I$724,7,0) -> #N/A | F50: =VLOOKUP(D50,'MPG Master'!$C$3:$D$724,2,0) -> #N/A | G50: 0032 | H50: =E50&G50 -> #N/A | I50: GITA DEVI | J50: 0 | N50: 0 | Q50: HDFC BANK LTD | R50: 50100180746575 | T50: HDFC0002684 | AC50: Old | AD50: Direct
...

Sheet Route Master
B2: Route Master
A3: State | B3: Route No (Old0 | D3: New Route Code | E3: Route Name | F3: BMC Name | G3: BMC Code | H3: Vehicle No | I3: Vehicle Type | J3: Vehicle Capcity (No of Cans) | K3: Vehicle Owner Name | L3: Route Kms | M3: Rate Per Km | N3: Fixed Cost | O3: Mileage | P3: Morning Arrival Time at BMC | Q3: Evening Arrival Time at BMC | R3: First MPG of Route | S3: Last MPG of Route
A4: Bihar | B4: 21 | C4: 01 | D4: =CONCATENATE(G4,C4) -> 100301 | E4: Mohanpur | F4: Asarganj | G4: =VLOOKUP(F4,'BMC Master'!$B$3:$E$16,4,0) -> 1003 | H4: NA | I4: Tata ACE | K4: Kapil kumar | L4: 154 | N4: 600 | O4: 14
A5: Bihar | B5: 23 | C5: 02 | D5: =CONCATENATE(G5,C5) -> 100302 | E5: Tarapur | F5: Asarganj | G5: =VLOOKUP(F5,'BMC Master'!$B$3:$E$16,4,0) -> 1003 | H5: NA | I5: Tata ACE | K5: Kapil kumar | L5: 140 | N5: 600 | O5: 14
A6: Bihar | B6: 12 | C6: 03 | D6: =CONCATENATE(G6,C6) -> 100303 | E6: Amaya | F6: Asarganj | G6: =VLOOKUP(F6,'BMC Master'!$B$3:$E$16,4,0) -> 1003 | H6: NA | I6: Tata ACE | K6: Kapil kumar | L6: 95 | N6: 600 | O6: 14
A7: Bihar | B7: 29 | C7: 01 | D7: =CONCATENATE(G7,C7) -> 100501 | E7: Kadwa+tintanga | F7: Jhandapur | G7: =VLOOKUP(F7,'BMC Master'!$B$3:$E$16,4,0) -> 1005 | H7: NA | I7: Tempo | K7: Mukesh Kumar | L7: 93 | N7: 600 | O7: 14
A8: Bihar | B8: 55 | C8: 01 | D8: =CONCATENATE(G8,C8) -> 100701 | E8: Luxmipur | F8: Araria | G8: =VLOOKUP(F8,'BMC Master'!$B$3:$E$16,4,0) -> 1007 | H8: NA | I8: Tata ACE | K8: Ankesh Kumar | L8: 136 | N8: 600 | O8: 14
A9: Bihar | B9: 56 | C9: 02 | D9: =CONCATENATE(G9,C9) -> 100702 | E9: Gauchaari | F9: Araria | G9: =VLOOKUP(F9,'BMC Master'!$B$3:$E$16,4,0) -> 1007 | H9: NA | I9: Tata ACE | K9: Ankesh Kumar | L9: 158 | N9: 600 | O9: 14
A10: Bihar | B10: 36 | C10: 03 | D10: =CONCATENATE(G10,C10) -> 100703 | E10: Lagar+Kabela | F10: Araria | G10: =VLOOKUP(F10,'BMC Master'!$B$3:$E$16,4,0) -> 1007 | H10: NA | I10: Tata ACE | K10: Ankesh Kumar | L10: 139 | N10: 600 | O10: 14
A11: Bihar | B11: 37 | C11: 04 | D11: =CONCATENATE(G11,C11) -> 100704 | E11: Lagar+Kabela | F11: Araria | G11: =VLOOKUP(F11,'BMC Master'!$B$3:$E$16,4,0) -> 1007 | H11: NA | I11: Tata ACE | K11: Ankesh Kumar | L11: 139 | N11: 600 | O11: 14
A12: Bihar | B12: 56VLC | C12: 05 | D12: =CONCATENATE(G12,C12) -> 100705 | E12: Viveka Yafdav | F12: Araria | G12: =VLOOKUP(F12,'BMC Master'!$B$3:$E$16,4,0) -> 1007 | H12: NA | I12: Pickup | K12: Ankesh Kumar | L12: 213 | N12: 700 | O12: 10
A13: Bihar | B13: 45 | C13: 01 | D13: =CONCATENATE(G13,C13) -> 101101 | E13: Dandari | F13: Sahibpur Kamal | G13: =VLOOKUP(F13,'BMC Master'!$B$3:$E$16,4,0) -> 1011 | H13: NA | I13: Pickup | K13: Chandan kumar | L13: 204.67742 | N13: 700 | O13: 10
A14: Bihar | B14: 48 | C14: 02 | D14: =CONCATENATE(G14,C14) -> 101102 | E14: Matihani | F14: Sahibpur Kamal | G14: =VLOOKUP(F14,'BMC Master'!$B$3:$E$16,4,0) -> 1011 | H14: NA | I14: Pickup | K14: Prem krishna Murari | L14: 160 | N14: 700 | O14: 10
A15: Bihar | B15: 48 | C15: 03 | D15: =CONCATENATE(G15,C15) -> 101103 | E15: Matihani | F15: Sahibpur Kamal | G15: =VLOOKUP(F15,'BMC Master'!$B$3:$E$16,4,0) -> 1011 | H15: NA | I15: Pickup | K15: Chandan kumar | L15: 160 | N15: 700 | O15: 10
A16: Bihar | B16: 53 | C16: 04 | D16: =CONCATENATE(G16,C16) -> 101104 | E16: Mathar | F16: Sahibpur Kamal | G16: =VLOOKUP(F16,'BMC Master'!$B$3:$E$16,4,0) -> 1011 | H16: NA | I16: Tractor | K16: Chandan kumar | L16: 108 | N16: 700 | O16: 5
A17: Bihar | B17: 51 | C17: 05 | D17: =CONCATENATE(G17,C17) -> 101105 | E17: Bisanpur | F17: Sahibpur Kamal | G17: =VLOOKUP(F17,'BMC Master'!$B$3:$E$16,4,0) -> 1011 | H17: NA | I17: Pickup | K17: Chandan kumar | L17: 126.3871 | N17: 700 | O17: 10
A18: Bihar | B18: 1 | C18: 01 | D18: =CONCATENATE(G18,C18) -> 100101 | E18: Kumbhi | F18: Majhaul | G18: =VLOOKUP(F18,'BMC Master'!$B$3:$E$16,4,0) -> 1001 | H18: NA | I18: Pickup | K18: Ghanshyam kumar | L18: 157.29412 | N18: 600 | O18: 14
A19: Bihar | B19: 2 | C19: 02 | D19: =CONCATENATE(G19,C19) -> 100102 | E19: Kaura | F19: Majhaul | G19: =VLOOKUP(F19,'BMC Master'!$B$3:$E$16,4,0) -> 1001 | H19: NA | I19: Tata ACE | K19: Bambam | L19: 162 | N19: 600 | O19: 14
A20: Bihar | B20: 3 | C20: 03 | D20: =CONCATENATE(G20,C20) -> 100103 | E20: Birpur | F20: Majhaul | G20: =VLOOKUP(F20,'BMC Master'!$B$3:$E$16,4,0) -> 1001 | H20: NA | I20: Tata ACE | K20: Maa Katayani | L20: 140 | N20: 600 | O20: 14
A21: Bihar | B21: 59 | C21: 01 | D21: =CONCATENATE(G21,C21) -> 100801 | E21: Rani | F21: Teghra | G21: =VLOOKUP(F21,'BMC Master'!$B$3:$E$16,4,0) -> 1008 | H21: NA | I21: Pickup | K21: Maa Katayani | L21: 196.35484 | N21: 700 | O21: 10
A22: Bihar | B22: 60 | C22: 02 | D22: =CONCATENATE(G22,C22) -> 100802 | E22: Bakhatpur | F22: Teghra | G22: =VLOOKUP(F22,'BMC Master'!$B$3:$E$16,4,0) -> 1008 | H22: NA | I22: Tata Ace | K22: Maa Katayani | L22: 160 | N22: 600 | O22: 14
A23: Bihar | B23: 5 | C23: 01 | D23: =CONCATENATE(G23,C23) -> 100201 | E23: Lal Diyara | F23: Laldiyara | G23: =VLOOKUP(F23,'BMC Master'!$B$3:$E$16,4,0) -> 1002 | H23: NA | I23: Pickup | K23: Akash kumar | L23: 152 | N23: 700 | O23: 10
A24: Bihar | B24: 50 | C24: 02 | D24: =CONCATENATE(G24,C24) -> 100202 | E24: Pipariya | F24: Laldiyara | G24: =VLOOKUP(F24,'BMC Master'!$B$3:$E$16,4,0) -> 1002 | H24: NA | I24: Tractor | K24: Akash kumar | L24: 112 | N24: 700 | O24: 5
... A38: Bihar | B38: 36 | C38: 05 | D38: =CONCATENATE(G38,C38) -> 101405 | E38: Dhirendra kumar | F38: Dumraon | G38: =VLOOKUP(F38,'BMC Master'!$B$3:$E$16,4,0) -> 1014 | H38: NA | I38: Tata ACE | K38: Dhirendra kumar/Baliram | L38: 138 | N38: 533 | O38: 14
A39: Bihar | B39: New | C39: 06 | D39: =CONCATENATE(G39,C39) -> 101406 | E39: Kaithi | F39: Dumraon | G39: =VLOOKUP(F39,'BMC Master'!$B$3:$E$16,4,0) -> 1014 | H39: NA | I39: Tempo | K39: Santosh kumar (Shayak) | L39: 0 | N39: 500 | O39: 0
A40: Bihar | B40: 9 | C40: 01 | D40: =CONCATENATE(G40,C40) -> 100601 | E40: Bijluiya | F40: Sonvarsha | G40: =VLOOKUP(F40,'BMC Master'!$B$3:$E$16,4,0) -> 1006 | H40: NA | I40: Tractor | K40: Narayan Singh | L40: 150 | N40: 700 | O40: 5
A41: Bihar | B41: 16 | C41: 02 | D41: =CONCATENATE(G41,C41) -> 100602 | E41: Sonvarsha | F41: Sonvarsha | G41: =VLOOKUP(F41,'BMC Master'!$B$3:$E$16,4,0) -> 1006 | H41: NA | I41: Tractor | K41: Narayan Singh | L41: 160 | N41: 700 | O41: 5
A42: Bihar | B42: 3 | C42: 03 | D42: =CONCATENATE(G42,C42) -> 100603 | E42: Mano | F42: Sonvarsha | G42: =VLOOKUP(F42,'BMC Master'!$B$3:$E$16,4,0) -> 1006 | H42: NA | I42: Pickup | K42: Narayan Singh | L42: 140 | N42: 700 | O42: 10
A43: Bihar | B43: 6 | C43: 04 | D43: =CONCATENATE(G43,C43) -> 100604 | E43: Hussaina | F43: Sonvarsha | G43: =VLOOKUP(F43,'BMC Master'!$B$3:$E$16,4,0) -> 1006 | H43: NA | I43: Pickup | K43: Narayan Singh | L43: 130 | N43: 700 | O43: 10
A44: Bihar | B44: 18 | C44: 01 | D44: =CONCATENATE(G44,C44) -> 100901 | E44: PARSHAMA | F44: Halsi | G44: =VLOOKUP(F44,'BMC Master'!$B$3:$E$16,4,0) -> 1009 | H44: NA | I44: Pickup | K44: Nitesh Kumar | L44: 150 | N44: 700 | O44: 10
A45: Bihar | B45: 35 | C45: 02 | D45: =CONCATENATE(G45,C45) -> 100902 | E45: Halsi | F45: Halsi | G45: =VLOOKUP(F45,'BMC Master'!$B$3:$E$16,4,0) -> 1009 | H45: NA | I45: Pickup | K45: Nitesh Kumar | L45: 160 | N45: 700 | O45: 10
A46: Bihar | B46: 44 | C46: 03 | D46: =CONCATENATE(G46,C46) -> 100903 | E46: KHAIRMA | F46: Halsi | G46: =VLOOKUP(F46,'BMC Master'!$B$3:$E$16,4,0) -> 1009 | H46: NA | I46: Pickup | K46: Nitesh Kumar | L46: 180 | N46: 700 | O46: 10

Sheet RMC Master
A1: MPG Master
A2: Sl. No. | B2: State | C2: RMC Name | D2: Old Code | E2: Type | F2: Address | G2: Connected BMC /RMC/Plant | H2: Sahayak Name | I2: Sahayak DOB | J2: Sahayak's Father Name | K2: Sahayak Contact No | L2: Bank Account Number | M2: Bank Name | N2: Bank IFSC Code | O2: Branch Name | P2: Supervisor Name | Q2: Route | R2: Route Code
A3: 1 | B3: Bihar | E3: RMC
A4: =+A3+1 -> 2
A5: =+A4+1 -> 3
A6: =+A5+1 -> 4
A7: =+A6+1 -> 5
A8: =+A7+1 -> 6
A9: =+A8+1 -> 7
A10: =+A9+1 -> 8
A11: =+A10+1 -> 9
A12: =+A11+1 -> 10
A13: =+A12+1 -> 11
A14: =+A13+1 -> 12
A15: =+A14+1 -> 13
... A55: =+A54+1 -> 53

Sheet Bulk vendor master
A1: MPG Master
A2: Sl. No. | B2: State | C2: VLC Name | D2: Old Code | E2: Type | F2: Address | G2: Connected BMC /RMC/Plant | H2: Vendor Name | I2: DOB | J2: Vendor Father Name | K2: Vendor Contact No | L2: Bank Account Number | M2: Bank Name | N2: Bank IFSC Code | O2: Branch Name | P2: Supervisor Name | Q2: Route | R2: Route Code
