Workbook
Name Account_Details: '[1]Farmer Payment Calc'!$V$2:$V$1048576
Name Amount: '[1]Farmer Payment Calc'!$I$2:$I$1048576
Name CF_Recovery: '[1]Farmer Payment Calc'!$M$2:$M$1048576
Name Code: '[1]Farmer Payment Calc'!$E$2:$E$1048576
Name Net_Amount: '[1]Farmer Payment Calc'!$P$2:$P$1048576
Name Other_Ded: '[1]Farmer Payment Calc'!$J$2:$J$1048576
Name Sample_Milk: '[1]Farmer Payment Calc'!$K$2:$K$1048576
Name Vol_L: '[1]Farmer Payment Calc'!$H$2:$H$1048576

Sheet Rates
A1: Brand | B1: Category | C1: Presentation | D1: MRP | E1: MPG Price | F1: Farmer Price | H1: Direct | J1: Fresh Issue
A2: Bestmin Gold 24 KG | B2: FS | C2: 24 kg | D2: 4980 | E2: 3,400 | F2: 3740 | H2: Indirect | J2: Old Issue
A3: Bestmin Gold 1.2 KG | B3: FS | C3: 1.2 kg | D3: 305.00 | E3: 240 | F3: 264
A4: Bestmin Gold 6 KG | B4: FS | C4: 6 kg | D4: 1405 | E4: 1,055 | F4: 1161
A5: Calup Gel 300 Gm | B5: FS | C5: 300 Grm | D5: 212.00 | E5: 170 | F5: 242
A6: Calup Gel Plus 400 Gm | B6: FS | C6: 400 Gm | D6: 282.00 | E6: 220 | F6: 242
A7: Liveferol 1LTR | B7: FS | C7: 1 Liter | D7: 297.00 | E7: 220 | F7: 242
A8: Liveferol 500 ml | B8: FS | C8: 500 ml | D8: 169.00 | E8: 130 | F8: 143
A9: Methochelated Provical Forte 1L | B9: FS | C9: 1 Liter | D9: 276.00 | E9: 220 | F9: 242
A10: Methochelated Provical Forte 20L | B10: FS | C10: 20 Liter | D10: 4130 | E10: 3,000 | F10: 3300
A11: Methochelated Provical Forte 10L | B11: FS | C11: 10 Liter | D11: 2103 | E11: 1,600 | F11: 1760
A12: Methochelated Provical Forte 5L | B12: FS | C12: 5 Liter | D12: 1092 | E12: 815 | F12: 897
A13: Shakti All in One | B13: FS | C13: 1 kg | D13: 810 | E13: 400 | F13: 440
A14: Galacshot 1Kg | B14: FS | C14: 1 kg | D14: 210.00 | E14: 170 | F14: 184
A15: Galacshot 5Kg | B15: FS | C15: 5 kg | D15: 970.00 | E15: 730 | F15: 803
A16: Gomukh Gold | B16: CF | C16: 50 kg | E16: 1300 | F16: 1350
A17: Gomukh Buffalo Special | B17: CF | C17: 50 kg | E17: 1450 | F17: 1500
A18: Gomukh Diamond | B18: CF | C18: 50 kg | E18: 1220 | F18: 1270
A19: Sudan Fodder Seed 5Kg | B19: FS | C19: 5 kg | E19: 49 | F19: 49
A20: Anant fodder seed 250 gm | B20: FS | C20: 250 gm | E20: 75.5 | F20: 75.5
A21: Oats (JAI) | B21: FS | C21: 25 Kg | E21: 1500 | F21: 1500
A22: Makhan Grass | B22: FS | C22: 1 kg | E22: 650 | F22: 650

Sheet Sheet1
A3: Sum of Final Amount | D3: Category
A4: Payment Type | B4: MPG Code | C4: Farmer code | D4: CF | E4: Grand Total | J4: ID | K4: Payment Type | L4: MPG Code | M4: Farmer code | N4: CF | O4: Grand Total | P4: CF Deduction | U4: Payment Type | V4: MPG Code | W4: Farmer code | X4: CF | Y4: Grand Total | Z4: CF Deduction
A5: Direct | B5: 10080016 | C5: 0002 | D5: 2600 | E5: 2600 | J5: =CONCATENATE(L5,M5) -> 100800160002 | K5: Direct | L5: 10080016 | M5: 0002 | N5: 2600 | O5: 2600 | P5: =IFERROR(VLOOKUP(J5,'[1]Farmer Payment Calc'!$A$2:$M$5286,13,0),0) -> 404 | U5: Indirect | V5: 10120001 | W5: 0002 | X5: 4350 | Y5: 4350 | Z5: =IFERROR(VLOOKUP(V5,'[1]MPG Payment'!$C$3:$T$928,17,0),0) -> 4700
A6: Direct | B6: 10080016 | C6: 0018 | D6: 2600 | E6: 2600 | J6: =CONCATENATE(L6,M6) -> 100800160018 | K6: Direct | L6: 10080016 | M6: 0018 | N6: 2600 | O6: 2600 | P6: =IFERROR(VLOOKUP(J6,'[1]Farmer Payment Calc'!$A$2:$M$5286,13,0),0) -> 2025 | U6: Indirect | V6: 10120010 | W6: 0002 | X6: 4050 | Y6: 4050 | Z6: =IFERROR(VLOOKUP(V6,'[1]MPG Payment'!$C$3:$T$928,17,0),0) -> 4050
A7: Direct | B7: 10080048 | C7: 0017 | D7: 3340 | E7: 3340 | J7: =CONCATENATE(L7,M7) -> 100800480017 | K7: Direct | L7: 10080048 | M7: 0017 | N7: 3340 | O7: 3340 | P7: =IFERROR(VLOOKUP(J7,'[1]Farmer Payment Calc'!$A$2:$M$5286,13,0),0) -> 3340 | U7: Indirect | V7: 10120013 | W7: 0002 | X7: 2700 | Y7: 2700 | Z7: =IFERROR(VLOOKUP(V7,'[1]MPG Payment'!$C$3:$T$928,17,0),0) -> 2700
A8: Direct | B8: 10120007 | C8: 0014 | D8: 1350 | E8: 1350 | J8: =CONCATENATE(L8,M8) -> 101200070014 | K8: Direct | L8: 10120007 | M8: 0014 | N8: 1350 | O8: 1350 | P8: =IFERROR(VLOOKUP(J8,'[1]Farmer Payment Calc'!$A$2:$M$5286,13,0),0) -> 507 | U8: Indirect | V8: 10130015 | W8: 0002 | X8: 2700 | Y8: 2700 | Z8: =IFERROR(VLOOKUP(V8,'[1]MPG Payment'!$C$3:$T$928,17,0),0) -> 2700
A9: Direct | B9: 10120007 | C9: 0040 | D9: 1350 | E9: 1350 | J9: =CONCATENATE(L9,M9) -> 101200070040 | K9: Direct | L9: 10120007 | M9: 0040 | N9: 1350 | O9: 1350 | P9: =IFERROR(VLOOKUP(J9,'[1]Farmer Payment Calc'!$A$2:$M$5286,13,0),0) -> 1295 | U9: Indirect | V9: 10130018 | W9: 0002 | X9: 1350 | Y9: 1350 | Z9: =IFERROR(VLOOKUP(V9,'[1]MPG Payment'!$C$3:$T$928,17,0),0) -> 1350
A10: Direct | B10: 10120007 | C10: 0149 | D10: 703 | E10: 703 | J10: =CONCATENATE(L10,M10) -> 101200070149 | K10: Direct | L10: 10120007 | M10: 0149 | N10: 703 | O10: 703 | P10: =IFERROR(VLOOKUP(J10,'[1]Farmer Payment Calc'!$A$2:$M$5286,13,0),0) -> 703 | U10: Indirect | V10: 10130025 | W10: 0002 | X10: 3000 | Y10: 3000 | Z10: =IFERROR(VLOOKUP(V10,'[1]MPG Payment'!$C$3:$T$928,17,0),0) -> 3000
A11: Direct | B11: 10120007 | C11: 0107 | D11: 2601 | E11: 2601 | J11: =CONCATENATE(L11,M11) -> 101200070107 | K11: Direct | L11: 10120007 | M11: 0107 | N11: 2601 | O11: 2601 | P11: =IFERROR(VLOOKUP(J11,'[1]Farmer Payment Calc'!$A$2:$M$5286,13,0),0) -> 2601 | U11: Indirect | V11: 10130031 | W11: 0002 | X11: 3000 | Y11: 3000 | Z11: =IFERROR(VLOOKUP(V11,'[1]MPG Payment'!$C$3:$T$928,17,0),0) -> 3000
A12: Direct | B12: 10120007 | C12: 0099 | D12: 1350 | E12: 1350 | J12: =CONCATENATE(L12,M12) -> 101200070099 | K12: Direct | L12: 10120007 | M12: 0099 | N12: 1350 | O12: 1350 | P12: =IFERROR(VLOOKUP(J12,'[1]Farmer Payment Calc'!$A$2:$M$5286,13,0),0) -> 1350 | U12: Indirect | V12: 10120096 | W12: 0002 | X12: 25000 | Y12: 25000 | Z12: =IFERROR(VLOOKUP(V12,'[1]MPG Payment'!$C$3:$T$928,17,0),0) -> 20582
A13: Direct | B13: 10120007 | C13: 0079 | D13: 1350 | E13: 1350 | J13: =CONCATENATE(L13,M13) -> 101200070079 | K13: Direct | L13: 10120007 | M13: 0079 | N13: 1350 | O13: 1350 | P13: =IFERROR(VLOOKUP(J13,'[1]Farmer Payment Calc'!$A$2:$M$5286,13,0),0) -> 839 | U13: Indirect | V13: 10130080 | W13: 0002 | X13: 1500 | Y13: 1500 | Z13: =IFERROR(VLOOKUP(V13,'[1]MPG Payment'!$C$3:$T$928,17,0),0) -> 1500
A14: Direct | B14: 10120007 | C14: 0093 | D14: 305 | E14: 305 | J14: =CONCATENATE(L14,M14) -> 101200070093 | K14: Direct | L14: 10120007 | M14: 0093 | N14: 305 | O14: 305 | P14: =IFERROR(VLOOKUP(J14,'[1]Farmer Payment Calc'!$A$2:$M$5286,13,0),0) -> 305 | U14: Indirect | V14: 10530063 | W14: 0002 | X14: 3000 | Y14: 3000 | Z14: =IFERROR(VLOOKUP(V14,'[1]MPG Payment'!$C$3:$T$928,17,0),0) -> 3000
A15: Direct | B15: 10120007 | C15: 0076 | D15: 232 | E15: 232 | J15: =CONCATENATE(L15,M15) -> 101200070076 | K15: Direct | L15: 10120007 | M15: 0076 | N15: 232 | O15: 232 | P15: =IFERROR(VLOOKUP(J15,'[1]Farmer Payment Calc'!$A$2:$M$5286,13,0),0) -> 232 | U15: Indirect | V15: 10530031 | W15: 0002 | X15: 1500 | Y15: 1500 | Z15: =IFERROR(VLOOKUP(V15,'[1]MPG Payment'!$C$3:$T$928,17,0),0) -> 1500
A16: Direct | B16: 10120007 | C16: 0077 | D16: 1350 | E16: 1350 | J16: =CONCATENATE(L16,M16) -> 101200070077 | K16: Direct | L16: 10120007 | M16: 0077 | N16: 1350 | O16: 1350 | P16: =IFERROR(VLOOKUP(J16,'[1]Farmer Payment Calc'!$A$2:$M$5286,13,0),0) -> 1350 | U16: Indirect | V16: 10530089 | W16: 0002 | X16: 1350 | Y16: 1350 | Z16: =IFERROR(VLOOKUP(V16,'[1]MPG Payment'!$C$3:$T$928,17,0),0) -> 1350
... A21: Direct | B21: 10120016 | C21: 0005 | D21: 638 | E21: 638 | J21: =CONCATENATE(L21,M21) -> 101200160005 | K21: Direct | L21: 10120016 | M21: 0005 | N21: 638 | O21: 638 | P21: =IFERROR(VLOOKUP(J21,'[1]Farmer Payment Calc'!$A$2:$M$5286,13,0),0) -> 638 | U21: Indirect | V21: 10080013 | W21: 0002 | X21: 6500 | Y21: 6500 | Z21: =IFERROR(VLOOKUP(V21,'[1]MPG Payment'!$C$3:$T$928,17,0),0) -> 6500
A22: Direct | B22: 10120017 | C22: 0002 | D22: 6750 | E22: 6750 | J22: =CONCATENATE(L22,M22) -> 101200170002 | K22: Direct | L22: 10120017 | M22: 0002 | N22: 6750 | O22: 6750 | P22: =IFERROR(VLOOKUP(J22,'[1]Farmer Payment Calc'!$A$2:$M$5286,13,0),0) -> 6750 | U22: Indirect Total | X22: 76650 | Y22: 76650 | Z22: =SUM(Z5:Z21) -> 72582
A23: Direct | B23: 10120025 | C23: 0002 | D23: 4050 | E23: 4050 | J23: =CONCATENATE(L23,M23) -> 101200250002 | K23: Direct | L23: 10120025 | M23: 0002 | N23: 4050 | O23: 4050 | P23: =IFERROR(VLOOKUP(J23,'[1]Farmer Payment Calc'!$A$2:$M$5286,13,0),0) -> 0
A24: Direct | B24: 10120034 | C24: 0002 | D24: 1200 | E24: 1200 | J24: =CONCATENATE(L24,M24) -> 101200340002 | K24: Direct | L24: 10120034 | M24: 0002 | N24: 1200 | O24: 1200 | P24: =IFERROR(VLOOKUP(J24,'[1]Farmer Payment Calc'!$A$2:$M$5286,13,0),0) -> 1200
A25: Direct | B25: 10120052 | C25: 0002 | D25: 3000 | E25: 3000 | J25: =CONCATENATE(L25,M25) -> 101200520002 | K25: Direct | L25: 10120052 | M25: 0002 | N25: 3000 | O25: 3000 | P25: =IFERROR(VLOOKUP(J25,'[1]Farmer Payment Calc'!$A$2:$M$5286,13,0),0) -> 3000
A26: Direct | B26: 10120052 | C26: 0005 | D26: 1350 | E26: 1350 | J26: =CONCATENATE(L26,M26) -> 101200520005 | K26: Direct | L26: 10120052 | M26: 0005 | N26: 1350 | O26: 1350 | P26: =IFERROR(VLOOKUP(J26,'[1]Farmer Payment Calc'!$A$2:$M$5286,13,0),0) -> 0
A27: Direct | B27: 10120053 | C27: 0002 | D27: 757 | E27: 757 | J27: =CONCATENATE(L27,M27) -> 101200530002 | K27: Direct | L27: 10120053 | M27: 0002 | N27: 757 | O27: 757 | P27: =IFERROR(VLOOKUP(J27,'[1]Farmer Payment Calc'!$A$2:$M$5286,13,0),0) -> 757
A28: Direct | B28: 10130044 | C28: 0002 | D28: 3000 | E28: 3000 | J28: =CONCATENATE(L28,M28) -> 101300440002 | K28: Direct | L28: 10130044 | M28: 0002 | N28: 3000 | O28: 3000 | P28: =IFERROR(VLOOKUP(J28,'[1]Farmer Payment Calc'!$A$2:$M$5286,13,0),0) -> 0
A29: Direct | B29: 10130046 | C29: 0003 | D29: 2700 | E29: 2700 | J29: =CONCATENATE(L29,M29) -> 101300460003 | K29: Direct | L29: 10130046 | M29: 0003 | N29: 2700 | O29: 2700 | P29: =IFERROR(VLOOKUP(J29,'[1]Farmer Payment Calc'!$A$2:$M$5286,13,0),0) -> 871
A30: Direct | B30: 10110124 | C30: 0006 | D30: 1350 | E30: 1350 | J30: =CONCATENATE(L30,M30) -> 101101240006 | K30: Direct | L30: 10110124 | M30: 0006 | N30: 1350 | O30: 1350 | P30: =IFERROR(VLOOKUP(J30,'[1]Farmer Payment Calc'!$A$2:$M$5286,13,0),0) -> 1350
A31: Direct | B31: 10110124 | C31: 0007 | D31: 5400 | E31: 5400 | J31: =CONCATENATE(L31,M31) -> 101101240007 | K31: Direct | L31: 10110124 | M31: 0007 | N31: 5400 | O31: 5400 | P31: =IFERROR(VLOOKUP(J31,'[1]Farmer Payment Calc'!$A$2:$M$5286,13,0),0) -> 0
A32: Direct | B32: 10110124 | C32: 0009 | D32: 1350 | E32: 1350 | J32: =CONCATENATE(L32,M32) -> 101101240009 | K32: Direct | L32: 10110124 | M32: 0009 | N32: 1350 | O32: 1350 | P32: =IFERROR(VLOOKUP(J32,'[1]Farmer Payment Calc'!$A$2:$M$5286,13,0),0) -> 1350
A33: Direct | B33: 10110124 | C33: 0008 | D33: 1350 | E33: 1350 | J33: =CONCATENATE(L33,M33) -> 101101240008 | K33: Direct | L33: 10110124 | M33: 0008 | N33: 1350 | O33: 1350 | P33: =IFERROR(VLOOKUP(J33,'[1]Farmer Payment Calc'!$A$2:$M$5286,13,0),0) -> 1350
A34: Direct | B34: 10110124 | C34: 0026 | D34: 1350 | E34: 1350 | J34: =CONCATENATE(L34,M34) -> 101101240026 | K34: Direct | L34: 10110124 | M34: 0026 | N34: 1350 | O34: 1350 | P34: =IFERROR(VLOOKUP(J34,'[1]Farmer Payment Calc'!$A$2:$M$5286,13,0),0) -> 1350
... A158: Direct | B158: 10120094 | C158: 0002 | D158: 6750 | E158: 6750 | J158: =CONCATENATE(L158,M158) -> 101200940002 | K158: Direct | L158: 10120094 | M158: 0002 | N158: 6750 | O158: 6750 | P158: =IFERROR(VLOOKUP(J158,'[1]Farmer Payment Calc'!$A$2:$M$5286,13,0),0) -> 3510
A159: Direct Total | D159: 439003.78 | E159: 439003.78 | J159: Direct Total | N159: 439003.78 | O159: 439003.78 | P159: =SUM(P5:P158) -> 346726
A160: Indirect | B160: 10120001 | C160: 0002 | D160: 4350 | E160: 4350
A161: Indirect | B161: 10120010 | C161: 0002 | D161: 4050 | E161: 4050
A162: Indirect | B162: 10120013 | C162: 0002 | D162: 2700 | E162: 2700
A163: Indirect | B163: 10130015 | C163: 0002 | D163: 2700 | E163: 2700
A164: Indirect | B164: 10130018 | C164: 0002 | D164: 1350 | E164: 1350
A165: Indirect | B165: 10130025 | C165: 0002 | D165: 3000 | E165: 3000
A166: Indirect | B166: 10130031 | C166: 0002 | D166: 3000 | E166: 3000
A167: Indirect | B167: 10120096 | C167: 0002 | D167: 25000 | E167: 25000
A168: Indirect | B168: 10130080 | C168: 0002 | D168: 1500 | E168: 1500
A169: Indirect | B169: 10530063 | C169: 0002 | D169: 3000 | E169: 3000
...

Sheet Sheet2
A3: Sum of CF Deduction
A4: MPG Code | B4: Total
A5: 10010038 | B5: 12500
A6: 10010145 | B6: 0
A7: 10070003 | B7: 6500
A8: 10070063 | B8: 0
A9: 10070077 | B9: 0
A10: 10080004 | B10: 1300
A11: 10080013 | B11: 6500
A12: 10080016 | B12: 2429
A13: 10080048 | B13: 3340
A14: 10080052 | B14: 6800
A15: 10080119 | B15: 6500
A16: 10100003 | B16: 13000
... A97: 10600013 | B97: 0
A98: Grand Total | B98: 420545

Sheet CF indent 01-07th May-26
A1: Order Date | B1: Deduction Cycle | C1: Deduction Type | D1: Category | E1: Item Name | F1: MPG Code | G1: MPG Name | H1: Farmer code | I1: Farmer name | J1: BMC Name | K1: CSP | L1: ID | M1: Payment Type | N1: Indent Qty | O1: Rate | P1: Amount | Q1: Final Qty | R1: Final Amount | S1: Milk Amount | T1: CF Deduction | U1: FS Deduction | V1: Remarks
B2: 01-05-2026 to 07-05-2026 | D2: =VLOOKUP(Table1[[#This Row],[ Item Name ]],Rates!$A$2:$B$22,2,0) -> CF | E2: Gomukh Gold | F2: 10120007 | G2: =VLOOKUP(Table1[[#This Row],[ MPG Code ]],[2]Master!$B:$G,6,0) -> ARMAULI-2 | H2: 0107 | J2: =VLOOKUP(Table1[[#This Row],[ MPG Code ]],[2]Master!$B:$N,13,0) -> DalsinghSarai | K2: Daya Society | L2: =CONCATENATE(Table1[[#This Row],[ MPG Code ]],Table1[[#This Row],[ Farmer code ]]) -> 101200070107 | M2: =VLOOKUP(Table1[[#This Row],[ MPG Code ]],[2]Master!$B:$F,5,0) -> Direct | N2: 1 | O2: =VLOOKUP(Table1[[#This Row],[ Item Name ]],Rates!$A$2:$F$22,6,0) -> 1350 | P2: =Table1[[#This Row],[Indent Qty]]*Table1[[#This Row],[ Rate ]] -> 1350 | Q2: =Table1[[#This Row],[Indent Qty]] -> 1 | R2: =Table1[[#This Row],[ Rate ]]*Table1[[#This Row],[Final Qty]] -> 1350 | T2: 1350
B3: 01-05-2026 to 07-05-2026 | D3: =VLOOKUP(Table1[[#This Row],[ Item Name ]],Rates!$A$2:$B$22,2,0) -> CF | E3: Gomukh Gold | F3: 10120007 | G3: =VLOOKUP(Table1[[#This Row],[ MPG Code ]],[2]Master!$B:$G,6,0) -> ARMAULI-2 | H3: 0099 | J3: =VLOOKUP(Table1[[#This Row],[ MPG Code ]],[2]Master!$B:$N,13,0) -> DalsinghSarai | K3: Daya Society | L3: =CONCATENATE(Table1[[#This Row],[ MPG Code ]],Table1[[#This Row],[ Farmer code ]]) -> 101200070099 | M3: =VLOOKUP(Table1[[#This Row],[ MPG Code ]],[2]Master!$B:$F,5,0) -> Direct | N3: 1 | O3: =VLOOKUP(Table1[[#This Row],[ Item Name ]],Rates!$A$2:$F$22,6,0) -> 1350 | P3: =Table1[[#This Row],[Indent Qty]]*Table1[[#This Row],[ Rate ]] -> 1350 | Q3: =Table1[[#This Row],[Indent Qty]] -> 1 | R3: =Table1[[#This Row],[ Rate ]]*Table1[[#This Row],[Final Qty]] -> 1350 | T3: 1350
B4: 01-05-2026 to 07-05-2026 | D4: =VLOOKUP(Table1[[#This Row],[ Item Name ]],Rates!$A$2:$B$22,2,0) -> CF | E4: Gomukh Gold | F4: 10120007 | G4: =VLOOKUP(Table1[[#This Row],[ MPG Code ]],[2]Master!$B:$G,6,0) -> ARMAULI-2 | H4: 0014 | J4: =VLOOKUP(Table1[[#This Row],[ MPG Code ]],[2]Master!$B:$N,13,0) -> DalsinghSarai | K4: Daya Society | L4: =CONCATENATE(Table1[[#This Row],[ MPG Code ]],Table1[[#This Row],[ Farmer code ]]) -> 101200070014 | M4: =VLOOKUP(Table1[[#This Row],[ MPG Code ]],[2]Master!$B:$F,5,0) -> Direct | N4: 1 | O4: =VLOOKUP(Table1[[#This Row],[ Item Name ]],Rates!$A$2:$F$22,6,0) -> 1350 | P4: =Table1[[#This Row],[Indent Qty]]*Table1[[#This Row],[ Rate ]] -> 1350 | Q4: =Table1[[#This Row],[Indent Qty]] -> 1 | R4: =Table1[[#This Row],[ Rate ]]*Table1[[#This Row],[Final Qty]] -> 1350 | T4: 507
B5: 01-05-2026 to 07-05-2026 | D5: =VLOOKUP(Table1[[#This Row],[ Item Name ]],Rates!$A$2:$B$22,2,0) -> CF | E5: Gomukh Gold | F5: 10120007 | G5: =VLOOKUP(Table1[[#This Row],[ MPG Code ]],[2]Master!$B:$G,6,0) -> ARMAULI-2 | H5: 0040 | J5: =VLOOKUP(Table1[[#This Row],[ MPG Code ]],[2]Master!$B:$N,13,0) -> DalsinghSarai | K5: Daya Society | L5: =CONCATENATE(Table1[[#This Row],[ MPG Code ]],Table1[[#This Row],[ Farmer code ]]) -> 101200070040 | M5: =VLOOKUP(Table1[[#This Row],[ MPG Code ]],[2]Master!$B:$F,5,0) -> Direct | N5: 1 | O5: =VLOOKUP(Table1[[#This Row],[ Item Name ]],Rates!$A$2:$F$22,6,0) -> 1350 | P5: =Table1[[#This Row],[Indent Qty]]*Table1[[#This Row],[ Rate ]] -> 1350 | Q5: =Table1[[#This Row],[Indent Qty]] -> 1 | R5: =Table1[[#This Row],[ Rate ]]*Table1[[#This Row],[Final Qty]] -> 1350 | T5: 1295
B6: 01-05-2026 to 07-05-2026 | D6: =VLOOKUP(Table1[[#This Row],[ Item Name ]],Rates!$A$2:$B$22,2,0) -> CF | E6: Gomukh Gold | F6: 10120007 | G6: =VLOOKUP(Table1[[#This Row],[ MPG Code ]],[2]Master!$B:$G,6,0) -> ARMAULI-2 | H6: 0079 | J6: =VLOOKUP(Table1[[#This Row],[ MPG Code ]],[2]Master!$B:$N,13,0) -> DalsinghSarai | K6: Daya Society | L6: =CONCATENATE(Table1[[#This Row],[ MPG Code ]],Table1[[#This Row],[ Farmer code ]]) -> 101200070079 | M6: =VLOOKUP(Table1[[#This Row],[ MPG Code ]],[2]Master!$B:$F,5,0) -> Direct | N6: 1 | O6: =VLOOKUP(Table1[[#This Row],[ Item Name ]],Rates!$A$2:$F$22,6,0) -> 1350 | P6: =Table1[[#This Row],[Indent Qty]]*Table1[[#This Row],[ Rate ]] -> 1350 | Q6: =Table1[[#This Row],[Indent Qty]] -> 1 | R6: =Table1[[#This Row],[ Rate ]]*Table1[[#This Row],[Final Qty]] -> 1350 | T6: 839
B7: 01-05-2026 to 07-05-2026 | D7: =VLOOKUP(Table1[[#This Row],[ Item Name ]],Rates!$A$2:$B$22,2,0) -> CF | E7: Gomukh Gold | F7: 10120007 | G7: =VLOOKUP(Table1[[#This Row],[ MPG Code ]],[2]Master!$B:$G,6,0) -> ARMAULI-2 | H7: 0107 | J7: =VLOOKUP(Table1[[#This Row],[ MPG Code ]],[2]Master!$B:$N,13,0) -> DalsinghSarai | K7: Daya Society | L7: =CONCATENATE(Table1[[#This Row],[ MPG Code ]],Table1[[#This Row],[ Farmer code ]]) -> 101200070107 | M7: =VLOOKUP(Table1[[#This Row],[ MPG Code ]],[2]Master!$B:$F,5,0) -> Direct | N7: 0 | O7: 0 | P7: 1251 | Q7: =Table1[[#This Row],[Indent Qty]] -> 0 | R7: 1251 | T7: 1251
B8: 01-05-2026 to 07-05-2026 | D8: =VLOOKUP(Table1[[#This Row],[ Item Name ]],Rates!$A$2:$B$22,2,0) -> CF | E8: Gomukh Gold | F8: 10120007 | G8: =VLOOKUP(Table1[[#This Row],[ MPG Code ]],[2]Master!$B:$G,6,0) -> ARMAULI-2 | H8: 0149 | J8: =VLOOKUP(Table1[[#This Row],[ MPG Code ]],[2]Master!$B:$N,13,0) -> DalsinghSarai | K8: Daya Society | L8: =CONCATENATE(Table1[[#This Row],[ MPG Code ]],Table1[[#This Row],[ Farmer code ]]) -> 101200070149 | M8: =VLOOKUP(Table1[[#This Row],[ MPG Code ]],[2]Master!$B:$F,5,0) -> Direct | N8: 0 | O8: 0 | P8: 703 | Q8: =Table1[[#This Row],[Indent Qty]] -> 0 | R8: 703 | T8: 703
B9: 01-05-2026 to 07-05-2026 | D9: =VLOOKUP(Table1[[#This Row],[ Item Name ]],Rates!$A$2:$B$22,2,0) -> CF | E9: Gomukh Gold | F9: 10120007 | G9: =VLOOKUP(Table1[[#This Row],[ MPG Code ]],[2]Master!$B:$G,6,0) -> ARMAULI-2 | H9: 0093 | J9: =VLOOKUP(Table1[[#This Row],[ MPG Code ]],[2]Master!$B:$N,13,0) -> DalsinghSarai | K9: Daya Society | L9: =CONCATENATE(Table1[[#This Row],[ MPG Code ]],Table1[[#This Row],[ Farmer code ]]) -> 101200070093 | M9: =VLOOKUP(Table1[[#This Row],[ MPG Code ]],[2]Master!$B:$F,5,0) -> Direct | N9: 0 | O9: 0 | P9: 305 | Q9: =Table1[[#This Row],[Indent Qty]] -> 0 | R9: 305 | T9: 305
B10: 01-05-2026 to 07-05-2026 | D10: =VLOOKUP(Table1[[#This Row],[ Item Name ]],Rates!$A$2:$B$22,2,0) -> CF | E10: Gomukh Gold | F10: 10120007 | G10: =VLOOKUP(Table1[[#This Row],[ MPG Code ]],[2]Master!$B:$G,6,0) -> ARMAULI-2 | H10: 0076 | J10: =VLOOKUP(Table1[[#This Row],[ MPG Code ]],[2]Master!$B:$N,13,0) -> DalsinghSarai | K10: Daya Society | L10: =CONCATENATE(Table1[[#This Row],[ MPG Code ]],Table1[[#This Row],[ Farmer code ]]) -> 101200070076 | M10: =VLOOKUP(Table1[[#This Row],[ MPG Code ]],[2]Master!$B:$F,5,0) -> Direct | N10: 0 | O10: 0 | P10: 232 | Q10: =Table1[[#This Row],[Indent Qty]] -> 0 | R10: 232 | T10: 232
B11: 01-05-2026 to 07-05-2026 | D11: =VLOOKUP(Table1[[#This Row],[ Item Name ]],Rates!$A$2:$B$22,2,0) -> CF | E11: Gomukh Gold | F11: 10110124 | G11: =VLOOKUP(Table1[[#This Row],[ MPG Code ]],[2]Master!$B:$G,6,0) -> GOMUKH ASHRAPHA DIYARA | H11: 0007 | J11: Matihani | K11: Daya Society | L11: =CONCATENATE(Table1[[#This Row],[ MPG Code ]],Table1[[#This Row],[ Farmer code ]]) -> 101101240007 | M11: =VLOOKUP(Table1[[#This Row],[ MPG Code ]],[2]Master!$B:$F,5,0) -> Direct | N11: 4 | O11: =VLOOKUP(Table1[[#This Row],[ Item Name ]],Rates!$A$2:$F$22,6,0) -> 1350 | P11: =Table1[[#This Row],[Indent Qty]]*Table1[[#This Row],[ Rate ]] -> 5400 | Q11: =Table1[[#This Row],[Indent Qty]] -> 4 | R11: =Table1[[#This Row],[ Rate ]]*Table1[[#This Row],[Final Qty]] -> 5400 | T11: 0
B12: 01-05-2026 to 07-05-2026 | D12: =VLOOKUP(Table1[[#This Row],[ Item Name ]],Rates!$A$2:$B$22,2,0) -> CF | E12: Gomukh Gold | F12: 10110123 | G12: =VLOOKUP(Table1[[#This Row],[ MPG Code ]],[2]Master!$B:$G,6,0) -> GOMUKH SHADIPUR | H12: 0007 | J12: Matihani | K12: Daya Society | L12: =CONCATENATE(Table1[[#This Row],[ MPG Code ]],Table1[[#This Row],[ Farmer code ]]) -> 101101230007 | M12: =VLOOKUP(Table1[[#This Row],[ MPG Code ]],[2]Master!$B:$F,5,0) -> Direct | N12: 4 | O12: =VLOOKUP(Table1[[#This Row],[ Item Name ]],Rates!$A$2:$F$22,6,0) -> 1350 | P12: =Table1[[#This Row],[Indent Qty]]*Table1[[#This Row],[ Rate ]] -> 5400 | Q12: =Table1[[#This Row],[Indent Qty]] -> 4 | R12: =Table1[[#This Row],[ Rate ]]*Table1[[#This Row],[Final Qty]] -> 5400 | T12: 4621
B13: 01-05-2026 to 07-05-2026 | D13: =VLOOKUP(Table1[[#This Row],[ Item Name ]],Rates!$A$2:$B$22,2,0) -> CF | E13: Gomukh Gold | F13: 10110123 | G13: =VLOOKUP(Table1[[#This Row],[ MPG Code ]],[2]Master!$B:$G,6,0) -> GOMUKH SHADIPUR | H13: 0015 | J13: Matihani | K13: Daya Society | L13: =CONCATENATE(Table1[[#This Row],[ MPG Code ]],Table1[[#This Row],[ Farmer code ]]) -> 101101230015 | M13: =VLOOKUP(Table1[[#This Row],[ MPG Code ]],[2]Master!$B:$F,5,0) -> Direct | N13: 1 | O13: =VLOOKUP(Table1[[#This Row],[ Item Name ]],Rates!$A$2:$F$22,6,0) -> 1350 | P13: =Table1[[#This Row],[Indent Qty]]*Table1[[#This Row],[ Rate ]] -> 1350 | Q13: =Table1[[#This Row],[Indent Qty]] -> 1 | R13: =Table1[[#This Row],[ Rate ]]*Table1[[#This Row],[Final Qty]] -> 1350 | T13: 1350
B14: 01-05-2026 to 07-05-2026 | D14: =VLOOKUP(Table1[[#This Row],[ Item Name ]],Rates!$A$2:$B$22,2,0) -> CF | E14: Gomukh Gold | F14: 10110123 | G14: =VLOOKUP(Table1[[#This Row],[ MPG Code ]],[2]Master!$B:$G,6,0) -> GOMUKH SHADIPUR | H14: 0011 | J14: Matihani | K14: Daya Society | L14: =CONCATENATE(Table1[[#This Row],[ MPG Code ]],Table1[[#This Row],[ Farmer code ]]) -> 101101230011 | M14: =VLOOKUP(Table1[[#This Row],[ MPG Code ]],[2]Master!$B:$F,5,0) -> Direct | N14: 2 | O14: =VLOOKUP(Table1[[#This Row],[ Item Name ]],Rates!$A$2:$F$22,6,0) -> 1350 | P14: =Table1[[#This Row],[Indent Qty]]*Table1[[#This Row],[ Rate ]] -> 2700 | Q14: =Table1[[#This Row],[Indent Qty]] -> 2 | R14: =Table1[[#This Row],[ Rate ]]*Table1[[#This Row],[Final Qty]] -> 2700 | T14: 2700
B15: 01-05-2026 to 07-05-2026 | D15: =VLOOKUP(Table1[[#This Row],[ Item Name ]],Rates!$A$2:$B$22,2,0) -> CF | E15: Gomukh Gold | F15: 10110123 | G15: =VLOOKUP(Table1[[#This Row],[ MPG Code ]],[2]Master!$B:$G,6,0) -> GOMUKH SHADIPUR | H15: 0002 | J15: Matihani | K15: Daya Society | L15: =CONCATENATE(Table1[[#This Row],[ MPG Code ]],Table1[[#This Row],[ Farmer code ]]) -> 101101230002 | M15: =VLOOKUP(Table1[[#This Row],[ MPG Code ]],[2]Master!$B:$F,5,0) -> Direct | N15: 2 | O15: 1300 | P15: =Table1[[#This Row],[Indent Qty]]*Table1[[#This Row],[ Rate ]] -> 2600 | Q15: =Table1[[#This Row],[Indent Qty]] -> 2 | R15: =Table1[[#This Row],[ Rate ]]*Table1[[#This Row],[Final Qty]] -> 2600 | T15: 2600
B16: 01-05-2026 to 07-05-2026 | D16: =VLOOKUP(Table1[[#This Row],[ Item Name ]],Rates!$A$2:$B$22,2,0) -> CF | E16: Gomukh Gold | F16: 10110123 | G16: =VLOOKUP(Table1[[#This Row],[ MPG Code ]],[2]Master!$B:$G,6,0) -> GOMUKH SHADIPUR | H16: 0006 | J16: Matihani | K16: Daya Society | L16: =CONCATENATE(Table1[[#This Row],[ MPG Code ]],Table1[[#This Row],[ Farmer code ]]) -> 101101230006 | M16: =VLOOKUP(Table1[[#This Row],[ MPG Code ]],[2]Master!$B:$F,5,0) -> Direct | N16: 1 | O16: =VLOOKUP(Table1[[#This Row],[ Item Name ]],Rates!$A$2:$F$22,6,0) -> 1350 | P16: =Table1[[#This Row],[Indent Qty]]*Table1[[#This Row],[ Rate ]] -> 1350 | Q16: =Table1[[#This Row],[Indent Qty]] -> 1 | R16: =Table1[[#This Row],[ Rate ]]*Table1[[#This Row],[Final Qty]] -> 1350 | T16: 1350
B17: 01-05-2026 to 07-05-2026 | D17: =VLOOKUP(Table1[[#This Row],[ Item Name ]],Rates!$A$2:$B$22,2,0) -> CF | E17: Gomukh Gold | F17: 10110124 | G17: =VLOOKUP(Table1[[#This Row],[ MPG Code ]],[2]Master!$B:$G,6,0) -> GOMUKH ASHRAPHA DIYARA | H17: 0006 | J17: Matihani | K17: Daya Society | L17: =CONCATENATE(Table1[[#This Row],[ MPG Code ]],Table1[[#This Row],[ Farmer code ]]) -> 101101240006 | M17: =VLOOKUP(Table1[[#This Row],[ MPG Code ]],[2]Master!$B:$F,5,0) -> Direct | N17: 1 | O17: =VLOOKUP(Table1[[#This Row],[ Item Name ]],Rates!$A$2:$F$22,6,0) -> 1350 | P17: =Table1[[#This Row],[Indent Qty]]*Table1[[#This Row],[ Rate ]] -> 1350 | Q17: =Table1[[#This Row],[Indent Qty]] -> 1 | R17: =Table1[[#This Row],[ Rate ]]*Table1[[#This Row],[Final Qty]] -> 1350 | T17: 1350
B18: 01-05-2026 to 07-05-2026 | D18: =VLOOKUP(Table1[[#This Row],[ Item Name ]],Rates!$A$2:$B$22,2,0) -> CF | E18: Gomukh Gold | F18: 10110124 | G18: =VLOOKUP(Table1[[#This Row],[ MPG Code ]],[2]Master!$B:$G,6,0) -> GOMUKH ASHRAPHA DIYARA | H18: 0008 | J18: Matihani | K18: Daya Society | L18: =CONCATENATE(Table1[[#This Row],[ MPG Code ]],Table1[[#This Row],[ Farmer code ]]) -> 101101240008 | M18: =VLOOKUP(Table1[[#This Row],[ MPG Code ]],[2]Master!$B:$F,5,0) -> Direct | N18: 1 | O18: =VLOOKUP(Table1[[#This Row],[ Item Name ]],Rates!$A$2:$F$22,6,0) -> 1350 | P18: =Table1[[#This Row],[Indent Qty]]*Table1[[#This Row],[ Rate ]] -> 1350 | Q18: =Table1[[#This Row],[Indent Qty]] -> 1 | R18: =Table1[[#This Row],[ Rate ]]*Table1[[#This Row],[Final Qty]] -> 1350 | T18: 1350
B19: 01-05-2026 to 07-05-2026 | D19: =VLOOKUP(Table1[[#This Row],[ Item Name ]],Rates!$A$2:$B$22,2,0) -> CF | E19: Gomukh Gold | F19: 10110124 | G19: =VLOOKUP(Table1[[#This Row],[ MPG Code ]],[2]Master!$B:$G,6,0) -> GOMUKH ASHRAPHA DIYARA | H19: 0009 | J19: Matihani | K19: Daya Society | L19: =CONCATENATE(Table1[[#This Row],[ MPG Code ]],Table1[[#This Row],[ Farmer code ]]) -> 101101240009 | M19: =VLOOKUP(Table1[[#This Row],[ MPG Code ]],[2]Master!$B:$F,5,0) -> Direct | N19: 1 | O19: =VLOOKUP(Table1[[#This Row],[ Item Name ]],Rates!$A$2:$F$22,6,0) -> 1350 | P19: =Table1[[#This Row],[Indent Qty]]*Table1[[#This Row],[ Rate ]] -> 1350 | Q19: =Table1[[#This Row],[Indent Qty]] -> 1 | R19: =Table1[[#This Row],[ Rate ]]*Table1[[#This Row],[Final Qty]] -> 1350 | T19: 1350
B20: 01-05-2026 to 07-05-2026 | D20: =VLOOKUP(Table1[[#This Row],[ Item Name ]],Rates!$A$2:$B$22,2,0) -> CF | E20: Gomukh Gold | F20: 10110124 | G20: =VLOOKUP(Table1[[#This Row],[ MPG Code ]],[2]Master!$B:$G,6,0) -> GOMUKH ASHRAPHA DIYARA | H20: 0026 | J20: Matihani | K20: Daya Society | L20: =CONCATENATE(Table1[[#This Row],[ MPG Code ]],Table1[[#This Row],[ Farmer code ]]) -> 101101240026 | M20: =VLOOKUP(Table1[[#This Row],[ MPG Code ]],[2]Master!$B:$F,5,0) -> Direct | N20: 1 | O20: =VLOOKUP(Table1[[#This Row],[ Item Name ]],Rates!$A$2:$F$22,6,0) -> 1350 | P20: =Table1[[#This Row],[Indent Qty]]*Table1[[#This Row],[ Rate ]] -> 1350 | Q20: =Table1[[#This Row],[Indent Qty]] -> 1 | R20: =Table1[[#This Row],[ Rate ]]*Table1[[#This Row],[Final Qty]] -> 1350 | T20: 1350
B21: 01-05-2026 to 07-05-2026 | D21: =VLOOKUP(Table1[[#This Row],[ Item Name ]],Rates!$A$2:$B$22,2,0) -> CF | E21: Gomukh Gold | F21: 10110110 | G21: =VLOOKUP(Table1[[#This Row],[ MPG Code ]],[2]Master!$B:$G,6,0) -> GOMUKH HANSPUR | H21: 0002 | J21: Matihani | K21: Daya Society | L21: =CONCATENATE(Table1[[#This Row],[ MPG Code ]],Table1[[#This Row],[ Farmer code ]]) -> 101101100002 | M21: =VLOOKUP(Table1[[#This Row],[ MPG Code ]],[2]Master!$B:$F,5,0) -> Direct | N21: 2 | O21: 1300 | P21: =Table1[[#This Row],[Indent Qty]]*Table1[[#This Row],[ Rate ]] -> 2600 | Q21: =Table1[[#This Row],[Indent Qty]] -> 2 | R21: =Table1[[#This Row],[ Rate ]]*Table1[[#This Row],[Final Qty]] -> 2600 | T21: 0
B22: 01-05-2026 to 07-05-2026 | D22: =VLOOKUP(Table1[[#This Row],[ Item Name ]],Rates!$A$2:$B$22,2,0) -> CF | E22: Gomukh Gold | F22: 10110001 | G22: =VLOOKUP(Table1[[#This Row],[ MPG Code ]],[2]Master!$B:$G,6,0) -> Gomukh Mahendrapur | H22: 0002 | J22: Matihani | K22: Daya Society | L22: =CONCATENATE(Table1[[#This Row],[ MPG Code ]],Table1[[#This Row],[ Farmer code ]]) -> 101100010002 | M22: =VLOOKUP(Table1[[#This Row],[ MPG Code ]],[2]Master!$B:$F,5,0) -> Direct | N22: 2 | O22: 1300 | P22: =Table1[[#This Row],[Indent Qty]]*Table1[[#This Row],[ Rate ]] -> 2600 | Q22: =Table1[[#This Row],[Indent Qty]] -> 2 | R22: =Table1[[#This Row],[ Rate ]]*Table1[[#This Row],[Final Qty]] -> 2600 | T22: 2600
B23: 01-05-2026 to 07-05-2026 | D23: =VLOOKUP(Table1[[#This Row],[ Item Name ]],Rates!$A$2:$B$22,2,0) -> CF | E23: Gomukh Gold | F23: 10120084 | G23: =VLOOKUP(Table1[[#This Row],[ MPG Code ]],[2]Master!$B:$G,6,0) -> Mahmmadipur | H23: 0002 | J23: =VLOOKUP(Table1[[#This Row],[ MPG Code ]],[2]Master!$B:$N,13,0) -> DalsinghSarai | K23: Daya Society | L23: =CONCATENATE(Table1[[#This Row],[ MPG Code ]],Table1[[#This Row],[ Farmer code ]]) -> 101200840002 | M23: =VLOOKUP(Table1[[#This Row],[ MPG Code ]],[2]Master!$B:$F,5,0) -> Direct | N23: 5 | O23: =VLOOKUP(Table1[[#This Row],[ Item Name ]],Rates!$A$2:$F$22,6,0) -> 1350 | P23: =Table1[[#This Row],[Indent Qty]]*Table1[[#This Row],[ Rate ]] -> 6750 | Q23: =Table1[[#This Row],[Indent Qty]] -> 5 | R23: =Table1[[#This Row],[ Rate ]]*Table1[[#This Row],[Final Qty]] -> 6750 | T23: 6750 | V23: Unregister Farmer
B24: 01-05-2026 to 07-05-2026 | D24: =VLOOKUP(Table1[[#This Row],[ Item Name ]],Rates!$A$2:$B$22,2,0) -> CF | E24: Gomukh Gold | F24: 10120053 | G24: =VLOOKUP(Table1[[#This Row],[ MPG Code ]],[2]Master!$B:$G,6,0) -> Jagdispur | H24: 0002 | J24: =VLOOKUP(Table1[[#This Row],[ MPG Code ]],[2]Master!$B:$N,13,0) -> DalsinghSarai | K24: Daya Society | L24: =CONCATENATE(Table1[[#This Row],[ MPG Code ]],Table1[[#This Row],[ Farmer code ]]) -> 101200530002 | M24: =VLOOKUP(Table1[[#This Row],[ MPG Code ]],[2]Master!$B:$F,5,0) -> Direct | N24: 0 | O24: 0 | P24: 757 | Q24: =Table1[[#This Row],[Indent Qty]] -> 0 | R24: 757 | T24: 757
B25: 01-05-2026 to 07-05-2026 | D25: =VLOOKUP(Table1[[#This Row],[ Item Name ]],Rates!$A$2:$B$22,2,0) -> CF | E25: Gomukh Gold | F25: 10120083 | G25: =VLOOKUP(Table1[[#This Row],[ MPG Code ]],[2]Master!$B:$G,6,0) -> Beri | H25: 0002 | J25: =VLOOKUP(Table1[[#This Row],[ MPG Code ]],[2]Master!$B:$N,13,0) -> DalsinghSarai | K25: Daya Society | L25: =CONCATENATE(Table1[[#This Row],[ MPG Code ]],Table1[[#This Row],[ Farmer code ]]) -> 101200830002 | M25: =VLOOKUP(Table1[[#This Row],[ MPG Code ]],[2]Master!$B:$F,5,0) -> Direct | N25: 0 | O25: 0 | P25: 757 | Q25: =Table1[[#This Row],[Indent Qty]] -> 0 | R25: 757 | T25: 0
B26: 01-05-2026 to 07-05-2026 | D26: =VLOOKUP(Table1[[#This Row],[ Item Name ]],Rates!$A$2:$B$22,2,0) -> CF | E26: Gomukh Gold | F26: 10120083 | G26: =VLOOKUP(Table1[[#This Row],[ MPG Code ]],[2]Master!$B:$G,6,0) -> Beri | H26: 0002 | J26: =VLOOKUP(Table1[[#This Row],[ MPG Code ]],[2]Master!$B:$N,13,0) -> DalsinghSarai | K26: Daya Society | L26: =CONCATENATE(Table1[[#This Row],[ MPG Code ]],Table1[[#This Row],[ Farmer code ]]) -> 101200830002 | M26: =VLOOKUP(Table1[[#This Row],[ MPG Code ]],[2]Master!$B:$F,5,0) -> Direct | N26: 20 | O26: 1250 | P26: =Table1[[#This Row],[Indent Qty]]*Table1[[#This Row],[ Rate ]] -> 25000 | Q26: =Table1[[#This Row],[Indent Qty]] -> 20 | R26: =Table1[[#This Row],[ Rate ]]*Table1[[#This Row],[Final Qty]] -> 25000 | T26: 10397
B27: 01-05-2026 to 07-05-2026 | D27: =VLOOKUP(Table1[[#This Row],[ Item Name ]],Rates!$A$2:$B$22,2,0) -> CF | E27: Gomukh Gold | F27: 10120123 | G27: =VLOOKUP(Table1[[#This Row],[ MPG Code ]],[2]Master!$B:$G,6,0) -> GOMUKH Chakhale dad | H27: 0002 | J27: =VLOOKUP(Table1[[#This Row],[ MPG Code ]],[2]Master!$B:$N,13,0) -> DalsinghSarai | K27: Daya Society | L27: =CONCATENATE(Table1[[#This Row],[ MPG Code ]],Table1[[#This Row],[ Farmer code ]]) -> 101201230002 | M27: =VLOOKUP(Table1[[#This Row],[ MPG Code ]],[2]Master!$B:$F,5,0) -> Direct | N27: 1 | O27: =VLOOKUP(Table1[[#This Row],[ Item Name ]],Rates!$A$2:$F$22,6,0) -> 1350 | P27: =Table1[[#This Row],[Indent Qty]]*Table1[[#This Row],[ Rate ]] -> 1350 | Q27: =Table1[[#This Row],[Indent Qty]] -> 1 | R27: =Table1[[#This Row],[ Rate ]]*Table1[[#This Row],[Final Qty]] -> 1350 | T27: 1350
B28: 01-05-2026 to 07-05-2026 | D28: =VLOOKUP(Table1[[#This Row],[ Item Name ]],Rates!$A$2:$B$22,2,0) -> CF | E28: Gomukh Gold | F28: 10120017 | G28: =VLOOKUP(Table1[[#This Row],[ MPG Code ]],[2]Master!$B:$G,6,0) -> Gomukh Dumduma | H28: 0002 | J28: =VLOOKUP(Table1[[#This Row],[ MPG Code ]],[2]Master!$B:$N,13,0) -> DalsinghSarai | K28: Daya Society | L28: =CONCATENATE(Table1[[#This Row],[ MPG Code ]],Table1[[#This Row],[ Farmer code ]]) -> 101200170002 | M28: =VLOOKUP(Table1[[#This Row],[ MPG Code ]],[2]Master!$B:$F,5,0) -> Direct | N28: 5 | O28: =VLOOKUP(Table1[[#This Row],[ Item Name ]],Rates!$A$2:$F$22,6,0) -> 1350 | P28: =Table1[[#This Row],[Indent Qty]]*Table1[[#This Row],[ Rate ]] -> 6750 | Q28: =Table1[[#This Row],[Indent Qty]] -> 5 | R28: =Table1[[#This Row],[ Rate ]]*Table1[[#This Row],[Final Qty]] -> 6750 | T28: 6750
B29: 01-05-2026 to 07-05-2026 | D29: =VLOOKUP(Table1[[#This Row],[ Item Name ]],Rates!$A$2:$B$22,2,0) -> CF | E29: Gomukh Gold | F29: 10120034 | G29: =VLOOKUP(Table1[[#This Row],[ MPG Code ]],[2]Master!$B:$G,6,0) -> Matior | H29: 0002 | J29: =VLOOKUP(Table1[[#This Row],[ MPG Code ]],[2]Master!$B:$N,13,0) -> DalsinghSarai | K29: Daya Society | L29: =CONCATENATE(Table1[[#This Row],[ MPG Code ]],Table1[[#This Row],[ Farmer code ]]) -> 101200340002 | M29: =VLOOKUP(Table1[[#This Row],[ MPG Code ]],[2]Master!$B:$F,5,0) -> Direct | N29: 0 | O29: 0 | P29: 1200 | Q29: =Table1[[#This Row],[Indent Qty]] -> 0 | R29: 1200 | T29: 1200
B30: 01-05-2026 to 07-05-2026 | D30: =VLOOKUP(Table1[[#This Row],[ Item Name ]],Rates!$A$2:$B$22,2,0) -> CF | E30: Gomukh Gold | F30: 10120123 | G30: =VLOOKUP(Table1[[#This Row],[ MPG Code ]],[2]Master!$B:$G,6,0) -> GOMUKH Chakhale dad | H30: 0002 | J30: =VLOOKUP(Table1[[#This Row],[ MPG Code ]],[2]Master!$B:$N,13,0) -> DalsinghSarai | K30: Daya Society | L30: =CONCATENATE(Table1[[#This Row],[ MPG Code ]],Table1[[#This Row],[ Farmer code ]]) -> 101201230002 | M30: =VLOOKUP(Table1[[#This Row],[ MPG Code ]],[2]Master!$B:$F,5,0) -> Direct | N30: 0 | O30: 0 | P30: 150 | Q30: =Table1[[#This Row],[Indent Qty]] -> 0 | R30: 150 | T30: 150
B31: 01-05-2026 to 07-05-2026 | D31: =VLOOKUP(Table1[[#This Row],[ Item Name ]],Rates!$A$2:$B$22,2,0) -> CF | E31: Gomukh Gold | F31: 10130077 | G31: =VLOOKUP(Table1[[#This Row],[ MPG Code ]],[2]Master!$B:$G,6,0) -> Gomukh Akaha | H31: 0003 | J31: =VLOOKUP(Table1[[#This Row],[ MPG Code ]],[2]Master!$B:$N,13,0) -> Musrigharari | K31: Daya Society | L31: =CONCATENATE(Table1[[#This Row],[ MPG Code ]],Table1[[#This Row],[ Farmer code ]]) -> 101300770003 | M31: =VLOOKUP(Table1[[#This Row],[ MPG Code ]],[2]Master!$B:$F,5,0) -> Direct | N31: 1 | O31: =VLOOKUP(Table1[[#This Row],[ Item Name ]],Rates!$A$2:$F$22,6,0) -> 1350 | P31: =Table1[[#This Row],[Indent Qty]]*Table1[[#This Row],[ Rate ]] -> 1350 | Q31: =Table1[[#This Row],[Indent Qty]] -> 1 | R31: =Table1[[#This Row],[ Rate ]]*Table1[[#This Row],[Final Qty]] -> 1350 | T31: 1350
B32: 01-05-2026 to 07-05-2026 | D32: =VLOOKUP(Table1[[#This Row],[ Item Name ]],Rates!$A$2:$B$22,2,0) -> CF | E32: Gomukh Buffalo Special | F32: 10130073 | G32: =VLOOKUP(Table1[[#This Row],[ MPG Code ]],[2]Master!$B:$G,6,0) -> Dagarua | H32: 0002 | J32: =VLOOKUP(Table1[[#This Row],[ MPG Code ]],[2]Master!$B:$N,13,0) -> Musrigharari | K32: Daya Society | L32: =CONCATENATE(Table1[[#This Row],[ MPG Code ]],Table1[[#This Row],[ Farmer code ]]) -> 101300730002 | M32: =VLOOKUP(Table1[[#This Row],[ MPG Code ]],[2]Master!$B:$F,5,0) -> Direct | N32: 1 | O32: =VLOOKUP(Table1[[#This Row],[ Item Name ]],Rates!$A$2:$F$22,6,0) -> 1500 | P32: =Table1[[#This Row],[Indent Qty]]*Table1[[#This Row],[ Rate ]] -> 1500 | Q32: =Table1[[#This Row],[Indent Qty]] -> 1 | R32: =Table1[[#This Row],[ Rate ]]*Table1[[#This Row],[Final Qty]] -> 1500 | T32: 1372
B33: 01-05-2026 to 07-05-2026 | D33: =VLOOKUP(Table1[[#This Row],[ Item Name ]],Rates!$A$2:$B$22,2,0) -> CF | E33: Gomukh Gold | F33: 10130116 | G33: =VLOOKUP(Table1[[#This Row],[ MPG Code ]],[2]Master!$B:$G,6,0) -> GOMUKH CHAKIRDI | H33: 0002 | J33: =VLOOKUP(Table1[[#This Row],[ MPG Code ]],[2]Master!$B:$N,13,0) -> Musrigharari | K33: Daya Society | L33: =CONCATENATE(Table1[[#This Row],[ MPG Code ]],Table1[[#This Row],[ Farmer code ]]) -> 101301160002 | M33: =VLOOKUP(Table1[[#This Row],[ MPG Code ]],[2]Master!$B:$F,5,0) -> Direct | N33: 1 | O33: =VLOOKUP(Table1[[#This Row],[ Item Name ]],Rates!$A$2:$F$22,6,0) -> 1350 | P33: =Table1[[#This Row],[Indent Qty]]*Table1[[#This Row],[ Rate ]] -> 1350 | Q33: =Table1[[#This Row],[Indent Qty]] -> 1 | R33: =Table1[[#This Row],[ Rate ]]*Table1[[#This Row],[Final Qty]] -> 1350 | T33: 568
B34: 01-05-2026 to 07-05-2026 | D34: =VLOOKUP(Table1[[#This Row],[ Item Name ]],Rates!$A$2:$B$22,2,0) -> CF | E34: Gomukh Gold | F34: 10120007 | G34: =VLOOKUP(Table1[[#This Row],[ MPG Code ]],[2]Master!$B:$G,6,0) -> ARMAULI-2 | H34: 0077 | J34: =VLOOKUP(Table1[[#This Row],[ MPG Code ]],[2]Master!$B:$N,13,0) -> DalsinghSarai | K34: Daya Society | L34: =CONCATENATE(Table1[[#This Row],[ MPG Code ]],Table1[[#This Row],[ Farmer code ]]) -> 101200070077 | M34: =VLOOKUP(Table1[[#This Row],[ MPG Code ]],[2]Master!$B:$F,5,0) -> Direct | N34: 1 | O34: =VLOOKUP(Table1[[#This Row],[ Item Name ]],Rates!$A$2:$F$22,6,0) -> 1350 | P34: =Table1[[#This Row],[Indent Qty]]*Table1[[#This Row],[ Rate ]] -> 1350 | Q34: =Table1[[#This Row],[Indent Qty]] -> 1 | R34: =Table1[[#This Row],[ Rate ]]*Table1[[#This Row],[Final Qty]] -> 1350 | T34: 1350
B35: 01-05-2026 to 07-05-2026 | D35: =VLOOKUP(Table1[[#This Row],[ Item Name ]],Rates!$A$2:$B$22,2,0) -> CF | E35: Gomukh Gold | F35: 10130046 | G35: =VLOOKUP(Table1[[#This Row],[ MPG Code ]],[2]Master!$B:$G,6,0) -> Jahangipur Salkhanni | H35: 0003 | J35: =VLOOKUP(Table1[[#This Row],[ MPG Code ]],[2]Master!$B:$N,13,0) -> Musrigharari | K35: Daya Society | L35: =CONCATENATE(Table1[[#This Row],[ MPG Code ]],Table1[[#This Row],[ Farmer code ]]) -> 101300460003 | M35: =VLOOKUP(Table1[[#This Row],[ MPG Code ]],[2]Master!$B:$F,5,0) -> Direct | N35: 2 | O35: =VLOOKUP(Table1[[#This Row],[ Item Name ]],Rates!$A$2:$F$22,6,0) -> 1350 | P35: =Table1[[#This Row],[Indent Qty]]*Table1[[#This Row],[ Rate ]] -> 2700 | Q35: =Table1[[#This Row],[Indent Qty]] -> 2 | R35: =Table1[[#This Row],[ Rate ]]*Table1[[#This Row],[Final Qty]] -> 2700 | T35: 871
B36: 01-05-2026 to 07-05-2026 | D36: =VLOOKUP(Table1[[#This Row],[ Item Name ]],Rates!$A$2:$B$22,2,0) -> CF | E36: Gomukh Buffalo Special | F36: 10130044 | G36: =VLOOKUP(Table1[[#This Row],[ MPG Code ]],[2]Master!$B:$G,6,0) -> Lakshmipur Western Tol - Rajeev | H36: 0002 | J36: =VLOOKUP(Table1[[#This Row],[ MPG Code ]],[2]Master!$B:$N,13,0) -> Musrigharari | K36: Daya Society | L36: =CONCATENATE(Table1[[#This Row],[ MPG Code ]],Table1[[#This Row],[ Farmer code ]]) -> 101300440002 | M36: =VLOOKUP(Table1[[#This Row],[ MPG Code ]],[2]Master!$B:$F,5,0) -> Direct | N36: 2 | O36: =VLOOKUP(Table1[[#This Row],[ Item Name ]],Rates!$A$2:$F$22,6,0) -> 1500 | P36: =Table1[[#This Row],[Indent Qty]]*Table1[[#This Row],[ Rate ]] -> 3000 | Q36: =Table1[[#This Row],[Indent Qty]] -> 2 | R36: =Table1[[#This Row],[ Rate ]]*Table1[[#This Row],[Final Qty]] -> 3000 | T36: 0
B37: 01-05-2026 to 07-05-2026 | D37: =VLOOKUP(Table1[[#This Row],[ Item Name ]],Rates!$A$2:$B$22,2,0) -> CF | E37: Gomukh Gold | F37: 10010038 | G37: =VLOOKUP(Table1[[#This Row],[ MPG Code ]],[2]Master!$B:$G,6,0) -> Gomukh Goriyari | H37: 0002 | J37: =VLOOKUP(Table1[[#This Row],[ MPG Code ]],[2]Master!$B:$N,13,0) -> Majhaul | K37: Daya Society | L37: =CONCATENATE(Table1[[#This Row],[ MPG Code ]],Table1[[#This Row],[ Farmer code ]]) -> 100100380002 | M37: =VLOOKUP(Table1[[#This Row],[ MPG Code ]],[2]Master!$B:$F,5,0) -> Direct | N37: 10 | O37: 1250 | P37: =Table1[[#This Row],[Indent Qty]]*Table1[[#This Row],[ Rate ]] -> 12500 | Q37: =Table1[[#This Row],[Indent Qty]] -> 10 | R37: =Table1[[#This Row],[ Rate ]]*Table1[[#This Row],[Final Qty]] -> 12500 | T37: 12500 | V37: Deduction by any code
B38: 01-05-2026 to 07-05-2026 | D38: =VLOOKUP(Table1[[#This Row],[ Item Name ]],Rates!$A$2:$B$22,2,0) -> CF | E38: Gomukh Gold | F38: 10530096 | G38: =VLOOKUP(Table1[[#This Row],[ MPG Code ]],[2]Master!$B:$G,6,0) -> GOMUKH BHARJA | H38: 0002 | J38: =VLOOKUP(Table1[[#This Row],[ MPG Code ]],[2]Master!$B:$N,13,0) -> Kalyanpur | K38: Daya Society | L38: =CONCATENATE(Table1[[#This Row],[ MPG Code ]],Table1[[#This Row],[ Farmer code ]]) -> 105300960002 | M38: =VLOOKUP(Table1[[#This Row],[ MPG Code ]],[2]Master!$B:$F,5,0) -> Direct | N38: 10 | O38: =VLOOKUP(Table1[[#This Row],[ Item Name ]],Rates!$A$2:$F$22,6,0) -> 1350 | P38: =Table1[[#This Row],[Indent Qty]]*Table1[[#This Row],[ Rate ]] -> 13500 | Q38: =Table1[[#This Row],[Indent Qty]] -> 10 | R38: =Table1[[#This Row],[ Rate ]]*Table1[[#This Row],[Final Qty]] -> 13500 | T38: 13500
B39: 01-05-2026 to 07-05-2026 | D39: =VLOOKUP(Table1[[#This Row],[ Item Name ]],Rates!$A$2:$B$22,2,0) -> CF | E39: Gomukh Gold | F39: 10530096 | G39: =VLOOKUP(Table1[[#This Row],[ MPG Code ]],[2]Master!$B:$G,6,0) -> GOMUKH BHARJA | H39: 0002 | J39: =VLOOKUP(Table1[[#This Row],[ MPG Code ]],[2]Master!$B:$N,13,0) -> Kalyanpur | K39: Daya Society | L39: =CONCATENATE(Table1[[#This Row],[ MPG Code ]],Table1[[#This Row],[ Farmer code ]]) -> 105300960002 | M39: =VLOOKUP(Table1[[#This Row],[ MPG Code ]],[2]Master!$B:$F,5,0) -> Direct | N39: 0 | O39: 0 | P39: 5674 | Q39: =Table1[[#This Row],[Indent Qty]] -> 0 | R39: 5674 | T39: 4823
B40: 01-05-2026 to 07-05-2026 | D40: =VLOOKUP(Table1[[#This Row],[ Item Name ]],Rates!$A$2:$B$22,2,0) -> CF | E40: Gomukh Gold | F40: 10530002 | G40: =VLOOKUP(Table1[[#This Row],[ MPG Code ]],[2]Master!$B:$G,6,0) -> GOMUKH HATHA | H40: 0002 | J40: =VLOOKUP(Table1[[#This Row],[ MPG Code ]],[2]Master!$B:$N,13,0) -> Kalyanpur | K40: Daya Society | L40: =CONCATENATE(Table1[[#This Row],[ MPG Code ]],Table1[[#This Row],[ Farmer code ]]) -> 105300020002 | M40: =VLOOKUP(Table1[[#This Row],[ MPG Code ]],[2]Master!$B:$F,5,0) -> Direct | N40: 4 | O40: =VLOOKUP(Table1[[#This Row],[ Item Name ]],Rates!$A$2:$F$22,6,0) -> 1350 | P40: =Table1[[#This Row],[Indent Qty]]*Table1[[#This Row],[ Rate ]] -> 5400 | Q40: =Table1[[#This Row],[Indent Qty]] -> 4 | R40: =Table1[[#This Row],[ Rate ]]*Table1[[#This Row],[Final Qty]] -> 5400 | T40: 4834
...

Sheet Sheet4
A1: BMC Code | B1: MCC Name | C1: Code | D1: MPG NAME | E1: Type | F1: Farmer Payment | G1: BMC Volume | H1: BMC Amount | I1: Vet Deduction | J1: CF Deduction | K1: Other | L1: Stop Payment | M1: Loss Remarks | N1: Cycle | P1: loss/gain | Q1: Nos.Of farmer | R1: CF OS | S1: Deduction | T1: Balance | U1: Blank | V1: Lean Recovery | W1: Sample milk | X1: Inward Penalty | Y1: Total | Z1: Recovered | AA1: Pending | AB1: Total Adj Pending | AC1: Payment month
A2: 1001 | B2: Majhaul | C2: 10010013 | D2: Gomukh Kumbhi | E2: MPG | F2: Direct | G2: 768.5 | H2: 29428.73 | I2: 0 | J2: 0 | K2: 0 | L2: 0 | N2: 06. 01-07 May | P2: 0.016382631 | Q2: 19 | R2: 0 | S2: 0 | T2: 0 | V2: 0 | W2: 0 | X2: 0 | Y2: 0 | Z2: 0 | AA2: 0 | AB2: 0 | AC2: 46142
A3: 1008 | B3: Teghra | C3: 10010017 | D3: Gomukh Amba | E3: MPG | F3: Direct | G3: 49.45 | H3: 1708.92 | I3: 0 | J3: 0 | K3: 72.41 | L3: Release1 | M3: Letter not received | N3: 06. 01-07 May | P3: -0.003769356 | Q3: 1 | R3: 0 | S3: 0 | T3: 0 | V3: 72.41106 | W3: 0 | X3: 0 | Y3: 72.41106 | Z3: 72.41 | AA3: -0.00106 | AB3: -0.00106 | AC3: 46142
A4: 1001 | B4: Majhaul | C4: 10010019 | D4: Gomukh Jagdar | E4: MPG | F4: Direct | G4: 739.8 | H4: 30204.13 | I4: 0 | J4: 0 | K4: 0 | L4: Release1 | M4: Letter not received | N4: 06. 01-07 May | P4: -0.011406073 | Q4: 13 | R4: 0 | S4: 0 | T4: 0 | V4: 0 | W4: 0 | X4: 0 | Y4: 0 | Z4: 0 | AA4: 0 | AB4: 0 | AC4: 46142
A5: 1058 | B5: Hasanpur | C5: 10010038 | D5: Gomukh Goriyari | E5: MPG | F5: Direct | G5: 1163.4 | H5: 45015.09 | I5: 0 | J5: 12500 | K5: 0 | L5: 0 | N5: 06. 01-07 May | P5: -0.0091142029 | Q5: 8 | R5: 0 | S5: 0 | T5: 0 | V5: 0 | W5: 0 | X5: 0 | Y5: 0 | Z5: 0 | AA5: 0 | AB5: 0 | AC5: 46142
A6: 1001 | B6: Majhaul | C6: 10010047 | D6: Mohanpur - Chandan | E6: vlc | F6: Indirect | G6: 14.1 | H6: 657.06 | I6: 0 | J6: 0 | K6: 587.58045 | L6: 0 | N6: 06. 01-07 May | P6: 0 | Q6: 0 | R6: 0 | S6: 0 | T6: 0 | V6: 587.58045 | W6: 0 | X6: 0 | Y6: 587.58045 | Z6: 587.58045 | AA6: 0 | AB6: 0 | AC6: 46142
A7: 1001 | B7: Majhaul | C7: 10010049 | D7: Birpur-2 - Pankaj | E7: vlc | F7: Indirect | G7: 141.4 | H7: 4811.59 | I7: 0 | J7: 0 | K7: 4590.3744 | L7: 0 | N7: 06. 01-07 May | P7: 0 | Q7: 0 | R7: 0 | S7: 0 | T7: 0 | V7: 4590.3744 | W7: 0 | X7: 0 | Y7: 4590.3744 | Z7: 4590.3744 | AA7: 0 | AB7: 0 | AC7: 46142
A8: 1058 | B8: Hasanpur | C8: 10010050 | D8: Ekamba - Ashutosh | E8: vlc | F8: Indirect | G8: 646.6 | H8: 24645.31 | I8: 0 | J8: 0 | K8: 0 | L8: 0 | N8: 06. 01-07 May | P8: 0 | Q8: 0 | R8: 0 | S8: 0 | T8: 0 | V8: 0 | W8: 0 | X8: 0 | Y8: 0 | Z8: 0 | AA8: 0 | AB8: 0 | AC8: 46142
A9: 1001 | B9: Majhaul | C9: 10010055 | D9: GOMUKH BIRPUR PASCHIM | E9: MPG | F9: Direct | G9: 136.5 | H9: 5618.98 | I9: 0 | J9: 0 | K9: 0 | L9: 0 | N9: 06. 01-07 May | P9: 0.021726858 | Q9: 2 | R9: 0 | S9: 0 | T9: 0 | V9: 0 | W9: 0 | X9: 0 | Y9: 0 | Z9: 0 | AA9: 0 | AB9: 0 | AC9: 46142
A10: 1001 | B10: Majhaul | C10: 10010057 | D10: Manish Dairy | E10: vlc | F10: Indirect | G10: 11063 | H10: 392059.06 | I10: 0 | J10: 0 | K10: 0 | L10: 0 | N10: 06. 01-07 May | P10: 0 | Q10: 0 | R10: 0 | S10: 0 | T10: 0 | V10: 0 | W10: 0 | X10: 0 | Y10: 0 | Z10: 0 | AA10: 0 | AB10: 0 | AC10: 46142
A11: 1001 | B11: Majhaul | C11: 10010076 | D11: Gomukh Bhith-02 | E11: MPG | F11: Direct | G11: 165.7 | H11: 6324.98 | I11: 0 | J11: 0 | K11: 1024.71 | L11: Release1 | M11: Letter not received | N11: 06. 01-07 May | P11: -0.08803369 | Q11: 4 | R11: 0 | S11: 0 | T11: 0 | V11: 1024.7142 | W11: 0 | X11: 0 | Y11: 1024.7142 | Z11: 1024.71 | AA11: -0.004179661 | AB11: -0.004179661 | AC11: 46142
A12: 1001 | B12: Majhaul | C12: 10010082 | D12: Gomukh Sharmatola Sahuri | E12: MPG | F12: Direct | G12: 1053.2 | H12: 40013.17 | I12: 0 | J12: 0 | K12: 0 | L12: Release1 | M12: Letter not received | N12: 06. 01-07 May | P12: -0.013362382 | Q12: 10 | R12: 0 | S12: 0 | T12: 0 | V12: 0 | W12: 0 | X12: 0 | Y12: 0 | Z12: 0 | AA12: 0 | AB12: 0 | AC12: 46142
A13: 1001 | B13: Majhaul | C13: 10010084 | D13: Sangat- Sanjeev Kumar | E13: vlc | F13: Indirect | G13: 144.9 | H13: 5209.43 | I13: 0 | J13: 0 | K13: 1.7164452 | L13: 0 | N13: 06. 01-07 May | P13: 0 | Q13: 0 | R13: 0 | S13: 0 | T13: 0 | V13: 1.7164452 | W13: 0 | X13: 0 | Y13: 1.7164452 | Z13: 1.7164452 | AA13: 0 | AB13: 0 | AC13: 46142
A14: 1058 | B14: Hasanpur | C14: 10010086 | D14: Gomukh Garhi Bisanpur | E14: MPG | F14: Direct | G14: 164.9 | H14: 6701.85 | I14: 0 | J14: 0 | K14: 0 | L14: Release1 | M14: Letter not received | N14: 06. 01-07 May | P14: -0.1073143 | Q14: 8 | R14: 0 | S14: 0 | T14: 0 | V14: 0 | W14: 0 | X14: 0 | Y14: 0 | Z14: 0 | AA14: 0 | AB14: 0 | AC14: 46142
A15: 1058 | B15: Hasanpur | C15: 10010087 | D15: Bagaraha-Gopal Yadav | E15: vlc | F15: Indirect | G15: 105.8 | H15: 3181.92 | I15: 0 | J15: 0 | K15: 237.11863 | L15: 0 | N15: 06. 01-07 May | P15: 0 | Q15: 0 | R15: 0 | S15: 0 | T15: 0 | V15: 237.11863 | W15: 0 | X15: 0 | Y15: 237.11863 | Z15: 237.11863 | AA15: 0 | AB15: 0 | AC15: 46142
A16: 1058 | B16: Hasanpur | C16: 10010089 | D16: Gomukh Barkurwa | E16: MPG | F16: Direct | G16: 396.2 | H16: 14824.74 | I16: 0 | J16: 0 | K16: 0 | L16: 0 | N16: 06. 01-07 May | P16: -0.049713749 | Q16: 16 | R16: 0 | S16: 0 | T16: 0 | V16: 0 | W16: 0 | X16: 0 | Y16: 0 | Z16: 0 | AA16: 0 | AB16: 0 | AC16: 46142
A17: 1001 | B17: Majhaul | C17: 10010092 | D17: Kamla- Amarjeet | E17: vlc | F17: Indirect | G17: 323.7 | H17: 10003.12 | I17: 0 | J17: 0 | K17: 447.02332 | L17: 0 | N17: 06. 01-07 May | P17: 0 | Q17: 0 | R17: 0 | S17: 0 | T17: 0 | V17: 447.02332 | W17: 0 | X17: 0 | Y17: 447.02332 | Z17: 447.02332 | AA17: 0 | AB17: 0 | AC17: 46142
A18: 1058 | B18: Hasanpur | C18: 10010095 | D18: Gomukh Goha-02 | E18: MPG | F18: Direct | G18: 391.4 | H18: 15052.36 | I18: 0 | J18: 0 | K18: 0 | L18: 0 | N18: 06. 01-07 May | P18: -0.0113771 | Q18: 3 | R18: 0 | S18: 0 | T18: 0 | V18: 0 | W18: 0 | X18: 0 | Y18: 0 | Z18: 0 | AA18: 0 | AB18: 0 | AC18: 46142
A19: 1001 | B19: Majhaul | C19: 10010097 | D19: Gomukh Cheria Bariarpur | E19: MPG | F19: Direct | G19: 1339.9 | H19: 49690.54 | I19: 0 | J19: 0 | K19: 0 | L19: 0 | N19: 06. 01-07 May | P19: -0.10470254 | Q19: 11 | R19: 0 | S19: 0 | T19: 0 | V19: 0 | W19: 0 | X19: 0 | Y19: 0 | Z19: 0 | AA19: 0 | AB19: 0 | AC19: 46142
A20: 1058 | B20: Hasanpur | C20: 10010098 | D20: Gomukh Rahul Nagar | E20: MPG | F20: Direct | G20: 289.8 | H20: 12074.08 | I20: 0 | J20: 0 | K20: 0 | L20: 0 | N20: 06. 01-07 May | P20: -0.11048641 | Q20: 8 | R20: 0 | S20: 0 | T20: 0 | V20: 0 | W20: 0 | X20: 0 | Y20: 0 | Z20: 0 | AA20: 0 | AB20: 0 | AC20: 46142
A21: 1058 | B21: Hasanpur | C21: 10010099 | D21: Gomukh Bagraha-01 | E21: MPG | F21: Direct | G21: 144.7 | H21: 5792.72 | I21: 0 | J21: 0 | K21: 86.61888 | L21: 0 | N21: 06. 01-07 May | P21: -0.041234452 | Q21: 1 | R21: 0 | S21: 0 | T21: 0 | V21: 86.61888 | W21: 0 | X21: 0 | Y21: 86.61888 | Z21: 86.61888 | AA21: 0 | AB21: 0 | AC21: 46142
A22: 1058 | B22: Hasanpur | C22: 10010103 | D22: Gomukh Shobhaipura | E22: MPG | F22: Direct | G22: 20.3 | H22: 753.82 | I22: 0 | J22: 0 | K22: 133.22523 | L22: 0 | N22: 06. 01-07 May | P22: 0.0088231718 | Q22: 1 | R22: 0 | S22: 0 | T22: 0 | V22: 133.22523 | W22: 0 | X22: 0 | Y22: 133.22523 | Z22: 133.22523 | AA22: 0 | AB22: 0 | AC22: 46142
A23: 1001 | B23: Majhaul | C23: 10010108 | D23: Gomukh Pirauna | E23: MPG | F23: Direct | G23: 123.2 | H23: 4196.08 | I23: 0 | J23: 0 | K23: 152.91 | L23: Release1 | M23: Letter not received | N23: 06. 01-07 May | P23: -0.18981544 | Q23: 2 | R23: 0 | S23: 0 | T23: 0 | V23: 152.90746 | W23: 0 | X23: 0 | Y23: 152.90746 | Z23: 152.91 | AA23: 0.0025384615 | AB23: 0.0025384615 | AC23: 46142
A24: 1001 | B24: Majhaul | C24: 10010109 | D24: Parra- Nagendra Kumar | E24: vlc | F24: Indirect | G24: 264.6 | H24: 9090.81 | I24: 0 | J24: 0 | K24: 0 | L24: 0 | N24: 06. 01-07 May | P24: 0 | Q24: 0 | R24: 0 | S24: 0 | T24: 0 | V24: 0 | W24: 0 | X24: 0 | Y24: 0 | Z24: 0 | AA24: 0 | AB24: 0 | AC24: 46142
A25: 1001 | B25: Majhaul | C25: 10010113 | D25: Gomukh Basahi | E25: MPG | F25: Direct | G25: 824 | H25: 32447.86 | I25: 0 | J25: 0 | K25: 0 | L25: 0 | N25: 06. 01-07 May | P25: -0.042603586 | Q25: 23 | R25: 0 | S25: 0 | T25: 0 | V25: 0 | W25: 0 | X25: 0 | Y25: 0 | Z25: 0 | AA25: 0 | AB25: 0 | AC25: 46142
A26: 1001 | B26: Majhaul | C26: 10010116 | D26: Mohanpur- Mukesh Kumar | E26: vlc | F26: Indirect | G26: 611.2 | H26: 22836.24 | I26: 0 | J26: 0 | K26: 81.996639 | L26: 0 | N26: 06. 01-07 May | P26: 0 | Q26: 0 | R26: 0 | S26: 0 | T26: 0 | V26: 81.996639 | W26: 0 | X26: 0 | Y26: 81.996639 | Z26: 81.996639 | AA26: 0 | AB26: 0 | AC26: 46142
A27: 1001 | B27: Majhaul | C27: 10010121 | D27: Gomukh Sawantpur | E27: MPG | F27: Direct | G27: 867.3 | H27: 32702.18 | I27: 0 | J27: 0 | K27: 55.252239 | L27: 0 | N27: 06. 01-07 May | P27: -0.021594527 | Q27: 11 | R27: 0 | S27: 0 | T27: 0 | V27: 55.252239 | W27: 0 | X27: 0 | Y27: 55.252239 | Z27: 55.252239 | AA27: 0 | AB27: 0 | AC27: 46142
A28: 1001 | B28: Majhaul | C28: 10010125 | D28: Maida- Ram Kumar | E28: vlc | F28: Indirect | G28: 119.3 | H28: 4267.86 | I28: 0 | J28: 0 | K28: 1092.2253 | L28: 0 | N28: 06. 01-07 May | P28: 0 | Q28: 0 | R28: 0 | S28: 0 | T28: 0 | V28: 1092.2253 | W28: 0 | X28: 0 | Y28: 1092.2253 | Z28: 1092.2253 | AA28: 0 | AB28: 0 | AC28: 46142
A29: 1001 | B29: Majhaul | C29: 10010128 | D29: Gomukh Aure Bikrampur | E29: MPG | F29: Direct | G29: 1312.3 | H29: 53215.11 | I29: 0 | J29: 0 | K29: 0 | L29: 0 | N29: 06. 01-07 May | P29: -0.075717765 | Q29: 5 | R29: 0 | S29: 0 | T29: 0 | V29: 0 | W29: 0 | X29: 0 | Y29: 0 | Z29: 0 | AA29: 0 | AB29: 0 | AC29: 46142
A30: 1001 | B30: Majhaul | C30: 10010129 | D30: Manjhaul- Gulshan Kumar | E30: vlc | F30: Indirect | G30: 502.7 | H30: 19873.94 | I30: 0 | J30: 0 | K30: 355.88826 | L30: 0 | N30: 06. 01-07 May | P30: 0 | Q30: 0 | R30: 0 | S30: 0 | T30: 0 | V30: 355.88826 | W30: 0 | X30: 0 | Y30: 355.88826 | Z30: 355.88826 | AA30: 0 | AB30: 0 | AC30: 46142
A31: 1001 | B31: Majhaul | C31: 10010130 | D31: Khaira Manjhaul | E31: vlc | F31: Indirect | G31: 708.3 | H31: 26008.84 | I31: 0 | J31: 0 | K31: 0 | L31: 0 | N31: 06. 01-07 May | P31: 0 | Q31: 0 | R31: 0 | S31: 0 | T31: 0 | V31: 0 | W31: 0 | X31: 0 | Y31: 0 | Z31: 0 | AA31: 0 | AB31: 0 | AC31: 46142
A32: 1001 | B32: Majhaul | C32: 10010131 | D32: Mehda Shahpur | E32: vlc | F32: Indirect | G32: 481.5 | H32: 18007.79 | I32: 0 | J32: 0 | K32: 0 | L32: 0 | N32: 06. 01-07 May | P32: 0 | Q32: 0 | R32: 0 | S32: 0 | T32: 0 | V32: 0 | W32: 0 | X32: 0 | Y32: 0 | Z32: 0 | AA32: 0 | AB32: 0 | AC32: 46142
A33: 1001 | B33: Majhaul | C33: 10010140 | D33: Shri Bhairav Laxmipur | E33: MPG | F33: Direct | G33: 226.3 | H33: 9273.05 | I33: 0 | J33: 0 | K33: 63.967052 | L33: 0 | N33: 06. 01-07 May | P33: -0.13688565 | Q33: 8 | R33: 0 | S33: 0 | T33: 0 | V33: 63.967052 | W33: 0 | X33: 0 | Y33: 63.967052 | Z33: 63.967052 | AA33: 0 | AB33: 0 | AC33: 46142
A34: 1001 | B34: Majhaul | C34: 10010141 | D34: Goapalpur | E34: MPG | F34: Direct | G34: 128.1 | H34: 4828.23 | I34: 0 | J34: 0 | K34: 117.84 | L34: Release1 | M34: Letter not received | N34: 06. 01-07 May | P34: -0.13161156 | Q34: 9 | R34: 0 | S34: 0 | T34: 0 | V34: 117.8445 | W34: 0 | X34: 0 | Y34: 117.8445 | Z34: 117.84 | AA34: -0.004495082 | AB34: -0.004495082 | AC34: 46142
A35: 1001 | B35: Majhaul | C35: 10010143 | D35: Gomukh Akaha | E35: MPG | F35: Direct | G35: 114.2 | H35: 3798.2 | I35: 0 | J35: 0 | K35: 0 | L35: Release1 | M35: Letter not received | N35: 06. 01-07 May | P35: -0.092157472 | Q35: 3 | R35: 0 | S35: 0 | T35: 0 | V35: 0 | W35: 0 | X35: 0 | Y35: 0 | Z35: 0 | AA35: 0 | AB35: 0 | AC35: 46142
A36: 1001 | B36: Majhaul | C36: 10010144 | D36: Gomukh Rajakpur | E36: MPG | F36: Direct | G36: 37.1 | H36: 1061.85 | I36: 0 | J36: 0 | K36: 0 | L36: Release1 | M36: Letter not received | N36: 06. 01-07 May | P36: -0.22783569 | Q36: 1 | R36: 0 | S36: 0 | T36: 0 | V36: 0 | W36: 0 | X36: 0 | Y36: 0 | Z36: 0 | AA36: 0 | AB36: 0 | AC36: 46142
A37: 1001 | B37: Majhaul | C37: 10010145 | D37: Gomukh Mohanpur | E37: MPG | F37: Direct | G37: 306.1 | H37: 11620.3 | I37: 0 | J37: 0 | K37: 0 | L37: 0 | N37: 06. 01-07 May | P37: -0.0015308378 | Q37: 10 | R37: 0 | S37: 0 | T37: 0 | V37: 0 | W37: 0 | X37: 0 | Y37: 0 | Z37: 0 | AA37: 0 | AB37: 0 | AC37: 46142
A38: 1001 | B38: Majhaul | C38: 10010146 | D38: Gomukh Chakka | E38: MPG | F38: Direct | G38: 188.3 | H38: 7114.71 | I38: 0 | J38: 0 | K38: 0 | L38: 0 | N38: 06. 01-07 May | P38: -0.0081071225 | Q38: 5 | R38: 0 | S38: 0 | T38: 0 | V38: 0 | W38: 0 | X38: 0 | Y38: 0 | Z38: 0 | AA38: 0 | AB38: 0 | AC38: 46142
A39: 1001 | B39: Majhaul | C39: 10010147 | D39: Gamharia | E39: vlc | F39: Indirect | G39: 148.5 | H39: 5729.85 | I39: 0 | J39: 0 | K39: 0 | L39: 0 | N39: 06. 01-07 May | P39: 0 | Q39: 0 | R39: 0 | S39: 0 | T39: 0 | V39: 0 | W39: 0 | X39: 0 | Y39: 0 | Z39: 0 | AA39: 0 | AB39: 0 | AC39: 46142
A40: 1001 | B40: Majhaul | C40: 10010148 | D40: Gomukh Meghaul-02 | E40: MPG | F40: Direct | G40: 314.6 | H40: 11723.51 | I40: 0 | J40: 0 | K40: 0 | L40: 0 | N40: 06. 01-07 May | P40: -0.016377995 | Q40: 7 | R40: 0 | S40: 0 | T40: 0 | V40: 0 | W40: 0 | X40: 0 | Y40: 0 | Z40: 0 | AA40: 0 | AB40: 0 | AC40: 46142
...

Sheet Sheet3
A1: Category | B1: CF
A3: Sum of Final Amount
A4: Payment Type | B4: MPG Code | C4: ID | D4: Total
A5: Direct | B5: 10120007 | C5: 101200070040 | D5: 1350
A6: Direct | B6: 10120007 | C6: 101200070149 | D6: 703
A7: Direct | B7: 10120007 | C7: 101200070107 | D7: 2601
A8: Direct | B8: 10120007 | C8: 101200070099 | D8: 1350
A9: Direct | B9: 10120007 | C9: 101200070014 | D9: 1350
A10: Direct | B10: 10120007 | C10: 101200070079 | D10: 1350
A11: Direct | B11: 10120007 | C11: 101200070093 | D11: 305
A12: Direct | B12: 10120007 | C12: 101200070076 | D12: 232
A13: Direct | B13: 10120007 | C13: 101200070077 | D13: 1350
A14: Direct | B14: 10120016 | C14: 101200160002 | D14: 500
A15: Direct | B15: 10120016 | C15: 101200160003 | D15: 600
A16: Direct | B16: 10120016 | C16: 101200160005 | D16: 638
... A158: Direct | B158: 10120094 | C158: 101200940002 | D158: 6750
A159: Direct Total | D159: 439003.78
A160: Indirect | B160: 10120010 | C160: 101200100002 | D160: 4050
A161: Indirect | B161: 10120013 | C161: 101200130002 | D161: 2700
A162: Indirect | B162: 10130015 | C162: 101300150002 | D162: 2700
A163: Indirect | B163: 10130025 | C163: 101300250002 | D163: 3000
A164: Indirect | B164: 10130031 | C164: 101300310002 | D164: 3000
A165: Indirect | B165: 10130018 | C165: 101300180002 | D165: 1350
A166: Indirect | B166: 10120001 | C166: 101200010002 | D166: 4350
A167: Indirect | B167: 10120096 | C167: 101200960002 | D167: 25000
A168: Indirect | B168: 10130080 | C168: 101300800002 | D168: 1500
A169: Indirect | B169: 10530063 | C169: 105300630002 | D169: 3000
A170: Indirect | B170: 10530031 | C170: 105300310002 | D170: 1500
A171: Indirect | B171: 10530089 | C171: 105300890002 | D171: 1350
... A176: Indirect | B176: 10080013 | C176: 100800130002 | D176: 6500
A177: Indirect Total | D177: 76650
A178: #N/A | B178: 10010145 | C178: 100101450013 | D178: 1300
A179: #N/A | B179: 10530111 | C179: 105301110003 | D179: 1500
A180: #N/A | B180: 10600013 | C180: 106000130002 | D180: 2600
A181: #N/A | B181: 10600012 | C181: 106000120002 | D181: 2600
A182: #N/A | B182: 10540046 | C182: 105400460002 | D182: 6750
A183: #N/A Total | D183: 14750
A184: Grand Total | D184: 530403.78
