Workbook

Sheet Sumarry
C2: State wise BMC wise Gain/(Loss)
C3: State | D3: Type | E3: Code | F3: BMC Name | G3: MTD Volume | H3: Vol Kg | I3: FAT kg | J3: SNF Kg | K3: FAT Rate | L3: SNF Rate | M3: Amount | N3: Loss/gain per Kg | O3: Day book received till | P3: Remarks
C4: BR | D4: Daya BMC | E4: 1001 | F4: Majhaul | G4: =Manjhaul!J66 -> 26816.874 | H4: =+Manjhaul!AM66 -> 261.126 | I4: =+Manjhaul!AN66 -> 48.795753 | J4: =+Manjhaul!AO66 -> 20.51428 | K4: 480.53255 | L4: 299.4911 | M4: =I4*K4+J4*L4 -> 29591.792 | N4: =M4/G4 -> 1.1034766 | O4: 46212 | P4: Report till updated 09th July 26 | U4: Remarks
C5: BR | D5: Daya BMC | E5: 1058 | F5: Hasanpur | G5: =Hasanpur!J66 -> 14494.706 | H5: =+Hasanpur!AM66 -> 674.2941 | I5: =+Hasanpur!AN66 -> 15.997696 | J5: =+Hasanpur!AO66 -> 34.055125 | K5: 480.53255 | L5: 299.4911 | M5: =I5*K5+J5*L5 -> 17886.62 | N5: =M5/G5 -> 1.2340106 | O5: 46212 | P5: Report till updated 09th July 26 | V5: Challan Missing | X5: Milk reject | Z5: Out Side sell
C6: BR | D6: Daya BMC | E6: 1011 | F6: Sahibpur Kamal | G6: =+'Sahibpur Kamal'!J66 -> 88653.748 | H6: =+'Sahibpur Kamal'!AM66 -> 290.252 | I6: =+'Sahibpur Kamal'!AN66 -> 61.270743 | J6: =+'Sahibpur Kamal'!AO66 -> 10.267126 | K6: 480.53255 | L6: 299.4911 | M6: =I6*K6+J6*L6 -> 32517.499 | N6: =M6/G6 -> 0.36679215 | O6: 46212 | P6: Report till updated 09th July 26
C7: BR | D7: Daya BMC | E7: 1011 | F7: Bachhwara | G7: =+Bachhwara!J66 -> 7173.744 | H7: =+Bachhwara!AM66 -> 48.256 | I7: =+Bachhwara!AN66 -> 3.024401 | J7: =+Bachhwara!AO66 -> 1.941775 | K7: 480.53255 | L7: 299.4911 | M7: =I7*K7+J7*L7 -> 2034.8674 | N7: =M7/G7 -> 0.28365487 | O7: 46212 | P7: Report till updated 09th July 26
C8: BR | D8: Daya BMC | E8: 1012 | F8: Dalsingsarai | G8: =+Dalsingsarai!J66 -> 77497.664 | H8: =+Dalsingsarai!AM66 -> 43.3365 | I8: =+Dalsingsarai!AN66 -> -31.286379 | J8: =+Dalsingsarai!AO66 -> -4.4184238 | K8: 480.53255 | L8: 299.4911 | M8: =I8*K8+J8*L8 -> -16357.402 | N8: =M8/G8 -> -0.21106961 | O8: 46212 | P8: Report till updated 09th July 26
C9: BR | D9: Daya BMC | E9: 1054 | F9: Alauli | G9: =+Alauli!J66 -> 44781.104 | H9: =+Alauli!AM66 -> -101.604 | I9: =+Alauli!AN66 -> -21.465775 | J9: =+Alauli!AO66 -> 2.81704 | K9: 480.53255 | L9: 299.4911 | M9: =I9*K9+J9*L9 -> -9471.3251 | N9: =M9/G9 -> -0.21150272 | O9: 46212 | P9: Report till updated 09th July 26
C10: BR | D10: Daya BMC | E10: 1055 | F10: Matihani | G10: =+Matihani!J66 -> 49563.909 | H10: =+Matihani!AM66 -> 301.091 | I10: =+Matihani!AN66 -> 1.668958 | J10: =+Matihani!AO66 -> 21.910306 | K10: 480.53255 | L10: 299.4911 | M10: =I10*K10+J10*L10 -> 7363.9302 | N10: =M10/G10 -> 0.14857444 | O10: 46212 | P10: Report till updated 09th July 26
C11: BR | D11: Daya BMC | E11: 1013 | F11: Musrigharari | G11: =+Musrigharari!R66 -> 37047.761 | H11: =+Musrigharari!AM66 -> 186.239 | I11: =+Musrigharari!AN66 -> 6.691964 | J11: =+Musrigharari!AO66 -> 19.646627 | K11: 480.53255 | L11: 299.4911 | M11: =I11*K11+J11*L11 -> 9099.6964 | N11: =M11/G11 -> 0.24562068 | O11: 46212 | P11: Report till updated 09th July 26
C12: BR | D12: Daya BMC | E12: 1013 | F12: Mahua | G12: =+Mahua!R66 -> 20488.039 | H12: =+Mahua!AM66 -> 238.561 | I12: =+Mahua!AN66 -> 15.70455 | J12: =+Mahua!AO66 -> -27.385072 | K12: 480.53255 | L12: 299.4911 | M12: =I12*K12+J12*L12 -> -655.03787 | N12: =M12/G12 -> -0.031971721 | O12: 46212 | P12: Report till updated 09th July 26
C13: BR | D13: Daya BMC | E13: 1014 | F13: Dumrao | G13: =+Buxar!J66 -> 55784.934 | H13: =+Buxar!AM66 -> 771.3661 | I13: =+Buxar!AN66 -> 75.938957 | J13: =+Buxar!AO66 -> -107.56531 | K13: 480.53255 | L13: 299.4911 | M13: =I13*K13+J13*L13 -> 4276.2861 | N13: =M13/G13 -> 0.076656649 | O13: 46212 | P13: Report till updated 09th July 26
C14: BR | D14: Daya BMC | E14: 1014 | F14: Gaighat | G14: =+Gaighat!J66 -> 24573.884 | H14: =+Gaighat!AM66 -> 374.3158 | I14: =+Gaighat!AN66 -> 38.679331 | J14: =+Gaighat!AO66 -> 59.0438 | K14: 480.53255 | L14: 299.4911 | M14: =I14*K14+J14*L14 -> 36269.77 | N14: =M14/G14 -> 1.4759478 | O14: 46212 | P14: Report till updated 09th July 26
C15: BR | D15: Daya BMC | E15: 1014 | F15: Rosera | G15: =+Rosera!J66 -> 10468.714 | H15: =+Rosera!AM66 -> 83.766 | I15: =+Rosera!AN66 -> 5.82347 | J15: =+Rosera!AO66 -> -6.285059 | K15: 480.53255 | L15: 299.4911 | M15: =I15*K15+J15*L15 -> 916.04765 | N15: =M15/G15 -> 0.08750336 | O15: 46212 | P15: Report till updated 09th July 26
C16: BR | D16: Daya BMC | E16: 1057 | F16: Warisnagar | G16: =+Warisnagar!J66 -> 28981.831 | H16: =+Warisnagar!AM66 -> 320.669 | I16: =+Warisnagar!AN66 -> 55.58361 | J16: =+Warisnagar!AO66 -> -35.289097 | K16: 480.53255 | L16: 299.4911 | M16: =I16*K16+J16*L16 -> 16140.963 | N16: =M16/G16 -> 0.55693387 | O16: 46212 | P16: Report till updated 09th July 26
C17: BR | D17: Daya BMC | E17: 1053 | F17: Kalyanpur | G17: =+Kalyanpur!J66 -> 96953.9 | H17: =+Kalyanpur!AM66 -> 732.4 | I17: =+Kalyanpur!AN66 -> 43.146032 | J17: =+Kalyanpur!AO66 -> 43.531386 | K17: 480.53255 | L17: 299.4911 | M17: =I17*K17+J17*L17 -> 33770.335 | N17: =M17/G17 -> 0.34831333 | O17: 46212 | P17: Report till updated 09th July 26
C18: Bihar Daya BMCTotal | G18: =SUM(G4:G17) -> 583280.81 | H18: =SUM(H4:H17) -> 4224.0685 | I18: =SUM(I4:I17) -> 319.57331 | J18: =SUM(J4:J17) -> 32.784498 | K18: =SUM(K4:K17) -> 6727.4556 | L18: =SUM(L4:L17) -> 4192.8754 | M18: =SUM(M4:M17) -> 163384.04 | N18: =M18/G18 -> 0.28011215
C20: BR | D20: Daya BMC | E20: 1064 | F20: Singhia | G20: ='Singhia '!J66 -> 12225.163 | H20: =+'Singhia '!AM66 -> -204.1627 | I20: =+'Singhia '!AN66 -> -58.039519 | J20: =+'Singhia '!AO66 -> -52.151576 | K20: 480.53255 | L20: 299.4911 | M20: =I20*K20+J20*L20 -> -43508.811 | N20: =M20/G20 -> -3.5589556 | O20: 46212 | P20: Report till updated 09th July 26
C21: BR | D21: SP BMC | E21: 1002 | F21: Laldiyara | G21: =+Laldiyara!J66 -> 139854.84 | H21: =+Laldiyara!AM66 -> 3085.158 | I21: =+Laldiyara!AN66 -> -29.924831 | J21: =+Laldiyara!AO66 -> 101.31268 | K21: 480.53255 | L21: 299.4911 | M21: =I21*K21+J21*L21 -> 15962.391 | N21: =M21/G21 -> 0.11413542 | O21: 46212 | P21: Report till updated 09th July 26
C22: BR | D22: SP BMC | E22: 1003 | F22: Asarganj | G22: =+Asarganj!J66 -> 113470.1 | H22: =+Asarganj!AM66 -> -1080.1045 | I22: =+Asarganj!AN66 -> 21.545848 | J22: =+Asarganj!AO66 -> -8.852215 | K22: 480.53255 | L22: 299.4911 | M22: =I22*K22+J22*L22 -> 7702.3219 | N22: =M22/G22 -> 0.067879746 | O22: 46212 | P22: Report till updated 09th July 26
C23: BR | D23: SP BMC | E23: 1010 | F23: Parbatta | G23: =+Parbatta!J66 -> 54711.025 | H23: =+Parbatta!AM66 -> 423.975 | I23: =+Parbatta!AN66 -> -19.207066 | J23: =+Parbatta!AO66 -> 22.597649 | K23: 480.53255 | L23: 299.4911 | M23: =I23*K23+J23*L23 -> -2461.8256 | N23: =M23/G23 -> -0.044996884 | O23: 46212 | P23: Report till updated 09th July 26
C24: BR | D24: SP RMC | E24: 1048 | F24: Mahadatpur | G24: =+Madhatpur!J66 -> 8510.684 | H24: =+Madhatpur!AM66 -> -23.684 | I24: =+Madhatpur!AN66 -> -16.274538 | J24: =+Madhatpur!AO66 -> -6.859237 | K24: 480.53255 | L24: 299.4911 | M24: =I24*K24+J24*L24 -> -9874.7256 | N24: =M24/G24 -> -1.160274 | O24: 46212 | P24: Report till updated 09th July 26
C25: BR | D25: SP RMC | E25: 1056 | F25: Chautham | G25: =+Chautham!J66 -> 31197.299 | H25: =+Chautham!AM66 -> -850.2992 | I25: =+Chautham!AN66 -> 15.181268 | J25: =+Chautham!AO66 -> -22.434739 | K25: 480.53255 | L25: 299.4911 | M25: =I25*K25+J25*L25 -> 576.08855 | N25: =M25/G25 -> 0.018465975 | O25: 46212 | P25: Report till updated 09th July 26
C26: BR | D26: SP BMC | E26: 1006 | F26: Sonvarsha | G26: =+Sonvarsha!J66 -> 65847.282 | H26: =+Sonvarsha!AM66 -> -85.282 | I26: =+Sonvarsha!AN66 -> -60.535826 | J26: =+Sonvarsha!AO66 -> 113.82328 | K26: 480.53255 | L26: 299.4911 | M26: =I26*K26+J26*L26 -> 4999.6238 | N26: =M26/G26 -> 0.075927566 | O26: 46212 | P26: Report till updated 09th July 26
C27: BR | D27: SP BMC | E27: 1059 | F27: Gopalpur | G27: =+Gopalpur!J66 -> 22450.817 | H27: =+Gopalpur!AM66 -> 111.1827 | I27: =+Gopalpur!AN66 -> -6.6929021 | J27: =+Gopalpur!AO66 -> 15.498259 | K27: 480.53255 | L27: 299.4911 | M27: =I27*K27+J27*L27 -> 1425.4332 | N27: =M27/G27 -> 0.063491372 | O27: 46212 | P27: Report till updated 09th July 26
C28: BR | D28: SP BMC | E28: 1007 | F28: Aariya | G28: =+Araiya!J66 -> 91716.865 | H28: =+Araiya!AM66 -> 422.435 | I28: =+Araiya!AN66 -> 29.618592 | J28: =+Araiya!AO66 -> -30.884407 | K28: 480.53255 | L28: 299.4911 | M28: =I28*K28+J28*L28 -> 4983.0925 | N28: =M28/G28 -> 0.054331256 | O28: 46212 | P28: Report till updated 09th July 26
C29: BR | D29: SP BMC | E29: 1008 | F29: Teghra | G29: =+Teghra!J66 -> 42795.161 | H29: =+Teghra!AM66 -> -60.161 | I29: =+Teghra!AN66 -> -15.438211 | J29: =+Teghra!AO66 -> 28.144357 | K29: 480.53255 | L29: 299.4911 | M29: =I29*K29+J29*L29 -> 1010.4215 | N29: =M29/G29 -> 0.023610649 | O29: 46212 | P29: Report till updated 09th July 26
C30: BR | D30: SP BMC | E30: 1009 | F30: Halsi | G30: =+Halsi!J66 -> 89948.767 | H30: =+Halsi!AM66 -> -1258.767 | I30: =+Halsi!AN66 -> 66.279145 | J30: =+Halsi!AO66 -> -76.154779 | K30: 480.53255 | L30: 299.4911 | M30: =I30*K30+J30*L30 -> 9041.608 | N30: =M30/G30 -> 0.10051953 | O30: 46212 | P30: Report till updated 09th July 26
C31: Bihar Service Provider Total | G31: =SUM(G21:G30) -> 660502.85 | H31: =SUM(H21:H30) -> 684.453 | I31: =SUM(I21:I30) -> -15.448521 | J31: =SUM(J21:J30) -> 136.19085 | K31: =SUM(K21:K30) -> 4805.3255 | L31: =SUM(L21:L30) -> 2994.911 | M31: =SUM(M21:M30) -> 33364.429 | N31: =M31/G31 -> 0.050513679
C33: =C3 -> State | D33: =D3 -> Type | E33: =E3 -> Code | F33: =F3 -> BMC Name | G33: =G3 -> MTD Volume | H33: =H3 -> Vol Kg | I33: =I3 -> FAT kg | J33: =J3 -> SNF Kg | ... P33: =P3 -> Remarks
C34: JH | D34: SP RMC | E34: 2001 | F34: Itki | G34: 43466.814 | H34: 230.8563 | I34: -43.968506 | J34: -36.410451 | K34: 436.77 | L34: 296.6 | M34: =I34*K34+J34*L34 -> -30003.464 | N34: =M34/G34 -> -0.69026141 | O34: 46212 | P34: Report till updated 09th July 26
C35: JH | D35: SP RMC | E35: 2002 | F35: Pali | G35: 49149.138 | H35: -367.1383 | I35: 32.8034 | J35: -28.5229 | K35: 436.77 | L35: 296.6 | M35: =I35*K35+J35*L35 -> 5867.6489 | N35: =M35/G35 -> 0.11938457 | O35: 46212 | P35: Report till updated 09th July 26
C36: JH | D36: SP RMC | E36: 2003 | F36: Hisri Thakurgaon | G36: 11085.375 | H36: 100.045 | I36: -3.801873 | J36: -4.887925 | K36: 436.77 | L36: 296.6 | M36: =I36*K36+J36*L36 -> -3110.3026 | N36: =M36/G36 -> -0.28057712 | O36: 46212 | P36: Report till updated 09th July 26
C37: JH | D37: SP RMC | E37: 2004 | F37: Choreya | G37: 9545.6074 | H37: 369.1026 | I37: -3.114093 | J37: 5.294575 | K37: 436.77 | L37: 296.6 | M37: =I37*K37+J37*L37 -> 210.22855 | N37: =M37/G37 -> 0.02202359 | O37: 46212 | P37: Report till updated 09th July 26
C38: JH | D38: SP RMC | E38: 2005 | F38: Baski | G38: 0 | H38: 0 | I38: 0 | J38: 0 | K38: 436.77 | L38: 296.6 | M38: =I38*K38+J38*L38 -> 0 | N38: =M38/G38 -> #DIV/0! | O38: 46212 | P38: Report till updated 09th July 26
C39: JH | D39: SP RMC | E39: 2006 | F39: Ormanjhi Rmc | G39: 19665.687 | H39: -120.687 | I39: 3.0232 | J39: -2.5004 | K39: 436.77 | L39: 296.6 | M39: =I39*K39+J39*L39 -> 578.82442 | N39: =M39/G39 -> 0.029433217 | O39: 46212 | P39: Report till updated 09th July 26
C40: JH | D40: SP RMC | E40: 2007 | F40: Piragutu Rmc | G40: 13812.558 | H40: 166.2925 | I40: -1.948 | J40: -9.1776 | K40: 436.77 | L40: 296.6 | M40: =I40*K40+J40*L40 -> -3572.9041 | N40: =M40/G40 -> -0.25867071 | O40: 46212 | P40: Report till updated 09th July 26
C41: JH | D41: SP RMC | E41: 2008 | F41: Bhandra | G41: 22127.16 | H41: 127.8396 | I41: -1.7436 | J41: -7.9683 | K41: 436.77 | L41: 296.6 | M41: =I41*K41+J41*L41 -> -3124.95 | N41: =M41/G41 -> -0.14122689 | O41: 46212 | P41: Report till updated 09th July 26
C42: JH | D42: SP RMC | E42: 2009 | F42: Chanho | G42: 19902.051 | H42: 164.9486 | I42: 5.0257 | J42: -6.8641 | K42: 436.77 | L42: 296.6 | M42: =I42*K42+J42*L42 -> 159.18293 | N42: =M42/G42 -> 0.0079983177 | O42: 46212 | P42: Report till updated 09th July 26
C43: Jharkhand Total | G43: =SUM(G34:G42) -> 188754.39 | H43: =SUM(H34:H42) -> 671.2593 | I43: =SUM(I34:I42) -> -13.723772 | J43: =SUM(J34:J42) -> -91.037101 | K43: =SUM(K34:K41) -> 3494.16 | L43: =SUM(L34:L41) -> 2372.8 | M43: =SUM(M34:M42) -> -32995.736 | N43: =M43/G43 -> -0.17480778
...

Sheet Manjhaul
B1: Manjhaul Bmc | AG1: 392 | AP1: =Sumarry!$K$4 -> 480.53255 | AQ1: =Sumarry!$L$4 -> 299.4911
B2: Date | C2: Shift | D2: OB | I2: Milk from MPG in Ltr | M2: Transfer from other BMC/RMC | R2: Total Milk Receipt in Kg | U2: Tanker Dispatch Details | AC2: Plant Receipt | AH2: CB | AM2: Loss/(Gain)
D3: Qty KG | E3: Fat% | F3: Snf% | G3: FAT Kg | H3: SNF Kg | I3: Qty Ltr | J3: Qty Kg | K3: Fat% | L3: Snf% | M3: From | N3: Tanker No | O3: Qty Kg | P3: Fat% | Q3: Snf% | R3: Qty Kg | S3: FAT Kg | T3: SNF Kg | U3: Tanker | V3: Challan | W3: To | X3: Qty KG | Y3: Fat% | Z3: Snf% | AA3: FAT Kg | AB3: SNF Kg | AC3: Qty KG | AD3: Fat% | AE3: Snf% | AF3: FAT Kg | AG3: SNF Kg | AH3: Qty KG | AI3: Fat% | AJ3: Snf% | AK3: FAT Kg | AL3: SNF Kg | AM3: Qty KG | AN3: FAT Kg | AO3: SNF Kg | AP3: TS Loss% | AQ3: Amount
A4: =CONCATENATE(B4,C4) -> 46204M | B4: 46204 | C4: M | D4: 0 | E4: 0 | F4: 0 | G4: =+D4*E4% -> 0 | H4: =+D4*F4% -> 0 | I4: 707.6 | J4: 728.828 | K4: 4.456091 | L4: 8.3111362 | M4: 0 | N4: 0 | O4: 0 | P4: 0 | Q4: 0 | R4: =+J4+O4 -> 728.828 | S4: =+J4*K4%+O4*P4% -> 32.477239 | T4: =+J4*L4%+O4*Q4% -> 60.573888 | U4: 0 | V4: 0 | W4: 0 | X4: 0 | Y4: 0 | Z4: 0 | AA4: =X4*Y4% -> 0 | AB4: =X4*Z4% -> 0 | AF4: =AC4*AD4% -> 0 | AG4: =AC4*AE4% -> 0 | AH4: 729 | AI4: 4.45 | AJ4: 8.3 | AK4: =AH4*AI4% -> 32.4405 | AL4: =AH4*AJ4% -> 60.507 | AM4: =+D4+R4-AC4-AH4 -> -0.172 | AN4: =+G4+S4-AF4-AK4 -> 0.036739 | AO4: =+H4+T4-AG4-AL4 -> 0.066888 | AP4: =(AN4+AO4)/(S4+T4) -> 0.0011136566 | AQ4: =($AP$1*AN4+$AQ$1*AO4) -> 37.686646 | AR4: =(D4+J4+O4)-(X4+AH4) -> -0.172
A5: =CONCATENATE(B5,C5) -> 46204E | B5: =+B4 -> 46204 | C5: E | D5: 729 | E5: 4.45 | F5: 8.3 | G5: =+D5*E5% -> 32.4405 | H5: =+D5*F5% -> 60.507 | I5: 2484.4 | J5: 2558.932 | K5: 3.6204798 | L5: 8.0191958 | M5: 0 | N5: 0 | O5: 0 | P5: 0 | Q5: 0 | R5: =+J5+O5 -> 2558.932 | S5: =+J5*K5%+O5*P5% -> 92.645616 | T5: =+J5*L5%+O5*Q5% -> 205.20577 | U5: 0 | V5: 0 | W5: 0 | X5: 0 | Y5: 0 | Z5: 0 | AA5: =X5*Y5% -> 0 | AB5: =X5*Z5% -> 0 | AF5: =AC5*AD5% -> 0 | AG5: =AC5*AE5% -> 0 | AH5: 3288 | AI5: 3.8 | AJ5: 8.11 | AK5: =AH5*AI5% -> 124.944 | AL5: =AH5*AJ5% -> 266.6568 | AM5: =+D5+R5-AC5-AH5 -> -0.068 | AN5: =+G5+S5-AF5-AK5 -> 0.142116 | AO5: =+H5+T5-AG5-AL5 -> -0.944033 | AP5: =(AN5+AO5)/(S5+T5) -> -0.0026923394 | AQ5: =($AP$1*AN5+$AQ$1*AO5) -> -214.43812 | AR5: =(D5+J5+O5)-(X5+AH5) -> -0.068
A6: =CONCATENATE(B6,C6) -> 46205M | B6: =+B4+1 -> 46205 | C6: M | D6: 3288 | E6: 3.8 | F6: 8.11 | G6: =+D6*E6% -> 124.944 | H6: =+D6*F6% -> 266.6568 | I6: 742.5 | J6: 764.775 | K6: 4.5745455 | L6: 8.3411313 | M6: 0 | N6: 0 | O6: 0 | P6: 0 | Q6: 0 | R6: =+J6+O6 -> 764.775 | S6: =+J6*K6%+O6*P6% -> 34.98498 | T6: =+J6*L6%+O6*Q6% -> 63.790887 | U6: 6545 | V6: 87688 | W6: Hasanpur | X6: 3130 | Y6: 4.15 | Z6: 8.24 | AA6: =X6*Y6% -> 129.895 | AB6: =X6*Z6% -> 257.912 | AC6: 3110 | AD6: 4 | AE6: 7.96 | AF6: =AC6*AD6% -> 124.4 | AG6: =AC6*AE6% -> 247.556 | AH6: 923 | AI6: 3.94 | AJ6: 8.24 | AK6: =AH6*AI6% -> 36.3662 | AL6: =AH6*AJ6% -> 76.0552 | AM6: =+D6+R6-AC6-AH6 -> 19.775 | AN6: =+G6+S6-AF6-AK6 -> -0.83722 | AO6: =+H6+T6-AG6-AL6 -> 6.836487 | AP6: =(AN6+AO6)/(S6+T6) -> 0.060736161 | AQ6: =($AP$1*AN6+$AQ$1*AO6) -> 1645.1555 | AR6: =(D6+J6+O6)-(X6+AH6) -> -0.225
A7: =CONCATENATE(B7,C7) -> 46205E | B7: =+B5+1 -> 46205 | C7: E | D7: 923 | E7: 3.94 | F7: 8.24 | G7: =+D7*E7% -> 36.3662 | H7: =+D7*F7% -> 76.0552 | I7: 1805.2 | J7: 1859.356 | K7: 3.5941115 | L7: 8.0980445 | M7: 0 | N7: 0 | O7: 0 | P7: 0 | Q7: 0 | R7: =+J7+O7 -> 1859.356 | S7: =+J7*K7%+O7*P7% -> 66.827327 | T7: =+J7*L7%+O7*Q7% -> 150.57148 | U7: 0 | V7: 0 | W7: 0 | X7: 0 | Y7: 0 | Z7: 0 | AA7: =X7*Y7% -> 0 | AB7: =X7*Z7% -> 0 | AF7: =AC7*AD7% -> 0 | AG7: =AC7*AE7% -> 0 | AH7: 2782 | AI7: 3.69 | AJ7: 8.1 | AK7: =AH7*AI7% -> 102.6558 | AL7: =AH7*AJ7% -> 225.342 | AM7: =+D7+R7-AC7-AH7 -> 0.356 | AN7: =+G7+S7-AF7-AK7 -> 0.537727 | AO7: =+H7+T7-AG7-AL7 -> 1.284677 | AP7: =(AN7+AO7)/(S7+T7) -> 0.0083827692 | AQ7: =($AP$1*AN7+$AQ$1*AO7) -> 643.14465 | AR7: =(D7+J7+O7)-(X7+AH7) -> 0.356
A8: =CONCATENATE(B8,C8) -> 46206M | B8: =+B6+1 -> 46206 | C8: M | D8: 2782 | E8: 3.69 | F8: 8.1 | G8: =+D8*E8% -> 102.6558 | H8: =+D8*F8% -> 225.342 | I8: 780.4 | J8: 803.812 | K8: 4.3227704 | L8: 8.2282035 | M8: 0 | N8: 0 | O8: 0 | P8: 0 | Q8: 0 | R8: =+J8+O8 -> 803.812 | S8: =+J8*K8%+O8*P8% -> 34.746947 | T8: =+J8*L8%+O8*Q8% -> 66.139287 | U8: 6545 | V8: 87689 | W8: Hasanpur | X8: 3130 | Y8: 4.15 | Z8: 8.24 | AA8: =X8*Y8% -> 129.895 | AB8: =X8*Z8% -> 257.912 | AC8: 3120 | AD8: 3.95 | AE8: 7.88 | AF8: =AC8*AD8% -> 123.24 | AG8: =AC8*AE8% -> 245.856 | AH8: 457 | AI8: 3.82 | AJ8: 8.12 | AK8: =AH8*AI8% -> 17.4574 | AL8: =AH8*AJ8% -> 37.1084 | AM8: =+D8+R8-AC8-AH8 -> 8.812 | AN8: =+G8+S8-AF8-AK8 -> -3.294653 | AO8: =+H8+T8-AG8-AL8 -> 8.516887 | AP8: =(AN8+AO8)/(S8+T8) -> 0.051763593 | AQ8: =($AP$1*AN8+$AQ$1*AO8) -> 967.54384 | AR8: =(D8+J8+O8)-(X8+AH8) -> -1.188
A9: =CONCATENATE(B9,C9) -> 46206E | B9: =+B7+1 -> 46206 | C9: E | D9: 457 | E9: 3.82 | F9: 8.12 | G9: =+D9*E9% -> 17.4574 | H9: =+D9*F9% -> 37.1084 | I9: 1969.7 | J9: 2028.791 | K9: 3.624689 | L9: 8.1042037 | M9: 0 | N9: 0 | O9: 0 | P9: 0 | Q9: 0 | R9: =+J9+O9 -> 2028.791 | S9: =+J9*K9%+O9*P9% -> 73.537365 | T9: =+J9*L9%+O9*Q9% -> 164.41735 | U9: 0 | V9: 0 | W9: 0 | X9: 0 | Y9: 0 | Z9: 0 | AA9: =X9*Y9% -> 0 | AB9: =X9*Z9% -> 0 | AF9: =AC9*AD9% -> 0 | AG9: =AC9*AE9% -> 0 | AH9: 2485 | AI9: 3.65 | AJ9: 8.08 | AK9: =AH9*AI9% -> 90.7025 | AL9: =AH9*AJ9% -> 200.788 | AM9: =+D9+R9-AC9-AH9 -> 0.791 | AN9: =+G9+S9-AF9-AK9 -> 0.292265 | AO9: =+H9+T9-AG9-AL9 -> 0.737755 | AP9: =(AN9+AO9)/(S9+T9) -> 0.0043286387 | AQ9: =($AP$1*AN9+$AQ$1*AO9) -> 361.3939 | AR9: =(D9+J9+O9)-(X9+AH9) -> 0.791
A10: =CONCATENATE(B10,C10) -> 46207M | B10: =+B8+1 -> 46207 | C10: M | D10: 2485 | E10: 3.65 | F10: 8.08 | G10: =+D10*E10% -> 90.7025 | H10: =+D10*F10% -> 200.788 | I10: 794.2 | J10: 818.026 | K10: 4.602556 | L10: 8.3408965 | M10: 0 | N10: 0 | O10: 0 | P10: 0 | Q10: 0 | R10: =+J10+O10 -> 818.026 | S10: =+J10*K10%+O10*P10% -> 37.650105 | T10: =+J10*L10%+O10*Q10% -> 68.230702 | U10: 7181 | V10: 87690 | W10: Munger | X10: 2950 | Y10: 4 | Z10: 8.21 | AA10: =X10*Y10% -> 118 | AB10: =X10*Z10% -> 242.195 | AC10: 2950 | AD10: 3.95 | AE10: 8.07 | AF10: =AC10*AD10% -> 116.525 | AG10: =AC10*AE10% -> 238.065 | AH10: 353 | AI10: 3.86 | AJ10: 8.14 | AK10: =AH10*AI10% -> 13.6258 | AL10: =AH10*AJ10% -> 28.7342 | AM10: =+D10+R10-AC10-AH10 -> 0.026 | AN10: =+G10+S10-AF10-AK10 -> -1.798195 | AO10: =+H10+T10-AG10-AL10 -> 2.219502 | AP10: =(AN10+AO10)/(S10+T10) -> 0.0039790687 | AQ10: =($AP$1*AN10+$AQ$1*AO10) -> -199.37013 | AR10: =(D10+J10+O10)-(X10+AH10) -> 0.026
A11: =CONCATENATE(B11,C11) -> 46207E | B11: =+B9+1 -> 46207 | C11: E | D11: 353 | E11: 3.86 | F11: 8.14 | G11: =+D11*E11% -> 13.6258 | H11: =+D11*F11% -> 28.7342 | I11: 941.1 | J11: 969.333 | K11: 3.6131654 | L11: 8.0144193 | M11: 0 | N11: 0 | O11: 0 | P11: 0 | Q11: 0 | R11: =+J11+O11 -> 969.333 | S11: =+J11*K11%+O11*P11% -> 35.023605 | T11: =+J11*L11%+O11*Q11% -> 77.686411 | U11: 0 | V11: 0 | W11: 0 | X11: 0 | Y11: 0 | Z11: 0 | AA11: =X11*Y11% -> 0 | AB11: =X11*Z11% -> 0 | AF11: =AC11*AD11% -> 0 | AG11: =AC11*AE11% -> 0 | AH11: 1322 | AI11: 3.66 | AJ11: 8.04 | AK11: =AH11*AI11% -> 48.3852 | AL11: =AH11*AJ11% -> 106.2888 | AM11: =+D11+R11-AC11-AH11 -> 0.333 | AN11: =+G11+S11-AF11-AK11 -> 0.264205 | AO11: =+H11+T11-AG11-AL11 -> 0.131811 | AP11: =(AN11+AO11)/(S11+T11) -> 0.003513583 | AQ11: =($AP$1*AN11+$AQ$1*AO11) -> 166.43532 | AR11: =(D11+J11+O11)-(X11+AH11) -> 0.333
A12: =CONCATENATE(B12,C12) -> 46208M | B12: =+B10+1 -> 46208 | C12: M | D12: 1322 | E12: 3.66 | F12: 8.04 | G12: =+D12*E12% -> 48.3852 | H12: =+D12*F12% -> 106.2888 | I12: 726.2 | J12: 747.986 | K12: 4.3811071 | L12: 8.1813963 | M12: 0 | N12: 0 | O12: 0 | P12: 0 | Q12: 0 | R12: =+J12+O12 -> 747.986 | S12: =+J12*K12%+O12*P12% -> 32.770068 | T12: =+J12*L12%+O12*Q12% -> 61.195699 | U12: 0 | V12: 0 | W12: 0 | X12: 0 | Y12: 0 | Z12: 0 | AA12: =X12*Y12% -> 0 | AB12: =X12*Z12% -> 0 | AF12: =AC12*AD12% -> 0 | AG12: =AC12*AE12% -> 0 | AH12: 2070 | AI12: 3.91 | AJ12: 8.08 | AK12: =AH12*AI12% -> 80.937 | AL12: =AH12*AJ12% -> 167.256 | AM12: =+D12+R12-AC12-AH12 -> -0.014 | AN12: =+G12+S12-AF12-AK12 -> 0.218268 | AO12: =+H12+T12-AG12-AL12 -> 0.228499 | AP12: =(AN12+AO12)/(S12+T12) -> 0.0047545719 | AQ12: =($AP$1*AN12+$AQ$1*AO12) -> 173.31829 | AR12: =(D12+J12+O12)-(X12+AH12) -> -0.014
A13: =CONCATENATE(B13,C13) -> 46208E | B13: =+B11+1 -> 46208 | C13: E | D13: 2070 | E13: 3.91 | F13: 8.08 | G13: =+D13*E13% -> 80.937 | H13: =+D13*F13% -> 167.256 | I13: 1108 | J13: 1141.24 | K13: 3.6536913 | L13: 7.9899819 | M13: 0 | N13: 0 | O13: 0 | P13: 0 | Q13: 0 | R13: =+J13+O13 -> 1141.24 | S13: =+J13*K13%+O13*P13% -> 41.697387 | T13: =+J13*L13%+O13*Q13% -> 91.18487 | U13: 0 | V13: 0 | W13: 0 | X13: 0 | Y13: 0 | Z13: 0 | AA13: =X13*Y13% -> 0 | AB13: =X13*Z13% -> 0 | AF13: =AC13*AD13% -> 0 | AG13: =AC13*AE13% -> 0 | AH13: 3211 | AI13: 3.83 | AJ13: 8.04 | AK13: =AH13*AI13% -> 122.9813 | AL13: =AH13*AJ13% -> 258.1644 | AM13: =+D13+R13-AC13-AH13 -> 0.24 | AN13: =+G13+S13-AF13-AK13 -> -0.346913 | AO13: =+H13+T13-AG13-AL13 -> 0.27647 | AP13: =(AN13+AO13)/(S13+T13) -> -0.00053011592 | AQ13: =($AP$1*AN13+$AQ$1*AO13) -> -83.902684 | AR13: =(D13+J13+O13)-(X13+AH13) -> 0.24
A14: =CONCATENATE(B14,C14) -> 46209M | B14: =+B12+1 -> 46209 | C14: M | D14: 3211 | E14: 3.83 | F14: 8.04 | G14: =+D14*E14% -> 122.9813 | H14: =+D14*F14% -> 258.1644 | I14: 701.5 | J14: 722.545 | K14: 4.366871 | L14: 8.2348396 | M14: 0 | N14: 0 | O14: 0 | P14: 0 | Q14: 0 | R14: =+J14+O14 -> 722.545 | S14: =+J14*K14%+O14*P14% -> 31.552608 | T14: =+J14*L14%+O14*Q14% -> 59.500422 | U14: 0 | V14: 0 | W14: 0 | X14: 0 | Y14: 0 | Z14: 0 | AA14: =X14*Y14% -> 0 | AB14: =X14*Z14% -> 0 | AF14: =AC14*AD14% -> 0 | AG14: =AC14*AE14% -> 0 | AH14: 3933 | AI14: 3.91 | AJ14: 8.07 | AK14: =AH14*AI14% -> 153.7803 | AL14: =AH14*AJ14% -> 317.3931 | AM14: =+D14+R14-AC14-AH14 -> 0.545 | AN14: =+G14+S14-AF14-AK14 -> 0.753608 | AO14: =+H14+T14-AG14-AL14 -> 0.271722 | AP14: =(AN14+AO14)/(S14+T14) -> 0.0112608 | AQ14: =($AP$1*AN14+$AQ$1*AO14) -> 443.51149 | AR14: =(D14+J14+O14)-(X14+AH14) -> 0.545
A15: =CONCATENATE(B15,C15) -> 46209E | B15: =+B13+1 -> 46209 | C15: E | D15: 3933 | E15: 3.91 | F15: 8.07 | G15: =+D15*E15% -> 153.7803 | H15: =+D15*F15% -> 317.3931 | I15: 2317.2 | J15: 2386.716 | K15: 3.7019377 | L15: 8.0034222 | M15: 0 | N15: 0 | O15: 0 | P15: 0 | Q15: 0 | R15: =+J15+O15 -> 2386.716 | S15: =+J15*K15%+O15*P15% -> 88.354739 | T15: =+J15*L15%+O15*Q15% -> 191.01896 | U15: 6545 | V15: 87691 | W15: Munger | X15: 6280 | Y15: 4.25 | Z15: 8.26 | AA15: =X15*Y15% -> 266.9 | AB15: =X15*Z15% -> 518.728 | AC15: 6290 | AD15: 4.15 | AE15: 8.24 | AF15: =AC15*AD15% -> 261.035 | AG15: =AC15*AE15% -> 518.296 | AH15: 40 | AI15: 3.82 | AJ15: 8.03 | AK15: =AH15*AI15% -> 1.528 | AL15: =AH15*AJ15% -> 3.212 | AM15: =+D15+R15-AC15-AH15 -> -10.284 | AN15: =+G15+S15-AF15-AK15 -> -20.427961 | AO15: =+H15+T15-AG15-AL15 -> -13.095941 | AP15: =(AN15+AO15)/(S15+T15) -> -0.11999663 | AQ15: =($AP$1*AN15+$AQ$1*AO15) -> -13738.418 | AR15: =(D15+J15+O15)-(X15+AH15) -> -0.284
A16: =CONCATENATE(B16,C16) -> 46210M | B16: =+B14+1 -> 46210 | C16: M | D16: 40 | E16: 3.82 | F16: 8.03 | G16: =+D16*E16% -> 1.528 | H16: =+D16*F16% -> 3.212 | I16: 781.2 | J16: 804.636 | K16: 4.1878392 | L16: 8.1912314 | M16: 0 | N16: 0 | O16: 0 | P16: 0 | Q16: 0 | R16: =+J16+O16 -> 804.636 | S16: =+J16*K16%+O16*P16% -> 33.696862 | T16: =+J16*L16%+O16*Q16% -> 65.909597 | U16: 0 | V16: 0 | W16: 0 | X16: 0 | Y16: 0 | Z16: 0 | AA16: =X16*Y16% -> 0 | AB16: =X16*Z16% -> 0 | AF16: =AC16*AD16% -> 0 | AG16: =AC16*AE16% -> 0 | AH16: 845 | AI16: 4.16 | AJ16: 8.17 | AK16: =AH16*AI16% -> 35.152 | AL16: =AH16*AJ16% -> 69.0365 | AM16: =+D16+R16-AC16-AH16 -> -0.364 | AN16: =+G16+S16-AF16-AK16 -> 0.072862 | AO16: =+H16+T16-AG16-AL16 -> 0.085097 | AP16: =(AN16+AO16)/(S16+T16) -> 0.0015858309 | AQ16: =($AP$1*AN16+$AQ$1*AO16) -> 60.498356 | AR16: =(D16+J16+O16)-(X16+AH16) -> -0.364
A17: =CONCATENATE(B17,C17) -> 46210E | B17: =+B15+1 -> 46210 | C17: E | D17: 845 | E17: 4.16 | F17: 8.17 | G17: =+D17*E17% -> 35.152 | H17: =+D17*F17% -> 69.0365 | I17: 2510.3 | J17: 2585.609 | K17: 3.5684858 | L17: 8.0651157 | M17: 0 | N17: 0 | O17: 0 | P17: 0 | Q17: 0 | R17: =+J17+O17 -> 2585.609 | S17: =+J17*K17%+O17*P17% -> 92.267091 | T17: =+J17*L17%+O17*Q17% -> 208.53236 | U17: 0 | V17: 0 | W17: 0 | X17: 0 | Y17: 0 | Z17: 0 | AA17: =X17*Y17% -> 0 | AB17: =X17*Z17% -> 0 | AF17: =AC17*AD17% -> 0 | AG17: =AC17*AE17% -> 0 | AH17: 3431 | AI17: 3.7 | AJ17: 8.1 | AK17: =AH17*AI17% -> 126.947 | AL17: =AH17*AJ17% -> 277.911 | AM17: =+D17+R17-AC17-AH17 -> -0.391 | AN17: =+G17+S17-AF17-AK17 -> 0.472091 | AO17: =+H17+T17-AG17-AL17 -> -0.342142 | AP17: =(AN17+AO17)/(S17+T17) -> 0.00043201209 | AQ17: =($AP$1*AN17+$AQ$1*AO17) -> 124.38661 | AR17: =(D17+J17+O17)-(X17+AH17) -> -0.391
A18: =CONCATENATE(B18,C18) -> 46211M | B18: =+B16+1 -> 46211 | C18: M | D18: 3431 | E18: 3.7 | F18: 8.1 | G18: =+D18*E18% -> 126.947 | H18: =+D18*F18% -> 277.911 | I18: 1047.5 | J18: 1078.925 | K18: 4.1439809 | L18: 8.1644582 | M18: 0 | N18: 0 | O18: 0 | P18: 0 | Q18: 0 | R18: =+J18+O18 -> 1078.925 | S18: =+J18*K18%+O18*P18% -> 44.710446 | T18: =+J18*L18%+O18*Q18% -> 88.088381 | U18: 5337 | V18: 87692 | W18: Skamal | X18: 4700 | Y18: 4.05 | Z18: 8.22 | AA18: =X18*Y18% -> 190.35 | AB18: =X18*Z18% -> 386.34 | AC18: 4790 | AD18: 4 | AE18: 8.08 | AF18: =AC18*AD18% -> 191.6 | AG18: =AC18*AE18% -> 387.032 | AH18: 0 | AI18: 0 | AJ18: 0 | AK18: =AH18*AI18% -> 0 | AL18: =AH18*AJ18% -> 0 | AM18: =+D18+R18-AC18-AH18 -> -280.075 | AN18: =+G18+S18-AF18-AK18 -> -19.942554 | AO18: =+H18+T18-AG18-AL18 -> -21.032619 | AP18: =(AN18+AO18)/(S18+T18) -> -0.30855071 | AQ18: =($AP$1*AN18+$AQ$1*AO18) -> -15882.128 | AR18: =(D18+J18+O18)-(X18+AH18) -> -190.075
A19: =CONCATENATE(B19,C19) -> 46211E | B19: =+B17+1 -> 46211 | C19: E | D19: 0 | E19: 0 | F19: 0 | G19: =+D19*E19% -> 0 | H19: =+D19*F19% -> 0 | I19: 2528.7 | J19: 2604.561 | K19: 3.6025191 | L19: 7.9931823 | M19: 0 | N19: 0 | O19: 0 | P19: 0 | Q19: 0 | R19: =+J19+O19 -> 2604.561 | S19: =+J19*K19%+O19*P19% -> 93.829807 | T19: =+J19*L19%+O19*Q19% -> 208.18731 | U19: 0 | V19: 0 | W19: 0 | X19: 0 | Y19: 0 | Z19: 0 | AA19: =X19*Y19% -> 0 | AB19: =X19*Z19% -> 0 | AF19: =AC19*AD19% -> 0 | AG19: =AC19*AE19% -> 0 | AH19: 2605 | AI19: 3.59 | AJ19: 8.05 | AK19: =AH19*AI19% -> 93.5195 | AL19: =AH19*AJ19% -> 209.7025 | AM19: =+D19+R19-AC19-AH19 -> -0.439 | AN19: =+G19+S19-AF19-AK19 -> 0.310307 | AO19: =+H19+T19-AG19-AL19 -> -1.515192 | AP19: =(AN19+AO19)/(S19+T19) -> -0.0039894593 | AQ19: =($AP$1*AN19+$AQ$1*AO19) -> -304.6739 | AR19: =(D19+J19+O19)-(X19+AH19) -> -0.439
A20: =CONCATENATE(B20,C20) -> 46212M | B20: =+B18+1 -> 46212 | C20: M | D20: 2605 | E20: 3.59 | F20: 8.05 | G20: =+D20*E20% -> 93.5195 | H20: =+D20*F20% -> 209.7025 | I20: 1341.4 | J20: 1381.642 | K20: 4.0038095 | L20: 8.1124199 | M20: 0 | N20: 0 | O20: 0 | P20: 0 | Q20: 0 | R20: =+J20+O20 -> 1381.642 | S20: =+J20*K20%+O20*P20% -> 55.318313 | T20: =+J20*L20%+O20*Q20% -> 112.0846 | U20: 6545 | V20: 87699 | W20: Hasanpur | X20: 3130 | Y20: 3.9 | Z20: 8.19 | AA20: =X20*Y20% -> 122.07 | AB20: =X20*Z20% -> 256.347 | AC20: 3130 | AD20: 3.9 | AE20: 8.19 | AF20: =AC20*AD20% -> 122.07 | AG20: =AC20*AE20% -> 256.347 | AH20: 857 | AI20: 3.73 | AJ20: 8.07 | AK20: =AH20*AI20% -> 31.9661 | AL20: =AH20*AJ20% -> 69.1599 | AM20: =+D20+R20-AC20-AH20 -> -0.358 | AN20: =+G20+S20-AF20-AK20 -> -5.198287 | AO20: =+H20+T20-AG20-AL20 -> -3.7198 | AP20: =(AN20+AO20)/(S20+T20) -> -0.053273189 | AQ20: =($AP$1*AN20+$AQ$1*AO20) -> -3611.9931 | AR20: =(D20+J20+O20)-(X20+AH20) -> -0.358
A21: =CONCATENATE(B21,C21) -> 46212E | B21: =+B19+1 -> 46212 | C21: E | D21: 857 | E21: 3.73 | F21: 8.07 | G21: =+D21*E21% -> 31.9661 | H21: =+D21*F21% -> 69.1599 | I21: 2748.7 | J21: 2831.161 | K21: 3.5977517 | L21: 8.0772147 | M21: 0 | N21: 0 | O21: 0 | P21: 0 | Q21: 0 | R21: =+J21+O21 -> 2831.161 | S21: =+J21*K21%+O21*P21% -> 101.85814 | T21: =+J21*L21%+O21*Q21% -> 228.67895 | U21: 0 | V21: 0 | W21: 0 | X21: 0 | Y21: 0 | Z21: 0 | AA21: =X21*Y21% -> 0 | AB21: =X21*Z21% -> 0 | AF21: =AC21*AD21% -> 0 | AG21: =AC21*AE21% -> 0 | AH21: 3688 | AI21: 3.63 | AJ21: 8.09 | AK21: =AH21*AI21% -> 133.8744 | AL21: =AH21*AJ21% -> 298.3592 | AM21: =+D21+R21-AC21-AH21 -> 0.161 | AN21: =+G21+S21-AF21-AK21 -> -0.050158 | AO21: =+H21+T21-AG21-AL21 -> -0.520348 | AP21: =(AN21+AO21)/(S21+T21) -> -0.0017259969 | AQ21: =($AP$1*AN21+$AQ$1*AO21) -> -179.94215 | AR21: =(D21+J21+O21)-(X21+AH21) -> 0.161
A22: =CONCATENATE(B22,C22) -> 46213M | B22: =+B20+1 -> 46213 | C22: M | G22: =+D22*E22% -> 0 | H22: =+D22*F22% -> 0 | R22: =+J22+O22 -> 0 | S22: =+J22*K22%+O22*P22% -> 0 | T22: =+J22*L22%+O22*Q22% -> 0 | AA22: =X22*Y22% -> 0 | AB22: =X22*Z22% -> 0 | AF22: =AC22*AD22% -> 0 | AG22: =AC22*AE22% -> 0 | AK22: =AH22*AI22% -> 0 | AL22: =AH22*AJ22% -> 0 | AM22: =+D22+R22-AC22-AH22 -> 0 | AN22: =+G22+S22-AF22-AK22 -> 0 | AO22: =+H22+T22-AG22-AL22 -> 0 | AP22: =(AN22+AO22)/(S22+T22) -> #DIV/0! | AQ22: =($AP$1*AN22+$AQ$1*AO22) -> 0 | AR22: =(D22+J22+O22)-(X22+AH22) -> 0
A23: =CONCATENATE(B23,C23) -> 46213E | B23: =+B21+1 -> 46213 | C23: E | G23: =+D23*E23% -> 0 | H23: =+D23*F23% -> 0 | R23: =+J23+O23 -> 0 | S23: =+J23*K23%+O23*P23% -> 0 | T23: =+J23*L23%+O23*Q23% -> 0 | AA23: =X23*Y23% -> 0 | AB23: =X23*Z23% -> 0 | AF23: =AC23*AD23% -> 0 | AG23: =AC23*AE23% -> 0 | AK23: =AH23*AI23% -> 0 | AL23: =AH23*AJ23% -> 0 | AM23: =+D23+R23-AC23-AH23 -> 0 | AN23: =+G23+S23-AF23-AK23 -> 0 | AO23: =+H23+T23-AG23-AL23 -> 0 | AP23: =(AN23+AO23)/(S23+T23) -> #DIV/0! | AQ23: =($AP$1*AN23+$AQ$1*AO23) -> 0 | AR23: =(D23+J23+O23)-(X23+AH23) -> 0
A24: =CONCATENATE(B24,C24) -> 46214M | B24: =+B22+1 -> 46214 | C24: M | G24: =+D24*E24% -> 0 | H24: =+D24*F24% -> 0 | R24: =+J24+O24 -> 0 | S24: =+J24*K24%+O24*P24% -> 0 | T24: =+J24*L24%+O24*Q24% -> 0 | AA24: =X24*Y24% -> 0 | AB24: =X24*Z24% -> 0 | AF24: =AC24*AD24% -> 0 | AG24: =AC24*AE24% -> 0 | AK24: =AH24*AI24% -> 0 | AL24: =AH24*AJ24% -> 0 | AM24: =+D24+R24-AC24-AH24 -> 0 | AN24: =+G24+S24-AF24-AK24 -> 0 | AO24: =+H24+T24-AG24-AL24 -> 0 | AP24: =(AN24+AO24)/(S24+T24) -> #DIV/0! | AQ24: =($AP$1*AN24+$AQ$1*AO24) -> 0 | AR24: =(D24+J24+O24)-(X24+AH24) -> 0
A25: =CONCATENATE(B25,C25) -> 46214E | B25: =+B23+1 -> 46214 | C25: E | G25: =+D25*E25% -> 0 | H25: =+D25*F25% -> 0 | R25: =+J25+O25 -> 0 | S25: =+J25*K25%+O25*P25% -> 0 | T25: =+J25*L25%+O25*Q25% -> 0 | AA25: =X25*Y25% -> 0 | AB25: =X25*Z25% -> 0 | AF25: =AC25*AD25% -> 0 | AG25: =AC25*AE25% -> 0 | AK25: =AH25*AI25% -> 0 | AL25: =AH25*AJ25% -> 0 | AM25: =+D25+R25-AC25-AH25 -> 0 | AN25: =+G25+S25-AF25-AK25 -> 0 | AO25: =+H25+T25-AG25-AL25 -> 0 | AP25: =(AN25+AO25)/(S25+T25) -> #DIV/0! | AQ25: =($AP$1*AN25+$AQ$1*AO25) -> 0 | AR25: =(D25+J25+O25)-(X25+AH25) -> 0
A26: =CONCATENATE(B26,C26) -> 46215M | B26: =+B24+1 -> 46215 | C26: M | G26: =+D26*E26% -> 0 | H26: =+D26*F26% -> 0 | R26: =+J26+O26 -> 0 | S26: =+J26*K26%+O26*P26% -> 0 | T26: =+J26*L26%+O26*Q26% -> 0 | AA26: =X26*Y26% -> 0 | AB26: =X26*Z26% -> 0 | AF26: =AC26*AD26% -> 0 | AG26: =AC26*AE26% -> 0 | AK26: =AH26*AI26% -> 0 | AL26: =AH26*AJ26% -> 0 | AM26: =+D26+R26-AC26-AH26 -> 0 | AN26: =+G26+S26-AF26-AK26 -> 0 | AO26: =+H26+T26-AG26-AL26 -> 0 | AP26: =(AN26+AO26)/(S26+T26) -> #DIV/0! | AQ26: =($AP$1*AN26+$AQ$1*AO26) -> 0 | AR26: =(D26+J26+O26)-(X26+AH26) -> 0
A27: =CONCATENATE(B27,C27) -> 46215E | B27: =+B25+1 -> 46215 | C27: E | G27: =+D27*E27% -> 0 | H27: =+D27*F27% -> 0 | R27: =+J27+O27 -> 0 | S27: =+J27*K27%+O27*P27% -> 0 | T27: =+J27*L27%+O27*Q27% -> 0 | AA27: =X27*Y27% -> 0 | AB27: =X27*Z27% -> 0 | AF27: =AC27*AD27% -> 0 | AG27: =AC27*AE27% -> 0 | AK27: =AH27*AI27% -> 0 | AL27: =AH27*AJ27% -> 0 | AM27: =+D27+R27-AC27-AH27 -> 0 | AN27: =+G27+S27-AF27-AK27 -> 0 | AO27: =+H27+T27-AG27-AL27 -> 0 | AP27: =(AN27+AO27)/(S27+T27) -> #DIV/0! | AQ27: =($AP$1*AN27+$AQ$1*AO27) -> 0 | AR27: =(D27+J27+O27)-(X27+AH27) -> 0
A28: =CONCATENATE(B28,C28) -> 46216M | B28: =+B26+1 -> 46216 | C28: M | G28: =+D28*E28% -> 0 | H28: =+D28*F28% -> 0 | R28: =+J28+O28 -> 0 | S28: =+J28*K28%+O28*P28% -> 0 | T28: =+J28*L28%+O28*Q28% -> 0 | AA28: =X28*Y28% -> 0 | AB28: =X28*Z28% -> 0 | AF28: =AC28*AD28% -> 0 | AG28: =AC28*AE28% -> 0 | AK28: =AH28*AI28% -> 0 | AL28: =AH28*AJ28% -> 0 | AM28: =+D28+R28-AC28-AH28 -> 0 | AN28: =+G28+S28-AF28-AK28 -> 0 | AO28: =+H28+T28-AG28-AL28 -> 0 | AP28: =(AN28+AO28)/(S28+T28) -> #DIV/0! | AQ28: =($AP$1*AN28+$AQ$1*AO28) -> 0 | AR28: =(D28+J28+O28)-(X28+AH28) -> 0
A29: =CONCATENATE(B29,C29) -> 46216E | B29: =+B27+1 -> 46216 | C29: E | G29: =+D29*E29% -> 0 | H29: =+D29*F29% -> 0 | R29: =+J29+O29 -> 0 | S29: =+J29*K29%+O29*P29% -> 0 | T29: =+J29*L29%+O29*Q29% -> 0 | AA29: =X29*Y29% -> 0 | AB29: =X29*Z29% -> 0 | AF29: =AC29*AD29% -> 0 | AG29: =AC29*AE29% -> 0 | AK29: =AH29*AI29% -> 0 | AL29: =AH29*AJ29% -> 0 | AM29: =+D29+R29-AC29-AH29 -> 0 | AN29: =+G29+S29-AF29-AK29 -> 0 | AO29: =+H29+T29-AG29-AL29 -> 0 | AP29: =(AN29+AO29)/(S29+T29) -> #DIV/0! | AQ29: =($AP$1*AN29+$AQ$1*AO29) -> 0 | AR29: =(D29+J29+O29)-(X29+AH29) -> 0
A30: =CONCATENATE(B30,C30) -> 46217M | B30: =+B28+1 -> 46217 | C30: M | G30: =+D30*E30% -> 0 | H30: =+D30*F30% -> 0 | R30: =+J30+O30 -> 0 | S30: =+J30*K30%+O30*P30% -> 0 | T30: =+J30*L30%+O30*Q30% -> 0 | AA30: =X30*Y30% -> 0 | AB30: =X30*Z30% -> 0 | AF30: =AC30*AD30% -> 0 | AG30: =AC30*AE30% -> 0 | AK30: =AH30*AI30% -> 0 | AL30: =AH30*AJ30% -> 0 | AM30: =+D30+R30-AC30-AH30 -> 0 | AN30: =+G30+S30-AF30-AK30 -> 0 | AO30: =+H30+T30-AG30-AL30 -> 0 | AP30: =(AN30+AO30)/(S30+T30) -> #DIV/0! | AQ30: =($AP$1*AN30+$AQ$1*AO30) -> 0 | AR30: =(D30+J30+O30)-(X30+AH30) -> 0
A31: =CONCATENATE(B31,C31) -> 46217E | B31: =+B29+1 -> 46217 | C31: E | G31: =+D31*E31% -> 0 | H31: =+D31*F31% -> 0 | R31: =+J31+O31 -> 0 | S31: =+J31*K31%+O31*P31% -> 0 | T31: =+J31*L31%+O31*Q31% -> 0 | AA31: =X31*Y31% -> 0 | AB31: =X31*Z31% -> 0 | AF31: =AC31*AD31% -> 0 | AG31: =AC31*AE31% -> 0 | AK31: =AH31*AI31% -> 0 | AL31: =AH31*AJ31% -> 0 | AM31: =+D31+R31-AC31-AH31 -> 0 | AN31: =+G31+S31-AF31-AK31 -> 0 | AO31: =+H31+T31-AG31-AL31 -> 0 | AP31: =(AN31+AO31)/(S31+T31) -> #DIV/0! | AQ31: =($AP$1*AN31+$AQ$1*AO31) -> 0 | AR31: =(D31+J31+O31)-(X31+AH31) -> 0
A32: =CONCATENATE(B32,C32) -> 46218M | B32: =+B30+1 -> 46218 | C32: M | G32: =+D32*E32% -> 0 | H32: =+D32*F32% -> 0 | R32: =+J32+O32 -> 0 | S32: =+J32*K32%+O32*P32% -> 0 | T32: =+J32*L32%+O32*Q32% -> 0 | AA32: =X32*Y32% -> 0 | AB32: =X32*Z32% -> 0 | AF32: =AC32*AD32% -> 0 | AG32: =AC32*AE32% -> 0 | AK32: =AH32*AI32% -> 0 | AL32: =AH32*AJ32% -> 0 | AM32: =+D32+R32-AC32-AH32 -> 0 | AN32: =+G32+S32-AF32-AK32 -> 0 | AO32: =+H32+T32-AG32-AL32 -> 0 | AP32: =(AN32+AO32)/(S32+T32) -> #DIV/0! | AQ32: =($AP$1*AN32+$AQ$1*AO32) -> 0 | AR32: =(D32+J32+O32)-(X32+AH32) -> 0
A33: =CONCATENATE(B33,C33) -> 46218E | B33: =+B31+1 -> 46218 | C33: E | G33: =+D33*E33% -> 0 | H33: =+D33*F33% -> 0 | R33: =+J33+O33 -> 0 | S33: =+J33*K33%+O33*P33% -> 0 | T33: =+J33*L33%+O33*Q33% -> 0 | AA33: =X33*Y33% -> 0 | AB33: =X33*Z33% -> 0 | AF33: =AC33*AD33% -> 0 | AG33: =AC33*AE33% -> 0 | AK33: =AH33*AI33% -> 0 | AL33: =AH33*AJ33% -> 0 | AM33: =+D33+R33-AC33-AH33 -> 0 | AN33: =+G33+S33-AF33-AK33 -> 0 | AO33: =+H33+T33-AG33-AL33 -> 0 | AP33: =(AN33+AO33)/(S33+T33) -> #DIV/0! | AQ33: =($AP$1*AN33+$AQ$1*AO33) -> 0 | AR33: =(D33+J33+O33)-(X33+AH33) -> 0
... A65: =CONCATENATE(B65,C65) -> 46234E | B65: =+B63+1 -> 46234 | C65: E | G65: =+D65*E65% -> 0 | H65: =+D65*F65% -> 0 | R65: =+J65+O65 -> 0 | S65: =+J65*K65%+O65*P65% -> 0 | T65: =+J65*L65%+O65*Q65% -> 0 | AA65: =X65*Y65% -> 0 | AB65: =X65*Z65% -> 0 | AF65: =AC65*AD65% -> 0 | AG65: =AC65*AE65% -> 0 | AK65: =AH65*AI65% -> 0 | AL65: =AH65*AJ65% -> 0 | AM65: =+D65+R65-AC65-AH65 -> 0 | AN65: =+G65+S65-AF65-AK65 -> 0 | AO65: =+H65+T65-AG65-AL65 -> 0 | AP65: =(AN65+AO65)/(S65+T65) -> #DIV/0! | AQ65: =($AP$1*AN65+$AQ$1*AO65) -> 0 | AR65: =(D65+J65+O65)-(X65+AH65) -> 0
J66: =SUM(J4:J65) -> 26816.874 | AM66: =-SUM(AM4:AM65) -> 261.126 | AN66: =-SUM(AN4:AN65) -> 48.795753 | AO66: =-SUM(AO4:AO65) -> 20.51428 | AP66: =-SUM(AP4:AP65) -> #DIV/0! | AQ66: =-SUM(AQ4:AQ65) -> 29591.792
Q67: =2126*27 -> 57402
Q68: =2600*37 -> 96200

Sheet Hasanpur
B1: Hasanpur Bmc | AG1: 392 | AP1: =Sumarry!$K$4 -> 480.53255 | AQ1: =Sumarry!$L$4 -> 299.4911
B2: Date | C2: Shift | D2: OB | I2: Milk from MPG in Ltr | M2: Transfer from other BMC/RMC | R2: Total Milk Receipt in Kg | U2: Tanker Dispatch Details | AC2: Plant Receipt | AH2: CB | AM2: Loss/(Gain)
D3: Qty KG | E3: Fat% | F3: Snf% | G3: FAT Kg | H3: SNF Kg | I3: Qty Ltr | J3: Qty Kg | K3: Fat% | L3: Snf% | M3: From | N3: Tanker No | O3: Qty Kg | P3: Fat% | Q3: Snf% | R3: Qty Kg | S3: FAT Kg | T3: SNF Kg | U3: Tanker | V3: Challan | W3: To | X3: Qty KG | Y3: Fat% | Z3: Snf% | AA3: FAT Kg | AB3: SNF Kg | AC3: Qty KG | AD3: Fat% | AE3: Snf% | AF3: FAT Kg | AG3: SNF Kg | AH3: Qty KG | AI3: Fat% | AJ3: Snf% | AK3: FAT Kg | AL3: SNF Kg | AM3: Qty KG | AN3: FAT Kg | AO3: SNF Kg | AP3: TS Loss% | AQ3: Amount
A4: =CONCATENATE(B4,C4) -> 46204M | B4: 46204 | C4: M | D4: 0 | E4: 0 | F4: 0 | G4: =+D4*E4% -> 0 | H4: =+D4*F4% -> 0 | I4: 559.06 | J4: 575.8318 | K4: 4.9612242 | L4: 8.4924302 | M4: 0 | N4: 0 | O4: 0 | P4: 0 | Q4: 0 | R4: =+J4+O4 -> 575.8318 | S4: =+J4*K4%+O4*P4% -> 28.568307 | T4: =+J4*L4%+O4*Q4% -> 48.902113 | U4: 0 | V4: 0 | W4: 0 | X4: 0 | Y4: 0 | Z4: 0 | AA4: =X4*Y4% -> 0 | AB4: =X4*Z4% -> 0 | AF4: =AC4*AD4% -> 0 | AG4: =AC4*AE4% -> 0 | AH4: 576 | AI4: 5 | AJ4: 8.5 | AK4: =AH4*AI4% -> 28.8 | AL4: =AH4*AJ4% -> 48.96 | AM4: =+D4+R4-AC4-AH4 -> -0.1682 | AN4: =+G4+S4-AF4-AK4 -> -0.2316934 | AO4: =+H4+T4-AG4-AL4 -> -0.0578866 | AP4: =(AN4+AO4)/(S4+T4) -> -0.0037379428 | AQ4: =($AP$1*AN4+$AQ$1*AO4) -> -128.67274 | AR4: =(D4+J4+O4)-(X4+AH4) -> -0.1682
A5: =CONCATENATE(B5,C5) -> 46204E | B5: =+B4 -> 46204 | C5: E | D5: 576 | E5: 5 | F5: 8.5 | G5: =+D5*E5% -> 28.8 | H5: =+D5*F5% -> 48.96 | I5: 201.33 | J5: 207.3699 | K5: 5.4829683 | L5: 8.6711618 | M5: Singhiya | N5: 87086 | O5: 1280 | P5: 4.2 | Q5: 8 | R5: =+J5+O5 -> 1487.3699 | S5: =+J5*K5%+O5*P5% -> 65.130026 | T5: =+J5*L5%+O5*Q5% -> 120.38138 | U5: 0 | V5: 0 | W5: 0 | X5: 0 | Y5: 0 | Z5: 0 | AA5: =X5*Y5% -> 0 | AB5: =X5*Z5% -> 0 | AF5: =AC5*AD5% -> 0 | AG5: =AC5*AE5% -> 0 | AH5: 2063 | AI5: 4.55 | AJ5: 8.21 | AK5: =AH5*AI5% -> 93.8665 | AL5: =AH5*AJ5% -> 169.3723 | AM5: =+D5+R5-AC5-AH5 -> 0.3699 | AN5: =+G5+S5-AF5-AK5 -> 0.0635258 | AO5: =+H5+T5-AG5-AL5 -> -0.0309205 | AP5: =(AN5+AO5)/(S5+T5) -> 0.000175759 | AQ5: =($AP$1*AN5+$AQ$1*AO5) -> 21.2658 | AR5: =(D5+J5+O5)-(X5+AH5) -> 0.3699
A6: =CONCATENATE(B6,C6) -> 46205M | B6: =+B4+1 -> 46205 | C6: M | D6: 2063 | E6: 4.55 | F6: 8.21 | G6: =+D6*E6% -> 93.8665 | H6: =+D6*F6% -> 169.3723 | I6: 670.64 | J6: 690.7592 | K6: 4.7663739 | L6: 8.567446 | M6: 0 | N6: 0 | O6: 0 | P6: 0 | Q6: 0 | R6: =+J6+O6 -> 690.7592 | S6: =+J6*K6%+O6*P6% -> 32.924166 | T6: =+J6*L6%+O6*Q6% -> 59.180422 | U6: 0 | V6: 0 | W6: 0 | X6: 0 | Y6: 0 | Z6: 0 | AA6: =X6*Y6% -> 0 | AB6: =X6*Z6% -> 0 | AF6: =AC6*AD6% -> 0 | AG6: =AC6*AE6% -> 0 | AH6: 2754 | AI6: 4.61 | AJ6: 8.3 | AK6: =AH6*AI6% -> 126.9594 | AL6: =AH6*AJ6% -> 228.582 | AM6: =+D6+R6-AC6-AH6 -> -0.2408 | AN6: =+G6+S6-AF6-AK6 -> -0.1687337 | AO6: =+H6+T6-AG6-AL6 -> -0.0292784 | AP6: =(AN6+AO6)/(S6+T6) -> -0.0021498614 | AQ6: =($AP$1*AN6+$AQ$1*AO6) -> -89.850655 | AR6: =(D6+J6+O6)-(X6+AH6) -> -0.2408
A7: =CONCATENATE(B7,C7) -> 46205E | B7: =+B5+1 -> 46205 | C7: E | D7: 2754 | E7: 4.61 | F7: 8.3 | G7: =+D7*E7% -> 126.9594 | H7: =+D7*F7% -> 228.582 | I7: 1004.5 | J7: 1034.635 | K7: 4.5035072 | L7: 8.4406341 | M7: Singhiya | N7: 87087 | O7: 1010 | P7: 4.1 | Q7: 8 | R7: =+J7+O7 -> 2044.635 | S7: =+J7*K7%+O7*P7% -> 88.004862 | T7: =+J7*L7%+O7*Q7% -> 168.12976 | U7: 6545 | V7: 87875 | W7: Munger | X7: 3150 | Y7: 4.2 | Z7: 8.13 | AA7: =X7*Y7% -> 132.3 | AB7: =X7*Z7% -> 256.095 | AC7: 3150 | AD7: 4.1 | AE7: 7.85 | AF7: =AC7*AD7% -> 129.15 | AG7: =AC7*AE7% -> 247.275 | AH7: 1649 | AI7: 4.47 | AJ7: 8.25 | AK7: =AH7*AI7% -> 73.7103 | AL7: =AH7*AJ7% -> 136.0425 | AM7: =+D7+R7-AC7-AH7 -> -0.365 | AN7: =+G7+S7-AF7-AK7 -> 12.103962 | AO7: =+H7+T7-AG7-AL7 -> 13.394255 | AP7: =(AN7+AO7)/(S7+T7) -> 0.099550062 | AQ7: =($AP$1*AN7+$AQ$1*AO7) -> 9827.8078 | AR7: =(D7+J7+O7)-(X7+AH7) -> -0.365
A8: =CONCATENATE(B8,C8) -> 46206M | B8: =+B6+1 -> 46206 | C8: M | D8: 1649 | E8: 4.47 | F8: 8.25 | G8: =+D8*E8% -> 73.7103 | H8: =+D8*F8% -> 136.0425 | I8: 605.05 | J8: 623.2015 | K8: 4.8882307 | L8: 8.6516833 | M8: 0 | N8: 0 | O8: 0 | P8: 0 | Q8: 0 | R8: =+J8+O8 -> 623.2015 | S8: =+J8*K8%+O8*P8% -> 30.463527 | T8: =+J8*L8%+O8*Q8% -> 53.91742 | U8: 0 | V8: 0 | W8: 0 | X8: 0 | Y8: 0 | Z8: 0 | AA8: =X8*Y8% -> 0 | AB8: =X8*Z8% -> 0 | AF8: =AC8*AD8% -> 0 | AG8: =AC8*AE8% -> 0 | AH8: 2110 | AI8: 4.56 | AJ8: 8.33 | AK8: =AH8*AI8% -> 96.216 | AL8: =AH8*AJ8% -> 175.763 | AM8: =+D8+R8-AC8-AH8 -> 162.2015 | AN8: =+G8+S8-AF8-AK8 -> 7.9578272 | AO8: =+H8+T8-AG8-AL8 -> 14.19692 | AP8: =(AN8+AO8)/(S8+T8) -> 0.26255628 | AQ8: =($AP$1*AN8+$AQ$1*AO8) -> 8075.8462 | AR8: =(D8+J8+O8)-(X8+AH8) -> 162.2015
A9: =CONCATENATE(B9,C9) -> 46206E | B9: =+B7+1 -> 46206 | C9: E | D9: 2110 | E9: 4.56 | F9: 8.33 | G9: =+D9*E9% -> 96.216 | H9: =+D9*F9% -> 175.763 | I9: 1083.82 | J9: 1116.3346 | K9: 4.503674 | L9: 8.2500941 | M9: Singhiya | N9: 87693 | O9: 1670 | P9: 4 | Q9: 8 | R9: =+J9+O9 -> 2786.3346 | S9: =+J9*K9%+O9*P9% -> 117.07607 | T9: =+J9*L9%+O9*Q9% -> 225.69866 | U9: 6545 | V9: 87501 | W9: Hajipur | X9: 3150 | Y9: 4.2 | Z9: 8.05 | AA9: =X9*Y9% -> 132.3 | AB9: =X9*Z9% -> 253.575 | AC9: 3170 | AD9: 4.15 | AE9: 7.99 | AF9: =AC9*AD9% -> 131.555 | AG9: =AC9*AE9% -> 253.283 | AH9: 1746 | AI9: 4.35 | AJ9: 8.18 | AK9: =AH9*AI9% -> 75.951 | AL9: =AH9*AJ9% -> 142.8228 | AM9: =+D9+R9-AC9-AH9 -> -19.6654 | AN9: =+G9+S9-AF9-AK9 -> 5.7860716 | AO9: =+H9+T9-AG9-AL9 -> 5.3558551 | AP9: =(AN9+AO9)/(S9+T9) -> 0.0325051 | AQ9: =($AP$1*AN9+$AQ$1*AO9) -> 4384.4266 | AR9: =(D9+J9+O9)-(X9+AH9) -> 0.3346
A10: =CONCATENATE(B10,C10) -> 46207M | B10: =+B8+1 -> 46207 | C10: M | D10: 1746 | E10: 4.35 | F10: 8.18 | G10: =+D10*E10% -> 75.951 | H10: =+D10*F10% -> 142.8228 | I10: 646.32 | J10: 665.7096 | K10: 4.8585221 | L10: 8.3000139 | M10: 0 | N10: 0 | O10: 0 | P10: 0 | Q10: 0 | R10: =+J10+O10 -> 665.7096 | S10: =+J10*K10%+O10*P10% -> 32.343648 | T10: =+J10*L10%+O10*Q10% -> 55.253989 | U10: 0 | V10: 0 | W10: 0 | X10: 0 | Y10: 0 | Z10: 0 | AA10: =X10*Y10% -> 0 | AB10: =X10*Z10% -> 0 | AF10: =AC10*AD10% -> 0 | AG10: =AC10*AE10% -> 0 | AH10: 2412 | AI10: 4.5 | AJ10: 8.21 | AK10: =AH10*AI10% -> 108.54 | AL10: =AH10*AJ10% -> 198.0252 | AM10: =+D10+R10-AC10-AH10 -> -0.2904 | AN10: =+G10+S10-AF10-AK10 -> -0.245352 | AO10: =+H10+T10-AG10-AL10 -> 0.0515895 | AP10: =(AN10+AO10)/(S10+T10) -> -0.0022119603 | AQ10: =($AP$1*AN10+$AQ$1*AO10) -> -102.44903 | AR10: =(D10+J10+O10)-(X10+AH10) -> -0.2904
A11: =CONCATENATE(B11,C11) -> 46207E | B11: =+B9+1 -> 46207 | C11: E | D11: 2412 | E11: 4.5 | F11: 8.21 | G11: =+D11*E11% -> 108.54 | H11: =+D11*F11% -> 198.0252 | I11: 1103.24 | J11: 1136.3372 | K11: 4.2164008 | L11: 8.2083454 | M11: Singhiya | N11: 87694 | O11: 1030 | P11: 4.1 | Q11: 8 | R11: =+J11+O11 -> 2166.3372 | S11: =+J11*K11%+O11*P11% -> 90.142531 | T11: =+J11*L11%+O11*Q11% -> 175.67448 | U11: 00 | V11: 0 | W11: 0 | X11: 0 | Y11: 0 | Z11: 0 | AA11: =X11*Y11% -> 0 | AB11: =X11*Z11% -> 0 | AF11: =AC11*AD11% -> 0 | AG11: =AC11*AE11% -> 0 | AH11: 4578 | AI11: 4.33 | AJ11: 8.16 | AK11: =AH11*AI11% -> 198.2274 | AL11: =AH11*AJ11% -> 373.5648 | AM11: =+D11+R11-AC11-AH11 -> 0.3372 | AN11: =+G11+S11-AF11-AK11 -> 0.4551306 | AO11: =+H11+T11-AG11-AL11 -> 0.1348825 | AP11: =(AN11+AO11)/(S11+T11) -> 0.0022196213 | AQ11: =($AP$1*AN11+$AQ$1*AO11) -> 259.10117 | AR11: =(D11+J11+O11)-(X11+AH11) -> 0.3372
A12: =CONCATENATE(B12,C12) -> 46208M | B12: =+B10+1 -> 46208 | C12: M | D12: 4578 | E12: 4.33 | F12: 8.16 | G12: =+D12*E12% -> 198.2274 | H12: =+D12*F12% -> 373.5648 | I12: 581.52 | J12: 598.9656 | K12: 4.8253439 | L12: 8.2871698 | M12: Bachhwara | N12: 89391 | O12: 3130 | P12: 4.2 | Q12: 8.15 | R12: =+J12+O12 -> 3728.9656 | S12: =+J12*K12%+O12*P12% -> 160.36215 | T12: =+J12*L12%+O12*Q12% -> 304.7323 | U12: 6545 | V12: 87504 | W12: Muzaffurpur | X12: 6280 | Y12: 4.28 | Z12: 8.2 | AA12: =X12*Y12% -> 268.784 | AB12: =X12*Z12% -> 514.96 | AC12: 6240 | AD12: 4.2254808 | AE12: 8.1296795 | AF12: =AC12*AD12% -> 263.67 | AG12: =AC12*AE12% -> 507.292 | AH12: 2027 | AI12: 4.31 | AJ12: 8.16 | AK12: =AH12*AI12% -> 87.3637 | AL12: =AH12*AJ12% -> 165.4032 | AM12: =+D12+R12-AC12-AH12 -> 39.9656 | AN12: =+G12+S12-AF12-AK12 -> 7.5558502 | AO12: =+H12+T12-AG12-AL12 -> 5.6018965 | AP12: =(AN12+AO12)/(S12+T12) -> 0.028290483 | AQ12: =($AP$1*AN12+$AQ$1*AO12) -> 5308.5501 | AR12: =(D12+J12+O12)-(X12+AH12) -> -0.0344
A13: =CONCATENATE(B13,C13) -> 46208E | B13: =+B11+1 -> 46208 | C13: E | D13: 2027 | E13: 4.31 | F13: 8.16 | G13: =+D13*E13% -> 87.3637 | H13: =+D13*F13% -> 165.4032 | I13: 1006.72 | J13: 1036.9216 | K13: 4.1625 | L13: 8.0943947 | M13: Singhiya | N13: 87695 | O13: 1300 | P13: 4.1 | Q13: 7.8 | R13: =+J13+O13 -> 2336.9216 | S13: =+J13*K13%+O13*P13% -> 96.461862 | T13: =+J13*L13%+O13*Q13% -> 185.33253 | U13: 0 | V13: 0 | W13: 0 | X13: 0 | Y13: 0 | Z13: 0 | AA13: =X13*Y13% -> 0 | AB13: =X13*Z13% -> 0 | AF13: =AC13*AD13% -> 0 | AG13: =AC13*AE13% -> 0 | AH13: 4364 | AI13: 4.22 | AJ13: 8.04 | AK13: =AH13*AI13% -> 184.1608 | AL13: =AH13*AJ13% -> 350.8656 | AM13: =+D13+R13-AC13-AH13 -> -0.0784 | AN13: =+G13+S13-AF13-AK13 -> -0.3352384 | AO13: =+H13+T13-AG13-AL13 -> -0.1298733 | AP13: =(AN13+AO13)/(S13+T13) -> -0.0016505357 | AQ13: =($AP$1*AN13+$AQ$1*AO13) -> -199.98886 | AR13: =(D13+J13+O13)-(X13+AH13) -> -0.0784
A14: =CONCATENATE(B14,C14) -> 46209M | B14: =+B12+1 -> 46209 | C14: M | D14: 4364 | E14: 4.22 | F14: 8.04 | G14: =+D14*E14% -> 184.1608 | H14: =+D14*F14% -> 350.8656 | I14: 624.67 | J14: 643.4101 | K14: 4.7318552 | L14: 8.2116157 | M14: Singhiya | N14: 87696 | O14: 1070 | P14: 4.3 | Q14: 8 | R14: =+J14+O14 -> 1713.4101 | S14: =+J14*K14%+O14*P14% -> 76.455234 | T14: =+J14*L14%+O14*Q14% -> 138.43437 | U14: 3461 | V14: 87506 | W14: Muzaffurpur | X14: 6550 | Y14: 4.4 | Z14: 8.23 | AA14: =X14*Y14% -> 288.2 | AB14: =X14*Z14% -> 539.065 | AC14: 6480 | AD14: 4.35 | AE14: 8.09 | AF14: =AC14*AD14% -> 281.88 | AG14: =AC14*AE14% -> 524.232 | AH14: 0 | AI14: 0 | AJ14: 0 | AK14: =AH14*AI14% -> 0 | AL14: =AH14*AJ14% -> 0 | AM14: =+D14+R14-AC14-AH14 -> -402.5899 | AN14: =+G14+S14-AF14-AK14 -> -21.263966 | AO14: =+H14+T14-AG14-AL14 -> -34.932035 | AP14: =(AN14+AO14)/(S14+T14) -> -0.26151103 | AQ14: =($AP$1*AN14+$AQ$1*AO14) -> -20679.861 | AR14: =(D14+J14+O14)-(X14+AH14) -> -472.5899
A15: =CONCATENATE(B15,C15) -> 46209E | B15: =+B13+1 -> 46209 | C15: E | D15: 0 | E15: 0 | F15: 0 | G15: =+D15*E15% -> 0 | H15: =+D15*F15% -> 0 | I15: 1003.46 | J15: 1033.5638 | K15: 4.1482989 | L15: 8.1678443 | M15: 0 | N15: 0 | O15: 0 | P15: 0 | Q15: 0 | R15: =+J15+O15 -> 1033.5638 | S15: =+J15*K15%+O15*P15% -> 42.875316 | T15: =+J15*L15%+O15*Q15% -> 84.419881 | U15: 0 | V15: 0 | W15: 0 | X15: 0 | Y15: 0 | Z15: 0 | AA15: =X15*Y15% -> 0 | AB15: =X15*Z15% -> 0 | AF15: =AC15*AD15% -> 0 | AG15: =AC15*AE15% -> 0 | AH15: 1033.6 | AI15: 4.2 | AJ15: 8.2 | AK15: =AH15*AI15% -> 43.4112 | AL15: =AH15*AJ15% -> 84.7552 | AM15: =+D15+R15-AC15-AH15 -> -0.0362 | AN15: =+G15+S15-AF15-AK15 -> -0.5358844 | AO15: =+H15+T15-AG15-AL15 -> -0.3353185 | AP15: =(AN15+AO15)/(S15+T15) -> -0.0068439574 | AQ15: =($AP$1*AN15+$AQ$1*AO15) -> -357.9348 | AR15: =(D15+J15+O15)-(X15+AH15) -> -0.0362
A16: =CONCATENATE(B16,C16) -> 46210M | B16: =+B14+1 -> 46210 | C16: M | D16: 1033.6 | E16: 4.2 | F16: 8.2 | G16: =+D16*E16% -> 43.4112 | H16: =+D16*F16% -> 84.7552 | I16: 686.61 | J16: 707.2083 | K16: 4.513169 | L16: 8.2835918 | M16: 0 | N16: 0 | O16: 0 | P16: 0 | Q16: 0 | R16: =+J16+O16 -> 707.2083 | S16: =+J16*K16%+O16*P16% -> 31.917506 | T16: =+J16*L16%+O16*Q16% -> 58.582249 | U16: 0 | V16: 0 | W16: 0 | X16: 0 | Y16: 0 | Z16: 0 | AA16: =X16*Y16% -> 0 | AB16: =X16*Z16% -> 0 | AF16: =AC16*AD16% -> 0 | AG16: =AC16*AE16% -> 0 | AH16: 1741 | AI16: 4.32 | AJ16: 8.23 | AK16: =AH16*AI16% -> 75.2112 | AL16: =AH16*AJ16% -> 143.2843 | AM16: =+D16+R16-AC16-AH16 -> -0.1917 | AN16: =+G16+S16-AF16-AK16 -> 0.1175061 | AO16: =+H16+T16-AG16-AL16 -> 0.0531491 | AP16: =(AN16+AO16)/(S16+T16) -> 0.0018856979 | AQ16: =($AP$1*AN16+$AQ$1*AO16) -> 72.383188 | AR16: =(D16+J16+O16)-(X16+AH16) -> -0.1917
A17: =CONCATENATE(B17,C17) -> 46210E | B17: =+B15+1 -> 46210 | C17: E | D17: 1741 | E17: 4.32 | F17: 8.23 | G17: =+D17*E17% -> 75.2112 | H17: =+D17*F17% -> 143.2843 | I17: 965.84 | J17: 994.8152 | K17: 4.2144289 | L17: 8.2241293 | M17: Singhiya/Bachhwara | N17: 87697/89392 | O17: 3910 | P17: 4.2 | Q17: 8.07 | R17: =+J17+O17 -> 4904.8152 | S17: =+J17*K17%+O17*P17% -> 206.14578 | T17: =+J17*L17%+O17*Q17% -> 397.35189 | U17: 3461 | V17: 87507 | W17: Hajipur | X17: 7100 | Y17: 4.33 | Z17: 8.09 | AA17: =X17*Y17% -> 307.43 | AB17: =X17*Z17% -> 574.39 | AC17: 7100 | AD17: 4.33 | AE17: 8.09 | AF17: =AC17*AD17% -> 307.43 | AG17: =AC17*AE17% -> 574.39 | AH17: 0 | AI17: 0 | AJ17: 0 | AK17: =AH17*AI17% -> 0 | AL17: =AH17*AJ17% -> 0 | AM17: =+D17+R17-AC17-AH17 -> -454.1848 | AN17: =+G17+S17-AF17-AK17 -> -26.073021 | AO17: =+H17+T17-AG17-AL17 -> -33.753812 | AP17: =(AN17+AO17)/(S17+T17) -> -0.099133495 | AQ17: =($AP$1*AN17+$AQ$1*AO17) -> -22637.901 | AR17: =(D17+J17+O17)-(X17+AH17) -> -454.1848
A18: =CONCATENATE(B18,C18) -> 46211M | B18: =+B16+1 -> 46211 | C18: M | D18: 0 | E18: 0 | F18: 0 | G18: =+D18*E18% -> 0 | H18: =+D18*F18% -> 0 | I18: 648.89 | J18: 668.3567 | K18: 4.770992 | L18: 8.362741 | M18: 0 | N18: 0 | O18: 0 | P18: 0 | Q18: 0 | R18: =+J18+O18 -> 668.3567 | S18: =+J18*K18%+O18*P18% -> 31.887245 | T18: =+J18*L18%+O18*Q18% -> 55.89294 | U18: 0 | V18: 0 | W18: 0 | X18: 0 | Y18: 0 | Z18: 0 | AA18: =X18*Y18% -> 0 | AB18: =X18*Z18% -> 0 | AF18: =AC18*AD18% -> 0 | AG18: =AC18*AE18% -> 0 | AH18: 668 | AI18: 4.8 | AJ18: 8.4 | AK18: =AH18*AI18% -> 32.064 | AL18: =AH18*AJ18% -> 56.112 | AM18: =+D18+R18-AC18-AH18 -> 0.3567 | AN18: =+G18+S18-AF18-AK18 -> -0.1767553 | AO18: =+H18+T18-AG18-AL18 -> -0.2190603 | AP18: =(AN18+AO18)/(S18+T18) -> -0.004509168 | AQ18: =($AP$1*AN18+$AQ$1*AO18) -> -150.54328 | AR18: =(D18+J18+O18)-(X18+AH18) -> 0.3567
A19: =CONCATENATE(B19,C19) -> 46211E | B19: =+B17+1 -> 46211 | C19: E | D19: 668 | E19: 4.8 | F19: 8.4 | G19: =+D19*E19% -> 32.064 | H19: =+D19*F19% -> 56.112 | I19: 1027.36 | J19: 1058.1808 | K19: 4.1903831 | L19: 8.2399091 | M19: singhiya | N19: 87698 | O19: 1310 | P19: 4.2 | Q19: 8 | R19: =+J19+O19 -> 2368.1808 | S19: =+J19*K19%+O19*P19% -> 99.36183 | T19: =+J19*L19%+O19*Q19% -> 191.99314 | U19: 0 | V19: 0 | W19: 0 | X19: 0 | Y19: 0 | Z19: 0 | AA19: =X19*Y19% -> 0 | AB19: =X19*Z19% -> 0 | AF19: =AC19*AD19% -> 0 | AG19: =AC19*AE19% -> 0 | AH19: 3036 | AI19: 4.33 | AJ19: 8.15 | AK19: =AH19*AI19% -> 131.4588 | AL19: =AH19*AJ19% -> 247.434 | AM19: =+D19+R19-AC19-AH19 -> 0.1808 | AN19: =+G19+S19-AF19-AK19 -> -0.0329704 | AO19: =+H19+T19-AG19-AL19 -> 0.6711359 | AP19: =(AN19+AO19)/(S19+T19) -> 0.0021903368 | AQ19: =($AP$1*AN19+$AQ$1*AO19) -> 185.15588 | AR19: =(D19+J19+O19)-(X19+AH19) -> 0.1808
A20: =CONCATENATE(B20,C20) -> 46212M | B20: =+B18+1 -> 46212 | C20: M | D20: 3036 | E20: 4.33 | F20: 8.15 | G20: =+D20*E20% -> 131.4588 | H20: =+D20*F20% -> 247.434 | I20: 639.54 | J20: 658.7262 | K20: 4.7573553 | L20: 8.2505035 | M20: 0 | N20: 0 | O20: 0 | P20: 0 | Q20: 0 | R20: =+J20+O20 -> 658.7262 | S20: =+J20*K20%+O20*P20% -> 31.337946 | T20: =+J20*L20%+O20*Q20% -> 54.348228 | U20: 6545 | V20: 87508 | W20: Munger | X20: 3150 | Y20: 4.45 | Z20: 8.3 | AA20: =X20*Y20% -> 140.175 | AB20: =X20*Z20% -> 261.45 | AC20: 3150 | AD20: 4.45 | AE20: 8.3 | AF20: =AC20*AD20% -> 140.175 | AG20: =AC20*AE20% -> 261.45 | AH20: 545 | AI20: 4.41 | AJ20: 8.17 | AK20: =AH20*AI20% -> 24.0345 | AL20: =AH20*AJ20% -> 44.5265 | AM20: =+D20+R20-AC20-AH20 -> -0.2738 | AN20: =+G20+S20-AF20-AK20 -> -1.4127543 | AO20: =+H20+T20-AG20-AL20 -> -4.1942719 | AP20: =(AN20+AO20)/(S20+T20) -> -0.065436767 | AQ20: =($AP$1*AN20+$AQ$1*AO20) -> -1935.0215 | AR20: =(D20+J20+O20)-(X20+AH20) -> -0.2738
A21: =CONCATENATE(B21,C21) -> 46212E | B21: =+B19+1 -> 46212 | C21: E | D21: 545 | E21: 4.41 | F21: 8.17 | G21: =+D21*E21% -> 24.0345 | H21: =+D21*F21% -> 44.5265 | I21: 1013.96 | J21: 1044.3788 | K21: 4.2374088 | L21: 8.0157265 | M21: 0 | N21: 0 | O21: 0 | P21: 0 | Q21: 0 | R21: =+J21+O21 -> 1044.3788 | S21: =+J21*K21%+O21*P21% -> 44.254599 | T21: =+J21*L21%+O21*Q21% -> 83.714548 | U21: 0 | V21: 0 | W21: 0 | X21: 0 | Y21: 0 | Z21: 0 | AA21: =X21*Y21% -> 0 | AB21: =X21*Z21% -> 0 | AF21: =AC21*AD21% -> 0 | AG21: =AC21*AE21% -> 0 | AH21: 1589 | AI21: 4.27 | AJ21: 8.06 | AK21: =AH21*AI21% -> 67.8503 | AL21: =AH21*AJ21% -> 128.0734 | AM21: =+D21+R21-AC21-AH21 -> 0.3788 | AN21: =+G21+S21-AF21-AK21 -> 0.4387989 | AO21: =+H21+T21-AG21-AL21 -> 0.1676478 | AP21: =(AN21+AO21)/(S21+T21) -> 0.0047390071 | AQ21: =($AP$1*AN21+$AQ$1*AO21) -> 261.06618 | AR21: =(D21+J21+O21)-(X21+AH21) -> 0.3788
A22: =CONCATENATE(B22,C22) -> 46213M | B22: =+B20+1 -> 46213 | C22: M | G22: =+D22*E22% -> 0 | H22: =+D22*F22% -> 0 | R22: =+J22+O22 -> 0 | S22: =+J22*K22%+O22*P22% -> 0 | T22: =+J22*L22%+O22*Q22% -> 0 | AA22: =X22*Y22% -> 0 | AB22: =X22*Z22% -> 0 | AF22: =AC22*AD22% -> 0 | AG22: =AC22*AE22% -> 0 | AK22: =AH22*AI22% -> 0 | AL22: =AH22*AJ22% -> 0 | AM22: =+D22+R22-AC22-AH22 -> 0 | AN22: =+G22+S22-AF22-AK22 -> 0 | AO22: =+H22+T22-AG22-AL22 -> 0 | AP22: =(AN22+AO22)/(S22+T22) -> #DIV/0! | AQ22: =($AP$1*AN22+$AQ$1*AO22) -> 0 | AR22: =(D22+J22+O22)-(X22+AH22) -> 0
A23: =CONCATENATE(B23,C23) -> 46213E | B23: =+B21+1 -> 46213 | C23: E | G23: =+D23*E23% -> 0 | H23: =+D23*F23% -> 0 | R23: =+J23+O23 -> 0 | S23: =+J23*K23%+O23*P23% -> 0 | T23: =+J23*L23%+O23*Q23% -> 0 | AA23: =X23*Y23% -> 0 | AB23: =X23*Z23% -> 0 | AF23: =AC23*AD23% -> 0 | AG23: =AC23*AE23% -> 0 | AK23: =AH23*AI23% -> 0 | AL23: =AH23*AJ23% -> 0 | AM23: =+D23+R23-AC23-AH23 -> 0 | AN23: =+G23+S23-AF23-AK23 -> 0 | AO23: =+H23+T23-AG23-AL23 -> 0 | AP23: =(AN23+AO23)/(S23+T23) -> #DIV/0! | AQ23: =($AP$1*AN23+$AQ$1*AO23) -> 0 | AR23: =(D23+J23+O23)-(X23+AH23) -> 0
A24: =CONCATENATE(B24,C24) -> 46214M | B24: =+B22+1 -> 46214 | C24: M | G24: =+D24*E24% -> 0 | H24: =+D24*F24% -> 0 | R24: =+J24+O24 -> 0 | S24: =+J24*K24%+O24*P24% -> 0 | T24: =+J24*L24%+O24*Q24% -> 0 | AA24: =X24*Y24% -> 0 | AB24: =X24*Z24% -> 0 | AF24: =AC24*AD24% -> 0 | AG24: =AC24*AE24% -> 0 | AK24: =AH24*AI24% -> 0 | AL24: =AH24*AJ24% -> 0 | AM24: =+D24+R24-AC24-AH24 -> 0 | AN24: =+G24+S24-AF24-AK24 -> 0 | AO24: =+H24+T24-AG24-AL24 -> 0 | AP24: =(AN24+AO24)/(S24+T24) -> #DIV/0! | AQ24: =($AP$1*AN24+$AQ$1*AO24) -> 0 | AR24: =(D24+J24+O24)-(X24+AH24) -> 0
A25: =CONCATENATE(B25,C25) -> 46214E | B25: =+B23+1 -> 46214 | C25: E | G25: =+D25*E25% -> 0 | H25: =+D25*F25% -> 0 | R25: =+J25+O25 -> 0 | S25: =+J25*K25%+O25*P25% -> 0 | T25: =+J25*L25%+O25*Q25% -> 0 | AA25: =X25*Y25% -> 0 | AB25: =X25*Z25% -> 0 | AF25: =AC25*AD25% -> 0 | AG25: =AC25*AE25% -> 0 | AK25: =AH25*AI25% -> 0 | AL25: =AH25*AJ25% -> 0 | AM25: =+D25+R25-AC25-AH25 -> 0 | AN25: =+G25+S25-AF25-AK25 -> 0 | AO25: =+H25+T25-AG25-AL25 -> 0 | AP25: =(AN25+AO25)/(S25+T25) -> #DIV/0! | AQ25: =($AP$1*AN25+$AQ$1*AO25) -> 0 | AR25: =(D25+J25+O25)-(X25+AH25) -> 0
A26: =CONCATENATE(B26,C26) -> 46215M | B26: =+B24+1 -> 46215 | C26: M | G26: =+D26*E26% -> 0 | H26: =+D26*F26% -> 0 | R26: =+J26+O26 -> 0 | S26: =+J26*K26%+O26*P26% -> 0 | T26: =+J26*L26%+O26*Q26% -> 0 | AA26: =X26*Y26% -> 0 | AB26: =X26*Z26% -> 0 | AF26: =AC26*AD26% -> 0 | AG26: =AC26*AE26% -> 0 | AK26: =AH26*AI26% -> 0 | AL26: =AH26*AJ26% -> 0 | AM26: =+D26+R26-AC26-AH26 -> 0 | AN26: =+G26+S26-AF26-AK26 -> 0 | AO26: =+H26+T26-AG26-AL26 -> 0 | AP26: =(AN26+AO26)/(S26+T26) -> #DIV/0! | AQ26: =($AP$1*AN26+$AQ$1*AO26) -> 0 | AR26: =(D26+J26+O26)-(X26+AH26) -> 0
A27: =CONCATENATE(B27,C27) -> 46215E | B27: =+B25+1 -> 46215 | C27: E | G27: =+D27*E27% -> 0 | H27: =+D27*F27% -> 0 | R27: =+J27+O27 -> 0 | S27: =+J27*K27%+O27*P27% -> 0 | T27: =+J27*L27%+O27*Q27% -> 0 | AA27: =X27*Y27% -> 0 | AB27: =X27*Z27% -> 0 | AF27: =AC27*AD27% -> 0 | AG27: =AC27*AE27% -> 0 | AK27: =AH27*AI27% -> 0 | AL27: =AH27*AJ27% -> 0 | AM27: =+D27+R27-AC27-AH27 -> 0 | AN27: =+G27+S27-AF27-AK27 -> 0 | AO27: =+H27+T27-AG27-AL27 -> 0 | AP27: =(AN27+AO27)/(S27+T27) -> #DIV/0! | AQ27: =($AP$1*AN27+$AQ$1*AO27) -> 0 | AR27: =(D27+J27+O27)-(X27+AH27) -> 0
A28: =CONCATENATE(B28,C28) -> 46216M | B28: =+B26+1 -> 46216 | C28: M | G28: =+D28*E28% -> 0 | H28: =+D28*F28% -> 0 | R28: =+J28+O28 -> 0 | S28: =+J28*K28%+O28*P28% -> 0 | T28: =+J28*L28%+O28*Q28% -> 0 | AA28: =X28*Y28% -> 0 | AB28: =X28*Z28% -> 0 | AF28: =AC28*AD28% -> 0 | AG28: =AC28*AE28% -> 0 | AK28: =AH28*AI28% -> 0 | AL28: =AH28*AJ28% -> 0 | AM28: =+D28+R28-AC28-AH28 -> 0 | AN28: =+G28+S28-AF28-AK28 -> 0 | AO28: =+H28+T28-AG28-AL28 -> 0 | AP28: =(AN28+AO28)/(S28+T28) -> #DIV/0! | AQ28: =($AP$1*AN28+$AQ$1*AO28) -> 0 | AR28: =(D28+J28+O28)-(X28+AH28) -> 0
A29: =CONCATENATE(B29,C29) -> 46216E | B29: =+B27+1 -> 46216 | C29: E | G29: =+D29*E29% -> 0 | H29: =+D29*F29% -> 0 | R29: =+J29+O29 -> 0 | S29: =+J29*K29%+O29*P29% -> 0 | T29: =+J29*L29%+O29*Q29% -> 0 | AA29: =X29*Y29% -> 0 | AB29: =X29*Z29% -> 0 | AF29: =AC29*AD29% -> 0 | AG29: =AC29*AE29% -> 0 | AK29: =AH29*AI29% -> 0 | AL29: =AH29*AJ29% -> 0 | AM29: =+D29+R29-AC29-AH29 -> 0 | AN29: =+G29+S29-AF29-AK29 -> 0 | AO29: =+H29+T29-AG29-AL29 -> 0 | AP29: =(AN29+AO29)/(S29+T29) -> #DIV/0! | AQ29: =($AP$1*AN29+$AQ$1*AO29) -> 0 | AR29: =(D29+J29+O29)-(X29+AH29) -> 0
A30: =CONCATENATE(B30,C30) -> 46217M | B30: =+B28+1 -> 46217 | C30: M | G30: =+D30*E30% -> 0 | H30: =+D30*F30% -> 0 | R30: =+J30+O30 -> 0 | S30: =+J30*K30%+O30*P30% -> 0 | T30: =+J30*L30%+O30*Q30% -> 0 | AA30: =X30*Y30% -> 0 | AB30: =X30*Z30% -> 0 | AF30: =AC30*AD30% -> 0 | AG30: =AC30*AE30% -> 0 | AK30: =AH30*AI30% -> 0 | AL30: =AH30*AJ30% -> 0 | AM30: =+D30+R30-AC30-AH30 -> 0 | AN30: =+G30+S30-AF30-AK30 -> 0 | AO30: =+H30+T30-AG30-AL30 -> 0 | AP30: =(AN30+AO30)/(S30+T30) -> #DIV/0! | AQ30: =($AP$1*AN30+$AQ$1*AO30) -> 0 | AR30: =(D30+J30+O30)-(X30+AH30) -> 0
A31: =CONCATENATE(B31,C31) -> 46217E | B31: =+B29+1 -> 46217 | C31: E | G31: =+D31*E31% -> 0 | H31: =+D31*F31% -> 0 | R31: =+J31+O31 -> 0 | S31: =+J31*K31%+O31*P31% -> 0 | T31: =+J31*L31%+O31*Q31% -> 0 | AA31: =X31*Y31% -> 0 | AB31: =X31*Z31% -> 0 | AF31: =AC31*AD31% -> 0 | AG31: =AC31*AE31% -> 0 | AK31: =AH31*AI31% -> 0 | AL31: =AH31*AJ31% -> 0 | AM31: =+D31+R31-AC31-AH31 -> 0 | AN31: =+G31+S31-AF31-AK31 -> 0 | AO31: =+H31+T31-AG31-AL31 -> 0 | AP31: =(AN31+AO31)/(S31+T31) -> #DIV/0! | AQ31: =($AP$1*AN31+$AQ$1*AO31) -> 0 | AR31: =(D31+J31+O31)-(X31+AH31) -> 0
A32: =CONCATENATE(B32,C32) -> 46218M | B32: =+B30+1 -> 46218 | C32: M | G32: =+D32*E32% -> 0 | H32: =+D32*F32% -> 0 | R32: =+J32+O32 -> 0 | S32: =+J32*K32%+O32*P32% -> 0 | T32: =+J32*L32%+O32*Q32% -> 0 | AA32: =X32*Y32% -> 0 | AB32: =X32*Z32% -> 0 | AF32: =AC32*AD32% -> 0 | AG32: =AC32*AE32% -> 0 | AK32: =AH32*AI32% -> 0 | AL32: =AH32*AJ32% -> 0 | AM32: =+D32+R32-AC32-AH32 -> 0 | AN32: =+G32+S32-AF32-AK32 -> 0 | AO32: =+H32+T32-AG32-AL32 -> 0 | AP32: =(AN32+AO32)/(S32+T32) -> #DIV/0! | AQ32: =($AP$1*AN32+$AQ$1*AO32) -> 0 | AR32: =(D32+J32+O32)-(X32+AH32) -> 0
