Workbook

Sheet PCB Details 
B7: Date | C7: Serial No | D7: New Code | E7: MPG Name | F7: BMC Name | G7: Total Qty | H7: Recovery Basis | I7: Non -Recovery Basis | J7: AMCU Repair | K7: Approved By | L7: Delivered By | M7: Receive by | N7: Remarks
B8: 45783 | C8: Stipl | D8: 10140007 | E8: English Dubauli | F8: Dumroan | G8: 1 | H8: =+G8 -> 1 | I8: 0 | J8: 0 | K8: Manish Sir | L8: Gaurav | M8: Courier | N8: Cost on recovery basis
B9: 45783 | C9: Stipl | D9: 10140013 | E9: Mathura Dera | F9: Dumroan | G9: 1 | H9: =+G9 -> 1 | I9: 0 | J9: 0 | K9: Manish Sir | L9: Gaurav | M9: Courier | N9: Cost on recovery basis
B10: 45783 | C10: Stipl | D10: 10510001 | E10: Arak | F10: Dumroan | G10: 1 | H10: =+G10 -> 1 | I10: 0 | J10: 0 | K10: Manish Sir | L10: Gaurav | M10: Courier | N10: Cost on recovery basis
B11: 45783 | C11: Stipl | D11: 10140001 | E11: Dumri Purvi | F11: Dumroan | G11: 1 | H11: 1 | I11: 0 | J11: 0 | K11: Manish Sir | L11: Gaurav | M11: Courier | N11: Cost on recovery basis
B12: 45784 | C12: GREP041400D4FQH077 | D12: 10030030 | E12: Mirahati-2 | F12: Asarganj | G12: 1 | H12: 0 | I12: 1 | J12: 0 | K12: Manish Sir | L12: Gaurav | M12: Babul | N12: used on non recovery basis in MPG
B13: 45784 | C13: GREP041400D4FQH103 | D13: 10030037 | E13: Launa | F13: Asarganj | G13: 1 | H13: 1 | I13: 0 | J13: 0 | K13: Manish Sir | L13: Gaurav | M13: Babul (paid) | N13: Cost on recovery basis
B14: 45787 | C14: GREP041400D4FQH079 | D14: 10060090 | E14: Sangrampur | F14: Sonvarsa | G14: 1 | H14: 0 | I14: 1 | J14: 0 | K14: Manish Sir | L14: Gaurav | M14: Umakant | N14: used on non recovery basis in MPG
B15: 45787 | C15: GREP041400D4FQH138 | D15: 10020021 | E15: Mohanpur | F15: Laldiyara | G15: 1 | H15: 1 | I15: 0 | J15: 0 | K15: Manish Sir | L15: Gaurav | M15: Umakant | N15: Cost on recovery basis
B16: 45787 | C16: GREP041400D4FQH080 | D16: 10090032 | E16: DHARSANDA | F16: Halsi | G16: 1 | H16: 1 | I16: 0 | J16: 0 | K16: Manish Sir | L16: Gaurav | M16: Umakant | N16: Cost on recovery basis
B17: 45787 | C17: GREP041400D4FQH084 | D17: 1009 | E17: Halsi BMC | F17: Halsi | G17: 1 | H17: 0 | I17: 1 | J17: 0 | K17: Manish Sir | L17: Gaurav | M17: Umakant | N17: Used on Non recovery basis in BMC
B18: 45800 | C18: GREP041400D4FQH070 | D18: 0 | E18: Munger Store | F18: Munger | G18: 1 | H18: 0 | I18: 0 | J18: 1 | K18: Manish Sir | L18: Gaurav | M18: Dharmendra Tiwari | N18: AMCU Repair
B19: 45803 | C19: GREP041400D4FQH126 | D19: 10010076 | E19: Gomukh Bhith | F19: Manjhaul | G19: 1 | H19: 1 | I19: 0 | J19: 0 | K19: Manish Sir | L19: Gaurav | M19: transport | N19: Used on Non recovery basis in BMC
B20: 45803 | C20: GREP041400D4FQH095 | D20: 10140022 | E20: Hemadpur | F20: Dumroan | G20: 1 | H20: 1 | I20: 0 | J20: 0 | K20: Verma Sir | L20: Gaurav | M20: transport | N20: Cost on recovery basis
B21: 45812 | C21: GREP041400D4FQH134 | D21: 10060077 | E21: Tilathi | F21: Sonvarsa | G21: 1 | H21: 0 | I21: 1 | J21: 0 | K21: Manish Sir | L21: Gaurav | M21: Arun AI | N21: used on non recovery basis in MPG
B22: 45814 | C22: GREP041400D4FQH100 | D22: 10140131 | E22: Basawkala | F22: Dumroan | G22: 1 | H22: 0 | I22: 1 | J22: 0 | K22: Verma Sir | L22: Gaurav | M22: DTDC Courier | N22: used on non recovery basis in MPG
... B30: 45834 | C30: GREP041400D4FQH094 | D30: 10130012 | E30: Arniyaganj | F30: Musrigharari | G30: 1 | H30: 1 | I30: 0 | J30: 0 | K30: Shankar sir | L30: Shahid | M30: Dev Prakash(AI | N30: Cost on recovery basis
B31: 45989 | C31: PFD-09258522 | D31: 1013 | E31: Musrigharari BMC | F31: Musrigharari | G31: 1 | H31: 0 | I31: 1 | J31: 0 | K31: Shankar sir | L31: Shahid | M31: Dev Prakash(AI | N31: Used on Non recovery basis in BMC | O31: Replace GREP041400D4FQH141
B32: 45834 | C32: GREP041400D4FQH140 | D32: 1012 | E32: Simri Store | F32: Simri | G32: 1 | H32: 0 | I32: 0 | J32: 1 | K32: Shankar sir | L32: Shahid | M32: Dev Prakash(AI | N32: AMCU Repair
B33: 45845 | C33: GREP041400D4FQH120 | D33: 10140129 | E33: Gomukh Paharpur | F33: Dumroan | G33: 1 | H33: 0 | I33: 1 | J33: 0 | K33: Shankar sir | L33: Gaurav | M33: Rakesh Sir | N33: used on non recovery basis in MPG
B34: 45845 | C34: GREP041400D4FQH127 | D34: 10090036 | E34: TAAL-SHAHARSHA | F34: Halsi | G34: 1 | H34: 1 | I34: 0 | J34: 0 | K34: Manish Sir | L34: Gaurav | M34: Gaurav | N34: Cost on recovery basis
B35: 45852 | C35: GREP041400D4FQH111 | D35: 10310001 | E35: Manikpur | F35: Sonvarsa | G35: 1 | H35: 1 | I35: 0 | J35: 0 | K35: Manish Sir | L35: Gaurav | M35: Umakant(done) | N35: Cost on recovery basis
B36: 45852 | C36: GREP041400D4FQH132 | D36: 10020037 | E36: Jaitpur | F36: Laldiyara | G36: 1 | H36: 1 | I36: 0 | J36: 0 | K36: Manish Sir | L36: Gaurav | M36: Umakant | N36: Cost on recovery basis
B37: 45852 | C37: GREP041400D4FQH118 | D37: 10120082 | E37: Dedua Balo Tol | F37: Simri | G37: 1 | H37: 1 | I37: 0 | J37: 0 | K37: Shankar sir | L37: Gaurav | M37: Kamesh ji | N37: Cost on recovery basis
B38: 45852 | C38: GREP041400D4FQH135 | E38: Transfer to WB | G38: 1 | H38: 0 | I38: 0 | J38: 1 | K38: Rakesh Sir | L38: Gaurav | M38: Asto | N38: AMCU Repair
B39: 45852 | C39: GREP041400D4FQH133 | E39: Transfer to WB | G39: 1 | H39: 0 | I39: 0 | J39: 1 | K39: Rakesh Sir | L39: Gaurav | M39: Asto | N39: AMCU Repair
B40: 45852 | C40: GREP041400D4FQH067 | E40: Transfer to WB | G40: 1 | H40: 0 | I40: 0 | J40: 1 | K40: Rakesh Sir | L40: Gaurav | M40: Asto | N40: AMCU Repair
B41: 45852 | C41: GREP041400D4FQH066 | E41: Transfer to WB | G41: 1 | H41: 0 | I41: 0 | J41: 1 | K41: Rakesh Sir | L41: Gaurav | M41: Asto | N41: AMCU Repair
B42: 45852 | C42: GREP041400D4FQH099 | E42: Transfer to WB | G42: 1 | H42: 0 | I42: 0 | J42: 1 | K42: Rakesh Sir | L42: Gaurav | M42: Asto | N42: AMCU Repair
B43: 45852 | C43: GREP041400D4FQH073 | E43: Transfer to WB | G43: 1 | H43: 0 | I43: 0 | J43: 1 | K43: Rakesh Sir | L43: Gaurav | M43: Asto | N43: AMCU Repair
B44: 45852 | C44: GREP041400D4FQH104 | E44: Transfer to WB | G44: 1 | H44: 0 | I44: 0 | J44: 1 | K44: Rakesh Sir | L44: Gaurav | M44: Asto | N44: AMCU Repair
B45: 45852 | C45: GREP041400D4FQH106 | E45: Transfer to WB | G45: 1 | H45: 0 | I45: 0 | J45: 1 | K45: Rakesh Sir | L45: Gaurav | M45: Asto | N45: AMCU Repair
B46: 45852 | C46: GREP041400D4FQH124 | E46: Transfer to WB | G46: 1 | H46: 0 | I46: 0 | J46: 1 | K46: Rakesh Sir | L46: Gaurav | M46: Asto | N46: AMCU Repair
B47: 45852 | C47: GREP041400D4FQH074 | E47: Transfer to WB | G47: 1 | H47: 0 | I47: 0 | J47: 1 | K47: Rakesh Sir | L47: Gaurav | M47: Asto | N47: AMCU Repair
B48: 45852 | C48: GREP041400D4FQH087 | E48: Transfer to WB | G48: 1 | H48: 0 | I48: 0 | J48: 1 | K48: Rakesh Sir | L48: Gaurav | M48: Asto | N48: AMCU Repair
B49: 45856 | C49: GREP041400D4FQH129 | D49: 10080100 | E49: Sibutol-2 | F49: Teghra | G49: 1 | H49: 0 | I49: 1 | J49: 0 | K49: Manish Sir | L49: Gaurav | M49: Navnit kumar | N49: used on non recovery basis in MPG
B50: 45867 | C50: GREP041400D4FQH091 | D50: 10090046 | E50: Rata | F50: Halsi | G50: 1 | H50: 1 | I50: 0 | J50: 0 | K50: Manish Sir | L50: Gaurav | M50: Ranjeet | N50: Cost on recovery basis
B51: 45869 | E51: Munger Store | F51: Munger | G51: 23 | H51: 0 | I51: 0 | J51: 23 | K51: Manish Sir | L51: Gaurav | M51: Dharmendra Tiwari | N51: AMCU Repair
B52: 45874 | C52: GREP041400D4FQH075 | D52: 10030010 | E52: Katni | F52: Asarganj | G52: 1 | H52: 1 | I52: 0 | J52: 0 | K52: Manish Sir | L52: Gaurav | M52: Tinku (Paid) | N52: Cost on recovery basis
B53: 45908 | C53: GREP041400D4FQH081 | D53: 10090008 | E53: Mahasoni | F53: Halsi | G53: 1 | H53: 1 | I53: 0 | J53: 0 | K53: Manish Sir | L53: Gaurav | M53: Umakant (Paid) | N53: Cost on recovery basis
...

Sheet Recovery Detail
A1: Issue Date | B1: MPG Code | C1: New MPG Code | D1: Name | E1: Total AMT | F1: In Bank | G1: Apr'25 | H1: May'25 | I1: Jun'25 | J1: July'25 | K1: Aug'25 | L1: Sep'25 | M1: Oct'25 | N1: Nov'25 | O1: Dec'25 | P1: Jan'26 | Q1: Feb'26 | R1: Mar'26 | S1: Due | T1: Remarks
B2: 1704 | C2: 10130027 | D2: Vishnupatti | E2: 640 | R2: 0 | S2: =E2-SUM(F2:R2) -> 640
B3: 9786 | C3: 10080014 | D3: Rachiyahi | E3: 7142 | G3: 1011 | H3: 481 | O3: 3000 | P3: 3517 | S3: =E3-SUM(F3:R3) -> -867
B4: 0314 | C4: #N/A | D4: Madhepur | E4: 8500 | S4: =E4-SUM(F4:R4) -> 8500
B5: 7101 | C5: #N/A | D5: Pachgachiya | E5: 6618 | S5: =E5-SUM(F5:R5) -> 6618
B6: 9149 | C6: 10080017 | D6: Bachhwara | E6: 14200 | S6: =E6-SUM(F6:R6) -> 14200
B7: 9759 | C7: 10110022 | D7: Sukhdeo Babutol | E7: 1878 | S7: =E7-SUM(F7:R7) -> 1878
B8: 8574 | C8: 10100004 | D8: Muradpur | E8: 7316 | G8: 146 | I8: 1265 | S8: =E8-SUM(F8:R8) -> 5905
B9: 5119 | C9: 10030020 | D9: Barui | E9: 14200 | S9: =E9-SUM(F9:R9) -> 14200
B10: 1198 | C10: 10090023 | D10: Tetharhat | E10: 9996 | S10: =E10-SUM(F10:R10) -> 9996
B11: 2121 | C11: 10120024 | D11: Badiya | E11: 704 | P11: 704 | S11: =E11-SUM(F11:R11) -> 0
B12: 2027 | C12: 10120022 | D12: Jaunapur | E12: 4825 | Q12: 63 | S12: =E12-SUM(F12:R12) -> 4762
B13: 7107 | C13: 10480004 | D13: Mirror Tola | E13: 6241 | S13: =E13-SUM(F13:R13) -> 6241
B14: 8649 | C14: 10100036 | D14: Bishauni | E14: 8196 | S14: =E14-SUM(F14:R14) -> 8196
A15: 45418 | B15: 1770 | C15: 10130045 | D15: Mahipura | E15: 7592 | S15: =E15-SUM(F15:R15) -> 7592
A16: 45510 | C16: 10140020 | D16: Rajapur | E16: 5683 | I16: 125 | S16: =E16-SUM(F16:R16) -> 5558
A17: 45561 | B17: 8594 | C17: 10100019 | D17: Bari Lagar | E17: 7238 | S17: =E17-SUM(F17:R17) -> 7238
A18: 45570 | B18: 1235 | C18: 10060030 | D18: Ramsir(10700-4000) | E18: 1420 | G18: 294 | H18: 547 | I18: 535 | S18: =E18-SUM(F18:R18) -> 44
A19: 45583 | B19: 0393 | C19: 10120034 | D19: Matior | E19: 4162 | G19: 1165 | H19: 395 | I19: 1005 | S19: =E19-SUM(F19:R19) -> 1597
A20: 45586 | B20: 2460 | C20: 10140043 | D20: Kaithi | E20: 6303 | G20: 415 | S20: =E20-SUM(F20:R20) -> 5888
A21: 45591 | B21: 1907 | C21: 10130013 | D21: Gomukh Sarmaspur | E21: 3401 | G21: 733 | H21: 1113 | I21: 642 | S21: =E21-SUM(F21:R21) -> 913
A22: 45640 | B22: 1287 | C22: 10090048 | D22: Noma(10700-5400) | E22: 10700 | F22: 5400 | S22: =E22-SUM(F22:R22) -> 5300
A23: 45719 | B23: 1723 | C23: 10130009 | D23: Gomukh BARDIHA TUTRI PETROL PUMP | E23: 10700 | S23: =E23-SUM(F23:R23) -> 10700
A24: 45766 | B24: 8582 | C24: 10100009 | D24: Gomukh Kanhaiyachak Pachhim | E24: 10700 | G24: 5000 | I24: 5000 | K24: 700 | S24: =E24-SUM(F24:R24) -> 0
A25: 45766 | B25: 7118 | C25: 10480014 | D25: Gomukh Amghatta Shreepur | E25: 10700 | G25: 3834 | H25: 497 | I25: 2476 | K25: 342 | S25: =E25-SUM(F25:R25) -> 3551
A26: 45783 | B26: 2401 | C26: 10140001 | D26: Dumri Purvi Tola | E26: 10700 | O26: 439 | P26: 2326 | Q26: 1172 | R26: 696 | S26: =E26-SUM(F26:R26) -> 6067
A27: 45787 | B27: 1224 | C27: 10090032 | D27: Dharsanda(10700-5000) | E27: 10700 | F27: 5000 | I27: 587 | S27: =E27-SUM(F27:R27) -> 5113
A28: 45787 | B28: 1196 | C28: 10020021 | D28: Mohanpur (10700-5000) | E28: 10700 | F28: 5000 | Q28: 3000 | R28: 2700 | S28: =E28-SUM(F28:R28) -> 0
A29: 45803 | B29: 2435 | C29: 10140022 | D29: HEMDAPUR | E29: 10700 | I29: 634 | P29: 1104 | Q29: 3000 | R29: 1211 | S29: =E29-SUM(F29:R29) -> 4751
A30: 45814 | B30: 2415 | C30: 10140008 | D30: Ramo Bariya | E30: 10700 | I30: 3000 | K30: 1373 | M30: 3000 | N30: 3000 | O30: 327 | S30: =E30-SUM(F30:R30) -> 0
A31: 45814 | B31: 2430 | C31: 10140015 | D31: Harnaha | E31: 10700 | S31: =E31-SUM(F31:R31) -> 10700
A32: 45828 | B32: 8613 | C32: 10070033 | D32: Gomukh Kabela | E32: 10700 | I32: 1173 | M32: 48 | O32: 829 | P32: 316 | Q32: 757 | S32: =E32-SUM(F32:R32) -> 7577
A33: 45828 | B33: 8650 | C33: 10100037 | D33: Gomukh Tehay | E33: 10700 | I33: 3000 | S33: =E33-SUM(F33:R33) -> 7700
A34: 45828 | B34: 10070049 | C34: 10070049 | D34: Sondiha | E34: 10700 | I34: 890 | J34: 3073 | K34: 2290 | L34: 2237 | S34: =E34-SUM(F34:R34) -> 2210
A35: 45834 | B35: 10120083 | C35: 10120083 | D35: Beri East | E35: 10700 | I35: 266 | K35: 443 | L35: 1030 | M35: 1825 | N35: 301 | O35: 1064 | P35: 678 | Q35: 618 | S35: =E35-SUM(F35:R35) -> 4475
A36: 45834 | B36: 2058 | C36: 10120046 | D36: Gomukh Ghataho | E36: 10700 | I36: 3000 | J36: 5000 | K36: 2700 | S36: =E36-SUM(F36:R36) -> 0
A37: 45834 | B37: 1901 | C37: 10130012 | D37: Gomukha Arniya Ganj | E37: 10700 | I37: 3000 | J37: 5000 | K37: 2700 | S37: =E37-SUM(F37:R37) -> 0
A38: 45845 | B38: 1244 | C38: 10090036 | D38: TAAL-SHAHARSHA (10700-5000) | E38: 10700 | F38: 5000 | L38: 562 | M38: 570 | N38: 1080 | O38: 3000 | P38: 488 | S38: =E38-SUM(F38:R38) -> 0
A39: 45852 | B39: 1225 | C39: 10020037 | D39: JAITPUR (10700-1000) | E39: 10700 | F39: 1000 | J39: 1620 | K39: 1088 | S39: =E39-SUM(F39:R39) -> 6992
A40: 45852 | B40: 10120082 | C40: 10120082 | D40: Dedua Balo Tol | E40: 10700 | S40: =E40-SUM(F40:R40) -> 10700
...

Sheet Deductable for Apr'26
C3: New MPG Code | D3: Name | E3: Amount
C4: 10130027 | D4: Vishnupatti | E4: 640
C5: 10080017 | D5: Bachhwara | E5: 14200
C6: 10110022 | D6: Sukhdeo Babutol | E6: 1878 | J6: New MPG Code | K6: MPG Name | L6: Due | M6: Deduction | N6: Remarks
C7: 10100004 | D7: Muradpur | E7: 5905 | J7: 10140020 | K7: RAJAPUR | L7: 10700 | M7: 5700 | N7: Deduct from milk bill payment
C8: 10030020 | D8: Barui | E8: 14200 | J8: 10140058 | K8: Gomukh Lewar | L8: 10700 | M8: 5700 | N8: Deduct from milk bill payment
C9: 10090023 | D9: Tetharhat | E9: 9996 | J9: 10120080 | K9: Manikatol | L9: 10700 | M9: 2000 | N9: Deduct from milk bill payment
C10: 10120022 | D10: Jaunapur | E10: 4762 | J10: 10130014 | K10: Tara Dhamaun dakshin | L10: 10700 | M10: 2000 | N10: Deduct from milk bill payment
C11: 10480004 | D11: Mirror Tola | E11: 6241
C12: 10100036 | D12: Bishauni | E12: 5000
C13: 10130045 | D13: Mahipura | E13: 5000
C14: 10140020 | D14: RAJAPUR | E14: 5558
C15: 10100019 | D15: Bari Lagar | E15: 5000
C16: 10060030 | D16: Ramsir(10700-4000) | E16: 44
C17: 10120034 | D17: Matior | E17: 1597
C18: 10140043 | D18: Kaithi | E18: 5888
C19: 10130013 | D19: Gomukh Sarmaspur | E19: 913
C20: 10090048 | D20: Noma(10700-5400) | E20: 5300
C21: 10130009 | D21: Gomukh BARDIHA TUTRI PETROL PUMP | E21: 5000
C22: 10480014 | D22: Gomukh Amghatta Shreepur | E22: 3551
... C78: 10070043 | D78: Araria | E78: 3000
C79: Total Amount | E79: =SUM(E4:E78) -> 274263

Sheet Purchase
C4: Date | D4: From Purhcase | E4: Opening | F4: Receive | G4: Issue | H4: Closing | I4: Fresh Faulty | J4: Total Closing Stock | K4: Remarks
C5: 45775 | D5: STIPL | E5: 0 | F5: 76 | G5: =+'PCB Details '!G155 -> 156 | H5: =D23 -> 14 | I5: =D22 -> 2 | J5: =+H5+I5 -> 16 | K5: 2 PCB sent from Store to STIPL for Replace
C6: 45939 | D6: EIPL | E6: 0 | F6: 25 | G6: =+'PCB Details '!G156 -> 0
C7: 45946 | D7: EIPL | E7: 0 | F7: 25 | G7: =+'PCB Details '!G157 -> 0
C8: 45732 | D8: EIPL | E8: 1 | F8: 25
C9: 45747 | D9: EIPL | E9: 0 | F9: 21
F11: =SUM(F5:F10) -> 172
C14: Particular | D14: Qty | E14: Rate | F14: Amout
C15: Purchase | D15: =F11 -> 172 | E15: 9598.3684 | F15: =D15*E15 -> 1650919.4
C16: Total Received | D16: =D15 -> 172 | E16: 9598.3684 | F16: 1209394.4
C17: PCB Issued on recoverable Basis | D17: ='PCB Details '!H155 -> 77 | E17: 9598.3684 | F17: =D17*E17 -> 739074.37
C18: PCB Issued on no recoverable basis | D18: ='PCB Details '!I155 -> 37 | E18: 9598.3684 | F18: =D18*E18 -> 355139.63 | G18: =+F18+F19 -> 758271.11
C19: AMCU Repair | D19: ='PCB Details '!J155 -> 42 | E19: 9598.3684 | F19: =D19*E19 -> 403131.47
C20: Total Issue | D20: =SUM(D17:D19) -> 156 | E20: 9598.3684 | F20: =SUM(F17:F19) -> 1497345.5
C22: Fresh Foulty | D22: 2 | E22: 9598.3684 | F22: =+D22*E22 -> 19196.737
C23: Closing in Stock | D23: =D16-(D20+D22) -> 14 | E23: 9598.3684 | F23: =+D23*E23 -> 134377.16

Sheet Old Purchase 
C5: Date | D5: Purchase Qty | E5: Purchase Amount | F5: Recovery from LY'23 | G5: Remarks
C6: 45139 | D6: Opening | E6: 393677 | F6: =1480226+258102 -> 1738328
C7: 45168 | D7: 20 | E7: 270722
C8: 45272 | D8: 25 | E8: 338041
C9: 45414 | D9: 20 | E9: 212400
C10: 45427 | D10: 20 | E10: 212400
C11: 45559 | D11: 30 | E11: =10620*30 -> 318600
C12: 45660 | D12: 25 | E12: =10620*25 -> 265500 | G12: Purchased from CSR
C13: 45661 | D13: 25 | E13: =10620*25 -> 265500 | G13: Purchased from CSR
C14: 45775 | D14: 76 | E14: 729476 | G14: Purchased from CSR
D15: =SUM(D6:D14) -> 241 | E15: =SUM(E6:E14) -> 3006316 | F15: =+E19 -> 0 | G15: Net Recoverable Amount

Sheet Not recover Old data
A1: SL No. | B1: BMC Name | C1: MPG Code | D1: Name | E1: Total AMT | F1: Due | G1: Remarks
A2: 1 | B2: Lakhisarai Area | C2: 1167 | D2: SANDH MAAF | E2: 14200 | F2: 2957 | G2: Close
A3: =+A2+1 -> 2 | B3: Samastipur Area | C3: 1726 | D3: Husainipur | E3: =14200+14200+14200 -> 42600 | F3: =4670+14200+431 -> 19301 | G3: Close
A4: =+A3+1 -> 3 | B4: Samastipur Area | C4: 1916 | D4: Gomukh Laxminarayanpur | E4: 14200 | F4: 5894 | G4: Close
A5: =+A4+1 -> 4 | B5: Samastipur Area | C5: 1703 | D5: Mahisor | E5: 14200 | F5: 14200 | G5: Close
A6: =+A5+1 -> 5 | B6: Samastipur Area | C6: 2020 | D6: Balthara | E6: 14200 | F6: 14200 | G6: Close
A7: =+A6+1 -> 6 | B7: Samastipur Area | C7: 1745 | D7: Banvira | E7: 14200 | F7: 14200 | G7: Close
A8: =+A7+1 -> 7 | B8: Samastipur Area | C8: 2001 | D8: Bagnoucha | E8: 14200 | F8: 14200 | G8: Close
A9: =+A8+1 -> 8 | B9: Samastipur Area | C9: 2011 | D9: Hentanpur | E9: 14200 | F9: 14200 | G9: Close
A10: =+A9+1 -> 9 | B10: Samastipur Area | C10: 0007 | D10: Jhandapur BMC | E10: 14200 | F10: 14200 | G10: Close
A11: =+A10+1 -> 10 | B11: Samastipur Area | C11: 0936 | D11: Rachiyahi | E11: 14200 | F11: 5650 | G11: Close
A12: =+A11+1 -> 11 | B12: Samastipur Area | C12: 1701 | D12: Madhopur | E12: 14200 | F12: 14200 | G12: Close
A13: =+A12+1 -> 12 | B13: Samastipur Area | C13: 0386 | D13: KURSAHATOL | E13: =14200+14200 -> 28400 | F13: =14200+14200 -> 28400 | G13: Close
A14: =+A13+1 -> 13 | B14: Samastipur Area | C14: 0342 | D14: PACHPAIKA | E14: 14200 | F14: 12275 | G14: Close
A15: =+A14+1 -> 14 | B15: Samastipur Area | C15: 0316 | D15: ASHINCHAK | E15: 14200 | F15: 14200 | G15: Close
A16: =+A15+1 -> 15 | B16: Samastipur Area | C16: 0356 | D16: BHOJPUR | E16: 14200 | F16: 14200 | G16: Close
A17: =+A16+1 -> 16 | B17: Samastipur Area | C17: 0380 | D17: Hargingpur kothi | E17: 14200 | F17: 13336 | G17: Close
A18: =+A17+1 -> 17 | B18: Samastipur Area | C18: 0314 | D18: Madhepur | E18: =14200+8500 -> 22700 | F18: 22700 | G18: Close
A19: =+A18+1 -> 18 | B19: Lakhisarai Area | C19: 0118 | D19: Nandpur | E19: 14200 | F19: 0 | G19: 0
A20: =+A19+1 -> 19 | B20: Bhagalpur Area | C20: 7101 | D20: Pachgachiya | E20: 14200 | F20: 6618 | G20: No deduction from One years
A21: =+A20+1 -> 20 | B21: Begusarai Area | C21: 9148 | D21: Gehuni | E21: 14200 | F21: 0 | G21: No deduction from Six Month
A22: =+A21+1 -> 21 | B22: Begusarai Area | C22: 9149 | D22: Bachhwara | E22: 14200 | F22: 14200 | G22: No deduction from One years
A23: =+A22+1 -> 22 | B23: Samastipur Area | C23: 2026 | D23: Bisunpur Beri | E23: 14200 | F23: 0 | G23: No deduction from One years
A24: =+A23+1 -> 23 | B24: Bhagalpur Area | C24: 5119 | D24: Barui | E24: 14200 | F24: 14200 | G24: No deduction from Six Month
A25: =+A24+1 -> 24 | B25: Lakhisarai Area | C25: 1198 | D25: Tetharhat | E25: 14200 | F25: 9996 | G25: No deduction from Six Month
E26: =SUM(E2:E25) -> 391900 | F26: =SUM(F2:F25) -> 283327
