Workbook
Name Proposed_Rate: #REF!
Name Proposed_Rate: #REF!
Name Proposed_Rate: #REF!
Name Sudha_rate: #REF!
Name Sudha_rate: #REF!
Name Sudha_rate: #REF!

Sheet Charts
C3: ALL | D3: 23-24 | E3: 24-25 | F3: 25-26 | G3: GOLY
C4: Q1 | D4: {=TRANSPOSE(Consolidate!Q9:U9)/1000} -> 165.47478 | E4: {=TRANSPOSE(Consolidate!Q14:U14)/1000} -> 171.2651 | F4: {=TRANSPOSE(Consolidate!Q19:U19)/1000} -> 194.65177 | G4: =+(F4-E4)/E4 -> 0.13655247
C5: Q2 | D5: 165.76916 | E5: 166.07731 | F5: 220.22352 | G5: =+(F5-E5)/E5 -> 0.32603015
C6: Q3 | D6: 174.09512 | E6: 158.77369 | F6: 216.27384 | G6: =+(F6-E6)/E6 -> 0.36215165
C7: Q4 (OL) | D7: 205.91769 | E7: 206.93885 | F7: 278.32653 | G7: =+(F7-E7)/E7 -> 0.34496988
C8: Total | D8: 177.78012 | E8: 175.61424 | F8: 227.17933 | G8: =+(F8-E8)/E8 -> 0.29362704
C17: BIHAR | D17: 23-24 | E17: 24-25 | F17: 25-26 | G17: GOLY
C18: Q1 | D18: {=TRANSPOSE(BIHAR!Q59:U59)/1000} -> 77.671396 | E18: {=TRANSPOSE(BIHAR!Q64:U64)/1000} -> 94.953511 | F18: {=TRANSPOSE(BIHAR!Q69:U69)/1000} -> 105.8037 | G18: =+(F18-E18)/E18 -> 0.1142684
C19: Q2 | D19: 97.55419 | E19: 101.18849 | F19: 115.10707 | G19: =+(F19-E19)/E19 -> 0.13755109
C20: Q3 | D20: 109.9413 | E20: 99.953328 | F20: 114.52539 | G20: =+(F20-E20)/E20 -> 0.14578867
C21: Q4 (OL) | D21: 139.82255 | E21: 147.11542 | F21: 174.20615 | G21: =+(F21-E21)/E21 -> 0.18414608
C22: Total | D22: 106.2427 | E22: 110.65614 | F22: 127.21336 | G22: =+(F22-E22)/E22 -> 0.14962772
C33: WB | D33: 23-24 | E33: 24-25 | F33: 25-26 | G33: GOLY
C34: Q1 | D34: {=TRANSPOSE('WEST BENGAL'!Q38:U38)/1000} -> 87.803386 | E34: {=TRANSPOSE('WEST BENGAL'!Q42:U42)/1000} -> 67.025841 | F34: {=TRANSPOSE('WEST BENGAL'!Q46:U46)/1000} -> 70.468206 | G34: =+(F34-E34)/E34 -> 0.051358777
C35: Q2 | D35: 67.763271 | E35: 53.65737 | F35: 84.668521 | G35: =+(F35-E35)/E35 -> 0.57794765
C36: Q3 | D36: 60.54968 | E36: 48.50834 | F36: 82.881054 | G36: =+(F36-E36)/E36 -> 0.70859392
C37: Q4 (OL) | D37: 59.59332 | E37: 48.583064 | F37: 86.614883 | G37: =+(F37-E37)/E37 -> 0.78282051
C38: Total | D38: 68.901344 | E38: 54.441295 | F38: 81.157554 | G38: =+(F38-E38)/E38 -> 0.49073519
D42: Vol Kg/day | H42: Supply Chain Cost
C43: Year | D43: BR | E43: WB | F43: JH | G43: Total Vol | H43: BR | I43: WB | J43: JH | K43: Total SCC
C44: FY 23-24 | D44: 106242.7 | E44: 68901.344 | F44: 4523.7654 | G44: =SUM(D44:F44) -> 179667.81 | H44: 2.9625336 | I44: 2.89 | J44: 4.1516524 | K44: =(D44*H44+E44*I44+F44*J44)/(F44+E44+D44) -> 2.9646577
C45: FY 24-25 | D45: 110656.14 | E45: 54441.295 | F45: =JHARKHAND!U20 -> 10516.81 | G45: =SUM(D45:F45) -> 175614.24 | H45: 2.8713666 | I45: 2.8986351 | J45: =JHARKHAND!U38 -> 3.6553669 | K45: =(D45*H45+E45*I45+F45*J45)/(F45+E45+D45) -> 2.9267705
C46: FY 25-26 | D46: =BIHAR!U69 -> 127213.36 | E46: ='WEST BENGAL'!U46 -> 81157.554 | F46: 19000 | G46: =SUM(D46:F46) -> 227370.91 | H46: 2.75 | I46: 2.86 | J46: 3.76 | K46: =(D46*H46+E46*I46+F46*J46)/(F46+E46+D46) -> 2.8736628
C47: PY 25-26 | D47: 201017.92 | E47: 120878.99 | F47: 31536.81 | G47: =SUM(D47:F47) -> 353433.72 | H47: 2.9046318 | I47: 2.8526454 | J47: 3.5 | K47: =(D47*H47+E47*I47+F47*J47)/(F47+E47+D47) -> 2.9399763
C49: Year | D49: =H43 -> BR | E49: =I43 -> WB | F49: =J43 -> JH | G49: =K43 -> Total SCC
C50: FY 23-24 | D50: =H44 -> 2.9625336 | E50: =I44 -> 2.89 | F50: =J44 -> 4.1516524 | G50: =K44 -> 2.9646577
C51: FY 24-25 | D51: =H45 -> 2.8713666 | E51: =I45 -> 2.8986351 | F51: =J45 -> 3.6553669 | G51: =K45 -> 2.9267705
C52: FY 25-26 | D52: =H46 -> 2.75 | E52: =I46 -> 2.86 | F52: =J46 -> 3.76 | G52: =K46 -> 2.8736628
C53: PY 1 | D53: =H47 -> 2.9046318 | E53: =I47 -> 2.8526454 | F53: =J47 -> 3.5 | G53: =K47 -> 2.9399763
C54: PY 3 | D54: 2.74 | E54: 2.8 | F54: 3.45 | G54: 2.8
C55: PY 5 | D55: 2.65 | E55: 2.75 | F55: 3.42 | G55: 2.72
C62: Farmers
C63: Year | D63: BR | E63: WB | F63: JH | G63: Total
C64: FY 23-24 | D64: 16.2 | E64: 6.4 | F64: 0.2 | G64: =SUM(D64:F64) -> 22.8
C65: FY 24-25 | D65: 19 | E65: 4.6 | F65: 2.2 | G65: =SUM(D65:F65) -> 25.8
C66: FY 25-26 | D66: 23 | E66: 6.8 | F66: 2.5 | G66: =SUM(D66:F66) -> 32.3
C67: PY 1 | D67: 29 | E67: 9 | F67: 3 | G67: =SUM(D67:F67) -> 41
C68: PY 3 | D68: 36 | E68: 13.5 | F68: 3.5 | G68: =SUM(D68:F68) -> 53
C69: PY 5 | D69: 43 | E69: 17 | F69: 3.7 | G69: =SUM(D69:F69) -> 63.7
C72: Capacity Utilization
...

Sheet Volume Summary
B3: Year | C3: BR | D3: WB | E3: JH | F3: Total | G3: GOLY
B4: 2017-18 | C4: =BIHAR!U40 -> 63237.577 | F4: =C4+D4+E4 -> 63237.577 | G4: 1
B5: 2018-19 | C5: =BIHAR!U42 -> 95322.951 | F5: =C5+D5+E5 -> 95322.951 | G5: =F5/F4 -> 1.5073783
B6: 2019-20 | C6: =BIHAR!U45 -> 78700.6 | D6: ='WEST BENGAL'!U26 -> 30847.099 | F6: =C6+D6+E6 -> 109547.7 | G6: =F6/F5 -> 1.1492269
B7: 2020-21 | C7: =BIHAR!U49 -> 85718.639 | D7: ='WEST BENGAL'!U29 -> 49747.2 | F7: =C7+D7+E7 -> 135465.84 | G7: =F7/F6 -> 1.2365923
B8: 2021-22 | C8: =BIHAR!U53 -> 110324.25 | D8: ='WEST BENGAL'!U33 -> 54835.418 | F8: =C8+D8+E8 -> 165159.67 | G8: =F8/F7 -> 1.2191979
B9: 2022-23 | C9: =BIHAR!U58 -> 137845.63 | D9: ='WEST BENGAL'!U37 -> 60401.684 | F9: =C9+D9+E9 -> 198247.31 | G9: =F9/F8 -> 1.2003373
B10: 2023-24 | C10: =BIHAR!U63 -> 142133.71 | D10: ='WEST BENGAL'!U41 -> 63798.738 | E10: =JHARKHAND!U19 -> 19848.561 | F10: =C10+D10+E10 -> 225781.01 | G10: =F10/F9 -> 1.1388856
B11: 2024-25 | C11: =BIHAR!U68 -> 154571.98 | D11: ='WEST BENGAL'!U45 -> 67664.381 | E11: =JHARKHAND!U24 -> 32342.837 | F11: =C11+D11+E11 -> 254579.19 | G11: =F11/F10 -> 1.1275492
B12: 2025-26 | C12: =BIHAR!U73 -> 199773.06 | D12: ='WEST BENGAL'!U49 -> 93620.165 | E12: =JHARKHAND!U29 -> 38794.675 | F12: =C12+D12+E12 -> 332187.9 | G12: =F12/F11 -> 1.3048509
B16: Particulars | C16: UoM | D16: 23-24 | E16: 24-25 | F16: YTD Sep’25
B17: Milk Producing Group (MPG) | C17: Nos. | D17: =BIHAR!P14+'WEST BENGAL'!V9+JHARKHAND!N4 -> 896 | E17: =BIHAR!P15+'WEST BENGAL'!V10+JHARKHAND!O5 -> 1038 | F17: =BIHAR!P16+'WEST BENGAL'!V11+JHARKHAND!H6 -> 1452
B18: Milk Volume | C18: Kg./Day | D18: =BIHAR!U59+'WEST BENGAL'!U38+JHARKHAND!U15 -> 179667.81 | E18: =BIHAR!U64+'WEST BENGAL'!U42+JHARKHAND!U20 -> 175614.24 | F18: =BIHAR!U69+'WEST BENGAL'!U46+JHARKHAND!U25 -> 227179.33
B19: Farmers | C19: Nos. | D19: =BIHAR!P28+'WEST BENGAL'!V18+JHARKHAND!O9 -> 20828 | E19: =BIHAR!P29+'WEST BENGAL'!V19+JHARKHAND!O10 -> 14119 | F19: =BIHAR!D30+'WEST BENGAL'!E20+JHARKHAND!H11 -> 12935
B20: Bulk Milk Chiller (BMC) | C20: Nos. | D20: =13+1+10 -> 24 | E20: =14+1+7 -> 22 | F20: =18+2+11 -> 31
B21: BMC Capacity | C21: KL/Day | D21: =93+80+5 -> 178 | E21: =110+5+62 -> 177 | F21: =125+82+10 -> 217
B22: BMC Utilization % | D22: 0.66 | E22: 0.7 | F22: 0.68
B23: Rapid Milk Chiller (RMC) | C23: KL/Day | D23: =39+4+10 -> 53 | E23: =29+8.5+29 -> 66.5 | F23: =32+11+22 -> 65
B24: RMC Utilization % | D24: 0.65 | E24: 0.44 | F24: 0.72
B29: Year | C29: 2020-21 | D29: 2021-22 | E29: 2022-23 | F29: 2023-24 | G29: 2024-25 | H29: 2025-26 | I29: 2026-27 Plan | J29: PY-1 | K29: PY-2 | L29: PY-3 | M29: PY-4 | N29: PY-5
B30: No of State | C30: 2 | D30: 2 | E30: 2 | F30: 3 | G30: 3 | H30: 3 | I30: 3 | J30: 3 | K30: 3 | L30: 3 | M30: 3 | N30: 3
B31: No of District | C31: 9 | D31: 10 | E31: 11 | F31: 12 | G31: 13
B32: No of Plant | C32: 2 | D32: 3 | E32: 3 | F32: 5 | G32: 6 | H32: 7 | I32: 7
B33: No of MPG | C33: {=TRANSPOSE(BIHAR!AA12:AA17)} -> 626 | D33: 618 | E33: 692 | F33: 894 | G33: 1038 | H33: 1464 | I33: =1602+342+205 -> 2149
B34: Total milk procured | C34: {=TRANSPOSE(F7:F12)} -> 135465.84 | D34: 165159.67 | E34: 198247.31 | F34: 225781.01 | G34: 254579.19 | H34: 332187.9 | I34: 502540.47 | J34: 569954 | K34: 669365 | L34: 790154 | M34: 934694 | N34: 1094380
B35: No of Farmers | C35: 16080.571 | D35: 14920.418 | E35: 16544.271 | F35: 23508.118 | G35: 25532.33 | H35: 25532.33 | I35: 25532.33

Sheet BR Slide SCC and Cost
B2: Bihar Network Volume Supply Chain Cost
B3: Particulars | C3: Actual | D3: Plan | E3: 2024-25 (YTD Dec) | G3: Jan Mar: 2024-25 | I3: Outlook
C4: 2023-24 | D4: 2024-25 | E4: Plan | F4: Actual | G4: Plan | H4: Outlook | I4: 2024-25
B5: Network Vol | C5: =BIHAR!#REF! -> #REF! | D5: 133366.8 | E5: 126070.42 | F5: 98847.558 | G5: 155661.27 | H5: 149990.18 | I5: 111458.07
B6: Procurement | C6: =BIHAR!#REF! -> #REF! | D6: 0.58121593 | E6: 0.5820299 | F6: 0.57592833 | G6: 0.57919447 | H6: 0.53592774 | I6: 0.56246821
B7: Inward | C7: =BIHAR!#REF! -> #REF! | D7: 0.93064174 | E7: 0.97272727 | F7: 1.0596895 | G7: 0.8261248 | H7: 0.76134258 | I7: 0.9592964
B8: Chilling | C8: =BIHAR!#REF! -> #REF! | D8: 0.45089134 | E8: 0.45827484 | F8: 0.52806338 | G8: 0.43255484 | H8: 0.45889161 | I8: 0.50478723
B9: Outward | C9: =BIHAR!#REF! -> #REF! | D9: 0.66388691 | E9: 0.66586288 | F9: 0.74057157 | G9: 0.65897972 | H9: 0.63082968 | I9: 0.70364366
B10: NGO Cost | C10: =BIHAR!#REF! -> #REF! | D10: 0.15338305 | E10: 0.15877001 | F10: 0.16915929 | G10: 0.14000485 | H10: 0.11185548 | I10: 0.14987668
B11: Network SCC | C11: =SUM(C6:C10) -> #REF! | D11: =SUM(D6:D10) -> 2.780019 | E11: =SUM(E6:E10) -> 2.8376649 | F11: =SUM(F6:F10) -> 3.0734121 | G11: =SUM(G6:G10) -> 2.6368587 | H11: =SUM(H6:H10) -> 2.4988471 | I11: =SUM(I6:I10) -> 2.8800722
B16: Bihar source wise milk cost
B17: Particulars | C17: Actual | D17: Plan | E17: 2024-25 (YTD Dec) | G17: Jan Mar: 2024-25 | I17: Outlook
C18: 2023-24 | D18: 2024-25 | E18: Plan | F18: Actual | G18: Plan | H18: Outlook | I18: 2024-25
B19: Network | C19: 40.354218 | D19: 40.375863 | E19: =37.5+E11 -> 40.337665 | F19: 40.243259 | G19: 40.350964 | H19: 39.976858 | I19: 40.153616
B20: WB Transfer | C20: 44.942229 | D20: 0 | E20: 0 | F20: 42.482687 | G20: 0 | H20: 0 | I20: 42.482687
B21: Moomark | C21: 41.221847 | D21: 38.964204 | E21: 38.944717 | F21: 41.26458 | G21: 39.011362 | H21: 0 | I21: 41.26458
B22: Outside Milk | C22: 41.705129 | D22: 38.554848 | E22: 38.554848 | F22: 39.545986 | G22: 0 | H22: 39.674024 | I22: 39.56548
B23: Total Landed Cost | C23: 40.774101 | D23: 40.121254 | E23: 40.121105 | F23: 40.005589 | G23: 40.260858 | H23: 39.930267 | I23: 39.984742
B26: Bihar Source wise milk cost FY 24-25
B27: Particulars | C27: Q1 | D27: Q2 | E27: Q3 | F27: Q4
C28: Actual | D28: Actual | E28: Actual | F28: Outlook | G28: FY24-25
B29: Network Milk | C29: 40.266068 | D29: 40.27255 | E29: 40.192012 | F29: 39.976858 | G29: 40.033094
B30: WB Transfer | C30: 42.572705 | D30: 42.264179 | E30: 42.934462 | F30: 0 | G30: 42.482687
B31: Moomark | C31: 40.612169 | D31: 42.146667 | E31: 42.146667 | F31: #DIV/0! | G31: 42.146667
B32: Outside Milk | C32: 39.296484 | D32: 39.701967 | E32: 39.609246 | F32: 39.674024 | G32: 39.571366
B33: Overall Cost | C33: 39.982095 | D33: 40.101607 | E33: 39.934709 | F33: 39.930267 | G33: 39.934111
B36: BIHAR: MILK COLLECTION (000 Kg/day)
B37: Period | C37: LY 23-24 | D37: Plan 24-25 | E37: Actual | F37: Collection 24-25
E38: Reqt | F38: BR | G38: 3P | H38: Outside | I38: Transfer | J38: Total
B39: Q1 | C39: {=TRANSPOSE(BIHAR!Q63:U63)/1000} -> 142.10088 | D39: 163.69097 | F39: {=TRANSPOSE(BIHAR!Q64:U67)/1000} -> 94.953511 | G39: 7.4086964 | H39: 45.192038 | I39: 1.9698104 | J39: =SUM(F39:I39) -> 149.52406
B40: Q2 | C40: 129.9635 | D40: 156.04419 | F40: 101.18849 | G40: 3.8657364 | H40: 48.936038 | I40: 0.71756454 | J40: =SUM(F40:I40) -> 154.70783
B41: Q3 | C41: 137.44905 | D41: 151.04432 | F41: 99.953328 | G41: 1.584606 | H41: 57.895009 | I41: 0.11219429 | J41: =SUM(F41:I41) -> 159.54514
B42: Q4 OL | C42: 159.17045 | D42: 167.67238 | F42: 147.11542 | G42: 0.45897778 | H42: 11.549487 | I42: -4.7069528 | J42: =SUM(F42:I42) -> 154.41693
B43: FY 23-24 | C43: 142.13371 | D43: 159.55763 | F43: 110.65614 | G43: 3.3340572 | H43: 41.042153 | I43: -0.46037038 | J43: =SUM(F43:I43) -> 154.57198

Sheet BR Slide Volume
B3: BIHAR Network Vol (MT)
C4: 21-22 | D4: 22-23 | E4: 23-24 | F4: 24-25 | G4: GOFY23 | H4: GOFY24
B5: Q1 | C5: {=TRANSPOSE(BIHAR!Q50:U50)/1000} -> 68.853737 | D5: {=TRANSPOSE(BIHAR!Q54:U54)/1000} -> 53.596667 | E5: {=TRANSPOSE(BIHAR!Q59:U59)/1000} -> 77.671396 | F5: {=TRANSPOSE(BIHAR!Q64:U64)/1000} -> 94.953511 | G5: =+(E5-D5)/D5 -> 0.44918333 | H5: =+(F5-E5)/E5 -> 0.22250295
B6: Q2 | C6: 51.136633 | D6: 73.824345 | E6: 97.55419 | F6: 101.18849 | G6: =+(E6-D6)/D6 -> 0.32143658 | H6: =+(F6-E6)/E6 -> 0.037254141
B7: Q3 | C7: 35.20158 | D7: 69.481634 | E7: 109.9413 | F7: 99.953328 | G7: =+(E7-D7)/D7 -> 0.58230733 | H7: =+(F7-E7)/E7 -> -0.090848223
B8: Q4 (OL) | C8: 60.999295 | D8: 87.775453 | E8: 139.82255 | F8: 147.11542 | G8: =+(E8-D8)/D8 -> 0.59295732 | H8: =+(F8-E8)/E8 -> 0.052158048
B9: Total | C9: 53.969157 | D9: 71.126678 | E9: 106.2427 | F9: 110.65614 | G9: =+(E9-D9)/D9 -> 0.49371097 | H9: =+(F9-E9)/E9 -> 0.041541071
B14: Sources | C14: 2019-20 | D14: 2020-21 | E14: 2021-22 | F14: 2022-23 | G14: 2023-24 | H14: 2024-25
B15: Own Network | C15: 78691 | D15: 56244 | E15: =BIHAR!U50 -> 53969.157 | F15: =BIHAR!U54 -> 71126.678 | G15: =BIHAR!U59 -> 106242.7 | H15: =BIHAR!U64 -> 110656.14
B16: Moo Mark | E16: =BIHAR!U51 -> 16078.224 | F16: =BIHAR!U55 -> 20981.02 | G16: =BIHAR!U60 -> 19164.621 | H16: =BIHAR!U65 -> 3334.0572
B17: Vendor | D17: 24567 | E17: =BIHAR!U52 -> 40276.87 | F17: =BIHAR!U56 -> 13372.743 | G17: =BIHAR!U61 -> 9652.8389 | H17: =BIHAR!U66 -> 41042.153
B18: Transfer | E18: 0 | F18: =BIHAR!U57 -> 32272.185 | G18: =BIHAR!U62 -> 7073.5547 | H18: =BIHAR!U67 -> -460.37038
B19: Avg Milk/Day @4% | C19: =SUM(C15:C18) -> 78691 | D19: =SUM(D15:D18) -> 80811 | E19: =SUM(E15:E18) -> 110324.25 | F19: =SUM(F15:F18) -> 137752.63 | G19: =SUM(G15:G18) -> 142133.71 | H19: =SUM(H15:H18) -> 154571.98
B22: OUTSIDE MILK IN BIHAR
B23: 2022-23 | C23: 2023-24 | D23: 2024-25
B24: 25% (34MT/day) | C24: 20% (29MT/day) | D24: 30% (48MT/day)
B25: =('BR Slide Volume'!F16+'BR Slide Volume'!F17)/'BR Slide Volume'!F19 -> 0.24938735 | C25: =('BR Slide Volume'!G16+'BR Slide Volume'!G17)/'BR Slide Volume'!G19 -> 0.20274894 | D25: =('BR Slide Volume'!H16+'BR Slide Volume'!H17)/'BR Slide Volume'!H19 -> 0.28709091
B26: =('BR Slide Volume'!F16+'BR Slide Volume'!F17)/1000 -> 34.353762 | C26: =('BR Slide Volume'!G16+'BR Slide Volume'!G17)/1000 -> 28.81746 | D26: =('BR Slide Volume'!H16+'BR Slide Volume'!H17)/1000 -> 44.37621
B30: Network Volume Growth
B31: Year | C31: 000"kg/day | D31: GOLY
B32: 21-22 | C32: =C5 -> 68.853737 | D32: =+(BIHAR!U50-BIHAR!U46)/BIHAR!U46 -> -0.040449158
B33: 22-23 | C33: =D5 -> 53.596667 | D33: =+(C33-C32)/C32 -> -0.22158667
B34: 23-24 | C34: =E5 -> 77.671396 | D34: =+(C34-C33)/C33 -> 0.44918333
B35: 24-25 | C35: =F5 -> 94.953511 | D35: =+(C35-C34)/C34 -> 0.22250295
B44: Pouring Farmers
B45: Year | C45: *000 Farmers | D45: GOLY
B46: 21-22 | C46: =+BIHAR!U26/1000 -> 7.8949945 | D46: =+(BIHAR!U26-BIHAR!U25)/BIHAR!U25 -> 0.084171668
B47: 22-23 | C47: =+BIHAR!U27/1000 -> 9.5779882 | D47: =+(C47-C46)/C46 -> 0.21317225
B48: 23-24 | C48: =+BIHAR!U28/1000 -> 6.4216202 | D48: =+(C48-C47)/C47 -> -0.32954394
B49: 23-24 | C49: =+BIHAR!U29/1000 -> 6.370137 | D49: =+(C49-C48)/C48 -> -0.0080171718

Sheet Consolidate
A1: Milk Procurement Historical Data- Overall
D2: 30 | E2: 31 | F2: 30 | G2: 31 | H2: 31 | I2: 30 | J2: 31 | K2: 30 | L2: 31 | M2: 31 | N2: 28 | O2: 31 | Q2: Quarterly | U2: =SUM(D2:O2) -> 365
D3: 30 | E3: 31 | F3: 30 | G3: 31 | H3: 31 | I3: 30 | J3: 31 | K3: 30 | L3: 31 | M3: 31 | N3: 29 | O3: 31 | Q3: Quarterly | U3: =SUM(D3:O3) -> 366
A4: Particulas | B4: UOM | C4: Months | D4: Apr | E4: May | F4: Jun | G4: Jul | H4: Aug | I4: Sep | J4: Oct | K4: Nov | L4: Dec | M4: Jan | N4: Feb | O4: Mar | Q4: Q1 | R4: Q2 | S4: Q3 | T4: Q4 | U4: FY
A5: No. of MPGs | B5: Nos | C5: FY 23-24 | D5: =BIHAR!D14+'WEST BENGAL'!D9+JHARKHAND!D4 -> 717 | E5: =BIHAR!E14+'WEST BENGAL'!E9+JHARKHAND!E4 -> 693 | F5: =BIHAR!F14+'WEST BENGAL'!F9+JHARKHAND!F4 -> 709 | G5: =BIHAR!G14+'WEST BENGAL'!G9+JHARKHAND!G4 -> 722 | H5: =BIHAR!H14+'WEST BENGAL'!H9+JHARKHAND!H4 -> 717 | I5: =BIHAR!I14+'WEST BENGAL'!I9+JHARKHAND!I4 -> 733 | J5: =BIHAR!J14+'WEST BENGAL'!J9+JHARKHAND!J4 -> 814 | K5: =BIHAR!K14+'WEST BENGAL'!K9+JHARKHAND!K4 -> 827 | ... O5: =BIHAR!O14+'WEST BENGAL'!O9+JHARKHAND!O4 -> 852 | P5: =MAX(D5:O5) -> 878 | Q5: =SUMPRODUCT(D5:F5,$D$2:$F$2)/SUM($D$2:$F$2) -> 706.18681 | R5: =SUMPRODUCT(G5:I5,$G$2:$I$2)/SUM($G$2:$I$2) -> 723.90217 | S5: =SUMPRODUCT(J5:L5,$J$2:$L$2)/SUM($J$2:$L$2) -> 828.68478 | T5: =SUMPRODUCT(M5:O5,$M$3:$O$3)/SUM($M$3:$O$3) -> 857.56044 | U5: =O5 -> 852
A6: No. of MPGs | B6: Nos | C6: FY 24-25 | D6: =BIHAR!D15+'WEST BENGAL'!D10+JHARKHAND!D5 -> 851 | E6: =BIHAR!E15+'WEST BENGAL'!E10+JHARKHAND!E5 -> 864 | F6: =BIHAR!F15+'WEST BENGAL'!F10+JHARKHAND!F5 -> 842 | G6: =BIHAR!G15+'WEST BENGAL'!G10+JHARKHAND!G5 -> 837 | H6: =BIHAR!H15+'WEST BENGAL'!H10+JHARKHAND!H5 -> 821 | I6: =BIHAR!I15+'WEST BENGAL'!I10+JHARKHAND!I5 -> 842 | J6: =BIHAR!J15+'WEST BENGAL'!J10+JHARKHAND!J5 -> 818 | K6: =BIHAR!K15+'WEST BENGAL'!K10+JHARKHAND!K5 -> 810 | ... O6: =BIHAR!O15+'WEST BENGAL'!O10+JHARKHAND!O5 -> 1038 | P6: =MAX(D6:O6) -> 1038 | Q6: =SUMPRODUCT(D6:F6,$D$2:$F$2)/SUM($D$2:$F$2) -> 852.46154 | R6: =SUMPRODUCT(G6:I6,$G$2:$I$2)/SUM($G$2:$I$2) -> 833.23913 | S6: =SUMPRODUCT(J6:L6,$J$2:$L$2)/SUM($J$2:$L$2) -> 829.88043 | T6: =SUMPRODUCT(M6:O6,$M$2:$O$2)/SUM($M$2:$O$2) -> 970.1 | U6: =O6 -> 1038
A7: No. of MPGs | B7: Nos | C7: FY 25-26 | D7: =BIHAR!D16+'WEST BENGAL'!D11+JHARKHAND!D6 -> 1075 | E7: =BIHAR!E16+'WEST BENGAL'!E11+JHARKHAND!E6 -> 1096 | F7: =BIHAR!F16+'WEST BENGAL'!F11+JHARKHAND!F6 -> 1107 | G7: =BIHAR!G16+'WEST BENGAL'!G11+JHARKHAND!G6 -> 1185 | H7: =BIHAR!H16+'WEST BENGAL'!H11+JHARKHAND!H6 -> 1241 | I7: =BIHAR!I16+'WEST BENGAL'!I11+JHARKHAND!I6 -> 1254 | J7: =BIHAR!J16+'WEST BENGAL'!J11+JHARKHAND!J6 -> 1260 | K7: =BIHAR!K16+'WEST BENGAL'!K11+JHARKHAND!K6 -> 1238 | ... O7: =BIHAR!O16+'WEST BENGAL'!O11+JHARKHAND!O6 -> 1464 | P7: =MAX(D7:O7) -> 1464 | Q7: =SUMPRODUCT(D7:F7,$D$2:$F$2)/SUM($D$2:$F$2) -> 1092.7033 | R7: =SUMPRODUCT(G7:I7,$G$2:$I$2)/SUM($G$2:$I$2) -> 1226.3696 | S7: =SUMPRODUCT(J7:L7,$J$2:$L$2)/SUM($J$2:$L$2) -> 1250.1304 | T7: =SUMPRODUCT(M7:O7,$M$2:$O$2)/SUM($M$2:$O$2) -> 1393.1444 | U7: =O7 -> 1464
A9: Own Network | B9: KG | C9: FY 23-24 | D9: =BIHAR!D59+'WEST BENGAL'!D38+JHARKHAND!D15 -> 159606.82 | E9: =BIHAR!E59+'WEST BENGAL'!E38+JHARKHAND!E15 -> 163904.2 | F9: =BIHAR!F59+'WEST BENGAL'!F38+JHARKHAND!F15 -> 172965.68 | G9: =BIHAR!G59+'WEST BENGAL'!G38+JHARKHAND!G15 -> 172933.75 | H9: =BIHAR!H59+'WEST BENGAL'!H38+JHARKHAND!H15 -> 152809.31 | I9: =BIHAR!I59+'WEST BENGAL'!I38+JHARKHAND!I15 -> 171757.59 | J9: =BIHAR!J59+'WEST BENGAL'!J38+JHARKHAND!J15 -> 179037.24 | K9: =BIHAR!K59+'WEST BENGAL'!K38+JHARKHAND!K15 -> 157367.23 | ... O9: =BIHAR!O59+'WEST BENGAL'!O38+JHARKHAND!O15 -> 205705.11 | Q9: =SUMPRODUCT(D9:F9,$D$2:$F$2)/SUM($D$2:$F$2) -> 165474.78 | R9: =SUMPRODUCT(G9:I9,$G$2:$I$2)/SUM($G$2:$I$2) -> 165769.16 | S9: =SUMPRODUCT(J9:L9,$J$2:$L$2)/SUM($J$2:$L$2) -> 174095.12 | T9: =SUMPRODUCT(M9:O9,$M$3:$O$3)/SUM($M$3:$O$3) -> 205917.69 | U9: =SUMPRODUCT(D9:O9,D$3:O$3)/SUM($D$3:$O$3)+9 -> 177780.12 | V9: =SUMPRODUCT(D9:I9,$D$3:$I$3)/SUM($D$3:$I$3) -> 165622.78
A10: Moo Mark | B10: KG | C10: FY 23-24 | D10: =BIHAR!D60+JHARKHAND!D16 -> 44467.283 | E10: =BIHAR!E60+JHARKHAND!E16 -> 38013.143 | F10: =BIHAR!F60+JHARKHAND!F16 -> 34917.698 | G10: =BIHAR!G60+JHARKHAND!G16 -> 22173.239 | H10: =BIHAR!H60+JHARKHAND!H16 -> 13835.113 | I10: =BIHAR!I60+JHARKHAND!I16 -> 23964.871 | J10: =BIHAR!J60+JHARKHAND!J16 -> 24633.355 | K10: =BIHAR!K60+JHARKHAND!K16 -> 22571.575 | ... O10: =BIHAR!O60+JHARKHAND!O16 -> 26217.621 | Q10: =SUMPRODUCT(D10:F10,$D$2:$F$2)/SUM($D$2:$F$2) -> 39120.405 | R10: =SUMPRODUCT(G10:I10,$G$2:$I$2)/SUM($G$2:$I$2) -> 19947.881 | S10: =SUMPRODUCT(J10:L10,$J$2:$L$2)/SUM($J$2:$L$2) -> 24445.094 | T10: =SUMPRODUCT(M10:O10,$M$3:$O$3)/SUM($M$3:$O$3) -> 24287.554 | U10: =SUMPRODUCT(D10:O10,D$3:O$3)/SUM($D$3:$O$3) -> 26924.256 | V10: =SUMPRODUCT(D10:I10,$D$3:$I$3)/SUM($D$3:$I$3) -> 29481.759
A11: Vendor | B11: KG | C11: FY 23-24 | D11: =BIHAR!D61+'WEST BENGAL'!D39+JHARKHAND!D17 -> 5063.1965 | E11: =BIHAR!E61+'WEST BENGAL'!E39+JHARKHAND!E17 -> 19366.883 | F11: =BIHAR!F61+'WEST BENGAL'!F39+JHARKHAND!F17 -> 0 | G11: =BIHAR!G61+'WEST BENGAL'!G39+JHARKHAND!G17 -> 0 | H11: =BIHAR!H61+'WEST BENGAL'!H39+JHARKHAND!H17 -> 9244.9395 | I11: =BIHAR!I61+'WEST BENGAL'!I39+JHARKHAND!I17 -> 8168.9708 | J11: =BIHAR!J61+'WEST BENGAL'!J39+JHARKHAND!J17 -> 6028.3266 | K11: =BIHAR!K61+'WEST BENGAL'!K39+JHARKHAND!K17 -> 25182.733 | ... O11: =BIHAR!O61+'WEST BENGAL'!O39+JHARKHAND!O17 -> 17368.069 | Q11: =SUMPRODUCT(D11:F11,$D$2:$F$2)/SUM($D$2:$F$2) -> 8266.6953 | R11: =SUMPRODUCT(G11:I11,$G$2:$I$2)/SUM($G$2:$I$2) -> 5778.9375 | S11: =SUMPRODUCT(J11:L11,$J$2:$L$2)/SUM($J$2:$L$2) -> 17445.743 | T11: =SUMPRODUCT(M11:O11,$M$3:$O$3)/SUM($M$3:$O$3) -> 19701.199 | U11: =SUMPRODUCT(D11:O11,D$3:O$3)/SUM($D$3:$O$3) -> 12791.664 | V11: =SUMPRODUCT(D11:I11,$D$3:$I$3)/SUM($D$3:$I$3) -> 7016.0192 | W11: =SUM(V10:V11) -> 36497.778
A12: Transfer | B12: KG | C12: FY 23-24 | D12: =BIHAR!D62+'WEST BENGAL'!D40+JHARKHAND!D18 -> -1.1368684e-13 | E12: =BIHAR!E62+'WEST BENGAL'!E40+JHARKHAND!E18 -> 2.1827873e-11 | F12: =BIHAR!F62+'WEST BENGAL'!F40+JHARKHAND!F18 -> -2.910383e-11 | G12: =BIHAR!G62+'WEST BENGAL'!G40+JHARKHAND!G18 -> 0 | H12: =BIHAR!H62+'WEST BENGAL'!H40+JHARKHAND!H18 -> 1.8189894e-12 | I12: =BIHAR!I62+'WEST BENGAL'!I40+JHARKHAND!I18 -> 0 | J12: =BIHAR!J62+'WEST BENGAL'!J40+JHARKHAND!J18 -> 0 | K12: =BIHAR!K62+'WEST BENGAL'!K40+JHARKHAND!K18 -> 0 | ... O12: =BIHAR!O62+'WEST BENGAL'!O40+JHARKHAND!O18 -> 0 | Q12: =SUMPRODUCT(D12:F12,$D$2:$F$2)/SUM($D$2:$F$2) -> -2.1962798e-12 | R12: =SUMPRODUCT(G12:I12,$G$2:$I$2)/SUM($G$2:$I$2) -> 6.1292034e-13 | S12: =SUMPRODUCT(J12:L12,$J$2:$L$2)/SUM($J$2:$L$2) -> 0 | T12: =SUMPRODUCT(M12:O12,$M$3:$O$3)/SUM($M$3:$O$3) -> 0 | U12: =SUMPRODUCT(D12:O12,D$3:O$3)/SUM($D$3:$O$3) -> -3.9200216e-13 | V12: =SUMPRODUCT(D12:I12,$D$3:$I$3)/SUM($D$3:$I$3) -> -7.8400431e-13
A13: Avg Milk/Day @4% | B13: KG | C13: FY 23-24 | D13: =SUM(D9:D12) -> 209137.3 | E13: =SUM(E9:E12) -> 221284.23 | F13: =SUM(F9:F12) -> 207883.38 | G13: =SUM(G9:G12) -> 195106.99 | H13: =SUM(H9:H12) -> 175889.36 | I13: =SUM(I9:I12) -> 203891.43 | J13: =SUM(J9:J12) -> 209698.92 | K13: =SUM(K9:K12) -> 205121.54 | ... O13: =SUM(O9:O12) -> 249290.8 | Q13: =SUMPRODUCT(D13:F13,$D$2:$F$2)/SUM($D$2:$F$2) -> 212861.88 | R13: =SUMPRODUCT(G13:I13,$G$2:$I$2)/SUM($G$2:$I$2) -> 191495.98 | S13: =SUMPRODUCT(J13:L13,$J$2:$L$2)/SUM($J$2:$L$2) -> 215985.96 | T13: =SUMPRODUCT(M13:O13,$M$3:$O$3)/SUM($M$3:$O$3) -> 249906.44 | U13: =SUMPRODUCT(D13:O13,D$3:O$3)/SUM($D$3:$O$3)+9 -> 217496.04 | V13: =SUMPRODUCT(D13:I13,$D$3:$I$3)/SUM($D$3:$I$3) -> 202120.55
A14: Own Network | B14: KG | C14: FY 24-25 | D14: =BIHAR!D64+'WEST BENGAL'!D42+JHARKHAND!D20 -> 166189.34 | E14: =BIHAR!E64+'WEST BENGAL'!E42+JHARKHAND!E20 -> 176072.69 | F14: =BIHAR!F64+'WEST BENGAL'!F42+JHARKHAND!F20 -> 171373.01 | G14: =BIHAR!G64+'WEST BENGAL'!G42+JHARKHAND!G20 -> 170587.54 | H14: =BIHAR!H64+'WEST BENGAL'!H42+JHARKHAND!H20 -> 154526.95 | I14: =BIHAR!I64+'WEST BENGAL'!I42+JHARKHAND!I20 -> 173352.11 | J14: =BIHAR!J64+'WEST BENGAL'!J42+JHARKHAND!J20 -> 160234.19 | K14: =BIHAR!K64+'WEST BENGAL'!K42+JHARKHAND!K20 -> 140828.89 | ... O14: =BIHAR!O64+'WEST BENGAL'!O42+JHARKHAND!O20 -> 203497.28 | Q14: =SUMPRODUCT(D14:F14,$D$2:$F$2)/SUM($D$2:$F$2) -> 171265.1 | R14: =SUMPRODUCT(G14:I14,$G$2:$I$2)/SUM($G$2:$I$2) -> 166077.31 | S14: =SUMPRODUCT(J14:L14,$J$2:$L$2)/SUM($J$2:$L$2) -> 158773.69 | T14: =SUMPRODUCT(M14:O14,$M$2:$O$2)/SUM($M$2:$O$2) -> 206938.85 | U14: =SUMPRODUCT(D14:O14,D$2:O$2)/SUM($D$2:$O$2)+9 -> 175614.24 | V14: =SUMPRODUCT(D14:I14,$D$2:$I$2)/SUM($D$2:$I$2) -> 168657.03
A15: Moo Mark | B15: KG | C15: FY 24-25 | D15: =BIHAR!D65+JHARKHAND!D21 -> 17483.704 | E15: =BIHAR!E65+JHARKHAND!E21 -> 9497.0202 | F15: =BIHAR!F65+JHARKHAND!F21 -> 6629.4625 | G15: =BIHAR!G65+JHARKHAND!G21 -> 9914.5948 | H15: =BIHAR!H65+JHARKHAND!H21 -> 8504.1956 | I15: =BIHAR!I65+JHARKHAND!I21 -> 18437.29 | J15: =BIHAR!J65+JHARKHAND!J21 -> 17470.823 | K15: =BIHAR!K65+JHARKHAND!K21 -> 12530.154 | ... O15: =BIHAR!O65+JHARKHAND!O21 -> 18197.323 | Q15: =SUMPRODUCT(D15:F15,$D$2:$F$2)/SUM($D$2:$F$2) -> 11184.644 | R15: =SUMPRODUCT(G15:I15,$G$2:$I$2)/SUM($G$2:$I$2) -> 12218.491 | S15: =SUMPRODUCT(J15:L15,$J$2:$L$2)/SUM($J$2:$L$2) -> 14768.11 | T15: =SUMPRODUCT(M15:O15,$M$2:$O$2)/SUM($M$2:$O$2) -> 18656.45 | U15: =SUMPRODUCT(D15:O15,D$2:O$2)/SUM($D$2:$O$2) -> 14190.823 | V15: =SUMPRODUCT(D15:I15,$D$2:$I$2)/SUM($D$2:$I$2) -> 11704.392
A16: Vendor | B16: KG | C16: FY 24-25 | D16: =BIHAR!D66+'WEST BENGAL'!D43+JHARKHAND!D22 -> 66174.279 | E16: =BIHAR!E66+'WEST BENGAL'!E43+JHARKHAND!E22 -> 53107.114 | F16: =BIHAR!F66+'WEST BENGAL'!F43+JHARKHAND!F22 -> 56589.874 | G16: =BIHAR!G66+'WEST BENGAL'!G43+JHARKHAND!G22 -> 55507.549 | H16: =BIHAR!H66+'WEST BENGAL'!H43+JHARKHAND!H22 -> 83820.342 | I16: =BIHAR!I66+'WEST BENGAL'!I43+JHARKHAND!I22 -> 54121.473 | J16: =BIHAR!J66+'WEST BENGAL'!J43+JHARKHAND!J22 -> 61280.42 | K16: =BIHAR!K66+'WEST BENGAL'!K43+JHARKHAND!K22 -> 116721.94 | ... O16: =BIHAR!O66+'WEST BENGAL'!O43+JHARKHAND!O22 -> 46927.335 | Q16: =SUMPRODUCT(D16:F16,$D$2:$F$2)/SUM($D$2:$F$2) -> 58563.133 | R16: =SUMPRODUCT(G16:I16,$G$2:$I$2)/SUM($G$2:$I$2) -> 64595.748 | S16: =SUMPRODUCT(J16:L16,$J$2:$L$2)/SUM($J$2:$L$2) -> 87274.698 | T16: =SUMPRODUCT(M16:O16,$M$2:$O$2)/SUM($M$2:$O$2) -> 48235.986 | U16: =SUMPRODUCT(D16:O16,D$2:O$2)/SUM($D$2:$O$2) -> 64774.15 | V16: =SUMPRODUCT(D16:I16,$D$2:$I$2)/SUM($D$2:$I$2) -> 61595.923 | W16: =V16+V15 -> 73300.315
A17: Transfer | B17: KG | C17: FY 24-25 | D17: =BIHAR!D67+'WEST BENGAL'!D44+'WEST BENGAL'!#REF!+JHARKHAND!D23 -> #REF! | E17: =BIHAR!E67+'WEST BENGAL'!E44+'WEST BENGAL'!#REF!+JHARKHAND!E23 -> #REF! | F17: =BIHAR!F67+'WEST BENGAL'!F44+'WEST BENGAL'!#REF!+JHARKHAND!F23 -> #REF! | G17: =BIHAR!G67+'WEST BENGAL'!G44+'WEST BENGAL'!#REF!+JHARKHAND!G23 -> #REF! | H17: =BIHAR!H67+'WEST BENGAL'!H44+'WEST BENGAL'!#REF!+JHARKHAND!H23 -> #REF! | I17: =BIHAR!I67+'WEST BENGAL'!I44+'WEST BENGAL'!#REF!+JHARKHAND!I23 -> #REF! | J17: =BIHAR!J67+'WEST BENGAL'!J44+'WEST BENGAL'!#REF!+JHARKHAND!J23 -> #REF! | K17: =BIHAR!K67+'WEST BENGAL'!K44+'WEST BENGAL'!#REF!+JHARKHAND!K23 -> #REF! | ... O17: =BIHAR!O67+'WEST BENGAL'!O44+'WEST BENGAL'!#REF!+JHARKHAND!O23 -> #REF! | Q17: =SUMPRODUCT(D17:F17,$D$2:$F$2)/SUM($D$2:$F$2) -> #REF! | R17: =SUMPRODUCT(G17:I17,$G$2:$I$2)/SUM($G$2:$I$2) -> #REF! | S17: =SUMPRODUCT(J17:L17,$J$2:$L$2)/SUM($J$2:$L$2) -> #REF! | T17: =SUMPRODUCT(M17:O17,$M$2:$O$2)/SUM($M$2:$O$2) -> #REF! | U17: =SUMPRODUCT(D17:O17,D$2:O$2)/SUM($D$2:$O$2) -> #REF! | V17: =SUMPRODUCT(D17:I17,$D$2:$I$2)/SUM($D$2:$I$2) -> #REF!
A18: Avg Milk/Day @4% | B18: KG | C18: FY 24-25 | D18: =SUM(D14:D17) -> #REF! | E18: =SUM(E14:E17) -> #REF! | F18: =SUM(F14:F17) -> #REF! | G18: =SUM(G14:G17) -> #REF! | H18: =SUM(H14:H17) -> #REF! | I18: =SUM(I14:I17) -> #REF! | J18: =SUM(J14:J17) -> #REF! | K18: =SUM(K14:K17) -> #REF! | ... O18: =SUM(O14:O17) -> #REF! | Q18: =SUMPRODUCT(D18:F18,$D$2:$F$2)/SUM($D$2:$F$2) -> #REF! | R18: =SUMPRODUCT(G18:I18,$G$2:$I$2)/SUM($G$2:$I$2) -> #REF! | S18: =SUMPRODUCT(J18:L18,$J$2:$L$2)/SUM($J$2:$L$2) -> #REF! | T18: =SUMPRODUCT(M18:O18,$M$2:$O$2)/SUM($M$2:$O$2) -> #REF! | U18: =SUMPRODUCT(D18:O18,D$2:O$2)/SUM($D$2:$O$2)+9 -> #REF! | V18: =SUMPRODUCT(D18:I18,$D$2:$I$2)/SUM($D$2:$I$2) -> #REF!
A19: Own Network | B19: KG | C19: FY 25-26 | D19: =BIHAR!D69+'WEST BENGAL'!D46+JHARKHAND!D25 -> 175408.74 | E19: =BIHAR!E69+'WEST BENGAL'!E46+JHARKHAND!E25 -> 192377.71 | F19: =BIHAR!F69+'WEST BENGAL'!F46+JHARKHAND!F25 -> 216244.66 | G19: =BIHAR!G69+'WEST BENGAL'!G46+JHARKHAND!G25 -> 230776.39 | H19: =BIHAR!H69+'WEST BENGAL'!H46+JHARKHAND!H25 -> 210409.23 | I19: =BIHAR!I69+'WEST BENGAL'!I46+JHARKHAND!I25 -> 219460.31 | J19: =BIHAR!J69+'WEST BENGAL'!J46+JHARKHAND!J25 -> 202010.17 | K19: =BIHAR!K69+'WEST BENGAL'!K46+JHARKHAND!K25 -> 196517.7 | ... O19: =BIHAR!O69+'WEST BENGAL'!O46+JHARKHAND!O25 -> 296431.23 | Q19: =SUMPRODUCT(D19:F19,$D$2:$F$2)/SUM($D$2:$F$2) -> 194651.77 | R19: =SUMPRODUCT(G19:I19,$G$2:$I$2)/SUM($G$2:$I$2) -> 220223.52 | S19: =SUMPRODUCT(J19:L19,$J$2:$L$2)/SUM($J$2:$L$2) -> 216273.84 | T19: =SUMPRODUCT(M19:O19,$M$2:$O$2)/SUM($M$2:$O$2) -> 278326.53 | U19: =SUMPRODUCT(D19:O19,D$2:O$2)/SUM($D$2:$O$2) -> 227179.33
A20: Moo Mark | B20: KG | C20: FY 25-26 | D20: =BIHAR!D70+JHARKHAND!D26 -> 16702.662 | E20: =BIHAR!E70+JHARKHAND!E26 -> 8841.0565 | F20: =BIHAR!F70+JHARKHAND!F26 -> 10478.258 | G20: =BIHAR!G70+JHARKHAND!G26 -> 9590.3105 | H20: =BIHAR!H70+JHARKHAND!H26 -> 10931.427 | I20: =BIHAR!I70+JHARKHAND!I26 -> 15192.413 | J20: =BIHAR!J70+JHARKHAND!J26 -> 21830.266 | K20: =BIHAR!K70+JHARKHAND!K26 -> 25080.375 | ... O20: =BIHAR!O70+JHARKHAND!O26 -> 33037.141 | Q20: =SUMPRODUCT(D20:F20,$D$2:$F$2)/SUM($D$2:$F$2) -> 11972.532 | R20: =SUMPRODUCT(G20:I20,$G$2:$I$2)/SUM($G$2:$I$2) -> 11868.981 | S20: =SUMPRODUCT(J20:L20,$J$2:$L$2)/SUM($J$2:$L$2) -> 24927.315 | T20: =SUMPRODUCT(M20:O20,$M$2:$O$2)/SUM($M$2:$O$2) -> 36133.789 | U20: =SUMPRODUCT(D20:O20,D$2:O$2)/SUM($D$2:$O$2) -> 21169.317
A21: Vendor | B21: KG | C21: FY 25-26 | D21: =BIHAR!D71+'WEST BENGAL'!D47+JHARKHAND!D27 -> 110264.15 | E21: =BIHAR!E71+'WEST BENGAL'!E47+JHARKHAND!E27 -> 136999.4 | F21: =BIHAR!F71+'WEST BENGAL'!F47+JHARKHAND!F27 -> 79832.755 | G21: =BIHAR!G71+'WEST BENGAL'!G47+JHARKHAND!G27 -> 60749.254 | H21: =BIHAR!H71+'WEST BENGAL'!H47+JHARKHAND!H27 -> 120094.59 | I21: =BIHAR!I71+'WEST BENGAL'!I47+JHARKHAND!I27 -> 106233.4 | J21: =BIHAR!J71+'WEST BENGAL'!J47+JHARKHAND!J27 -> 97864.39 | K21: =BIHAR!K71+'WEST BENGAL'!K47+JHARKHAND!K27 -> 101276.23 | ... O21: =BIHAR!O71+'WEST BENGAL'!O47+JHARKHAND!O27 -> 53445.056 | Q21: =SUMPRODUCT(D21:F21,$D$2:$F$2)/SUM($D$2:$F$2) -> 109339.43 | R21: =SUMPRODUCT(G21:I21,$G$2:$I$2)/SUM($G$2:$I$2) -> 95577.84 | S21: =SUMPRODUCT(J21:L21,$J$2:$L$2)/SUM($J$2:$L$2) -> 78871.597 | T21: =SUMPRODUCT(M21:O21,$M$2:$O$2)/SUM($M$2:$O$2) -> 51134.328 | U21: =SUMPRODUCT(D21:O21,D$2:O$2)/SUM($D$2:$O$2) -> 83839.25
A22: Transfer | B22: KG | C22: FY 25-26 | D22: =BIHAR!D72+'WEST BENGAL'!D48+'WEST BENGAL'!#REF!+JHARKHAND!D28 -> #REF! | E22: =BIHAR!E72+'WEST BENGAL'!E48+'WEST BENGAL'!#REF!+JHARKHAND!E28 -> #REF! | F22: =BIHAR!F72+'WEST BENGAL'!F48+'WEST BENGAL'!#REF!+JHARKHAND!F28 -> #REF! | G22: =BIHAR!G72+'WEST BENGAL'!G48+'WEST BENGAL'!#REF!+JHARKHAND!G28 -> #REF! | H22: =BIHAR!H72+'WEST BENGAL'!H48+'WEST BENGAL'!#REF!+JHARKHAND!H28 -> #REF! | I22: =BIHAR!I72+'WEST BENGAL'!I48+'WEST BENGAL'!#REF!+JHARKHAND!I28 -> #REF! | J22: =BIHAR!J72+'WEST BENGAL'!J48+'WEST BENGAL'!#REF!+JHARKHAND!J28 -> #REF! | K22: =BIHAR!K72+'WEST BENGAL'!K48+'WEST BENGAL'!#REF!+JHARKHAND!K28 -> #REF! | ... O22: =BIHAR!O72+'WEST BENGAL'!O48+'WEST BENGAL'!#REF!+JHARKHAND!O28 -> #REF! | Q22: =SUMPRODUCT(D22:F22,$D$2:$F$2)/SUM($D$2:$F$2) -> #REF! | R22: =SUMPRODUCT(G22:I22,$G$2:$I$2)/SUM($G$2:$I$2) -> #REF! | S22: =SUMPRODUCT(J22:L22,$J$2:$L$2)/SUM($J$2:$L$2) -> #REF! | T22: =SUMPRODUCT(M22:O22,$M$2:$O$2)/SUM($M$2:$O$2) -> #REF! | U22: =SUMPRODUCT(D22:O22,D$2:O$2)/SUM($D$2:$O$2) -> #REF!
A23: Avg Milk/Day @4% | B23: KG | C23: FY 25-26 | D23: =SUM(D19:D22) -> #REF! | E23: =SUM(E19:E22) -> #REF! | F23: =SUM(F19:F22) -> #REF! | G23: =SUM(G19:G22) -> #REF! | H23: =SUM(H19:H22) -> #REF! | I23: =SUM(I19:I22) -> #REF! | J23: =SUM(J19:J22) -> #REF! | K23: =SUM(K19:K22) -> #REF! | ... O23: =SUM(O19:O22) -> #REF! | Q23: =SUMPRODUCT(D23:F23,$D$2:$F$2)/SUM($D$2:$F$2) -> #REF! | R23: =SUMPRODUCT(G23:I23,$G$2:$I$2)/SUM($G$2:$I$2) -> #REF! | S23: =SUMPRODUCT(J23:L23,$J$2:$L$2)/SUM($J$2:$L$2) -> #REF! | T23: =SUMPRODUCT(M23:O23,$M$2:$O$2)/SUM($M$2:$O$2) -> #REF! | U23: =SUMPRODUCT(D23:O23,D$2:O$2)/SUM($D$2:$O$2) -> #REF!
A25: Supply chain Cost | B25: Rs/Kg | C25: FY 23-24 | D25: =(BIHAR!D59*BIHAR!D87+'WEST BENGAL'!D38*'WEST BENGAL'!D60+JHARKHAND!D15*JHARKHAND!D37)/Consolidate!D9 -> 3.0529488 | E25: =(BIHAR!E59*BIHAR!E87+'WEST BENGAL'!E38*'WEST BENGAL'!E60+JHARKHAND!E15*JHARKHAND!E37)/Consolidate!E9 -> 3.1859219 | F25: =(BIHAR!F59*BIHAR!F87+'WEST BENGAL'!F38*'WEST BENGAL'!F60+JHARKHAND!F15*JHARKHAND!F37)/Consolidate!F9 -> 3.093475 | G25: =(BIHAR!G59*BIHAR!G87+'WEST BENGAL'!G38*'WEST BENGAL'!G60+JHARKHAND!G15*JHARKHAND!G37)/Consolidate!G9 -> 3.1704964 | H25: =(BIHAR!H59*BIHAR!H87+'WEST BENGAL'!H38*'WEST BENGAL'!H60+JHARKHAND!H15*JHARKHAND!H37)/Consolidate!H9 -> 3.2370379 | I25: =(BIHAR!I59*BIHAR!I87+'WEST BENGAL'!I38*'WEST BENGAL'!I60+JHARKHAND!I15*JHARKHAND!I37)/Consolidate!I9 -> 3.2104731 | J25: =(BIHAR!J59*BIHAR!J87+'WEST BENGAL'!J38*'WEST BENGAL'!J60+JHARKHAND!J15*JHARKHAND!J37)/Consolidate!J9 -> 3.0744134 | K25: =(BIHAR!K59*BIHAR!K87+'WEST BENGAL'!K38*'WEST BENGAL'!K60+JHARKHAND!K15*JHARKHAND!K37)/Consolidate!K9 -> 2.9628136 | ... O25: =(BIHAR!O59*BIHAR!O87+'WEST BENGAL'!O38*'WEST BENGAL'!O60+JHARKHAND!O15*JHARKHAND!O37)/Consolidate!O9 -> 2.555034 | Q25: =SUMPRODUCT(D25:F25,D9:F9)/SUM(D9:F9) -> 3.1109666 | R25: =SUMPRODUCT(G25:I25,G9:I9)/SUM(G9:I9) -> 3.2047365 | S25: =SUMPRODUCT(J25:L25,J9:L9)/SUM(J9:L9) -> 2.9448557 | T25: =SUMPRODUCT(M25:O25,M9:O9)/SUM(M9:O9) -> 2.5548888 | U25: =SUMPRODUCT(D25:O25,D9:O9)/SUM(D9:O9) -> 2.9310789
A26: Supply chain Cost | B26: Rs/Kg | C26: FY 24-25 | D26: =(BIHAR!D64*BIHAR!D88+'WEST BENGAL'!D42*'WEST BENGAL'!D61+JHARKHAND!D20*JHARKHAND!D38)/Consolidate!D14 -> 3.0129284 | E26: =(BIHAR!E64*BIHAR!E88+'WEST BENGAL'!E42*'WEST BENGAL'!E61+JHARKHAND!E20*JHARKHAND!E38)/Consolidate!E14 -> 2.942535 | F26: =(BIHAR!F64*BIHAR!F88+'WEST BENGAL'!F42*'WEST BENGAL'!F61+JHARKHAND!F20*JHARKHAND!F38)/Consolidate!F14 -> 3.1648239 | G26: =(BIHAR!G64*BIHAR!G88+'WEST BENGAL'!G42*'WEST BENGAL'!G61+JHARKHAND!G20*JHARKHAND!G38)/Consolidate!G14 -> 2.9596152 | H26: =(BIHAR!H64*BIHAR!H88+'WEST BENGAL'!H42*'WEST BENGAL'!H61+JHARKHAND!H20*JHARKHAND!H38)/Consolidate!H14 -> 3.210469 | I26: =(BIHAR!I64*BIHAR!I88+'WEST BENGAL'!I42*'WEST BENGAL'!I61+JHARKHAND!I20*JHARKHAND!I38)/Consolidate!I14 -> 3.0213372 | J26: =(BIHAR!J64*BIHAR!J88+'WEST BENGAL'!J42*'WEST BENGAL'!J61+JHARKHAND!J20*JHARKHAND!J38)/Consolidate!J14 -> 3.052242 | K26: =(BIHAR!K64*BIHAR!K88+'WEST BENGAL'!K42*'WEST BENGAL'!K61+JHARKHAND!K20*JHARKHAND!K38)/Consolidate!K14 -> 3.1229431 | ... O26: =(BIHAR!O64*BIHAR!O88+'WEST BENGAL'!O42*'WEST BENGAL'!O61+JHARKHAND!O20*JHARKHAND!O38)/Consolidate!O14 -> 2.6364921 | Q26: =SUMPRODUCT(D26:F26,$D$14:$F$14)/SUM($D$14:$F$14) -> 3.0394773 | R26: =SUMPRODUCT(G26:I26,$G$14:$I$14)/SUM($G$14:$I$14) -> 3.0588461 | S26: =SUMPRODUCT(J26:L26,$J$14:$L$14)/SUM($J$14:$L$14) -> 2.9852958 | T26: =SUMPRODUCT(M26:O26,$M$14:$O$14)/SUM($M$14:$O$14) -> 2.6841698 | U26: =SUMPRODUCT(D26:O26,$D$14:$O$14)/SUM($D$14:$O$14) -> 2.9271026
A27: Supply chain Cost | B27: Rs/Kg | C27: FY 25-26 | D27: =(BIHAR!D69*BIHAR!D89+'WEST BENGAL'!D46*'WEST BENGAL'!D62+JHARKHAND!D29*JHARKHAND!D39)/Consolidate!D19 -> 3.4200312 | E27: =(BIHAR!E69*BIHAR!E89+'WEST BENGAL'!E46*'WEST BENGAL'!E62+JHARKHAND!E29*JHARKHAND!E39)/Consolidate!E19 -> 3.0950463 | F27: =(BIHAR!F69*BIHAR!F89+'WEST BENGAL'!F46*'WEST BENGAL'!F62+JHARKHAND!F29*JHARKHAND!F39)/Consolidate!F19 -> 3.129632 | G27: =(BIHAR!G69*BIHAR!G89+'WEST BENGAL'!G46*'WEST BENGAL'!G62+JHARKHAND!G29*JHARKHAND!G39)/Consolidate!G19 -> 3.1463961 | H27: =(BIHAR!H69*BIHAR!H89+'WEST BENGAL'!H46*'WEST BENGAL'!H62+JHARKHAND!H29*JHARKHAND!H39)/Consolidate!H19 -> 3.3553903 | I27: =(BIHAR!I69*BIHAR!I89+'WEST BENGAL'!I46*'WEST BENGAL'!I62+JHARKHAND!I29*JHARKHAND!I39)/Consolidate!I19 -> 3.4633218 | J27: =(BIHAR!J69*BIHAR!J89+'WEST BENGAL'!J46*'WEST BENGAL'!J62+JHARKHAND!J29*JHARKHAND!J39)/Consolidate!J19 -> 3.4500593 | K27: =(BIHAR!K69*BIHAR!K89+'WEST BENGAL'!K46*'WEST BENGAL'!K62+JHARKHAND!K29*JHARKHAND!K39)/Consolidate!K19 -> 3.4364832 | ... O27: =(BIHAR!O69*BIHAR!O89+'WEST BENGAL'!O46*'WEST BENGAL'!O62+JHARKHAND!O29*JHARKHAND!O39)/Consolidate!O19 -> 3.0026764 | Q27: =SUMPRODUCT(D27:F27,$D$14:$F$14)/SUM($D$14:$F$14) -> 3.2117363 | R27: =SUMPRODUCT(G27:I27,$G$14:$I$14)/SUM($G$14:$I$14) -> 3.3214028 | S27: =SUMPRODUCT(J27:L27,$J$14:$L$14)/SUM($J$14:$L$14) -> 3.3226259 | T27: =SUMPRODUCT(M27:O27,$M$14:$O$14)/SUM($M$14:$O$14) -> 3.0900145 | U27: =SUMPRODUCT(D27:O27,$D$14:$O$14)/SUM($D$14:$O$14) -> 3.2267734
A29: Network Milk @ 4% & 8.5%
A30: Landed Cost | B30: Rs/Kg | C30: =+C25 -> FY 23-24 | D30: 39.505867 | E30: 43.16434 | F30: 41.883471 | G30: 40.488292 | H30: 40.366275 | I30: 40.278411 | J30: 40.135896 | K30: 40.171526 | L30: 40.17219 | M30: 39.954948 | N30: 39.765445 | O30: 37.668034 | Q30: =SUMPRODUCT(D30:F30,D9:F9)/SUM(D9:F9) -> 41.541981 | R30: =SUMPRODUCT(G30:I30,G9:I9)/SUM(G9:I9) -> 40.378354 | S30: =SUMPRODUCT(J30:L30,J9:L9)/SUM(J9:L9) -> 40.159536 | T30: =SUMPRODUCT(M30:O30,M9:O9)/SUM(M9:O9) -> 39.127989 | U30: =SUMPRODUCT(D30:O30,D9:O9)/SUM(D9:O9) -> 40.233236
A31: Landed Cost | B31: Rs/Kg | C31: =+C26 -> FY 24-25 | D31: 40.390525 | E31: 40.288558 | F31: 40.110018 | G31: 40.388447 | H31: 40.268682 | I31: 40.179058 | J31: 40.200487 | K31: 40.098044 | L31: 40.129005 | M31: 39.67431 | N31: 39.622887 | O31: 39.608032 | Q31: =SUMPRODUCT(D31:F31,$D$14:$F$14)/SUM($D$14:$F$14) -> 40.261981 | R31: =SUMPRODUCT(G31:I31,$G$14:$I$14)/SUM($G$14:$I$14) -> 40.2785 | S31: =SUMPRODUCT(J31:L31,$J$14:$L$14)/SUM($J$14:$L$14) -> 40.143916 | T31: =SUMPRODUCT(M31:O31,$M$14:$O$14)/SUM($M$14:$O$14) -> 39.634604 | U31: =SUMPRODUCT(D31:O31,$D$14:$O$14)/SUM($D$14:$O$14) -> 40.05433
A32: Landed Cost | B32: Rs/Kg | C32: =+C27 -> FY 25-26 | D32: 39.668827 | E32: 39.581598 | F32: 41.247675 | G32: 41.185119 | H32: 39.699687 | I32: 41.636332 | J32: 41.51735 | K32: 41.151717 | L32: 41.064458 | M32: 41.04 | N32: 40.95 | O32: 41.03 | Q32: =SUMPRODUCT(D32:F32,$D$14:$F$14)/SUM($D$14:$F$14) -> 40.165704 | R32: =SUMPRODUCT(G32:I32,$G$14:$I$14)/SUM($G$14:$I$14) -> 40.881547 | S32: =SUMPRODUCT(J32:L32,$J$14:$L$14)/SUM($J$14:$L$14) -> 41.242826 | T32: =SUMPRODUCT(M32:O32,$M$14:$O$14)/SUM($M$14:$O$14) -> 41.005193 | U32: =SUMPRODUCT(D32:O32,$D$14:$O$14)/SUM($D$14:$O$14) -> 40.825182
A34: Overall Milk @ 4% & 8.5%
A35: Landed Cost | B35: Rs/Kg | C35: =+C30 -> FY 23-24 | D35: 40.821937 | E35: 43.813182 | F35: 42.466038 | G35: 41.045352 | H35: 40.735333 | I35: 40.474853 | J35: 40.436419 | K35: 40.487047 | L35: 40.050294 | M35: 39.761417 | N35: 39.730649 | O35: 37.573854 | Q35: =SUMPRODUCT(D35:F35,D13:F13)/SUM(D13:F13) -> 42.394378 | R35: =SUMPRODUCT(G35:I35,G13:I13)/SUM(G13:I13) -> 40.748166 | S35: =SUMPRODUCT(J35:L35,J13:L13)/SUM(J13:L13) -> 40.313659 | T35: =SUMPRODUCT(M35:O35,M13:O13)/SUM(M13:O13) -> 39.023801 | U35: =SUMPRODUCT(D35:O35,D13:O13)/SUM(D13:O13) -> 40.54762
A36: Landed Cost | B36: Rs/Kg | C36: =+C31 -> FY 24-25 | D36: 39.795941 | E36: 40.200718 | F36: 39.963435 | G36: 40.068535 | H36: 40.112316 | I36: 40.122147 | J36: 39.920105 | K36: 39.936021 | L36: 39.90973 | M36: 39.887151 | N36: 39.651687 | O36: 39.649927 | Q36: =SUMPRODUCT(D36:F36,$D$18:$F$18)/SUM($D$18:$F$18) -> #REF! | R36: =SUMPRODUCT(G36:I36,$G$18:$I$18)/SUM($G$18:$I$18) -> #REF! | S36: =SUMPRODUCT(J36:L36,$J$18:$L$18)/SUM($J$18:$L$18) -> #REF! | T36: =SUMPRODUCT(M36:O36,$M$18:$O$18)/SUM($M$18:$O$18) -> #REF! | U36: =SUMPRODUCT(D36:O36,$D$18:$O$18)/SUM($D$18:$O$18) -> #REF!
A37: Landed Cost | B37: Rs/Kg | C37: =+C32 -> FY 25-26 | D37: 41.24041 | E37: 42.052587 | F37: 42.100919 | G37: 41.899131 | H37: 42.377159 | I37: 44.355577 | J37: 44.62035 | K37: 44.15821 | L37: 42.115952 | M37: 42.220807 | N37: 41.367607 | O37: 41.638477 | Q37: =SUMPRODUCT(D37:F37,$D$18:$F$18)/SUM($D$18:$F$18) -> #REF! | R37: =SUMPRODUCT(G37:I37,$G$18:$I$18)/SUM($G$18:$I$18) -> #REF! | S37: =SUMPRODUCT(J37:L37,$J$18:$L$18)/SUM($J$18:$L$18) -> #REF! | T37: =SUMPRODUCT(M37:O37,$M$18:$O$18)/SUM($M$18:$O$18) -> #REF! | U37: =SUMPRODUCT(D37:O37,$D$18:$O$18)/SUM($D$18:$O$18) -> #REF!

Sheet BIHAR
A1: Milk Procurement Historical Data- BIHAR
D2: 30 | E2: 31 | F2: 30 | G2: 31 | H2: 31 | I2: 30 | J2: 31 | K2: 30 | L2: 31 | M2: 31 | N2: 28 | O2: 31 | Q2: Quarterly | U2: =SUM(D2:O2) -> 365
D3: 30 | E3: 31 | F3: 30 | G3: 31 | H3: 31 | I3: 30 | J3: 31 | K3: 30 | L3: 31 | M3: 31 | N3: 29 | O3: 31 | Q3: Quarterly | U3: =SUM(D3:O3) -> 366
A4: Particulas | B4: UOM | C4: Months | D4: Apr | E4: May | F4: Jun | G4: Jul | H4: Aug | I4: Sep | J4: Oct | K4: Nov | L4: Dec | M4: Jan | N4: Feb | O4: Mar | Q4: Q1 | R4: Q2 | S4: Q3 | T4: Q4 | U4: YTD
A5: No. of MPGs | B5: Nos | C5: FY 14-15 | D5: 196.2 | E5: 190.93548 | F5: 185.16667 | G5: 192.70968 | H5: 222.19355 | I5: 257.2 | J5: 244.70968 | K5: 270.06667 | L5: 276.74194 | M5: 246.89655 | N5: 253.71429 | O5: 226.7 | Q5: =SUMPRODUCT(D5:F5,$D$2:$F$2)/SUM($D$2:$F$2) -> 190.76923 | R5: =SUMPRODUCT(G5:I5,$G$2:$I$2)/SUM($G$2:$I$2) -> 223.67391 | S5: =SUMPRODUCT(J5:L5,$J$2:$L$2)/SUM($J$2:$L$2) -> 263.77174 | T5: =SUMPRODUCT(M5:O5,$M$2:$O$2)/SUM($M$2:$O$2) -> 242.06103 | U5: =SUMPRODUCT(D5:O5,$D$2:$O$2)/SUM($D$2:$O$2) -> 230.11094
A6: No. of MPGs | B6: Nos | C6: FY 15-16 | D6: 269 | E6: 243 | F6: 262 | G6: 268 | H6: 290 | I6: 263 | J6: 274 | K6: 276 | L6: 271 | M6: 265 | N6: 244 | O6: 239 | Q6: =SUMPRODUCT(D6:F6,$D$2:$F$2)/SUM($D$2:$F$2) -> 257.83516 | R6: =SUMPRODUCT(G6:I6,$G$2:$I$2)/SUM($G$2:$I$2) -> 273.78261 | S6: =SUMPRODUCT(J6:L6,$J$2:$L$2)/SUM($J$2:$L$2) -> 273.6413 | T6: =SUMPRODUCT(M6:O6,$M$2:$O$2)/SUM($M$2:$O$2) -> 249.51111 | U6: =SUMPRODUCT(D6:O6,$D$2:$O$2)/SUM($D$2:$O$2) -> 263.7863
A7: No. of MPGs | B7: Nos | C7: FY 16-17 | D7: 226 | E7: 257 | F7: 259 | G7: 291 | H7: 302 | I7: 292 | J7: 312 | K7: 309 | L7: 334 | M7: 335 | N7: 335 | O7: 355 | Q7: =SUMPRODUCT(D7:F7,$D$2:$F$2)/SUM($D$2:$F$2) -> 247.43956 | R7: =SUMPRODUCT(G7:I7,$G$2:$I$2)/SUM($G$2:$I$2) -> 295.03261 | S7: =SUMPRODUCT(J7:L7,$J$2:$L$2)/SUM($J$2:$L$2) -> 318.43478 | T7: =SUMPRODUCT(M7:O7,$M$2:$O$2)/SUM($M$2:$O$2) -> 341.88889 | U7: =SUMPRODUCT(D7:O7,$D$2:$O$2)/SUM($D$2:$O$2) -> 300.61918
A8: No. of MPGs | B8: Nos | C8: FY 17-18 | D8: 368 | E8: 357 | F8: 336 | G8: 375 | H8: 413 | I8: 419 | J8: 416 | K8: 416 | L8: 436 | M8: 428 | N8: 430 | O8: 440 | Q8: =SUMPRODUCT(D8:F8,$D$2:$F$2)/SUM($D$2:$F$2) -> 353.7033 | R8: =SUMPRODUCT(G8:I8,$G$2:$I$2)/SUM($G$2:$I$2) -> 402.15217 | S8: =SUMPRODUCT(J8:L8,$J$2:$L$2)/SUM($J$2:$L$2) -> 422.73913 | T8: =SUMPRODUCT(M8:O8,$M$2:$O$2)/SUM($M$2:$O$2) -> 432.75556 | U8: =SUMPRODUCT(D8:O8,$D$2:$O$2)/SUM($D$2:$O$2) -> 402.80822
A9: No. of MPGs | B9: Nos | C9: FY 18-19 | D9: 419 | E9: 388 | F9: 356 | G9: 354 | H9: 345 | I9: 330 | J9: 344 | K9: 360 | L9: 364 | M9: 357 | N9: 352 | O9: 349 | Q9: =SUMPRODUCT(D9:F9,$D$2:$F$2)/SUM($D$2:$F$2) -> 387.67033 | R9: =SUMPRODUCT(G9:I9,$G$2:$I$2)/SUM($G$2:$I$2) -> 343.1413 | S9: =SUMPRODUCT(J9:L9,$J$2:$L$2)/SUM($J$2:$L$2) -> 355.95652 | T9: =SUMPRODUCT(M9:O9,$M$2:$O$2)/SUM($M$2:$O$2) -> 352.68889 | U9: =SUMPRODUCT(D9:O9,$D$2:$O$2)/SUM($D$2:$O$2) -> 359.8274
A10: No. of MPGs | B10: Nos | C10: FY 19-20 | D10: 324 | E10: 312 | F10: 312 | G10: 316 | H10: 336 | I10: 347 | J10: 356 | K10: 369 | L10: 373 | M10: 376 | N10: 383 | O10: 460 | Q10: =SUMPRODUCT(D10:F10,$D$2:$F$2)/SUM($D$2:$F$2) -> 315.95604 | R10: =SUMPRODUCT(G10:I10,$G$2:$I$2)/SUM($G$2:$I$2) -> 332.84783 | S10: =SUMPRODUCT(J10:L10,$J$2:$L$2)/SUM($J$2:$L$2) -> 365.96739 | T10: =SUMPRODUCT(M10:O10,$M$2:$O$2)/SUM($M$2:$O$2) -> 407.11111 | U10: =SUMPRODUCT(D10:O10,$D$2:$O$2)/SUM($D$2:$O$2) -> 355.29589 | W10: No of MPGs
A11: No. of MPGs | B11: Nos | C11: FY 20-21 | D11: 489 | E11: 487 | F11: 431 | G11: 395 | H11: 407 | I11: 367 | J11: 405 | K11: 356 | L11: 398 | M11: 412 | N11: 407 | O11: 478 | P11: =MAX(D11:O11) -> 489 | Q11: =SUMPRODUCT(D11:F11,$D$2:$F$2)/SUM($D$2:$F$2) -> 469.1978 | R11: =SUMPRODUCT(G11:I11,$G$2:$I$2)/SUM($G$2:$I$2) -> 389.91304 | S11: =SUMPRODUCT(J11:L11,$J$2:$L$2)/SUM($J$2:$L$2) -> 386.66304 | T11: =SUMPRODUCT(M11:O11,$M$2:$O$2)/SUM($M$2:$O$2) -> 433.17778 | U11: =SUMPRODUCT(D11:O11,$D$2:$O$2)/SUM($D$2:$O$2) -> 419.52877 | W11: Year | X11: BR | Y11: WB | Z11: JH | AA11: Total
A12: No. of MPGs | B12: Nos | C12: FY 21-22 | D12: 474 | E12: 444 | F12: 445 | G12: 453 | H12: 444 | I12: 413 | J12: 394 | K12: 359 | L12: 388 | M12: 371 | N12: 355 | O12: 352 | P12: =MAX(D12:O12) -> 474 | Q12: =SUMPRODUCT(D12:F12,$D$2:$F$2)/SUM($D$2:$F$2) -> 454.21978 | R12: =SUMPRODUCT(G12:I12,$G$2:$I$2)/SUM($G$2:$I$2) -> 436.92391 | S12: =SUMPRODUCT(J12:L12,$J$2:$L$2)/SUM($J$2:$L$2) -> 380.56522 | T12: =SUMPRODUCT(M12:O12,$M$2:$O$2)/SUM($M$2:$O$2) -> 359.47778 | U12: =SUMPRODUCT(D12:O12,$D$2:$O$2)/SUM($D$2:$O$2) -> 407.93425 | W12: FY 20-21 | X12: 489 | Y12: ='WEST BENGAL'!V6 -> 137 | AA12: =SUM(X12:Z12) -> 626
A13: No. of MPGs | B13: Nos | C13: FY 22-23 | D13: 360 | E13: 346 | F13: 357 | G13: 374 | H13: 385 | I13: 372 | J13: 369 | K13: 360 | L13: 379 | M13: 385 | N13: 431 | O13: 528 | P13: =MAX(D13:O13) -> 528 | Q13: =SUMPRODUCT(D13:F13,$D$2:$F$2)/SUM($D$2:$F$2) -> 354.24176 | R13: =SUMPRODUCT(G13:I13,$G$2:$I$2)/SUM($G$2:$I$2) -> 377.05435 | S13: =SUMPRODUCT(J13:L13,$J$2:$L$2)/SUM($J$2:$L$2) -> 369.43478 | T13: =SUMPRODUCT(M13:O13,$M$2:$O$2)/SUM($M$2:$O$2) -> 448.56667 | U13: =O13 -> 528 | W13: FY 21-22 | X13: 474 | Y13: ='WEST BENGAL'!V7 -> 144 | AA13: =SUM(X13:Z13) -> 618
A14: No. of MPGs | B14: Nos | C14: FY 23-24 | D14: 548 | E14: 519 | F14: 538 | G14: 555 | H14: 554 | I14: 555 | J14: 628 | K14: 638 | L14: 655 | M14: 650 | N14: 681 | O14: 659 | P14: =MAX(D14:O14) -> 681 | Q14: =MAX(D14:F14) -> 548 | R14: =MAX(G14:I14) -> 555 | S14: =MAX(J14:L14) -> 655 | T14: =MAX(M14:O14) -> 681 | U14: =O14 -> 659 | W14: FY 22-23 | X14: 528 | Y14: ='WEST BENGAL'!V8 -> 164 | AA14: =SUM(X14:Z14) -> 692
A15: No. of MPGs | B15: Nos | C15: FY 24-25 | D15: 656 | E15: 665 | F15: 646 | G15: 644 | H15: 633 | I15: 639 | J15: 617 | K15: 604 | L15: 653 | M15: 684 | N15: 732 | O15: 784 | P15: =MAX(D15:O15) -> 784 | Q15: =MAX(D15:F15) -> 665 | R15: =MAX(G15:I15) -> 644 | S15: =MAX(J15:L15) -> 653 | T15: =MAX(M15:O15) -> 784 | U15: =O15 -> 784 | W15: FY 23-24 | X15: 681 | Y15: ='WEST BENGAL'!V9 -> 174 | Z15: =JHARKHAND!O4 -> 39 | AA15: =SUM(X15:Z15) -> 894
A16: No. of MPGs | B16: Nos | C16: FY 25-26 | D16: 805 | E16: 800 | F16: 812 | G16: 867 | H16: 897 | I16: 897 | J16: 905 | K16: 883 | L16: 893 | M16: 928 | N16: =M16+120 -> 1048 | O16: 1087 | P16: =MAX(D16:O16) -> 1087 | Q16: =MAX(D16:F16) -> 812 | R16: =MAX(G16:I16) -> 897 | S16: =MAX(J16:L16) -> 905 | T16: =MAX(M16:O16) -> 1087 | U16: =O16 -> 1087 | W16: FY 24-25 | X16: 784 | Y16: ='WEST BENGAL'!V10 -> 151 | Z16: =JHARKHAND!O5 -> 103 | AA16: =SUM(X16:Z16) -> 1038
A17: No. of MPGs | B17: Nos | C17: FY 26-27 | D17: 1073 | E17: 1042 | F17: 1046 | P17: =MAX(D17:O17) -> 1073 | Q17: =MAX(D17:F17) -> 1073 | R17: =MAX(G17:I17) -> 0 | S17: =MAX(J17:L17) -> 0 | T17: =MAX(M17:O17) -> 0 | U17: =O17 -> 0 | W17: FY 25-26 | X17: 1087 | Y17: ='WEST BENGAL'!V11 -> 232 | Z17: =JHARKHAND!O6 -> 145 | AA17: =SUM(X17:Z17) -> 1464
W18: FY 26-27
A19: Farmers | B19: Nos | C19: FY 14-15 | D19: 3901.3667 | E19: 3261.0323 | F19: 3352.3667 | G19: 3603.8065 | H19: 3729.7097 | I19: 3648.6 | J19: 3136.5161 | K19: 3520.0667 | L19: 3799 | M19: 3147.8621 | N19: 3668.3214 | O19: 3355 | Q19: =SUMPRODUCT(D19:F19,$D$2:$F$2)/SUM($D$2:$F$2) -> 3502.2418 | R19: =SUMPRODUCT(G19:I19,$G$2:$I$2)/SUM($G$2:$I$2) -> 3660.837 | S19: =SUMPRODUCT(J19:L19,$J$2:$L$2)/SUM($J$2:$L$2) -> 3484.8152 | T19: =SUMPRODUCT(M19:O19,$M$2:$O$2)/SUM($M$2:$O$2) -> 3381.1303 | U19: =SUMPRODUCT(D19:O19,$D$2:$O$2)/SUM($D$2:$O$2) -> 3507.9609
A20: Farmers | B20: Nos | C20: FY 15-16 | D20: 4522 | E20: 3969 | F20: 4069 | G20: 4448 | H20: 4707 | I20: 3729 | J20: 3559 | K20: 3483 | L20: 3388 | M20: 3899 | N20: 3849 | O20: 3692 | Q20: =SUMPRODUCT(D20:F20,$D$2:$F$2)/SUM($D$2:$F$2) -> 4184.2747 | R20: =SUMPRODUCT(G20:I20,$G$2:$I$2)/SUM($G$2:$I$2) -> 4300.8152 | S20: =SUMPRODUCT(J20:L20,$J$2:$L$2)/SUM($J$2:$L$2) -> 3476.5978 | T20: =SUMPRODUCT(M20:O20,$M$2:$O$2)/SUM($M$2:$O$2) -> 3812.1444 | U20: =SUMPRODUCT(D20:O20,$D$2:$O$2)/SUM($D$2:$O$2) -> 3943.5178
A21: Farmers | B21: Nos | C21: FY 16-17 | D21: 3314 | E21: 3172 | F21: 3184 | G21: 3938 | H21: 4024 | I21: 3762 | J21: 3794 | K21: 3602 | L21: 3999 | M21: 5589 | N21: 6014.6096 | O21: 6343 | Q21: =SUMPRODUCT(D21:F21,$D$2:$F$2)/SUM($D$2:$F$2) -> 3222.7692 | R21: =SUMPRODUCT(G21:I21,$G$2:$I$2)/SUM($G$2:$I$2) -> 3909.587 | S21: =SUMPRODUCT(J21:L21,$J$2:$L$2)/SUM($J$2:$L$2) -> 3800.4674 | T21: =SUMPRODUCT(M21:O21,$M$2:$O$2)/SUM($M$2:$O$2) -> 5981.123 | U21: =SUMPRODUCT(D21:O21,$D$2:$O$2)/SUM($D$2:$O$2) -> 4221.6385
A22: Farmers | B22: Nos | C22: FY 17-18 | D22: 6318 | E22: 6738 | F22: 6208 | G22: 6968 | H22: 7930 | I22: 7973 | J22: 7652 | K22: 6691 | L22: 8015 | M22: 8657 | N22: 10316 | O22: 11222 | Q22: =SUMPRODUCT(D22:F22,$D$2:$F$2)/SUM($D$2:$F$2) -> 6424.8132 | R22: =SUMPRODUCT(G22:I22,$G$2:$I$2)/SUM($G$2:$I$2) -> 7619.8696 | S22: =SUMPRODUCT(J22:L22,$J$2:$L$2)/SUM($J$2:$L$2) -> 7460.9457 | T22: =SUMPRODUCT(M22:O22,$M$2:$O$2)/SUM($M$2:$O$2) -> 10056.633 | U22: =SUMPRODUCT(D22:O22,$D$2:$O$2)/SUM($D$2:$O$2) -> 7882.7123
A23: Farmers | B23: Nos | C23: FY 18-19 | D23: 10764 | E23: 9650 | F23: 9257 | G23: 10915 | H23: 8860 | I23: 9599 | J23: 10216 | K23: 10500 | L23: =+L42/6.8 -> 16161.022 | M23: =+M42/7 -> 16711.962 | N23: =+N42/7 -> 20009.535 | O23: =+O42/7.2 -> 17875.674 | Q23: =SUMPRODUCT(D23:F23,$D$2:$F$2)/SUM($D$2:$F$2) -> 9887.6923 | R23: =SUMPRODUCT(G23:I23,$G$2:$I$2)/SUM($G$2:$I$2) -> 9793.4239 | S23: =SUMPRODUCT(J23:L23,$J$2:$L$2)/SUM($J$2:$L$2) -> 12311.823 | T23: =SUMPRODUCT(M23:O23,$M$2:$O$2)/SUM($M$2:$O$2) -> 18138.708 | U23: =SUMPRODUCT(D23:O23,$D$2:$O$2)/SUM($D$2:$O$2) -> 12509.442
A24: Farmers | B24: Nos | C24: FY 19-20 | D24: =+D45/7 -> 15162.67 | E24: =+E45/7.3 -> 9694.7105 | F24: =+F45/6.7 -> 8729.3358 | G24: =+G45/5.9 -> 11287.542 | H24: =+H45/7 -> 11392.751 | I24: =+I45/7.2 -> 11512.26 | J24: =+J45/7 -> 9830.9257 | K24: 8730 | L24: 9028 | M24: 11214 | N24: 8456 | O24: 10541 | Q24: =SUMPRODUCT(D24:F24,$D$2:$F$2)/SUM($D$2:$F$2) -> 11179.079 | R24: =SUMPRODUCT(G24:I24,$G$2:$I$2)/SUM($G$2:$I$2) -> 11396.271 | S24: =SUMPRODUCT(J24:L24,$J$2:$L$2)/SUM($J$2:$L$2) -> 9201.3771 | T24: =SUMPRODUCT(M24:O24,$M$2:$O$2)/SUM($M$2:$O$2) -> 10124.144 | U24: =SUMPRODUCT(D24:O24,$D$2:$O$2)/SUM($D$2:$O$2) -> 10475.213
A25: Farmers | B25: Nos | C25: FY 20-21 | D25: 11658 | E25: 10615 | F25: 9536 | G25: 7106 | H25: 5274 | I25: 5578 | J25: 5379 | K25: 2916 | L25: 2916 | M25: 6078 | N25: 8949 | O25: 11559 | P25: =MAX(D25:O25) -> 11658 | Q25: =SUMPRODUCT(D25:F25,$D$2:$F$2)/SUM($D$2:$F$2) -> 10603.132 | R25: =SUMPRODUCT(G25:I25,$G$2:$I$2)/SUM($G$2:$I$2) -> 5990.4348 | S25: =SUMPRODUCT(J25:L25,$J$2:$L$2)/SUM($J$2:$L$2) -> 3745.9239 | T25: =SUMPRODUCT(M25:O25,$M$2:$O$2)/SUM($M$2:$O$2) -> 8859.1 | U25: =SUMPRODUCT(D25:O25,$D$2:$O$2)/SUM($D$2:$O$2) -> 7282.0521
A26: Farmers | B26: Nos | C26: FY 21-22 | D26: 8814 | E26: 6689 | F26: 9876 | G26: 9004 | H26: 6902 | I26: 7457 | J26: 5036 | K26: 5423 | L26: 7834 | M26: 8932 | N26: 9852 | O26: 9110 | P26: =MAX(D26:O26) -> 9876 | Q26: =SUMPRODUCT(D26:F26,$D$2:$F$2)/SUM($D$2:$F$2) -> 8440.2088 | R26: =SUMPRODUCT(G26:I26,$G$2:$I$2)/SUM($G$2:$I$2) -> 7791.2609 | S26: =SUMPRODUCT(J26:L26,$J$2:$L$2)/SUM($J$2:$L$2) -> 6105 | T26: =SUMPRODUCT(M26:O26,$M$2:$O$2)/SUM($M$2:$O$2) -> 9279.5333 | U26: =SUMPRODUCT(D26:O26,$D$2:$O$2)/SUM($D$2:$O$2) -> 7894.9945
A27: Farmers | B27: Nos | C27: =+C13 -> FY 22-23 | D27: 9116 | E27: 7045 | F27: 9979 | G27: 10214.368 | H27: 10164.185 | I27: 10082 | J27: 9530.5726 | K27: 9184.6789 | L27: 10431.181 | M27: 9151.8605 | N27: 10517.934 | O27: 9611.6454 | P27: =MAX(D27:O27) -> 10517.934 | Q27: =SUMPRODUCT(D27:F27,$D$2:$F$2)/SUM($D$2:$F$2) -> 8695 | R27: =SUMPRODUCT(G27:I27,$G$2:$I$2)/SUM($G$2:$I$2) -> 10154.295 | S27: =SUMPRODUCT(J27:L27,$J$2:$L$2)/SUM($J$2:$L$2) -> 9721.2472 | T27: =SUMPRODUCT(M27:O27,$M$2:$O$2)/SUM($M$2:$O$2) -> 9735.2315 | U27: =SUMPRODUCT(D27:O27,$D$2:$O$2)/SUM($D$2:$O$2) -> 9577.9882
A28: Farmers | B28: Nos | C28: =+C14 -> FY 23-24 | D28: 4785 | E28: 4810 | F28: 4769 | G28: 5187 | H28: 5292 | I28: 5241 | J28: 5523 | K28: 5496 | L28: 5651 | M28: 5918 | N28: 11267 | O28: 13259 | P28: =MAX(D28:O28) -> 13259 | Q28: =SUMPRODUCT(D28:F28,$D$2:$F$2)/SUM($D$2:$F$2) -> 4788.2418 | R28: =SUMPRODUCT(G28:I28,$G$2:$I$2)/SUM($G$2:$I$2) -> 5239.9891 | S28: =SUMPRODUCT(J28:L28,$J$2:$L$2)/SUM($J$2:$L$2) -> 5557.3261 | T28: =SUMPRODUCT(M28:O28,$M$3:$O$3)/SUM($M$3:$O$3) -> 10123.407 | U28: =SUMPRODUCT(D28:O28,$D$3:$O$3)/SUM($D$3:$O$3) -> 6421.6202
A29: Farmers | B29: Nos | C29: =C15 -> FY 24-25 | D29: 7611 | E29: 6577 | F29: 6103 | G29: 6234 | H29: 5847 | I29: 6038 | J29: 5850 | K29: 5559 | L29: 6012 | M29: 6685 | N29: 7040 | O29: 6945 | P29: =MAX(D29:O29) -> 7611 | Q29: =SUMPRODUCT(D29:F29,$D$2:$F$2)/SUM($D$2:$F$2) -> 6761.6154 | R29: =SUMPRODUCT(G29:I29,$G$2:$I$2)/SUM($G$2:$I$2) -> 6039.6848 | S29: =SUMPRODUCT(J29:L29,$J$2:$L$2)/SUM($J$2:$L$2) -> 5809.6957 | T29: =SUMPRODUCT(M29:O29,$M$2:$O$2)/SUM($M$2:$O$2) -> 6885 | U29: =SUMPRODUCT(D29:O29,$D$2:$O$2)/SUM($D$2:$O$2) -> 6370.137
A30: Farmers | B30: Nos | C30: =C16 -> FY 25-26 | D30: 6568 | E30: 6083 | F30: 6478 | G30: 6633 | H30: 6704 | I30: 6552 | J30: 6008 | K30: 5877 | L30: 6362 | M30: 6378 | N30: 6759 | O30: 7148 | P30: =MAX(D30:O30) -> 7148 | Q30: =SUMPRODUCT(D30:F30,$D$2:$F$2)/SUM($D$2:$F$2) -> 6373.1099 | R30: =SUMPRODUCT(G30:I30,$G$2:$I$2)/SUM($G$2:$I$2) -> 6630.5109 | S30: =SUMPRODUCT(J30:L30,$J$2:$L$2)/SUM($J$2:$L$2) -> 6084.5652 | T30: =SUMPRODUCT(M30:O30,$M$2:$O$2)/SUM($M$2:$O$2) -> 6761.7556 | U30: =SUMPRODUCT(D30:O30,$D$2:$O$2)/SUM($D$2:$O$2) -> 6461.0904
A31: Farmers | B31: Nos | C31: =C17 -> FY 26-27 | D31: 6486 | E31: 6190 | F31: 7055 | P31: =MAX(D31:O31) -> 7055 | Q31: =SUMPRODUCT(D31:F31,$D$2:$F$2)/SUM($D$2:$F$2) -> 6572.7473 | R31: =SUMPRODUCT(G31:I31,$G$2:$I$2)/SUM($G$2:$I$2) -> 0 | S31: =SUMPRODUCT(J31:L31,$J$2:$L$2)/SUM($J$2:$L$2) -> 0 | T31: =SUMPRODUCT(M31:O31,$M$2:$O$2)/SUM($M$2:$O$2) -> 0 | U31: =SUMPRODUCT(D31:O31,$D$2:$O$2)/SUM($D$2:$O$2) -> 1638.6849
A33: Particulas | B33: UOM | C33: Months | D33: Apr | E33: May | F33: Jun | G33: Jul | H33: Aug | I33: Sep | J33: Oct | K33: Nov | L33: Dec | M33: Jan | N33: Feb | O33: Mar | Q33: Q1 | R33: Q2 | S33: Q3 | T33: Q4 | U33: YTD
A34: Own Network | B34: KG | C34: FY 14-15 | D34: 27523.337 | E34: 19529.787 | F34: 21279.55 | G34: 23337.6 | H34: 24493.671 | I34: 22991.327 | J34: 21279.339 | K34: 26886.832 | L34: 36137.999 | M34: 36482.189 | N34: 44226.084 | O34: 36454.152 | Q34: =SUMPRODUCT(D34:F34,$D$2:$F$2)/SUM($D$2:$F$2) -> 22741.868 | R34: =SUMPRODUCT(G34:I34,$G$2:$I$2)/SUM($G$2:$I$2) -> 23614.23 | S34: =SUMPRODUCT(J34:L34,$J$2:$L$2)/SUM($J$2:$L$2) -> 28114.591 | T34: =SUMPRODUCT(M34:O34,$M$2:$O$2)/SUM($M$2:$O$2) -> 38881.744 | U34: =SUMPRODUCT(D34:O34,$D$2:$O$2)/SUM($D$2:$O$2) -> 28295.667 | V34: =S34/Q34 -> 1.2362481 | W34: =R34/Q34 -> 1.0383593 | X34: =S34/R34 -> 1.1905783 | Y34: =T34/Q34 -> 1.7096988
A35: Avg Milk/Day @4% | B35: KG | C35: FY 14-15 | D35: 27523.337 | E35: 19529.787 | F35: 21279.55 | G35: 23337.6 | H35: 24493.671 | I35: 22991.327 | J35: 21279.339 | K35: 26886.832 | L35: 36137.999 | M35: 36482.189 | N35: 44226.084 | O35: 36454.152 | Q35: =SUMPRODUCT(D35:F35,$D$2:$F$2)/SUM($D$2:$F$2) -> 22741.868 | R35: =SUMPRODUCT(G35:I35,$G$2:$I$2)/SUM($G$2:$I$2) -> 23614.23 | S35: =SUMPRODUCT(J35:L35,$J$2:$L$2)/SUM($J$2:$L$2) -> 28114.591 | T35: =SUMPRODUCT(M35:O35,$M$2:$O$2)/SUM($M$2:$O$2) -> 38881.744 | U35: =SUMPRODUCT(D35:O35,$D$2:$O$2)/SUM($D$2:$O$2) -> 28295.667 | V35: =S35/Q35 -> 1.2362481 | W35: =R35/Q35 -> 1.0383593 | X35: =S35/R35 -> 1.1905783 | Y35: =T35/Q35 -> 1.7096988
A36: Own Network | B36: KG | C36: FY 15-16 | D36: 28376.167 | E36: 19995.942 | F36: 21898.075 | G36: 30228.653 | H36: 25438.456 | I36: 29278.399 | J36: 28639.441 | K36: 23539.3 | L36: 28268.191 | M36: 32102 | N36: 34487 | O36: 31243.602 | Q36: =SUMPRODUCT(D36:F36,$D$2:$F$2)/SUM($D$2:$F$2) -> 23385.73 | R36: =SUMPRODUCT(G36:I36,$G$2:$I$2)/SUM($G$2:$I$2) -> 28304.699 | S36: =SUMPRODUCT(J36:L36,$J$2:$L$2)/SUM($J$2:$L$2) -> 26851.256 | T36: =SUMPRODUCT(M36:O36,$M$2:$O$2)/SUM($M$2:$O$2) -> 32548.33 | U36: =SUMPRODUCT(D36:O36,$D$2:$O$2)/SUM($D$2:$O$2) -> 27758.353 | V36: =S36/Q36 -> 1.1481898 | W36: =R36/Q36 -> 1.2103406 | X36: =S36/R36 -> 0.94865012 | Y36: =T36/Q36 -> 1.391803
A37: Avg Milk/Day @4% | B37: KG | C37: FY 15-16 | D37: 28376.167 | E37: 19995.942 | F37: 21898.075 | G37: 30228.653 | H37: 25438.456 | I37: 29278.399 | J37: 28639.441 | K37: 23539.3 | L37: 28268.191 | M37: 32102 | N37: 34487 | O37: 31243.602 | Q37: =SUMPRODUCT(D37:F37,$D$2:$F$2)/SUM($D$2:$F$2) -> 23385.73 | R37: =SUMPRODUCT(G37:I37,$G$2:$I$2)/SUM($G$2:$I$2) -> 28304.699 | S37: =SUMPRODUCT(J37:L37,$J$2:$L$2)/SUM($J$2:$L$2) -> 26851.256 | T37: =SUMPRODUCT(M37:O37,$M$2:$O$2)/SUM($M$2:$O$2) -> 32548.33 | U37: =SUMPRODUCT(D37:O37,$D$2:$O$2)/SUM($D$2:$O$2) -> 27758.353 | V37: =S37/Q37 -> 1.1481898 | W37: =R37/Q37 -> 1.2103406 | X37: =S37/R37 -> 0.94865012 | Y37: =T37/Q37 -> 1.391803
A38: Own Network | B38: KG | C38: FY 16-17 | D38: 19667.127 | E38: 20038 | F38: 19100 | G38: 24313 | H38: 30251 | I38: 24912 | J38: 22918 | K38: 22726 | L38: 29284 | M38: 36401 | N38: 47756 | O38: 56938.586 | Q38: =SUMPRODUCT(D38:F38,$D$2:$F$2)/SUM($D$2:$F$2) -> 19606.503 | R38: =SUMPRODUCT(G38:I38,$G$2:$I$2)/SUM($G$2:$I$2) -> 26509.174 | S38: =SUMPRODUCT(J38:L38,$J$2:$L$2)/SUM($J$2:$L$2) -> 25000.457 | T38: =SUMPRODUCT(M38:O38,$M$2:$O$2)/SUM($M$2:$O$2) -> 47007.724 | U38: =SUMPRODUCT(D38:O38,$D$2:$O$2)/SUM($D$2:$O$2) -> 29462.392 | V38: =S38/Q38 -> 1.2751104 | W38: =R38/Q38 -> 1.3520603 | X38: =S38/R38 -> 0.94308697 | Y38: =T38/Q38 -> 2.3975578
A39: Avg Milk/Day @4% | B39: KG | C39: FY 16-17 | D39: 19667.127 | E39: 20038 | F39: 19100 | G39: 24313 | H39: 30251 | I39: 24912 | J39: 22918 | K39: 22726 | L39: 29284 | M39: 36401 | N39: 47756 | O39: 56938.586 | Q39: =SUMPRODUCT(D39:F39,$D$2:$F$2)/SUM($D$2:$F$2) -> 19606.503 | R39: =SUMPRODUCT(G39:I39,$G$2:$I$2)/SUM($G$2:$I$2) -> 26509.174 | S39: =SUMPRODUCT(J39:L39,$J$2:$L$2)/SUM($J$2:$L$2) -> 25000.457 | T39: =SUMPRODUCT(M39:O39,$M$2:$O$2)/SUM($M$2:$O$2) -> 47007.724 | U39: =SUMPRODUCT(D39:O39,$D$2:$O$2)/SUM($D$2:$O$2) -> 29462.392 | V39: =S39/Q39 -> 1.2751104 | W39: =R39/Q39 -> 1.3520603 | X39: =S39/R39 -> 0.94308697 | Y39: =T39/Q39 -> 2.3975578
A40: Own Network | B40: KG | C40: FY 17-18 | D40: 48457 | E40: 40866 | F40: 47102 | G40: 54007 | H40: 55935 | I40: 45109 | J40: 50462.567 | K40: 47188 | L40: 77510 | M40: 79145 | N40: 105888 | O40: 109209 | Q40: =SUMPRODUCT(D40:F40,$D$2:$F$2)/SUM($D$2:$F$2) -> 45424.352 | R40: =SUMPRODUCT(G40:I40,$G$2:$I$2)/SUM($G$2:$I$2) -> 51755.13 | S40: =SUMPRODUCT(J40:L40,$J$2:$L$2)/SUM($J$2:$L$2) -> 58508.582 | T40: =SUMPRODUCT(M40:O40,$M$2:$O$2)/SUM($M$2:$O$2) -> 97820.422 | U40: =SUMPRODUCT(D40:O40,$D$2:$O$2)/SUM($D$2:$O$2) -> 63237.577 | V40: =S40/Q40 -> 1.2880444 | W40: =R40/Q40 -> 1.1393697 | X40: =S40/R40 -> 1.1304885 | Y40: =T40/Q40 -> 2.1534798
A41: Avg Milk/Day @4% | B41: KG | C41: FY 17-18 | D41: 48457 | E41: 40866 | F41: 47102 | G41: 54007 | H41: 55935 | I41: 45109 | J41: 50462.567 | K41: 47188 | L41: 77510 | M41: 79145 | N41: 105888 | O41: 109209 | Q41: =SUMPRODUCT(D41:F41,$D$2:$F$2)/SUM($D$2:$F$2) -> 45424.352 | R41: =SUMPRODUCT(G41:I41,$G$2:$I$2)/SUM($G$2:$I$2) -> 51755.13 | S41: =SUMPRODUCT(J41:L41,$J$2:$L$2)/SUM($J$2:$L$2) -> 58508.582 | T41: =SUMPRODUCT(M41:O41,$M$2:$O$2)/SUM($M$2:$O$2) -> 97820.422 | U41: =SUMPRODUCT(D41:O41,$D$2:$O$2)/SUM($D$2:$O$2) -> 63237.577 | V41: =S41/Q41 -> 1.2880444 | W41: =R41/Q41 -> 1.1393697 | X41: =S41/R41 -> 1.1304885 | Y41: =T41/Q41 -> 2.1534798
...

Sheet WEST BENGAL
A1: Milk Procurement Historical Data_WB
D2: 30 | E2: 31 | F2: 30 | G2: 31 | H2: 31 | I2: 30 | J2: 31 | K2: 30 | L2: 31 | M2: 31 | N2: 28 | O2: 31 | Q2: =SUM(D2:F2) -> 91 | R2: =SUM(G2:I2) -> 92 | S2: =SUM(J2:L2) -> 92 | T2: =SUM(M2:O2) -> 90 | U2: =SUM(Q2:T2) -> 365
D3: 30 | E3: 31 | F3: 30 | G3: 31 | H3: 31 | I3: 30 | J3: 31 | K3: 30 | L3: 31 | M3: 31 | N3: 29 | O3: 31 | Q3: =SUM(D3:F3) -> 91 | R3: =SUM(G3:I3) -> 92 | S3: =SUM(J3:L3) -> 92 | T3: =SUM(M3:O3) -> 91 | U3: =SUM(Q3:T3) -> 366
