Workbook

Sheet Sumarry
C2: State wise BMC wise Gain/(Loss)
C3: State | D3: Type | E3: Code | F3: BMC Name | G3: MTD Volume | H3: Vol Kg | I3: FAT kg | J3: SNF Kg | K3: FAT Rate | L3: SNF Rate | M3: Amount | N3: Loss/gain per Kg | O3: Day book received till | P3: Remarks
C4: BR | D4: Daya BMC | E4: 1001 | F4: Majhaul | G4: =Manjhaul!J66 -> 37533.715 | H4: =+Manjhaul!AM66 -> -170.715 | I4: =+Manjhaul!AN66 -> 15.577818 | J4: =+Manjhaul!AO66 -> -24.48254 | K4: 448.91 | L4: =K4*2/3 -> 299.27333 | M4: =I4*K4+J4*L4 -> -333.93315 | N4: =M4/G4 -> -0.0088968851 | O4: 46182 | P4: Report till updated 09th June 26 | U4: Remarks
C5: BR | D5: Daya BMC | E5: 1058 | F5: Hasanpur | G5: =Hasanpur!J66 -> 20426.548 | H5: =+Hasanpur!AM66 -> 510.252 | I5: =+Hasanpur!AN66 -> 50.58999 | J5: =+Hasanpur!AO66 -> 60.146947 | K5: 448.91 | L5: =K5*2/3 -> 299.27333 | M5: =I5*K5+J5*L5 -> 40710.73 | N5: =M5/G5 -> 1.9930303 | O5: 46184 | P5: Report till updated 11th June 26 | V5: Challan Missing | X5: Milk reject | Z5: Out Side sell
C6: BR | D6: Daya BMC | E6: 1011 | F6: Sahibpur Kamal | G6: =+'Sahibpur Kamal'!J66 -> 91062.094 | H6: =+'Sahibpur Kamal'!AM66 -> 218.906 | I6: =+'Sahibpur Kamal'!AN66 -> 76.667234 | J6: =+'Sahibpur Kamal'!AO66 -> -8.1414302 | K6: 448.91 | L6: =K6*2/3 -> 299.27333 | M6: =I6*K6+J6*L6 -> 31980.175 | N6: =M6/G6 -> 0.35119086 | O6: 46184 | P6: Report till updated 11th June 26
C7: BR | D7: Daya BMC | E7: 1011 | F7: Bachhwara | G7: =+Bachhwara!J66 -> 14979.805 | H7: =+Bachhwara!AM66 -> 54.195 | I7: =+Bachhwara!AN66 -> 5.9641393 | J7: =+Bachhwara!AO66 -> -22.406394 | K7: 448.91 | L7: =K7*2/3 -> 299.27333 | M7: =I7*K7+J7*L7 -> -4028.2743 | N7: =M7/G7 -> -0.26891367 | O7: 46184 | P7: Report till updated 11th June 26
C8: BR | D8: Daya BMC | E8: 1012 | F8: Dalsingsarai | G8: =+Dalsingsarai!J66 -> 125928.37 | H8: =+Dalsingsarai!AM66 -> -61.3665 | I8: =+Dalsingsarai!AN66 -> 101.62155 | J8: =+Dalsingsarai!AO66 -> -100.80511 | K8: 448.91 | L8: =K8*2/3 -> 299.27333 | M8: =I8*K8+J8*L8 -> 15450.646 | N8: =M8/G8 -> 0.12269393 | O8: 46183 | P8: Report till updated 10th June 26
C9: BR | D9: Daya BMC | E9: 1054 | F9: Alauli | G9: =+Alauli!J66 -> 56583.153 | H9: =+Alauli!AM66 -> -151.053 | I9: =+Alauli!AN66 -> 12.796429 | J9: =+Alauli!AO66 -> 20.613994 | K9: 448.91 | L9: =K9*2/3 -> 299.27333 | M9: =I9*K9+J9*L9 -> 11913.664 | N9: =M9/G9 -> 0.21055143 | O9: 46184 | P9: Report till updated 11th June 26
C10: BR | D10: Daya BMC | E10: 1055 | F10: Matihani | G10: =+Matihani!J66 -> 73236.605 | H10: =+Matihani!AM66 -> 465.395 | I10: =+Matihani!AN66 -> 31.267184 | J10: =+Matihani!AO66 -> 38.981571 | K10: 448.91 | L10: =K10*2/3 -> 299.27333 | M10: =I10*K10+J10*L10 -> 25702.296 | N10: =M10/G10 -> 0.35094877 | O10: 46184 | P10: Report till updated 11th June 26
C11: BR | D11: Daya BMC | E11: 1013 | F11: Musrigharari | G11: =+Musrigharari!R66 -> 46060.158 | H11: =+Musrigharari!AM66 -> 63.842 | I11: =+Musrigharari!AN66 -> 42.865291 | J11: =+Musrigharari!AO66 -> 10.587751 | K11: 448.91 | L11: =K11*2/3 -> 299.27333 | M11: =I11*K11+J11*L11 -> 22411.289 | N11: =M11/G11 -> 0.48656562 | O11: 46183 | P11: Report till updated 10th June 26
C12: BR | D12: Daya BMC | E12: 1013 | F12: Mahua | G12: =+Mahua!R66 -> 22170.853 | H12: =+Mahua!AM66 -> 779.347 | I12: =+Mahua!AN66 -> 77.553346 | J12: =+Mahua!AO66 -> 116.03488 | K12: 448.91 | L12: =K12*2/3 -> 299.27333 | M12: =I12*K12+J12*L12 -> 69540.618 | N12: =M12/G12 -> 3.1365784 | O12: 46184 | P12: Report till updated 11th June 26
C13: BR | D13: Daya BMC | E13: 1014 | F13: Dumrao | G13: =+Buxar!J66 -> 74530.8 | H13: =+Buxar!AM66 -> 695.4 | I13: =+Buxar!AN66 -> 151.0716 | J13: =+Buxar!AO66 -> -180.32868 | K13: 448.91 | L13: =K13*2/3 -> 299.27333 | M13: =I13*K13+J13*L13 -> 13849.988 | N13: =M13/G13 -> 0.18582906 | O13: 46184 | P13: Report till updated 11th June 26
C14: BR | D14: Daya BMC | E14: 1014 | F14: Gaighat | G14: =+Gaighat!J66 -> 24399.67 | H14: =+Gaighat!AM66 -> 361.03 | I14: =+Gaighat!AN66 -> 8.0405695 | J14: =+Gaighat!AO66 -> -10.464334 | K14: 448.91 | L14: =K14*2/3 -> 299.27333 | M14: =I14*K14+J14*L14 -> 477.79606 | N14: =M14/G14 -> 0.01958207 | O14: 46184 | P14: Report till updated 11th June 26
C15: BR | D15: Daya BMC | E15: 1057 | F15: Warisnagar | G15: =+Warisnagar!J66 -> 32709.813 | H15: =+Warisnagar!AM66 -> 89.887 | I15: =+Warisnagar!AN66 -> 39.259266 | J15: =+Warisnagar!AO66 -> -17.329006 | K15: 448.91 | L15: =K15*2/3 -> 299.27333 | M15: =I15*K15+J15*L15 -> 12437.768 | N15: =M15/G15 -> 0.38024577 | O15: 46182 | P15: Report till updated 09th June 26
C16: BR | D16: Daya BMC | E16: 1053 | F16: Kalyanpur | G16: =+Kalyanpur!J66 -> 130300.56 | H16: =+Kalyanpur!AM66 -> 460.638 | I16: =+Kalyanpur!AN66 -> 92.23365 | J16: =+Kalyanpur!AO66 -> 79.162847 | K16: 448.91 | L16: =K16*2/3 -> 299.27333 | M16: =I16*K16+J16*L16 -> 65095.937 | N16: =M16/G16 -> 0.49958293 | O16: 46184 | P16: Report till updated 11th June 26
C17: Bihar Daya BMCTotal | G17: =SUM(G4:G16) -> 749922.14 | H17: =SUM(H4:H16) -> 3315.7575 | I17: =SUM(I4:I16) -> 705.50807 | J17: =SUM(J4:J16) -> -38.429506 | K17: =SUM(K4:K16) -> 5835.83 | L17: =SUM(L4:L16) -> 3890.5533 | M17: =SUM(M4:M16) -> 305208.7 | N17: =M17/G17 -> 0.40698718
C19: BR | D19: Daya BMC | E19: 1064 | F19: Singhia | G19: ='Singhia '!J66 -> 14325.075 | H19: =+'Singhia '!AM66 -> 770.8248 | I19: =+'Singhia '!AN66 -> 1.5865826 | J19: =+'Singhia '!AO66 -> 28.84478 | K19: 448.91 | L19: =K19*2/3 -> 299.27333 | M19: =I19*K19+J19*L19 -> 9344.7063 | N19: =M19/G19 -> 0.65233209 | O19: 46184 | P19: Report till updated 11th June 26
C20: BR | D20: SP BMC | E20: 1002 | F20: Laldiyara | G20: =+Laldiyara!J66 -> 128432.19 | H20: =+Laldiyara!AM66 -> -670.1935 | I20: =+Laldiyara!AN66 -> 39.390462 | J20: =+Laldiyara!AO66 -> -128.06078 | K20: 448.91002 | L20: =K20*2/3 -> 299.27334 | M20: =I20*K20+J20*L20 -> -20642.406 | N20: =M20/G20 -> -0.1607261 | O20: 46182 | P20: Report till updated 09th June 26
C21: BR | D21: SP BMC | E21: 1003 | F21: Asarganj | G21: =+Asarganj!J66 -> 125905.86 | H21: =+Asarganj!AM66 -> -266.861 | I21: =+Asarganj!AN66 -> -21.305352 | J21: =+Asarganj!AO66 -> -45.605311 | K21: 448.91002 | L21: =K21*2/3 -> 299.27334 | M21: =I21*K21+J21*L21 -> -23212.64 | N21: =M21/G21 -> -0.18436504 | O21: 46183 | P21: Report till updated 10th June 26
C22: BR | D22: SP BMC | E22: 1010 | F22: Parbatta | G22: =+Parbatta!J66 -> 78825.179 | H22: =+Parbatta!AM66 -> -72.179 | I22: =+Parbatta!AN66 -> -92.384279 | J22: =+Parbatta!AO66 -> 41.534127 | K22: 448.91002 | L22: =K22*2/3 -> 299.27334 | M22: =I22*K22+J22*L22 -> -29042.171 | N22: =M22/G22 -> -0.36843774 | O22: 46183 | P22: Report till updated 10th June 26
C23: BR | D23: SP RMC | E23: 1048 | F23: Mahadatpur | G23: =+Madhatpur!J66 -> 12981.811 | H23: =+Madhatpur!AM66 -> -20.811 | I23: =+Madhatpur!AN66 -> -2.9607861 | J23: =+Madhatpur!AO66 -> -11.201198 | K23: 448.91002 | L23: =K23*2/3 -> 299.27334 | M23: =I23*K23+J23*L23 -> -4681.3464 | N23: =M23/G23 -> -0.36060812 | O23: 46184 | P23: Report till updated 11th June 26
C24: BR | D24: SP RMC | E24: 1056 | F24: Chautham | G24: =+Chautham!J66 -> 45900.827 | H24: =+Chautham!AM66 -> 346.1727 | I24: =+Chautham!AN66 -> -32.274795 | J24: =+Chautham!AO66 -> 21.397707 | K24: 448.91002 | L24: =K24*2/3 -> 299.27334 | M24: =I24*K24+J24*L24 -> -8084.7152 | N24: =M24/G24 -> -0.17613441 | O24: 46184 | P24: Report till updated 11th June 26
C25: BR | D25: SP BMC | E25: 1006 | F25: Sonvarsha | G25: =+Sonvarsha!J66 -> 73171.715 | H25: =+Sonvarsha!AM66 -> 78.285 | I25: =+Sonvarsha!AN66 -> -14.575022 | J25: =+Sonvarsha!AO66 -> 68.916593 | K25: 448.91002 | L25: =K25*2/3 -> 299.27334 | M25: =I25*K25+J25*L25 -> 14082.026 | N25: =M25/G25 -> 0.19245177 | O25: 46182 | P25: Report till updated 09th June 26
C26: BR | D26: SP BMC | E26: 1059 | F26: Gopalpur | G26: =+Gopalpur!J66 -> 24402.348 | H26: =+Gopalpur!AM66 -> 351.652 | I26: =+Gopalpur!AN66 -> 4.7709275 | J26: =+Gopalpur!AO66 -> -6.4395427 | K26: 448.91002 | L26: =K26*2/3 -> 299.27334 | M26: =I26*K26+J26*L26 -> 214.53366 | N26: =M26/G26 -> 0.0087915172 | O26: 46183 | P26: Report till updated 10th June 26
C27: BR | D27: SP BMC | E27: 1007 | F27: Aariya | G27: =+Araiya!J66 -> 104417.49 | H27: =+Araiya!AM66 -> 153.814 | I27: =+Araiya!AN66 -> 43.674607 | J27: =+Araiya!AO66 -> -11.009152 | K27: 448.91002 | L27: =K27*2/3 -> 299.27334 | M27: =I27*K27+J27*L27 -> 16311.223 | N27: =M27/G27 -> 0.1562116 | O27: 46183 | P27: Report till updated 10th June 26
C28: BR | D28: SP BMC | E28: 1008 | F28: Teghra | G28: =+Teghra!J66 -> 50629.393 | H28: =+Teghra!AM66 -> 386.6075 | I28: =+Teghra!AN66 -> 33.477854 | J28: =+Teghra!AO66 -> 102.29164 | K28: 448.91002 | L28: =K28*2/3 -> 299.27334 | M28: =I28*K28+J28*L28 -> 45641.704 | N28: =M28/G28 -> 0.90148631 | O28: 46184 | P28: Report till updated 11th June 26
C29: BR | D29: SP BMC | E29: 1009 | F29: Halsi | G29: =+Halsi!J66 -> 81916.003 | H29: =+Halsi!AM66 -> -308.003 | I29: =+Halsi!AN66 -> 110.60746 | J29: =+Halsi!AO66 -> -45.72645 | K29: 448.91002 | L29: =K29*2/3 -> 299.27334 | M29: =I29*K29+J29*L29 -> 35968.089 | N29: =M29/G29 -> 0.439085 | O29: 46181 | P29: Report till updated 08th June 26
C30: Bihar Service Provider Total | G30: =SUM(G20:G29) -> 726582.82 | H30: =SUM(H20:H29) -> -21.5163 | I30: =SUM(I20:I29) -> 68.421077 | J30: =SUM(J20:J29) -> -13.902372 | K30: =SUM(K20:K29) -> 4489.1002 | L30: =SUM(L20:L29) -> 2992.7334 | M30: =SUM(M20:M29) -> 26554.297 | N30: =M30/G30 -> 0.036546828
C32: =C3 -> State | D32: =D3 -> Type | E32: =E3 -> Code | F32: =F3 -> BMC Name | G32: =G3 -> MTD Volume | H32: =H3 -> Vol Kg | I32: =I3 -> FAT kg | J32: =J3 -> SNF Kg | ... P32: =P3 -> Remarks
C33: JH | D33: SP RMC | E33: 2001 | F33: Itki | G33: 50361.799 | H33: 204.2015 | I33: -31.4813 | J33: -35.0129 | K33: 436.77 | L33: 296.6 | M33: =I33*K33+J33*L33 -> -24134.914 | N33: =M33/G33 -> -0.47923057 | O33: 46184 | P33: Report till updated 11th June 26
C34: JH | D34: SP RMC | E34: 2002 | F34: Pali | G34: 55815.752 | H34: -253.8915 | I34: -5.048648 | J34: -62.14806 | K34: 436.77 | L34: 296.6 | M34: =I34*K34+J34*L34 -> -20638.213 | N34: =M34/G34 -> -0.36975606 | O34: 46184 | P34: Report till updated 11th June 26
C35: JH | D35: SP RMC | E35: 2003 | F35: Hisri Thakurgaon | G35: 14476.619 | H35: -16.2691 | I35: -6.933165 | J35: -21.573148 | K35: 436.77 | L35: 296.6 | M35: =I35*K35+J35*L35 -> -9426.7942 | N35: =M35/G35 -> -0.65117374 | O35: 46184 | P35: Report till updated 11th June 26
C36: JH | D36: SP RMC | E36: 2004 | F36: Choreya | G36: 6665.851 | H36: 88.009 | I36: -28.111424 | J36: -20.091168 | K36: 436.77 | L36: 296.6 | M36: =I36*K36+J36*L36 -> -18237.267 | N36: =M36/G36 -> -2.7359248 | O36: 46184 | P36: Report till updated 11th June 26
C37: JH | D37: SP RMC | E37: 2005 | F37: Baski | G37: 0 | H37: 0 | I37: 0 | J37: 0 | K37: 436.77 | L37: 296.6 | M37: =I37*K37+J37*L37 -> 0 | N37: =M37/G37 -> #DIV/0! | O37: 46184 | P37: Report till updated 11th June 26
C38: JH | D38: SP RMC | E38: 2006 | F38: Ormanjhi Rmc | G38: 28830.761 | H38: 1196.2391 | I38: -30.1178 | J38: 45.2479 | K38: 436.77 | L38: 296.6 | M38: =I38*K38+J38*L38 -> 265.97563 | N38: =M38/G38 -> 0.0092254115 | O38: 46184 | P38: Report till updated 11th June 26
C39: JH | D39: SP RMC | E39: 2007 | F39: Piragutu Rmc | G39: 17268.578 | H39: -142.9583 | I39: -15.656588 | J39: -40.535792 | K39: 436.77 | L39: 296.6 | M39: =I39*K39+J39*L39 -> -18861.244 | N39: =M39/G39 -> -1.0922291 | O39: 46184 | P39: Report till updated 11th June 26
C40: JH | D40: SP RMC | E40: 2008 | F40: Bhandra | G40: 29859.412 | H40: 1051.5884 | I40: -6.9077 | J40: 2.1373 | K40: 436.77 | L40: 296.6 | M40: =I40*K40+J40*L40 -> -2383.1529 | N40: =M40/G40 -> -0.079812455 | O40: 46184 | P40: Report till updated 11th June 26
C41: JH | D41: SP RMC | E41: 2009 | F41: Chanho | G41: 24711.554 | H41: 228.446 | I41: 11.0649 | J41: -19.7894 | K41: 436.77 | L41: 296.6 | M41: =I41*K41+J41*L41 -> -1036.7197 | N41: =M41/G41 -> -0.041952832 | O41: 46184 | P41: Report till updated 11th June 26
C42: Jharkhand Total | G42: =SUM(G33:G41) -> 227990.32 | H42: =SUM(H33:H41) -> 2355.3651 | I42: =SUM(I33:I41) -> -113.19173 | J42: =SUM(J33:J41) -> -151.76527 | K42: =SUM(K33:K40) -> 3494.16 | L42: =SUM(L33:L40) -> 2372.8 | M42: =SUM(M33:M41) -> -94452.328 | N42: =M42/G42 -> -0.41428218
C44: =C32 -> State | D44: =D32 -> Type | E44: =E32 -> Code | F44: =F32 -> BMC Name | G44: =G32 -> MTD Volume | H44: =H32 -> Vol Kg | I44: =I32 -> FAT kg | J44: =J32 -> SNF Kg | ... P44: =P32 -> Remarks
...

Sheet Manjhaul
B1: Manjhaul Bmc | AG1: 392 | AP1: =Sumarry!$K$4 -> 448.91 | AQ1: =Sumarry!$L$4 -> 299.27333
B2: Date | C2: Shift | D2: OB | I2: Milk from MPG in Ltr | M2: Transfer from other BMC/RMC | R2: Total Milk Receipt in Kg | U2: Tanker Dispatch Details | AC2: Plant Receipt | AH2: CB | AM2: Loss/(Gain)
D3: Qty KG | E3: Fat% | F3: Snf% | G3: FAT Kg | H3: SNF Kg | I3: Qty Ltr | J3: Qty Kg | K3: Fat% | L3: Snf% | M3: From | N3: Tanker No | O3: Qty Kg | P3: Fat% | Q3: Snf% | R3: Qty Kg | S3: FAT Kg | T3: SNF Kg | U3: Tanker | V3: Challan | W3: To | X3: Qty KG | Y3: Fat% | Z3: Snf% | AA3: FAT Kg | AB3: SNF Kg | AC3: Qty KG | AD3: Fat% | AE3: Snf% | AF3: FAT Kg | AG3: SNF Kg | AH3: Qty KG | AI3: Fat% | AJ3: Snf% | AK3: FAT Kg | AL3: SNF Kg | AM3: Qty KG | AN3: FAT Kg | AO3: SNF Kg | AP3: TS Loss% | AQ3: Amount
A4: =CONCATENATE(B4,C4) -> 46174M | B4: 46174 | C4: M | D4: 4003 | E4: 3.7 | F4: 8.08 | G4: =+D4*E4% -> 148.111 | H4: =+D4*F4% -> 323.4424 | I4: 1416.1 | J4: 1458.583 | K4: 4.1664501 | L4: 8.1952475 | M4: 0 | N4: 0 | O4: 0 | P4: 0 | Q4: 0 | R4: =+J4+O4 -> 1458.583 | S4: =+J4*K4%+O4*P4% -> 60.771133 | T4: =+J4*L4%+O4*Q4% -> 119.53449 | U4: 3461 | V4: 87788 | W4: Matihani | X4: 3650 | Y4: 4 | Z4: 8.33 | AA4: =X4*Y4% -> 146 | AB4: =X4*Z4% -> 304.045 | AC4: 3650 | AD4: 3.9 | AE4: 8.07 | AF4: =AC4*AD4% -> 142.35 | AG4: =AC4*AE4% -> 294.555 | AH4: 1812 | AI4: 3.82 | AJ4: 8.1 | AK4: =AH4*AI4% -> 69.2184 | AL4: =AH4*AJ4% -> 146.772 | AM4: =+D4+R4-AC4-AH4 -> -0.417 | AN4: =+G4+S4-AF4-AK4 -> -2.686267 | AO4: =+H4+T4-AG4-AL4 -> 1.649887 | AP4: =(AN4+AO4)/(S4+T4) -> -0.0057479074 | AQ4: =($AP$1*AN4+$AQ$1*AO4) -> -712.12494 | AR4: =(D4+J4+O4)-(X4+AH4) -> -0.417
A5: =CONCATENATE(B5,C5) -> 46174E | B5: =+B4 -> 46174 | C5: E | D5: 1812 | E5: 3.82 | F5: 8.1 | G5: =+D5*E5% -> 69.2184 | H5: =+D5*F5% -> 146.772 | I5: 2598.5 | J5: 2676.455 | K5: 3.7264768 | L5: 8.1239946 | M5: 0 | N5: 0 | O5: 0 | P5: 0 | Q5: 0 | R5: =+J5+O5 -> 2676.455 | S5: =+J5*K5%+O5*P5% -> 99.737475 | T5: =+J5*L5%+O5*Q5% -> 217.43506 | U5: 0 | V5: 0 | W5: 0 | X5: 0 | Y5: 0 | Z5: 0 | AA5: =X5*Y5% -> 0 | AB5: =X5*Z5% -> 0 | AF5: =AC5*AD5% -> 0 | AG5: =AC5*AE5% -> 0 | AH5: 4488 | AI5: 3.76 | AJ5: 8.07 | AK5: =AH5*AI5% -> 168.7488 | AL5: =AH5*AJ5% -> 362.1816 | AM5: =+D5+R5-AC5-AH5 -> 0.455 | AN5: =+G5+S5-AF5-AK5 -> 0.207075 | AO5: =+H5+T5-AG5-AL5 -> 2.02546 | AP5: =(AN5+AO5)/(S5+T5) -> 0.0070388661 | AQ5: =($AP$1*AN5+$AQ$1*AO5) -> 699.1242 | AR5: =(D5+J5+O5)-(X5+AH5) -> 0.455
A6: =CONCATENATE(B6,C6) -> 46175M | B6: =+B4+1 -> 46175 | C6: M | D6: 4488 | E6: 3.76 | F6: 8.07 | G6: =+D6*E6% -> 168.7488 | H6: =+D6*F6% -> 362.1816 | I6: 1142.2 | J6: 1176.466 | K6: 4.3726318 | L6: 8.2112502 | M6: 0 | N6: 0 | O6: 0 | P6: 0 | Q6: 0 | R6: =+J6+O6 -> 1176.466 | S6: =+J6*K6%+O6*P6% -> 51.442526 | T6: =+J6*L6%+O6*Q6% -> 96.602567 | U6: 6102 | V6: 87789 | W6: Munger | X6: 4870 | Y6: 4 | Z6: 8.21 | AA6: =X6*Y6% -> 194.8 | AB6: =X6*Z6% -> 399.827 | AC6: 4850 | AD6: 3.9 | AE6: 8.19 | AF6: =AC6*AD6% -> 189.15 | AG6: =AC6*AE6% -> 397.215 | AH6: 794 | AI6: 3.88 | AJ6: 8.09 | AK6: =AH6*AI6% -> 30.8072 | AL6: =AH6*AJ6% -> 64.2346 | AM6: =+D6+R6-AC6-AH6 -> 20.466 | AN6: =+G6+S6-AF6-AK6 -> 0.234126 | AO6: =+H6+T6-AG6-AL6 -> -2.665433 | AP6: =(AN6+AO6)/(S6+T6) -> -0.016422746 | AQ6: =($AP$1*AN6+$AQ$1*AO6) -> -692.59152 | AR6: =(D6+J6+O6)-(X6+AH6) -> 0.466
A7: =CONCATENATE(B7,C7) -> 46175E | B7: =+B5+1 -> 46175 | C7: E | D7: 794 | E7: 3.88 | F7: 8.09 | G7: =+D7*E7% -> 30.8072 | H7: =+D7*F7% -> 64.2346 | I7: 2548.3 | J7: 2624.749 | K7: 3.63261 | L7: 8.0804301 | M7: 0 | N7: 0 | O7: 0 | P7: 0 | Q7: 0 | R7: =+J7+O7 -> 2624.749 | S7: =+J7*K7%+O7*P7% -> 95.346894 | T7: =+J7*L7%+O7*Q7% -> 212.09101 | U7: 9071 | V7: 87790 | W7: Matihani | X7: 3100 | Y7: 3.85 | Z7: 8.18 | AA7: =X7*Y7% -> 119.35 | AB7: =X7*Z7% -> 253.58 | AC7: 3060 | AD7: 4 | AE7: 7.96 | AF7: =AC7*AD7% -> 122.4 | AG7: =AC7*AE7% -> 243.576 | AH7: 318 | AI7: 3.66 | AJ7: 8.07 | AK7: =AH7*AI7% -> 11.6388 | AL7: =AH7*AJ7% -> 25.6626 | AM7: =+D7+R7-AC7-AH7 -> 40.749 | AN7: =+G7+S7-AF7-AK7 -> -7.884706 | AO7: =+H7+T7-AG7-AL7 -> 7.087008 | AP7: =(AN7+AO7)/(S7+T7) -> -0.0025946638 | AQ7: =($AP$1*AN7+$AQ$1*AO7) -> -1418.5709 | AR7: =(D7+J7+O7)-(X7+AH7) -> 0.749
A8: =CONCATENATE(B8,C8) -> 46176M | B8: =+B6+1 -> 46176 | C8: M | D8: 318 | E8: 3.66 | F8: 8.07 | G8: =+D8*E8% -> 11.6388 | H8: =+D8*F8% -> 25.6626 | I8: 1659.9 | J8: 1709.697 | K8: 4.193102 | L8: 8.1770589 | M8: 0 | N8: 0 | O8: 0 | P8: 0 | Q8: 0 | R8: =+J8+O8 -> 1709.697 | S8: =+J8*K8%+O8*P8% -> 71.689339 | T8: =+J8*L8%+O8*Q8% -> 139.80293 | U8: 0 | V8: 0 | W8: 0 | X8: 0 | Y8: 0 | Z8: 0 | AA8: =X8*Y8% -> 0 | AB8: =X8*Z8% -> 0 | AF8: =AC8*AD8% -> 0 | AG8: =AC8*AE8% -> 0 | AH8: 2028 | AI8: 4.1 | AJ8: 8.15 | AK8: =AH8*AI8% -> 83.148 | AL8: =AH8*AJ8% -> 165.282 | AM8: =+D8+R8-AC8-AH8 -> -0.303 | AN8: =+G8+S8-AF8-AK8 -> 0.180139 | AO8: =+H8+T8-AG8-AL8 -> 0.18353 | AP8: =(AN8+AO8)/(S8+T8) -> 0.001719538 | AQ8: =($AP$1*AN8+$AQ$1*AO8) -> 135.79183 | AR8: =(D8+J8+O8)-(X8+AH8) -> -0.303
A9: =CONCATENATE(B9,C9) -> 46176E | B9: =+B7+1 -> 46176 | C9: E | D9: 2028 | E9: 4.1 | F9: 8.15 | G9: =+D9*E9% -> 83.148 | H9: =+D9*F9% -> 165.282 | I9: 3053.8 | J9: 3145.414 | K9: 3.697711 | L9: 8.0720283 | M9: 0 | N9: 0 | O9: 0 | P9: 0 | Q9: 0 | R9: =+J9+O9 -> 3145.414 | S9: =+J9*K9%+O9*P9% -> 116.30832 | T9: =+J9*L9%+O9*Q9% -> 253.89871 | U9: 0 | V9: 0 | W9: 0 | X9: 0 | Y9: 0 | Z9: 0 | AA9: =X9*Y9% -> 0 | AB9: =X9*Z9% -> 0 | AF9: =AC9*AD9% -> 0 | AG9: =AC9*AE9% -> 0 | AH9: 5173 | AI9: 3.85 | AJ9: 8.09 | AK9: =AH9*AI9% -> 199.1605 | AL9: =AH9*AJ9% -> 418.4957 | AM9: =+D9+R9-AC9-AH9 -> 0.414 | AN9: =+G9+S9-AF9-AK9 -> 0.295821 | AO9: =+H9+T9-AG9-AL9 -> 0.685008 | AP9: =(AN9+AO9)/(S9+T9) -> 0.0026494067 | AQ9: =($AP$1*AN9+$AQ$1*AO9) -> 337.80163 | AR9: =(D9+J9+O9)-(X9+AH9) -> 0.414
A10: =CONCATENATE(B10,C10) -> 46177M | B10: =+B8+1 -> 46177 | C10: M | D10: 5173 | E10: 3.85 | F10: 8.09 | G10: =+D10*E10% -> 199.1605 | H10: =+D10*F10% -> 418.4957 | I10: 1151.7 | J10: 1186.251 | K10: 4.3506295 | L10: 8.2383694 | M10: Bachhwara | N10: 89380 | O10: 1360 | P10: 4.1 | Q10: 8.04 | R10: =+J10+O10 -> 2546.251 | S10: =+J10*K10%+O10*P10% -> 107.36939 | T10: =+J10*L10%+O10*Q10% -> 207.07174 | U10: 9071/3461 | V10: 87791/92 | W10: Muzaffurpur/Hasanpur | X10: 6750 | Y10: 4.1 | Z10: 8.26 | AA10: =X10*Y10% -> 276.75 | AB10: =X10*Z10% -> 557.55 | AC10: 6740 | AD10: 4.0272255 | AE10: 8.1554451 | AF10: =AC10*AD10% -> 271.435 | AG10: =AC10*AE10% -> 549.677 | AH10: 969 | AI10: 3.94 | AJ10: 8.11 | AK10: =AH10*AI10% -> 38.1786 | AL10: =AH10*AJ10% -> 78.5859 | AM10: =+D10+R10-AC10-AH10 -> 10.251 | AN10: =+G10+S10-AF10-AK10 -> -3.083714 | AO10: =+H10+T10-AG10-AL10 -> -2.695461 | AP10: =(AN10+AO10)/(S10+T10) -> -0.018379196 | AQ10: =($AP$1*AN10+$AQ$1*AO10) -> -2190.9897 | AR10: =(D10+J10+O10)-(X10+AH10) -> 0.251
A11: =CONCATENATE(B11,C11) -> 46177E | B11: =+B9+1 -> 46177 | C11: E | D11: 969 | E11: 3.94 | F11: 8.11 | G11: =+D11*E11% -> 38.1786 | H11: =+D11*F11% -> 78.5859 | I11: 2851.2 | J11: 2936.736 | K11: 3.6417789 | L11: 8.1097608 | M11: 0 | N11: 0 | O11: 0 | P11: 0 | Q11: 0 | R11: =+J11+O11 -> 2936.736 | S11: =+J11*K11%+O11*P11% -> 106.94943 | T11: =+J11*L11%+O11*Q11% -> 238.16227 | U11: 0 | V11: 0 | W11: 0 | X11: 0 | Y11: 0 | Z11: 0 | AA11: =X11*Y11% -> 0 | AB11: =X11*Z11% -> 0 | AF11: =AC11*AD11% -> 0 | AG11: =AC11*AE11% -> 0 | AH11: 3905 | AI11: 3.7 | AJ11: 8.05 | AK11: =AH11*AI11% -> 144.485 | AL11: =AH11*AJ11% -> 314.3525 | AM11: =+D11+R11-AC11-AH11 -> 0.736 | AN11: =+G11+S11-AF11-AK11 -> 0.643032 | AO11: =+H11+T11-AG11-AL11 -> 2.395665 | AP11: =(AN11+AO11)/(S11+T11) -> 0.0088049667 | AQ11: =($AP$1*AN11+$AQ$1*AO11) -> 1005.6221 | AR11: =(D11+J11+O11)-(X11+AH11) -> 0.736
A12: =CONCATENATE(B12,C12) -> 46178M | B12: =+B10+1 -> 46178 | C12: M | D12: 3905 | E12: 3.7 | F12: 8.05 | G12: =+D12*E12% -> 144.485 | H12: =+D12*F12% -> 314.3525 | I12: 1114.1 | J12: 1147.523 | K12: 4.48 | L12: 8.13 | M12: 0 | N12: 0 | O12: 0 | P12: 0 | Q12: 0 | R12: =+J12+O12 -> 1147.523 | S12: =+J12*K12%+O12*P12% -> 51.40903 | T12: =+J12*L12%+O12*Q12% -> 93.29362 | U12: 9071 | V12: 87793 | W12: Munger | X12: 5200 | Y12: 4.05 | Z12: 8.22 | AA12: =X12*Y12% -> 210.6 | AB12: =X12*Z12% -> 427.44 | AC12: 5120 | AD12: 4 | AE12: 8.08 | AF12: =AC12*AD12% -> 204.8 | AG12: =AC12*AE12% -> 413.696 | AH12: 0 | AI12: 0 | AJ12: 0 | AK12: =AH12*AI12% -> 0 | AL12: =AH12*AJ12% -> 0 | AM12: =+D12+R12-AC12-AH12 -> -67.477 | AN12: =+G12+S12-AF12-AK12 -> -8.9059696 | AO12: =+H12+T12-AG12-AL12 -> -6.0498801 | AP12: =(AN12+AO12)/(S12+T12) -> -0.10335574 | AQ12: =($AP$1*AN12+$AQ$1*AO12) -> -5808.5466 | AR12: =(D12+J12+O12)-(X12+AH12) -> -147.477
A13: =CONCATENATE(B13,C13) -> 46178E | B13: =+B11+1 -> 46178 | C13: E | D13: 0 | E13: 0 | F13: 0 | G13: =+D13*E13% -> 0 | H13: =+D13*F13% -> 0 | I13: 2973.4 | J13: 3062.602 | K13: 3.6 | L13: 8.05 | M13: 0 | N13: 0 | O13: 0 | P13: 0 | Q13: 0 | R13: =+J13+O13 -> 3062.602 | S13: =+J13*K13%+O13*P13% -> 110.25367 | T13: =+J13*L13%+O13*Q13% -> 246.53946 | U13: 0 | V13: 0 | W13: 0 | X13: 0 | Y13: 0 | Z13: 0 | AA13: =X13*Y13% -> 0 | AB13: =X13*Z13% -> 0 | AF13: =AC13*AD13% -> 0 | AG13: =AC13*AE13% -> 0 | AH13: 3063 | AI13: 3.6 | AJ13: 8.05 | AK13: =AH13*AI13% -> 110.268 | AL13: =AH13*AJ13% -> 246.5715 | AM13: =+D13+R13-AC13-AH13 -> -0.398 | AN13: =+G13+S13-AF13-AK13 -> -0.014328 | AO13: =+H13+T13-AG13-AL13 -> -0.032039 | AP13: =(AN13+AO13)/(S13+T13) -> -0.00012995486 | AQ13: =($AP$1*AN13+$AQ$1*AO13) -> -16.020401 | AR13: =(D13+J13+O13)-(X13+AH13) -> -0.398
A14: =CONCATENATE(B14,C14) -> 46179M | B14: =+B12+1 -> 46179 | C14: M | D14: 3063 | E14: 3.6 | F14: 8.05 | G14: =+D14*E14% -> 110.268 | H14: =+D14*F14% -> 246.5715 | I14: 1568.1 | J14: 1615.143 | K14: 4.21 | L14: 8.11 | M14: 0 | N14: 0 | O14: 0 | P14: 0 | Q14: 0 | R14: =+J14+O14 -> 1615.143 | S14: =+J14*K14%+O14*P14% -> 67.99752 | T14: =+J14*L14%+O14*Q14% -> 130.9881 | U14: 0 | V14: 0 | W14: 0 | X14: 0 | Y14: 0 | Z14: 0 | AA14: =X14*Y14% -> 0 | AB14: =X14*Z14% -> 0 | AF14: =AC14*AD14% -> 0 | AG14: =AC14*AE14% -> 0 | AH14: 4678 | AI14: 3.81 | AJ14: 8.07 | AK14: =AH14*AI14% -> 178.2318 | AL14: =AH14*AJ14% -> 377.5146 | AM14: =+D14+R14-AC14-AH14 -> 0.143 | AN14: =+G14+S14-AF14-AK14 -> 0.0337203 | AO14: =+H14+T14-AG14-AL14 -> 0.0449973 | AP14: =(AN14+AO14)/(S14+T14) -> 0.00039559442 | AQ14: =($AP$1*AN14+$AQ$1*AO14) -> 28.603872 | AR14: =(D14+J14+O14)-(X14+AH14) -> 0.143
A15: =CONCATENATE(B15,C15) -> 46179E | B15: =+B13+1 -> 46179 | C15: E | D15: 4678 | E15: 3.81 | F15: 8.07 | G15: =+D15*E15% -> 178.2318 | H15: =+D15*F15% -> 377.5146 | I15: 2954.1 | J15: 3042.723 | K15: 3.61 | L15: 8.02 | M15: 0 | N15: 0 | O15: 0 | P15: 0 | Q15: 0 | R15: =+J15+O15 -> 3042.723 | S15: =+J15*K15%+O15*P15% -> 109.8423 | T15: =+J15*L15%+O15*Q15% -> 244.02638 | U15: 9071 | V15: 87794 | W15: Muzaffurpur | X15: 6200 | Y15: 3.95 | Z15: 8.2 | AA15: =X15*Y15% -> 244.9 | AB15: =X15*Z15% -> 508.4 | AC15: 6140 | AD15: 3.8 | AE15: 7.98 | AF15: =AC15*AD15% -> 233.32 | AG15: =AC15*AE15% -> 489.972 | AH15: 1521 | AI15: 3.73 | AJ15: 8.05 | AK15: =AH15*AI15% -> 56.7333 | AL15: =AH15*AJ15% -> 122.4405 | AM15: =+D15+R15-AC15-AH15 -> 59.723 | AN15: =+G15+S15-AF15-AK15 -> -1.9791997 | AO15: =+H15+T15-AG15-AL15 -> 9.1284846 | AP15: =(AN15+AO15)/(S15+T15) -> 0.020203214 | AQ15: =($AP$1*AN15+$AQ$1*AO15) -> 1843.4295 | AR15: =(D15+J15+O15)-(X15+AH15) -> -0.277
A16: =CONCATENATE(B16,C16) -> 46180M | B16: =+B14+1 -> 46180 | C16: M | D16: 1521 | E16: 3.73 | F16: 8.05 | G16: =+D16*E16% -> 56.7333 | H16: =+D16*F16% -> 122.4405 | I16: 1248.6 | J16: 1286.058 | K16: 4.2 | L16: 8.16 | M16: 0 | N16: 0 | O16: 0 | P16: 0 | Q16: 0 | R16: =+J16+O16 -> 1286.058 | S16: =+J16*K16%+O16*P16% -> 54.014436 | T16: =+J16*L16%+O16*Q16% -> 104.94233 | U16: 0 | V16: 0 | W16: 0 | X16: 0 | Y16: 0 | Z16: 0 | AA16: =X16*Y16% -> 0 | AB16: =X16*Z16% -> 0 | AF16: =AC16*AD16% -> 0 | AG16: =AC16*AE16% -> 0 | AH16: 2807 | AI16: 3.95 | AJ16: 8.1 | AK16: =AH16*AI16% -> 110.8765 | AL16: =AH16*AJ16% -> 227.367 | AM16: =+D16+R16-AC16-AH16 -> 0.058 | AN16: =+G16+S16-AF16-AK16 -> -0.128764 | AO16: =+H16+T16-AG16-AL16 -> 0.0158328 | AP16: =(AN16+AO16)/(S16+T16) -> -0.00071045229 | AQ16: =($AP$1*AN16+$AQ$1*AO16) -> -53.065112 | AR16: =(D16+J16+O16)-(X16+AH16) -> 0.058
A17: =CONCATENATE(B17,C17) -> 46180E | B17: =+B15+1 -> 46180 | C17: E | D17: 2807 | E17: 3.95 | F17: 8.1 | G17: =+D17*E17% -> 110.8765 | H17: =+D17*F17% -> 227.367 | I17: 2747.9 | J17: 2830.337 | K17: 3.69 | L17: 8.07 | M17: Hasanpur | N17: 6545/57859 | O17: 2400 | P17: 4.25 | Q17: 8.1 | R17: =+J17+O17 -> 5230.337 | S17: =+J17*K17%+O17*P17% -> 206.43944 | T17: =+J17*L17%+O17*Q17% -> 422.8082 | U17: 6545 | V17: 87795 | W17: Muzaffurpur | X17: 3150 | Y17: 4.15 | Z17: 8 | AA17: =X17*Y17% -> 130.725 | AB17: =X17*Z17% -> 252 | AC17: 3130 | AD17: 4.05 | AE17: 7.9 | AF17: =AC17*AD17% -> 126.765 | AG17: =AC17*AE17% -> 247.27 | AH17: 4937 | AI17: 3.95 | AJ17: 8.09 | AK17: =AH17*AI17% -> 195.0115 | AL17: =AH17*AJ17% -> 399.4033 | AM17: =+D17+R17-AC17-AH17 -> -29.663 | AN17: =+G17+S17-AF17-AK17 -> -4.4605647 | AO17: =+H17+T17-AG17-AL17 -> 3.5018959 | AP17: =(AN17+AO17)/(S17+T17) -> -0.0015235159 | AQ17: =($AP$1*AN17+$AQ$1*AO17) -> -954.36804 | AR17: =(D17+J17+O17)-(X17+AH17) -> -49.663
A18: =CONCATENATE(B18,C18) -> 46181M | B18: =+B16+1 -> 46181 | C18: M | D18: 4937 | E18: 3.95 | F18: 8.09 | G18: =+D18*E18% -> 195.0115 | H18: =+D18*F18% -> 399.4033 | I18: 1191.6 | J18: 1227.348 | K18: 4.15 | L18: 8.2 | M18: 0 | N18: 0 | O18: 0 | P18: 0 | Q18: 0 | R18: =+J18+O18 -> 1227.348 | S18: =+J18*K18%+O18*P18% -> 50.934942 | T18: =+J18*L18%+O18*Q18% -> 100.64254 | U18: 9071 | V18: 87797 | W18: Munger | X18: 6110 | Y18: 3.93 | Z18: 8.14 | AA18: =X18*Y18% -> 240.123 | AB18: =X18*Z18% -> 497.354 | AC18: 6110 | AD18: 3.93 | AE18: 8.14 | AF18: =AC18*AD18% -> 240.123 | AG18: =AC18*AE18% -> 497.354 | AH18: 0 | AI18: 0 | AJ18: 0 | AK18: =AH18*AI18% -> 0 | AL18: =AH18*AJ18% -> 0 | AM18: =+D18+R18-AC18-AH18 -> 54.348 | AN18: =+G18+S18-AF18-AK18 -> 5.823442 | AO18: =+H18+T18-AG18-AL18 -> 2.691836 | AP18: =(AN18+AO18)/(S18+T18) -> 0.056177726 | AQ18: =($AP$1*AN18+$AQ$1*AO18) -> 3419.7961 | AR18: =(D18+J18+O18)-(X18+AH18) -> 54.348
A19: =CONCATENATE(B19,C19) -> 46181E | B19: =+B17+1 -> 46181 | C19: E | D19: 0 | E19: 0 | F19: 0 | G19: =+D19*E19% -> 0 | H19: =+D19*F19% -> 0 | I19: 2702.1 | J19: 2783.163 | K19: 3.77 | L19: 8.07 | M19: 0 | N19: 0 | O19: 0 | P19: 0 | Q19: 0 | R19: =+J19+O19 -> 2783.163 | S19: =+J19*K19%+O19*P19% -> 104.92525 | T19: =+J19*L19%+O19*Q19% -> 224.60125 | U19: 0 | V19: 0 | W19: 0 | X19: 0 | Y19: 0 | Z19: 0 | AA19: =X19*Y19% -> 0 | AB19: =X19*Z19% -> 0 | AF19: =AC19*AD19% -> 0 | AG19: =AC19*AE19% -> 0 | AH19: 2783 | AI19: 3.77 | AJ19: 8.07 | AK19: =AH19*AI19% -> 104.9191 | AL19: =AH19*AJ19% -> 224.5881 | AM19: =+D19+R19-AC19-AH19 -> 0.163 | AN19: =+G19+S19-AF19-AK19 -> 0.0061451 | AO19: =+H19+T19-AG19-AL19 -> 0.0131541 | AP19: =(AN19+AO19)/(S19+T19) -> 5.8566458e-05 | AQ19: =($AP$1*AN19+$AQ$1*AO19) -> 6.6952682 | AR19: =(D19+J19+O19)-(X19+AH19) -> 0.163
A20: =CONCATENATE(B20,C20) -> 46182M | B20: =+B18+1 -> 46182 | C20: M | D20: 2783 | E20: 3.77 | F20: 8.07 | G20: =+D20*E20% -> 104.9191 | H20: =+D20*F20% -> 224.5881 | I20: 1085.8 | J20: 1118.374 | K20: 4.27 | L20: 8.24 | M20: Bachhwara | N20: 6545/89382 | O20: 2370 | P20: 4.2 | Q20: 8 | R20: =+J20+O20 -> 3488.374 | S20: =+J20*K20%+O20*P20% -> 147.29457 | T20: =+J20*L20%+O20*Q20% -> 281.75402 | U20: 6545 | V20: 87798 | W20: Munger | X20: 6230 | Y20: 4.03 | Z20: 8.1 | AA20: =X20*Y20% -> 251.069 | AB20: =X20*Z20% -> 504.63 | AC20: 6190 | AD20: 3.9753635 | AE20: 8.0750727 | AF20: =AC20*AD20% -> 246.075 | AG20: =AC20*AE20% -> 499.847 | AH20: 0 | AI20: 0 | AJ20: 0 | AK20: =AH20*AI20% -> 0 | AL20: =AH20*AJ20% -> 0 | AM20: =+D20+R20-AC20-AH20 -> 81.374 | AN20: =+G20+S20-AF20-AK20 -> 6.1386698 | AO20: =+H20+T20-AG20-AL20 -> 6.4951176 | AP20: =(AN20+AO20)/(S20+T20) -> 0.029446053 | AQ20: =($AP$1*AN20+$AQ$1*AO20) -> 4699.5258 | AR20: =(D20+J20+O20)-(X20+AH20) -> 41.374
A21: =CONCATENATE(B21,C21) -> 46182E | B21: =+B19+1 -> 46182 | C21: E | D21: 0 | E21: 0 | F21: 0 | G21: =+D21*E21% -> 0 | H21: =+D21*F21% -> 0 | I21: 2433.1 | J21: 2506.093 | K21: 3.79 | L21: 8.04 | M21: 0 | N21: 0 | O21: 0 | P21: 0 | Q21: 0 | R21: =+J21+O21 -> 2506.093 | S21: =+J21*K21%+O21*P21% -> 94.980925 | T21: =+J21*L21%+O21*Q21% -> 201.48988 | U21: 0 | V21: 0 | W21: 0 | X21: 0 | Y21: 0 | Z21: 0 | AA21: =X21*Y21% -> 0 | AB21: =X21*Z21% -> 0 | AF21: =AC21*AD21% -> 0 | AG21: =AC21*AE21% -> 0 | AH21: 2506 | AI21: 3.79 | AJ21: 8.04 | AK21: =AH21*AI21% -> 94.9774 | AL21: =AH21*AJ21% -> 201.4824 | AM21: =+D21+R21-AC21-AH21 -> 0.093 | AN21: =+G21+S21-AF21-AK21 -> 0.0035247 | AO21: =+H21+T21-AG21-AL21 -> 0.0074772 | AP21: =(AN21+AO21)/(S21+T21) -> 3.7109557e-05 | AQ21: =($AP$1*AN21+$AQ$1*AO21) -> 3.8199996 | AR21: =(D21+J21+O21)-(X21+AH21) -> 0.093
A22: =CONCATENATE(B22,C22) -> 46183M | B22: =+B20+1 -> 46183 | C22: M | G22: =+D22*E22% -> 0 | H22: =+D22*F22% -> 0 | R22: =+J22+O22 -> 0 | S22: =+J22*K22%+O22*P22% -> 0 | T22: =+J22*L22%+O22*Q22% -> 0 | AA22: =X22*Y22% -> 0 | AB22: =X22*Z22% -> 0 | AF22: =AC22*AD22% -> 0 | AG22: =AC22*AE22% -> 0 | AK22: =AH22*AI22% -> 0 | AL22: =AH22*AJ22% -> 0 | AM22: =+D22+R22-AC22-AH22 -> 0 | AN22: =+G22+S22-AF22-AK22 -> 0 | AO22: =+H22+T22-AG22-AL22 -> 0 | AP22: =(AN22+AO22)/(S22+T22) -> #DIV/0! | AQ22: =($AP$1*AN22+$AQ$1*AO22) -> 0 | AR22: =(D22+J22+O22)-(X22+AH22) -> 0
A23: =CONCATENATE(B23,C23) -> 46183E | B23: =+B21+1 -> 46183 | C23: E | G23: =+D23*E23% -> 0 | H23: =+D23*F23% -> 0 | R23: =+J23+O23 -> 0 | S23: =+J23*K23%+O23*P23% -> 0 | T23: =+J23*L23%+O23*Q23% -> 0 | AA23: =X23*Y23% -> 0 | AB23: =X23*Z23% -> 0 | AF23: =AC23*AD23% -> 0 | AG23: =AC23*AE23% -> 0 | AK23: =AH23*AI23% -> 0 | AL23: =AH23*AJ23% -> 0 | AM23: =+D23+R23-AC23-AH23 -> 0 | AN23: =+G23+S23-AF23-AK23 -> 0 | AO23: =+H23+T23-AG23-AL23 -> 0 | AP23: =(AN23+AO23)/(S23+T23) -> #DIV/0! | AQ23: =($AP$1*AN23+$AQ$1*AO23) -> 0 | AR23: =(D23+J23+O23)-(X23+AH23) -> 0
A24: =CONCATENATE(B24,C24) -> 46184M | B24: =+B22+1 -> 46184 | C24: M | G24: =+D24*E24% -> 0 | H24: =+D24*F24% -> 0 | R24: =+J24+O24 -> 0 | S24: =+J24*K24%+O24*P24% -> 0 | T24: =+J24*L24%+O24*Q24% -> 0 | AA24: =X24*Y24% -> 0 | AB24: =X24*Z24% -> 0 | AF24: =AC24*AD24% -> 0 | AG24: =AC24*AE24% -> 0 | AK24: =AH24*AI24% -> 0 | AL24: =AH24*AJ24% -> 0 | AM24: =+D24+R24-AC24-AH24 -> 0 | AN24: =+G24+S24-AF24-AK24 -> 0 | AO24: =+H24+T24-AG24-AL24 -> 0 | AP24: =(AN24+AO24)/(S24+T24) -> #DIV/0! | AQ24: =($AP$1*AN24+$AQ$1*AO24) -> 0 | AR24: =(D24+J24+O24)-(X24+AH24) -> 0
A25: =CONCATENATE(B25,C25) -> 46184E | B25: =+B23+1 -> 46184 | C25: E | G25: =+D25*E25% -> 0 | H25: =+D25*F25% -> 0 | R25: =+J25+O25 -> 0 | S25: =+J25*K25%+O25*P25% -> 0 | T25: =+J25*L25%+O25*Q25% -> 0 | AA25: =X25*Y25% -> 0 | AB25: =X25*Z25% -> 0 | AF25: =AC25*AD25% -> 0 | AG25: =AC25*AE25% -> 0 | AK25: =AH25*AI25% -> 0 | AL25: =AH25*AJ25% -> 0 | AM25: =+D25+R25-AC25-AH25 -> 0 | AN25: =+G25+S25-AF25-AK25 -> 0 | AO25: =+H25+T25-AG25-AL25 -> 0 | AP25: =(AN25+AO25)/(S25+T25) -> #DIV/0! | AQ25: =($AP$1*AN25+$AQ$1*AO25) -> 0 | AR25: =(D25+J25+O25)-(X25+AH25) -> 0
A26: =CONCATENATE(B26,C26) -> 46185M | B26: =+B24+1 -> 46185 | C26: M | G26: =+D26*E26% -> 0 | H26: =+D26*F26% -> 0 | R26: =+J26+O26 -> 0 | S26: =+J26*K26%+O26*P26% -> 0 | T26: =+J26*L26%+O26*Q26% -> 0 | AA26: =X26*Y26% -> 0 | AB26: =X26*Z26% -> 0 | AF26: =AC26*AD26% -> 0 | AG26: =AC26*AE26% -> 0 | AK26: =AH26*AI26% -> 0 | AL26: =AH26*AJ26% -> 0 | AM26: =+D26+R26-AC26-AH26 -> 0 | AN26: =+G26+S26-AF26-AK26 -> 0 | AO26: =+H26+T26-AG26-AL26 -> 0 | AP26: =(AN26+AO26)/(S26+T26) -> #DIV/0! | AQ26: =($AP$1*AN26+$AQ$1*AO26) -> 0 | AR26: =(D26+J26+O26)-(X26+AH26) -> 0
A27: =CONCATENATE(B27,C27) -> 46185E | B27: =+B25+1 -> 46185 | C27: E | G27: =+D27*E27% -> 0 | H27: =+D27*F27% -> 0 | R27: =+J27+O27 -> 0 | S27: =+J27*K27%+O27*P27% -> 0 | T27: =+J27*L27%+O27*Q27% -> 0 | AA27: =X27*Y27% -> 0 | AB27: =X27*Z27% -> 0 | AF27: =AC27*AD27% -> 0 | AG27: =AC27*AE27% -> 0 | AK27: =AH27*AI27% -> 0 | AL27: =AH27*AJ27% -> 0 | AM27: =+D27+R27-AC27-AH27 -> 0 | AN27: =+G27+S27-AF27-AK27 -> 0 | AO27: =+H27+T27-AG27-AL27 -> 0 | AP27: =(AN27+AO27)/(S27+T27) -> #DIV/0! | AQ27: =($AP$1*AN27+$AQ$1*AO27) -> 0 | AR27: =(D27+J27+O27)-(X27+AH27) -> 0
A28: =CONCATENATE(B28,C28) -> 46186M | B28: =+B26+1 -> 46186 | C28: M | G28: =+D28*E28% -> 0 | H28: =+D28*F28% -> 0 | R28: =+J28+O28 -> 0 | S28: =+J28*K28%+O28*P28% -> 0 | T28: =+J28*L28%+O28*Q28% -> 0 | AA28: =X28*Y28% -> 0 | AB28: =X28*Z28% -> 0 | AF28: =AC28*AD28% -> 0 | AG28: =AC28*AE28% -> 0 | AK28: =AH28*AI28% -> 0 | AL28: =AH28*AJ28% -> 0 | AM28: =+D28+R28-AC28-AH28 -> 0 | AN28: =+G28+S28-AF28-AK28 -> 0 | AO28: =+H28+T28-AG28-AL28 -> 0 | AP28: =(AN28+AO28)/(S28+T28) -> #DIV/0! | AQ28: =($AP$1*AN28+$AQ$1*AO28) -> 0 | AR28: =(D28+J28+O28)-(X28+AH28) -> 0
A29: =CONCATENATE(B29,C29) -> 46186E | B29: =+B27+1 -> 46186 | C29: E | G29: =+D29*E29% -> 0 | H29: =+D29*F29% -> 0 | R29: =+J29+O29 -> 0 | S29: =+J29*K29%+O29*P29% -> 0 | T29: =+J29*L29%+O29*Q29% -> 0 | AA29: =X29*Y29% -> 0 | AB29: =X29*Z29% -> 0 | AF29: =AC29*AD29% -> 0 | AG29: =AC29*AE29% -> 0 | AK29: =AH29*AI29% -> 0 | AL29: =AH29*AJ29% -> 0 | AM29: =+D29+R29-AC29-AH29 -> 0 | AN29: =+G29+S29-AF29-AK29 -> 0 | AO29: =+H29+T29-AG29-AL29 -> 0 | AP29: =(AN29+AO29)/(S29+T29) -> #DIV/0! | AQ29: =($AP$1*AN29+$AQ$1*AO29) -> 0 | AR29: =(D29+J29+O29)-(X29+AH29) -> 0
A30: =CONCATENATE(B30,C30) -> 46187M | B30: =+B28+1 -> 46187 | C30: M | G30: =+D30*E30% -> 0 | H30: =+D30*F30% -> 0 | R30: =+J30+O30 -> 0 | S30: =+J30*K30%+O30*P30% -> 0 | T30: =+J30*L30%+O30*Q30% -> 0 | AA30: =X30*Y30% -> 0 | AB30: =X30*Z30% -> 0 | AF30: =AC30*AD30% -> 0 | AG30: =AC30*AE30% -> 0 | AK30: =AH30*AI30% -> 0 | AL30: =AH30*AJ30% -> 0 | AM30: =+D30+R30-AC30-AH30 -> 0 | AN30: =+G30+S30-AF30-AK30 -> 0 | AO30: =+H30+T30-AG30-AL30 -> 0 | AP30: =(AN30+AO30)/(S30+T30) -> #DIV/0! | AQ30: =($AP$1*AN30+$AQ$1*AO30) -> 0 | AR30: =(D30+J30+O30)-(X30+AH30) -> 0
A31: =CONCATENATE(B31,C31) -> 46187E | B31: =+B29+1 -> 46187 | C31: E | G31: =+D31*E31% -> 0 | H31: =+D31*F31% -> 0 | R31: =+J31+O31 -> 0 | S31: =+J31*K31%+O31*P31% -> 0 | T31: =+J31*L31%+O31*Q31% -> 0 | AA31: =X31*Y31% -> 0 | AB31: =X31*Z31% -> 0 | AF31: =AC31*AD31% -> 0 | AG31: =AC31*AE31% -> 0 | AK31: =AH31*AI31% -> 0 | AL31: =AH31*AJ31% -> 0 | AM31: =+D31+R31-AC31-AH31 -> 0 | AN31: =+G31+S31-AF31-AK31 -> 0 | AO31: =+H31+T31-AG31-AL31 -> 0 | AP31: =(AN31+AO31)/(S31+T31) -> #DIV/0! | AQ31: =($AP$1*AN31+$AQ$1*AO31) -> 0 | AR31: =(D31+J31+O31)-(X31+AH31) -> 0
A32: =CONCATENATE(B32,C32) -> 46188M | B32: =+B30+1 -> 46188 | C32: M | G32: =+D32*E32% -> 0 | H32: =+D32*F32% -> 0 | R32: =+J32+O32 -> 0 | S32: =+J32*K32%+O32*P32% -> 0 | T32: =+J32*L32%+O32*Q32% -> 0 | AA32: =X32*Y32% -> 0 | AB32: =X32*Z32% -> 0 | AF32: =AC32*AD32% -> 0 | AG32: =AC32*AE32% -> 0 | AK32: =AH32*AI32% -> 0 | AL32: =AH32*AJ32% -> 0 | AM32: =+D32+R32-AC32-AH32 -> 0 | AN32: =+G32+S32-AF32-AK32 -> 0 | AO32: =+H32+T32-AG32-AL32 -> 0 | AP32: =(AN32+AO32)/(S32+T32) -> #DIV/0! | AQ32: =($AP$1*AN32+$AQ$1*AO32) -> 0 | AR32: =(D32+J32+O32)-(X32+AH32) -> 0
A33: =CONCATENATE(B33,C33) -> 46188E | B33: =+B31+1 -> 46188 | C33: E | G33: =+D33*E33% -> 0 | H33: =+D33*F33% -> 0 | R33: =+J33+O33 -> 0 | S33: =+J33*K33%+O33*P33% -> 0 | T33: =+J33*L33%+O33*Q33% -> 0 | AA33: =X33*Y33% -> 0 | AB33: =X33*Z33% -> 0 | AF33: =AC33*AD33% -> 0 | AG33: =AC33*AE33% -> 0 | AK33: =AH33*AI33% -> 0 | AL33: =AH33*AJ33% -> 0 | AM33: =+D33+R33-AC33-AH33 -> 0 | AN33: =+G33+S33-AF33-AK33 -> 0 | AO33: =+H33+T33-AG33-AL33 -> 0 | AP33: =(AN33+AO33)/(S33+T33) -> #DIV/0! | AQ33: =($AP$1*AN33+$AQ$1*AO33) -> 0 | AR33: =(D33+J33+O33)-(X33+AH33) -> 0
... A65: =CONCATENATE(B65,C65) -> 46204E | B65: =+B63+1 -> 46204 | C65: E | G65: =+D65*E65% -> 0 | H65: =+D65*F65% -> 0 | R65: =+J65+O65 -> 0 | S65: =+J65*K65%+O65*P65% -> 0 | T65: =+J65*L65%+O65*Q65% -> 0 | AA65: =X65*Y65% -> 0 | AB65: =X65*Z65% -> 0 | AF65: =AC65*AD65% -> 0 | AG65: =AC65*AE65% -> 0 | AK65: =AH65*AI65% -> 0 | AL65: =AH65*AJ65% -> 0 | AM65: =+D65+R65-AC65-AH65 -> 0 | AN65: =+G65+S65-AF65-AK65 -> 0 | AO65: =+H65+T65-AG65-AL65 -> 0 | AP65: =(AN65+AO65)/(S65+T65) -> #DIV/0! | AQ65: =($AP$1*AN65+$AQ$1*AO65) -> 0 | AR65: =(D65+J65+O65)-(X65+AH65) -> 0
J66: =SUM(J4:J65) -> 37533.715 | AM66: =-SUM(AM4:AM65) -> -170.715 | AN66: =-SUM(AN4:AN65) -> 15.577818 | AO66: =-SUM(AO4:AO65) -> -24.48254 | AP66: =-SUM(AP4:AP65) -> #DIV/0! | AQ66: =-SUM(AQ4:AQ65) -> -333.93315
Q67: =2126*27 -> 57402
Q68: =2600*37 -> 96200

Sheet Hasanpur
B1: Hasanpur Bmc | AG1: 392 | AP1: =Sumarry!$K$4 -> 448.91 | AQ1: =Sumarry!$L$4 -> 299.27333
B2: Date | C2: Shift | D2: OB | I2: Milk from MPG in Ltr | M2: Transfer from other BMC/RMC | R2: Total Milk Receipt in Kg | U2: Tanker Dispatch Details | AC2: Plant Receipt | AH2: CB | AM2: Loss/(Gain)
D3: Qty KG | E3: Fat% | F3: Snf% | G3: FAT Kg | H3: SNF Kg | I3: Qty Ltr | J3: Qty Kg | K3: Fat% | L3: Snf% | M3: From | N3: Tanker No | O3: Qty Kg | P3: Fat% | Q3: Snf% | R3: Qty Kg | S3: FAT Kg | T3: SNF Kg | U3: Tanker | V3: Challan | W3: To | X3: Qty KG | Y3: Fat% | Z3: Snf% | AA3: FAT Kg | AB3: SNF Kg | AC3: Qty KG | AD3: Fat% | AE3: Snf% | AF3: FAT Kg | AG3: SNF Kg | AH3: Qty KG | AI3: Fat% | AJ3: Snf% | AK3: FAT Kg | AL3: SNF Kg | AM3: Qty KG | AN3: FAT Kg | AO3: SNF Kg | AP3: TS Loss% | AQ3: Amount
A4: =CONCATENATE(B4,C4) -> 46174M | B4: 46174 | C4: M | D4: 2645.2 | E4: 4.25 | F4: 8.2 | G4: =+D4*E4% -> 112.421 | H4: =+D4*F4% -> 216.9064 | I4: 754.8 | J4: 777.444 | K4: 4.404796 | L4: 8.1855856 | M4: 0 | N4: 0 | O4: 0 | P4: 0 | Q4: 0 | R4: =+J4+O4 -> 777.444 | S4: =+J4*K4%+O4*P4% -> 34.244822 | T4: =+J4*L4%+O4*Q4% -> 63.638344 | U4: 0 | V4: 0 | W4: 0 | X4: 0 | Y4: 0 | Z4: 0 | AA4: =X4*Y4% -> 0 | AB4: =X4*Z4% -> 0 | AF4: =AC4*AD4% -> 0 | AG4: =AC4*AE4% -> 0 | AH4: 3422 | AI4: 4.3 | AJ4: 8.2 | AK4: =AH4*AI4% -> 147.146 | AL4: =AH4*AJ4% -> 280.604 | AM4: =+D4+R4-AC4-AH4 -> 0.644 | AN4: =+G4+S4-AF4-AK4 -> -0.480178 | AO4: =+H4+T4-AG4-AL4 -> -0.059256 | AP4: =(AN4+AO4)/(S4+T4) -> -0.0055109987 | AQ4: =($AP$1*AN4+$AQ$1*AO4) -> -233.29045 | AR4: =(D4+J4+O4)-(X4+AH4) -> 0.644
A5: =CONCATENATE(B5,C5) -> 46174E | B5: =+B4 -> 46174 | C5: E | D5: 3422 | E5: 4.3 | F5: 8.2 | G5: =+D5*E5% -> 147.146 | H5: =+D5*F5% -> 280.604 | I5: 1164.2 | J5: 1199.126 | K5: 3.7507215 | L5: 7.9814121 | M5: 0 | N5: 0 | O5: 0 | P5: 0 | Q5: 0 | R5: =+J5+O5 -> 1199.126 | S5: =+J5*K5%+O5*P5% -> 44.975877 | T5: =+J5*L5%+O5*Q5% -> 95.707188 | U5: 0 | V5: 0 | W5: 0 | X5: 0 | Y5: 0 | Z5: 0 | AA5: =X5*Y5% -> 0 | AB5: =X5*Z5% -> 0 | AF5: =AC5*AD5% -> 0 | AG5: =AC5*AE5% -> 0 | AH5: 4622 | AI5: 4.17 | AJ5: 8.15 | AK5: =AH5*AI5% -> 192.7374 | AL5: =AH5*AJ5% -> 376.693 | AM5: =+D5+R5-AC5-AH5 -> -0.874 | AN5: =+G5+S5-AF5-AK5 -> -0.615523 | AO5: =+H5+T5-AG5-AL5 -> -0.381812 | AP5: =(AN5+AO5)/(S5+T5) -> -0.0070892328 | AQ5: =($AP$1*AN5+$AQ$1*AO5) -> -390.58058 | AR5: =(D5+J5+O5)-(X5+AH5) -> -0.874
A6: =CONCATENATE(B6,C6) -> 46175M | B6: =+B4+1 -> 46175 | C6: M | D6: 4622 | E6: 4.17 | F6: 8.15 | G6: =+D6*E6% -> 192.7374 | H6: =+D6*F6% -> 376.693 | I6: 759.5 | J6: 782.285 | K6: 4.4207505 | L6: 8.1474523 | M6: Singhiya | N6: 87610 | O6: 1790 | P6: 4.3 | Q6: 7.77 | R6: =+J6+O6 -> 2572.285 | S6: =+J6*K6%+O6*P6% -> 111.55287 | T6: =+J6*L6%+O6*Q6% -> 202.8193 | U6: 9071 | V6: 87855 | W6: Muzaffurpur | X6: 6200 | Y6: 4.3 | Z6: 8.27 | AA6: =X6*Y6% -> 266.6 | AB6: =X6*Z6% -> 512.74 | AC6: 6170 | AD6: 4.25 | AE6: 8.2 | AF6: =AC6*AD6% -> 262.225 | AG6: =AC6*AE6% -> 505.94 | AH6: 994 | AI6: 4.22 | AJ6: 8.05 | AK6: =AH6*AI6% -> 41.9468 | AL6: =AH6*AJ6% -> 80.017 | AM6: =+D6+R6-AC6-AH6 -> 30.285 | AN6: =+G6+S6-AF6-AK6 -> 0.118468 | AO6: =+H6+T6-AG6-AL6 -> -6.444703 | AP6: =(AN6+AO6)/(S6+T6) -> -0.020123394 | AQ6: =($AP$1*AN6+$AQ$1*AO6) -> -1875.5463 | AR6: =(D6+J6+O6)-(X6+AH6) -> 0.285
A7: =CONCATENATE(B7,C7) -> 46175E | B7: =+B5+1 -> 46175 | C7: E | D7: 994 | E7: 4.22 | F7: 8.05 | G7: =+D7*E7% -> 41.9468 | H7: =+D7*F7% -> 80.017 | I7: 1083.5 | J7: 1116.005 | K7: 3.7462021 | L7: 8.0374804 | M7: 0 | N7: 0 | O7: 0 | P7: 0 | Q7: 0 | R7: =+J7+O7 -> 1116.005 | S7: =+J7*K7%+O7*P7% -> 41.807803 | T7: =+J7*L7%+O7*Q7% -> 89.698683 | U7: 0 | V7: 0 | W7: 0 | X7: 0 | Y7: 0 | Z7: 0 | AA7: =X7*Y7% -> 0 | AB7: =X7*Z7% -> 0 | AF7: =AC7*AD7% -> 0 | AG7: =AC7*AE7% -> 0 | AH7: 2110 | AI7: 3.94 | AJ7: 8.02 | AK7: =AH7*AI7% -> 83.134 | AL7: =AH7*AJ7% -> 169.222 | AM7: =+D7+R7-AC7-AH7 -> 0.005 | AN7: =+G7+S7-AF7-AK7 -> 0.620603 | AO7: =+H7+T7-AG7-AL7 -> 0.493683 | AP7: =(AN7+AO7)/(S7+T7) -> 0.0084732399 | AQ7: =($AP$1*AN7+$AQ$1*AO7) -> 426.34105 | AR7: =(D7+J7+O7)-(X7+AH7) -> 0.005
A8: =CONCATENATE(B8,C8) -> 46176M | B8: =+B6+1 -> 46176 | C8: M | D8: 2110 | E8: 3.94 | F8: 8.02 | G8: =+D8*E8% -> 83.134 | H8: =+D8*F8% -> 169.222 | I8: 705.7 | J8: 726.871 | K8: 4.5484058 | L8: 8.1759104 | M8: Singhiya | N8: 87611 | O8: 1478 | P8: 4.5 | Q8: 8.06 | R8: =+J8+O8 -> 2204.871 | S8: =+J8*K8%+O8*P8% -> 99.571043 | T8: =+J8*L8%+O8*Q8% -> 178.55512 | U8: 00 | V8: 0 | W8: 0 | X8: 0 | Y8: 0 | Z8: 0 | AA8: =X8*Y8% -> 0 | AB8: =X8*Z8% -> 0 | AF8: =AC8*AD8% -> 0 | AG8: =AC8*AE8% -> 0 | AH8: 4315 | AI8: 4.23 | AJ8: 8.06 | AK8: =AH8*AI8% -> 182.5245 | AL8: =AH8*AJ8% -> 347.789 | AM8: =+D8+R8-AC8-AH8 -> -0.129 | AN8: =+G8+S8-AF8-AK8 -> 0.180543 | AO8: =+H8+T8-AG8-AL8 -> -0.011878 | AP8: =(AN8+AO8)/(S8+T8) -> 0.00060643341 | AQ8: =($AP$1*AN8+$AQ$1*AO8) -> 77.492789 | AR8: =(D8+J8+O8)-(X8+AH8) -> -0.129
A9: =CONCATENATE(B9,C9) -> 46176E | B9: =+B7+1 -> 46176 | C9: E | D9: 4315 | E9: 4.23 | F9: 8.06 | G9: =+D9*E9% -> 182.5245 | H9: =+D9*F9% -> 347.789 | I9: 830.1 | J9: 855.003 | K9: 3.7429828 | L9: 8.0582339 | M9: 0 | N9: 0 | O9: 0 | P9: 0 | Q9: 0 | R9: =+J9+O9 -> 855.003 | S9: =+J9*K9%+O9*P9% -> 32.002615 | T9: =+J9*L9%+O9*Q9% -> 68.898142 | U9: 9071 | V9: 87856 | W9: Manjhaul | X9: 3100 | Y9: 4.3 | Z9: 8.14 | AA9: =X9*Y9% -> 133.3 | AB9: =X9*Z9% -> 252.34 | AC9: 3090 | AD9: 4.25 | AE9: 8.07 | AF9: =AC9*AD9% -> 131.325 | AG9: =AC9*AE9% -> 249.363 | AH9: 2070 | AI9: 4.14 | AJ9: 8.06 | AK9: =AH9*AI9% -> 85.698 | AL9: =AH9*AJ9% -> 166.842 | AM9: =+D9+R9-AC9-AH9 -> 10.003 | AN9: =+G9+S9-AF9-AK9 -> -2.495885 | AO9: =+H9+T9-AG9-AL9 -> 0.482142 | AP9: =(AN9+AO9)/(S9+T9) -> -0.01995766 | AQ9: =($AP$1*AN9+$AQ$1*AO9) -> -976.13549 | AR9: =(D9+J9+O9)-(X9+AH9) -> 0.003
A10: =CONCATENATE(B10,C10) -> 46177M | B10: =+B8+1 -> 46177 | C10: M | D10: 2070 | E10: 4.14 | F10: 8.06 | G10: =+D10*E10% -> 85.698 | H10: =+D10*F10% -> 166.842 | I10: 756.5 | J10: 779.195 | K10: 4.6381097 | L10: 8.2042168 | M10: 0 | N10: 0 | O10: 0 | P10: 0 | Q10: 0 | R10: =+J10+O10 -> 779.195 | S10: =+J10*K10%+O10*P10% -> 36.139919 | T10: =+J10*L10%+O10*Q10% -> 63.926847 | U10: 0 | V10: 0 | W10: 0 | X10: 0 | Y10: 0 | Z10: 0 | AA10: =X10*Y10% -> 0 | AB10: =X10*Z10% -> 0 | AF10: =AC10*AD10% -> 0 | AG10: =AC10*AE10% -> 0 | AH10: 2850 | AI10: 4.26 | AJ10: 8.09 | AK10: =AH10*AI10% -> 121.41 | AL10: =AH10*AJ10% -> 230.565 | AM10: =+D10+R10-AC10-AH10 -> -0.805 | AN10: =+G10+S10-AF10-AK10 -> 0.427919 | AO10: =+H10+T10-AG10-AL10 -> 0.203847 | AP10: =(AN10+AO10)/(S10+T10) -> 0.0063134448 | AQ10: =($AP$1*AN10+$AQ$1*AO10) -> 253.10309 | AR10: =(D10+J10+O10)-(X10+AH10) -> -0.805
A11: =CONCATENATE(B11,C11) -> 46177E | B11: =+B9+1 -> 46177 | C11: E | D11: 2850 | E11: 4.26 | F11: 8.09 | G11: =+D11*E11% -> 121.41 | H11: =+D11*F11% -> 230.565 | I11: 1269.5 | J11: 1307.585 | K11: 3.9375345 | L11: 8.093462 | M11: Singhiya | N11: 87612 | O11: 2150 | P11: 4.45 | Q11: 7.93 | R11: =+J11+O11 -> 3457.585 | S11: =+J11*K11%+O11*P11% -> 147.16161 | T11: =+J11*L11%+O11*Q11% -> 276.32389 | U11: 3461 | V11: 87857 | W11: Muzaffurpur | X11: 3400 | Y11: 4.6 | Z11: 8.14 | AA11: =X11*Y11% -> 156.4 | AB11: =X11*Z11% -> 276.76 | AC11: 3450 | AD11: 4.55 | AE11: 8.07 | AF11: =AC11*AD11% -> 156.975 | AG11: =AC11*AE11% -> 278.415 | AH11: 2907 | AI11: 4.25 | AJ11: 8.04 | AK11: =AH11*AI11% -> 123.5475 | AL11: =AH11*AJ11% -> 233.7228 | AM11: =+D11+R11-AC11-AH11 -> -49.415 | AN11: =+G11+S11-AF11-AK11 -> -11.95089 | AO11: =+H11+T11-AG11-AL11 -> -5.248905 | AP11: =(AN11+AO11)/(S11+T11) -> -0.040614838 | AQ11: =($AP$1*AN11+$AQ$1*AO11) -> -6935.7313 | AR11: =(D11+J11+O11)-(X11+AH11) -> 0.585
A12: =CONCATENATE(B12,C12) -> 46178M | B12: =+B10+1 -> 46178 | C12: M | D12: 2907 | E12: 4.25 | F12: 8.04 | G12: =+D12*E12% -> 123.5475 | H12: =+D12*F12% -> 233.7228 | I12: 685.6 | J12: 706.168 | K12: 4.7 | L12: 8.2 | M12: 0 | N12: 0 | O12: 0 | P12: 0 | Q12: 0 | R12: =+J12+O12 -> 706.168 | S12: =+J12*K12%+O12*P12% -> 33.189896 | T12: =+J12*L12%+O12*Q12% -> 57.905776 | V12: 0 | W12: 0 | X12: 0 | Y12: 0 | Z12: 0 | AA12: =X12*Y12% -> 0 | AB12: =X12*Z12% -> 0 | AF12: =AC12*AD12% -> 0 | AG12: =AC12*AE12% -> 0 | AH12: 3613 | AI12: 4.34 | AJ12: 8.07 | AK12: =AH12*AI12% -> 156.8042 | AL12: =AH12*AJ12% -> 291.5691 | AM12: =+D12+R12-AC12-AH12 -> 0.168 | AN12: =+G12+S12-AF12-AK12 -> -0.066804 | AO12: =+H12+T12-AG12-AL12 -> 0.059476 | AP12: =(AN12+AO12)/(S12+T12) -> -8.04429e-05 | AQ12: =($AP$1*AN12+$AQ$1*AO12) -> -12.189403 | AR12: =(D12+J12+O12)-(X12+AH12) -> 0.168
A13: =CONCATENATE(B13,C13) -> 46178E | B13: =+B11+1 -> 46178 | C13: E | D13: 3613 | E13: 4.34 | F13: 8.07 | G13: =+D13*E13% -> 156.8042 | H13: =+D13*F13% -> 291.5691 | I13: 1096.6 | J13: 1129.498 | K13: 3.9 | L13: 8.1 | M13: Singhiya | N13: 87029 | O13: 1740 | P13: 4.2 | Q13: 7.6 | R13: =+J13+O13 -> 2869.498 | S13: =+J13*K13%+O13*P13% -> 117.13042 | T13: =+J13*L13%+O13*Q13% -> 223.72934 | U13: 6545 | V13: 87858 | W13: Muzaffurpur | X13: 6280 | Y13: 4.45 | Z13: 8.24 | AA13: =X13*Y13% -> 279.46 | AB13: =X13*Z13% -> 517.472 | AC13: 6250 | AD13: 4.34992 | AE13: 7.939936 | AF13: =AC13*AD13% -> 271.87 | AG13: =AC13*AE13% -> 496.246 | AH13: 183 | AI13: 4.22 | AJ13: 7.95 | AK13: =AH13*AI13% -> 7.7226 | AL13: =AH13*AJ13% -> 14.5485 | AM13: =+D13+R13-AC13-AH13 -> 49.498 | AN13: =+G13+S13-AF13-AK13 -> -5.657978 | AO13: =+H13+T13-AG13-AL13 -> 4.503938 | AP13: =(AN13+AO13)/(S13+T13) -> -0.0033856739 | AQ13: =($AP$1*AN13+$AQ$1*AO13) -> -1192.0144 | AR13: =(D13+J13+O13)-(X13+AH13) -> 19.498
A14: =CONCATENATE(B14,C14) -> 46179M | B14: =+B12+1 -> 46179 | C14: M | D14: 183 | E14: 4.22 | F14: 7.95 | G14: =+D14*E14% -> 7.7226 | H14: =+D14*F14% -> 14.5485 | I14: 693.4 | J14: 714.202 | K14: 4.6 | L14: 8.3 | M14: 0 | N14: 00 | O14: 0 | P14: 0 | Q14: 0 | R14: =+J14+O14 -> 714.202 | S14: =+J14*K14%+O14*P14% -> 32.853292 | T14: =+J14*L14%+O14*Q14% -> 59.278766 | U14: 0 | V14: 0 | W14: 0 | X14: 0 | Y14: 0 | Z14: 0 | AA14: =X14*Y14% -> 0 | AB14: =X14*Z14% -> 0 | AF14: =AC14*AD14% -> 0 | AG14: =AC14*AE14% -> 0 | AH14: 897.2 | AI14: 4.52 | AJ14: 8.23 | AK14: =AH14*AI14% -> 40.55344 | AL14: =AH14*AJ14% -> 73.83956 | AM14: =+D14+R14-AC14-AH14 -> 0.002 | AN14: =+G14+S14-AF14-AK14 -> 0.022452 | AO14: =+H14+T14-AG14-AL14 -> -0.012294 | AP14: =(AN14+AO14)/(S14+T14) -> 0.00011025478 | AQ14: =($AP$1*AN14+$AQ$1*AO14) -> 6.399661 | AR14: =(D14+J14+O14)-(X14+AH14) -> 0.002
A15: =CONCATENATE(B15,C15) -> 46179E | B15: =+B13+1 -> 46179 | C15: E | D15: 897.2 | E15: 4.52 | F15: 8.23 | G15: =+D15*E15% -> 40.55344 | H15: =+D15*F15% -> 73.83956 | I15: 1095.3 | J15: 1128.159 | K15: 3.9 | L15: 8 | M15: 0 | N15: 0 | O15: 0 | P15: 0 | Q15: 0 | R15: =+J15+O15 -> 1128.159 | S15: =+J15*K15%+O15*P15% -> 43.998201 | T15: =+J15*L15%+O15*Q15% -> 90.25272 | U15: 0 | V15: 0 | W15: 0 | X15: 0 | Y15: 0 | Z15: 0 | AA15: =X15*Y15% -> 0 | AB15: =X15*Z15% -> 0 | AF15: =AC15*AD15% -> 0 | AG15: =AC15*AE15% -> 0 | AH15: 2025.4 | AI15: 4.18 | AJ15: 8.1 | AK15: =AH15*AI15% -> 84.66172 | AL15: =AH15*AJ15% -> 164.0574 | AM15: =+D15+R15-AC15-AH15 -> -0.041 | AN15: =+G15+S15-AF15-AK15 -> -0.110079 | AO15: =+H15+T15-AG15-AL15 -> 0.03488 | AP15: =(AN15+AO15)/(S15+T15) -> -0.00056013768 | AQ15: =($AP$1*AN15+$AQ$1*AO15) -> -38.97691 | AR15: =(D15+J15+O15)-(X15+AH15) -> -0.041
A16: =CONCATENATE(B16,C16) -> 46180M | B16: =+B14+1 -> 46180 | C16: M | D16: 2025.4 | E16: 4.18 | F16: 8.1 | G16: =+D16*E16% -> 84.66172 | H16: =+D16*F16% -> 164.0574 | I16: 658.4 | J16: 678.152 | K16: 4.5 | L16: 8.3 | M16: Singhiya | N16: 87030 | O16: 2270 | P16: 4.2 | Q16: 8 | R16: =+J16+O16 -> 2948.152 | S16: =+J16*K16%+O16*P16% -> 125.85684 | T16: =+J16*L16%+O16*Q16% -> 237.88662 | U16: 6545 | V16: 87859 | W16: Manjhaul | X16: 5530 | Y16: 4.4264014 | Z16: 8.1132007 | AA16: =X16*Y16% -> 244.78 | AB16: =X16*Z16% -> 448.66 | AC16: 5520 | AD16: 4.2217391 | AE16: 8.0095652 | AF16: =AC16*AD16% -> 233.04 | AG16: =AC16*AE16% -> 442.128 | AH16: 0 | AI16: 0 | AJ16: 0 | AK16: =AH16*AI16% -> 0 | AL16: =AH16*AJ16% -> 0 | AM16: =+D16+R16-AC16-AH16 -> -546.448 | AN16: =+G16+S16-AF16-AK16 -> -22.52144 | AO16: =+H16+T16-AG16-AL16 -> -40.183984 | AP16: =(AN16+AO16)/(S16+T16) -> -0.17238915 | AQ16: =($AP$1*AN16+$AQ$1*AO16) -> -22136.094 | AR16: =(D16+J16+O16)-(X16+AH16) -> -556.448
A17: =CONCATENATE(B17,C17) -> 46180E | B17: =+B15+1 -> 46180 | C17: E | D17: 0 | E17: 0 | F17: 0 | G17: =+D17*E17% -> 0 | H17: =+D17*F17% -> 0 | I17: 1146.6 | J17: 1180.998 | K17: 3.9 | L17: 8.1 | M17: 0 | N17: 0 | O17: 0 | P17: 0 | Q17: 0 | R17: =+J17+O17 -> 1180.998 | S17: =+J17*K17%+O17*P17% -> 46.058922 | T17: =+J17*L17%+O17*Q17% -> 95.660838 | U17: 0 | V17: 0 | W17: 0 | X17: 0 | Y17: 0 | Z17: 0 | AA17: =X17*Y17% -> 0 | AB17: =X17*Z17% -> 0 | AF17: =AC17*AD17% -> 0 | AG17: =AC17*AE17% -> 0 | AH17: 1180.9 | AI17: 3.9 | AJ17: 8.1 | AK17: =AH17*AI17% -> 46.0551 | AL17: =AH17*AJ17% -> 95.6529 | AM17: =+D17+R17-AC17-AH17 -> 0.098 | AN17: =+G17+S17-AF17-AK17 -> 0.003822 | AO17: =+H17+T17-AG17-AL17 -> 0.007938 | AP17: =(AN17+AO17)/(S17+T17) -> 8.2980666e-05 | AQ17: =($AP$1*AN17+$AQ$1*AO17) -> 4.0913657 | AR17: =(D17+J17+O17)-(X17+AH17) -> 0.098
A18: =CONCATENATE(B18,C18) -> 46181M | B18: =+B16+1 -> 46181 | C18: M | D18: 1180.9 | E18: 3.9 | F18: 8.1 | G18: =+D18*E18% -> 46.0551 | H18: =+D18*F18% -> 95.6529 | I18: 748.3 | J18: 770.749 | K18: 4.5 | L18: 8.2 | M18: Singhiya | N18: 87031 | O18: 1370 | P18: 4.1 | Q18: 8 | R18: =+J18+O18 -> 2140.749 | S18: =+J18*K18%+O18*P18% -> 90.853705 | T18: =+J18*L18%+O18*Q18% -> 172.80142 | U18: 0 | V18: 0 | W18: 0 | X18: 0 | Y18: 0 | Z18: 0 | AA18: =X18*Y18% -> 0 | AB18: =X18*Z18% -> 0 | AF18: =AC18*AD18% -> 0 | AG18: =AC18*AE18% -> 0 | AH18: 3321.6 | AI18: 4.12 | AJ18: 8.08 | AK18: =AH18*AI18% -> 136.84992 | AL18: =AH18*AJ18% -> 268.38528 | AM18: =+D18+R18-AC18-AH18 -> 0.049 | AN18: =+G18+S18-AF18-AK18 -> 0.058885 | AO18: =+H18+T18-AG18-AL18 -> 0.069038 | AP18: =(AN18+AO18)/(S18+T18) -> 0.00048519065 | AQ18: =($AP$1*AN18+$AQ$1*AO18) -> 47.095298 | AR18: =(D18+J18+O18)-(X18+AH18) -> 0.049
A19: =CONCATENATE(B19,C19) -> 46181E | B19: =+B17+1 -> 46181 | C19: E | D19: 3321.6 | E19: 4.12 | F19: 8.08 | G19: =+D19*E19% -> 136.84992 | H19: =+D19*F19% -> 268.38528 | I19: 1136.9 | J19: 1171.007 | K19: 3.8 | L19: 8 | M19: 0 | N19: 0 | O19: 0 | P19: 0 | Q19: 0 | R19: =+J19+O19 -> 1171.007 | S19: =+J19*K19%+O19*P19% -> 44.498266 | T19: =+J19*L19%+O19*Q19% -> 93.68056 | U19: 0 | V19: 0 | W19: 0 | X19: 0 | Y19: 0 | Z19: 0 | AA19: =X19*Y19% -> 0 | AB19: =X19*Z19% -> 0 | AF19: =AC19*AD19% -> 0 | AG19: =AC19*AE19% -> 0 | AH19: 4493 | AI19: 4.03 | AJ19: 8.05 | AK19: =AH19*AI19% -> 181.0679 | AL19: =AH19*AJ19% -> 361.6865 | AM19: =+D19+R19-AC19-AH19 -> -0.393 | AN19: =+G19+S19-AF19-AK19 -> 0.280286 | AO19: =+H19+T19-AG19-AL19 -> 0.37934 | AP19: =(AN19+AO19)/(S19+T19) -> 0.0047737126 | AQ19: =($AP$1*AN19+$AQ$1*AO19) -> 239.34953 | AR19: =(D19+J19+O19)-(X19+AH19) -> -0.393
A20: =CONCATENATE(B20,C20) -> 46182M | B20: =+B18+1 -> 46182 | C20: M | D20: 4493 | E20: 4.03 | F20: 8.05 | G20: =+D20*E20% -> 181.0679 | H20: =+D20*F20% -> 361.6865 | I20: 665.5 | J20: 685.465 | K20: 4.5 | L20: 8.1 | M20: 0 | N20: 0 | O20: 0 | P20: 0 | Q20: 0 | R20: =+J20+O20 -> 685.465 | S20: =+J20*K20%+O20*P20% -> 30.845925 | T20: =+J20*L20%+O20*Q20% -> 55.522665 | U20: 9071 | V20: 87050 | W20: Munger | X20: 5300 | Y20: 4.16 | Z20: 8.07 | AA20: =X20*Y20% -> 220.48 | AB20: =X20*Z20% -> 427.71 | AC20: 5180 | AD20: 4.1081081 | AE20: 8.0513514 | AF20: =AC20*AD20% -> 212.8 | AG20: =AC20*AE20% -> 417.06 | AH20: 0 | AI20: 0 | AJ20: 0 | AK20: =AH20*AI20% -> 0 | AL20: =AH20*AJ20% -> 0 | AM20: =+D20+R20-AC20-AH20 -> -1.535 | AN20: =+G20+S20-AF20-AK20 -> -0.886175 | AO20: =+H20+T20-AG20-AL20 -> 0.149165 | AP20: =(AN20+AO20)/(S20+T20) -> -0.0085333105 | AQ20: =($AP$1*AN20+$AQ$1*AO20) -> -353.17171 | AR20: =(D20+J20+O20)-(X20+AH20) -> -121.535
A21: =CONCATENATE(B21,C21) -> 46182E | B21: =+B19+1 -> 46182 | C21: E | D21: 0 | E21: 0 | F21: 0 | G21: =+D21*E21% -> 0 | H21: =+D21*F21% -> 0 | I21: 1069.2 | J21: 1101.276 | K21: 4 | L21: 8.1 | M21: Singhiya | N21: 2950/87032 | O21: 1486 | P21: 4 | Q21: 7.96 | R21: =+J21+O21 -> 2587.276 | S21: =+J21*K21%+O21*P21% -> 103.49104 | T21: =+J21*L21%+O21*Q21% -> 207.48896 | U21: 0 | V21: 0 | W21: 0 | X21: 0 | Y21: 0 | Z21: 0 | AA21: =X21*Y21% -> 0 | AB21: =X21*Z21% -> 0 | AF21: =AC21*AD21% -> 0 | AG21: =AC21*AE21% -> 0 | AH21: 2587.3 | AI21: 4 | AJ21: 8.1 | AK21: =AH21*AI21% -> 103.492 | AL21: =AH21*AJ21% -> 209.5713 | AM21: =+D21+R21-AC21-AH21 -> -0.024 | AN21: =+G21+S21-AF21-AK21 -> -0.00096 | AO21: =+H21+T21-AG21-AL21 -> -2.082344 | AP21: =(AN21+AO21)/(S21+T21) -> -0.0066991576 | AQ21: =($AP$1*AN21+$AQ$1*AO21) -> -623.62098 | AR21: =(D21+J21+O21)-(X21+AH21) -> -0.024
A22: =CONCATENATE(B22,C22) -> 46183M | B22: =+B20+1 -> 46183 | C22: M | D22: 2587.3 | E22: 4 | F22: 8.1 | G22: =+D22*E22% -> 103.492 | H22: =+D22*F22% -> 209.5713 | I22: 645.2 | J22: 664.556 | K22: 4.4 | L22: 8.21 | M22: 0 | N22: 0 | O22: 0 | P22: 0 | Q22: 0 | R22: =+J22+O22 -> 664.556 | S22: =+J22*K22%+O22*P22% -> 29.240464 | T22: =+J22*L22%+O22*Q22% -> 54.560048 | U22: 0 | V22: 0 | W22: 0 | X22: 0 | Y22: 0 | Z22: 0 | AA22: =X22*Y22% -> 0 | AB22: =X22*Z22% -> 0 | AF22: =AC22*AD22% -> 0 | AG22: =AC22*AE22% -> 0 | AH22: 3252 | AI22: 4.08 | AJ22: 8.12 | AK22: =AH22*AI22% -> 132.6816 | AL22: =AH22*AJ22% -> 264.0624 | AM22: =+D22+R22-AC22-AH22 -> -0.144 | AN22: =+G22+S22-AF22-AK22 -> 0.050864 | AO22: =+H22+T22-AG22-AL22 -> 0.0689476 | AP22: =(AN22+AO22)/(S22+T22) -> 0.001429724 | AQ22: =($AP$1*AN22+$AQ$1*AO22) -> 43.467536 | AR22: =(D22+J22+O22)-(X22+AH22) -> -0.144
A23: =CONCATENATE(B23,C23) -> 46183E | B23: =+B21+1 -> 46183 | C23: E | D23: 3252 | E23: 4.08 | F23: 8.12 | G23: =+D23*E23% -> 132.6816 | H23: =+D23*F23% -> 264.0624 | I23: 1089.8 | J23: 1122.494 | K23: 4 | L23: 8.1 | M23: 0 | N23: 0 | O23: 0 | P23: 0 | Q23: 0 | R23: =+J23+O23 -> 1122.494 | S23: =+J23*K23%+O23*P23% -> 44.89976 | T23: =+J23*L23%+O23*Q23% -> 90.922014 | U23: 0 | V23: 0 | W23: 0 | X23: 0 | Y23: 0 | Z23: 0 | AA23: =X23*Y23% -> 0 | AB23: =X23*Z23% -> 0 | AF23: =AC23*AD23% -> 0 | AG23: =AC23*AE23% -> 0 | AH23: 4375 | AI23: 4.06 | AJ23: 8.11 | AK23: =AH23*AI23% -> 177.625 | AL23: =AH23*AJ23% -> 354.8125 | AM23: =+D23+R23-AC23-AH23 -> -0.506 | AN23: =+G23+S23-AF23-AK23 -> -0.04364 | AO23: =+H23+T23-AG23-AL23 -> 0.171914 | AP23: =(AN23+AO23)/(S23+T23) -> 0.00094442884 | AQ23: =($AP$1*AN23+$AQ$1*AO23) -> 31.858843 | AR23: =(D23+J23+O23)-(X23+AH23) -> -0.506
A24: =CONCATENATE(B24,C24) -> 46184M | B24: =+B22+1 -> 46184 | C24: M | D24: 4375 | E24: 4.06 | F24: 8.11 | G24: =+D24*E24% -> 177.625 | H24: =+D24*F24% -> 354.8125 | I24: 706 | J24: 727.18 | K24: 4.4 | L24: 8.2 | M24: Singhiya | N24: 83492 | O24: 1545 | P24: 4.2 | Q24: 7.85 | R24: =+J24+O24 -> 2272.18 | S24: =+J24*K24%+O24*P24% -> 96.88592 | T24: =+J24*L24%+O24*Q24% -> 180.91126 | U24: 9071 | V24: 87861 | W24: Muzaffurpur | X24: 6200 | Y24: 4.25 | Z24: 8.26 | AA24: =X24*Y24% -> 263.5 | AB24: =X24*Z24% -> 512.12 | AC24: 6200 | AD24: 4.25 | AE24: 8.26 | AF24: =AC24*AD24% -> 263.5 | AG24: =AC24*AE24% -> 512.12 | AH24: 448 | AI24: 4.13 | AJ24: 8.05 | AK24: =AH24*AI24% -> 18.5024 | AL24: =AH24*AJ24% -> 36.064 | AM24: =+D24+R24-AC24-AH24 -> -0.82 | AN24: =+G24+S24-AF24-AK24 -> -7.49148 | AO24: =+H24+T24-AG24-AL24 -> -12.46024 | AP24: =(AN24+AO24)/(S24+T24) -> -0.071821175 | AQ24: =($AP$1*AN24+$AQ$1*AO24) -> -7092.0178 | AR24: =(D24+J24+O24)-(X24+AH24) -> -0.82
A25: =CONCATENATE(B25,C25) -> 46184E | B25: =+B23+1 -> 46184 | C25: E | D25: 448 | E25: 4.13 | F25: 8.05 | G25: =+D25*E25% -> 18.5024 | H25: =+D25*F25% -> 36.064 | I25: 1071 | J25: 1103.13 | K25: 4 | L25: 8.2 | M25: 0 | N25: 0 | O25: 0 | P25: 0 | Q25: 0 | R25: =+J25+O25 -> 1103.13 | S25: =+J25*K25%+O25*P25% -> 44.1252 | T25: =+J25*L25%+O25*Q25% -> 90.45666 | U25: 0 | V25: 0 | W25: 0 | X25: 0 | Y25: 0 | Z25: 0 | AA25: =X25*Y25% -> 0 | AB25: =X25*Z25% -> 0 | AF25: =AC25*AD25% -> 0 | AG25: =AC25*AE25% -> 0 | AH25: 1551 | AI25: 4.04 | AJ25: 8.15 | AK25: =AH25*AI25% -> 62.6604 | AL25: =AH25*AJ25% -> 126.4065 | AM25: =+D25+R25-AC25-AH25 -> 0.13 | AN25: =+G25+S25-AF25-AK25 -> -0.0328 | AO25: =+H25+T25-AG25-AL25 -> 0.11416 | AP25: =(AN25+AO25)/(S25+T25) -> 0.00060453913 | AQ25: =($AP$1*AN25+$AQ$1*AO25) -> 19.440796 | AR25: =(D25+J25+O25)-(X25+AH25) -> 0.13
A26: =CONCATENATE(B26,C26) -> 46185M | B26: =+B24+1 -> 46185 | C26: M | G26: =+D26*E26% -> 0 | H26: =+D26*F26% -> 0 | R26: =+J26+O26 -> 0 | S26: =+J26*K26%+O26*P26% -> 0 | T26: =+J26*L26%+O26*Q26% -> 0 | AA26: =X26*Y26% -> 0 | AB26: =X26*Z26% -> 0 | AF26: =AC26*AD26% -> 0 | AG26: =AC26*AE26% -> 0 | AK26: =AH26*AI26% -> 0 | AL26: =AH26*AJ26% -> 0 | AM26: =+D26+R26-AC26-AH26 -> 0 | AN26: =+G26+S26-AF26-AK26 -> 0 | AO26: =+H26+T26-AG26-AL26 -> 0 | AP26: =(AN26+AO26)/(S26+T26) -> #DIV/0! | AQ26: =($AP$1*AN26+$AQ$1*AO26) -> 0 | AR26: =(D26+J26+O26)-(X26+AH26) -> 0
A27: =CONCATENATE(B27,C27) -> 46185E | B27: =+B25+1 -> 46185 | C27: E | G27: =+D27*E27% -> 0 | H27: =+D27*F27% -> 0 | R27: =+J27+O27 -> 0 | S27: =+J27*K27%+O27*P27% -> 0 | T27: =+J27*L27%+O27*Q27% -> 0 | AA27: =X27*Y27% -> 0 | AB27: =X27*Z27% -> 0 | AF27: =AC27*AD27% -> 0 | AG27: =AC27*AE27% -> 0 | AK27: =AH27*AI27% -> 0 | AL27: =AH27*AJ27% -> 0 | AM27: =+D27+R27-AC27-AH27 -> 0 | AN27: =+G27+S27-AF27-AK27 -> 0 | AO27: =+H27+T27-AG27-AL27 -> 0 | AP27: =(AN27+AO27)/(S27+T27) -> #DIV/0! | AQ27: =($AP$1*AN27+$AQ$1*AO27) -> 0 | AR27: =(D27+J27+O27)-(X27+AH27) -> 0
A28: =CONCATENATE(B28,C28) -> 46186M | B28: =+B26+1 -> 46186 | C28: M | G28: =+D28*E28% -> 0 | H28: =+D28*F28% -> 0 | R28: =+J28+O28 -> 0 | S28: =+J28*K28%+O28*P28% -> 0 | T28: =+J28*L28%+O28*Q28% -> 0 | AA28: =X28*Y28% -> 0 | AB28: =X28*Z28% -> 0 | AF28: =AC28*AD28% -> 0 | AG28: =AC28*AE28% -> 0 | AK28: =AH28*AI28% -> 0 | AL28: =AH28*AJ28% -> 0 | AM28: =+D28+R28-AC28-AH28 -> 0 | AN28: =+G28+S28-AF28-AK28 -> 0 | AO28: =+H28+T28-AG28-AL28 -> 0 | AP28: =(AN28+AO28)/(S28+T28) -> #DIV/0! | AQ28: =($AP$1*AN28+$AQ$1*AO28) -> 0 | AR28: =(D28+J28+O28)-(X28+AH28) -> 0
A29: =CONCATENATE(B29,C29) -> 46186E | B29: =+B27+1 -> 46186 | C29: E | G29: =+D29*E29% -> 0 | H29: =+D29*F29% -> 0 | R29: =+J29+O29 -> 0 | S29: =+J29*K29%+O29*P29% -> 0 | T29: =+J29*L29%+O29*Q29% -> 0 | AA29: =X29*Y29% -> 0 | AB29: =X29*Z29% -> 0 | AF29: =AC29*AD29% -> 0 | AG29: =AC29*AE29% -> 0 | AK29: =AH29*AI29% -> 0 | AL29: =AH29*AJ29% -> 0 | AM29: =+D29+R29-AC29-AH29 -> 0 | AN29: =+G29+S29-AF29-AK29 -> 0 | AO29: =+H29+T29-AG29-AL29 -> 0 | AP29: =(AN29+AO29)/(S29+T29) -> #DIV/0! | AQ29: =($AP$1*AN29+$AQ$1*AO29) -> 0 | AR29: =(D29+J29+O29)-(X29+AH29) -> 0
